Workbook

Sheet How To Use
A1: Claims Template - AIN SHAMS UNIVERSITY - EMPLOYEES & PENSIONERS (Chronic)
A3: Monthly steps
A4: 1. Open the 'Per Line' tab. Delete the old data in the BLUE columns only (row 2 down). Never delete the green or grey columns.
A5: 2. Paste the new month's data as VALUES starting at A2, into the blue columns: A-P, R-AA, AF-AM (same order as the system export).
A6: 3. Green columns (Q, AB, AC, AD, AE) and the grey helper columns (AN-AR) calculate automatically - do not paste over them.
A7: 4. 'Per Invoice' fills itself from 'Per Line' (one row per Order #, split into IMP / Local). No pivot table, no refresh.
A8: 5. The ONLY manual column in 'Per Invoice' is column A 'Invoice' (blue): type it yourself. Everything else is formula.
A9: 6. The tabs, the Arabic 'Template ...' sheets and 'Summary' fill themselves from 'Per Invoice'. Column 'Site Tab (##)' decides which tab each invoice goes to (rule and limit are in Settings).
A10: 7. Open 'Settings' and check STATUS says OK (Per Line = Per Invoice, and every invoice has a payer that is listed in Settings).
A12: Colour legend
A13: Blue header = typed/pasted by you (raw data, and 'Invoice' in Per Invoice). Green header = formula (do not paste over). Grey header = helper formula (do not touch). Yellow cell (Settings) = editable rate.
A15: Calculation rules (taken from the October 2026 sheet)
... A22: Max Limit rule (as in the old sheet): if an invoice's Grand Total is above its Max Limit, Co val = Co Payment x Max Limit / 100 + (Grand Total - Max Limit). Per Line keeps the plain Co val, so 'Settings' shows the difference as 'Max Limit adjustment'.

Sheet Settings
B1: Company settings & checks
B3: Insurance Company | C3: AIN SHAMS UNIVERSITY - EMPLOYEES & PENSIONERS | D3: Informational only
B4: Corporate | C4: Ain Shams University Employees; Ain Shams University Pensioners | D4: Informational only
B5: Sheet type | C5: Chronic | D5: Informational only
B6: Local products rebate % | C6: 0.19 | D6: Source: Oct sheet (Rebates = 19 on Local lines).
B7: Imported (IMP) products rebate % | C7: 0.09 | D7: Source: Oct sheet (Rebates = 9 on non-local lines).
B9: Month totals / reconciliation
B10: Lines loaded | C10: =COUNTA('Per Line'!$E$2:$E$3001)
B11: Invoices (unique Order #) | C11: =MAX('Per Line'!$AO$2:$AO$3001)
B12: Invoices shown in Per Invoice | C12: =SUMPRODUCT(--('Per Invoice'!$B$2:$B$601<>""))
B13: Grand Total - Per Line (Product Total) | C13: =SUM('Per Line'!$Y$2:$Y$3001)
B14: Grand Total - Per Invoice | C14: =SUM('Per Invoice'!$Y$2:$Y$601)
B15: Discount - Per Line | C15: =SUM('Per Line'!$AC$2:$AC$3001)
B16: Discount - Per Invoice | C16: =SUM('Per Invoice'!$W$2:$W$601)
B17: Co val - Per Line | C17: =SUM('Per Line'!$Q$2:$Q$3001)
B18: Co val - Per Invoice | C18: =SUM('Per Invoice'!$K$2:$K$601)
B19: Net - Per Line | C19: =SUM('Per Line'!$AE$2:$AE$3001)
B20: Net - Per Invoice | C20: =SUM('Per Invoice'!$Z$2:$Z$601)
B21: Max Limit adjustment (Co val, Per Invoice only) | C21: =SUM('Per Invoice'!$AB$2:$AB$601) | D21: Invoices whose Grand Total is above the Max Limit: Co val = Co% x Max Limit / 100 + (Grand Total - Max Limit). This difference exists only in Per Invoice, as in the old sheet.
B23: STATUS | C23: =IF(C10=0,"No data loaded",IF(COUNTA('Per Line'!$E:$E)-1>3000,"TOO MANY LINES - extend template",IF(C11>600,"TOO MANY INVOICES - extend template",IF(AND(ROUND(C13-C14,2)=0,ROUND(C15-C16,2)=0,ROUND(C17+C21-C18,2)=0,ROUND(C19-C21-C20,2)=0,C11=C12,C35=0,MAX(D26:D33)<=200),"OK","CHECK - Per Line and Per Invoice do not match")))) | D23: Must say OK after you paste the month data.
B25: Site tabs | C25: Site name exactly as in the Site Tab (##) column | D25: Invoices (formula)
B26: October Employees | C26: October Ain Shams University Employees | D26: =IF(C26="",0,COUNTIF('Per Invoice'!$C$2:$C$601,C26))
B27: October Pensioners | C27: October Ain Shams University Pensioners | D27: =IF(C27="",0,COUNTIF('Per Invoice'!$C$2:$C$601,C27))
B28: September Employees | C28: September Ain Shams University Employees | D28: =IF(C28="",0,COUNTIF('Per Invoice'!$C$2:$C$601,C28))
B29: September Pensioners | C29: September Ain Shams University Pensioners | D29: =IF(C29="",0,COUNTIF('Per Invoice'!$C$2:$C$601,C29))
B30: September Staff | C30: September Ain Shams University Staff | D30: =IF(C30="",0,COUNTIF('Per Invoice'!$C$2:$C$601,C30))
B31: October Staff | C31: October Ain Shams University Staff | D31: =IF(C31="",0,COUNTIF('Per Invoice'!$C$2:$C$601,C31))
B32: Extra 1 | D32: =IF(C32="",0,COUNTIF('Per Invoice'!$C$2:$C$601,C32))
B33: Extra 2 | D33: =IF(C33="",0,COUNTIF('Per Invoice'!$C$2:$C$601,C33))
B35: Invoices not in any site tab (must be 0) | C35: =C11-SUM(D26:D33) | D35: If not 0: a new site appeared. Type its exact name in one of the empty yellow cells above (Extra 1 ... Extra n); the tab Extra n then shows it. Each tab holds up to 200 invoices.

Sheet Summary
A1: Corporate | B1: Count | C1: اجمالي المحلي | D1: اجمالي المستورد | E1: الخصم | F1: التحمل | G1: ما زاد عن الحد | H1: الصافي
A2: =IF(Settings!$C$26="","",Settings!$C$26) | B2: =IF($A2="","",COUNTIF('Per Invoice'!$C$2:$C$601,$A2)) | C2: =IF($A2="","",SUMIFS('Per Invoice'!$U$2:$U$601,'Per Invoice'!$C$2:$C$601,$A2)) | D2: =IF($A2="","",SUMIFS('Per Invoice'!$R$2:$R$601,'Per Invoice'!$C$2:$C$601,$A2)) | E2: =IF($A2="","",SUMIFS('Per Invoice'!$W$2:$W$601,'Per Invoice'!$C$2:$C$601,$A2)) | F2: =IF($A2="","",SUMIFS('Per Invoice'!$K$2:$K$601,'Per Invoice'!$C$2:$C$601,$A2)) | G2: =IF($A2="","",SUMIFS('Per Invoice'!$O$2:$O$601,'Per Invoice'!$C$2:$C$601,$A2)) | H2: =IF($A2="","",SUMIFS('Per Invoice'!$Z$2:$Z$601,'Per Invoice'!$C$2:$C$601,$A2))
A3: =IF(Settings!$C$27="","",Settings!$C$27) | B3: =IF($A3="","",COUNTIF('Per Invoice'!$C$2:$C$601,$A3)) | C3: =IF($A3="","",SUMIFS('Per Invoice'!$U$2:$U$601,'Per Invoice'!$C$2:$C$601,$A3)) | D3: =IF($A3="","",SUMIFS('Per Invoice'!$R$2:$R$601,'Per Invoice'!$C$2:$C$601,$A3)) | E3: =IF($A3="","",SUMIFS('Per Invoice'!$W$2:$W$601,'Per Invoice'!$C$2:$C$601,$A3)) | F3: =IF($A3="","",SUMIFS('Per Invoice'!$K$2:$K$601,'Per Invoice'!$C$2:$C$601,$A3)) | G3: =IF($A3="","",SUMIFS('Per Invoice'!$O$2:$O$601,'Per Invoice'!$C$2:$C$601,$A3)) | H3: =IF($A3="","",SUMIFS('Per Invoice'!$Z$2:$Z$601,'Per Invoice'!$C$2:$C$601,$A3))
A4: =IF(Settings!$C$28="","",Settings!$C$28) | B4: =IF($A4="","",COUNTIF('Per Invoice'!$C$2:$C$601,$A4)) | C4: =IF($A4="","",SUMIFS('Per Invoice'!$U$2:$U$601,'Per Invoice'!$C$2:$C$601,$A4)) | D4: =IF($A4="","",SUMIFS('Per Invoice'!$R$2:$R$601,'Per Invoice'!$C$2:$C$601,$A4)) | E4: =IF($A4="","",SUMIFS('Per Invoice'!$W$2:$W$601,'Per Invoice'!$C$2:$C$601,$A4)) | F4: =IF($A4="","",SUMIFS('Per Invoice'!$K$2:$K$601,'Per Invoice'!$C$2:$C$601,$A4)) | G4: =IF($A4="","",SUMIFS('Per Invoice'!$O$2:$O$601,'Per Invoice'!$C$2:$C$601,$A4)) | H4: =IF($A4="","",SUMIFS('Per Invoice'!$Z$2:$Z$601,'Per Invoice'!$C$2:$C$601,$A4))
A5: =IF(Settings!$C$29="","",Settings!$C$29) | B5: =IF($A5="","",COUNTIF('Per Invoice'!$C$2:$C$601,$A5)) | C5: =IF($A5="","",SUMIFS('Per Invoice'!$U$2:$U$601,'Per Invoice'!$C$2:$C$601,$A5)) | D5: =IF($A5="","",SUMIFS('Per Invoice'!$R$2:$R$601,'Per Invoice'!$C$2:$C$601,$A5)) | E5: =IF($A5="","",SUMIFS('Per Invoice'!$W$2:$W$601,'Per Invoice'!$C$2:$C$601,$A5)) | F5: =IF($A5="","",SUMIFS('Per Invoice'!$K$2:$K$601,'Per Invoice'!$C$2:$C$601,$A5)) | G5: =IF($A5="","",SUMIFS('Per Invoice'!$O$2:$O$601,'Per Invoice'!$C$2:$C$601,$A5)) | H5: =IF($A5="","",SUMIFS('Per Invoice'!$Z$2:$Z$601,'Per Invoice'!$C$2:$C$601,$A5))
A6: =IF(Settings!$C$30="","",Settings!$C$30) | B6: =IF($A6="","",COUNTIF('Per Invoice'!$C$2:$C$601,$A6)) | C6: =IF($A6="","",SUMIFS('Per Invoice'!$U$2:$U$601,'Per Invoice'!$C$2:$C$601,$A6)) | D6: =IF($A6="","",SUMIFS('Per Invoice'!$R$2:$R$601,'Per Invoice'!$C$2:$C$601,$A6)) | E6: =IF($A6="","",SUMIFS('Per Invoice'!$W$2:$W$601,'Per Invoice'!$C$2:$C$601,$A6)) | F6: =IF($A6="","",SUMIFS('Per Invoice'!$K$2:$K$601,'Per Invoice'!$C$2:$C$601,$A6)) | G6: =IF($A6="","",SUMIFS('Per Invoice'!$O$2:$O$601,'Per Invoice'!$C$2:$C$601,$A6)) | H6: =IF($A6="","",SUMIFS('Per Invoice'!$Z$2:$Z$601,'Per Invoice'!$C$2:$C$601,$A6))
A7: =IF(Settings!$C$31="","",Settings!$C$31) | B7: =IF($A7="","",COUNTIF('Per Invoice'!$C$2:$C$601,$A7)) | C7: =IF($A7="","",SUMIFS('Per Invoice'!$U$2:$U$601,'Per Invoice'!$C$2:$C$601,$A7)) | D7: =IF($A7="","",SUMIFS('Per Invoice'!$R$2:$R$601,'Per Invoice'!$C$2:$C$601,$A7)) | E7: =IF($A7="","",SUMIFS('Per Invoice'!$W$2:$W$601,'Per Invoice'!$C$2:$C$601,$A7)) | F7: =IF($A7="","",SUMIFS('Per Invoice'!$K$2:$K$601,'Per Invoice'!$C$2:$C$601,$A7)) | G7: =IF($A7="","",SUMIFS('Per Invoice'!$O$2:$O$601,'Per Invoice'!$C$2:$C$601,$A7)) | H7: =IF($A7="","",SUMIFS('Per Invoice'!$Z$2:$Z$601,'Per Invoice'!$C$2:$C$601,$A7))
A8: =IF(Settings!$C$32="","",Settings!$C$32) | B8: =IF($A8="","",COUNTIF('Per Invoice'!$C$2:$C$601,$A8)) | C8: =IF($A8="","",SUMIFS('Per Invoice'!$U$2:$U$601,'Per Invoice'!$C$2:$C$601,$A8)) | D8: =IF($A8="","",SUMIFS('Per Invoice'!$R$2:$R$601,'Per Invoice'!$C$2:$C$601,$A8)) | E8: =IF($A8="","",SUMIFS('Per Invoice'!$W$2:$W$601,'Per Invoice'!$C$2:$C$601,$A8)) | F8: =IF($A8="","",SUMIFS('Per Invoice'!$K$2:$K$601,'Per Invoice'!$C$2:$C$601,$A8)) | G8: =IF($A8="","",SUMIFS('Per Invoice'!$O$2:$O$601,'Per Invoice'!$C$2:$C$601,$A8)) | H8: =IF($A8="","",SUMIFS('Per Invoice'!$Z$2:$Z$601,'Per Invoice'!$C$2:$C$601,$A8))
A9: =IF(Settings!$C$33="","",Settings!$C$33) | B9: =IF($A9="","",COUNTIF('Per Invoice'!$C$2:$C$601,$A9)) | C9: =IF($A9="","",SUMIFS('Per Invoice'!$U$2:$U$601,'Per Invoice'!$C$2:$C$601,$A9)) | D9: =IF($A9="","",SUMIFS('Per Invoice'!$R$2:$R$601,'Per Invoice'!$C$2:$C$601,$A9)) | E9: =IF($A9="","",SUMIFS('Per Invoice'!$W$2:$W$601,'Per Invoice'!$C$2:$C$601,$A9)) | F9: =IF($A9="","",SUMIFS('Per Invoice'!$K$2:$K$601,'Per Invoice'!$C$2:$C$601,$A9)) | G9: =IF($A9="","",SUMIFS('Per Invoice'!$O$2:$O$601,'Per Invoice'!$C$2:$C$601,$A9)) | H9: =IF($A9="","",SUMIFS('Per Invoice'!$Z$2:$Z$601,'Per Invoice'!$C$2:$C$601,$A9))
A10: الاجمالي | B10: =SUM(B2:B9) | C10: =SUM(C2:C9) | D10: =SUM(D2:D9) | E10: =SUM(E2:E9) | F10: =SUM(F2:F9) | G10: =SUM(G2:G9) | H10: =SUM(H2:H9)

Sheet Per Line
A1: Cycle | B1: Ticket # | C1: Stage | D1: Approval Ref | E1: Order # | F1: Channel | G1: Create At | H1: Insurance Company | I1: Country Portal ID | J1: Corporate | K1: Card | L1: Name | M1: Status | N1: Local Rebates | O1: Imported Rebates | P1: Order Co Payment | Q1: Co val | R1: By Patient | S1: heisenberg id | T1: Product Name | U1: Local | V1: Unit | W1: Quantity | X1: Unit Price | Y1: Product Total | Z1: ERX ID | AA1: Special Rebates? | AB1: Rebates | AC1: Discount | AD1: Subtotal | AE1: Net | AF1: Approval Type | AG1: Max Limit | AH1: Exceeding Limit | AI1: Amount collected from customer | AJ1: By Patient (Delivered) | AK1: Dispense Number | AL1: Dispense Date | AM1: Has OTP? | AN1: Order 1st Row (helper) | AO1: Invoice # (helper) | AP1: Is Local (helper) | AQ1: Is Special (helper) | AR1: Sort Key (helper)
Q2: =IF($E2="","",P2*Y2/100) | AB2: =IF($E2="","",IF($AQ2=1,0,IF($AP2=1,Settings!$C$6,Settings!$C$7))*100) | AC2: =IF($E2="","",Y2*AB2/100) | AD2: =IF($E2="","",Y2-AC2) | AE2: =IF($E2="","",AD2-Q2) | AN2: =IF($E2="","",IF(COUNTIF($E$2:$E2,$E2)=1,1,0)) | AO2: =IF($AN2=1,SUMPRODUCT(--($AR$2:$AR$3001<$AR2))+1,"") | AP2: =IF($E2="","",IF(OR($U2=TRUE(),$U2="TRUE"),1,0)) | AQ2: =IF($E2="","",IF($AA2="Yes",1,0)) | AR2: =IF($AN2=1,IFERROR(IF(VALUE($E2)<100000000,VALUE($E2),1000000000),IFERROR(IF(VALUE(MID($E2,2,20))<100000000,VALUE(MID($E2,2,20)),1000000000),1000000000))+ROW()/100000,"")
Q3: =IF($E3="","",P3*Y3/100) | AB3: =IF($E3="","",IF($AQ3=1,0,IF($AP3=1,Settings!$C$6,Settings!$C$7))*100) | AC3: =IF($E3="","",Y3*AB3/100) | AD3: =IF($E3="","",Y3-AC3) | AE3: =IF($E3="","",AD3-Q3) | AN3: =IF($E3="","",IF(COUNTIF($E$2:$E3,$E3)=1,1,0)) | AO3: =IF($AN3=1,SUMPRODUCT(--($AR$2:$AR$3001<$AR3))+1,"") | AP3: =IF($E3="","",IF(OR($U3=TRUE(),$U3="TRUE"),1,0)) | AQ3: =IF($E3="","",IF($AA3="Yes",1,0)) | AR3: =IF($AN3=1,IFERROR(IF(VALUE($E3)<100000000,VALUE($E3),1000000000),IFERROR(IF(VALUE(MID($E3,2,20))<100000000,VALUE(MID($E3,2,20)),1000000000),1000000000))+ROW()/100000,"")
Q4: =IF($E4="","",P4*Y4/100) | AB4: =IF($E4="","",IF($AQ4=1,0,IF($AP4=1,Settings!$C$6,Settings!$C$7))*100) | AC4: =IF($E4="","",Y4*AB4/100) | AD4: =IF($E4="","",Y4-AC4) | AE4: =IF($E4="","",AD4-Q4) | AN4: =IF($E4="","",IF(COUNTIF($E$2:$E4,$E4)=1,1,0)) | AO4: =IF($AN4=1,SUMPRODUCT(--($AR$2:$AR$3001<$AR4))+1,"") | AP4: =IF($E4="","",IF(OR($U4=TRUE(),$U4="TRUE"),1,0)) | AQ4: =IF($E4="","",IF($AA4="Yes",1,0)) | AR4: =IF($AN4=1,IFERROR(IF(VALUE($E4)<100000000,VALUE($E4),1000000000),IFERROR(IF(VALUE(MID($E4,2,20))<100000000,VALUE(MID($E4,2,20)),1000000000),1000000000))+ROW()/100000,"")
Q5: =IF($E5="","",P5*Y5/100) | AB5: =IF($E5="","",IF($AQ5=1,0,IF($AP5=1,Settings!$C$6,Settings!$C$7))*100) | AC5: =IF($E5="","",Y5*AB5/100) | AD5: =IF($E5="","",Y5-AC5) | AE5: =IF($E5="","",AD5-Q5) | AN5: =IF($E5="","",IF(COUNTIF($E$2:$E5,$E5)=1,1,0)) | AO5: =IF($AN5=1,SUMPRODUCT(--($AR$2:$AR$3001<$AR5))+1,"") | AP5: =IF($E5="","",IF(OR($U5=TRUE(),$U5="TRUE"),1,0)) | AQ5: =IF($E5="","",IF($AA5="Yes",1,0)) | AR5: =IF($AN5=1,IFERROR(IF(VALUE($E5)<100000000,VALUE($E5),1000000000),IFERROR(IF(VALUE(MID($E5,2,20))<100000000,VALUE(MID($E5,2,20)),1000000000),1000000000))+ROW()/100000,"")
Q6: =IF($E6="","",P6*Y6/100) | AB6: =IF($E6="","",IF($AQ6=1,0,IF($AP6=1,Settings!$C$6,Settings!$C$7))*100) | AC6: =IF($E6="","",Y6*AB6/100) | AD6: =IF($E6="","",Y6-AC6) | AE6: =IF($E6="","",AD6-Q6) | AN6: =IF($E6="","",IF(COUNTIF($E$2:$E6,$E6)=1,1,0)) | AO6: =IF($AN6=1,SUMPRODUCT(--($AR$2:$AR$3001<$AR6))+1,"") | AP6: =IF($E6="","",IF(OR($U6=TRUE(),$U6="TRUE"),1,0)) | AQ6: =IF($E6="","",IF($AA6="Yes",1,0)) | AR6: =IF($AN6=1,IFERROR(IF(VALUE($E6)<100000000,VALUE($E6),1000000000),IFERROR(IF(VALUE(MID($E6,2,20))<100000000,VALUE(MID($E6,2,20)),1000000000),1000000000))+ROW()/100000,"")
Q7: =IF($E7="","",P7*Y7/100) | AB7: =IF($E7="","",IF($AQ7=1,0,IF($AP7=1,Settings!$C$6,Settings!$C$7))*100) | AC7: =IF($E7="","",Y7*AB7/100) | AD7: =IF($E7="","",Y7-AC7) | AE7: =IF($E7="","",AD7-Q7) | AN7: =IF($E7="","",IF(COUNTIF($E$2:$E7,$E7)=1,1,0)) | AO7: =IF($AN7=1,SUMPRODUCT(--($AR$2:$AR$3001<$AR7))+1,"") | AP7: =IF($E7="","",IF(OR($U7=TRUE(),$U7="TRUE"),1,0)) | AQ7: =IF($E7="","",IF($AA7="Yes",1,0)) | AR7: =IF($AN7=1,IFERROR(IF(VALUE($E7)<100000000,VALUE($E7),1000000000),IFERROR(IF(VALUE(MID($E7,2,20))<100000000,VALUE(MID($E7,2,20)),1000000000),1000000000))+ROW()/100000,"")
Q8: =IF($E8="","",P8*Y8/100) | AB8: =IF($E8="","",IF($AQ8=1,0,IF($AP8=1,Settings!$C$6,Settings!$C$7))*100) | AC8: =IF($E8="","",Y8*AB8/100) | AD8: =IF($E8="","",Y8-AC8) | AE8: =IF($E8="","",AD8-Q8) | AN8: =IF($E8="","",IF(COUNTIF($E$2:$E8,$E8)=1,1,0)) | AO8: =IF($AN8=1,SUMPRODUCT(--($AR$2:$AR$3001<$AR8))+1,"") | AP8: =IF($E8="","",IF(OR($U8=TRUE(),$U8="TRUE"),1,0)) | AQ8: =IF($E8="","",IF($AA8="Yes",1,0)) | AR8: =IF($AN8=1,IFERROR(IF(VALUE($E8)<100000000,VALUE($E8),1000000000),IFERROR(IF(VALUE(MID($E8,2,20))<100000000,VALUE(MID($E8,2,20)),1000000000),1000000000))+ROW()/100000,"")
Q9: =IF($E9="","",P9*Y9/100) | AB9: =IF($E9="","",IF($AQ9=1,0,IF($AP9=1,Settings!$C$6,Settings!$C$7))*100) | AC9: =IF($E9="","",Y9*AB9/100) | AD9: =IF($E9="","",Y9-AC9) | AE9: =IF($E9="","",AD9-Q9) | AN9: =IF($E9="","",IF(COUNTIF($E$2:$E9,$E9)=1,1,0)) | AO9: =IF($AN9=1,SUMPRODUCT(--($AR$2:$AR$3001<$AR9))+1,"") | AP9: =IF($E9="","",IF(OR($U9=TRUE(),$U9="TRUE"),1,0)) | AQ9: =IF($E9="","",IF($AA9="Yes",1,0)) | AR9: =IF($AN9=1,IFERROR(IF(VALUE($E9)<100000000,VALUE($E9),1000000000),IFERROR(IF(VALUE(MID($E9,2,20))<100000000,VALUE(MID($E9,2,20)),1000000000),1000000000))+ROW()/100000,"")
Q10: =IF($E10="","",P10*Y10/100) | AB10: =IF($E10="","",IF($AQ10=1,0,IF($AP10=1,Settings!$C$6,Settings!$C$7))*100) | AC10: =IF($E10="","",Y10*AB10/100) | AD10: =IF($E10="","",Y10-AC10) | AE10: =IF($E10="","",AD10-Q10) | AN10: =IF($E10="","",IF(COUNTIF($E$2:$E10,$E10)=1,1,0)) | AO10: =IF($AN10=1,SUMPRODUCT(--($AR$2:$AR$3001<$AR10))+1,"") | AP10: =IF($E10="","",IF(OR($U10=TRUE(),$U10="TRUE"),1,0)) | AQ10: =IF($E10="","",IF($AA10="Yes",1,0)) | AR10: =IF($AN10=1,IFERROR(IF(VALUE($E10)<100000000,VALUE($E10),1000000000),IFERROR(IF(VALUE(MID($E10,2,20))<100000000,VALUE(MID($E10,2,20)),1000000000),1000000000))+ROW()/100000,"")
Q11: =IF($E11="","",P11*Y11/100) | AB11: =IF($E11="","",IF($AQ11=1,0,IF($AP11=1,Settings!$C$6,Settings!$C$7))*100) | AC11: =IF($E11="","",Y11*AB11/100) | AD11: =IF($E11="","",Y11-AC11) | AE11: =IF($E11="","",AD11-Q11) | AN11: =IF($E11="","",IF(COUNTIF($E$2:$E11,$E11)=1,1,0)) | AO11: =IF($AN11=1,SUMPRODUCT(--($AR$2:$AR$3001<$AR11))+1,"") | AP11: =IF($E11="","",IF(OR($U11=TRUE(),$U11="TRUE"),1,0)) | AQ11: =IF($E11="","",IF($AA11="Yes",1,0)) | AR11: =IF($AN11=1,IFERROR(IF(VALUE($E11)<100000000,VALUE($E11),1000000000),IFERROR(IF(VALUE(MID($E11,2,20))<100000000,VALUE(MID($E11,2,20)),1000000000),1000000000))+ROW()/100000,"")
Q12: =IF($E12="","",P12*Y12/100) | AB12: =IF($E12="","",IF($AQ12=1,0,IF($AP12=1,Settings!$C$6,Settings!$C$7))*100) | AC12: =IF($E12="","",Y12*AB12/100) | AD12: =IF($E12="","",Y12-AC12) | AE12: =IF($E12="","",AD12-Q12) | AN12: =IF($E12="","",IF(COUNTIF($E$2:$E12,$E12)=1,1,0)) | AO12: =IF($AN12=1,SUMPRODUCT(--($AR$2:$AR$3001<$AR12))+1,"") | AP12: =IF($E12="","",IF(OR($U12=TRUE(),$U12="TRUE"),1,0)) | AQ12: =IF($E12="","",IF($AA12="Yes",1,0)) | AR12: =IF($AN12=1,IFERROR(IF(VALUE($E12)<100000000,VALUE($E12),1000000000),IFERROR(IF(VALUE(MID($E12,2,20))<100000000,VALUE(MID($E12,2,20)),1000000000),1000000000))+ROW()/100000,"")
Q13: =IF($E13="","",P13*Y13/100) | AB13: =IF($E13="","",IF($AQ13=1,0,IF($AP13=1,Settings!$C$6,Settings!$C$7))*100) | AC13: =IF($E13="","",Y13*AB13/100) | AD13: =IF($E13="","",Y13-AC13) | AE13: =IF($E13="","",AD13-Q13) | AN13: =IF($E13="","",IF(COUNTIF($E$2:$E13,$E13)=1,1,0)) | AO13: =IF($AN13=1,SUMPRODUCT(--($AR$2:$AR$3001<$AR13))+1,"") | AP13: =IF($E13="","",IF(OR($U13=TRUE(),$U13="TRUE"),1,0)) | AQ13: =IF($E13="","",IF($AA13="Yes",1,0)) | AR13: =IF($AN13=1,IFERROR(IF(VALUE($E13)<100000000,VALUE($E13),1000000000),IFERROR(IF(VALUE(MID($E13,2,20))<100000000,VALUE(MID($E13,2,20)),1000000000),1000000000))+ROW()/100000,"")
... Q3001: =IF($E3001="","",P3001*Y3001/100) | AB3001: =IF($E3001="","",IF($AQ3001=1,0,IF($AP3001=1,Settings!$C$6,Settings!$C$7))*100) | AC3001: =IF($E3001="","",Y3001*AB3001/100) | AD3001: =IF($E3001="","",Y3001-AC3001) | AE3001: =IF($E3001="","",AD3001-Q3001) | AN3001: =IF($E3001="","",IF(COUNTIF($E$2:$E3001,$E3001)=1,1,0)) | AO3001: =IF($AN3001=1,SUMPRODUCT(--($AR$2:$AR$3001<$AR3001))+1,"") | AP3001: =IF($E3001="","",IF(OR($U3001=TRUE(),$U3001="TRUE"),1,0)) | AQ3001: =IF($E3001="","",IF($AA3001="Yes",1,0)) | AR3001: =IF($AN3001=1,IFERROR(IF(VALUE($E3001)<100000000,VALUE($E3001),1000000000),IFERROR(IF(VALUE(MID($E3001,2,20))<100000000,VALUE(MID($E3001,2,20)),1000000000),1000000000))+ROW()/100000,"")

Sheet Per Invoice
A1: Invoice | B1: Order # | C1: Site Tab (##) | D1: Cycle | E1: Create At | F1: Insurance Company | G1: Corporate | H1: Card | I1: Name | J1: Order Co Payment | K1: Co val | L1: ERX ID | M1: Max Limit | N1: Exceeding Limit | O1: Exceeding BY | P1: Special | Q1: IMP % | R1: IMP | S1: IMP VAL | T1: LOCAL% | U1: LOCAL | V1: LOCAL VAL | W1: TOTAL VAL | X1: SUBTOTAL | Y1: Grand Total | Z1: NET | AA1: Src Row (helper) | AB1: Limit Adj (helper) | AC1: Payer Key (helper)
B2: =IF($AA2="","",INDEX('Per Line'!$E$2:$E$3001,$AA2)&"") | C2: =IF($AA2="","",D2&" "&G2) | D2: =IF($AA2="","",INDEX('Per Line'!$A$2:$A$3001,$AA2)&"") | E2: =IF($AA2="","",INDEX('Per Line'!$G$2:$G$3001,$AA2)) | F2: =IF($AA2="","",INDEX('Per Line'!$H$2:$H$3001,$AA2)&"") | G2: =IF($AA2="","",INDEX('Per Line'!$J$2:$J$3001,$AA2)&"") | H2: =IF($AA2="","",INDEX('Per Line'!$K$2:$K$3001,$AA2)&"") | I2: =IF($AA2="","",INDEX('Per Line'!$L$2:$L$3001,$AA2)&"") | J2: =IF($AA2="","",INDEX('Per Line'!$P$2:$P$3001,$AA2)) | K2: =IF($AA2="","",IF(AND(ISNUMBER(M2),M2>0,Y2>M2),J2*M2/100+(Y2-M2),J2*Y2/100)) | L2: =IF($AA2="","",INDEX('Per Line'!$Z$2:$Z$3001,$AA2)&"") | M2: =IF($AA2="","",INDEX('Per Line'!$AG$2:$AG$3001,$AA2)) | N2: =IF($AA2="","",IF(AND(ISNUMBER(M2),M2>0),Y2>M2,FALSE)) | O2: =IF($AA2="","",IF(AND(ISNUMBER(M2),M2>0,Y2>M2),Y2-M2,"")) | P2: =IF($AA2="","",SUMIFS('Per Line'!$Y$2:$Y$3001,'Per Line'!$E$2:$E$3001,$B2,'Per Line'!$AQ$2:$AQ$3001,1)) | Q2: =IF($AA2="","",Settings!$C$7) | R2: =IF($AA2="","",SUMIFS('Per Line'!$Y$2:$Y$3001,'Per Line'!$E$2:$E$3001,$B2,'Per Line'!$AP$2:$AP$3001,0,'Per Line'!$AQ$2:$AQ$3001,0)) | S2: =IF($AA2="","",R2*Q2) | T2: =IF($AA2="","",Settings!$C$6) | U2: =IF($AA2="","",SUMIFS('Per Line'!$Y$2:$Y$3001,'Per Line'!$E$2:$E$3001,$B2,'Per Line'!$AP$2:$AP$3001,1,'Per Line'!$AQ$2:$AQ$3001,0)) | V2: =IF($AA2="","",U2*T2) | W2: =IF($AA2="","",V2+S2) | X2: =IF($AA2="","",Y2-W2) | Y2: =IF($AA2="","",R2+U2+P2) | Z2: =IF($AA2="","",Y2-W2-K2) | AA2: =IF(ROWS($AA$2:$AA2)<=MAX('Per Line'!$AO$2:$AO$3001),MATCH(ROWS($AA$2:$AA2),'Per Line'!$AO$2:$AO$3001,0),"") | AB2: =IF($AA2="","",K2-J2*Y2/100) | AC2: =IF($AA2="","",C2&"|"&COUNTIF($C$2:$C2,C2))
B3: =IF($AA3="","",INDEX('Per Line'!$E$2:$E$3001,$AA3)&"") | C3: =IF($AA3="","",D3&" "&G3) | D3: =IF($AA3="","",INDEX('Per Line'!$A$2:$A$3001,$AA3)&"") | E3: =IF($AA3="","",INDEX('Per Line'!$G$2:$G$3001,$AA3)) | F3: =IF($AA3="","",INDEX('Per Line'!$H$2:$H$3001,$AA3)&"") | G3: =IF($AA3="","",INDEX('Per Line'!$J$2:$J$3001,$AA3)&"") | H3: =IF($AA3="","",INDEX('Per Line'!$K$2:$K$3001,$AA3)&"") | I3: =IF($AA3="","",INDEX('Per Line'!$L$2:$L$3001,$AA3)&"") | J3: =IF($AA3="","",INDEX('Per Line'!$P$2:$P$3001,$AA3)) | K3: =IF($AA3="","",IF(AND(ISNUMBER(M3),M3>0,Y3>M3),J3*M3/100+(Y3-M3),J3*Y3/100)) | L3: =IF($AA3="","",INDEX('Per Line'!$Z$2:$Z$3001,$AA3)&"") | M3: =IF($AA3="","",INDEX('Per Line'!$AG$2:$AG$3001,$AA3)) | N3: =IF($AA3="","",IF(AND(ISNUMBER(M3),M3>0),Y3>M3,FALSE)) | O3: =IF($AA3="","",IF(AND(ISNUMBER(M3),M3>0,Y3>M3),Y3-M3,"")) | P3: =IF($AA3="","",SUMIFS('Per Line'!$Y$2:$Y$3001,'Per Line'!$E$2:$E$3001,$B3,'Per Line'!$AQ$2:$AQ$3001,1)) | Q3: =IF($AA3="","",Settings!$C$7) | R3: =IF($AA3="","",SUMIFS('Per Line'!$Y$2:$Y$3001,'Per Line'!$E$2:$E$3001,$B3,'Per Line'!$AP$2:$AP$3001,0,'Per Line'!$AQ$2:$AQ$3001,0)) | S3: =IF($AA3="","",R3*Q3) | T3: =IF($AA3="","",Settings!$C$6) | U3: =IF($AA3="","",SUMIFS('Per Line'!$Y$2:$Y$3001,'Per Line'!$E$2:$E$3001,$B3,'Per Line'!$AP$2:$AP$3001,1,'Per Line'!$AQ$2:$AQ$3001,0)) | V3: =IF($AA3="","",U3*T3) | W3: =IF($AA3="","",V3+S3) | X3: =IF($AA3="","",Y3-W3) | Y3: =IF($AA3="","",R3+U3+P3) | Z3: =IF($AA3="","",Y3-W3-K3) | AA3: =IF(ROWS($AA$2:$AA3)<=MAX('Per Line'!$AO$2:$AO$3001),MATCH(ROWS($AA$2:$AA3),'Per Line'!$AO$2:$AO$3001,0),"") | AB3: =IF($AA3="","",K3-J3*Y3/100) | AC3: =IF($AA3="","",C3&"|"&COUNTIF($C$2:$C3,C3))
B4: =IF($AA4="","",INDEX('Per Line'!$E$2:$E$3001,$AA4)&"") | C4: =IF($AA4="","",D4&" "&G4) | D4: =IF($AA4="","",INDEX('Per Line'!$A$2:$A$3001,$AA4)&"") | E4: =IF($AA4="","",INDEX('Per Line'!$G$2:$G$3001,$AA4)) | F4: =IF($AA4="","",INDEX('Per Line'!$H$2:$H$3001,$AA4)&"") | G4: =IF($AA4="","",INDEX('Per Line'!$J$2:$J$3001,$AA4)&"") | H4: =IF($AA4="","",INDEX('Per Line'!$K$2:$K$3001,$AA4)&"") | I4: =IF($AA4="","",INDEX('Per Line'!$L$2:$L$3001,$AA4)&"") | J4: =IF($AA4="","",INDEX('Per Line'!$P$2:$P$3001,$AA4)) | K4: =IF($AA4="","",IF(AND(ISNUMBER(M4),M4>0,Y4>M4),J4*M4/100+(Y4-M4),J4*Y4/100)) | L4: =IF($AA4="","",INDEX('Per Line'!$Z$2:$Z$3001,$AA4)&"") | M4: =IF($AA4="","",INDEX('Per Line'!$AG$2:$AG$3001,$AA4)) | N4: =IF($AA4="","",IF(AND(ISNUMBER(M4),M4>0),Y4>M4,FALSE)) | O4: =IF($AA4="","",IF(AND(ISNUMBER(M4),M4>0,Y4>M4),Y4-M4,"")) | P4: =IF($AA4="","",SUMIFS('Per Line'!$Y$2:$Y$3001,'Per Line'!$E$2:$E$3001,$B4,'Per Line'!$AQ$2:$AQ$3001,1)) | Q4: =IF($AA4="","",Settings!$C$7) | R4: =IF($AA4="","",SUMIFS('Per Line'!$Y$2:$Y$3001,'Per Line'!$E$2:$E$3001,$B4,'Per Line'!$AP$2:$AP$3001,0,'Per Line'!$AQ$2:$AQ$3001,0)) | S4: =IF($AA4="","",R4*Q4) | T4: =IF($AA4="","",Settings!$C$6) | U4: =IF($AA4="","",SUMIFS('Per Line'!$Y$2:$Y$3001,'Per Line'!$E$2:$E$3001,$B4,'Per Line'!$AP$2:$AP$3001,1,'Per Line'!$AQ$2:$AQ$3001,0)) | V4: =IF($AA4="","",U4*T4) | W4: =IF($AA4="","",V4+S4) | X4: =IF($AA4="","",Y4-W4) | Y4: =IF($AA4="","",R4+U4+P4) | Z4: =IF($AA4="","",Y4-W4-K4) | AA4: =IF(ROWS($AA$2:$AA4)<=MAX('Per Line'!$AO$2:$AO$3001),MATCH(ROWS($AA$2:$AA4),'Per Line'!$AO$2:$AO$3001,0),"") | AB4: =IF($AA4="","",K4-J4*Y4/100) | AC4: =IF($AA4="","",C4&"|"&COUNTIF($C$2:$C4,C4))
B5: =IF($AA5="","",INDEX('Per Line'!$E$2:$E$3001,$AA5)&"") | C5: =IF($AA5="","",D5&" "&G5) | D5: =IF($AA5="","",INDEX('Per Line'!$A$2:$A$3001,$AA5)&"") | E5: =IF($AA5="","",INDEX('Per Line'!$G$2:$G$3001,$AA5)) | F5: =IF($AA5="","",INDEX('Per Line'!$H$2:$H$3001,$AA5)&"") | G5: =IF($AA5="","",INDEX('Per Line'!$J$2:$J$3001,$AA5)&"") | H5: =IF($AA5="","",INDEX('Per Line'!$K$2:$K$3001,$AA5)&"") | I5: =IF($AA5="","",INDEX('Per Line'!$L$2:$L$3001,$AA5)&"") | J5: =IF($AA5="","",INDEX('Per Line'!$P$2:$P$3001,$AA5)) | K5: =IF($AA5="","",IF(AND(ISNUMBER(M5),M5>0,Y5>M5),J5*M5/100+(Y5-M5),J5*Y5/100)) | L5: =IF($AA5="","",INDEX('Per Line'!$Z$2:$Z$3001,$AA5)&"") | M5: =IF($AA5="","",INDEX('Per Line'!$AG$2:$AG$3001,$AA5)) | N5: =IF($AA5="","",IF(AND(ISNUMBER(M5),M5>0),Y5>M5,FALSE)) | O5: =IF($AA5="","",IF(AND(ISNUMBER(M5),M5>0,Y5>M5),Y5-M5,"")) | P5: =IF($AA5="","",SUMIFS('Per Line'!$Y$2:$Y$3001,'Per Line'!$E$2:$E$3001,$B5,'Per Line'!$AQ$2:$AQ$3001,1)) | Q5: =IF($AA5="","",Settings!$C$7) | R5: =IF($AA5="","",SUMIFS('Per Line'!$Y$2:$Y$3001,'Per Line'!$E$2:$E$3001,$B5,'Per Line'!$AP$2:$AP$3001,0,'Per Line'!$AQ$2:$AQ$3001,0)) | S5: =IF($AA5="","",R5*Q5) | T5: =IF($AA5="","",Settings!$C$6) | U5: =IF($AA5="","",SUMIFS('Per Line'!$Y$2:$Y$3001,'Per Line'!$E$2:$E$3001,$B5,'Per Line'!$AP$2:$AP$3001,1,'Per Line'!$AQ$2:$AQ$3001,0)) | V5: =IF($AA5="","",U5*T5) | W5: =IF($AA5="","",V5+S5) | X5: =IF($AA5="","",Y5-W5) | Y5: =IF($AA5="","",R5+U5+P5) | Z5: =IF($AA5="","",Y5-W5-K5) | AA5: =IF(ROWS($AA$2:$AA5)<=MAX('Per Line'!$AO$2:$AO$3001),MATCH(ROWS($AA$2:$AA5),'Per Line'!$AO$2:$AO$3001,0),"") | AB5: =IF($AA5="","",K5-J5*Y5/100) | AC5: =IF($AA5="","",C5&"|"&COUNTIF($C$2:$C5,C5))
B6: =IF($AA6="","",INDEX('Per Line'!$E$2:$E$3001,$AA6)&"") | C6: =IF($AA6="","",D6&" "&G6) | D6: =IF($AA6="","",INDEX('Per Line'!$A$2:$A$3001,$AA6)&"") | E6: =IF($AA6="","",INDEX('Per Line'!$G$2:$G$3001,$AA6)) | F6: =IF($AA6="","",INDEX('Per Line'!$H$2:$H$3001,$AA6)&"") | G6: =IF($AA6="","",INDEX('Per Line'!$J$2:$J$3001,$AA6)&"") | H6: =IF($AA6="","",INDEX('Per Line'!$K$2:$K$3001,$AA6)&"") | I6: =IF($AA6="","",INDEX('Per Line'!$L$2:$L$3001,$AA6)&"") | J6: =IF($AA6="","",INDEX('Per Line'!$P$2:$P$3001,$AA6)) | K6: =IF($AA6="","",IF(AND(ISNUMBER(M6),M6>0,Y6>M6),J6*M6/100+(Y6-M6),J6*Y6/100)) | L6: =IF($AA6="","",INDEX('Per Line'!$Z$2:$Z$3001,$AA6)&"") | M6: =IF($AA6="","",INDEX('Per Line'!$AG$2:$AG$3001,$AA6)) | N6: =IF($AA6="","",IF(AND(ISNUMBER(M6),M6>0),Y6>M6,FALSE)) | O6: =IF($AA6="","",IF(AND(ISNUMBER(M6),M6>0,Y6>M6),Y6-M6,"")) | P6: =IF($AA6="","",SUMIFS('Per Line'!$Y$2:$Y$3001,'Per Line'!$E$2:$E$3001,$B6,'Per Line'!$AQ$2:$AQ$3001,1)) | Q6: =IF($AA6="","",Settings!$C$7) | R6: =IF($AA6="","",SUMIFS('Per Line'!$Y$2:$Y$3001,'Per Line'!$E$2:$E$3001,$B6,'Per Line'!$AP$2:$AP$3001,0,'Per Line'!$AQ$2:$AQ$3001,0)) | S6: =IF($AA6="","",R6*Q6) | T6: =IF($AA6="","",Settings!$C$6) | U6: =IF($AA6="","",SUMIFS('Per Line'!$Y$2:$Y$3001,'Per Line'!$E$2:$E$3001,$B6,'Per Line'!$AP$2:$AP$3001,1,'Per Line'!$AQ$2:$AQ$3001,0)) | V6: =IF($AA6="","",U6*T6) | W6: =IF($AA6="","",V6+S6) | X6: =IF($AA6="","",Y6-W6) | Y6: =IF($AA6="","",R6+U6+P6) | Z6: =IF($AA6="","",Y6-W6-K6) | AA6: =IF(ROWS($AA$2:$AA6)<=MAX('Per Line'!$AO$2:$AO$3001),MATCH(ROWS($AA$2:$AA6),'Per Line'!$AO$2:$AO$3001,0),"") | AB6: =IF($AA6="","",K6-J6*Y6/100) | AC6: =IF($AA6="","",C6&"|"&COUNTIF($C$2:$C6,C6))
B7: =IF($AA7="","",INDEX('Per Line'!$E$2:$E$3001,$AA7)&"") | C7: =IF($AA7="","",D7&" "&G7) | D7: =IF($AA7="","",INDEX('Per Line'!$A$2:$A$3001,$AA7)&"") | E7: =IF($AA7="","",INDEX('Per Line'!$G$2:$G$3001,$AA7)) | F7: =IF($AA7="","",INDEX('Per Line'!$H$2:$H$3001,$AA7)&"") | G7: =IF($AA7="","",INDEX('Per Line'!$J$2:$J$3001,$AA7)&"") | H7: =IF($AA7="","",INDEX('Per Line'!$K$2:$K$3001,$AA7)&"") | I7: =IF($AA7="","",INDEX('Per Line'!$L$2:$L$3001,$AA7)&"") | J7: =IF($AA7="","",INDEX('Per Line'!$P$2:$P$3001,$AA7)) | K7: =IF($AA7="","",IF(AND(ISNUMBER(M7),M7>0,Y7>M7),J7*M7/100+(Y7-M7),J7*Y7/100)) | L7: =IF($AA7="","",INDEX('Per Line'!$Z$2:$Z$3001,$AA7)&"") | M7: =IF($AA7="","",INDEX('Per Line'!$AG$2:$AG$3001,$AA7)) | N7: =IF($AA7="","",IF(AND(ISNUMBER(M7),M7>0),Y7>M7,FALSE)) | O7: =IF($AA7="","",IF(AND(ISNUMBER(M7),M7>0,Y7>M7),Y7-M7,"")) | P7: =IF($AA7="","",SUMIFS('Per Line'!$Y$2:$Y$3001,'Per Line'!$E$2:$E$3001,$B7,'Per Line'!$AQ$2:$AQ$3001,1)) | Q7: =IF($AA7="","",Settings!$C$7) | R7: =IF($AA7="","",SUMIFS('Per Line'!$Y$2:$Y$3001,'Per Line'!$E$2:$E$3001,$B7,'Per Line'!$AP$2:$AP$3001,0,'Per Line'!$AQ$2:$AQ$3001,0)) | S7: =IF($AA7="","",R7*Q7) | T7: =IF($AA7="","",Settings!$C$6) | U7: =IF($AA7="","",SUMIFS('Per Line'!$Y$2:$Y$3001,'Per Line'!$E$2:$E$3001,$B7,'Per Line'!$AP$2:$AP$3001,1,'Per Line'!$AQ$2:$AQ$3001,0)) | V7: =IF($AA7="","",U7*T7) | W7: =IF($AA7="","",V7+S7) | X7: =IF($AA7="","",Y7-W7) | Y7: =IF($AA7="","",R7+U7+P7) | Z7: =IF($AA7="","",Y7-W7-K7) | AA7: =IF(ROWS($AA$2:$AA7)<=MAX('Per Line'!$AO$2:$AO$3001),MATCH(ROWS($AA$2:$AA7),'Per Line'!$AO$2:$AO$3001,0),"") | AB7: =IF($AA7="","",K7-J7*Y7/100) | AC7: =IF($AA7="","",C7&"|"&COUNTIF($C$2:$C7,C7))
B8: =IF($AA8="","",INDEX('Per Line'!$E$2:$E$3001,$AA8)&"") | C8: =IF($AA8="","",D8&" "&G8) | D8: =IF($AA8="","",INDEX('Per Line'!$A$2:$A$3001,$AA8)&"") | E8: =IF($AA8="","",INDEX('Per Line'!$G$2:$G$3001,$AA8)) | F8: =IF($AA8="","",INDEX('Per Line'!$H$2:$H$3001,$AA8)&"") | G8: =IF($AA8="","",INDEX('Per Line'!$J$2:$J$3001,$AA8)&"") | H8: =IF($AA8="","",INDEX('Per Line'!$K$2:$K$3001,$AA8)&"") | I8: =IF($AA8="","",INDEX('Per Line'!$L$2:$L$3001,$AA8)&"") | J8: =IF($AA8="","",INDEX('Per Line'!$P$2:$P$3001,$AA8)) | K8: =IF($AA8="","",IF(AND(ISNUMBER(M8),M8>0,Y8>M8),J8*M8/100+(Y8-M8),J8*Y8/100)) | L8: =IF($AA8="","",INDEX('Per Line'!$Z$2:$Z$3001,$AA8)&"") | M8: =IF($AA8="","",INDEX('Per Line'!$AG$2:$AG$3001,$AA8)) | N8: =IF($AA8="","",IF(AND(ISNUMBER(M8),M8>0),Y8>M8,FALSE)) | O8: =IF($AA8="","",IF(AND(ISNUMBER(M8),M8>0,Y8>M8),Y8-M8,"")) | P8: =IF($AA8="","",SUMIFS('Per Line'!$Y$2:$Y$3001,'Per Line'!$E$2:$E$3001,$B8,'Per Line'!$AQ$2:$AQ$3001,1)) | Q8: =IF($AA8="","",Settings!$C$7) | R8: =IF($AA8="","",SUMIFS('Per Line'!$Y$2:$Y$3001,'Per Line'!$E$2:$E$3001,$B8,'Per Line'!$AP$2:$AP$3001,0,'Per Line'!$AQ$2:$AQ$3001,0)) | S8: =IF($AA8="","",R8*Q8) | T8: =IF($AA8="","",Settings!$C$6) | U8: =IF($AA8="","",SUMIFS('Per Line'!$Y$2:$Y$3001,'Per Line'!$E$2:$E$3001,$B8,'Per Line'!$AP$2:$AP$3001,1,'Per Line'!$AQ$2:$AQ$3001,0)) | V8: =IF($AA8="","",U8*T8) | W8: =IF($AA8="","",V8+S8) | X8: =IF($AA8="","",Y8-W8) | Y8: =IF($AA8="","",R8+U8+P8) | Z8: =IF($AA8="","",Y8-W8-K8) | AA8: =IF(ROWS($AA$2:$AA8)<=MAX('Per Line'!$AO$2:$AO$3001),MATCH(ROWS($AA$2:$AA8),'Per Line'!$AO$2:$AO$3001,0),"") | AB8: =IF($AA8="","",K8-J8*Y8/100) | AC8: =IF($AA8="","",C8&"|"&COUNTIF($C$2:$C8,C8))
B9: =IF($AA9="","",INDEX('Per Line'!$E$2:$E$3001,$AA9)&"") | C9: =IF($AA9="","",D9&" "&G9) | D9: =IF($AA9="","",INDEX('Per Line'!$A$2:$A$3001,$AA9)&"") | E9: =IF($AA9="","",INDEX('Per Line'!$G$2:$G$3001,$AA9)) | F9: =IF($AA9="","",INDEX('Per Line'!$H$2:$H$3001,$AA9)&"") | G9: =IF($AA9="","",INDEX('Per Line'!$J$2:$J$3001,$AA9)&"") | H9: =IF($AA9="","",INDEX('Per Line'!$K$2:$K$3001,$AA9)&"") | I9: =IF($AA9="","",INDEX('Per Line'!$L$2:$L$3001,$AA9)&"") | J9: =IF($AA9="","",INDEX('Per Line'!$P$2:$P$3001,$AA9)) | K9: =IF($AA9="","",IF(AND(ISNUMBER(M9),M9>0,Y9>M9),J9*M9/100+(Y9-M9),J9*Y9/100)) | L9: =IF($AA9="","",INDEX('Per Line'!$Z$2:$Z$3001,$AA9)&"") | M9: =IF($AA9="","",INDEX('Per Line'!$AG$2:$AG$3001,$AA9)) | N9: =IF($AA9="","",IF(AND(ISNUMBER(M9),M9>0),Y9>M9,FALSE)) | O9: =IF($AA9="","",IF(AND(ISNUMBER(M9),M9>0,Y9>M9),Y9-M9,"")) | P9: =IF($AA9="","",SUMIFS('Per Line'!$Y$2:$Y$3001,'Per Line'!$E$2:$E$3001,$B9,'Per Line'!$AQ$2:$AQ$3001,1)) | Q9: =IF($AA9="","",Settings!$C$7) | R9: =IF($AA9="","",SUMIFS('Per Line'!$Y$2:$Y$3001,'Per Line'!$E$2:$E$3001,$B9,'Per Line'!$AP$2:$AP$3001,0,'Per Line'!$AQ$2:$AQ$3001,0)) | S9: =IF($AA9="","",R9*Q9) | T9: =IF($AA9="","",Settings!$C$6) | U9: =IF($AA9="","",SUMIFS('Per Line'!$Y$2:$Y$3001,'Per Line'!$E$2:$E$3001,$B9,'Per Line'!$AP$2:$AP$3001,1,'Per Line'!$AQ$2:$AQ$3001,0)) | V9: =IF($AA9="","",U9*T9) | W9: =IF($AA9="","",V9+S9) | X9: =IF($AA9="","",Y9-W9) | Y9: =IF($AA9="","",R9+U9+P9) | Z9: =IF($AA9="","",Y9-W9-K9) | AA9: =IF(ROWS($AA$2:$AA9)<=MAX('Per Line'!$AO$2:$AO$3001),MATCH(ROWS($AA$2:$AA9),'Per Line'!$AO$2:$AO$3001,0),"") | AB9: =IF($AA9="","",K9-J9*Y9/100) | AC9: =IF($AA9="","",C9&"|"&COUNTIF($C$2:$C9,C9))
B10: =IF($AA10="","",INDEX('Per Line'!$E$2:$E$3001,$AA10)&"") | C10: =IF($AA10="","",D10&" "&G10) | D10: =IF($AA10="","",INDEX('Per Line'!$A$2:$A$3001,$AA10)&"") | E10: =IF($AA10="","",INDEX('Per Line'!$G$2:$G$3001,$AA10)) | F10: =IF($AA10="","",INDEX('Per Line'!$H$2:$H$3001,$AA10)&"") | G10: =IF($AA10="","",INDEX('Per Line'!$J$2:$J$3001,$AA10)&"") | H10: =IF($AA10="","",INDEX('Per Line'!$K$2:$K$3001,$AA10)&"") | I10: =IF($AA10="","",INDEX('Per Line'!$L$2:$L$3001,$AA10)&"") | J10: =IF($AA10="","",INDEX('Per Line'!$P$2:$P$3001,$AA10)) | K10: =IF($AA10="","",IF(AND(ISNUMBER(M10),M10>0,Y10>M10),J10*M10/100+(Y10-M10),J10*Y10/100)) | L10: =IF($AA10="","",INDEX('Per Line'!$Z$2:$Z$3001,$AA10)&"") | M10: =IF($AA10="","",INDEX('Per Line'!$AG$2:$AG$3001,$AA10)) | N10: =IF($AA10="","",IF(AND(ISNUMBER(M10),M10>0),Y10>M10,FALSE)) | O10: =IF($AA10="","",IF(AND(ISNUMBER(M10),M10>0,Y10>M10),Y10-M10,"")) | P10: =IF($AA10="","",SUMIFS('Per Line'!$Y$2:$Y$3001,'Per Line'!$E$2:$E$3001,$B10,'Per Line'!$AQ$2:$AQ$3001,1)) | Q10: =IF($AA10="","",Settings!$C$7) | R10: =IF($AA10="","",SUMIFS('Per Line'!$Y$2:$Y$3001,'Per Line'!$E$2:$E$3001,$B10,'Per Line'!$AP$2:$AP$3001,0,'Per Line'!$AQ$2:$AQ$3001,0)) | S10: =IF($AA10="","",R10*Q10) | T10: =IF($AA10="","",Settings!$C$6) | U10: =IF($AA10="","",SUMIFS('Per Line'!$Y$2:$Y$3001,'Per Line'!$E$2:$E$3001,$B10,'Per Line'!$AP$2:$AP$3001,1,'Per Line'!$AQ$2:$AQ$3001,0)) | V10: =IF($AA10="","",U10*T10) | W10: =IF($AA10="","",V10+S10) | X10: =IF($AA10="","",Y10-W10) | Y10: =IF($AA10="","",R10+U10+P10) | Z10: =IF($AA10="","",Y10-W10-K10) | AA10: =IF(ROWS($AA$2:$AA10)<=MAX('Per Line'!$AO$2:$AO$3001),MATCH(ROWS($AA$2:$AA10),'Per Line'!$AO$2:$AO$3001,0),"") | AB10: =IF($AA10="","",K10-J10*Y10/100) | AC10: =IF($AA10="","",C10&"|"&COUNTIF($C$2:$C10,C10))
B11: =IF($AA11="","",INDEX('Per Line'!$E$2:$E$3001,$AA11)&"") | C11: =IF($AA11="","",D11&" "&G11) | D11: =IF($AA11="","",INDEX('Per Line'!$A$2:$A$3001,$AA11)&"") | E11: =IF($AA11="","",INDEX('Per Line'!$G$2:$G$3001,$AA11)) | F11: =IF($AA11="","",INDEX('Per Line'!$H$2:$H$3001,$AA11)&"") | G11: =IF($AA11="","",INDEX('Per Line'!$J$2:$J$3001,$AA11)&"") | H11: =IF($AA11="","",INDEX('Per Line'!$K$2:$K$3001,$AA11)&"") | I11: =IF($AA11="","",INDEX('Per Line'!$L$2:$L$3001,$AA11)&"") | J11: =IF($AA11="","",INDEX('Per Line'!$P$2:$P$3001,$AA11)) | K11: =IF($AA11="","",IF(AND(ISNUMBER(M11),M11>0,Y11>M11),J11*M11/100+(Y11-M11),J11*Y11/100)) | L11: =IF($AA11="","",INDEX('Per Line'!$Z$2:$Z$3001,$AA11)&"") | M11: =IF($AA11="","",INDEX('Per Line'!$AG$2:$AG$3001,$AA11)) | N11: =IF($AA11="","",IF(AND(ISNUMBER(M11),M11>0),Y11>M11,FALSE)) | O11: =IF($AA11="","",IF(AND(ISNUMBER(M11),M11>0,Y11>M11),Y11-M11,"")) | P11: =IF($AA11="","",SUMIFS('Per Line'!$Y$2:$Y$3001,'Per Line'!$E$2:$E$3001,$B11,'Per Line'!$AQ$2:$AQ$3001,1)) | Q11: =IF($AA11="","",Settings!$C$7) | R11: =IF($AA11="","",SUMIFS('Per Line'!$Y$2:$Y$3001,'Per Line'!$E$2:$E$3001,$B11,'Per Line'!$AP$2:$AP$3001,0,'Per Line'!$AQ$2:$AQ$3001,0)) | S11: =IF($AA11="","",R11*Q11) | T11: =IF($AA11="","",Settings!$C$6) | U11: =IF($AA11="","",SUMIFS('Per Line'!$Y$2:$Y$3001,'Per Line'!$E$2:$E$3001,$B11,'Per Line'!$AP$2:$AP$3001,1,'Per Line'!$AQ$2:$AQ$3001,0)) | V11: =IF($AA11="","",U11*T11) | W11: =IF($AA11="","",V11+S11) | X11: =IF($AA11="","",Y11-W11) | Y11: =IF($AA11="","",R11+U11+P11) | Z11: =IF($AA11="","",Y11-W11-K11) | AA11: =IF(ROWS($AA$2:$AA11)<=MAX('Per Line'!$AO$2:$AO$3001),MATCH(ROWS($AA$2:$AA11),'Per Line'!$AO$2:$AO$3001,0),"") | AB11: =IF($AA11="","",K11-J11*Y11/100) | AC11: =IF($AA11="","",C11&"|"&COUNTIF($C$2:$C11,C11))
B12: =IF($AA12="","",INDEX('Per Line'!$E$2:$E$3001,$AA12)&"") | C12: =IF($AA12="","",D12&" "&G12) | D12: =IF($AA12="","",INDEX('Per Line'!$A$2:$A$3001,$AA12)&"") | E12: =IF($AA12="","",INDEX('Per Line'!$G$2:$G$3001,$AA12)) | F12: =IF($AA12="","",INDEX('Per Line'!$H$2:$H$3001,$AA12)&"") | G12: =IF($AA12="","",INDEX('Per Line'!$J$2:$J$3001,$AA12)&"") | H12: =IF($AA12="","",INDEX('Per Line'!$K$2:$K$3001,$AA12)&"") | I12: =IF($AA12="","",INDEX('Per Line'!$L$2:$L$3001,$AA12)&"") | J12: =IF($AA12="","",INDEX('Per Line'!$P$2:$P$3001,$AA12)) | K12: =IF($AA12="","",IF(AND(ISNUMBER(M12),M12>0,Y12>M12),J12*M12/100+(Y12-M12),J12*Y12/100)) | L12: =IF($AA12="","",INDEX('Per Line'!$Z$2:$Z$3001,$AA12)&"") | M12: =IF($AA12="","",INDEX('Per Line'!$AG$2:$AG$3001,$AA12)) | N12: =IF($AA12="","",IF(AND(ISNUMBER(M12),M12>0),Y12>M12,FALSE)) | O12: =IF($AA12="","",IF(AND(ISNUMBER(M12),M12>0,Y12>M12),Y12-M12,"")) | P12: =IF($AA12="","",SUMIFS('Per Line'!$Y$2:$Y$3001,'Per Line'!$E$2:$E$3001,$B12,'Per Line'!$AQ$2:$AQ$3001,1)) | Q12: =IF($AA12="","",Settings!$C$7) | R12: =IF($AA12="","",SUMIFS('Per Line'!$Y$2:$Y$3001,'Per Line'!$E$2:$E$3001,$B12,'Per Line'!$AP$2:$AP$3001,0,'Per Line'!$AQ$2:$AQ$3001,0)) | S12: =IF($AA12="","",R12*Q12) | T12: =IF($AA12="","",Settings!$C$6) | U12: =IF($AA12="","",SUMIFS('Per Line'!$Y$2:$Y$3001,'Per Line'!$E$2:$E$3001,$B12,'Per Line'!$AP$2:$AP$3001,1,'Per Line'!$AQ$2:$AQ$3001,0)) | V12: =IF($AA12="","",U12*T12) | W12: =IF($AA12="","",V12+S12) | X12: =IF($AA12="","",Y12-W12) | Y12: =IF($AA12="","",R12+U12+P12) | Z12: =IF($AA12="","",Y12-W12-K12) | AA12: =IF(ROWS($AA$2:$AA12)<=MAX('Per Line'!$AO$2:$AO$3001),MATCH(ROWS($AA$2:$AA12),'Per Line'!$AO$2:$AO$3001,0),"") | AB12: =IF($AA12="","",K12-J12*Y12/100) | AC12: =IF($AA12="","",C12&"|"&COUNTIF($C$2:$C12,C12))
B13: =IF($AA13="","",INDEX('Per Line'!$E$2:$E$3001,$AA13)&"") | C13: =IF($AA13="","",D13&" "&G13) | D13: =IF($AA13="","",INDEX('Per Line'!$A$2:$A$3001,$AA13)&"") | E13: =IF($AA13="","",INDEX('Per Line'!$G$2:$G$3001,$AA13)) | F13: =IF($AA13="","",INDEX('Per Line'!$H$2:$H$3001,$AA13)&"") | G13: =IF($AA13="","",INDEX('Per Line'!$J$2:$J$3001,$AA13)&"") | H13: =IF($AA13="","",INDEX('Per Line'!$K$2:$K$3001,$AA13)&"") | I13: =IF($AA13="","",INDEX('Per Line'!$L$2:$L$3001,$AA13)&"") | J13: =IF($AA13="","",INDEX('Per Line'!$P$2:$P$3001,$AA13)) | K13: =IF($AA13="","",IF(AND(ISNUMBER(M13),M13>0,Y13>M13),J13*M13/100+(Y13-M13),J13*Y13/100)) | L13: =IF($AA13="","",INDEX('Per Line'!$Z$2:$Z$3001,$AA13)&"") | M13: =IF($AA13="","",INDEX('Per Line'!$AG$2:$AG$3001,$AA13)) | N13: =IF($AA13="","",IF(AND(ISNUMBER(M13),M13>0),Y13>M13,FALSE)) | O13: =IF($AA13="","",IF(AND(ISNUMBER(M13),M13>0,Y13>M13),Y13-M13,"")) | P13: =IF($AA13="","",SUMIFS('Per Line'!$Y$2:$Y$3001,'Per Line'!$E$2:$E$3001,$B13,'Per Line'!$AQ$2:$AQ$3001,1)) | Q13: =IF($AA13="","",Settings!$C$7) | R13: =IF($AA13="","",SUMIFS('Per Line'!$Y$2:$Y$3001,'Per Line'!$E$2:$E$3001,$B13,'Per Line'!$AP$2:$AP$3001,0,'Per Line'!$AQ$2:$AQ$3001,0)) | S13: =IF($AA13="","",R13*Q13) | T13: =IF($AA13="","",Settings!$C$6) | U13: =IF($AA13="","",SUMIFS('Per Line'!$Y$2:$Y$3001,'Per Line'!$E$2:$E$3001,$B13,'Per Line'!$AP$2:$AP$3001,1,'Per Line'!$AQ$2:$AQ$3001,0)) | V13: =IF($AA13="","",U13*T13) | W13: =IF($AA13="","",V13+S13) | X13: =IF($AA13="","",Y13-W13) | Y13: =IF($AA13="","",R13+U13+P13) | Z13: =IF($AA13="","",Y13-W13-K13) | AA13: =IF(ROWS($AA$2:$AA13)<=MAX('Per Line'!$AO$2:$AO$3001),MATCH(ROWS($AA$2:$AA13),'Per Line'!$AO$2:$AO$3001,0),"") | AB13: =IF($AA13="","",K13-J13*Y13/100) | AC13: =IF($AA13="","",C13&"|"&COUNTIF($C$2:$C13,C13))
... B601: =IF($AA601="","",INDEX('Per Line'!$E$2:$E$3001,$AA601)&"") | C601: =IF($AA601="","",D601&" "&G601) | D601: =IF($AA601="","",INDEX('Per Line'!$A$2:$A$3001,$AA601)&"") | E601: =IF($AA601="","",INDEX('Per Line'!$G$2:$G$3001,$AA601)) | F601: =IF($AA601="","",INDEX('Per Line'!$H$2:$H$3001,$AA601)&"") | G601: =IF($AA601="","",INDEX('Per Line'!$J$2:$J$3001,$AA601)&"") | H601: =IF($AA601="","",INDEX('Per Line'!$K$2:$K$3001,$AA601)&"") | I601: =IF($AA601="","",INDEX('Per Line'!$L$2:$L$3001,$AA601)&"") | J601: =IF($AA601="","",INDEX('Per Line'!$P$2:$P$3001,$AA601)) | K601: =IF($AA601="","",IF(AND(ISNUMBER(M601),M601>0,Y601>M601),J601*M601/100+(Y601-M601),J601*Y601/100)) | L601: =IF($AA601="","",INDEX('Per Line'!$Z$2:$Z$3001,$AA601)&"") | M601: =IF($AA601="","",INDEX('Per Line'!$AG$2:$AG$3001,$AA601)) | N601: =IF($AA601="","",IF(AND(ISNUMBER(M601),M601>0),Y601>M601,FALSE)) | O601: =IF($AA601="","",IF(AND(ISNUMBER(M601),M601>0,Y601>M601),Y601-M601,"")) | P601: =IF($AA601="","",SUMIFS('Per Line'!$Y$2:$Y$3001,'Per Line'!$E$2:$E$3001,$B601,'Per Line'!$AQ$2:$AQ$3001,1)) | Q601: =IF($AA601="","",Settings!$C$7) | R601: =IF($AA601="","",SUMIFS('Per Line'!$Y$2:$Y$3001,'Per Line'!$E$2:$E$3001,$B601,'Per Line'!$AP$2:$AP$3001,0,'Per Line'!$AQ$2:$AQ$3001,0)) | S601: =IF($AA601="","",R601*Q601) | T601: =IF($AA601="","",Settings!$C$6) | U601: =IF($AA601="","",SUMIFS('Per Line'!$Y$2:$Y$3001,'Per Line'!$E$2:$E$3001,$B601,'Per Line'!$AP$2:$AP$3001,1,'Per Line'!$AQ$2:$AQ$3001,0)) | V601: =IF($AA601="","",U601*T601) | W601: =IF($AA601="","",V601+S601) | X601: =IF($AA601="","",Y601-W601) | Y601: =IF($AA601="","",R601+U601+P601) | Z601: =IF($AA601="","",Y601-W601-K601) | AA601: =IF(ROWS($AA$2:$AA601)<=MAX('Per Line'!$AO$2:$AO$3001),MATCH(ROWS($AA$2:$AA601),'Per Line'!$AO$2:$AO$3001,0),"") | AB601: =IF($AA601="","",K601-J601*Y601/100) | AC601: =IF($AA601="","",C601&"|"&COUNTIF($C$2:$C601,C601))

Sheet October Employees
A1: Invoice | B1: Order # | C1: Site Tab (##) | D1: Cycle | E1: Create At | F1: Insurance Company | G1: Corporate | H1: Card | I1: Name | J1: Order Co Payment | K1: Co val | L1: ERX ID | M1: Max Limit | N1: Exceeding Limit | O1: Exceeding BY | P1: Special | Q1: IMP % | R1: IMP | S1: IMP VAL | T1: LOCAL% | U1: LOCAL | V1: LOCAL VAL | W1: TOTAL VAL | X1: SUBTOTAL | Y1: Grand Total | Z1: NET | AA1: Src Row (helper)
A2: =IF($AA2="","",IF(INDEX('Per Invoice'!A$2:A$601,$AA2)="","",INDEX('Per Invoice'!A$2:A$601,$AA2))) | B2: =IF($AA2="","",IF(INDEX('Per Invoice'!B$2:B$601,$AA2)="","",INDEX('Per Invoice'!B$2:B$601,$AA2))) | C2: =IF($AA2="","",IF(INDEX('Per Invoice'!C$2:C$601,$AA2)="","",INDEX('Per Invoice'!C$2:C$601,$AA2))) | D2: =IF($AA2="","",IF(INDEX('Per Invoice'!D$2:D$601,$AA2)="","",INDEX('Per Invoice'!D$2:D$601,$AA2))) | E2: =IF($AA2="","",IF(INDEX('Per Invoice'!E$2:E$601,$AA2)="","",INDEX('Per Invoice'!E$2:E$601,$AA2))) | F2: =IF($AA2="","",IF(INDEX('Per Invoice'!F$2:F$601,$AA2)="","",INDEX('Per Invoice'!F$2:F$601,$AA2))) | G2: =IF($AA2="","",IF(INDEX('Per Invoice'!G$2:G$601,$AA2)="","",INDEX('Per Invoice'!G$2:G$601,$AA2))) | H2: =IF($AA2="","",IF(INDEX('Per Invoice'!H$2:H$601,$AA2)="","",INDEX('Per Invoice'!H$2:H$601,$AA2))) | ... Z2: =IF($AA2="","",IF(INDEX('Per Invoice'!Z$2:Z$601,$AA2)="","",INDEX('Per Invoice'!Z$2:Z$601,$AA2))) | AA2: =IFERROR(MATCH(Settings!$C$26&"|"&ROWS($AA$2:$AA2),'Per Invoice'!$AC$2:$AC$601,0),"")
A3: =IF($AA3="","",IF(INDEX('Per Invoice'!A$2:A$601,$AA3)="","",INDEX('Per Invoice'!A$2:A$601,$AA3))) | B3: =IF($AA3="","",IF(INDEX('Per Invoice'!B$2:B$601,$AA3)="","",INDEX('Per Invoice'!B$2:B$601,$AA3))) | C3: =IF($AA3="","",IF(INDEX('Per Invoice'!C$2:C$601,$AA3)="","",INDEX('Per Invoice'!C$2:C$601,$AA3))) | D3: =IF($AA3="","",IF(INDEX('Per Invoice'!D$2:D$601,$AA3)="","",INDEX('Per Invoice'!D$2:D$601,$AA3))) | E3: =IF($AA3="","",IF(INDEX('Per Invoice'!E$2:E$601,$AA3)="","",INDEX('Per Invoice'!E$2:E$601,$AA3))) | F3: =IF($AA3="","",IF(INDEX('Per Invoice'!F$2:F$601,$AA3)="","",INDEX('Per Invoice'!F$2:F$601,$AA3))) | G3: =IF($AA3="","",IF(INDEX('Per Invoice'!G$2:G$601,$AA3)="","",INDEX('Per Invoice'!G$2:G$601,$AA3))) | H3: =IF($AA3="","",IF(INDEX('Per Invoice'!H$2:H$601,$AA3)="","",INDEX('Per Invoice'!H$2:H$601,$AA3))) | ... Z3: =IF($AA3="","",IF(INDEX('Per Invoice'!Z$2:Z$601,$AA3)="","",INDEX('Per Invoice'!Z$2:Z$601,$AA3))) | AA3: =IFERROR(MATCH(Settings!$C$26&"|"&ROWS($AA$2:$AA3),'Per Invoice'!$AC$2:$AC$601,0),"")
A4: =IF($AA4="","",IF(INDEX('Per Invoice'!A$2:A$601,$AA4)="","",INDEX('Per Invoice'!A$2:A$601,$AA4))) | B4: =IF($AA4="","",IF(INDEX('Per Invoice'!B$2:B$601,$AA4)="","",INDEX('Per Invoice'!B$2:B$601,$AA4))) | C4: =IF($AA4="","",IF(INDEX('Per Invoice'!C$2:C$601,$AA4)="","",INDEX('Per Invoice'!C$2:C$601,$AA4))) | D4: =IF($AA4="","",IF(INDEX('Per Invoice'!D$2:D$601,$AA4)="","",INDEX('Per Invoice'!D$2:D$601,$AA4))) | E4: =IF($AA4="","",IF(INDEX('Per Invoice'!E$2:E$601,$AA4)="","",INDEX('Per Invoice'!E$2:E$601,$AA4))) | F4: =IF($AA4="","",IF(INDEX('Per Invoice'!F$2:F$601,$AA4)="","",INDEX('Per Invoice'!F$2:F$601,$AA4))) | G4: =IF($AA4="","",IF(INDEX('Per Invoice'!G$2:G$601,$AA4)="","",INDEX('Per Invoice'!G$2:G$601,$AA4))) | H4: =IF($AA4="","",IF(INDEX('Per Invoice'!H$2:H$601,$AA4)="","",INDEX('Per Invoice'!H$2:H$601,$AA4))) | ... Z4: =IF($AA4="","",IF(INDEX('Per Invoice'!Z$2:Z$601,$AA4)="","",INDEX('Per Invoice'!Z$2:Z$601,$AA4))) | AA4: =IFERROR(MATCH(Settings!$C$26&"|"&ROWS($AA$2:$AA4),'Per Invoice'!$AC$2:$AC$601,0),"")
A5: =IF($AA5="","",IF(INDEX('Per Invoice'!A$2:A$601,$AA5)="","",INDEX('Per Invoice'!A$2:A$601,$AA5))) | B5: =IF($AA5="","",IF(INDEX('Per Invoice'!B$2:B$601,$AA5)="","",INDEX('Per Invoice'!B$2:B$601,$AA5))) | C5: =IF($AA5="","",IF(INDEX('Per Invoice'!C$2:C$601,$AA5)="","",INDEX('Per Invoice'!C$2:C$601,$AA5))) | D5: =IF($AA5="","",IF(INDEX('Per Invoice'!D$2:D$601,$AA5)="","",INDEX('Per Invoice'!D$2:D$601,$AA5))) | E5: =IF($AA5="","",IF(INDEX('Per Invoice'!E$2:E$601,$AA5)="","",INDEX('Per Invoice'!E$2:E$601,$AA5))) | F5: =IF($AA5="","",IF(INDEX('Per Invoice'!F$2:F$601,$AA5)="","",INDEX('Per Invoice'!F$2:F$601,$AA5))) | G5: =IF($AA5="","",IF(INDEX('Per Invoice'!G$2:G$601,$AA5)="","",INDEX('Per Invoice'!G$2:G$601,$AA5))) | H5: =IF($AA5="","",IF(INDEX('Per Invoice'!H$2:H$601,$AA5)="","",INDEX('Per Invoice'!H$2:H$601,$AA5))) | ... Z5: =IF($AA5="","",IF(INDEX('Per Invoice'!Z$2:Z$601,$AA5)="","",INDEX('Per Invoice'!Z$2:Z$601,$AA5))) | AA5: =IFERROR(MATCH(Settings!$C$26&"|"&ROWS($AA$2:$AA5),'Per Invoice'!$AC$2:$AC$601,0),"")
A6: =IF($AA6="","",IF(INDEX('Per Invoice'!A$2:A$601,$AA6)="","",INDEX('Per Invoice'!A$2:A$601,$AA6))) | B6: =IF($AA6="","",IF(INDEX('Per Invoice'!B$2:B$601,$AA6)="","",INDEX('Per Invoice'!B$2:B$601,$AA6))) | C6: =IF($AA6="","",IF(INDEX('Per Invoice'!C$2:C$601,$AA6)="","",INDEX('Per Invoice'!C$2:C$601,$AA6))) | D6: =IF($AA6="","",IF(INDEX('Per Invoice'!D$2:D$601,$AA6)="","",INDEX('Per Invoice'!D$2:D$601,$AA6))) | E6: =IF($AA6="","",IF(INDEX('Per Invoice'!E$2:E$601,$AA6)="","",INDEX('Per Invoice'!E$2:E$601,$AA6))) | F6: =IF($AA6="","",IF(INDEX('Per Invoice'!F$2:F$601,$AA6)="","",INDEX('Per Invoice'!F$2:F$601,$AA6))) | G6: =IF($AA6="","",IF(INDEX('Per Invoice'!G$2:G$601,$AA6)="","",INDEX('Per Invoice'!G$2:G$601,$AA6))) | H6: =IF($AA6="","",IF(INDEX('Per Invoice'!H$2:H$601,$AA6)="","",INDEX('Per Invoice'!H$2:H$601,$AA6))) | ... Z6: =IF($AA6="","",IF(INDEX('Per Invoice'!Z$2:Z$601,$AA6)="","",INDEX('Per Invoice'!Z$2:Z$601,$AA6))) | AA6: =IFERROR(MATCH(Settings!$C$26&"|"&ROWS($AA$2:$AA6),'Per Invoice'!$AC$2:$AC$601,0),"")
A7: =IF($AA7="","",IF(INDEX('Per Invoice'!A$2:A$601,$AA7)="","",INDEX('Per Invoice'!A$2:A$601,$AA7))) | B7: =IF($AA7="","",IF(INDEX('Per Invoice'!B$2:B$601,$AA7)="","",INDEX('Per Invoice'!B$2:B$601,$AA7))) | C7: =IF($AA7="","",IF(INDEX('Per Invoice'!C$2:C$601,$AA7)="","",INDEX('Per Invoice'!C$2:C$601,$AA7))) | D7: =IF($AA7="","",IF(INDEX('Per Invoice'!D$2:D$601,$AA7)="","",INDEX('Per Invoice'!D$2:D$601,$AA7))) | E7: =IF($AA7="","",IF(INDEX('Per Invoice'!E$2:E$601,$AA7)="","",INDEX('Per Invoice'!E$2:E$601,$AA7))) | F7: =IF($AA7="","",IF(INDEX('Per Invoice'!F$2:F$601,$AA7)="","",INDEX('Per Invoice'!F$2:F$601,$AA7))) | G7: =IF($AA7="","",IF(INDEX('Per Invoice'!G$2:G$601,$AA7)="","",INDEX('Per Invoice'!G$2:G$601,$AA7))) | H7: =IF($AA7="","",IF(INDEX('Per Invoice'!H$2:H$601,$AA7)="","",INDEX('Per Invoice'!H$2:H$601,$AA7))) | ... Z7: =IF($AA7="","",IF(INDEX('Per Invoice'!Z$2:Z$601,$AA7)="","",INDEX('Per Invoice'!Z$2:Z$601,$AA7))) | AA7: =IFERROR(MATCH(Settings!$C$26&"|"&ROWS($AA$2:$AA7),'Per Invoice'!$AC$2:$AC$601,0),"")
A8: =IF($AA8="","",IF(INDEX('Per Invoice'!A$2:A$601,$AA8)="","",INDEX('Per Invoice'!A$2:A$601,$AA8))) | B8: =IF($AA8="","",IF(INDEX('Per Invoice'!B$2:B$601,$AA8)="","",INDEX('Per Invoice'!B$2:B$601,$AA8))) | C8: =IF($AA8="","",IF(INDEX('Per Invoice'!C$2:C$601,$AA8)="","",INDEX('Per Invoice'!C$2:C$601,$AA8))) | D8: =IF($AA8="","",IF(INDEX('Per Invoice'!D$2:D$601,$AA8)="","",INDEX('Per Invoice'!D$2:D$601,$AA8))) | E8: =IF($AA8="","",IF(INDEX('Per Invoice'!E$2:E$601,$AA8)="","",INDEX('Per Invoice'!E$2:E$601,$AA8))) | F8: =IF($AA8="","",IF(INDEX('Per Invoice'!F$2:F$601,$AA8)="","",INDEX('Per Invoice'!F$2:F$601,$AA8))) | G8: =IF($AA8="","",IF(INDEX('Per Invoice'!G$2:G$601,$AA8)="","",INDEX('Per Invoice'!G$2:G$601,$AA8))) | H8: =IF($AA8="","",IF(INDEX('Per Invoice'!H$2:H$601,$AA8)="","",INDEX('Per Invoice'!H$2:H$601,$AA8))) | ... Z8: =IF($AA8="","",IF(INDEX('Per Invoice'!Z$2:Z$601,$AA8)="","",INDEX('Per Invoice'!Z$2:Z$601,$AA8))) | AA8: =IFERROR(MATCH(Settings!$C$26&"|"&ROWS($AA$2:$AA8),'Per Invoice'!$AC$2:$AC$601,0),"")
A9: =IF($AA9="","",IF(INDEX('Per Invoice'!A$2:A$601,$AA9)="","",INDEX('Per Invoice'!A$2:A$601,$AA9))) | B9: =IF($AA9="","",IF(INDEX('Per Invoice'!B$2:B$601,$AA9)="","",INDEX('Per Invoice'!B$2:B$601,$AA9))) | C9: =IF($AA9="","",IF(INDEX('Per Invoice'!C$2:C$601,$AA9)="","",INDEX('Per Invoice'!C$2:C$601,$AA9))) | D9: =IF($AA9="","",IF(INDEX('Per Invoice'!D$2:D$601,$AA9)="","",INDEX('Per Invoice'!D$2:D$601,$AA9))) | E9: =IF($AA9="","",IF(INDEX('Per Invoice'!E$2:E$601,$AA9)="","",INDEX('Per Invoice'!E$2:E$601,$AA9))) | F9: =IF($AA9="","",IF(INDEX('Per Invoice'!F$2:F$601,$AA9)="","",INDEX('Per Invoice'!F$2:F$601,$AA9))) | G9: =IF($AA9="","",IF(INDEX('Per Invoice'!G$2:G$601,$AA9)="","",INDEX('Per Invoice'!G$2:G$601,$AA9))) | H9: =IF($AA9="","",IF(INDEX('Per Invoice'!H$2:H$601,$AA9)="","",INDEX('Per Invoice'!H$2:H$601,$AA9))) | ... Z9: =IF($AA9="","",IF(INDEX('Per Invoice'!Z$2:Z$601,$AA9)="","",INDEX('Per Invoice'!Z$2:Z$601,$AA9))) | AA9: =IFERROR(MATCH(Settings!$C$26&"|"&ROWS($AA$2:$AA9),'Per Invoice'!$AC$2:$AC$601,0),"")
A10: =IF($AA10="","",IF(INDEX('Per Invoice'!A$2:A$601,$AA10)="","",INDEX('Per Invoice'!A$2:A$601,$AA10))) | B10: =IF($AA10="","",IF(INDEX('Per Invoice'!B$2:B$601,$AA10)="","",INDEX('Per Invoice'!B$2:B$601,$AA10))) | C10: =IF($AA10="","",IF(INDEX('Per Invoice'!C$2:C$601,$AA10)="","",INDEX('Per Invoice'!C$2:C$601,$AA10))) | D10: =IF($AA10="","",IF(INDEX('Per Invoice'!D$2:D$601,$AA10)="","",INDEX('Per Invoice'!D$2:D$601,$AA10))) | E10: =IF($AA10="","",IF(INDEX('Per Invoice'!E$2:E$601,$AA10)="","",INDEX('Per Invoice'!E$2:E$601,$AA10))) | F10: =IF($AA10="","",IF(INDEX('Per Invoice'!F$2:F$601,$AA10)="","",INDEX('Per Invoice'!F$2:F$601,$AA10))) | G10: =IF($AA10="","",IF(INDEX('Per Invoice'!G$2:G$601,$AA10)="","",INDEX('Per Invoice'!G$2:G$601,$AA10))) | H10: =IF($AA10="","",IF(INDEX('Per Invoice'!H$2:H$601,$AA10)="","",INDEX('Per Invoice'!H$2:H$601,$AA10))) | ... Z10: =IF($AA10="","",IF(INDEX('Per Invoice'!Z$2:Z$601,$AA10)="","",INDEX('Per Invoice'!Z$2:Z$601,$AA10))) | AA10: =IFERROR(MATCH(Settings!$C$26&"|"&ROWS($AA$2:$AA10),'Per Invoice'!$AC$2:$AC$601,0),"")
A11: =IF($AA11="","",IF(INDEX('Per Invoice'!A$2:A$601,$AA11)="","",INDEX('Per Invoice'!A$2:A$601,$AA11))) | B11: =IF($AA11="","",IF(INDEX('Per Invoice'!B$2:B$601,$AA11)="","",INDEX('Per Invoice'!B$2:B$601,$AA11))) | C11: =IF($AA11="","",IF(INDEX('Per Invoice'!C$2:C$601,$AA11)="","",INDEX('Per Invoice'!C$2:C$601,$AA11))) | D11: =IF($AA11="","",IF(INDEX('Per Invoice'!D$2:D$601,$AA11)="","",INDEX('Per Invoice'!D$2:D$601,$AA11))) | E11: =IF($AA11="","",IF(INDEX('Per Invoice'!E$2:E$601,$AA11)="","",INDEX('Per Invoice'!E$2:E$601,$AA11))) | F11: =IF($AA11="","",IF(INDEX('Per Invoice'!F$2:F$601,$AA11)="","",INDEX('Per Invoice'!F$2:F$601,$AA11))) | G11: =IF($AA11="","",IF(INDEX('Per Invoice'!G$2:G$601,$AA11)="","",INDEX('Per Invoice'!G$2:G$601,$AA11))) | H11: =IF($AA11="","",IF(INDEX('Per Invoice'!H$2:H$601,$AA11)="","",INDEX('Per Invoice'!H$2:H$601,$AA11))) | ... Z11: =IF($AA11="","",IF(INDEX('Per Invoice'!Z$2:Z$601,$AA11)="","",INDEX('Per Invoice'!Z$2:Z$601,$AA11))) | AA11: =IFERROR(MATCH(Settings!$C$26&"|"&ROWS($AA$2:$AA11),'Per Invoice'!$AC$2:$AC$601,0),"")
A12: =IF($AA12="","",IF(INDEX('Per Invoice'!A$2:A$601,$AA12)="","",INDEX('Per Invoice'!A$2:A$601,$AA12))) | B12: =IF($AA12="","",IF(INDEX('Per Invoice'!B$2:B$601,$AA12)="","",INDEX('Per Invoice'!B$2:B$601,$AA12))) | C12: =IF($AA12="","",IF(INDEX('Per Invoice'!C$2:C$601,$AA12)="","",INDEX('Per Invoice'!C$2:C$601,$AA12))) | D12: =IF($AA12="","",IF(INDEX('Per Invoice'!D$2:D$601,$AA12)="","",INDEX('Per Invoice'!D$2:D$601,$AA12))) | E12: =IF($AA12="","",IF(INDEX('Per Invoice'!E$2:E$601,$AA12)="","",INDEX('Per Invoice'!E$2:E$601,$AA12))) | F12: =IF($AA12="","",IF(INDEX('Per Invoice'!F$2:F$601,$AA12)="","",INDEX('Per Invoice'!F$2:F$601,$AA12))) | G12: =IF($AA12="","",IF(INDEX('Per Invoice'!G$2:G$601,$AA12)="","",INDEX('Per Invoice'!G$2:G$601,$AA12))) | H12: =IF($AA12="","",IF(INDEX('Per Invoice'!H$2:H$601,$AA12)="","",INDEX('Per Invoice'!H$2:H$601,$AA12))) | ... Z12: =IF($AA12="","",IF(INDEX('Per Invoice'!Z$2:Z$601,$AA12)="","",INDEX('Per Invoice'!Z$2:Z$601,$AA12))) | AA12: =IFERROR(MATCH(Settings!$C$26&"|"&ROWS($AA$2:$AA12),'Per Invoice'!$AC$2:$AC$601,0),"")
A13: =IF($AA13="","",IF(INDEX('Per Invoice'!A$2:A$601,$AA13)="","",INDEX('Per Invoice'!A$2:A$601,$AA13))) | B13: =IF($AA13="","",IF(INDEX('Per Invoice'!B$2:B$601,$AA13)="","",INDEX('Per Invoice'!B$2:B$601,$AA13))) | C13: =IF($AA13="","",IF(INDEX('Per Invoice'!C$2:C$601,$AA13)="","",INDEX('Per Invoice'!C$2:C$601,$AA13))) | D13: =IF($AA13="","",IF(INDEX('Per Invoice'!D$2:D$601,$AA13)="","",INDEX('Per Invoice'!D$2:D$601,$AA13))) | E13: =IF($AA13="","",IF(INDEX('Per Invoice'!E$2:E$601,$AA13)="","",INDEX('Per Invoice'!E$2:E$601,$AA13))) | F13: =IF($AA13="","",IF(INDEX('Per Invoice'!F$2:F$601,$AA13)="","",INDEX('Per Invoice'!F$2:F$601,$AA13))) | G13: =IF($AA13="","",IF(INDEX('Per Invoice'!G$2:G$601,$AA13)="","",INDEX('Per Invoice'!G$2:G$601,$AA13))) | H13: =IF($AA13="","",IF(INDEX('Per Invoice'!H$2:H$601,$AA13)="","",INDEX('Per Invoice'!H$2:H$601,$AA13))) | ... Z13: =IF($AA13="","",IF(INDEX('Per Invoice'!Z$2:Z$601,$AA13)="","",INDEX('Per Invoice'!Z$2:Z$601,$AA13))) | AA13: =IFERROR(MATCH(Settings!$C$26&"|"&ROWS($AA$2:$AA13),'Per Invoice'!$AC$2:$AC$601,0),"")
... A201: =IF($AA201="","",IF(INDEX('Per Invoice'!A$2:A$601,$AA201)="","",INDEX('Per Invoice'!A$2:A$601,$AA201))) | B201: =IF($AA201="","",IF(INDEX('Per Invoice'!B$2:B$601,$AA201)="","",INDEX('Per Invoice'!B$2:B$601,$AA201))) | C201: =IF($AA201="","",IF(INDEX('Per Invoice'!C$2:C$601,$AA201)="","",INDEX('Per Invoice'!C$2:C$601,$AA201))) | D201: =IF($AA201="","",IF(INDEX('Per Invoice'!D$2:D$601,$AA201)="","",INDEX('Per Invoice'!D$2:D$601,$AA201))) | E201: =IF($AA201="","",IF(INDEX('Per Invoice'!E$2:E$601,$AA201)="","",INDEX('Per Invoice'!E$2:E$601,$AA201))) | F201: =IF($AA201="","",IF(INDEX('Per Invoice'!F$2:F$601,$AA201)="","",INDEX('Per Invoice'!F$2:F$601,$AA201))) | G201: =IF($AA201="","",IF(INDEX('Per Invoice'!G$2:G$601,$AA201)="","",INDEX('Per Invoice'!G$2:G$601,$AA201))) | H201: =IF($AA201="","",IF(INDEX('Per Invoice'!H$2:H$601,$AA201)="","",INDEX('Per Invoice'!H$2:H$601,$AA201))) | ... Z201: =IF($AA201="","",IF(INDEX('Per Invoice'!Z$2:Z$601,$AA201)="","",INDEX('Per Invoice'!Z$2:Z$601,$AA201))) | AA201: =IFERROR(MATCH(Settings!$C$26&"|"&ROWS($AA$2:$AA201),'Per Invoice'!$AC$2:$AC$601,0),"")

Sheet October Pensioners
A1: Invoice | B1: Order # | C1: Site Tab (##) | D1: Cycle | E1: Create At | F1: Insurance Company | G1: Corporate | H1: Card | I1: Name | J1: Order Co Payment | K1: Co val | L1: ERX ID | M1: Max Limit | N1: Exceeding Limit | O1: Exceeding BY | P1: Special | Q1: IMP % | R1: IMP | S1: IMP VAL | T1: LOCAL% | U1: LOCAL | V1: LOCAL VAL | W1: TOTAL VAL | X1: SUBTOTAL | Y1: Grand Total | Z1: NET | AA1: Src Row (helper)
A2: =IF($AA2="","",IF(INDEX('Per Invoice'!A$2:A$601,$AA2)="","",INDEX('Per Invoice'!A$2:A$601,$AA2))) | B2: =IF($AA2="","",IF(INDEX('Per Invoice'!B$2:B$601,$AA2)="","",INDEX('Per Invoice'!B$2:B$601,$AA2))) | C2: =IF($AA2="","",IF(INDEX('Per Invoice'!C$2:C$601,$AA2)="","",INDEX('Per Invoice'!C$2:C$601,$AA2))) | D2: =IF($AA2="","",IF(INDEX('Per Invoice'!D$2:D$601,$AA2)="","",INDEX('Per Invoice'!D$2:D$601,$AA2))) | E2: =IF($AA2="","",IF(INDEX('Per Invoice'!E$2:E$601,$AA2)="","",INDEX('Per Invoice'!E$2:E$601,$AA2))) | F2: =IF($AA2="","",IF(INDEX('Per Invoice'!F$2:F$601,$AA2)="","",INDEX('Per Invoice'!F$2:F$601,$AA2))) | G2: =IF($AA2="","",IF(INDEX('Per Invoice'!G$2:G$601,$AA2)="","",INDEX('Per Invoice'!G$2:G$601,$AA2))) | H2: =IF($AA2="","",IF(INDEX('Per Invoice'!H$2:H$601,$AA2)="","",INDEX('Per Invoice'!H$2:H$601,$AA2))) | ... Z2: =IF($AA2="","",IF(INDEX('Per Invoice'!Z$2:Z$601,$AA2)="","",INDEX('Per Invoice'!Z$2:Z$601,$AA2))) | AA2: =IFERROR(MATCH(Settings!$C$27&"|"&ROWS($AA$2:$AA2),'Per Invoice'!$AC$2:$AC$601,0),"")
A3: =IF($AA3="","",IF(INDEX('Per Invoice'!A$2:A$601,$AA3)="","",INDEX('Per Invoice'!A$2:A$601,$AA3))) | B3: =IF($AA3="","",IF(INDEX('Per Invoice'!B$2:B$601,$AA3)="","",INDEX('Per Invoice'!B$2:B$601,$AA3))) | C3: =IF($AA3="","",IF(INDEX('Per Invoice'!C$2:C$601,$AA3)="","",INDEX('Per Invoice'!C$2:C$601,$AA3))) | D3: =IF($AA3="","",IF(INDEX('Per Invoice'!D$2:D$601,$AA3)="","",INDEX('Per Invoice'!D$2:D$601,$AA3))) | E3: =IF($AA3="","",IF(INDEX('Per Invoice'!E$2:E$601,$AA3)="","",INDEX('Per Invoice'!E$2:E$601,$AA3))) | F3: =IF($AA3="","",IF(INDEX('Per Invoice'!F$2:F$601,$AA3)="","",INDEX('Per Invoice'!F$2:F$601,$AA3))) | G3: =IF($AA3="","",IF(INDEX('Per Invoice'!G$2:G$601,$AA3)="","",INDEX('Per Invoice'!G$2:G$601,$AA3))) | H3: =IF($AA3="","",IF(INDEX('Per Invoice'!H$2:H$601,$AA3)="","",INDEX('Per Invoice'!H$2:H$601,$AA3))) | ... Z3: =IF($AA3="","",IF(INDEX('Per Invoice'!Z$2:Z$601,$AA3)="","",INDEX('Per Invoice'!Z$2:Z$601,$AA3))) | AA3: =IFERROR(MATCH(Settings!$C$27&"|"&ROWS($AA$2:$AA3),'Per Invoice'!$AC$2:$AC$601,0),"")
A4: =IF($AA4="","",IF(INDEX('Per Invoice'!A$2:A$601,$AA4)="","",INDEX('Per Invoice'!A$2:A$601,$AA4))) | B4: =IF($AA4="","",IF(INDEX('Per Invoice'!B$2:B$601,$AA4)="","",INDEX('Per Invoice'!B$2:B$601,$AA4))) | C4: =IF($AA4="","",IF(INDEX('Per Invoice'!C$2:C$601,$AA4)="","",INDEX('Per Invoice'!C$2:C$601,$AA4))) | D4: =IF($AA4="","",IF(INDEX('Per Invoice'!D$2:D$601,$AA4)="","",INDEX('Per Invoice'!D$2:D$601,$AA4))) | E4: =IF($AA4="","",IF(INDEX('Per Invoice'!E$2:E$601,$AA4)="","",INDEX('Per Invoice'!E$2:E$601,$AA4))) | F4: =IF($AA4="","",IF(INDEX('Per Invoice'!F$2:F$601,$AA4)="","",INDEX('Per Invoice'!F$2:F$601,$AA4))) | G4: =IF($AA4="","",IF(INDEX('Per Invoice'!G$2:G$601,$AA4)="","",INDEX('Per Invoice'!G$2:G$601,$AA4))) | H4: =IF($AA4="","",IF(INDEX('Per Invoice'!H$2:H$601,$AA4)="","",INDEX('Per Invoice'!H$2:H$601,$AA4))) | ... Z4: =IF($AA4="","",IF(INDEX('Per Invoice'!Z$2:Z$601,$AA4)="","",INDEX('Per Invoice'!Z$2:Z$601,$AA4))) | AA4: =IFERROR(MATCH(Settings!$C$27&"|"&ROWS($AA$2:$AA4),'Per Invoice'!$AC$2:$AC$601,0),"")
