Workbook

Sheet How To Use
A1: Claims Template - AIN SHAMS UNIVERSITY - STAFF (Chronic)
A3: Monthly steps
A4: 1. Open the 'Per Line' tab. Delete the old data in the BLUE columns only (row 2 down). Never delete the green or grey columns.
A5: 2. Paste the new month's data as VALUES starting at A2, into the blue columns: A-M, O-X, AC-AJ (same order as the system export).
A6: 3. Green columns (N, Y, Z, AA, AB) and the grey helper columns (AK-AO) calculate automatically - do not paste over them.
A7: 4. 'Per Invoice' fills itself from 'Per Line' (one row per Order #, split into IMP / Local). No pivot table, no refresh.
A8: 5. The ONLY manual column in 'Per Invoice' is column A 'Invoice' (blue): type it yourself. Everything else is formula.
A9: 6. The tabs, the Arabic 'Template ...' sheets and 'Summary' fill themselves from 'Per Invoice'. Column 'Site Tab (##)' decides which tab each invoice goes to (rule and limit are in Settings).
A10: 7. Open 'Settings' and check STATUS says OK (Per Line = Per Invoice, and every invoice has a payer that is listed in Settings).
A12: Colour legend
A13: Blue header = typed/pasted by you (raw data, and 'Invoice' in Per Invoice). Green header = formula (do not paste over). Grey header = helper formula (do not touch). Yellow cell (Settings) = editable rate.
A15: Calculation rules (taken from the September 2026 sheet)
... A22: Max Limit rule (as in the old sheet): if an invoice's Grand Total is above its Max Limit, Co val = Co Payment x Max Limit / 100 + (Grand Total - Max Limit). Per Line keeps the plain Co val, so 'Settings' shows the difference as 'Max Limit adjustment'.

Sheet Settings
B1: Company settings & checks
B3: Insurance Company | C3: AIN SHAMS UNIVERSITY - STAFF | D3: Informational only
B4: Corporate | C4: Ain Shams University Staff | D4: Informational only
B5: Sheet type | C5: Chronic | D5: Informational only
B6: Local products rebate % | C6: 0.19 | D6: Source: Sep sheet (Rebates = 19 on Local lines).
B7: Imported (IMP) products rebate % | C7: 0.09 | D7: Source: Sep sheet (Rebates = 9 on non-local lines).
B8: Invoice amount limit (Grand Total) | C8: 10000 | D8: Invoices with Grand Total below this go to tab "INV<10000", the rest to tab "Inv>10000".
B9: Month totals / reconciliation
B10: Lines loaded | C10: =COUNTA('Per Line'!$D$2:$D$7001)
B11: Invoices (unique Order #) | C11: =MAX('Per Line'!$AL$2:$AL$7001)
B12: Invoices shown in Per Invoice | C12: =SUMPRODUCT(--('Per Invoice'!$B$2:$B$1201<>""))
B13: Grand Total - Per Line (Product Total) | C13: =SUM('Per Line'!$V$2:$V$7001)
B14: Grand Total - Per Invoice | C14: =SUM('Per Invoice'!$X$2:$X$1201)
B15: Discount - Per Line | C15: =SUM('Per Line'!$Z$2:$Z$7001)
B16: Discount - Per Invoice | C16: =SUM('Per Invoice'!$V$2:$V$1201)
B17: Co val - Per Line | C17: =SUM('Per Line'!$N$2:$N$7001)
B18: Co val - Per Invoice | C18: =SUM('Per Invoice'!$K$2:$K$1201)
B19: Net - Per Line | C19: =SUM('Per Line'!$AB$2:$AB$7001)
B20: Net - Per Invoice | C20: =SUM('Per Invoice'!$Y$2:$Y$1201)
B21: Max Limit adjustment (Co val, Per Invoice only) | C21: =SUM('Per Invoice'!$AA$2:$AA$1201) | D21: Invoices whose Grand Total is above the Max Limit: Co val = Co% x Max Limit / 100 + (Grand Total - Max Limit). This difference exists only in Per Invoice, as in the old sheet.
B23: STATUS | C23: =IF(C10=0,"No data loaded",IF(COUNTA('Per Line'!$D:$D)-1>7000,"TOO MANY LINES - extend template",IF(C11>1200,"TOO MANY INVOICES - extend template",IF(AND(ROUND(C13-C14,2)=0,ROUND(C15-C16,2)=0,ROUND(C17+C21-C18,2)=0,ROUND(C19-C21-C20,2)=0,C11=C12,C29=0,MAX(D26:D27)<=1000),"OK","CHECK - Per Line and Per Invoice do not match")))) | D23: Must say OK after you paste the month data.
B25: Site tabs | C25: Site name exactly as in the Site Tab (##) column | D25: Invoices (formula)
B26: INV<10000 | C26: INV<10000 | D26: =IF(C26="",0,COUNTIF('Per Invoice'!$C$2:$C$1201,C26))
B27: Inv>10000 | C27: Inv>10000 | D27: =IF(C27="",0,COUNTIF('Per Invoice'!$C$2:$C$1201,C27))
B29: Invoices not in any site tab (must be 0) | C29: =C11-SUM(D26:D27) | D29: If not 0: a new site appeared. Type its exact name in one of the empty yellow cells above (Extra 1 ... Extra n); the tab Extra n then shows it. Each tab holds up to 1000 invoices.

Sheet Summary
A1: Corporate | B1: Count | C1: اجمالي المحلي | D1: اجمالي المستورد | E1: الخصم | F1: التحمل | G1: الصافي
A2: =IF(Settings!$C$26="","",Settings!$C$26) | B2: =IF($A2="","",COUNTIF('Per Invoice'!$C$2:$C$1201,$A2)) | C2: =IF($A2="","",SUMIFS('Per Invoice'!$T$2:$T$1201,'Per Invoice'!$C$2:$C$1201,$A2)) | D2: =IF($A2="","",SUMIFS('Per Invoice'!$Q$2:$Q$1201,'Per Invoice'!$C$2:$C$1201,$A2)) | E2: =IF($A2="","",SUMIFS('Per Invoice'!$V$2:$V$1201,'Per Invoice'!$C$2:$C$1201,$A2)) | F2: =IF($A2="","",SUMIFS('Per Invoice'!$K$2:$K$1201,'Per Invoice'!$C$2:$C$1201,$A2)) | G2: =IF($A2="","",SUMIFS('Per Invoice'!$Y$2:$Y$1201,'Per Invoice'!$C$2:$C$1201,$A2))
A3: =IF(Settings!$C$27="","",Settings!$C$27) | B3: =IF($A3="","",COUNTIF('Per Invoice'!$C$2:$C$1201,$A3)) | C3: =IF($A3="","",SUMIFS('Per Invoice'!$T$2:$T$1201,'Per Invoice'!$C$2:$C$1201,$A3)) | D3: =IF($A3="","",SUMIFS('Per Invoice'!$Q$2:$Q$1201,'Per Invoice'!$C$2:$C$1201,$A3)) | E3: =IF($A3="","",SUMIFS('Per Invoice'!$V$2:$V$1201,'Per Invoice'!$C$2:$C$1201,$A3)) | F3: =IF($A3="","",SUMIFS('Per Invoice'!$K$2:$K$1201,'Per Invoice'!$C$2:$C$1201,$A3)) | G3: =IF($A3="","",SUMIFS('Per Invoice'!$Y$2:$Y$1201,'Per Invoice'!$C$2:$C$1201,$A3))
A4: الاجمالي | B4: =SUM(B2:B3) | C4: =SUM(C2:C3) | D4: =SUM(D2:D3) | E4: =SUM(E2:E3) | F4: =SUM(F2:F3) | G4: =SUM(G2:G3)

Sheet Per Line
A1: Cycle | B1: Ticket # | C1: Stage | D1: Order # | E1: Channel | F1: Create At | G1: Insurance Company | H1: Country Portal ID | I1: Corporate | J1: Card | K1: Name | L1: Status | M1: Order Co Payment | N1: Co val | O1: By Patient | P1: heisenberg id | Q1: Product Name | R1: Local | S1: Unit | T1: Quantity | U1: Unit Price | V1: Product Total | W1: ERX ID | X1: Special Rebates? | Y1: Rebates | Z1: Discount | AA1: Subtotal | AB1: Net | AC1: Approval Type | AD1: Max Limit | AE1: Exceeding Limit | AF1: Amount collected from customer | AG1: By Patient (Delivered) | AH1: Dispense Number | AI1: Dispense Date | AJ1: Has OTP? | AK1: Order 1st Row (helper) | AL1: Invoice # (helper) | AM1: Is Local (helper) | AN1: Is Special (helper) | AO1: Sort Key (helper)
N2: =IF($D2="","",M2*V2/100) | Y2: =IF($D2="","",IF($AN2=1,0,IF($AM2=1,Settings!$C$6,Settings!$C$7))*100) | Z2: =IF($D2="","",V2*Y2/100) | AA2: =IF($D2="","",V2-Z2) | AB2: =IF($D2="","",AA2-N2) | AK2: =IF($D2="","",IF(COUNTIF($D$2:$D2,$D2)=1,1,0)) | AL2: =IF($AK2=1,SUMPRODUCT(--($AO$2:$AO$7001<$AO2))+1,"") | AM2: =IF($D2="","",IF(OR($R2=TRUE(),$R2="TRUE"),1,0)) | AN2: =IF($D2="","",IF($X2="Yes",1,0)) | AO2: =IF($AK2=1,IFERROR(IF(VALUE($D2)<100000000,VALUE($D2),1000000000),IFERROR(IF(VALUE(MID($D2,2,20))<100000000,VALUE(MID($D2,2,20)),1000000000),1000000000))+ROW()/100000,"")
N3: =IF($D3="","",M3*V3/100) | Y3: =IF($D3="","",IF($AN3=1,0,IF($AM3=1,Settings!$C$6,Settings!$C$7))*100) | Z3: =IF($D3="","",V3*Y3/100) | AA3: =IF($D3="","",V3-Z3) | AB3: =IF($D3="","",AA3-N3) | AK3: =IF($D3="","",IF(COUNTIF($D$2:$D3,$D3)=1,1,0)) | AL3: =IF($AK3=1,SUMPRODUCT(--($AO$2:$AO$7001<$AO3))+1,"") | AM3: =IF($D3="","",IF(OR($R3=TRUE(),$R3="TRUE"),1,0)) | AN3: =IF($D3="","",IF($X3="Yes",1,0)) | AO3: =IF($AK3=1,IFERROR(IF(VALUE($D3)<100000000,VALUE($D3),1000000000),IFERROR(IF(VALUE(MID($D3,2,20))<100000000,VALUE(MID($D3,2,20)),1000000000),1000000000))+ROW()/100000,"")
N4: =IF($D4="","",M4*V4/100) | Y4: =IF($D4="","",IF($AN4=1,0,IF($AM4=1,Settings!$C$6,Settings!$C$7))*100) | Z4: =IF($D4="","",V4*Y4/100) | AA4: =IF($D4="","",V4-Z4) | AB4: =IF($D4="","",AA4-N4) | AK4: =IF($D4="","",IF(COUNTIF($D$2:$D4,$D4)=1,1,0)) | AL4: =IF($AK4=1,SUMPRODUCT(--($AO$2:$AO$7001<$AO4))+1,"") | AM4: =IF($D4="","",IF(OR($R4=TRUE(),$R4="TRUE"),1,0)) | AN4: =IF($D4="","",IF($X4="Yes",1,0)) | AO4: =IF($AK4=1,IFERROR(IF(VALUE($D4)<100000000,VALUE($D4),1000000000),IFERROR(IF(VALUE(MID($D4,2,20))<100000000,VALUE(MID($D4,2,20)),1000000000),1000000000))+ROW()/100000,"")
N5: =IF($D5="","",M5*V5/100) | Y5: =IF($D5="","",IF($AN5=1,0,IF($AM5=1,Settings!$C$6,Settings!$C$7))*100) | Z5: =IF($D5="","",V5*Y5/100) | AA5: =IF($D5="","",V5-Z5) | AB5: =IF($D5="","",AA5-N5) | AK5: =IF($D5="","",IF(COUNTIF($D$2:$D5,$D5)=1,1,0)) | AL5: =IF($AK5=1,SUMPRODUCT(--($AO$2:$AO$7001<$AO5))+1,"") | AM5: =IF($D5="","",IF(OR($R5=TRUE(),$R5="TRUE"),1,0)) | AN5: =IF($D5="","",IF($X5="Yes",1,0)) | AO5: =IF($AK5=1,IFERROR(IF(VALUE($D5)<100000000,VALUE($D5),1000000000),IFERROR(IF(VALUE(MID($D5,2,20))<100000000,VALUE(MID($D5,2,20)),1000000000),1000000000))+ROW()/100000,"")
N6: =IF($D6="","",M6*V6/100) | Y6: =IF($D6="","",IF($AN6=1,0,IF($AM6=1,Settings!$C$6,Settings!$C$7))*100) | Z6: =IF($D6="","",V6*Y6/100) | AA6: =IF($D6="","",V6-Z6) | AB6: =IF($D6="","",AA6-N6) | AK6: =IF($D6="","",IF(COUNTIF($D$2:$D6,$D6)=1,1,0)) | AL6: =IF($AK6=1,SUMPRODUCT(--($AO$2:$AO$7001<$AO6))+1,"") | AM6: =IF($D6="","",IF(OR($R6=TRUE(),$R6="TRUE"),1,0)) | AN6: =IF($D6="","",IF($X6="Yes",1,0)) | AO6: =IF($AK6=1,IFERROR(IF(VALUE($D6)<100000000,VALUE($D6),1000000000),IFERROR(IF(VALUE(MID($D6,2,20))<100000000,VALUE(MID($D6,2,20)),1000000000),1000000000))+ROW()/100000,"")
N7: =IF($D7="","",M7*V7/100) | Y7: =IF($D7="","",IF($AN7=1,0,IF($AM7=1,Settings!$C$6,Settings!$C$7))*100) | Z7: =IF($D7="","",V7*Y7/100) | AA7: =IF($D7="","",V7-Z7) | AB7: =IF($D7="","",AA7-N7) | AK7: =IF($D7="","",IF(COUNTIF($D$2:$D7,$D7)=1,1,0)) | AL7: =IF($AK7=1,SUMPRODUCT(--($AO$2:$AO$7001<$AO7))+1,"") | AM7: =IF($D7="","",IF(OR($R7=TRUE(),$R7="TRUE"),1,0)) | AN7: =IF($D7="","",IF($X7="Yes",1,0)) | AO7: =IF($AK7=1,IFERROR(IF(VALUE($D7)<100000000,VALUE($D7),1000000000),IFERROR(IF(VALUE(MID($D7,2,20))<100000000,VALUE(MID($D7,2,20)),1000000000),1000000000))+ROW()/100000,"")
N8: =IF($D8="","",M8*V8/100) | Y8: =IF($D8="","",IF($AN8=1,0,IF($AM8=1,Settings!$C$6,Settings!$C$7))*100) | Z8: =IF($D8="","",V8*Y8/100) | AA8: =IF($D8="","",V8-Z8) | AB8: =IF($D8="","",AA8-N8) | AK8: =IF($D8="","",IF(COUNTIF($D$2:$D8,$D8)=1,1,0)) | AL8: =IF($AK8=1,SUMPRODUCT(--($AO$2:$AO$7001<$AO8))+1,"") | AM8: =IF($D8="","",IF(OR($R8=TRUE(),$R8="TRUE"),1,0)) | AN8: =IF($D8="","",IF($X8="Yes",1,0)) | AO8: =IF($AK8=1,IFERROR(IF(VALUE($D8)<100000000,VALUE($D8),1000000000),IFERROR(IF(VALUE(MID($D8,2,20))<100000000,VALUE(MID($D8,2,20)),1000000000),1000000000))+ROW()/100000,"")
N9: =IF($D9="","",M9*V9/100) | Y9: =IF($D9="","",IF($AN9=1,0,IF($AM9=1,Settings!$C$6,Settings!$C$7))*100) | Z9: =IF($D9="","",V9*Y9/100) | AA9: =IF($D9="","",V9-Z9) | AB9: =IF($D9="","",AA9-N9) | AK9: =IF($D9="","",IF(COUNTIF($D$2:$D9,$D9)=1,1,0)) | AL9: =IF($AK9=1,SUMPRODUCT(--($AO$2:$AO$7001<$AO9))+1,"") | AM9: =IF($D9="","",IF(OR($R9=TRUE(),$R9="TRUE"),1,0)) | AN9: =IF($D9="","",IF($X9="Yes",1,0)) | AO9: =IF($AK9=1,IFERROR(IF(VALUE($D9)<100000000,VALUE($D9),1000000000),IFERROR(IF(VALUE(MID($D9,2,20))<100000000,VALUE(MID($D9,2,20)),1000000000),1000000000))+ROW()/100000,"")
N10: =IF($D10="","",M10*V10/100) | Y10: =IF($D10="","",IF($AN10=1,0,IF($AM10=1,Settings!$C$6,Settings!$C$7))*100) | Z10: =IF($D10="","",V10*Y10/100) | AA10: =IF($D10="","",V10-Z10) | AB10: =IF($D10="","",AA10-N10) | AK10: =IF($D10="","",IF(COUNTIF($D$2:$D10,$D10)=1,1,0)) | AL10: =IF($AK10=1,SUMPRODUCT(--($AO$2:$AO$7001<$AO10))+1,"") | AM10: =IF($D10="","",IF(OR($R10=TRUE(),$R10="TRUE"),1,0)) | AN10: =IF($D10="","",IF($X10="Yes",1,0)) | AO10: =IF($AK10=1,IFERROR(IF(VALUE($D10)<100000000,VALUE($D10),1000000000),IFERROR(IF(VALUE(MID($D10,2,20))<100000000,VALUE(MID($D10,2,20)),1000000000),1000000000))+ROW()/100000,"")
N11: =IF($D11="","",M11*V11/100) | Y11: =IF($D11="","",IF($AN11=1,0,IF($AM11=1,Settings!$C$6,Settings!$C$7))*100) | Z11: =IF($D11="","",V11*Y11/100) | AA11: =IF($D11="","",V11-Z11) | AB11: =IF($D11="","",AA11-N11) | AK11: =IF($D11="","",IF(COUNTIF($D$2:$D11,$D11)=1,1,0)) | AL11: =IF($AK11=1,SUMPRODUCT(--($AO$2:$AO$7001<$AO11))+1,"") | AM11: =IF($D11="","",IF(OR($R11=TRUE(),$R11="TRUE"),1,0)) | AN11: =IF($D11="","",IF($X11="Yes",1,0)) | AO11: =IF($AK11=1,IFERROR(IF(VALUE($D11)<100000000,VALUE($D11),1000000000),IFERROR(IF(VALUE(MID($D11,2,20))<100000000,VALUE(MID($D11,2,20)),1000000000),1000000000))+ROW()/100000,"")
N12: =IF($D12="","",M12*V12/100) | Y12: =IF($D12="","",IF($AN12=1,0,IF($AM12=1,Settings!$C$6,Settings!$C$7))*100) | Z12: =IF($D12="","",V12*Y12/100) | AA12: =IF($D12="","",V12-Z12) | AB12: =IF($D12="","",AA12-N12) | AK12: =IF($D12="","",IF(COUNTIF($D$2:$D12,$D12)=1,1,0)) | AL12: =IF($AK12=1,SUMPRODUCT(--($AO$2:$AO$7001<$AO12))+1,"") | AM12: =IF($D12="","",IF(OR($R12=TRUE(),$R12="TRUE"),1,0)) | AN12: =IF($D12="","",IF($X12="Yes",1,0)) | AO12: =IF($AK12=1,IFERROR(IF(VALUE($D12)<100000000,VALUE($D12),1000000000),IFERROR(IF(VALUE(MID($D12,2,20))<100000000,VALUE(MID($D12,2,20)),1000000000),1000000000))+ROW()/100000,"")
N13: =IF($D13="","",M13*V13/100) | Y13: =IF($D13="","",IF($AN13=1,0,IF($AM13=1,Settings!$C$6,Settings!$C$7))*100) | Z13: =IF($D13="","",V13*Y13/100) | AA13: =IF($D13="","",V13-Z13) | AB13: =IF($D13="","",AA13-N13) | AK13: =IF($D13="","",IF(COUNTIF($D$2:$D13,$D13)=1,1,0)) | AL13: =IF($AK13=1,SUMPRODUCT(--($AO$2:$AO$7001<$AO13))+1,"") | AM13: =IF($D13="","",IF(OR($R13=TRUE(),$R13="TRUE"),1,0)) | AN13: =IF($D13="","",IF($X13="Yes",1,0)) | AO13: =IF($AK13=1,IFERROR(IF(VALUE($D13)<100000000,VALUE($D13),1000000000),IFERROR(IF(VALUE(MID($D13,2,20))<100000000,VALUE(MID($D13,2,20)),1000000000),1000000000))+ROW()/100000,"")
... N7001: =IF($D7001="","",M7001*V7001/100) | Y7001: =IF($D7001="","",IF($AN7001=1,0,IF($AM7001=1,Settings!$C$6,Settings!$C$7))*100) | Z7001: =IF($D7001="","",V7001*Y7001/100) | AA7001: =IF($D7001="","",V7001-Z7001) | AB7001: =IF($D7001="","",AA7001-N7001) | AK7001: =IF($D7001="","",IF(COUNTIF($D$2:$D7001,$D7001)=1,1,0)) | AL7001: =IF($AK7001=1,SUMPRODUCT(--($AO$2:$AO$7001<$AO7001))+1,"") | AM7001: =IF($D7001="","",IF(OR($R7001=TRUE(),$R7001="TRUE"),1,0)) | AN7001: =IF($D7001="","",IF($X7001="Yes",1,0)) | AO7001: =IF($AK7001=1,IFERROR(IF(VALUE($D7001)<100000000,VALUE($D7001),1000000000),IFERROR(IF(VALUE(MID($D7001,2,20))<100000000,VALUE(MID($D7001,2,20)),1000000000),1000000000))+ROW()/100000,"")

Sheet Per Invoice
A1: Invoice | B1: Order # | C1: Site Tab (##) | D1: Cycle | E1: Create At | F1: Insurance Company | G1: Corporate | H1: Card | I1: Name | J1: Order Co Payment | K1: Co val | L1: ERX ID | M1: Max Limit | N1: Exceeding Limit | O1: Special | P1: IMP % | Q1: IMP | R1: IMP VAL | S1: LOCAL % | T1: LOCAL | U1: LOCAL VAL | V1: TOTAL VAL | W1: SUBTOTAL | X1: Grand Total | Y1: NET | Z1: Src Row (helper) | AA1: Limit Adj (helper) | AB1: Payer Key (helper)
B2: =IF($Z2="","",INDEX('Per Line'!$D$2:$D$7001,$Z2)&"") | C2: =IF($Z2="","",IF(X2<Settings!$C$8,"INV<10000","Inv>10000")) | D2: =IF($Z2="","",INDEX('Per Line'!$A$2:$A$7001,$Z2)&"") | E2: =IF($Z2="","",INDEX('Per Line'!$F$2:$F$7001,$Z2)) | F2: =IF($Z2="","",INDEX('Per Line'!$G$2:$G$7001,$Z2)&"") | G2: =IF($Z2="","",INDEX('Per Line'!$I$2:$I$7001,$Z2)&"") | H2: =IF($Z2="","",INDEX('Per Line'!$J$2:$J$7001,$Z2)&"") | I2: =IF($Z2="","",INDEX('Per Line'!$K$2:$K$7001,$Z2)&"") | J2: =IF($Z2="","",INDEX('Per Line'!$M$2:$M$7001,$Z2)) | K2: =IF($Z2="","",IF(AND(ISNUMBER(M2),M2>0,X2>M2),J2*M2/100+(X2-M2),J2*X2/100)) | L2: =IF($Z2="","",INDEX('Per Line'!$W$2:$W$7001,$Z2)&"") | M2: =IF($Z2="","",INDEX('Per Line'!$AD$2:$AD$7001,$Z2)) | N2: =IF($Z2="","",IF(AND(ISNUMBER(M2),M2>0),X2>M2,FALSE)) | O2: =IF($Z2="","",SUMIFS('Per Line'!$V$2:$V$7001,'Per Line'!$D$2:$D$7001,$B2,'Per Line'!$AN$2:$AN$7001,1)) | P2: =IF($Z2="","",Settings!$C$7) | Q2: =IF($Z2="","",SUMIFS('Per Line'!$V$2:$V$7001,'Per Line'!$D$2:$D$7001,$B2,'Per Line'!$AM$2:$AM$7001,0,'Per Line'!$AN$2:$AN$7001,0)) | R2: =IF($Z2="","",Q2*P2) | S2: =IF($Z2="","",Settings!$C$6) | T2: =IF($Z2="","",SUMIFS('Per Line'!$V$2:$V$7001,'Per Line'!$D$2:$D$7001,$B2,'Per Line'!$AM$2:$AM$7001,1,'Per Line'!$AN$2:$AN$7001,0)) | U2: =IF($Z2="","",T2*S2) | V2: =IF($Z2="","",U2+R2) | W2: =IF($Z2="","",X2-V2) | X2: =IF($Z2="","",Q2+T2+O2) | Y2: =IF($Z2="","",X2-V2-K2) | Z2: =IF(ROWS($Z$2:$Z2)<=MAX('Per Line'!$AL$2:$AL$7001),MATCH(ROWS($Z$2:$Z2),'Per Line'!$AL$2:$AL$7001,0),"") | AA2: =IF($Z2="","",K2-J2*X2/100) | AB2: =IF($Z2="","",C2&"|"&COUNTIF($C$2:$C2,C2))
B3: =IF($Z3="","",INDEX('Per Line'!$D$2:$D$7001,$Z3)&"") | C3: =IF($Z3="","",IF(X3<Settings!$C$8,"INV<10000","Inv>10000")) | D3: =IF($Z3="","",INDEX('Per Line'!$A$2:$A$7001,$Z3)&"") | E3: =IF($Z3="","",INDEX('Per Line'!$F$2:$F$7001,$Z3)) | F3: =IF($Z3="","",INDEX('Per Line'!$G$2:$G$7001,$Z3)&"") | G3: =IF($Z3="","",INDEX('Per Line'!$I$2:$I$7001,$Z3)&"") | H3: =IF($Z3="","",INDEX('Per Line'!$J$2:$J$7001,$Z3)&"") | I3: =IF($Z3="","",INDEX('Per Line'!$K$2:$K$7001,$Z3)&"") | J3: =IF($Z3="","",INDEX('Per Line'!$M$2:$M$7001,$Z3)) | K3: =IF($Z3="","",IF(AND(ISNUMBER(M3),M3>0,X3>M3),J3*M3/100+(X3-M3),J3*X3/100)) | L3: =IF($Z3="","",INDEX('Per Line'!$W$2:$W$7001,$Z3)&"") | M3: =IF($Z3="","",INDEX('Per Line'!$AD$2:$AD$7001,$Z3)) | N3: =IF($Z3="","",IF(AND(ISNUMBER(M3),M3>0),X3>M3,FALSE)) | O3: =IF($Z3="","",SUMIFS('Per Line'!$V$2:$V$7001,'Per Line'!$D$2:$D$7001,$B3,'Per Line'!$AN$2:$AN$7001,1)) | P3: =IF($Z3="","",Settings!$C$7) | Q3: =IF($Z3="","",SUMIFS('Per Line'!$V$2:$V$7001,'Per Line'!$D$2:$D$7001,$B3,'Per Line'!$AM$2:$AM$7001,0,'Per Line'!$AN$2:$AN$7001,0)) | R3: =IF($Z3="","",Q3*P3) | S3: =IF($Z3="","",Settings!$C$6) | T3: =IF($Z3="","",SUMIFS('Per Line'!$V$2:$V$7001,'Per Line'!$D$2:$D$7001,$B3,'Per Line'!$AM$2:$AM$7001,1,'Per Line'!$AN$2:$AN$7001,0)) | U3: =IF($Z3="","",T3*S3) | V3: =IF($Z3="","",U3+R3) | W3: =IF($Z3="","",X3-V3) | X3: =IF($Z3="","",Q3+T3+O3) | Y3: =IF($Z3="","",X3-V3-K3) | Z3: =IF(ROWS($Z$2:$Z3)<=MAX('Per Line'!$AL$2:$AL$7001),MATCH(ROWS($Z$2:$Z3),'Per Line'!$AL$2:$AL$7001,0),"") | AA3: =IF($Z3="","",K3-J3*X3/100) | AB3: =IF($Z3="","",C3&"|"&COUNTIF($C$2:$C3,C3))
B4: =IF($Z4="","",INDEX('Per Line'!$D$2:$D$7001,$Z4)&"") | C4: =IF($Z4="","",IF(X4<Settings!$C$8,"INV<10000","Inv>10000")) | D4: =IF($Z4="","",INDEX('Per Line'!$A$2:$A$7001,$Z4)&"") | E4: =IF($Z4="","",INDEX('Per Line'!$F$2:$F$7001,$Z4)) | F4: =IF($Z4="","",INDEX('Per Line'!$G$2:$G$7001,$Z4)&"") | G4: =IF($Z4="","",INDEX('Per Line'!$I$2:$I$7001,$Z4)&"") | H4: =IF($Z4="","",INDEX('Per Line'!$J$2:$J$7001,$Z4)&"") | I4: =IF($Z4="","",INDEX('Per Line'!$K$2:$K$7001,$Z4)&"") | J4: =IF($Z4="","",INDEX('Per Line'!$M$2:$M$7001,$Z4)) | K4: =IF($Z4="","",IF(AND(ISNUMBER(M4),M4>0,X4>M4),J4*M4/100+(X4-M4),J4*X4/100)) | L4: =IF($Z4="","",INDEX('Per Line'!$W$2:$W$7001,$Z4)&"") | M4: =IF($Z4="","",INDEX('Per Line'!$AD$2:$AD$7001,$Z4)) | N4: =IF($Z4="","",IF(AND(ISNUMBER(M4),M4>0),X4>M4,FALSE)) | O4: =IF($Z4="","",SUMIFS('Per Line'!$V$2:$V$7001,'Per Line'!$D$2:$D$7001,$B4,'Per Line'!$AN$2:$AN$7001,1)) | P4: =IF($Z4="","",Settings!$C$7) | Q4: =IF($Z4="","",SUMIFS('Per Line'!$V$2:$V$7001,'Per Line'!$D$2:$D$7001,$B4,'Per Line'!$AM$2:$AM$7001,0,'Per Line'!$AN$2:$AN$7001,0)) | R4: =IF($Z4="","",Q4*P4) | S4: =IF($Z4="","",Settings!$C$6) | T4: =IF($Z4="","",SUMIFS('Per Line'!$V$2:$V$7001,'Per Line'!$D$2:$D$7001,$B4,'Per Line'!$AM$2:$AM$7001,1,'Per Line'!$AN$2:$AN$7001,0)) | U4: =IF($Z4="","",T4*S4) | V4: =IF($Z4="","",U4+R4) | W4: =IF($Z4="","",X4-V4) | X4: =IF($Z4="","",Q4+T4+O4) | Y4: =IF($Z4="","",X4-V4-K4) | Z4: =IF(ROWS($Z$2:$Z4)<=MAX('Per Line'!$AL$2:$AL$7001),MATCH(ROWS($Z$2:$Z4),'Per Line'!$AL$2:$AL$7001,0),"") | AA4: =IF($Z4="","",K4-J4*X4/100) | AB4: =IF($Z4="","",C4&"|"&COUNTIF($C$2:$C4,C4))
B5: =IF($Z5="","",INDEX('Per Line'!$D$2:$D$7001,$Z5)&"") | C5: =IF($Z5="","",IF(X5<Settings!$C$8,"INV<10000","Inv>10000")) | D5: =IF($Z5="","",INDEX('Per Line'!$A$2:$A$7001,$Z5)&"") | E5: =IF($Z5="","",INDEX('Per Line'!$F$2:$F$7001,$Z5)) | F5: =IF($Z5="","",INDEX('Per Line'!$G$2:$G$7001,$Z5)&"") | G5: =IF($Z5="","",INDEX('Per Line'!$I$2:$I$7001,$Z5)&"") | H5: =IF($Z5="","",INDEX('Per Line'!$J$2:$J$7001,$Z5)&"") | I5: =IF($Z5="","",INDEX('Per Line'!$K$2:$K$7001,$Z5)&"") | J5: =IF($Z5="","",INDEX('Per Line'!$M$2:$M$7001,$Z5)) | K5: =IF($Z5="","",IF(AND(ISNUMBER(M5),M5>0,X5>M5),J5*M5/100+(X5-M5),J5*X5/100)) | L5: =IF($Z5="","",INDEX('Per Line'!$W$2:$W$7001,$Z5)&"") | M5: =IF($Z5="","",INDEX('Per Line'!$AD$2:$AD$7001,$Z5)) | N5: =IF($Z5="","",IF(AND(ISNUMBER(M5),M5>0),X5>M5,FALSE)) | O5: =IF($Z5="","",SUMIFS('Per Line'!$V$2:$V$7001,'Per Line'!$D$2:$D$7001,$B5,'Per Line'!$AN$2:$AN$7001,1)) | P5: =IF($Z5="","",Settings!$C$7) | Q5: =IF($Z5="","",SUMIFS('Per Line'!$V$2:$V$7001,'Per Line'!$D$2:$D$7001,$B5,'Per Line'!$AM$2:$AM$7001,0,'Per Line'!$AN$2:$AN$7001,0)) | R5: =IF($Z5="","",Q5*P5) | S5: =IF($Z5="","",Settings!$C$6) | T5: =IF($Z5="","",SUMIFS('Per Line'!$V$2:$V$7001,'Per Line'!$D$2:$D$7001,$B5,'Per Line'!$AM$2:$AM$7001,1,'Per Line'!$AN$2:$AN$7001,0)) | U5: =IF($Z5="","",T5*S5) | V5: =IF($Z5="","",U5+R5) | W5: =IF($Z5="","",X5-V5) | X5: =IF($Z5="","",Q5+T5+O5) | Y5: =IF($Z5="","",X5-V5-K5) | Z5: =IF(ROWS($Z$2:$Z5)<=MAX('Per Line'!$AL$2:$AL$7001),MATCH(ROWS($Z$2:$Z5),'Per Line'!$AL$2:$AL$7001,0),"") | AA5: =IF($Z5="","",K5-J5*X5/100) | AB5: =IF($Z5="","",C5&"|"&COUNTIF($C$2:$C5,C5))
B6: =IF($Z6="","",INDEX('Per Line'!$D$2:$D$7001,$Z6)&"") | C6: =IF($Z6="","",IF(X6<Settings!$C$8,"INV<10000","Inv>10000")) | D6: =IF($Z6="","",INDEX('Per Line'!$A$2:$A$7001,$Z6)&"") | E6: =IF($Z6="","",INDEX('Per Line'!$F$2:$F$7001,$Z6)) | F6: =IF($Z6="","",INDEX('Per Line'!$G$2:$G$7001,$Z6)&"") | G6: =IF($Z6="","",INDEX('Per Line'!$I$2:$I$7001,$Z6)&"") | H6: =IF($Z6="","",INDEX('Per Line'!$J$2:$J$7001,$Z6)&"") | I6: =IF($Z6="","",INDEX('Per Line'!$K$2:$K$7001,$Z6)&"") | J6: =IF($Z6="","",INDEX('Per Line'!$M$2:$M$7001,$Z6)) | K6: =IF($Z6="","",IF(AND(ISNUMBER(M6),M6>0,X6>M6),J6*M6/100+(X6-M6),J6*X6/100)) | L6: =IF($Z6="","",INDEX('Per Line'!$W$2:$W$7001,$Z6)&"") | M6: =IF($Z6="","",INDEX('Per Line'!$AD$2:$AD$7001,$Z6)) | N6: =IF($Z6="","",IF(AND(ISNUMBER(M6),M6>0),X6>M6,FALSE)) | O6: =IF($Z6="","",SUMIFS('Per Line'!$V$2:$V$7001,'Per Line'!$D$2:$D$7001,$B6,'Per Line'!$AN$2:$AN$7001,1)) | P6: =IF($Z6="","",Settings!$C$7) | Q6: =IF($Z6="","",SUMIFS('Per Line'!$V$2:$V$7001,'Per Line'!$D$2:$D$7001,$B6,'Per Line'!$AM$2:$AM$7001,0,'Per Line'!$AN$2:$AN$7001,0)) | R6: =IF($Z6="","",Q6*P6) | S6: =IF($Z6="","",Settings!$C$6) | T6: =IF($Z6="","",SUMIFS('Per Line'!$V$2:$V$7001,'Per Line'!$D$2:$D$7001,$B6,'Per Line'!$AM$2:$AM$7001,1,'Per Line'!$AN$2:$AN$7001,0)) | U6: =IF($Z6="","",T6*S6) | V6: =IF($Z6="","",U6+R6) | W6: =IF($Z6="","",X6-V6) | X6: =IF($Z6="","",Q6+T6+O6) | Y6: =IF($Z6="","",X6-V6-K6) | Z6: =IF(ROWS($Z$2:$Z6)<=MAX('Per Line'!$AL$2:$AL$7001),MATCH(ROWS($Z$2:$Z6),'Per Line'!$AL$2:$AL$7001,0),"") | AA6: =IF($Z6="","",K6-J6*X6/100) | AB6: =IF($Z6="","",C6&"|"&COUNTIF($C$2:$C6,C6))
B7: =IF($Z7="","",INDEX('Per Line'!$D$2:$D$7001,$Z7)&"") | C7: =IF($Z7="","",IF(X7<Settings!$C$8,"INV<10000","Inv>10000")) | D7: =IF($Z7="","",INDEX('Per Line'!$A$2:$A$7001,$Z7)&"") | E7: =IF($Z7="","",INDEX('Per Line'!$F$2:$F$7001,$Z7)) | F7: =IF($Z7="","",INDEX('Per Line'!$G$2:$G$7001,$Z7)&"") | G7: =IF($Z7="","",INDEX('Per Line'!$I$2:$I$7001,$Z7)&"") | H7: =IF($Z7="","",INDEX('Per Line'!$J$2:$J$7001,$Z7)&"") | I7: =IF($Z7="","",INDEX('Per Line'!$K$2:$K$7001,$Z7)&"") | J7: =IF($Z7="","",INDEX('Per Line'!$M$2:$M$7001,$Z7)) | K7: =IF($Z7="","",IF(AND(ISNUMBER(M7),M7>0,X7>M7),J7*M7/100+(X7-M7),J7*X7/100)) | L7: =IF($Z7="","",INDEX('Per Line'!$W$2:$W$7001,$Z7)&"") | M7: =IF($Z7="","",INDEX('Per Line'!$AD$2:$AD$7001,$Z7)) | N7: =IF($Z7="","",IF(AND(ISNUMBER(M7),M7>0),X7>M7,FALSE)) | O7: =IF($Z7="","",SUMIFS('Per Line'!$V$2:$V$7001,'Per Line'!$D$2:$D$7001,$B7,'Per Line'!$AN$2:$AN$7001,1)) | P7: =IF($Z7="","",Settings!$C$7) | Q7: =IF($Z7="","",SUMIFS('Per Line'!$V$2:$V$7001,'Per Line'!$D$2:$D$7001,$B7,'Per Line'!$AM$2:$AM$7001,0,'Per Line'!$AN$2:$AN$7001,0)) | R7: =IF($Z7="","",Q7*P7) | S7: =IF($Z7="","",Settings!$C$6) | T7: =IF($Z7="","",SUMIFS('Per Line'!$V$2:$V$7001,'Per Line'!$D$2:$D$7001,$B7,'Per Line'!$AM$2:$AM$7001,1,'Per Line'!$AN$2:$AN$7001,0)) | U7: =IF($Z7="","",T7*S7) | V7: =IF($Z7="","",U7+R7) | W7: =IF($Z7="","",X7-V7) | X7: =IF($Z7="","",Q7+T7+O7) | Y7: =IF($Z7="","",X7-V7-K7) | Z7: =IF(ROWS($Z$2:$Z7)<=MAX('Per Line'!$AL$2:$AL$7001),MATCH(ROWS($Z$2:$Z7),'Per Line'!$AL$2:$AL$7001,0),"") | AA7: =IF($Z7="","",K7-J7*X7/100) | AB7: =IF($Z7="","",C7&"|"&COUNTIF($C$2:$C7,C7))
B8: =IF($Z8="","",INDEX('Per Line'!$D$2:$D$7001,$Z8)&"") | C8: =IF($Z8="","",IF(X8<Settings!$C$8,"INV<10000","Inv>10000")) | D8: =IF($Z8="","",INDEX('Per Line'!$A$2:$A$7001,$Z8)&"") | E8: =IF($Z8="","",INDEX('Per Line'!$F$2:$F$7001,$Z8)) | F8: =IF($Z8="","",INDEX('Per Line'!$G$2:$G$7001,$Z8)&"") | G8: =IF($Z8="","",INDEX('Per Line'!$I$2:$I$7001,$Z8)&"") | H8: =IF($Z8="","",INDEX('Per Line'!$J$2:$J$7001,$Z8)&"") | I8: =IF($Z8="","",INDEX('Per Line'!$K$2:$K$7001,$Z8)&"") | J8: =IF($Z8="","",INDEX('Per Line'!$M$2:$M$7001,$Z8)) | K8: =IF($Z8="","",IF(AND(ISNUMBER(M8),M8>0,X8>M8),J8*M8/100+(X8-M8),J8*X8/100)) | L8: =IF($Z8="","",INDEX('Per Line'!$W$2:$W$7001,$Z8)&"") | M8: =IF($Z8="","",INDEX('Per Line'!$AD$2:$AD$7001,$Z8)) | N8: =IF($Z8="","",IF(AND(ISNUMBER(M8),M8>0),X8>M8,FALSE)) | O8: =IF($Z8="","",SUMIFS('Per Line'!$V$2:$V$7001,'Per Line'!$D$2:$D$7001,$B8,'Per Line'!$AN$2:$AN$7001,1)) | P8: =IF($Z8="","",Settings!$C$7) | Q8: =IF($Z8="","",SUMIFS('Per Line'!$V$2:$V$7001,'Per Line'!$D$2:$D$7001,$B8,'Per Line'!$AM$2:$AM$7001,0,'Per Line'!$AN$2:$AN$7001,0)) | R8: =IF($Z8="","",Q8*P8) | S8: =IF($Z8="","",Settings!$C$6) | T8: =IF($Z8="","",SUMIFS('Per Line'!$V$2:$V$7001,'Per Line'!$D$2:$D$7001,$B8,'Per Line'!$AM$2:$AM$7001,1,'Per Line'!$AN$2:$AN$7001,0)) | U8: =IF($Z8="","",T8*S8) | V8: =IF($Z8="","",U8+R8) | W8: =IF($Z8="","",X8-V8) | X8: =IF($Z8="","",Q8+T8+O8) | Y8: =IF($Z8="","",X8-V8-K8) | Z8: =IF(ROWS($Z$2:$Z8)<=MAX('Per Line'!$AL$2:$AL$7001),MATCH(ROWS($Z$2:$Z8),'Per Line'!$AL$2:$AL$7001,0),"") | AA8: =IF($Z8="","",K8-J8*X8/100) | AB8: =IF($Z8="","",C8&"|"&COUNTIF($C$2:$C8,C8))
B9: =IF($Z9="","",INDEX('Per Line'!$D$2:$D$7001,$Z9)&"") | C9: =IF($Z9="","",IF(X9<Settings!$C$8,"INV<10000","Inv>10000")) | D9: =IF($Z9="","",INDEX('Per Line'!$A$2:$A$7001,$Z9)&"") | E9: =IF($Z9="","",INDEX('Per Line'!$F$2:$F$7001,$Z9)) | F9: =IF($Z9="","",INDEX('Per Line'!$G$2:$G$7001,$Z9)&"") | G9: =IF($Z9="","",INDEX('Per Line'!$I$2:$I$7001,$Z9)&"") | H9: =IF($Z9="","",INDEX('Per Line'!$J$2:$J$7001,$Z9)&"") | I9: =IF($Z9="","",INDEX('Per Line'!$K$2:$K$7001,$Z9)&"") | J9: =IF($Z9="","",INDEX('Per Line'!$M$2:$M$7001,$Z9)) | K9: =IF($Z9="","",IF(AND(ISNUMBER(M9),M9>0,X9>M9),J9*M9/100+(X9-M9),J9*X9/100)) | L9: =IF($Z9="","",INDEX('Per Line'!$W$2:$W$7001,$Z9)&"") | M9: =IF($Z9="","",INDEX('Per Line'!$AD$2:$AD$7001,$Z9)) | N9: =IF($Z9="","",IF(AND(ISNUMBER(M9),M9>0),X9>M9,FALSE)) | O9: =IF($Z9="","",SUMIFS('Per Line'!$V$2:$V$7001,'Per Line'!$D$2:$D$7001,$B9,'Per Line'!$AN$2:$AN$7001,1)) | P9: =IF($Z9="","",Settings!$C$7) | Q9: =IF($Z9="","",SUMIFS('Per Line'!$V$2:$V$7001,'Per Line'!$D$2:$D$7001,$B9,'Per Line'!$AM$2:$AM$7001,0,'Per Line'!$AN$2:$AN$7001,0)) | R9: =IF($Z9="","",Q9*P9) | S9: =IF($Z9="","",Settings!$C$6) | T9: =IF($Z9="","",SUMIFS('Per Line'!$V$2:$V$7001,'Per Line'!$D$2:$D$7001,$B9,'Per Line'!$AM$2:$AM$7001,1,'Per Line'!$AN$2:$AN$7001,0)) | U9: =IF($Z9="","",T9*S9) | V9: =IF($Z9="","",U9+R9) | W9: =IF($Z9="","",X9-V9) | X9: =IF($Z9="","",Q9+T9+O9) | Y9: =IF($Z9="","",X9-V9-K9) | Z9: =IF(ROWS($Z$2:$Z9)<=MAX('Per Line'!$AL$2:$AL$7001),MATCH(ROWS($Z$2:$Z9),'Per Line'!$AL$2:$AL$7001,0),"") | AA9: =IF($Z9="","",K9-J9*X9/100) | AB9: =IF($Z9="","",C9&"|"&COUNTIF($C$2:$C9,C9))
B10: =IF($Z10="","",INDEX('Per Line'!$D$2:$D$7001,$Z10)&"") | C10: =IF($Z10="","",IF(X10<Settings!$C$8,"INV<10000","Inv>10000")) | D10: =IF($Z10="","",INDEX('Per Line'!$A$2:$A$7001,$Z10)&"") | E10: =IF($Z10="","",INDEX('Per Line'!$F$2:$F$7001,$Z10)) | F10: =IF($Z10="","",INDEX('Per Line'!$G$2:$G$7001,$Z10)&"") | G10: =IF($Z10="","",INDEX('Per Line'!$I$2:$I$7001,$Z10)&"") | H10: =IF($Z10="","",INDEX('Per Line'!$J$2:$J$7001,$Z10)&"") | I10: =IF($Z10="","",INDEX('Per Line'!$K$2:$K$7001,$Z10)&"") | J10: =IF($Z10="","",INDEX('Per Line'!$M$2:$M$7001,$Z10)) | K10: =IF($Z10="","",IF(AND(ISNUMBER(M10),M10>0,X10>M10),J10*M10/100+(X10-M10),J10*X10/100)) | L10: =IF($Z10="","",INDEX('Per Line'!$W$2:$W$7001,$Z10)&"") | M10: =IF($Z10="","",INDEX('Per Line'!$AD$2:$AD$7001,$Z10)) | N10: =IF($Z10="","",IF(AND(ISNUMBER(M10),M10>0),X10>M10,FALSE)) | O10: =IF($Z10="","",SUMIFS('Per Line'!$V$2:$V$7001,'Per Line'!$D$2:$D$7001,$B10,'Per Line'!$AN$2:$AN$7001,1)) | P10: =IF($Z10="","",Settings!$C$7) | Q10: =IF($Z10="","",SUMIFS('Per Line'!$V$2:$V$7001,'Per Line'!$D$2:$D$7001,$B10,'Per Line'!$AM$2:$AM$7001,0,'Per Line'!$AN$2:$AN$7001,0)) | R10: =IF($Z10="","",Q10*P10) | S10: =IF($Z10="","",Settings!$C$6) | T10: =IF($Z10="","",SUMIFS('Per Line'!$V$2:$V$7001,'Per Line'!$D$2:$D$7001,$B10,'Per Line'!$AM$2:$AM$7001,1,'Per Line'!$AN$2:$AN$7001,0)) | U10: =IF($Z10="","",T10*S10) | V10: =IF($Z10="","",U10+R10) | W10: =IF($Z10="","",X10-V10) | X10: =IF($Z10="","",Q10+T10+O10) | Y10: =IF($Z10="","",X10-V10-K10) | Z10: =IF(ROWS($Z$2:$Z10)<=MAX('Per Line'!$AL$2:$AL$7001),MATCH(ROWS($Z$2:$Z10),'Per Line'!$AL$2:$AL$7001,0),"") | AA10: =IF($Z10="","",K10-J10*X10/100) | AB10: =IF($Z10="","",C10&"|"&COUNTIF($C$2:$C10,C10))
B11: =IF($Z11="","",INDEX('Per Line'!$D$2:$D$7001,$Z11)&"") | C11: =IF($Z11="","",IF(X11<Settings!$C$8,"INV<10000","Inv>10000")) | D11: =IF($Z11="","",INDEX('Per Line'!$A$2:$A$7001,$Z11)&"") | E11: =IF($Z11="","",INDEX('Per Line'!$F$2:$F$7001,$Z11)) | F11: =IF($Z11="","",INDEX('Per Line'!$G$2:$G$7001,$Z11)&"") | G11: =IF($Z11="","",INDEX('Per Line'!$I$2:$I$7001,$Z11)&"") | H11: =IF($Z11="","",INDEX('Per Line'!$J$2:$J$7001,$Z11)&"") | I11: =IF($Z11="","",INDEX('Per Line'!$K$2:$K$7001,$Z11)&"") | J11: =IF($Z11="","",INDEX('Per Line'!$M$2:$M$7001,$Z11)) | K11: =IF($Z11="","",IF(AND(ISNUMBER(M11),M11>0,X11>M11),J11*M11/100+(X11-M11),J11*X11/100)) | L11: =IF($Z11="","",INDEX('Per Line'!$W$2:$W$7001,$Z11)&"") | M11: =IF($Z11="","",INDEX('Per Line'!$AD$2:$AD$7001,$Z11)) | N11: =IF($Z11="","",IF(AND(ISNUMBER(M11),M11>0),X11>M11,FALSE)) | O11: =IF($Z11="","",SUMIFS('Per Line'!$V$2:$V$7001,'Per Line'!$D$2:$D$7001,$B11,'Per Line'!$AN$2:$AN$7001,1)) | P11: =IF($Z11="","",Settings!$C$7) | Q11: =IF($Z11="","",SUMIFS('Per Line'!$V$2:$V$7001,'Per Line'!$D$2:$D$7001,$B11,'Per Line'!$AM$2:$AM$7001,0,'Per Line'!$AN$2:$AN$7001,0)) | R11: =IF($Z11="","",Q11*P11) | S11: =IF($Z11="","",Settings!$C$6) | T11: =IF($Z11="","",SUMIFS('Per Line'!$V$2:$V$7001,'Per Line'!$D$2:$D$7001,$B11,'Per Line'!$AM$2:$AM$7001,1,'Per Line'!$AN$2:$AN$7001,0)) | U11: =IF($Z11="","",T11*S11) | V11: =IF($Z11="","",U11+R11) | W11: =IF($Z11="","",X11-V11) | X11: =IF($Z11="","",Q11+T11+O11) | Y11: =IF($Z11="","",X11-V11-K11) | Z11: =IF(ROWS($Z$2:$Z11)<=MAX('Per Line'!$AL$2:$AL$7001),MATCH(ROWS($Z$2:$Z11),'Per Line'!$AL$2:$AL$7001,0),"") | AA11: =IF($Z11="","",K11-J11*X11/100) | AB11: =IF($Z11="","",C11&"|"&COUNTIF($C$2:$C11,C11))
B12: =IF($Z12="","",INDEX('Per Line'!$D$2:$D$7001,$Z12)&"") | C12: =IF($Z12="","",IF(X12<Settings!$C$8,"INV<10000","Inv>10000")) | D12: =IF($Z12="","",INDEX('Per Line'!$A$2:$A$7001,$Z12)&"") | E12: =IF($Z12="","",INDEX('Per Line'!$F$2:$F$7001,$Z12)) | F12: =IF($Z12="","",INDEX('Per Line'!$G$2:$G$7001,$Z12)&"") | G12: =IF($Z12="","",INDEX('Per Line'!$I$2:$I$7001,$Z12)&"") | H12: =IF($Z12="","",INDEX('Per Line'!$J$2:$J$7001,$Z12)&"") | I12: =IF($Z12="","",INDEX('Per Line'!$K$2:$K$7001,$Z12)&"") | J12: =IF($Z12="","",INDEX('Per Line'!$M$2:$M$7001,$Z12)) | K12: =IF($Z12="","",IF(AND(ISNUMBER(M12),M12>0,X12>M12),J12*M12/100+(X12-M12),J12*X12/100)) | L12: =IF($Z12="","",INDEX('Per Line'!$W$2:$W$7001,$Z12)&"") | M12: =IF($Z12="","",INDEX('Per Line'!$AD$2:$AD$7001,$Z12)) | N12: =IF($Z12="","",IF(AND(ISNUMBER(M12),M12>0),X12>M12,FALSE)) | O12: =IF($Z12="","",SUMIFS('Per Line'!$V$2:$V$7001,'Per Line'!$D$2:$D$7001,$B12,'Per Line'!$AN$2:$AN$7001,1)) | P12: =IF($Z12="","",Settings!$C$7) | Q12: =IF($Z12="","",SUMIFS('Per Line'!$V$2:$V$7001,'Per Line'!$D$2:$D$7001,$B12,'Per Line'!$AM$2:$AM$7001,0,'Per Line'!$AN$2:$AN$7001,0)) | R12: =IF($Z12="","",Q12*P12) | S12: =IF($Z12="","",Settings!$C$6) | T12: =IF($Z12="","",SUMIFS('Per Line'!$V$2:$V$7001,'Per Line'!$D$2:$D$7001,$B12,'Per Line'!$AM$2:$AM$7001,1,'Per Line'!$AN$2:$AN$7001,0)) | U12: =IF($Z12="","",T12*S12) | V12: =IF($Z12="","",U12+R12) | W12: =IF($Z12="","",X12-V12) | X12: =IF($Z12="","",Q12+T12+O12) | Y12: =IF($Z12="","",X12-V12-K12) | Z12: =IF(ROWS($Z$2:$Z12)<=MAX('Per Line'!$AL$2:$AL$7001),MATCH(ROWS($Z$2:$Z12),'Per Line'!$AL$2:$AL$7001,0),"") | AA12: =IF($Z12="","",K12-J12*X12/100) | AB12: =IF($Z12="","",C12&"|"&COUNTIF($C$2:$C12,C12))
B13: =IF($Z13="","",INDEX('Per Line'!$D$2:$D$7001,$Z13)&"") | C13: =IF($Z13="","",IF(X13<Settings!$C$8,"INV<10000","Inv>10000")) | D13: =IF($Z13="","",INDEX('Per Line'!$A$2:$A$7001,$Z13)&"") | E13: =IF($Z13="","",INDEX('Per Line'!$F$2:$F$7001,$Z13)) | F13: =IF($Z13="","",INDEX('Per Line'!$G$2:$G$7001,$Z13)&"") | G13: =IF($Z13="","",INDEX('Per Line'!$I$2:$I$7001,$Z13)&"") | H13: =IF($Z13="","",INDEX('Per Line'!$J$2:$J$7001,$Z13)&"") | I13: =IF($Z13="","",INDEX('Per Line'!$K$2:$K$7001,$Z13)&"") | J13: =IF($Z13="","",INDEX('Per Line'!$M$2:$M$7001,$Z13)) | K13: =IF($Z13="","",IF(AND(ISNUMBER(M13),M13>0,X13>M13),J13*M13/100+(X13-M13),J13*X13/100)) | L13: =IF($Z13="","",INDEX('Per Line'!$W$2:$W$7001,$Z13)&"") | M13: =IF($Z13="","",INDEX('Per Line'!$AD$2:$AD$7001,$Z13)) | N13: =IF($Z13="","",IF(AND(ISNUMBER(M13),M13>0),X13>M13,FALSE)) | O13: =IF($Z13="","",SUMIFS('Per Line'!$V$2:$V$7001,'Per Line'!$D$2:$D$7001,$B13,'Per Line'!$AN$2:$AN$7001,1)) | P13: =IF($Z13="","",Settings!$C$7) | Q13: =IF($Z13="","",SUMIFS('Per Line'!$V$2:$V$7001,'Per Line'!$D$2:$D$7001,$B13,'Per Line'!$AM$2:$AM$7001,0,'Per Line'!$AN$2:$AN$7001,0)) | R13: =IF($Z13="","",Q13*P13) | S13: =IF($Z13="","",Settings!$C$6) | T13: =IF($Z13="","",SUMIFS('Per Line'!$V$2:$V$7001,'Per Line'!$D$2:$D$7001,$B13,'Per Line'!$AM$2:$AM$7001,1,'Per Line'!$AN$2:$AN$7001,0)) | U13: =IF($Z13="","",T13*S13) | V13: =IF($Z13="","",U13+R13) | W13: =IF($Z13="","",X13-V13) | X13: =IF($Z13="","",Q13+T13+O13) | Y13: =IF($Z13="","",X13-V13-K13) | Z13: =IF(ROWS($Z$2:$Z13)<=MAX('Per Line'!$AL$2:$AL$7001),MATCH(ROWS($Z$2:$Z13),'Per Line'!$AL$2:$AL$7001,0),"") | AA13: =IF($Z13="","",K13-J13*X13/100) | AB13: =IF($Z13="","",C13&"|"&COUNTIF($C$2:$C13,C13))
... B1201: =IF($Z1201="","",INDEX('Per Line'!$D$2:$D$7001,$Z1201)&"") | C1201: =IF($Z1201="","",IF(X1201<Settings!$C$8,"INV<10000","Inv>10000")) | D1201: =IF($Z1201="","",INDEX('Per Line'!$A$2:$A$7001,$Z1201)&"") | E1201: =IF($Z1201="","",INDEX('Per Line'!$F$2:$F$7001,$Z1201)) | F1201: =IF($Z1201="","",INDEX('Per Line'!$G$2:$G$7001,$Z1201)&"") | G1201: =IF($Z1201="","",INDEX('Per Line'!$I$2:$I$7001,$Z1201)&"") | H1201: =IF($Z1201="","",INDEX('Per Line'!$J$2:$J$7001,$Z1201)&"") | I1201: =IF($Z1201="","",INDEX('Per Line'!$K$2:$K$7001,$Z1201)&"") | J1201: =IF($Z1201="","",INDEX('Per Line'!$M$2:$M$7001,$Z1201)) | K1201: =IF($Z1201="","",IF(AND(ISNUMBER(M1201),M1201>0,X1201>M1201),J1201*M1201/100+(X1201-M1201),J1201*X1201/100)) | L1201: =IF($Z1201="","",INDEX('Per Line'!$W$2:$W$7001,$Z1201)&"") | M1201: =IF($Z1201="","",INDEX('Per Line'!$AD$2:$AD$7001,$Z1201)) | N1201: =IF($Z1201="","",IF(AND(ISNUMBER(M1201),M1201>0),X1201>M1201,FALSE)) | O1201: =IF($Z1201="","",SUMIFS('Per Line'!$V$2:$V$7001,'Per Line'!$D$2:$D$7001,$B1201,'Per Line'!$AN$2:$AN$7001,1)) | P1201: =IF($Z1201="","",Settings!$C$7) | Q1201: =IF($Z1201="","",SUMIFS('Per Line'!$V$2:$V$7001,'Per Line'!$D$2:$D$7001,$B1201,'Per Line'!$AM$2:$AM$7001,0,'Per Line'!$AN$2:$AN$7001,0)) | R1201: =IF($Z1201="","",Q1201*P1201) | S1201: =IF($Z1201="","",Settings!$C$6) | T1201: =IF($Z1201="","",SUMIFS('Per Line'!$V$2:$V$7001,'Per Line'!$D$2:$D$7001,$B1201,'Per Line'!$AM$2:$AM$7001,1,'Per Line'!$AN$2:$AN$7001,0)) | U1201: =IF($Z1201="","",T1201*S1201) | V1201: =IF($Z1201="","",U1201+R1201) | W1201: =IF($Z1201="","",X1201-V1201) | X1201: =IF($Z1201="","",Q1201+T1201+O1201) | Y1201: =IF($Z1201="","",X1201-V1201-K1201) | Z1201: =IF(ROWS($Z$2:$Z1201)<=MAX('Per Line'!$AL$2:$AL$7001),MATCH(ROWS($Z$2:$Z1201),'Per Line'!$AL$2:$AL$7001,0),"") | AA1201: =IF($Z1201="","",K1201-J1201*X1201/100) | AB1201: =IF($Z1201="","",C1201&"|"&COUNTIF($C$2:$C1201,C1201))

Sheet INV<10000
A1: Invoice | B1: Order # | C1: Site Tab (##) | D1: Cycle | E1: Create At | F1: Insurance Company | G1: Corporate | H1: Card | I1: Name | J1: Order Co Payment | K1: Co val | L1: ERX ID | M1: Max Limit | N1: Exceeding Limit | O1: Special | P1: IMP % | Q1: IMP | R1: IMP VAL | S1: LOCAL % | T1: LOCAL | U1: LOCAL VAL | V1: TOTAL VAL | W1: SUBTOTAL | X1: Grand Total | Y1: NET | Z1: Src Row (helper)
A2: =IF($Z2="","",IF(INDEX('Per Invoice'!A$2:A$1201,$Z2)="","",INDEX('Per Invoice'!A$2:A$1201,$Z2))) | B2: =IF($Z2="","",IF(INDEX('Per Invoice'!B$2:B$1201,$Z2)="","",INDEX('Per Invoice'!B$2:B$1201,$Z2))) | C2: =IF($Z2="","",IF(INDEX('Per Invoice'!C$2:C$1201,$Z2)="","",INDEX('Per Invoice'!C$2:C$1201,$Z2))) | D2: =IF($Z2="","",IF(INDEX('Per Invoice'!D$2:D$1201,$Z2)="","",INDEX('Per Invoice'!D$2:D$1201,$Z2))) | E2: =IF($Z2="","",IF(INDEX('Per Invoice'!E$2:E$1201,$Z2)="","",INDEX('Per Invoice'!E$2:E$1201,$Z2))) | F2: =IF($Z2="","",IF(INDEX('Per Invoice'!F$2:F$1201,$Z2)="","",INDEX('Per Invoice'!F$2:F$1201,$Z2))) | G2: =IF($Z2="","",IF(INDEX('Per Invoice'!G$2:G$1201,$Z2)="","",INDEX('Per Invoice'!G$2:G$1201,$Z2))) | H2: =IF($Z2="","",IF(INDEX('Per Invoice'!H$2:H$1201,$Z2)="","",INDEX('Per Invoice'!H$2:H$1201,$Z2))) | ... Y2: =IF($Z2="","",IF(INDEX('Per Invoice'!Y$2:Y$1201,$Z2)="","",INDEX('Per Invoice'!Y$2:Y$1201,$Z2))) | Z2: =IFERROR(MATCH(Settings!$C$26&"|"&ROWS($Z$2:$Z2),'Per Invoice'!$AB$2:$AB$1201,0),"")
A3: =IF($Z3="","",IF(INDEX('Per Invoice'!A$2:A$1201,$Z3)="","",INDEX('Per Invoice'!A$2:A$1201,$Z3))) | B3: =IF($Z3="","",IF(INDEX('Per Invoice'!B$2:B$1201,$Z3)="","",INDEX('Per Invoice'!B$2:B$1201,$Z3))) | C3: =IF($Z3="","",IF(INDEX('Per Invoice'!C$2:C$1201,$Z3)="","",INDEX('Per Invoice'!C$2:C$1201,$Z3))) | D3: =IF($Z3="","",IF(INDEX('Per Invoice'!D$2:D$1201,$Z3)="","",INDEX('Per Invoice'!D$2:D$1201,$Z3))) | E3: =IF($Z3="","",IF(INDEX('Per Invoice'!E$2:E$1201,$Z3)="","",INDEX('Per Invoice'!E$2:E$1201,$Z3))) | F3: =IF($Z3="","",IF(INDEX('Per Invoice'!F$2:F$1201,$Z3)="","",INDEX('Per Invoice'!F$2:F$1201,$Z3))) | G3: =IF($Z3="","",IF(INDEX('Per Invoice'!G$2:G$1201,$Z3)="","",INDEX('Per Invoice'!G$2:G$1201,$Z3))) | H3: =IF($Z3="","",IF(INDEX('Per Invoice'!H$2:H$1201,$Z3)="","",INDEX('Per Invoice'!H$2:H$1201,$Z3))) | ... Y3: =IF($Z3="","",IF(INDEX('Per Invoice'!Y$2:Y$1201,$Z3)="","",INDEX('Per Invoice'!Y$2:Y$1201,$Z3))) | Z3: =IFERROR(MATCH(Settings!$C$26&"|"&ROWS($Z$2:$Z3),'Per Invoice'!$AB$2:$AB$1201,0),"")
A4: =IF($Z4="","",IF(INDEX('Per Invoice'!A$2:A$1201,$Z4)="","",INDEX('Per Invoice'!A$2:A$1201,$Z4))) | B4: =IF($Z4="","",IF(INDEX('Per Invoice'!B$2:B$1201,$Z4)="","",INDEX('Per Invoice'!B$2:B$1201,$Z4))) | C4: =IF($Z4="","",IF(INDEX('Per Invoice'!C$2:C$1201,$Z4)="","",INDEX('Per Invoice'!C$2:C$1201,$Z4))) | D4: =IF($Z4="","",IF(INDEX('Per Invoice'!D$2:D$1201,$Z4)="","",INDEX('Per Invoice'!D$2:D$1201,$Z4))) | E4: =IF($Z4="","",IF(INDEX('Per Invoice'!E$2:E$1201,$Z4)="","",INDEX('Per Invoice'!E$2:E$1201,$Z4))) | F4: =IF($Z4="","",IF(INDEX('Per Invoice'!F$2:F$1201,$Z4)="","",INDEX('Per Invoice'!F$2:F$1201,$Z4))) | G4: =IF($Z4="","",IF(INDEX('Per Invoice'!G$2:G$1201,$Z4)="","",INDEX('Per Invoice'!G$2:G$1201,$Z4))) | H4: =IF($Z4="","",IF(INDEX('Per Invoice'!H$2:H$1201,$Z4)="","",INDEX('Per Invoice'!H$2:H$1201,$Z4))) | ... Y4: =IF($Z4="","",IF(INDEX('Per Invoice'!Y$2:Y$1201,$Z4)="","",INDEX('Per Invoice'!Y$2:Y$1201,$Z4))) | Z4: =IFERROR(MATCH(Settings!$C$26&"|"&ROWS($Z$2:$Z4),'Per Invoice'!$AB$2:$AB$1201,0),"")
A5: =IF($Z5="","",IF(INDEX('Per Invoice'!A$2:A$1201,$Z5)="","",INDEX('Per Invoice'!A$2:A$1201,$Z5))) | B5: =IF($Z5="","",IF(INDEX('Per Invoice'!B$2:B$1201,$Z5)="","",INDEX('Per Invoice'!B$2:B$1201,$Z5))) | C5: =IF($Z5="","",IF(INDEX('Per Invoice'!C$2:C$1201,$Z5)="","",INDEX('Per Invoice'!C$2:C$1201,$Z5))) | D5: =IF($Z5="","",IF(INDEX('Per Invoice'!D$2:D$1201,$Z5)="","",INDEX('Per Invoice'!D$2:D$1201,$Z5))) | E5: =IF($Z5="","",IF(INDEX('Per Invoice'!E$2:E$1201,$Z5)="","",INDEX('Per Invoice'!E$2:E$1201,$Z5))) | F5: =IF($Z5="","",IF(INDEX('Per Invoice'!F$2:F$1201,$Z5)="","",INDEX('Per Invoice'!F$2:F$1201,$Z5))) | G5: =IF($Z5="","",IF(INDEX('Per Invoice'!G$2:G$1201,$Z5)="","",INDEX('Per Invoice'!G$2:G$1201,$Z5))) | H5: =IF($Z5="","",IF(INDEX('Per Invoice'!H$2:H$1201,$Z5)="","",INDEX('Per Invoice'!H$2:H$1201,$Z5))) | ... Y5: =IF($Z5="","",IF(INDEX('Per Invoice'!Y$2:Y$1201,$Z5)="","",INDEX('Per Invoice'!Y$2:Y$1201,$Z5))) | Z5: =IFERROR(MATCH(Settings!$C$26&"|"&ROWS($Z$2:$Z5),'Per Invoice'!$AB$2:$AB$1201,0),"")
A6: =IF($Z6="","",IF(INDEX('Per Invoice'!A$2:A$1201,$Z6)="","",INDEX('Per Invoice'!A$2:A$1201,$Z6))) | B6: =IF($Z6="","",IF(INDEX('Per Invoice'!B$2:B$1201,$Z6)="","",INDEX('Per Invoice'!B$2:B$1201,$Z6))) | C6: =IF($Z6="","",IF(INDEX('Per Invoice'!C$2:C$1201,$Z6)="","",INDEX('Per Invoice'!C$2:C$1201,$Z6))) | D6: =IF($Z6="","",IF(INDEX('Per Invoice'!D$2:D$1201,$Z6)="","",INDEX('Per Invoice'!D$2:D$1201,$Z6))) | E6: =IF($Z6="","",IF(INDEX('Per Invoice'!E$2:E$1201,$Z6)="","",INDEX('Per Invoice'!E$2:E$1201,$Z6))) | F6: =IF($Z6="","",IF(INDEX('Per Invoice'!F$2:F$1201,$Z6)="","",INDEX('Per Invoice'!F$2:F$1201,$Z6))) | G6: =IF($Z6="","",IF(INDEX('Per Invoice'!G$2:G$1201,$Z6)="","",INDEX('Per Invoice'!G$2:G$1201,$Z6))) | H6: =IF($Z6="","",IF(INDEX('Per Invoice'!H$2:H$1201,$Z6)="","",INDEX('Per Invoice'!H$2:H$1201,$Z6))) | ... Y6: =IF($Z6="","",IF(INDEX('Per Invoice'!Y$2:Y$1201,$Z6)="","",INDEX('Per Invoice'!Y$2:Y$1201,$Z6))) | Z6: =IFERROR(MATCH(Settings!$C$26&"|"&ROWS($Z$2:$Z6),'Per Invoice'!$AB$2:$AB$1201,0),"")
A7: =IF($Z7="","",IF(INDEX('Per Invoice'!A$2:A$1201,$Z7)="","",INDEX('Per Invoice'!A$2:A$1201,$Z7))) | B7: =IF($Z7="","",IF(INDEX('Per Invoice'!B$2:B$1201,$Z7)="","",INDEX('Per Invoice'!B$2:B$1201,$Z7))) | C7: =IF($Z7="","",IF(INDEX('Per Invoice'!C$2:C$1201,$Z7)="","",INDEX('Per Invoice'!C$2:C$1201,$Z7))) | D7: =IF($Z7="","",IF(INDEX('Per Invoice'!D$2:D$1201,$Z7)="","",INDEX('Per Invoice'!D$2:D$1201,$Z7))) | E7: =IF($Z7="","",IF(INDEX('Per Invoice'!E$2:E$1201,$Z7)="","",INDEX('Per Invoice'!E$2:E$1201,$Z7))) | F7: =IF($Z7="","",IF(INDEX('Per Invoice'!F$2:F$1201,$Z7)="","",INDEX('Per Invoice'!F$2:F$1201,$Z7))) | G7: =IF($Z7="","",IF(INDEX('Per Invoice'!G$2:G$1201,$Z7)="","",INDEX('Per Invoice'!G$2:G$1201,$Z7))) | H7: =IF($Z7="","",IF(INDEX('Per Invoice'!H$2:H$1201,$Z7)="","",INDEX('Per Invoice'!H$2:H$1201,$Z7))) | ... Y7: =IF($Z7="","",IF(INDEX('Per Invoice'!Y$2:Y$1201,$Z7)="","",INDEX('Per Invoice'!Y$2:Y$1201,$Z7))) | Z7: =IFERROR(MATCH(Settings!$C$26&"|"&ROWS($Z$2:$Z7),'Per Invoice'!$AB$2:$AB$1201,0),"")
A8: =IF($Z8="","",IF(INDEX('Per Invoice'!A$2:A$1201,$Z8)="","",INDEX('Per Invoice'!A$2:A$1201,$Z8))) | B8: =IF($Z8="","",IF(INDEX('Per Invoice'!B$2:B$1201,$Z8)="","",INDEX('Per Invoice'!B$2:B$1201,$Z8))) | C8: =IF($Z8="","",IF(INDEX('Per Invoice'!C$2:C$1201,$Z8)="","",INDEX('Per Invoice'!C$2:C$1201,$Z8))) | D8: =IF($Z8="","",IF(INDEX('Per Invoice'!D$2:D$1201,$Z8)="","",INDEX('Per Invoice'!D$2:D$1201,$Z8))) | E8: =IF($Z8="","",IF(INDEX('Per Invoice'!E$2:E$1201,$Z8)="","",INDEX('Per Invoice'!E$2:E$1201,$Z8))) | F8: =IF($Z8="","",IF(INDEX('Per Invoice'!F$2:F$1201,$Z8)="","",INDEX('Per Invoice'!F$2:F$1201,$Z8))) | G8: =IF($Z8="","",IF(INDEX('Per Invoice'!G$2:G$1201,$Z8)="","",INDEX('Per Invoice'!G$2:G$1201,$Z8))) | H8: =IF($Z8="","",IF(INDEX('Per Invoice'!H$2:H$1201,$Z8)="","",INDEX('Per Invoice'!H$2:H$1201,$Z8))) | ... Y8: =IF($Z8="","",IF(INDEX('Per Invoice'!Y$2:Y$1201,$Z8)="","",INDEX('Per Invoice'!Y$2:Y$1201,$Z8))) | Z8: =IFERROR(MATCH(Settings!$C$26&"|"&ROWS($Z$2:$Z8),'Per Invoice'!$AB$2:$AB$1201,0),"")
A9: =IF($Z9="","",IF(INDEX('Per Invoice'!A$2:A$1201,$Z9)="","",INDEX('Per Invoice'!A$2:A$1201,$Z9))) | B9: =IF($Z9="","",IF(INDEX('Per Invoice'!B$2:B$1201,$Z9)="","",INDEX('Per Invoice'!B$2:B$1201,$Z9))) | C9: =IF($Z9="","",IF(INDEX('Per Invoice'!C$2:C$1201,$Z9)="","",INDEX('Per Invoice'!C$2:C$1201,$Z9))) | D9: =IF($Z9="","",IF(INDEX('Per Invoice'!D$2:D$1201,$Z9)="","",INDEX('Per Invoice'!D$2:D$1201,$Z9))) | E9: =IF($Z9="","",IF(INDEX('Per Invoice'!E$2:E$1201,$Z9)="","",INDEX('Per Invoice'!E$2:E$1201,$Z9))) | F9: =IF($Z9="","",IF(INDEX('Per Invoice'!F$2:F$1201,$Z9)="","",INDEX('Per Invoice'!F$2:F$1201,$Z9))) | G9: =IF($Z9="","",IF(INDEX('Per Invoice'!G$2:G$1201,$Z9)="","",INDEX('Per Invoice'!G$2:G$1201,$Z9))) | H9: =IF($Z9="","",IF(INDEX('Per Invoice'!H$2:H$1201,$Z9)="","",INDEX('Per Invoice'!H$2:H$1201,$Z9))) | ... Y9: =IF($Z9="","",IF(INDEX('Per Invoice'!Y$2:Y$1201,$Z9)="","",INDEX('Per Invoice'!Y$2:Y$1201,$Z9))) | Z9: =IFERROR(MATCH(Settings!$C$26&"|"&ROWS($Z$2:$Z9),'Per Invoice'!$AB$2:$AB$1201,0),"")
A10: =IF($Z10="","",IF(INDEX('Per Invoice'!A$2:A$1201,$Z10)="","",INDEX('Per Invoice'!A$2:A$1201,$Z10))) | B10: =IF($Z10="","",IF(INDEX('Per Invoice'!B$2:B$1201,$Z10)="","",INDEX('Per Invoice'!B$2:B$1201,$Z10))) | C10: =IF($Z10="","",IF(INDEX('Per Invoice'!C$2:C$1201,$Z10)="","",INDEX('Per Invoice'!C$2:C$1201,$Z10))) | D10: =IF($Z10="","",IF(INDEX('Per Invoice'!D$2:D$1201,$Z10)="","",INDEX('Per Invoice'!D$2:D$1201,$Z10))) | E10: =IF($Z10="","",IF(INDEX('Per Invoice'!E$2:E$1201,$Z10)="","",INDEX('Per Invoice'!E$2:E$1201,$Z10))) | F10: =IF($Z10="","",IF(INDEX('Per Invoice'!F$2:F$1201,$Z10)="","",INDEX('Per Invoice'!F$2:F$1201,$Z10))) | G10: =IF($Z10="","",IF(INDEX('Per Invoice'!G$2:G$1201,$Z10)="","",INDEX('Per Invoice'!G$2:G$1201,$Z10))) | H10: =IF($Z10="","",IF(INDEX('Per Invoice'!H$2:H$1201,$Z10)="","",INDEX('Per Invoice'!H$2:H$1201,$Z10))) | ... Y10: =IF($Z10="","",IF(INDEX('Per Invoice'!Y$2:Y$1201,$Z10)="","",INDEX('Per Invoice'!Y$2:Y$1201,$Z10))) | Z10: =IFERROR(MATCH(Settings!$C$26&"|"&ROWS($Z$2:$Z10),'Per Invoice'!$AB$2:$AB$1201,0),"")
A11: =IF($Z11="","",IF(INDEX('Per Invoice'!A$2:A$1201,$Z11)="","",INDEX('Per Invoice'!A$2:A$1201,$Z11))) | B11: =IF($Z11="","",IF(INDEX('Per Invoice'!B$2:B$1201,$Z11)="","",INDEX('Per Invoice'!B$2:B$1201,$Z11))) | C11: =IF($Z11="","",IF(INDEX('Per Invoice'!C$2:C$1201,$Z11)="","",INDEX('Per Invoice'!C$2:C$1201,$Z11))) | D11: =IF($Z11="","",IF(INDEX('Per Invoice'!D$2:D$1201,$Z11)="","",INDEX('Per Invoice'!D$2:D$1201,$Z11))) | E11: =IF($Z11="","",IF(INDEX('Per Invoice'!E$2:E$1201,$Z11)="","",INDEX('Per Invoice'!E$2:E$1201,$Z11))) | F11: =IF($Z11="","",IF(INDEX('Per Invoice'!F$2:F$1201,$Z11)="","",INDEX('Per Invoice'!F$2:F$1201,$Z11))) | G11: =IF($Z11="","",IF(INDEX('Per Invoice'!G$2:G$1201,$Z11)="","",INDEX('Per Invoice'!G$2:G$1201,$Z11))) | H11: =IF($Z11="","",IF(INDEX('Per Invoice'!H$2:H$1201,$Z11)="","",INDEX('Per Invoice'!H$2:H$1201,$Z11))) | ... Y11: =IF($Z11="","",IF(INDEX('Per Invoice'!Y$2:Y$1201,$Z11)="","",INDEX('Per Invoice'!Y$2:Y$1201,$Z11))) | Z11: =IFERROR(MATCH(Settings!$C$26&"|"&ROWS($Z$2:$Z11),'Per Invoice'!$AB$2:$AB$1201,0),"")
A12: =IF($Z12="","",IF(INDEX('Per Invoice'!A$2:A$1201,$Z12)="","",INDEX('Per Invoice'!A$2:A$1201,$Z12))) | B12: =IF($Z12="","",IF(INDEX('Per Invoice'!B$2:B$1201,$Z12)="","",INDEX('Per Invoice'!B$2:B$1201,$Z12))) | C12: =IF($Z12="","",IF(INDEX('Per Invoice'!C$2:C$1201,$Z12)="","",INDEX('Per Invoice'!C$2:C$1201,$Z12))) | D12: =IF($Z12="","",IF(INDEX('Per Invoice'!D$2:D$1201,$Z12)="","",INDEX('Per Invoice'!D$2:D$1201,$Z12))) | E12: =IF($Z12="","",IF(INDEX('Per Invoice'!E$2:E$1201,$Z12)="","",INDEX('Per Invoice'!E$2:E$1201,$Z12))) | F12: =IF($Z12="","",IF(INDEX('Per Invoice'!F$2:F$1201,$Z12)="","",INDEX('Per Invoice'!F$2:F$1201,$Z12))) | G12: =IF($Z12="","",IF(INDEX('Per Invoice'!G$2:G$1201,$Z12)="","",INDEX('Per Invoice'!G$2:G$1201,$Z12))) | H12: =IF($Z12="","",IF(INDEX('Per Invoice'!H$2:H$1201,$Z12)="","",INDEX('Per Invoice'!H$2:H$1201,$Z12))) | ... Y12: =IF($Z12="","",IF(INDEX('Per Invoice'!Y$2:Y$1201,$Z12)="","",INDEX('Per Invoice'!Y$2:Y$1201,$Z12))) | Z12: =IFERROR(MATCH(Settings!$C$26&"|"&ROWS($Z$2:$Z12),'Per Invoice'!$AB$2:$AB$1201,0),"")
A13: =IF($Z13="","",IF(INDEX('Per Invoice'!A$2:A$1201,$Z13)="","",INDEX('Per Invoice'!A$2:A$1201,$Z13))) | B13: =IF($Z13="","",IF(INDEX('Per Invoice'!B$2:B$1201,$Z13)="","",INDEX('Per Invoice'!B$2:B$1201,$Z13))) | C13: =IF($Z13="","",IF(INDEX('Per Invoice'!C$2:C$1201,$Z13)="","",INDEX('Per Invoice'!C$2:C$1201,$Z13))) | D13: =IF($Z13="","",IF(INDEX('Per Invoice'!D$2:D$1201,$Z13)="","",INDEX('Per Invoice'!D$2:D$1201,$Z13))) | E13: =IF($Z13="","",IF(INDEX('Per Invoice'!E$2:E$1201,$Z13)="","",INDEX('Per Invoice'!E$2:E$1201,$Z13))) | F13: =IF($Z13="","",IF(INDEX('Per Invoice'!F$2:F$1201,$Z13)="","",INDEX('Per Invoice'!F$2:F$1201,$Z13))) | G13: =IF($Z13="","",IF(INDEX('Per Invoice'!G$2:G$1201,$Z13)="","",INDEX('Per Invoice'!G$2:G$1201,$Z13))) | H13: =IF($Z13="","",IF(INDEX('Per Invoice'!H$2:H$1201,$Z13)="","",INDEX('Per Invoice'!H$2:H$1201,$Z13))) | ... Y13: =IF($Z13="","",IF(INDEX('Per Invoice'!Y$2:Y$1201,$Z13)="","",INDEX('Per Invoice'!Y$2:Y$1201,$Z13))) | Z13: =IFERROR(MATCH(Settings!$C$26&"|"&ROWS($Z$2:$Z13),'Per Invoice'!$AB$2:$AB$1201,0),"")
... A1001: =IF($Z1001="","",IF(INDEX('Per Invoice'!A$2:A$1201,$Z1001)="","",INDEX('Per Invoice'!A$2:A$1201,$Z1001))) | B1001: =IF($Z1001="","",IF(INDEX('Per Invoice'!B$2:B$1201,$Z1001)="","",INDEX('Per Invoice'!B$2:B$1201,$Z1001))) | C1001: =IF($Z1001="","",IF(INDEX('Per Invoice'!C$2:C$1201,$Z1001)="","",INDEX('Per Invoice'!C$2:C$1201,$Z1001))) | D1001: =IF($Z1001="","",IF(INDEX('Per Invoice'!D$2:D$1201,$Z1001)="","",INDEX('Per Invoice'!D$2:D$1201,$Z1001))) | E1001: =IF($Z1001="","",IF(INDEX('Per Invoice'!E$2:E$1201,$Z1001)="","",INDEX('Per Invoice'!E$2:E$1201,$Z1001))) | F1001: =IF($Z1001="","",IF(INDEX('Per Invoice'!F$2:F$1201,$Z1001)="","",INDEX('Per Invoice'!F$2:F$1201,$Z1001))) | G1001: =IF($Z1001="","",IF(INDEX('Per Invoice'!G$2:G$1201,$Z1001)="","",INDEX('Per Invoice'!G$2:G$1201,$Z1001))) | H1001: =IF($Z1001="","",IF(INDEX('Per Invoice'!H$2:H$1201,$Z1001)="","",INDEX('Per Invoice'!H$2:H$1201,$Z1001))) | ... Y1001: =IF($Z1001="","",IF(INDEX('Per Invoice'!Y$2:Y$1201,$Z1001)="","",INDEX('Per Invoice'!Y$2:Y$1201,$Z1001))) | Z1001: =IFERROR(MATCH(Settings!$C$26&"|"&ROWS($Z$2:$Z1001),'Per Invoice'!$AB$2:$AB$1201,0),"")

Sheet Inv>10000
A1: Invoice | B1: Order # | C1: Site Tab (##) | D1: Cycle | E1: Create At | F1: Insurance Company | G1: Corporate | H1: Card | I1: Name | J1: Order Co Payment | K1: Co val | L1: ERX ID | M1: Max Limit | N1: Exceeding Limit | O1: Special | P1: IMP % | Q1: IMP | R1: IMP VAL | S1: LOCAL % | T1: LOCAL | U1: LOCAL VAL | V1: TOTAL VAL | W1: SUBTOTAL | X1: Grand Total | Y1: NET | Z1: Src Row (helper)
A2: =IF($Z2="","",IF(INDEX('Per Invoice'!A$2:A$1201,$Z2)="","",INDEX('Per Invoice'!A$2:A$1201,$Z2))) | B2: =IF($Z2="","",IF(INDEX('Per Invoice'!B$2:B$1201,$Z2)="","",INDEX('Per Invoice'!B$2:B$1201,$Z2))) | C2: =IF($Z2="","",IF(INDEX('Per Invoice'!C$2:C$1201,$Z2)="","",INDEX('Per Invoice'!C$2:C$1201,$Z2))) | D2: =IF($Z2="","",IF(INDEX('Per Invoice'!D$2:D$1201,$Z2)="","",INDEX('Per Invoice'!D$2:D$1201,$Z2))) | E2: =IF($Z2="","",IF(INDEX('Per Invoice'!E$2:E$1201,$Z2)="","",INDEX('Per Invoice'!E$2:E$1201,$Z2))) | F2: =IF($Z2="","",IF(INDEX('Per Invoice'!F$2:F$1201,$Z2)="","",INDEX('Per Invoice'!F$2:F$1201,$Z2))) | G2: =IF($Z2="","",IF(INDEX('Per Invoice'!G$2:G$1201,$Z2)="","",INDEX('Per Invoice'!G$2:G$1201,$Z2))) | H2: =IF($Z2="","",IF(INDEX('Per Invoice'!H$2:H$1201,$Z2)="","",INDEX('Per Invoice'!H$2:H$1201,$Z2))) | ... Y2: =IF($Z2="","",IF(INDEX('Per Invoice'!Y$2:Y$1201,$Z2)="","",INDEX('Per Invoice'!Y$2:Y$1201,$Z2))) | Z2: =IFERROR(MATCH(Settings!$C$27&"|"&ROWS($Z$2:$Z2),'Per Invoice'!$AB$2:$AB$1201,0),"")
A3: =IF($Z3="","",IF(INDEX('Per Invoice'!A$2:A$1201,$Z3)="","",INDEX('Per Invoice'!A$2:A$1201,$Z3))) | B3: =IF($Z3="","",IF(INDEX('Per Invoice'!B$2:B$1201,$Z3)="","",INDEX('Per Invoice'!B$2:B$1201,$Z3))) | C3: =IF($Z3="","",IF(INDEX('Per Invoice'!C$2:C$1201,$Z3)="","",INDEX('Per Invoice'!C$2:C$1201,$Z3))) | D3: =IF($Z3="","",IF(INDEX('Per Invoice'!D$2:D$1201,$Z3)="","",INDEX('Per Invoice'!D$2:D$1201,$Z3))) | E3: =IF($Z3="","",IF(INDEX('Per Invoice'!E$2:E$1201,$Z3)="","",INDEX('Per Invoice'!E$2:E$1201,$Z3))) | F3: =IF($Z3="","",IF(INDEX('Per Invoice'!F$2:F$1201,$Z3)="","",INDEX('Per Invoice'!F$2:F$1201,$Z3))) | G3: =IF($Z3="","",IF(INDEX('Per Invoice'!G$2:G$1201,$Z3)="","",INDEX('Per Invoice'!G$2:G$1201,$Z3))) | H3: =IF($Z3="","",IF(INDEX('Per Invoice'!H$2:H$1201,$Z3)="","",INDEX('Per Invoice'!H$2:H$1201,$Z3))) | ... Y3: =IF($Z3="","",IF(INDEX('Per Invoice'!Y$2:Y$1201,$Z3)="","",INDEX('Per Invoice'!Y$2:Y$1201,$Z3))) | Z3: =IFERROR(MATCH(Settings!$C$27&"|"&ROWS($Z$2:$Z3),'Per Invoice'!$AB$2:$AB$1201,0),"")
A4: =IF($Z4="","",IF(INDEX('Per Invoice'!A$2:A$1201,$Z4)="","",INDEX('Per Invoice'!A$2:A$1201,$Z4))) | B4: =IF($Z4="","",IF(INDEX('Per Invoice'!B$2:B$1201,$Z4)="","",INDEX('Per Invoice'!B$2:B$1201,$Z4))) | C4: =IF($Z4="","",IF(INDEX('Per Invoice'!C$2:C$1201,$Z4)="","",INDEX('Per Invoice'!C$2:C$1201,$Z4))) | D4: =IF($Z4="","",IF(INDEX('Per Invoice'!D$2:D$1201,$Z4)="","",INDEX('Per Invoice'!D$2:D$1201,$Z4))) | E4: =IF($Z4="","",IF(INDEX('Per Invoice'!E$2:E$1201,$Z4)="","",INDEX('Per Invoice'!E$2:E$1201,$Z4))) | F4: =IF($Z4="","",IF(INDEX('Per Invoice'!F$2:F$1201,$Z4)="","",INDEX('Per Invoice'!F$2:F$1201,$Z4))) | G4: =IF($Z4="","",IF(INDEX('Per Invoice'!G$2:G$1201,$Z4)="","",INDEX('Per Invoice'!G$2:G$1201,$Z4))) | H4: =IF($Z4="","",IF(INDEX('Per Invoice'!H$2:H$1201,$Z4)="","",INDEX('Per Invoice'!H$2:H$1201,$Z4))) | ... Y4: =IF($Z4="","",IF(INDEX('Per Invoice'!Y$2:Y$1201,$Z4)="","",INDEX('Per Invoice'!Y$2:Y$1201,$Z4))) | Z4: =IFERROR(MATCH(Settings!$C$27&"|"&ROWS($Z$2:$Z4),'Per Invoice'!$AB$2:$AB$1201,0),"")
A5: =IF($Z5="","",IF(INDEX('Per Invoice'!A$2:A$1201,$Z5)="","",INDEX('Per Invoice'!A$2:A$1201,$Z5))) | B5: =IF($Z5="","",IF(INDEX('Per Invoice'!B$2:B$1201,$Z5)="","",INDEX('Per Invoice'!B$2:B$1201,$Z5))) | C5: =IF($Z5="","",IF(INDEX('Per Invoice'!C$2:C$1201,$Z5)="","",INDEX('Per Invoice'!C$2:C$1201,$Z5))) | D5: =IF($Z5="","",IF(INDEX('Per Invoice'!D$2:D$1201,$Z5)="","",INDEX('Per Invoice'!D$2:D$1201,$Z5))) | E5: =IF($Z5="","",IF(INDEX('Per Invoice'!E$2:E$1201,$Z5)="","",INDEX('Per Invoice'!E$2:E$1201,$Z5))) | F5: =IF($Z5="","",IF(INDEX('Per Invoice'!F$2:F$1201,$Z5)="","",INDEX('Per Invoice'!F$2:F$1201,$Z5))) | G5: =IF($Z5="","",IF(INDEX('Per Invoice'!G$2:G$1201,$Z5)="","",INDEX('Per Invoice'!G$2:G$1201,$Z5))) | H5: =IF($Z5="","",IF(INDEX('Per Invoice'!H$2:H$1201,$Z5)="","",INDEX('Per Invoice'!H$2:H$1201,$Z5))) | ... Y5: =IF($Z5="","",IF(INDEX('Per Invoice'!Y$2:Y$1201,$Z5)="","",INDEX('Per Invoice'!Y$2:Y$1201,$Z5))) | Z5: =IFERROR(MATCH(Settings!$C$27&"|"&ROWS($Z$2:$Z5),'Per Invoice'!$AB$2:$AB$1201,0),"")
A6: =IF($Z6="","",IF(INDEX('Per Invoice'!A$2:A$1201,$Z6)="","",INDEX('Per Invoice'!A$2:A$1201,$Z6))) | B6: =IF($Z6="","",IF(INDEX('Per Invoice'!B$2:B$1201,$Z6)="","",INDEX('Per Invoice'!B$2:B$1201,$Z6))) | C6: =IF($Z6="","",IF(INDEX('Per Invoice'!C$2:C$1201,$Z6)="","",INDEX('Per Invoice'!C$2:C$1201,$Z6))) | D6: =IF($Z6="","",IF(INDEX('Per Invoice'!D$2:D$1201,$Z6)="","",INDEX('Per Invoice'!D$2:D$1201,$Z6))) | E6: =IF($Z6="","",IF(INDEX('Per Invoice'!E$2:E$1201,$Z6)="","",INDEX('Per Invoice'!E$2:E$1201,$Z6))) | F6: =IF($Z6="","",IF(INDEX('Per Invoice'!F$2:F$1201,$Z6)="","",INDEX('Per Invoice'!F$2:F$1201,$Z6))) | G6: =IF($Z6="","",IF(INDEX('Per Invoice'!G$2:G$1201,$Z6)="","",INDEX('Per Invoice'!G$2:G$1201,$Z6))) | H6: =IF($Z6="","",IF(INDEX('Per Invoice'!H$2:H$1201,$Z6)="","",INDEX('Per Invoice'!H$2:H$1201,$Z6))) | ... Y6: =IF($Z6="","",IF(INDEX('Per Invoice'!Y$2:Y$1201,$Z6)="","",INDEX('Per Invoice'!Y$2:Y$1201,$Z6))) | Z6: =IFERROR(MATCH(Settings!$C$27&"|"&ROWS($Z$2:$Z6),'Per Invoice'!$AB$2:$AB$1201,0),"")
A7: =IF($Z7="","",IF(INDEX('Per Invoice'!A$2:A$1201,$Z7)="","",INDEX('Per Invoice'!A$2:A$1201,$Z7))) | B7: =IF($Z7="","",IF(INDEX('Per Invoice'!B$2:B$1201,$Z7)="","",INDEX('Per Invoice'!B$2:B$1201,$Z7))) | C7: =IF($Z7="","",IF(INDEX('Per Invoice'!C$2:C$1201,$Z7)="","",INDEX('Per Invoice'!C$2:C$1201,$Z7))) | D7: =IF($Z7="","",IF(INDEX('Per Invoice'!D$2:D$1201,$Z7)="","",INDEX('Per Invoice'!D$2:D$1201,$Z7))) | E7: =IF($Z7="","",IF(INDEX('Per Invoice'!E$2:E$1201,$Z7)="","",INDEX('Per Invoice'!E$2:E$1201,$Z7))) | F7: =IF($Z7="","",IF(INDEX('Per Invoice'!F$2:F$1201,$Z7)="","",INDEX('Per Invoice'!F$2:F$1201,$Z7))) | G7: =IF($Z7="","",IF(INDEX('Per Invoice'!G$2:G$1201,$Z7)="","",INDEX('Per Invoice'!G$2:G$1201,$Z7))) | H7: =IF($Z7="","",IF(INDEX('Per Invoice'!H$2:H$1201,$Z7)="","",INDEX('Per Invoice'!H$2:H$1201,$Z7))) | ... Y7: =IF($Z7="","",IF(INDEX('Per Invoice'!Y$2:Y$1201,$Z7)="","",INDEX('Per Invoice'!Y$2:Y$1201,$Z7))) | Z7: =IFERROR(MATCH(Settings!$C$27&"|"&ROWS($Z$2:$Z7),'Per Invoice'!$AB$2:$AB$1201,0),"")
A8: =IF($Z8="","",IF(INDEX('Per Invoice'!A$2:A$1201,$Z8)="","",INDEX('Per Invoice'!A$2:A$1201,$Z8))) | B8: =IF($Z8="","",IF(INDEX('Per Invoice'!B$2:B$1201,$Z8)="","",INDEX('Per Invoice'!B$2:B$1201,$Z8))) | C8: =IF($Z8="","",IF(INDEX('Per Invoice'!C$2:C$1201,$Z8)="","",INDEX('Per Invoice'!C$2:C$1201,$Z8))) | D8: =IF($Z8="","",IF(INDEX('Per Invoice'!D$2:D$1201,$Z8)="","",INDEX('Per Invoice'!D$2:D$1201,$Z8))) | E8: =IF($Z8="","",IF(INDEX('Per Invoice'!E$2:E$1201,$Z8)="","",INDEX('Per Invoice'!E$2:E$1201,$Z8))) | F8: =IF($Z8="","",IF(INDEX('Per Invoice'!F$2:F$1201,$Z8)="","",INDEX('Per Invoice'!F$2:F$1201,$Z8))) | G8: =IF($Z8="","",IF(INDEX('Per Invoice'!G$2:G$1201,$Z8)="","",INDEX('Per Invoice'!G$2:G$1201,$Z8))) | H8: =IF($Z8="","",IF(INDEX('Per Invoice'!H$2:H$1201,$Z8)="","",INDEX('Per Invoice'!H$2:H$1201,$Z8))) | ... Y8: =IF($Z8="","",IF(INDEX('Per Invoice'!Y$2:Y$1201,$Z8)="","",INDEX('Per Invoice'!Y$2:Y$1201,$Z8))) | Z8: =IFERROR(MATCH(Settings!$C$27&"|"&ROWS($Z$2:$Z8),'Per Invoice'!$AB$2:$AB$1201,0),"")
A9: =IF($Z9="","",IF(INDEX('Per Invoice'!A$2:A$1201,$Z9)="","",INDEX('Per Invoice'!A$2:A$1201,$Z9))) | B9: =IF($Z9="","",IF(INDEX('Per Invoice'!B$2:B$1201,$Z9)="","",INDEX('Per Invoice'!B$2:B$1201,$Z9))) | C9: =IF($Z9="","",IF(INDEX('Per Invoice'!C$2:C$1201,$Z9)="","",INDEX('Per Invoice'!C$2:C$1201,$Z9))) | D9: =IF($Z9="","",IF(INDEX('Per Invoice'!D$2:D$1201,$Z9)="","",INDEX('Per Invoice'!D$2:D$1201,$Z9))) | E9: =IF($Z9="","",IF(INDEX('Per Invoice'!E$2:E$1201,$Z9)="","",INDEX('Per Invoice'!E$2:E$1201,$Z9))) | F9: =IF($Z9="","",IF(INDEX('Per Invoice'!F$2:F$1201,$Z9)="","",INDEX('Per Invoice'!F$2:F$1201,$Z9))) | G9: =IF($Z9="","",IF(INDEX('Per Invoice'!G$2:G$1201,$Z9)="","",INDEX('Per Invoice'!G$2:G$1201,$Z9))) | H9: =IF($Z9="","",IF(INDEX('Per Invoice'!H$2:H$1201,$Z9)="","",INDEX('Per Invoice'!H$2:H$1201,$Z9))) | ... Y9: =IF($Z9="","",IF(INDEX('Per Invoice'!Y$2:Y$1201,$Z9)="","",INDEX('Per Invoice'!Y$2:Y$1201,$Z9))) | Z9: =IFERROR(MATCH(Settings!$C$27&"|"&ROWS($Z$2:$Z9),'Per Invoice'!$AB$2:$AB$1201,0),"")
A10: =IF($Z10="","",IF(INDEX('Per Invoice'!A$2:A$1201,$Z10)="","",INDEX('Per Invoice'!A$2:A$1201,$Z10))) | B10: =IF($Z10="","",IF(INDEX('Per Invoice'!B$2:B$1201,$Z10)="","",INDEX('Per Invoice'!B$2:B$1201,$Z10))) | C10: =IF($Z10="","",IF(INDEX('Per Invoice'!C$2:C$1201,$Z10)="","",INDEX('Per Invoice'!C$2:C$1201,$Z10))) | D10: =IF($Z10="","",IF(INDEX('Per Invoice'!D$2:D$1201,$Z10)="","",INDEX('Per Invoice'!D$2:D$1201,$Z10))) | E10: =IF($Z10="","",IF(INDEX('Per Invoice'!E$2:E$1201,$Z10)="","",INDEX('Per Invoice'!E$2:E$1201,$Z10))) | F10: =IF($Z10="","",IF(INDEX('Per Invoice'!F$2:F$1201,$Z10)="","",INDEX('Per Invoice'!F$2:F$1201,$Z10))) | G10: =IF($Z10="","",IF(INDEX('Per Invoice'!G$2:G$1201,$Z10)="","",INDEX('Per Invoice'!G$2:G$1201,$Z10))) | H10: =IF($Z10="","",IF(INDEX('Per Invoice'!H$2:H$1201,$Z10)="","",INDEX('Per Invoice'!H$2:H$1201,$Z10))) | ... Y10: =IF($Z10="","",IF(INDEX('Per Invoice'!Y$2:Y$1201,$Z10)="","",INDEX('Per Invoice'!Y$2:Y$1201,$Z10))) | Z10: =IFERROR(MATCH(Settings!$C$27&"|"&ROWS($Z$2:$Z10),'Per Invoice'!$AB$2:$AB$1201,0),"")
