Workbook

Sheet How To Use
A1: El Tawoon template - Bahary
A3: Monthly steps
A4: 1. Open 'PERLINE'. Delete the old data in the BLUE columns only (row 2 down). Never delete the green or grey columns.
A5: 2. Paste the new month's lines as VALUES starting at A2 into the blue columns (same order as the system export).
A6: 3. Type the invoice number (INV column in PERLINE) yourself. It can start from any number (1, 351, 1200 ...): all lines of the same Order # get the same number. The invoice list and the statement pages show the INV numbers in ascending order, whatever the first number is.
A7: 4. Everything else fills itself: the invoice list tab 'BAHARY', the statement pages 'كشف (1)', 'كشف (2)' ..., 'الاجمالى' and 'كشف المطالبة'.
A8: 5. In 'كشف المطالبة' choose the month (E2). Also check the part (E3), the type (E4) and the rates 14% / 7% (D5 / D6).
A9: 6. Open 'Check': STATUS must say OK (Perline = invoice list = statement pages = claim sheet).
A10: 7. Statement pages that are not needed stay empty - print or send only the pages that have patients (40 patients per page).
A12: Colour legend
A13: Blue header = pasted by you. Green header = formula (do not paste over). Grey header = helper formula (do not touch).
A15: Calculation rules (taken from your files)
... A22: Capacity: 3000 lines, 900 invoices in the invoice list, 12 statement pages (480 patients). 'Check' warns if exceeded.

Sheet Check
B1: Checks
B3: Lines loaded | C3: =COUNTA(PERLINE!$A$2:$A$3001) -> 0
B4: Invoices (distinct INV numbers) | C4: =COUNT(PERLINE!$AL$2:$AL$3001) -> 0
B5: Statement pages needed (40 per page) | C5: =ROUNDUP(C4/40,0) -> 0
B6: Statement pages available in this file | C6: 12
B7: Month entered in 'كشف المطالبة'!E2 | C7: =IF('كشف المطالبة'!$E$2="","",'كشف المطالبة'!$E$2)
B8: Lines without an INV number | C8: =COUNTA(PERLINE!$A$2:$A$3001)-COUNT(PERLINE!$N$2:$N$3001) -> 0
C9: Perline | D9: Invoice list (BAHARY) | E9: Statement pages | F9: Claim sheet
B10: Total before discount | C10: =SUM(PERLINE!$U$2:$U$3001) -> 0 | D10: =SUM(BAHARY!$K$2:$K$901) -> 0 | E10: =الاجمالى!$D$16 -> 0 | F10: ='كشف المطالبة'!$C$4 -> 0
B11: Discount | C11: =SUM(PERLINE!$W$2:$W$3001) -> 0 | D11: =SUM(BAHARY!$J$2:$J$901) -> 0 | E11: =الاجمالى!$D$16-الاجمالى!$G$16 -> 0 | F11: ='كشف المطالبة'!$C$8 -> 0
B12: Loading / copayment (CO VAL) | C12: =SUM(PERLINE!$M$2:$M$3001) -> 0 | D12: =SUM(BAHARY!$N$2:$N$901) -> 0 | E12: =الاجمالى!$H$16 -> 0 | F12: ='كشف المطالبة'!$C$7 -> 0
B13: Net | C13: =SUM(PERLINE!$Y$2:$Y$3001) -> 0 | D13: =SUM(BAHARY!$L$2:$L$901) -> 0 | E13: =الاجمالى!$I$16 -> 0 | F13: ='كشف المطالبة'!$C$10 -> 0
B15: STATUS | C15: =IF(C3=0,"No data loaded",IF(COUNTA(PERLINE!$A:$A)-1>3000,"TOO MANY LINES - extend template",IF(C4>900,"TOO MANY INVOICES - extend the invoice list",IF(C5>C6,"NOT ENOUGH STATEMENT PAGES - need "&C5&" pages, file has "&C6,IF(C8>0,"FILL THE INV NUMBER on "&C8&" line(s)",IF(TRIM(C7&"")="","SET THE MONTH in 'كشف المطالبة'!E2",IF(AND(ROUND(C10-D10,2)=0,ROUND(D10-E10,2)=0,ROUND(E10-F10,2)=0,ROUND(C11-D11,2)=0,ROUND(D11-E11,2)=0,ROUND(E11-F11,2)=0,ROUND(C12-D12,2)=0,ROUND(E12-F12,2)=0,ROUND(C13-D13,2)=0,ROUND(E13-F13,2)=0,ROUND(E13+(E12-D12)-D13,2)=0),"OK","CHECK - totals do not match"))))))) -> No data loaded

Sheet BAHARY
A1: INV | B1: الاسم | C1: رقم الأداء | D1: نسبة خصم المستورد% | E1: مستورد قبل الخصم | F1: قيمة الخصم للمستورد | G1: خصم المحلي% | H1: محلي قبل الخصم | I1: قيمة خصم المحلي | J1: اجمالي الخصم | K1: الاجمالي | L1: الصافي | M1: SO | N1: قيمه التحمل
A2: =IF(ROWS($A$2:$A2)<=Check!$C$4,SMALL(PERLINE!$AL$2:$AL$3001,ROWS($A$2:$A2)),"") | B2: =IF($A2="","",INDEX(PERLINE!$J$2:$J$3001,MATCH($A2,PERLINE!$N$2:$N$3001,0))) | C2: =IF($A2="","",INDEX(PERLINE!$I$2:$I$3001,MATCH($A2,PERLINE!$N$2:$N$3001,0))) | D2: =IF($A2="","",'كشف المطالبة'!$D$6) | E2: =IF($A2="","",SUMIFS(PERLINE!$U$2:$U$3001,PERLINE!$N$2:$N$3001,$A2,PERLINE!$AK$2:$AK$3001,0)) | F2: =IF($A2="","",E2*D2) | G2: =IF($A2="","",'كشف المطالبة'!$D$5) | H2: =IF($A2="","",SUMIFS(PERLINE!$U$2:$U$3001,PERLINE!$N$2:$N$3001,$A2,PERLINE!$AK$2:$AK$3001,1)) | I2: =IF($A2="","",H2*G2) | J2: =IF($A2="","",F2+I2) | K2: =IF($A2="","",H2+E2) | L2: =IF($A2="","",K2-J2-N2) | M2: =IF($A2="","",INDEX(PERLINE!$A$2:$A$3001,MATCH($A2,PERLINE!$N$2:$N$3001,0))) | N2: =IF($A2="","",SUMIFS(PERLINE!$M$2:$M$3001,PERLINE!$N$2:$N$3001,$A2))
A3: =IF(ROWS($A$2:$A3)<=Check!$C$4,SMALL(PERLINE!$AL$2:$AL$3001,ROWS($A$2:$A3)),"") | B3: =IF($A3="","",INDEX(PERLINE!$J$2:$J$3001,MATCH($A3,PERLINE!$N$2:$N$3001,0))) | C3: =IF($A3="","",INDEX(PERLINE!$I$2:$I$3001,MATCH($A3,PERLINE!$N$2:$N$3001,0))) | D3: =IF($A3="","",'كشف المطالبة'!$D$6) | E3: =IF($A3="","",SUMIFS(PERLINE!$U$2:$U$3001,PERLINE!$N$2:$N$3001,$A3,PERLINE!$AK$2:$AK$3001,0)) | F3: =IF($A3="","",E3*D3) | G3: =IF($A3="","",'كشف المطالبة'!$D$5) | H3: =IF($A3="","",SUMIFS(PERLINE!$U$2:$U$3001,PERLINE!$N$2:$N$3001,$A3,PERLINE!$AK$2:$AK$3001,1)) | I3: =IF($A3="","",H3*G3) | J3: =IF($A3="","",F3+I3) | K3: =IF($A3="","",H3+E3) | L3: =IF($A3="","",K3-J3-N3) | M3: =IF($A3="","",INDEX(PERLINE!$A$2:$A$3001,MATCH($A3,PERLINE!$N$2:$N$3001,0))) | N3: =IF($A3="","",SUMIFS(PERLINE!$M$2:$M$3001,PERLINE!$N$2:$N$3001,$A3))
A4: =IF(ROWS($A$2:$A4)<=Check!$C$4,SMALL(PERLINE!$AL$2:$AL$3001,ROWS($A$2:$A4)),"") | B4: =IF($A4="","",INDEX(PERLINE!$J$2:$J$3001,MATCH($A4,PERLINE!$N$2:$N$3001,0))) | C4: =IF($A4="","",INDEX(PERLINE!$I$2:$I$3001,MATCH($A4,PERLINE!$N$2:$N$3001,0))) | D4: =IF($A4="","",'كشف المطالبة'!$D$6) | E4: =IF($A4="","",SUMIFS(PERLINE!$U$2:$U$3001,PERLINE!$N$2:$N$3001,$A4,PERLINE!$AK$2:$AK$3001,0)) | F4: =IF($A4="","",E4*D4) | G4: =IF($A4="","",'كشف المطالبة'!$D$5) | H4: =IF($A4="","",SUMIFS(PERLINE!$U$2:$U$3001,PERLINE!$N$2:$N$3001,$A4,PERLINE!$AK$2:$AK$3001,1)) | I4: =IF($A4="","",H4*G4) | J4: =IF($A4="","",F4+I4) | K4: =IF($A4="","",H4+E4) | L4: =IF($A4="","",K4-J4-N4) | M4: =IF($A4="","",INDEX(PERLINE!$A$2:$A$3001,MATCH($A4,PERLINE!$N$2:$N$3001,0))) | N4: =IF($A4="","",SUMIFS(PERLINE!$M$2:$M$3001,PERLINE!$N$2:$N$3001,$A4))
A5: =IF(ROWS($A$2:$A5)<=Check!$C$4,SMALL(PERLINE!$AL$2:$AL$3001,ROWS($A$2:$A5)),"") | B5: =IF($A5="","",INDEX(PERLINE!$J$2:$J$3001,MATCH($A5,PERLINE!$N$2:$N$3001,0))) | C5: =IF($A5="","",INDEX(PERLINE!$I$2:$I$3001,MATCH($A5,PERLINE!$N$2:$N$3001,0))) | D5: =IF($A5="","",'كشف المطالبة'!$D$6) | E5: =IF($A5="","",SUMIFS(PERLINE!$U$2:$U$3001,PERLINE!$N$2:$N$3001,$A5,PERLINE!$AK$2:$AK$3001,0)) | F5: =IF($A5="","",E5*D5) | G5: =IF($A5="","",'كشف المطالبة'!$D$5) | H5: =IF($A5="","",SUMIFS(PERLINE!$U$2:$U$3001,PERLINE!$N$2:$N$3001,$A5,PERLINE!$AK$2:$AK$3001,1)) | I5: =IF($A5="","",H5*G5) | J5: =IF($A5="","",F5+I5) | K5: =IF($A5="","",H5+E5) | L5: =IF($A5="","",K5-J5-N5) | M5: =IF($A5="","",INDEX(PERLINE!$A$2:$A$3001,MATCH($A5,PERLINE!$N$2:$N$3001,0))) | N5: =IF($A5="","",SUMIFS(PERLINE!$M$2:$M$3001,PERLINE!$N$2:$N$3001,$A5))
A6: =IF(ROWS($A$2:$A6)<=Check!$C$4,SMALL(PERLINE!$AL$2:$AL$3001,ROWS($A$2:$A6)),"") | B6: =IF($A6="","",INDEX(PERLINE!$J$2:$J$3001,MATCH($A6,PERLINE!$N$2:$N$3001,0))) | C6: =IF($A6="","",INDEX(PERLINE!$I$2:$I$3001,MATCH($A6,PERLINE!$N$2:$N$3001,0))) | D6: =IF($A6="","",'كشف المطالبة'!$D$6) | E6: =IF($A6="","",SUMIFS(PERLINE!$U$2:$U$3001,PERLINE!$N$2:$N$3001,$A6,PERLINE!$AK$2:$AK$3001,0)) | F6: =IF($A6="","",E6*D6) | G6: =IF($A6="","",'كشف المطالبة'!$D$5) | H6: =IF($A6="","",SUMIFS(PERLINE!$U$2:$U$3001,PERLINE!$N$2:$N$3001,$A6,PERLINE!$AK$2:$AK$3001,1)) | I6: =IF($A6="","",H6*G6) | J6: =IF($A6="","",F6+I6) | K6: =IF($A6="","",H6+E6) | L6: =IF($A6="","",K6-J6-N6) | M6: =IF($A6="","",INDEX(PERLINE!$A$2:$A$3001,MATCH($A6,PERLINE!$N$2:$N$3001,0))) | N6: =IF($A6="","",SUMIFS(PERLINE!$M$2:$M$3001,PERLINE!$N$2:$N$3001,$A6))
A7: =IF(ROWS($A$2:$A7)<=Check!$C$4,SMALL(PERLINE!$AL$2:$AL$3001,ROWS($A$2:$A7)),"") | B7: =IF($A7="","",INDEX(PERLINE!$J$2:$J$3001,MATCH($A7,PERLINE!$N$2:$N$3001,0))) | C7: =IF($A7="","",INDEX(PERLINE!$I$2:$I$3001,MATCH($A7,PERLINE!$N$2:$N$3001,0))) | D7: =IF($A7="","",'كشف المطالبة'!$D$6) | E7: =IF($A7="","",SUMIFS(PERLINE!$U$2:$U$3001,PERLINE!$N$2:$N$3001,$A7,PERLINE!$AK$2:$AK$3001,0)) | F7: =IF($A7="","",E7*D7) | G7: =IF($A7="","",'كشف المطالبة'!$D$5) | H7: =IF($A7="","",SUMIFS(PERLINE!$U$2:$U$3001,PERLINE!$N$2:$N$3001,$A7,PERLINE!$AK$2:$AK$3001,1)) | I7: =IF($A7="","",H7*G7) | J7: =IF($A7="","",F7+I7) | K7: =IF($A7="","",H7+E7) | L7: =IF($A7="","",K7-J7-N7) | M7: =IF($A7="","",INDEX(PERLINE!$A$2:$A$3001,MATCH($A7,PERLINE!$N$2:$N$3001,0))) | N7: =IF($A7="","",SUMIFS(PERLINE!$M$2:$M$3001,PERLINE!$N$2:$N$3001,$A7))
A8: =IF(ROWS($A$2:$A8)<=Check!$C$4,SMALL(PERLINE!$AL$2:$AL$3001,ROWS($A$2:$A8)),"") | B8: =IF($A8="","",INDEX(PERLINE!$J$2:$J$3001,MATCH($A8,PERLINE!$N$2:$N$3001,0))) | C8: =IF($A8="","",INDEX(PERLINE!$I$2:$I$3001,MATCH($A8,PERLINE!$N$2:$N$3001,0))) | D8: =IF($A8="","",'كشف المطالبة'!$D$6) | E8: =IF($A8="","",SUMIFS(PERLINE!$U$2:$U$3001,PERLINE!$N$2:$N$3001,$A8,PERLINE!$AK$2:$AK$3001,0)) | F8: =IF($A8="","",E8*D8) | G8: =IF($A8="","",'كشف المطالبة'!$D$5) | H8: =IF($A8="","",SUMIFS(PERLINE!$U$2:$U$3001,PERLINE!$N$2:$N$3001,$A8,PERLINE!$AK$2:$AK$3001,1)) | I8: =IF($A8="","",H8*G8) | J8: =IF($A8="","",F8+I8) | K8: =IF($A8="","",H8+E8) | L8: =IF($A8="","",K8-J8-N8) | M8: =IF($A8="","",INDEX(PERLINE!$A$2:$A$3001,MATCH($A8,PERLINE!$N$2:$N$3001,0))) | N8: =IF($A8="","",SUMIFS(PERLINE!$M$2:$M$3001,PERLINE!$N$2:$N$3001,$A8))
A9: =IF(ROWS($A$2:$A9)<=Check!$C$4,SMALL(PERLINE!$AL$2:$AL$3001,ROWS($A$2:$A9)),"") | B9: =IF($A9="","",INDEX(PERLINE!$J$2:$J$3001,MATCH($A9,PERLINE!$N$2:$N$3001,0))) | C9: =IF($A9="","",INDEX(PERLINE!$I$2:$I$3001,MATCH($A9,PERLINE!$N$2:$N$3001,0))) | D9: =IF($A9="","",'كشف المطالبة'!$D$6) | E9: =IF($A9="","",SUMIFS(PERLINE!$U$2:$U$3001,PERLINE!$N$2:$N$3001,$A9,PERLINE!$AK$2:$AK$3001,0)) | F9: =IF($A9="","",E9*D9) | G9: =IF($A9="","",'كشف المطالبة'!$D$5) | H9: =IF($A9="","",SUMIFS(PERLINE!$U$2:$U$3001,PERLINE!$N$2:$N$3001,$A9,PERLINE!$AK$2:$AK$3001,1)) | I9: =IF($A9="","",H9*G9) | J9: =IF($A9="","",F9+I9) | K9: =IF($A9="","",H9+E9) | L9: =IF($A9="","",K9-J9-N9) | M9: =IF($A9="","",INDEX(PERLINE!$A$2:$A$3001,MATCH($A9,PERLINE!$N$2:$N$3001,0))) | N9: =IF($A9="","",SUMIFS(PERLINE!$M$2:$M$3001,PERLINE!$N$2:$N$3001,$A9))
A10: =IF(ROWS($A$2:$A10)<=Check!$C$4,SMALL(PERLINE!$AL$2:$AL$3001,ROWS($A$2:$A10)),"") | B10: =IF($A10="","",INDEX(PERLINE!$J$2:$J$3001,MATCH($A10,PERLINE!$N$2:$N$3001,0))) | C10: =IF($A10="","",INDEX(PERLINE!$I$2:$I$3001,MATCH($A10,PERLINE!$N$2:$N$3001,0))) | D10: =IF($A10="","",'كشف المطالبة'!$D$6) | E10: =IF($A10="","",SUMIFS(PERLINE!$U$2:$U$3001,PERLINE!$N$2:$N$3001,$A10,PERLINE!$AK$2:$AK$3001,0)) | F10: =IF($A10="","",E10*D10) | G10: =IF($A10="","",'كشف المطالبة'!$D$5) | H10: =IF($A10="","",SUMIFS(PERLINE!$U$2:$U$3001,PERLINE!$N$2:$N$3001,$A10,PERLINE!$AK$2:$AK$3001,1)) | I10: =IF($A10="","",H10*G10) | J10: =IF($A10="","",F10+I10) | K10: =IF($A10="","",H10+E10) | L10: =IF($A10="","",K10-J10-N10) | M10: =IF($A10="","",INDEX(PERLINE!$A$2:$A$3001,MATCH($A10,PERLINE!$N$2:$N$3001,0))) | N10: =IF($A10="","",SUMIFS(PERLINE!$M$2:$M$3001,PERLINE!$N$2:$N$3001,$A10))
A11: =IF(ROWS($A$2:$A11)<=Check!$C$4,SMALL(PERLINE!$AL$2:$AL$3001,ROWS($A$2:$A11)),"") | B11: =IF($A11="","",INDEX(PERLINE!$J$2:$J$3001,MATCH($A11,PERLINE!$N$2:$N$3001,0))) | C11: =IF($A11="","",INDEX(PERLINE!$I$2:$I$3001,MATCH($A11,PERLINE!$N$2:$N$3001,0))) | D11: =IF($A11="","",'كشف المطالبة'!$D$6) | E11: =IF($A11="","",SUMIFS(PERLINE!$U$2:$U$3001,PERLINE!$N$2:$N$3001,$A11,PERLINE!$AK$2:$AK$3001,0)) | F11: =IF($A11="","",E11*D11) | G11: =IF($A11="","",'كشف المطالبة'!$D$5) | H11: =IF($A11="","",SUMIFS(PERLINE!$U$2:$U$3001,PERLINE!$N$2:$N$3001,$A11,PERLINE!$AK$2:$AK$3001,1)) | I11: =IF($A11="","",H11*G11) | J11: =IF($A11="","",F11+I11) | K11: =IF($A11="","",H11+E11) | L11: =IF($A11="","",K11-J11-N11) | M11: =IF($A11="","",INDEX(PERLINE!$A$2:$A$3001,MATCH($A11,PERLINE!$N$2:$N$3001,0))) | N11: =IF($A11="","",SUMIFS(PERLINE!$M$2:$M$3001,PERLINE!$N$2:$N$3001,$A11))
A12: =IF(ROWS($A$2:$A12)<=Check!$C$4,SMALL(PERLINE!$AL$2:$AL$3001,ROWS($A$2:$A12)),"") | B12: =IF($A12="","",INDEX(PERLINE!$J$2:$J$3001,MATCH($A12,PERLINE!$N$2:$N$3001,0))) | C12: =IF($A12="","",INDEX(PERLINE!$I$2:$I$3001,MATCH($A12,PERLINE!$N$2:$N$3001,0))) | D12: =IF($A12="","",'كشف المطالبة'!$D$6) | E12: =IF($A12="","",SUMIFS(PERLINE!$U$2:$U$3001,PERLINE!$N$2:$N$3001,$A12,PERLINE!$AK$2:$AK$3001,0)) | F12: =IF($A12="","",E12*D12) | G12: =IF($A12="","",'كشف المطالبة'!$D$5) | H12: =IF($A12="","",SUMIFS(PERLINE!$U$2:$U$3001,PERLINE!$N$2:$N$3001,$A12,PERLINE!$AK$2:$AK$3001,1)) | I12: =IF($A12="","",H12*G12) | J12: =IF($A12="","",F12+I12) | K12: =IF($A12="","",H12+E12) | L12: =IF($A12="","",K12-J12-N12) | M12: =IF($A12="","",INDEX(PERLINE!$A$2:$A$3001,MATCH($A12,PERLINE!$N$2:$N$3001,0))) | N12: =IF($A12="","",SUMIFS(PERLINE!$M$2:$M$3001,PERLINE!$N$2:$N$3001,$A12))
A13: =IF(ROWS($A$2:$A13)<=Check!$C$4,SMALL(PERLINE!$AL$2:$AL$3001,ROWS($A$2:$A13)),"") | B13: =IF($A13="","",INDEX(PERLINE!$J$2:$J$3001,MATCH($A13,PERLINE!$N$2:$N$3001,0))) | C13: =IF($A13="","",INDEX(PERLINE!$I$2:$I$3001,MATCH($A13,PERLINE!$N$2:$N$3001,0))) | D13: =IF($A13="","",'كشف المطالبة'!$D$6) | E13: =IF($A13="","",SUMIFS(PERLINE!$U$2:$U$3001,PERLINE!$N$2:$N$3001,$A13,PERLINE!$AK$2:$AK$3001,0)) | F13: =IF($A13="","",E13*D13) | G13: =IF($A13="","",'كشف المطالبة'!$D$5) | H13: =IF($A13="","",SUMIFS(PERLINE!$U$2:$U$3001,PERLINE!$N$2:$N$3001,$A13,PERLINE!$AK$2:$AK$3001,1)) | I13: =IF($A13="","",H13*G13) | J13: =IF($A13="","",F13+I13) | K13: =IF($A13="","",H13+E13) | L13: =IF($A13="","",K13-J13-N13) | M13: =IF($A13="","",INDEX(PERLINE!$A$2:$A$3001,MATCH($A13,PERLINE!$N$2:$N$3001,0))) | N13: =IF($A13="","",SUMIFS(PERLINE!$M$2:$M$3001,PERLINE!$N$2:$N$3001,$A13))
... A901: =IF(ROWS($A$2:$A901)<=Check!$C$4,SMALL(PERLINE!$AL$2:$AL$3001,ROWS($A$2:$A901)),"") | B901: =IF($A901="","",INDEX(PERLINE!$J$2:$J$3001,MATCH($A901,PERLINE!$N$2:$N$3001,0))) | C901: =IF($A901="","",INDEX(PERLINE!$I$2:$I$3001,MATCH($A901,PERLINE!$N$2:$N$3001,0))) | D901: =IF($A901="","",'كشف المطالبة'!$D$6) | E901: =IF($A901="","",SUMIFS(PERLINE!$U$2:$U$3001,PERLINE!$N$2:$N$3001,$A901,PERLINE!$AK$2:$AK$3001,0)) | F901: =IF($A901="","",E901*D901) | G901: =IF($A901="","",'كشف المطالبة'!$D$5) | H901: =IF($A901="","",SUMIFS(PERLINE!$U$2:$U$3001,PERLINE!$N$2:$N$3001,$A901,PERLINE!$AK$2:$AK$3001,1)) | I901: =IF($A901="","",H901*G901) | J901: =IF($A901="","",F901+I901) | K901: =IF($A901="","",H901+E901) | L901: =IF($A901="","",K901-J901-N901) | M901: =IF($A901="","",INDEX(PERLINE!$A$2:$A$3001,MATCH($A901,PERLINE!$N$2:$N$3001,0))) | N901: =IF($A901="","",SUMIFS(PERLINE!$M$2:$M$3001,PERLINE!$N$2:$N$3001,$A901))

Sheet PERLINE
A1: Order # | B1: Cycle | C1: Stage | D1: Channel | E1: Create At | F1: Insurance Company | G1: Country Portal ID | H1: Corporate | I1: Card | J1: Name | K1: Status | L1: Order Co Payment | M1: CO VAL | N1: inv | O1: heisenberg id | P1: Product Name | Q1: Local | R1: Unit | S1: Quantity | T1: Unit Price | U1: Product Total | V1: GROSS | W1: DISC | X1: SUBTOTAL | Y1: NET | Z1: ERX ID | AA1: Special Rebates? | AB1: Rebates | AC1: Approval Type | AD1: Max Limit | AE1: Exceeding Limit | AF1: Amount collected from customer | AG1: By Patient (Delivered) | AH1: Dispense Number | AI1: Dispense Date | AJ1: Has OTP? | AK1: Local Flag (helper) | AL1: INV 1st Row (helper)
M2: =IF($A2="","",$L2*$U2/100) | W2: =IF($A2="","",U2*AB2/100) | X2: =IF($A2="","",U2-W2) | Y2: =IF($A2="","",U2-W2-M2) | AB2: =IF($A2="","",IF($AK2=1,'كشف المطالبة'!$D$5,'كشف المطالبة'!$D$6)*100) | AK2: =IF($A2="","",IF(OR($Q2=TRUE(),$Q2="TRUE"),1,0)) | AL2: =IF($N2="","",IF(MATCH($N2,$N$2:$N$3001,0)=ROWS($N$2:$N2),$N2,""))
M3: =IF($A3="","",$L3*$U3/100) | W3: =IF($A3="","",U3*AB3/100) | X3: =IF($A3="","",U3-W3) | Y3: =IF($A3="","",U3-W3-M3) | AB3: =IF($A3="","",IF($AK3=1,'كشف المطالبة'!$D$5,'كشف المطالبة'!$D$6)*100) | AK3: =IF($A3="","",IF(OR($Q3=TRUE(),$Q3="TRUE"),1,0)) | AL3: =IF($N3="","",IF(MATCH($N3,$N$2:$N$3001,0)=ROWS($N$2:$N3),$N3,""))
M4: =IF($A4="","",$L4*$U4/100) | W4: =IF($A4="","",U4*AB4/100) | X4: =IF($A4="","",U4-W4) | Y4: =IF($A4="","",U4-W4-M4) | AB4: =IF($A4="","",IF($AK4=1,'كشف المطالبة'!$D$5,'كشف المطالبة'!$D$6)*100) | AK4: =IF($A4="","",IF(OR($Q4=TRUE(),$Q4="TRUE"),1,0)) | AL4: =IF($N4="","",IF(MATCH($N4,$N$2:$N$3001,0)=ROWS($N$2:$N4),$N4,""))
M5: =IF($A5="","",$L5*$U5/100) | W5: =IF($A5="","",U5*AB5/100) | X5: =IF($A5="","",U5-W5) | Y5: =IF($A5="","",U5-W5-M5) | AB5: =IF($A5="","",IF($AK5=1,'كشف المطالبة'!$D$5,'كشف المطالبة'!$D$6)*100) | AK5: =IF($A5="","",IF(OR($Q5=TRUE(),$Q5="TRUE"),1,0)) | AL5: =IF($N5="","",IF(MATCH($N5,$N$2:$N$3001,0)=ROWS($N$2:$N5),$N5,""))
M6: =IF($A6="","",$L6*$U6/100) | W6: =IF($A6="","",U6*AB6/100) | X6: =IF($A6="","",U6-W6) | Y6: =IF($A6="","",U6-W6-M6) | AB6: =IF($A6="","",IF($AK6=1,'كشف المطالبة'!$D$5,'كشف المطالبة'!$D$6)*100) | AK6: =IF($A6="","",IF(OR($Q6=TRUE(),$Q6="TRUE"),1,0)) | AL6: =IF($N6="","",IF(MATCH($N6,$N$2:$N$3001,0)=ROWS($N$2:$N6),$N6,""))
M7: =IF($A7="","",$L7*$U7/100) | W7: =IF($A7="","",U7*AB7/100) | X7: =IF($A7="","",U7-W7) | Y7: =IF($A7="","",U7-W7-M7) | AB7: =IF($A7="","",IF($AK7=1,'كشف المطالبة'!$D$5,'كشف المطالبة'!$D$6)*100) | AK7: =IF($A7="","",IF(OR($Q7=TRUE(),$Q7="TRUE"),1,0)) | AL7: =IF($N7="","",IF(MATCH($N7,$N$2:$N$3001,0)=ROWS($N$2:$N7),$N7,""))
M8: =IF($A8="","",$L8*$U8/100) | W8: =IF($A8="","",U8*AB8/100) | X8: =IF($A8="","",U8-W8) | Y8: =IF($A8="","",U8-W8-M8) | AB8: =IF($A8="","",IF($AK8=1,'كشف المطالبة'!$D$5,'كشف المطالبة'!$D$6)*100) | AK8: =IF($A8="","",IF(OR($Q8=TRUE(),$Q8="TRUE"),1,0)) | AL8: =IF($N8="","",IF(MATCH($N8,$N$2:$N$3001,0)=ROWS($N$2:$N8),$N8,""))
M9: =IF($A9="","",$L9*$U9/100) | W9: =IF($A9="","",U9*AB9/100) | X9: =IF($A9="","",U9-W9) | Y9: =IF($A9="","",U9-W9-M9) | AB9: =IF($A9="","",IF($AK9=1,'كشف المطالبة'!$D$5,'كشف المطالبة'!$D$6)*100) | AK9: =IF($A9="","",IF(OR($Q9=TRUE(),$Q9="TRUE"),1,0)) | AL9: =IF($N9="","",IF(MATCH($N9,$N$2:$N$3001,0)=ROWS($N$2:$N9),$N9,""))
M10: =IF($A10="","",$L10*$U10/100) | W10: =IF($A10="","",U10*AB10/100) | X10: =IF($A10="","",U10-W10) | Y10: =IF($A10="","",U10-W10-M10) | AB10: =IF($A10="","",IF($AK10=1,'كشف المطالبة'!$D$5,'كشف المطالبة'!$D$6)*100) | AK10: =IF($A10="","",IF(OR($Q10=TRUE(),$Q10="TRUE"),1,0)) | AL10: =IF($N10="","",IF(MATCH($N10,$N$2:$N$3001,0)=ROWS($N$2:$N10),$N10,""))
M11: =IF($A11="","",$L11*$U11/100) | W11: =IF($A11="","",U11*AB11/100) | X11: =IF($A11="","",U11-W11) | Y11: =IF($A11="","",U11-W11-M11) | AB11: =IF($A11="","",IF($AK11=1,'كشف المطالبة'!$D$5,'كشف المطالبة'!$D$6)*100) | AK11: =IF($A11="","",IF(OR($Q11=TRUE(),$Q11="TRUE"),1,0)) | AL11: =IF($N11="","",IF(MATCH($N11,$N$2:$N$3001,0)=ROWS($N$2:$N11),$N11,""))
M12: =IF($A12="","",$L12*$U12/100) | W12: =IF($A12="","",U12*AB12/100) | X12: =IF($A12="","",U12-W12) | Y12: =IF($A12="","",U12-W12-M12) | AB12: =IF($A12="","",IF($AK12=1,'كشف المطالبة'!$D$5,'كشف المطالبة'!$D$6)*100) | AK12: =IF($A12="","",IF(OR($Q12=TRUE(),$Q12="TRUE"),1,0)) | AL12: =IF($N12="","",IF(MATCH($N12,$N$2:$N$3001,0)=ROWS($N$2:$N12),$N12,""))
M13: =IF($A13="","",$L13*$U13/100) | W13: =IF($A13="","",U13*AB13/100) | X13: =IF($A13="","",U13-W13) | Y13: =IF($A13="","",U13-W13-M13) | AB13: =IF($A13="","",IF($AK13=1,'كشف المطالبة'!$D$5,'كشف المطالبة'!$D$6)*100) | AK13: =IF($A13="","",IF(OR($Q13=TRUE(),$Q13="TRUE"),1,0)) | AL13: =IF($N13="","",IF(MATCH($N13,$N$2:$N$3001,0)=ROWS($N$2:$N13),$N13,""))
... M3001: =IF($A3001="","",$L3001*$U3001/100) | W3001: =IF($A3001="","",U3001*AB3001/100) | X3001: =IF($A3001="","",U3001-W3001) | Y3001: =IF($A3001="","",U3001-W3001-M3001) | AB3001: =IF($A3001="","",IF($AK3001=1,'كشف المطالبة'!$D$5,'كشف المطالبة'!$D$6)*100) | AK3001: =IF($A3001="","",IF(OR($Q3001=TRUE(),$Q3001="TRUE"),1,0)) | AL3001: =IF($N3001="","",IF(MATCH($N3001,$N$2:$N$3001,0)=ROWS($N$2:$N3001),$N3001,""))

Sheet كشف المطالبة
A1: صيدلية د / woods pharma
B2: مطالبة مقدمة لشركة : التعاون للبترول | C2: ="عدد الروشتات : "&Check!$C$4 -> عدد الروشتات : 0 | D2: عن شهر : | F2: 1
B3: عاملين | C3: عائلات | D3: معاشات | E3: الجزء الاول | F3: 2
B4: اجمالى الادوية : | C4: =C5+C6 -> 0 | E4: عاملين | F4: 3
B5: اجمالى المحلى : | C5: =SUM(BAHARY!$H$2:$H$901) -> 0 | D5: 0.14 | E5: =C5*D5 -> 0 | F5: 4
B6: اجمالى المستورد : | C6: =SUM(BAHARY!$E$2:$E$901) -> 0 | D6: 0.07 | E6: =C6*D6 -> 0 | F6: 5
B7: اجمالى التحميل : | C7: =الاجمالى!$H$16 -> 0 | F7: 6
B8: اجمالى خصم المحلى و المستورد : | C8: =E6+E5 -> 0 | F8: 7
B9: اجمالى الادوية - التحميل | C9: =C4-C7 -> 0 | F9: 8
B10: الاجمالى بعد الخصم و التحميل : | C10: =C4-C8-C7 -> 0 | F10: 9
B11: المطلوب سداده | C11: =C4-C7-C8 -> 0 | F11: 10
B12: فقط لا غير | C12: =IFERROR(numbertotext(C11,"جنيه","قرشا"),"") | F12: 11
B13: الجزء الاول | C13: الجزء الثانى | D13: الجزء الثالث | E13: الجزء الرابع | F13: 12

Sheet الاجمالى
A1: شركة التعاون للبترول | E1: ="مطالبة صيدلية woods pharma عن شهر :"&'كشف المطالبة'!$E$2 -> مطالبة صيدلية woods pharma عن شهر : | H1: ="("&'كشف المطالبة'!E3&")" -> (الجزء الاول) | I1: ='كشف المطالبة'!E4 -> عاملين
A2: م | B2: محلى قبل الخصم | C2: مستورد قبل الخصم | D2: الاجمالى قبل الخصم | E2: ="محلى بعد خصم "&ROUND('كشف المطالبة'!$D$5*100,2)&"%" -> محلى بعد خصم 14% | F2: ="مستورد بعد خصم"&ROUND('كشف المطالبة'!$D$6*100,2)&"%" -> مستورد بعد خصم7% | G2: الاجمالى بعد الاخصم | H2: التحميل | I2: الصافى
A3: =IF(1<=Check!$C$5,1,"") | B3: =IF($A3="","",'كشف (1)'!D45) | C3: =IF($A3="","",'كشف (1)'!E45) | D3: =IF($A3="","",C3+B3) | E3: =IF($A3="","",'كشف (1)'!G45) | F3: =IF($A3="","",'كشف (1)'!H45) | G3: =IF($A3="","",F3+E3) | H3: =IF($A3="","",'كشف (1)'!K45) | I3: =IF($A3="","",'كشف (1)'!L45)
A4: =IF(2<=Check!$C$5,2,"") | B4: =IF($A4="","",'كشف (2)'!D45) | C4: =IF($A4="","",'كشف (2)'!E45) | D4: =IF($A4="","",C4+B4) | E4: =IF($A4="","",'كشف (2)'!G45) | F4: =IF($A4="","",'كشف (2)'!H45) | G4: =IF($A4="","",F4+E4) | H4: =IF($A4="","",'كشف (2)'!K45) | I4: =IF($A4="","",'كشف (2)'!L45)
A5: =IF(3<=Check!$C$5,3,"") | B5: =IF($A5="","",'كشف (3)'!D45) | C5: =IF($A5="","",'كشف (3)'!E45) | D5: =IF($A5="","",C5+B5) | E5: =IF($A5="","",'كشف (3)'!G45) | F5: =IF($A5="","",'كشف (3)'!H45) | G5: =IF($A5="","",F5+E5) | H5: =IF($A5="","",'كشف (3)'!K45) | I5: =IF($A5="","",'كشف (3)'!L45)
A6: =IF(4<=Check!$C$5,4,"") | B6: =IF($A6="","",'كشف (4)'!D45) | C6: =IF($A6="","",'كشف (4)'!E45) | D6: =IF($A6="","",C6+B6) | E6: =IF($A6="","",'كشف (4)'!G45) | F6: =IF($A6="","",'كشف (4)'!H45) | G6: =IF($A6="","",F6+E6) | H6: =IF($A6="","",'كشف (4)'!K45) | I6: =IF($A6="","",'كشف (4)'!L45)
A7: =IF(5<=Check!$C$5,5,"") | B7: =IF($A7="","",'كشف (5)'!D45) | C7: =IF($A7="","",'كشف (5)'!E45) | D7: =IF($A7="","",C7+B7) | E7: =IF($A7="","",'كشف (5)'!G45) | F7: =IF($A7="","",'كشف (5)'!H45) | G7: =IF($A7="","",F7+E7) | H7: =IF($A7="","",'كشف (5)'!K45) | I7: =IF($A7="","",'كشف (5)'!L45)
A8: =IF(6<=Check!$C$5,6,"") | B8: =IF($A8="","",'كشف (6)'!D45) | C8: =IF($A8="","",'كشف (6)'!E45) | D8: =IF($A8="","",C8+B8) | E8: =IF($A8="","",'كشف (6)'!G45) | F8: =IF($A8="","",'كشف (6)'!H45) | G8: =IF($A8="","",F8+E8) | H8: =IF($A8="","",'كشف (6)'!K45) | I8: =IF($A8="","",'كشف (6)'!L45)
A9: =IF(7<=Check!$C$5,7,"") | B9: =IF($A9="","",'كشف (7)'!D45) | C9: =IF($A9="","",'كشف (7)'!E45) | D9: =IF($A9="","",C9+B9) | E9: =IF($A9="","",'كشف (7)'!G45) | F9: =IF($A9="","",'كشف (7)'!H45) | G9: =IF($A9="","",F9+E9) | H9: =IF($A9="","",'كشف (7)'!K45) | I9: =IF($A9="","",'كشف (7)'!L45)
A10: =IF(8<=Check!$C$5,8,"") | B10: =IF($A10="","",'كشف (8)'!D45) | C10: =IF($A10="","",'كشف (8)'!E45) | D10: =IF($A10="","",C10+B10) | E10: =IF($A10="","",'كشف (8)'!G45) | F10: =IF($A10="","",'كشف (8)'!H45) | G10: =IF($A10="","",F10+E10) | H10: =IF($A10="","",'كشف (8)'!K45) | I10: =IF($A10="","",'كشف (8)'!L45)
A11: =IF(9<=Check!$C$5,9,"") | B11: =IF($A11="","",'كشف (9)'!D45) | C11: =IF($A11="","",'كشف (9)'!E45) | D11: =IF($A11="","",C11+B11) | E11: =IF($A11="","",'كشف (9)'!G45) | F11: =IF($A11="","",'كشف (9)'!H45) | G11: =IF($A11="","",F11+E11) | H11: =IF($A11="","",'كشف (9)'!K45) | I11: =IF($A11="","",'كشف (9)'!L45)
A12: =IF(10<=Check!$C$5,10,"") | B12: =IF($A12="","",'كشف (10)'!D45) | C12: =IF($A12="","",'كشف (10)'!E45) | D12: =IF($A12="","",C12+B12) | E12: =IF($A12="","",'كشف (10)'!G45) | F12: =IF($A12="","",'كشف (10)'!H45) | G12: =IF($A12="","",F12+E12) | H12: =IF($A12="","",'كشف (10)'!K45) | I12: =IF($A12="","",'كشف (10)'!L45)
A13: =IF(11<=Check!$C$5,11,"") | B13: =IF($A13="","",'كشف (11)'!D45) | C13: =IF($A13="","",'كشف (11)'!E45) | D13: =IF($A13="","",C13+B13) | E13: =IF($A13="","",'كشف (11)'!G45) | F13: =IF($A13="","",'كشف (11)'!H45) | G13: =IF($A13="","",F13+E13) | H13: =IF($A13="","",'كشف (11)'!K45) | I13: =IF($A13="","",'كشف (11)'!L45)
A14: =IF(12<=Check!$C$5,12,"") | B14: =IF($A14="","",'كشف (12)'!D45) | C14: =IF($A14="","",'كشف (12)'!E45) | D14: =IF($A14="","",C14+B14) | E14: =IF($A14="","",'كشف (12)'!G45) | F14: =IF($A14="","",'كشف (12)'!H45) | G14: =IF($A14="","",F14+E14) | H14: =IF($A14="","",'كشف (12)'!K45) | I14: =IF($A14="","",'كشف (12)'!L45)
B16: =SUM(B3:B14) -> 0 | C16: =SUM(C3:C14) -> 0 | D16: =SUM(D3:D14) -> 0 | E16: =SUM(E3:E14) -> 0 | F16: =SUM(F3:F14) -> 0 | G16: =SUM(G3:G14) -> 0 | H16: =SUM(H3:H14) -> 0 | I16: =SUM(I3:I14) -> 0

Sheet كشف  (1)
A1: شركة التعاون للبترول | E1: مطالبة صيدلية woods pharma عن شهر : | H1: ='كشف المطالبة'!E2 -> 0 | I1: ='كشف المطالبة'!E3 -> الجزء الاول | K1: ='كشف المطالبة'!E4 -> عاملين
A2: م | B2: الاسم | C2: رقم الأداء | D2: محلى قبل الخصم | E2: مستورد قبل الخصم | F2: الاجمالى قبل الخصم | G2: ="محلى بعد خصم "&ROUND('كشف المطالبة'!$D$5*100,2)&"%" -> محلى بعد خصم 14% | H2: ="مستورد بعد خصم "&ROUND('كشف المطالبة'!$D$6*100,2)&"%" -> مستورد بعد خصم 7% | I2: الاجمالى بعد الاخصم | J2: نسبة التحميل | K2: التحميل | L2: الصافى
A3: =IF(1<=Check!$C$4,INDEX(BAHARY!$A$2:$A$901,1),"") | B3: =IF($A3="","",INDEX(BAHARY!$B$2:$B$901,1)) | C3: =IF($A3="","",INDEX(BAHARY!$C$2:$C$901,1)) | D3: =IF($A3="","",INDEX(BAHARY!$H$2:$H$901,1)) | E3: =IF($A3="","",INDEX(BAHARY!$E$2:$E$901,1)) | F3: =IF($A3="","",D3+E3) | G3: =IF($A3="","",D3*(1-'كشف المطالبة'!$D$5)) | H3: =IF($A3="","",E3*(1-'كشف المطالبة'!$D$6)) | I3: =IF($A3="","",G3+H3) | J3: =IF($A3="","",0) | K3: =IF($A3="","",F3*J3+INDEX(BAHARY!$N$2:$N$901,1)) | L3: =IF($A3="","",I3-K3)
A4: =IF(2<=Check!$C$4,INDEX(BAHARY!$A$2:$A$901,2),"") | B4: =IF($A4="","",INDEX(BAHARY!$B$2:$B$901,2)) | C4: =IF($A4="","",INDEX(BAHARY!$C$2:$C$901,2)) | D4: =IF($A4="","",INDEX(BAHARY!$H$2:$H$901,2)) | E4: =IF($A4="","",INDEX(BAHARY!$E$2:$E$901,2)) | F4: =IF($A4="","",D4+E4) | G4: =IF($A4="","",D4*(1-'كشف المطالبة'!$D$5)) | H4: =IF($A4="","",E4*(1-'كشف المطالبة'!$D$6)) | I4: =IF($A4="","",G4+H4) | J4: =IF($A4="","",0) | K4: =IF($A4="","",F4*J4+INDEX(BAHARY!$N$2:$N$901,2)) | L4: =IF($A4="","",I4-K4)
A5: =IF(3<=Check!$C$4,INDEX(BAHARY!$A$2:$A$901,3),"") | B5: =IF($A5="","",INDEX(BAHARY!$B$2:$B$901,3)) | C5: =IF($A5="","",INDEX(BAHARY!$C$2:$C$901,3)) | D5: =IF($A5="","",INDEX(BAHARY!$H$2:$H$901,3)) | E5: =IF($A5="","",INDEX(BAHARY!$E$2:$E$901,3)) | F5: =IF($A5="","",D5+E5) | G5: =IF($A5="","",D5*(1-'كشف المطالبة'!$D$5)) | H5: =IF($A5="","",E5*(1-'كشف المطالبة'!$D$6)) | I5: =IF($A5="","",G5+H5) | J5: =IF($A5="","",0) | K5: =IF($A5="","",F5*J5+INDEX(BAHARY!$N$2:$N$901,3)) | L5: =IF($A5="","",I5-K5)
A6: =IF(4<=Check!$C$4,INDEX(BAHARY!$A$2:$A$901,4),"") | B6: =IF($A6="","",INDEX(BAHARY!$B$2:$B$901,4)) | C6: =IF($A6="","",INDEX(BAHARY!$C$2:$C$901,4)) | D6: =IF($A6="","",INDEX(BAHARY!$H$2:$H$901,4)) | E6: =IF($A6="","",INDEX(BAHARY!$E$2:$E$901,4)) | F6: =IF($A6="","",D6+E6) | G6: =IF($A6="","",D6*(1-'كشف المطالبة'!$D$5)) | H6: =IF($A6="","",E6*(1-'كشف المطالبة'!$D$6)) | I6: =IF($A6="","",G6+H6) | J6: =IF($A6="","",0) | K6: =IF($A6="","",F6*J6+INDEX(BAHARY!$N$2:$N$901,4)) | L6: =IF($A6="","",I6-K6)
A7: =IF(5<=Check!$C$4,INDEX(BAHARY!$A$2:$A$901,5),"") | B7: =IF($A7="","",INDEX(BAHARY!$B$2:$B$901,5)) | C7: =IF($A7="","",INDEX(BAHARY!$C$2:$C$901,5)) | D7: =IF($A7="","",INDEX(BAHARY!$H$2:$H$901,5)) | E7: =IF($A7="","",INDEX(BAHARY!$E$2:$E$901,5)) | F7: =IF($A7="","",D7+E7) | G7: =IF($A7="","",D7*(1-'كشف المطالبة'!$D$5)) | H7: =IF($A7="","",E7*(1-'كشف المطالبة'!$D$6)) | I7: =IF($A7="","",G7+H7) | J7: =IF($A7="","",0) | K7: =IF($A7="","",F7*J7+INDEX(BAHARY!$N$2:$N$901,5)) | L7: =IF($A7="","",I7-K7)
A8: =IF(6<=Check!$C$4,INDEX(BAHARY!$A$2:$A$901,6),"") | B8: =IF($A8="","",INDEX(BAHARY!$B$2:$B$901,6)) | C8: =IF($A8="","",INDEX(BAHARY!$C$2:$C$901,6)) | D8: =IF($A8="","",INDEX(BAHARY!$H$2:$H$901,6)) | E8: =IF($A8="","",INDEX(BAHARY!$E$2:$E$901,6)) | F8: =IF($A8="","",D8+E8) | G8: =IF($A8="","",D8*(1-'كشف المطالبة'!$D$5)) | H8: =IF($A8="","",E8*(1-'كشف المطالبة'!$D$6)) | I8: =IF($A8="","",G8+H8) | J8: =IF($A8="","",0) | K8: =IF($A8="","",F8*J8+INDEX(BAHARY!$N$2:$N$901,6)) | L8: =IF($A8="","",I8-K8)
A9: =IF(7<=Check!$C$4,INDEX(BAHARY!$A$2:$A$901,7),"") | B9: =IF($A9="","",INDEX(BAHARY!$B$2:$B$901,7)) | C9: =IF($A9="","",INDEX(BAHARY!$C$2:$C$901,7)) | D9: =IF($A9="","",INDEX(BAHARY!$H$2:$H$901,7)) | E9: =IF($A9="","",INDEX(BAHARY!$E$2:$E$901,7)) | F9: =IF($A9="","",D9+E9) | G9: =IF($A9="","",D9*(1-'كشف المطالبة'!$D$5)) | H9: =IF($A9="","",E9*(1-'كشف المطالبة'!$D$6)) | I9: =IF($A9="","",G9+H9) | J9: =IF($A9="","",0) | K9: =IF($A9="","",F9*J9+INDEX(BAHARY!$N$2:$N$901,7)) | L9: =IF($A9="","",I9-K9)
A10: =IF(8<=Check!$C$4,INDEX(BAHARY!$A$2:$A$901,8),"") | B10: =IF($A10="","",INDEX(BAHARY!$B$2:$B$901,8)) | C10: =IF($A10="","",INDEX(BAHARY!$C$2:$C$901,8)) | D10: =IF($A10="","",INDEX(BAHARY!$H$2:$H$901,8)) | E10: =IF($A10="","",INDEX(BAHARY!$E$2:$E$901,8)) | F10: =IF($A10="","",D10+E10) | G10: =IF($A10="","",D10*(1-'كشف المطالبة'!$D$5)) | H10: =IF($A10="","",E10*(1-'كشف المطالبة'!$D$6)) | I10: =IF($A10="","",G10+H10) | J10: =IF($A10="","",0) | K10: =IF($A10="","",F10*J10+INDEX(BAHARY!$N$2:$N$901,8)) | L10: =IF($A10="","",I10-K10)
A11: =IF(9<=Check!$C$4,INDEX(BAHARY!$A$2:$A$901,9),"") | B11: =IF($A11="","",INDEX(BAHARY!$B$2:$B$901,9)) | C11: =IF($A11="","",INDEX(BAHARY!$C$2:$C$901,9)) | D11: =IF($A11="","",INDEX(BAHARY!$H$2:$H$901,9)) | E11: =IF($A11="","",INDEX(BAHARY!$E$2:$E$901,9)) | F11: =IF($A11="","",D11+E11) | G11: =IF($A11="","",D11*(1-'كشف المطالبة'!$D$5)) | H11: =IF($A11="","",E11*(1-'كشف المطالبة'!$D$6)) | I11: =IF($A11="","",G11+H11) | J11: =IF($A11="","",0) | K11: =IF($A11="","",F11*J11+INDEX(BAHARY!$N$2:$N$901,9)) | L11: =IF($A11="","",I11-K11)
A12: =IF(10<=Check!$C$4,INDEX(BAHARY!$A$2:$A$901,10),"") | B12: =IF($A12="","",INDEX(BAHARY!$B$2:$B$901,10)) | C12: =IF($A12="","",INDEX(BAHARY!$C$2:$C$901,10)) | D12: =IF($A12="","",INDEX(BAHARY!$H$2:$H$901,10)) | E12: =IF($A12="","",INDEX(BAHARY!$E$2:$E$901,10)) | F12: =IF($A12="","",D12+E12) | G12: =IF($A12="","",D12*(1-'كشف المطالبة'!$D$5)) | H12: =IF($A12="","",E12*(1-'كشف المطالبة'!$D$6)) | I12: =IF($A12="","",G12+H12) | J12: =IF($A12="","",0) | K12: =IF($A12="","",F12*J12+INDEX(BAHARY!$N$2:$N$901,10)) | L12: =IF($A12="","",I12-K12)
A13: =IF(11<=Check!$C$4,INDEX(BAHARY!$A$2:$A$901,11),"") | B13: =IF($A13="","",INDEX(BAHARY!$B$2:$B$901,11)) | C13: =IF($A13="","",INDEX(BAHARY!$C$2:$C$901,11)) | D13: =IF($A13="","",INDEX(BAHARY!$H$2:$H$901,11)) | E13: =IF($A13="","",INDEX(BAHARY!$E$2:$E$901,11)) | F13: =IF($A13="","",D13+E13) | G13: =IF($A13="","",D13*(1-'كشف المطالبة'!$D$5)) | H13: =IF($A13="","",E13*(1-'كشف المطالبة'!$D$6)) | I13: =IF($A13="","",G13+H13) | J13: =IF($A13="","",0) | K13: =IF($A13="","",F13*J13+INDEX(BAHARY!$N$2:$N$901,11)) | L13: =IF($A13="","",I13-K13)
A14: =IF(12<=Check!$C$4,INDEX(BAHARY!$A$2:$A$901,12),"") | B14: =IF($A14="","",INDEX(BAHARY!$B$2:$B$901,12)) | C14: =IF($A14="","",INDEX(BAHARY!$C$2:$C$901,12)) | D14: =IF($A14="","",INDEX(BAHARY!$H$2:$H$901,12)) | E14: =IF($A14="","",INDEX(BAHARY!$E$2:$E$901,12)) | F14: =IF($A14="","",D14+E14) | G14: =IF($A14="","",D14*(1-'كشف المطالبة'!$D$5)) | H14: =IF($A14="","",E14*(1-'كشف المطالبة'!$D$6)) | I14: =IF($A14="","",G14+H14) | J14: =IF($A14="","",0) | K14: =IF($A14="","",F14*J14+INDEX(BAHARY!$N$2:$N$901,12)) | L14: =IF($A14="","",I14-K14)
A15: =IF(13<=Check!$C$4,INDEX(BAHARY!$A$2:$A$901,13),"") | B15: =IF($A15="","",INDEX(BAHARY!$B$2:$B$901,13)) | C15: =IF($A15="","",INDEX(BAHARY!$C$2:$C$901,13)) | D15: =IF($A15="","",INDEX(BAHARY!$H$2:$H$901,13)) | E15: =IF($A15="","",INDEX(BAHARY!$E$2:$E$901,13)) | F15: =IF($A15="","",D15+E15) | G15: =IF($A15="","",D15*(1-'كشف المطالبة'!$D$5)) | H15: =IF($A15="","",E15*(1-'كشف المطالبة'!$D$6)) | I15: =IF($A15="","",G15+H15) | J15: =IF($A15="","",0) | K15: =IF($A15="","",F15*J15+INDEX(BAHARY!$N$2:$N$901,13)) | L15: =IF($A15="","",I15-K15)
A16: =IF(14<=Check!$C$4,INDEX(BAHARY!$A$2:$A$901,14),"") | B16: =IF($A16="","",INDEX(BAHARY!$B$2:$B$901,14)) | C16: =IF($A16="","",INDEX(BAHARY!$C$2:$C$901,14)) | D16: =IF($A16="","",INDEX(BAHARY!$H$2:$H$901,14)) | E16: =IF($A16="","",INDEX(BAHARY!$E$2:$E$901,14)) | F16: =IF($A16="","",D16+E16) | G16: =IF($A16="","",D16*(1-'كشف المطالبة'!$D$5)) | H16: =IF($A16="","",E16*(1-'كشف المطالبة'!$D$6)) | I16: =IF($A16="","",G16+H16) | J16: =IF($A16="","",0) | K16: =IF($A16="","",F16*J16+INDEX(BAHARY!$N$2:$N$901,14)) | L16: =IF($A16="","",I16-K16)
A17: =IF(15<=Check!$C$4,INDEX(BAHARY!$A$2:$A$901,15),"") | B17: =IF($A17="","",INDEX(BAHARY!$B$2:$B$901,15)) | C17: =IF($A17="","",INDEX(BAHARY!$C$2:$C$901,15)) | D17: =IF($A17="","",INDEX(BAHARY!$H$2:$H$901,15)) | E17: =IF($A17="","",INDEX(BAHARY!$E$2:$E$901,15)) | F17: =IF($A17="","",D17+E17) | G17: =IF($A17="","",D17*(1-'كشف المطالبة'!$D$5)) | H17: =IF($A17="","",E17*(1-'كشف المطالبة'!$D$6)) | I17: =IF($A17="","",G17+H17) | J17: =IF($A17="","",0) | K17: =IF($A17="","",F17*J17+INDEX(BAHARY!$N$2:$N$901,15)) | L17: =IF($A17="","",I17-K17)
A18: =IF(16<=Check!$C$4,INDEX(BAHARY!$A$2:$A$901,16),"") | B18: =IF($A18="","",INDEX(BAHARY!$B$2:$B$901,16)) | C18: =IF($A18="","",INDEX(BAHARY!$C$2:$C$901,16)) | D18: =IF($A18="","",INDEX(BAHARY!$H$2:$H$901,16)) | E18: =IF($A18="","",INDEX(BAHARY!$E$2:$E$901,16)) | F18: =IF($A18="","",D18+E18) | G18: =IF($A18="","",D18*(1-'كشف المطالبة'!$D$5)) | H18: =IF($A18="","",E18*(1-'كشف المطالبة'!$D$6)) | I18: =IF($A18="","",G18+H18) | J18: =IF($A18="","",0) | K18: =IF($A18="","",F18*J18+INDEX(BAHARY!$N$2:$N$901,16)) | L18: =IF($A18="","",I18-K18)
A19: =IF(17<=Check!$C$4,INDEX(BAHARY!$A$2:$A$901,17),"") | B19: =IF($A19="","",INDEX(BAHARY!$B$2:$B$901,17)) | C19: =IF($A19="","",INDEX(BAHARY!$C$2:$C$901,17)) | D19: =IF($A19="","",INDEX(BAHARY!$H$2:$H$901,17)) | E19: =IF($A19="","",INDEX(BAHARY!$E$2:$E$901,17)) | F19: =IF($A19="","",D19+E19) | G19: =IF($A19="","",D19*(1-'كشف المطالبة'!$D$5)) | H19: =IF($A19="","",E19*(1-'كشف المطالبة'!$D$6)) | I19: =IF($A19="","",G19+H19) | J19: =IF($A19="","",0) | K19: =IF($A19="","",F19*J19+INDEX(BAHARY!$N$2:$N$901,17)) | L19: =IF($A19="","",I19-K19)
A20: =IF(18<=Check!$C$4,INDEX(BAHARY!$A$2:$A$901,18),"") | B20: =IF($A20="","",INDEX(BAHARY!$B$2:$B$901,18)) | C20: =IF($A20="","",INDEX(BAHARY!$C$2:$C$901,18)) | D20: =IF($A20="","",INDEX(BAHARY!$H$2:$H$901,18)) | E20: =IF($A20="","",INDEX(BAHARY!$E$2:$E$901,18)) | F20: =IF($A20="","",D20+E20) | G20: =IF($A20="","",D20*(1-'كشف المطالبة'!$D$5)) | H20: =IF($A20="","",E20*(1-'كشف المطالبة'!$D$6)) | I20: =IF($A20="","",G20+H20) | J20: =IF($A20="","",0) | K20: =IF($A20="","",F20*J20+INDEX(BAHARY!$N$2:$N$901,18)) | L20: =IF($A20="","",I20-K20)
A21: =IF(19<=Check!$C$4,INDEX(BAHARY!$A$2:$A$901,19),"") | B21: =IF($A21="","",INDEX(BAHARY!$B$2:$B$901,19)) | C21: =IF($A21="","",INDEX(BAHARY!$C$2:$C$901,19)) | D21: =IF($A21="","",INDEX(BAHARY!$H$2:$H$901,19)) | E21: =IF($A21="","",INDEX(BAHARY!$E$2:$E$901,19)) | F21: =IF($A21="","",D21+E21) | G21: =IF($A21="","",D21*(1-'كشف المطالبة'!$D$5)) | H21: =IF($A21="","",E21*(1-'كشف المطالبة'!$D$6)) | I21: =IF($A21="","",G21+H21) | J21: =IF($A21="","",0) | K21: =IF($A21="","",F21*J21+INDEX(BAHARY!$N$2:$N$901,19)) | L21: =IF($A21="","",I21-K21)
A22: =IF(20<=Check!$C$4,INDEX(BAHARY!$A$2:$A$901,20),"") | B22: =IF($A22="","",INDEX(BAHARY!$B$2:$B$901,20)) | C22: =IF($A22="","",INDEX(BAHARY!$C$2:$C$901,20)) | D22: =IF($A22="","",INDEX(BAHARY!$H$2:$H$901,20)) | E22: =IF($A22="","",INDEX(BAHARY!$E$2:$E$901,20)) | F22: =IF($A22="","",D22+E22) | G22: =IF($A22="","",D22*(1-'كشف المطالبة'!$D$5)) | H22: =IF($A22="","",E22*(1-'كشف المطالبة'!$D$6)) | I22: =IF($A22="","",G22+H22) | J22: =IF($A22="","",0) | K22: =IF($A22="","",F22*J22+INDEX(BAHARY!$N$2:$N$901,20)) | L22: =IF($A22="","",I22-K22)
A23: =IF(21<=Check!$C$4,INDEX(BAHARY!$A$2:$A$901,21),"") | B23: =IF($A23="","",INDEX(BAHARY!$B$2:$B$901,21)) | C23: =IF($A23="","",INDEX(BAHARY!$C$2:$C$901,21)) | D23: =IF($A23="","",INDEX(BAHARY!$H$2:$H$901,21)) | E23: =IF($A23="","",INDEX(BAHARY!$E$2:$E$901,21)) | F23: =IF($A23="","",D23+E23) | G23: =IF($A23="","",D23*(1-'كشف المطالبة'!$D$5)) | H23: =IF($A23="","",E23*(1-'كشف المطالبة'!$D$6)) | I23: =IF($A23="","",G23+H23) | J23: =IF($A23="","",0) | K23: =IF($A23="","",F23*J23+INDEX(BAHARY!$N$2:$N$901,21)) | L23: =IF($A23="","",I23-K23)
A24: =IF(22<=Check!$C$4,INDEX(BAHARY!$A$2:$A$901,22),"") | B24: =IF($A24="","",INDEX(BAHARY!$B$2:$B$901,22)) | C24: =IF($A24="","",INDEX(BAHARY!$C$2:$C$901,22)) | D24: =IF($A24="","",INDEX(BAHARY!$H$2:$H$901,22)) | E24: =IF($A24="","",INDEX(BAHARY!$E$2:$E$901,22)) | F24: =IF($A24="","",D24+E24) | G24: =IF($A24="","",D24*(1-'كشف المطالبة'!$D$5)) | H24: =IF($A24="","",E24*(1-'كشف المطالبة'!$D$6)) | I24: =IF($A24="","",G24+H24) | J24: =IF($A24="","",0) | K24: =IF($A24="","",F24*J24+INDEX(BAHARY!$N$2:$N$901,22)) | L24: =IF($A24="","",I24-K24)
A25: =IF(23<=Check!$C$4,INDEX(BAHARY!$A$2:$A$901,23),"") | B25: =IF($A25="","",INDEX(BAHARY!$B$2:$B$901,23)) | C25: =IF($A25="","",INDEX(BAHARY!$C$2:$C$901,23)) | D25: =IF($A25="","",INDEX(BAHARY!$H$2:$H$901,23)) | E25: =IF($A25="","",INDEX(BAHARY!$E$2:$E$901,23)) | F25: =IF($A25="","",D25+E25) | G25: =IF($A25="","",D25*(1-'كشف المطالبة'!$D$5)) | H25: =IF($A25="","",E25*(1-'كشف المطالبة'!$D$6)) | I25: =IF($A25="","",G25+H25) | J25: =IF($A25="","",0) | K25: =IF($A25="","",F25*J25+INDEX(BAHARY!$N$2:$N$901,23)) | L25: =IF($A25="","",I25-K25)
A26: =IF(24<=Check!$C$4,INDEX(BAHARY!$A$2:$A$901,24),"") | B26: =IF($A26="","",INDEX(BAHARY!$B$2:$B$901,24)) | C26: =IF($A26="","",INDEX(BAHARY!$C$2:$C$901,24)) | D26: =IF($A26="","",INDEX(BAHARY!$H$2:$H$901,24)) | E26: =IF($A26="","",INDEX(BAHARY!$E$2:$E$901,24)) | F26: =IF($A26="","",D26+E26) | G26: =IF($A26="","",D26*(1-'كشف المطالبة'!$D$5)) | H26: =IF($A26="","",E26*(1-'كشف المطالبة'!$D$6)) | I26: =IF($A26="","",G26+H26) | J26: =IF($A26="","",0) | K26: =IF($A26="","",F26*J26+INDEX(BAHARY!$N$2:$N$901,24)) | L26: =IF($A26="","",I26-K26)
A27: =IF(25<=Check!$C$4,INDEX(BAHARY!$A$2:$A$901,25),"") | B27: =IF($A27="","",INDEX(BAHARY!$B$2:$B$901,25)) | C27: =IF($A27="","",INDEX(BAHARY!$C$2:$C$901,25)) | D27: =IF($A27="","",INDEX(BAHARY!$H$2:$H$901,25)) | E27: =IF($A27="","",INDEX(BAHARY!$E$2:$E$901,25)) | F27: =IF($A27="","",D27+E27) | G27: =IF($A27="","",D27*(1-'كشف المطالبة'!$D$5)) | H27: =IF($A27="","",E27*(1-'كشف المطالبة'!$D$6)) | I27: =IF($A27="","",G27+H27) | J27: =IF($A27="","",0) | K27: =IF($A27="","",F27*J27+INDEX(BAHARY!$N$2:$N$901,25)) | L27: =IF($A27="","",I27-K27)
A28: =IF(26<=Check!$C$4,INDEX(BAHARY!$A$2:$A$901,26),"") | B28: =IF($A28="","",INDEX(BAHARY!$B$2:$B$901,26)) | C28: =IF($A28="","",INDEX(BAHARY!$C$2:$C$901,26)) | D28: =IF($A28="","",INDEX(BAHARY!$H$2:$H$901,26)) | E28: =IF($A28="","",INDEX(BAHARY!$E$2:$E$901,26)) | F28: =IF($A28="","",D28+E28) | G28: =IF($A28="","",D28*(1-'كشف المطالبة'!$D$5)) | H28: =IF($A28="","",E28*(1-'كشف المطالبة'!$D$6)) | I28: =IF($A28="","",G28+H28) | J28: =IF($A28="","",0) | K28: =IF($A28="","",F28*J28+INDEX(BAHARY!$N$2:$N$901,26)) | L28: =IF($A28="","",I28-K28)
A29: =IF(27<=Check!$C$4,INDEX(BAHARY!$A$2:$A$901,27),"") | B29: =IF($A29="","",INDEX(BAHARY!$B$2:$B$901,27)) | C29: =IF($A29="","",INDEX(BAHARY!$C$2:$C$901,27)) | D29: =IF($A29="","",INDEX(BAHARY!$H$2:$H$901,27)) | E29: =IF($A29="","",INDEX(BAHARY!$E$2:$E$901,27)) | F29: =IF($A29="","",D29+E29) | G29: =IF($A29="","",D29*(1-'كشف المطالبة'!$D$5)) | H29: =IF($A29="","",E29*(1-'كشف المطالبة'!$D$6)) | I29: =IF($A29="","",G29+H29) | J29: =IF($A29="","",0) | K29: =IF($A29="","",F29*J29+INDEX(BAHARY!$N$2:$N$901,27)) | L29: =IF($A29="","",I29-K29)
A30: =IF(28<=Check!$C$4,INDEX(BAHARY!$A$2:$A$901,28),"") | B30: =IF($A30="","",INDEX(BAHARY!$B$2:$B$901,28)) | C30: =IF($A30="","",INDEX(BAHARY!$C$2:$C$901,28)) | D30: =IF($A30="","",INDEX(BAHARY!$H$2:$H$901,28)) | E30: =IF($A30="","",INDEX(BAHARY!$E$2:$E$901,28)) | F30: =IF($A30="","",D30+E30) | G30: =IF($A30="","",D30*(1-'كشف المطالبة'!$D$5)) | H30: =IF($A30="","",E30*(1-'كشف المطالبة'!$D$6)) | I30: =IF($A30="","",G30+H30) | J30: =IF($A30="","",0) | K30: =IF($A30="","",F30*J30+INDEX(BAHARY!$N$2:$N$901,28)) | L30: =IF($A30="","",I30-K30)
A31: =IF(29<=Check!$C$4,INDEX(BAHARY!$A$2:$A$901,29),"") | B31: =IF($A31="","",INDEX(BAHARY!$B$2:$B$901,29)) | C31: =IF($A31="","",INDEX(BAHARY!$C$2:$C$901,29)) | D31: =IF($A31="","",INDEX(BAHARY!$H$2:$H$901,29)) | E31: =IF($A31="","",INDEX(BAHARY!$E$2:$E$901,29)) | F31: =IF($A31="","",D31+E31) | G31: =IF($A31="","",D31*(1-'كشف المطالبة'!$D$5)) | H31: =IF($A31="","",E31*(1-'كشف المطالبة'!$D$6)) | I31: =IF($A31="","",G31+H31) | J31: =IF($A31="","",0) | K31: =IF($A31="","",F31*J31+INDEX(BAHARY!$N$2:$N$901,29)) | L31: =IF($A31="","",I31-K31)
A32: =IF(30<=Check!$C$4,INDEX(BAHARY!$A$2:$A$901,30),"") | B32: =IF($A32="","",INDEX(BAHARY!$B$2:$B$901,30)) | C32: =IF($A32="","",INDEX(BAHARY!$C$2:$C$901,30)) | D32: =IF($A32="","",INDEX(BAHARY!$H$2:$H$901,30)) | E32: =IF($A32="","",INDEX(BAHARY!$E$2:$E$901,30)) | F32: =IF($A32="","",D32+E32) | G32: =IF($A32="","",D32*(1-'كشف المطالبة'!$D$5)) | H32: =IF($A32="","",E32*(1-'كشف المطالبة'!$D$6)) | I32: =IF($A32="","",G32+H32) | J32: =IF($A32="","",0) | K32: =IF($A32="","",F32*J32+INDEX(BAHARY!$N$2:$N$901,30)) | L32: =IF($A32="","",I32-K32)
A33: =IF(31<=Check!$C$4,INDEX(BAHARY!$A$2:$A$901,31),"") | B33: =IF($A33="","",INDEX(BAHARY!$B$2:$B$901,31)) | C33: =IF($A33="","",INDEX(BAHARY!$C$2:$C$901,31)) | D33: =IF($A33="","",INDEX(BAHARY!$H$2:$H$901,31)) | E33: =IF($A33="","",INDEX(BAHARY!$E$2:$E$901,31)) | F33: =IF($A33="","",D33+E33) | G33: =IF($A33="","",D33*(1-'كشف المطالبة'!$D$5)) | H33: =IF($A33="","",E33*(1-'كشف المطالبة'!$D$6)) | I33: =IF($A33="","",G33+H33) | J33: =IF($A33="","",0) | K33: =IF($A33="","",F33*J33+INDEX(BAHARY!$N$2:$N$901,31)) | L33: =IF($A33="","",I33-K33)
A34: =IF(32<=Check!$C$4,INDEX(BAHARY!$A$2:$A$901,32),"") | B34: =IF($A34="","",INDEX(BAHARY!$B$2:$B$901,32)) | C34: =IF($A34="","",INDEX(BAHARY!$C$2:$C$901,32)) | D34: =IF($A34="","",INDEX(BAHARY!$H$2:$H$901,32)) | E34: =IF($A34="","",INDEX(BAHARY!$E$2:$E$901,32)) | F34: =IF($A34="","",D34+E34) | G34: =IF($A34="","",D34*(1-'كشف المطالبة'!$D$5)) | H34: =IF($A34="","",E34*(1-'كشف المطالبة'!$D$6)) | I34: =IF($A34="","",G34+H34) | J34: =IF($A34="","",0) | K34: =IF($A34="","",F34*J34+INDEX(BAHARY!$N$2:$N$901,32)) | L34: =IF($A34="","",I34-K34)
A35: =IF(33<=Check!$C$4,INDEX(BAHARY!$A$2:$A$901,33),"") | B35: =IF($A35="","",INDEX(BAHARY!$B$2:$B$901,33)) | C35: =IF($A35="","",INDEX(BAHARY!$C$2:$C$901,33)) | D35: =IF($A35="","",INDEX(BAHARY!$H$2:$H$901,33)) | E35: =IF($A35="","",INDEX(BAHARY!$E$2:$E$901,33)) | F35: =IF($A35="","",D35+E35) | G35: =IF($A35="","",D35*(1-'كشف المطالبة'!$D$5)) | H35: =IF($A35="","",E35*(1-'كشف المطالبة'!$D$6)) | I35: =IF($A35="","",G35+H35) | J35: =IF($A35="","",0) | K35: =IF($A35="","",F35*J35+INDEX(BAHARY!$N$2:$N$901,33)) | L35: =IF($A35="","",I35-K35)
A36: =IF(34<=Check!$C$4,INDEX(BAHARY!$A$2:$A$901,34),"") | B36: =IF($A36="","",INDEX(BAHARY!$B$2:$B$901,34)) | C36: =IF($A36="","",INDEX(BAHARY!$C$2:$C$901,34)) | D36: =IF($A36="","",INDEX(BAHARY!$H$2:$H$901,34)) | E36: =IF($A36="","",INDEX(BAHARY!$E$2:$E$901,34)) | F36: =IF($A36="","",D36+E36) | G36: =IF($A36="","",D36*(1-'كشف المطالبة'!$D$5)) | H36: =IF($A36="","",E36*(1-'كشف المطالبة'!$D$6)) | I36: =IF($A36="","",G36+H36) | J36: =IF($A36="","",0) | K36: =IF($A36="","",F36*J36+INDEX(BAHARY!$N$2:$N$901,34)) | L36: =IF($A36="","",I36-K36)
A37: =IF(35<=Check!$C$4,INDEX(BAHARY!$A$2:$A$901,35),"") | B37: =IF($A37="","",INDEX(BAHARY!$B$2:$B$901,35)) | C37: =IF($A37="","",INDEX(BAHARY!$C$2:$C$901,35)) | D37: =IF($A37="","",INDEX(BAHARY!$H$2:$H$901,35)) | E37: =IF($A37="","",INDEX(BAHARY!$E$2:$E$901,35)) | F37: =IF($A37="","",D37+E37) | G37: =IF($A37="","",D37*(1-'كشف المطالبة'!$D$5)) | H37: =IF($A37="","",E37*(1-'كشف المطالبة'!$D$6)) | I37: =IF($A37="","",G37+H37) | J37: =IF($A37="","",0) | K37: =IF($A37="","",F37*J37+INDEX(BAHARY!$N$2:$N$901,35)) | L37: =IF($A37="","",I37-K37)
A38: =IF(36<=Check!$C$4,INDEX(BAHARY!$A$2:$A$901,36),"") | B38: =IF($A38="","",INDEX(BAHARY!$B$2:$B$901,36)) | C38: =IF($A38="","",INDEX(BAHARY!$C$2:$C$901,36)) | D38: =IF($A38="","",INDEX(BAHARY!$H$2:$H$901,36)) | E38: =IF($A38="","",INDEX(BAHARY!$E$2:$E$901,36)) | F38: =IF($A38="","",D38+E38) | G38: =IF($A38="","",D38*(1-'كشف المطالبة'!$D$5)) | H38: =IF($A38="","",E38*(1-'كشف المطالبة'!$D$6)) | I38: =IF($A38="","",G38+H38) | J38: =IF($A38="","",0) | K38: =IF($A38="","",F38*J38+INDEX(BAHARY!$N$2:$N$901,36)) | L38: =IF($A38="","",I38-K38)
A39: =IF(37<=Check!$C$4,INDEX(BAHARY!$A$2:$A$901,37),"") | B39: =IF($A39="","",INDEX(BAHARY!$B$2:$B$901,37)) | C39: =IF($A39="","",INDEX(BAHARY!$C$2:$C$901,37)) | D39: =IF($A39="","",INDEX(BAHARY!$H$2:$H$901,37)) | E39: =IF($A39="","",INDEX(BAHARY!$E$2:$E$901,37)) | F39: =IF($A39="","",D39+E39) | G39: =IF($A39="","",D39*(1-'كشف المطالبة'!$D$5)) | H39: =IF($A39="","",E39*(1-'كشف المطالبة'!$D$6)) | I39: =IF($A39="","",G39+H39) | J39: =IF($A39="","",0) | K39: =IF($A39="","",F39*J39+INDEX(BAHARY!$N$2:$N$901,37)) | L39: =IF($A39="","",I39-K39)
A40: =IF(38<=Check!$C$4,INDEX(BAHARY!$A$2:$A$901,38),"") | B40: =IF($A40="","",INDEX(BAHARY!$B$2:$B$901,38)) | C40: =IF($A40="","",INDEX(BAHARY!$C$2:$C$901,38)) | D40: =IF($A40="","",INDEX(BAHARY!$H$2:$H$901,38)) | E40: =IF($A40="","",INDEX(BAHARY!$E$2:$E$901,38)) | F40: =IF($A40="","",D40+E40) | G40: =IF($A40="","",D40*(1-'كشف المطالبة'!$D$5)) | H40: =IF($A40="","",E40*(1-'كشف المطالبة'!$D$6)) | I40: =IF($A40="","",G40+H40) | J40: =IF($A40="","",0) | K40: =IF($A40="","",F40*J40+INDEX(BAHARY!$N$2:$N$901,38)) | L40: =IF($A40="","",I40-K40)
...

Sheet كشف  (2)
A1: شركة التعاون للبترول | E1: مطالبة صيدلية woods pharma عن شهر : | H1: ='كشف المطالبة'!E2 -> 0 | I1: ='كشف المطالبة'!E3 -> الجزء الاول | K1: ='كشف المطالبة'!E4 -> عاملين
A2: م | B2: الاسم | C2: رقم الأداء | D2: محلى قبل الخصم | E2: مستورد قبل الخصم | F2: الاجمالى قبل الخصم | G2: ="محلى بعد خصم "&ROUND('كشف المطالبة'!$D$5*100,2)&"%" -> محلى بعد خصم 14% | H2: ="مستورد بعد خصم "&ROUND('كشف المطالبة'!$D$6*100,2)&"%" -> مستورد بعد خصم 7% | I2: الاجمالى بعد الاخصم | J2: نسبة التحميل | K2: التحميل | L2: الصافى
A3: =IF(41<=Check!$C$4,INDEX(BAHARY!$A$2:$A$901,41),"") | B3: =IF($A3="","",INDEX(BAHARY!$B$2:$B$901,41)) | C3: =IF($A3="","",INDEX(BAHARY!$C$2:$C$901,41)) | D3: =IF($A3="","",INDEX(BAHARY!$H$2:$H$901,41)) | E3: =IF($A3="","",INDEX(BAHARY!$E$2:$E$901,41)) | F3: =IF($A3="","",D3+E3) | G3: =IF($A3="","",D3*(1-'كشف المطالبة'!$D$5)) | H3: =IF($A3="","",E3*(1-'كشف المطالبة'!$D$6)) | I3: =IF($A3="","",G3+H3) | J3: =IF($A3="","",0) | K3: =IF($A3="","",F3*J3+INDEX(BAHARY!$N$2:$N$901,41)) | L3: =IF($A3="","",I3-K3)
A4: =IF(42<=Check!$C$4,INDEX(BAHARY!$A$2:$A$901,42),"") | B4: =IF($A4="","",INDEX(BAHARY!$B$2:$B$901,42)) | C4: =IF($A4="","",INDEX(BAHARY!$C$2:$C$901,42)) | D4: =IF($A4="","",INDEX(BAHARY!$H$2:$H$901,42)) | E4: =IF($A4="","",INDEX(BAHARY!$E$2:$E$901,42)) | F4: =IF($A4="","",D4+E4) | G4: =IF($A4="","",D4*(1-'كشف المطالبة'!$D$5)) | H4: =IF($A4="","",E4*(1-'كشف المطالبة'!$D$6)) | I4: =IF($A4="","",G4+H4) | J4: =IF($A4="","",0) | K4: =IF($A4="","",F4*J4+INDEX(BAHARY!$N$2:$N$901,42)) | L4: =IF($A4="","",I4-K4)
A5: =IF(43<=Check!$C$4,INDEX(BAHARY!$A$2:$A$901,43),"") | B5: =IF($A5="","",INDEX(BAHARY!$B$2:$B$901,43)) | C5: =IF($A5="","",INDEX(BAHARY!$C$2:$C$901,43)) | D5: =IF($A5="","",INDEX(BAHARY!$H$2:$H$901,43)) | E5: =IF($A5="","",INDEX(BAHARY!$E$2:$E$901,43)) | F5: =IF($A5="","",D5+E5) | G5: =IF($A5="","",D5*(1-'كشف المطالبة'!$D$5)) | H5: =IF($A5="","",E5*(1-'كشف المطالبة'!$D$6)) | I5: =IF($A5="","",G5+H5) | J5: =IF($A5="","",0) | K5: =IF($A5="","",F5*J5+INDEX(BAHARY!$N$2:$N$901,43)) | L5: =IF($A5="","",I5-K5)
A6: =IF(44<=Check!$C$4,INDEX(BAHARY!$A$2:$A$901,44),"") | B6: =IF($A6="","",INDEX(BAHARY!$B$2:$B$901,44)) | C6: =IF($A6="","",INDEX(BAHARY!$C$2:$C$901,44)) | D6: =IF($A6="","",INDEX(BAHARY!$H$2:$H$901,44)) | E6: =IF($A6="","",INDEX(BAHARY!$E$2:$E$901,44)) | F6: =IF($A6="","",D6+E6) | G6: =IF($A6="","",D6*(1-'كشف المطالبة'!$D$5)) | H6: =IF($A6="","",E6*(1-'كشف المطالبة'!$D$6)) | I6: =IF($A6="","",G6+H6) | J6: =IF($A6="","",0) | K6: =IF($A6="","",F6*J6+INDEX(BAHARY!$N$2:$N$901,44)) | L6: =IF($A6="","",I6-K6)
A7: =IF(45<=Check!$C$4,INDEX(BAHARY!$A$2:$A$901,45),"") | B7: =IF($A7="","",INDEX(BAHARY!$B$2:$B$901,45)) | C7: =IF($A7="","",INDEX(BAHARY!$C$2:$C$901,45)) | D7: =IF($A7="","",INDEX(BAHARY!$H$2:$H$901,45)) | E7: =IF($A7="","",INDEX(BAHARY!$E$2:$E$901,45)) | F7: =IF($A7="","",D7+E7) | G7: =IF($A7="","",D7*(1-'كشف المطالبة'!$D$5)) | H7: =IF($A7="","",E7*(1-'كشف المطالبة'!$D$6)) | I7: =IF($A7="","",G7+H7) | J7: =IF($A7="","",0) | K7: =IF($A7="","",F7*J7+INDEX(BAHARY!$N$2:$N$901,45)) | L7: =IF($A7="","",I7-K7)
A8: =IF(46<=Check!$C$4,INDEX(BAHARY!$A$2:$A$901,46),"") | B8: =IF($A8="","",INDEX(BAHARY!$B$2:$B$901,46)) | C8: =IF($A8="","",INDEX(BAHARY!$C$2:$C$901,46)) | D8: =IF($A8="","",INDEX(BAHARY!$H$2:$H$901,46)) | E8: =IF($A8="","",INDEX(BAHARY!$E$2:$E$901,46)) | F8: =IF($A8="","",D8+E8) | G8: =IF($A8="","",D8*(1-'كشف المطالبة'!$D$5)) | H8: =IF($A8="","",E8*(1-'كشف المطالبة'!$D$6)) | I8: =IF($A8="","",G8+H8) | J8: =IF($A8="","",0) | K8: =IF($A8="","",F8*J8+INDEX(BAHARY!$N$2:$N$901,46)) | L8: =IF($A8="","",I8-K8)
A9: =IF(47<=Check!$C$4,INDEX(BAHARY!$A$2:$A$901,47),"") | B9: =IF($A9="","",INDEX(BAHARY!$B$2:$B$901,47)) | C9: =IF($A9="","",INDEX(BAHARY!$C$2:$C$901,47)) | D9: =IF($A9="","",INDEX(BAHARY!$H$2:$H$901,47)) | E9: =IF($A9="","",INDEX(BAHARY!$E$2:$E$901,47)) | F9: =IF($A9="","",D9+E9) | G9: =IF($A9="","",D9*(1-'كشف المطالبة'!$D$5)) | H9: =IF($A9="","",E9*(1-'كشف المطالبة'!$D$6)) | I9: =IF($A9="","",G9+H9) | J9: =IF($A9="","",0) | K9: =IF($A9="","",F9*J9+INDEX(BAHARY!$N$2:$N$901,47)) | L9: =IF($A9="","",I9-K9)
A10: =IF(48<=Check!$C$4,INDEX(BAHARY!$A$2:$A$901,48),"") | B10: =IF($A10="","",INDEX(BAHARY!$B$2:$B$901,48)) | C10: =IF($A10="","",INDEX(BAHARY!$C$2:$C$901,48)) | D10: =IF($A10="","",INDEX(BAHARY!$H$2:$H$901,48)) | E10: =IF($A10="","",INDEX(BAHARY!$E$2:$E$901,48)) | F10: =IF($A10="","",D10+E10) | G10: =IF($A10="","",D10*(1-'كشف المطالبة'!$D$5)) | H10: =IF($A10="","",E10*(1-'كشف المطالبة'!$D$6)) | I10: =IF($A10="","",G10+H10) | J10: =IF($A10="","",0) | K10: =IF($A10="","",F10*J10+INDEX(BAHARY!$N$2:$N$901,48)) | L10: =IF($A10="","",I10-K10)
A11: =IF(49<=Check!$C$4,INDEX(BAHARY!$A$2:$A$901,49),"") | B11: =IF($A11="","",INDEX(BAHARY!$B$2:$B$901,49)) | C11: =IF($A11="","",INDEX(BAHARY!$C$2:$C$901,49)) | D11: =IF($A11="","",INDEX(BAHARY!$H$2:$H$901,49)) | E11: =IF($A11="","",INDEX(BAHARY!$E$2:$E$901,49)) | F11: =IF($A11="","",D11+E11) | G11: =IF($A11="","",D11*(1-'كشف المطالبة'!$D$5)) | H11: =IF($A11="","",E11*(1-'كشف المطالبة'!$D$6)) | I11: =IF($A11="","",G11+H11) | J11: =IF($A11="","",0) | K11: =IF($A11="","",F11*J11+INDEX(BAHARY!$N$2:$N$901,49)) | L11: =IF($A11="","",I11-K11)
A12: =IF(50<=Check!$C$4,INDEX(BAHARY!$A$2:$A$901,50),"") | B12: =IF($A12="","",INDEX(BAHARY!$B$2:$B$901,50)) | C12: =IF($A12="","",INDEX(BAHARY!$C$2:$C$901,50)) | D12: =IF($A12="","",INDEX(BAHARY!$H$2:$H$901,50)) | E12: =IF($A12="","",INDEX(BAHARY!$E$2:$E$901,50)) | F12: =IF($A12="","",D12+E12) | G12: =IF($A12="","",D12*(1-'كشف المطالبة'!$D$5)) | H12: =IF($A12="","",E12*(1-'كشف المطالبة'!$D$6)) | I12: =IF($A12="","",G12+H12) | J12: =IF($A12="","",0) | K12: =IF($A12="","",F12*J12+INDEX(BAHARY!$N$2:$N$901,50)) | L12: =IF($A12="","",I12-K12)
A13: =IF(51<=Check!$C$4,INDEX(BAHARY!$A$2:$A$901,51),"") | B13: =IF($A13="","",INDEX(BAHARY!$B$2:$B$901,51)) | C13: =IF($A13="","",INDEX(BAHARY!$C$2:$C$901,51)) | D13: =IF($A13="","",INDEX(BAHARY!$H$2:$H$901,51)) | E13: =IF($A13="","",INDEX(BAHARY!$E$2:$E$901,51)) | F13: =IF($A13="","",D13+E13) | G13: =IF($A13="","",D13*(1-'كشف المطالبة'!$D$5)) | H13: =IF($A13="","",E13*(1-'كشف المطالبة'!$D$6)) | I13: =IF($A13="","",G13+H13) | J13: =IF($A13="","",0) | K13: =IF($A13="","",F13*J13+INDEX(BAHARY!$N$2:$N$901,51)) | L13: =IF($A13="","",I13-K13)
A14: =IF(52<=Check!$C$4,INDEX(BAHARY!$A$2:$A$901,52),"") | B14: =IF($A14="","",INDEX(BAHARY!$B$2:$B$901,52)) | C14: =IF($A14="","",INDEX(BAHARY!$C$2:$C$901,52)) | D14: =IF($A14="","",INDEX(BAHARY!$H$2:$H$901,52)) | E14: =IF($A14="","",INDEX(BAHARY!$E$2:$E$901,52)) | F14: =IF($A14="","",D14+E14) | G14: =IF($A14="","",D14*(1-'كشف المطالبة'!$D$5)) | H14: =IF($A14="","",E14*(1-'كشف المطالبة'!$D$6)) | I14: =IF($A14="","",G14+H14) | J14: =IF($A14="","",0) | K14: =IF($A14="","",F14*J14+INDEX(BAHARY!$N$2:$N$901,52)) | L14: =IF($A14="","",I14-K14)
A15: =IF(53<=Check!$C$4,INDEX(BAHARY!$A$2:$A$901,53),"") | B15: =IF($A15="","",INDEX(BAHARY!$B$2:$B$901,53)) | C15: =IF($A15="","",INDEX(BAHARY!$C$2:$C$901,53)) | D15: =IF($A15="","",INDEX(BAHARY!$H$2:$H$901,53)) | E15: =IF($A15="","",INDEX(BAHARY!$E$2:$E$901,53)) | F15: =IF($A15="","",D15+E15) | G15: =IF($A15="","",D15*(1-'كشف المطالبة'!$D$5)) | H15: =IF($A15="","",E15*(1-'كشف المطالبة'!$D$6)) | I15: =IF($A15="","",G15+H15) | J15: =IF($A15="","",0) | K15: =IF($A15="","",F15*J15+INDEX(BAHARY!$N$2:$N$901,53)) | L15: =IF($A15="","",I15-K15)
A16: =IF(54<=Check!$C$4,INDEX(BAHARY!$A$2:$A$901,54),"") | B16: =IF($A16="","",INDEX(BAHARY!$B$2:$B$901,54)) | C16: =IF($A16="","",INDEX(BAHARY!$C$2:$C$901,54)) | D16: =IF($A16="","",INDEX(BAHARY!$H$2:$H$901,54)) | E16: =IF($A16="","",INDEX(BAHARY!$E$2:$E$901,54)) | F16: =IF($A16="","",D16+E16) | G16: =IF($A16="","",D16*(1-'كشف المطالبة'!$D$5)) | H16: =IF($A16="","",E16*(1-'كشف المطالبة'!$D$6)) | I16: =IF($A16="","",G16+H16) | J16: =IF($A16="","",0) | K16: =IF($A16="","",F16*J16+INDEX(BAHARY!$N$2:$N$901,54)) | L16: =IF($A16="","",I16-K16)
A17: =IF(55<=Check!$C$4,INDEX(BAHARY!$A$2:$A$901,55),"") | B17: =IF($A17="","",INDEX(BAHARY!$B$2:$B$901,55)) | C17: =IF($A17="","",INDEX(BAHARY!$C$2:$C$901,55)) | D17: =IF($A17="","",INDEX(BAHARY!$H$2:$H$901,55)) | E17: =IF($A17="","",INDEX(BAHARY!$E$2:$E$901,55)) | F17: =IF($A17="","",D17+E17) | G17: =IF($A17="","",D17*(1-'كشف المطالبة'!$D$5)) | H17: =IF($A17="","",E17*(1-'كشف المطالبة'!$D$6)) | I17: =IF($A17="","",G17+H17) | J17: =IF($A17="","",0) | K17: =IF($A17="","",F17*J17+INDEX(BAHARY!$N$2:$N$901,55)) | L17: =IF($A17="","",I17-K17)
A18: =IF(56<=Check!$C$4,INDEX(BAHARY!$A$2:$A$901,56),"") | B18: =IF($A18="","",INDEX(BAHARY!$B$2:$B$901,56)) | C18: =IF($A18="","",INDEX(BAHARY!$C$2:$C$901,56)) | D18: =IF($A18="","",INDEX(BAHARY!$H$2:$H$901,56)) | E18: =IF($A18="","",INDEX(BAHARY!$E$2:$E$901,56)) | F18: =IF($A18="","",D18+E18) | G18: =IF($A18="","",D18*(1-'كشف المطالبة'!$D$5)) | H18: =IF($A18="","",E18*(1-'كشف المطالبة'!$D$6)) | I18: =IF($A18="","",G18+H18) | J18: =IF($A18="","",0) | K18: =IF($A18="","",F18*J18+INDEX(BAHARY!$N$2:$N$901,56)) | L18: =IF($A18="","",I18-K18)
A19: =IF(57<=Check!$C$4,INDEX(BAHARY!$A$2:$A$901,57),"") | B19: =IF($A19="","",INDEX(BAHARY!$B$2:$B$901,57)) | C19: =IF($A19="","",INDEX(BAHARY!$C$2:$C$901,57)) | D19: =IF($A19="","",INDEX(BAHARY!$H$2:$H$901,57)) | E19: =IF($A19="","",INDEX(BAHARY!$E$2:$E$901,57)) | F19: =IF($A19="","",D19+E19) | G19: =IF($A19="","",D19*(1-'كشف المطالبة'!$D$5)) | H19: =IF($A19="","",E19*(1-'كشف المطالبة'!$D$6)) | I19: =IF($A19="","",G19+H19) | J19: =IF($A19="","",0) | K19: =IF($A19="","",F19*J19+INDEX(BAHARY!$N$2:$N$901,57)) | L19: =IF($A19="","",I19-K19)
A20: =IF(58<=Check!$C$4,INDEX(BAHARY!$A$2:$A$901,58),"") | B20: =IF($A20="","",INDEX(BAHARY!$B$2:$B$901,58)) | C20: =IF($A20="","",INDEX(BAHARY!$C$2:$C$901,58)) | D20: =IF($A20="","",INDEX(BAHARY!$H$2:$H$901,58)) | E20: =IF($A20="","",INDEX(BAHARY!$E$2:$E$901,58)) | F20: =IF($A20="","",D20+E20) | G20: =IF($A20="","",D20*(1-'كشف المطالبة'!$D$5)) | H20: =IF($A20="","",E20*(1-'كشف المطالبة'!$D$6)) | I20: =IF($A20="","",G20+H20) | J20: =IF($A20="","",0) | K20: =IF($A20="","",F20*J20+INDEX(BAHARY!$N$2:$N$901,58)) | L20: =IF($A20="","",I20-K20)
A21: =IF(59<=Check!$C$4,INDEX(BAHARY!$A$2:$A$901,59),"") | B21: =IF($A21="","",INDEX(BAHARY!$B$2:$B$901,59)) | C21: =IF($A21="","",INDEX(BAHARY!$C$2:$C$901,59)) | D21: =IF($A21="","",INDEX(BAHARY!$H$2:$H$901,59)) | E21: =IF($A21="","",INDEX(BAHARY!$E$2:$E$901,59)) | F21: =IF($A21="","",D21+E21) | G21: =IF($A21="","",D21*(1-'كشف المطالبة'!$D$5)) | H21: =IF($A21="","",E21*(1-'كشف المطالبة'!$D$6)) | I21: =IF($A21="","",G21+H21) | J21: =IF($A21="","",0) | K21: =IF($A21="","",F21*J21+INDEX(BAHARY!$N$2:$N$901,59)) | L21: =IF($A21="","",I21-K21)
A22: =IF(60<=Check!$C$4,INDEX(BAHARY!$A$2:$A$901,60),"") | B22: =IF($A22="","",INDEX(BAHARY!$B$2:$B$901,60)) | C22: =IF($A22="","",INDEX(BAHARY!$C$2:$C$901,60)) | D22: =IF($A22="","",INDEX(BAHARY!$H$2:$H$901,60)) | E22: =IF($A22="","",INDEX(BAHARY!$E$2:$E$901,60)) | F22: =IF($A22="","",D22+E22) | G22: =IF($A22="","",D22*(1-'كشف المطالبة'!$D$5)) | H22: =IF($A22="","",E22*(1-'كشف المطالبة'!$D$6)) | I22: =IF($A22="","",G22+H22) | J22: =IF($A22="","",0) | K22: =IF($A22="","",F22*J22+INDEX(BAHARY!$N$2:$N$901,60)) | L22: =IF($A22="","",I22-K22)
A23: =IF(61<=Check!$C$4,INDEX(BAHARY!$A$2:$A$901,61),"") | B23: =IF($A23="","",INDEX(BAHARY!$B$2:$B$901,61)) | C23: =IF($A23="","",INDEX(BAHARY!$C$2:$C$901,61)) | D23: =IF($A23="","",INDEX(BAHARY!$H$2:$H$901,61)) | E23: =IF($A23="","",INDEX(BAHARY!$E$2:$E$901,61)) | F23: =IF($A23="","",D23+E23) | G23: =IF($A23="","",D23*(1-'كشف المطالبة'!$D$5)) | H23: =IF($A23="","",E23*(1-'كشف المطالبة'!$D$6)) | I23: =IF($A23="","",G23+H23) | J23: =IF($A23="","",0) | K23: =IF($A23="","",F23*J23+INDEX(BAHARY!$N$2:$N$901,61)) | L23: =IF($A23="","",I23-K23)
A24: =IF(62<=Check!$C$4,INDEX(BAHARY!$A$2:$A$901,62),"") | B24: =IF($A24="","",INDEX(BAHARY!$B$2:$B$901,62)) | C24: =IF($A24="","",INDEX(BAHARY!$C$2:$C$901,62)) | D24: =IF($A24="","",INDEX(BAHARY!$H$2:$H$901,62)) | E24: =IF($A24="","",INDEX(BAHARY!$E$2:$E$901,62)) | F24: =IF($A24="","",D24+E24) | G24: =IF($A24="","",D24*(1-'كشف المطالبة'!$D$5)) | H24: =IF($A24="","",E24*(1-'كشف المطالبة'!$D$6)) | I24: =IF($A24="","",G24+H24) | J24: =IF($A24="","",0) | K24: =IF($A24="","",F24*J24+INDEX(BAHARY!$N$2:$N$901,62)) | L24: =IF($A24="","",I24-K24)
A25: =IF(63<=Check!$C$4,INDEX(BAHARY!$A$2:$A$901,63),"") | B25: =IF($A25="","",INDEX(BAHARY!$B$2:$B$901,63)) | C25: =IF($A25="","",INDEX(BAHARY!$C$2:$C$901,63)) | D25: =IF($A25="","",INDEX(BAHARY!$H$2:$H$901,63)) | E25: =IF($A25="","",INDEX(BAHARY!$E$2:$E$901,63)) | F25: =IF($A25="","",D25+E25) | G25: =IF($A25="","",D25*(1-'كشف المطالبة'!$D$5)) | H25: =IF($A25="","",E25*(1-'كشف المطالبة'!$D$6)) | I25: =IF($A25="","",G25+H25) | J25: =IF($A25="","",0) | K25: =IF($A25="","",F25*J25+INDEX(BAHARY!$N$2:$N$901,63)) | L25: =IF($A25="","",I25-K25)
A26: =IF(64<=Check!$C$4,INDEX(BAHARY!$A$2:$A$901,64),"") | B26: =IF($A26="","",INDEX(BAHARY!$B$2:$B$901,64)) | C26: =IF($A26="","",INDEX(BAHARY!$C$2:$C$901,64)) | D26: =IF($A26="","",INDEX(BAHARY!$H$2:$H$901,64)) | E26: =IF($A26="","",INDEX(BAHARY!$E$2:$E$901,64)) | F26: =IF($A26="","",D26+E26) | G26: =IF($A26="","",D26*(1-'كشف المطالبة'!$D$5)) | H26: =IF($A26="","",E26*(1-'كشف المطالبة'!$D$6)) | I26: =IF($A26="","",G26+H26) | J26: =IF($A26="","",0) | K26: =IF($A26="","",F26*J26+INDEX(BAHARY!$N$2:$N$901,64)) | L26: =IF($A26="","",I26-K26)
A27: =IF(65<=Check!$C$4,INDEX(BAHARY!$A$2:$A$901,65),"") | B27: =IF($A27="","",INDEX(BAHARY!$B$2:$B$901,65)) | C27: =IF($A27="","",INDEX(BAHARY!$C$2:$C$901,65)) | D27: =IF($A27="","",INDEX(BAHARY!$H$2:$H$901,65)) | E27: =IF($A27="","",INDEX(BAHARY!$E$2:$E$901,65)) | F27: =IF($A27="","",D27+E27) | G27: =IF($A27="","",D27*(1-'كشف المطالبة'!$D$5)) | H27: =IF($A27="","",E27*(1-'كشف المطالبة'!$D$6)) | I27: =IF($A27="","",G27+H27) | J27: =IF($A27="","",0) | K27: =IF($A27="","",F27*J27+INDEX(BAHARY!$N$2:$N$901,65)) | L27: =IF($A27="","",I27-K27)
