Workbook

Sheet How To Use
A1: Claims Template - MEDNET (VPN)
A3: Monthly steps
A4: 1. Open the 'Per Line' tab. Delete the old data in the BLUE columns only (row 2 down). Never delete the green or grey columns.
A5: 2. Paste the new month's data as VALUES starting at A2, into the blue columns: B-V, X-AI, AM-AN (same order as the system export).
A6: 3. Green columns (A, W, AJ, AK, AL, AO) and the grey helper columns (AP-AS) calculate automatically - do not paste over them.
A7: 4. 'Per Invoice' fills itself from 'Per Line' (one row per Order #, split into IMP / Local). No pivot table, no refresh.
A8: 5. The columns you type yourself in 'Per Invoice' (blue headers): A 'Invoice', D 'Payer'. Everything else is formula. Type them AFTER pasting the month data (they follow the row, not the order).
A9: 6. The payer tabs ('<name> Perinv') and 'Summary' fill themselves from 'Per Invoice'.
A10: 7. Open 'Settings' and check STATUS says OK (Per Line = Per Invoice, and every invoice has a payer that is listed in Settings).
A12: Colour legend
A13: Blue header = typed/pasted by you (raw data, and 'Invoice' in Per Invoice). Green header = formula (do not paste over). Grey header = helper formula (do not touch). Yellow cell (Settings) = editable rate.
A15: Calculation rules (taken from the September 2026 sheet)
... A21: Capacity: up to 1,500 lines and 500 invoices per month. A line with an empty Order # is ignored.

Sheet Settings
B1: Company settings & checks
B3: Insurance Company | C3: MEDNET | D3: Informational only
B4: Corporate | C4: - | D4: Informational only
B5: Sheet type | C5: VPN | D5: Informational only
B6: Local products rebate % | C6: 0.14 | D6: Source: Sep sheet (Rebates = 0.14 when Imported = FALSE).
B7: Imported (IMP) products rebate % | C7: 0.05 | D7: Source: Sep sheet (Rebates = 0.05 when Imported = TRUE).
B9: Month totals / reconciliation
B10: Lines loaded | C10: =COUNTA('Per Line'!$D$2:$D$1501)
B11: Invoices (unique Order #) | C11: =MAX('Per Line'!$AQ$2:$AQ$1501)
B12: Invoices shown in Per Invoice | C12: =SUMPRODUCT(--('Per Invoice'!$B$2:$B$501<>""))
B13: Grand Total - Per Line (Product Total) | C13: =SUM('Per Line'!$AM$2:$AM$1501)
B14: Grand Total - Per Invoice | C14: =SUM('Per Invoice'!$W$2:$W$501)
B15: Discount - Per Line | C15: =SUM('Per Line'!$AJ$2:$AJ$1501)
B16: Discount - Per Invoice | C16: =SUM('Per Invoice'!$U$2:$U$501)
B17: Co val - Per Line | C17: =SUM('Per Line'!$W$2:$W$1501)
B18: Co val - Per Invoice | C18: =SUM('Per Invoice'!$L$2:$L$501)
B19: Net - Per Line | C19: =SUM('Per Line'!$AL$2:$AL$1501)
B20: Net - Per Invoice | C20: =SUM('Per Invoice'!$X$2:$X$501)
B21: Max Limit adjustment (Co val, Per Invoice only) | C21: 0 | D21: This company's Per Invoice has no Max Limit rule.
B23: STATUS | C23: =IF(C10=0,"No data loaded",IF(COUNTA('Per Line'!$D:$D)-1>1500,"TOO MANY LINES - extend template",IF(C11>500,"TOO MANY INVOICES - extend template",IF(AND(ROUND(C13-C14,2)=0,ROUND(C15-C16,2)=0,ROUND(C17+C21-C18,2)=0,ROUND(C19-C21-C20,2)=0,C11=C12,C39=0,MAX(D26:D37)<=300),"OK","CHECK - Per Line and Per Invoice do not match")))) | D23: Must say OK after you paste the month data.
B25: Payer tabs | C25: Payer name exactly as in PAYER column | D25: Invoices (formula)
B26: Mohandes | C26: Mohandes | D26: =IF(C26="",0,COUNTIF('Per Invoice'!$D$2:$D$501,C26))
B27: Arope | C27: 160 Arope Insurance Company | D27: =IF(C27="",0,COUNTIF('Per Invoice'!$D$2:$D$501,C27))
B28: Mada | C28: 165 Mada Insurance Company | D28: =IF(C28="",0,COUNTIF('Per Invoice'!$D$2:$D$501,C28))
B29: Misr Insurance | C29: 170 Misr Insurance Company | D29: =IF(C29="",0,COUNTIF('Per Invoice'!$D$2:$D$501,C29))
B30: GIG Egypt | C30: Gulf Insurance Group-GIG Egypt | D30: =IF(C30="",0,COUNTIF('Per Invoice'!$D$2:$D$501,C30))
B31: GIG April | C31: 204 Gulf Insurance Group-April | D31: =IF(C31="",0,COUNTIF('Per Invoice'!$D$2:$D$501,C31))
B32: Cigna Healthcare | C32: 212 Cigna Healthcare Insurance Company | D32: =IF(C32="",0,COUNTIF('Per Invoice'!$D$2:$D$501,C32))
B33: Royal Insurance | C33: 45 Royal Insurance Company | D33: =IF(C33="",0,COUNTIF('Per Invoice'!$D$2:$D$501,C33))
B34: CHUBB | C34: 80 CHUBB Insurance Company | D34: =IF(C34="",0,COUNTIF('Per Invoice'!$D$2:$D$501,C34))
B35: Orient | C35: Orient | D35: =IF(C35="",0,COUNTIF('Per Invoice'!$D$2:$D$501,C35))
B36: Extra 1 | D36: =IF(C36="",0,COUNTIF('Per Invoice'!$D$2:$D$501,C36))
B37: Extra 2 | D37: =IF(C37="",0,COUNTIF('Per Invoice'!$D$2:$D$501,C37))
B39: Invoices not in any payer tab (must be 0) | C39: =C11-SUM(D26:D37) | D39: If not 0: a new payer appeared. Type its exact PAYER name in one of the empty yellow cells above (Extra 1 / Extra 2). Each payer tab holds up to 300 invoices.

Sheet Summary
A1: Row Labels | B1: Count of Order Number | C1: Sum of SUBTOTAL | D1: Sum of COVAL | E1: Sum of NET
A2: =IF(Settings!$C$26="","",Settings!$C$26) | B2: =IF($A2="","",COUNTIF('Per Invoice'!$D$2:$D$501,$A2)) | C2: =IF($A2="","",SUMIFS('Per Invoice'!$V$2:$V$501,'Per Invoice'!$D$2:$D$501,$A2)) | D2: =IF($A2="","",SUMIFS('Per Invoice'!$L$2:$L$501,'Per Invoice'!$D$2:$D$501,$A2)) | E2: =IF($A2="","",SUMIFS('Per Invoice'!$X$2:$X$501,'Per Invoice'!$D$2:$D$501,$A2))
A3: =IF(Settings!$C$27="","",Settings!$C$27) | B3: =IF($A3="","",COUNTIF('Per Invoice'!$D$2:$D$501,$A3)) | C3: =IF($A3="","",SUMIFS('Per Invoice'!$V$2:$V$501,'Per Invoice'!$D$2:$D$501,$A3)) | D3: =IF($A3="","",SUMIFS('Per Invoice'!$L$2:$L$501,'Per Invoice'!$D$2:$D$501,$A3)) | E3: =IF($A3="","",SUMIFS('Per Invoice'!$X$2:$X$501,'Per Invoice'!$D$2:$D$501,$A3))
A4: =IF(Settings!$C$28="","",Settings!$C$28) | B4: =IF($A4="","",COUNTIF('Per Invoice'!$D$2:$D$501,$A4)) | C4: =IF($A4="","",SUMIFS('Per Invoice'!$V$2:$V$501,'Per Invoice'!$D$2:$D$501,$A4)) | D4: =IF($A4="","",SUMIFS('Per Invoice'!$L$2:$L$501,'Per Invoice'!$D$2:$D$501,$A4)) | E4: =IF($A4="","",SUMIFS('Per Invoice'!$X$2:$X$501,'Per Invoice'!$D$2:$D$501,$A4))
A5: =IF(Settings!$C$29="","",Settings!$C$29) | B5: =IF($A5="","",COUNTIF('Per Invoice'!$D$2:$D$501,$A5)) | C5: =IF($A5="","",SUMIFS('Per Invoice'!$V$2:$V$501,'Per Invoice'!$D$2:$D$501,$A5)) | D5: =IF($A5="","",SUMIFS('Per Invoice'!$L$2:$L$501,'Per Invoice'!$D$2:$D$501,$A5)) | E5: =IF($A5="","",SUMIFS('Per Invoice'!$X$2:$X$501,'Per Invoice'!$D$2:$D$501,$A5))
A6: =IF(Settings!$C$30="","",Settings!$C$30) | B6: =IF($A6="","",COUNTIF('Per Invoice'!$D$2:$D$501,$A6)) | C6: =IF($A6="","",SUMIFS('Per Invoice'!$V$2:$V$501,'Per Invoice'!$D$2:$D$501,$A6)) | D6: =IF($A6="","",SUMIFS('Per Invoice'!$L$2:$L$501,'Per Invoice'!$D$2:$D$501,$A6)) | E6: =IF($A6="","",SUMIFS('Per Invoice'!$X$2:$X$501,'Per Invoice'!$D$2:$D$501,$A6))
A7: =IF(Settings!$C$31="","",Settings!$C$31) | B7: =IF($A7="","",COUNTIF('Per Invoice'!$D$2:$D$501,$A7)) | C7: =IF($A7="","",SUMIFS('Per Invoice'!$V$2:$V$501,'Per Invoice'!$D$2:$D$501,$A7)) | D7: =IF($A7="","",SUMIFS('Per Invoice'!$L$2:$L$501,'Per Invoice'!$D$2:$D$501,$A7)) | E7: =IF($A7="","",SUMIFS('Per Invoice'!$X$2:$X$501,'Per Invoice'!$D$2:$D$501,$A7))
A8: =IF(Settings!$C$32="","",Settings!$C$32) | B8: =IF($A8="","",COUNTIF('Per Invoice'!$D$2:$D$501,$A8)) | C8: =IF($A8="","",SUMIFS('Per Invoice'!$V$2:$V$501,'Per Invoice'!$D$2:$D$501,$A8)) | D8: =IF($A8="","",SUMIFS('Per Invoice'!$L$2:$L$501,'Per Invoice'!$D$2:$D$501,$A8)) | E8: =IF($A8="","",SUMIFS('Per Invoice'!$X$2:$X$501,'Per Invoice'!$D$2:$D$501,$A8))
A9: =IF(Settings!$C$33="","",Settings!$C$33) | B9: =IF($A9="","",COUNTIF('Per Invoice'!$D$2:$D$501,$A9)) | C9: =IF($A9="","",SUMIFS('Per Invoice'!$V$2:$V$501,'Per Invoice'!$D$2:$D$501,$A9)) | D9: =IF($A9="","",SUMIFS('Per Invoice'!$L$2:$L$501,'Per Invoice'!$D$2:$D$501,$A9)) | E9: =IF($A9="","",SUMIFS('Per Invoice'!$X$2:$X$501,'Per Invoice'!$D$2:$D$501,$A9))
A10: =IF(Settings!$C$34="","",Settings!$C$34) | B10: =IF($A10="","",COUNTIF('Per Invoice'!$D$2:$D$501,$A10)) | C10: =IF($A10="","",SUMIFS('Per Invoice'!$V$2:$V$501,'Per Invoice'!$D$2:$D$501,$A10)) | D10: =IF($A10="","",SUMIFS('Per Invoice'!$L$2:$L$501,'Per Invoice'!$D$2:$D$501,$A10)) | E10: =IF($A10="","",SUMIFS('Per Invoice'!$X$2:$X$501,'Per Invoice'!$D$2:$D$501,$A10))
A11: =IF(Settings!$C$35="","",Settings!$C$35) | B11: =IF($A11="","",COUNTIF('Per Invoice'!$D$2:$D$501,$A11)) | C11: =IF($A11="","",SUMIFS('Per Invoice'!$V$2:$V$501,'Per Invoice'!$D$2:$D$501,$A11)) | D11: =IF($A11="","",SUMIFS('Per Invoice'!$L$2:$L$501,'Per Invoice'!$D$2:$D$501,$A11)) | E11: =IF($A11="","",SUMIFS('Per Invoice'!$X$2:$X$501,'Per Invoice'!$D$2:$D$501,$A11))
A12: =IF(Settings!$C$36="","",Settings!$C$36) | B12: =IF($A12="","",COUNTIF('Per Invoice'!$D$2:$D$501,$A12)) | C12: =IF($A12="","",SUMIFS('Per Invoice'!$V$2:$V$501,'Per Invoice'!$D$2:$D$501,$A12)) | D12: =IF($A12="","",SUMIFS('Per Invoice'!$L$2:$L$501,'Per Invoice'!$D$2:$D$501,$A12)) | E12: =IF($A12="","",SUMIFS('Per Invoice'!$X$2:$X$501,'Per Invoice'!$D$2:$D$501,$A12))
A13: =IF(Settings!$C$37="","",Settings!$C$37) | B13: =IF($A13="","",COUNTIF('Per Invoice'!$D$2:$D$501,$A13)) | C13: =IF($A13="","",SUMIFS('Per Invoice'!$V$2:$V$501,'Per Invoice'!$D$2:$D$501,$A13)) | D13: =IF($A13="","",SUMIFS('Per Invoice'!$L$2:$L$501,'Per Invoice'!$D$2:$D$501,$A13)) | E13: =IF($A13="","",SUMIFS('Per Invoice'!$X$2:$X$501,'Per Invoice'!$D$2:$D$501,$A13))
A14: Grand Total | B14: =SUM(B2:B13) | C14: =SUM(C2:C13) | D14: =SUM(D2:D13) | E14: =SUM(E2:E13)

Sheet Per Line
A1: invioc | B1: ERX ID | C1: Mongo Order ID | D1: Order Number | E1: Pool ID | F1: Approval Number | G1: Approval Reference | H1: Group ID | I1: Group | J1: Branch ID | K1: Branch | L1: Order Status | M1: Total (EGP) | N1: Delivery Fees (EGP) | O1: By Patient (EGP) | P1: Order Type | Q1: Original Order Type | R1: Payer | S1: Card Holder Name | T1: User Mobile Name | U1: Card Number | V1: Co Payment (%) | W1: Co val | X1: Creation Date | Y1: Creation Time | Z1: Dispatch Date | AA1: Dispatch Time | AB1: Delivery Date | AC1: Delivery Time | AD1: Heisenberg ID | AE1: Item | AF1: Item Unit | AG1: Item Form | AH1: Item Price (EGP) | AI1: Item Quantity | AJ1: Discount | AK1: Subtotal | AL1: Net | AM1: Item Total Price (EGP) | AN1: Imported | AO1: Rebates | AP1: Order 1st Row (helper) | AQ1: Invoice # (helper) | AR1: Is Local (helper) | AS1: Sort Key (helper)
A2: =IF($D2="","",IFERROR(IF(INDEX('Per Invoice'!$A$2:$A$501,MATCH($D2,'Per Invoice'!$B$2:$B$501,0))=0,"",INDEX('Per Invoice'!$A$2:$A$501,MATCH($D2,'Per Invoice'!$B$2:$B$501,0))),"")) | W2: =IF($D2="","",V2*AM2/100) | AJ2: =IF($D2="","",AO2*AM2) | AK2: =IF($D2="","",AM2-AJ2) | AL2: =IF($D2="","",AK2-W2) | AO2: =IF($D2="","",IF($AR2=1,Settings!$C$6,Settings!$C$7)*1) | AP2: =IF($D2="","",IF(COUNTIF($D$2:$D2,$D2)=1,1,0)) | AQ2: =IF($AP2=1,SUMPRODUCT(--($AS$2:$AS$1501<$AS2))+1,"") | AR2: =IF($D2="","",IF(OR($AN2=TRUE(),$AN2="TRUE"),0,1)) | AS2: =IF($AP2=1,IFERROR(IF(VALUE($D2)<100000000,VALUE($D2),1000000000),IFERROR(IF(VALUE(MID($D2,2,20))<100000000,VALUE(MID($D2,2,20)),1000000000),1000000000))+ROW()/100000,"")
A3: =IF($D3="","",IFERROR(IF(INDEX('Per Invoice'!$A$2:$A$501,MATCH($D3,'Per Invoice'!$B$2:$B$501,0))=0,"",INDEX('Per Invoice'!$A$2:$A$501,MATCH($D3,'Per Invoice'!$B$2:$B$501,0))),"")) | W3: =IF($D3="","",V3*AM3/100) | AJ3: =IF($D3="","",AO3*AM3) | AK3: =IF($D3="","",AM3-AJ3) | AL3: =IF($D3="","",AK3-W3) | AO3: =IF($D3="","",IF($AR3=1,Settings!$C$6,Settings!$C$7)*1) | AP3: =IF($D3="","",IF(COUNTIF($D$2:$D3,$D3)=1,1,0)) | AQ3: =IF($AP3=1,SUMPRODUCT(--($AS$2:$AS$1501<$AS3))+1,"") | AR3: =IF($D3="","",IF(OR($AN3=TRUE(),$AN3="TRUE"),0,1)) | AS3: =IF($AP3=1,IFERROR(IF(VALUE($D3)<100000000,VALUE($D3),1000000000),IFERROR(IF(VALUE(MID($D3,2,20))<100000000,VALUE(MID($D3,2,20)),1000000000),1000000000))+ROW()/100000,"")
A4: =IF($D4="","",IFERROR(IF(INDEX('Per Invoice'!$A$2:$A$501,MATCH($D4,'Per Invoice'!$B$2:$B$501,0))=0,"",INDEX('Per Invoice'!$A$2:$A$501,MATCH($D4,'Per Invoice'!$B$2:$B$501,0))),"")) | W4: =IF($D4="","",V4*AM4/100) | AJ4: =IF($D4="","",AO4*AM4) | AK4: =IF($D4="","",AM4-AJ4) | AL4: =IF($D4="","",AK4-W4) | AO4: =IF($D4="","",IF($AR4=1,Settings!$C$6,Settings!$C$7)*1) | AP4: =IF($D4="","",IF(COUNTIF($D$2:$D4,$D4)=1,1,0)) | AQ4: =IF($AP4=1,SUMPRODUCT(--($AS$2:$AS$1501<$AS4))+1,"") | AR4: =IF($D4="","",IF(OR($AN4=TRUE(),$AN4="TRUE"),0,1)) | AS4: =IF($AP4=1,IFERROR(IF(VALUE($D4)<100000000,VALUE($D4),1000000000),IFERROR(IF(VALUE(MID($D4,2,20))<100000000,VALUE(MID($D4,2,20)),1000000000),1000000000))+ROW()/100000,"")
A5: =IF($D5="","",IFERROR(IF(INDEX('Per Invoice'!$A$2:$A$501,MATCH($D5,'Per Invoice'!$B$2:$B$501,0))=0,"",INDEX('Per Invoice'!$A$2:$A$501,MATCH($D5,'Per Invoice'!$B$2:$B$501,0))),"")) | W5: =IF($D5="","",V5*AM5/100) | AJ5: =IF($D5="","",AO5*AM5) | AK5: =IF($D5="","",AM5-AJ5) | AL5: =IF($D5="","",AK5-W5) | AO5: =IF($D5="","",IF($AR5=1,Settings!$C$6,Settings!$C$7)*1) | AP5: =IF($D5="","",IF(COUNTIF($D$2:$D5,$D5)=1,1,0)) | AQ5: =IF($AP5=1,SUMPRODUCT(--($AS$2:$AS$1501<$AS5))+1,"") | AR5: =IF($D5="","",IF(OR($AN5=TRUE(),$AN5="TRUE"),0,1)) | AS5: =IF($AP5=1,IFERROR(IF(VALUE($D5)<100000000,VALUE($D5),1000000000),IFERROR(IF(VALUE(MID($D5,2,20))<100000000,VALUE(MID($D5,2,20)),1000000000),1000000000))+ROW()/100000,"")
A6: =IF($D6="","",IFERROR(IF(INDEX('Per Invoice'!$A$2:$A$501,MATCH($D6,'Per Invoice'!$B$2:$B$501,0))=0,"",INDEX('Per Invoice'!$A$2:$A$501,MATCH($D6,'Per Invoice'!$B$2:$B$501,0))),"")) | W6: =IF($D6="","",V6*AM6/100) | AJ6: =IF($D6="","",AO6*AM6) | AK6: =IF($D6="","",AM6-AJ6) | AL6: =IF($D6="","",AK6-W6) | AO6: =IF($D6="","",IF($AR6=1,Settings!$C$6,Settings!$C$7)*1) | AP6: =IF($D6="","",IF(COUNTIF($D$2:$D6,$D6)=1,1,0)) | AQ6: =IF($AP6=1,SUMPRODUCT(--($AS$2:$AS$1501<$AS6))+1,"") | AR6: =IF($D6="","",IF(OR($AN6=TRUE(),$AN6="TRUE"),0,1)) | AS6: =IF($AP6=1,IFERROR(IF(VALUE($D6)<100000000,VALUE($D6),1000000000),IFERROR(IF(VALUE(MID($D6,2,20))<100000000,VALUE(MID($D6,2,20)),1000000000),1000000000))+ROW()/100000,"")
A7: =IF($D7="","",IFERROR(IF(INDEX('Per Invoice'!$A$2:$A$501,MATCH($D7,'Per Invoice'!$B$2:$B$501,0))=0,"",INDEX('Per Invoice'!$A$2:$A$501,MATCH($D7,'Per Invoice'!$B$2:$B$501,0))),"")) | W7: =IF($D7="","",V7*AM7/100) | AJ7: =IF($D7="","",AO7*AM7) | AK7: =IF($D7="","",AM7-AJ7) | AL7: =IF($D7="","",AK7-W7) | AO7: =IF($D7="","",IF($AR7=1,Settings!$C$6,Settings!$C$7)*1) | AP7: =IF($D7="","",IF(COUNTIF($D$2:$D7,$D7)=1,1,0)) | AQ7: =IF($AP7=1,SUMPRODUCT(--($AS$2:$AS$1501<$AS7))+1,"") | AR7: =IF($D7="","",IF(OR($AN7=TRUE(),$AN7="TRUE"),0,1)) | AS7: =IF($AP7=1,IFERROR(IF(VALUE($D7)<100000000,VALUE($D7),1000000000),IFERROR(IF(VALUE(MID($D7,2,20))<100000000,VALUE(MID($D7,2,20)),1000000000),1000000000))+ROW()/100000,"")
A8: =IF($D8="","",IFERROR(IF(INDEX('Per Invoice'!$A$2:$A$501,MATCH($D8,'Per Invoice'!$B$2:$B$501,0))=0,"",INDEX('Per Invoice'!$A$2:$A$501,MATCH($D8,'Per Invoice'!$B$2:$B$501,0))),"")) | W8: =IF($D8="","",V8*AM8/100) | AJ8: =IF($D8="","",AO8*AM8) | AK8: =IF($D8="","",AM8-AJ8) | AL8: =IF($D8="","",AK8-W8) | AO8: =IF($D8="","",IF($AR8=1,Settings!$C$6,Settings!$C$7)*1) | AP8: =IF($D8="","",IF(COUNTIF($D$2:$D8,$D8)=1,1,0)) | AQ8: =IF($AP8=1,SUMPRODUCT(--($AS$2:$AS$1501<$AS8))+1,"") | AR8: =IF($D8="","",IF(OR($AN8=TRUE(),$AN8="TRUE"),0,1)) | AS8: =IF($AP8=1,IFERROR(IF(VALUE($D8)<100000000,VALUE($D8),1000000000),IFERROR(IF(VALUE(MID($D8,2,20))<100000000,VALUE(MID($D8,2,20)),1000000000),1000000000))+ROW()/100000,"")
A9: =IF($D9="","",IFERROR(IF(INDEX('Per Invoice'!$A$2:$A$501,MATCH($D9,'Per Invoice'!$B$2:$B$501,0))=0,"",INDEX('Per Invoice'!$A$2:$A$501,MATCH($D9,'Per Invoice'!$B$2:$B$501,0))),"")) | W9: =IF($D9="","",V9*AM9/100) | AJ9: =IF($D9="","",AO9*AM9) | AK9: =IF($D9="","",AM9-AJ9) | AL9: =IF($D9="","",AK9-W9) | AO9: =IF($D9="","",IF($AR9=1,Settings!$C$6,Settings!$C$7)*1) | AP9: =IF($D9="","",IF(COUNTIF($D$2:$D9,$D9)=1,1,0)) | AQ9: =IF($AP9=1,SUMPRODUCT(--($AS$2:$AS$1501<$AS9))+1,"") | AR9: =IF($D9="","",IF(OR($AN9=TRUE(),$AN9="TRUE"),0,1)) | AS9: =IF($AP9=1,IFERROR(IF(VALUE($D9)<100000000,VALUE($D9),1000000000),IFERROR(IF(VALUE(MID($D9,2,20))<100000000,VALUE(MID($D9,2,20)),1000000000),1000000000))+ROW()/100000,"")
A10: =IF($D10="","",IFERROR(IF(INDEX('Per Invoice'!$A$2:$A$501,MATCH($D10,'Per Invoice'!$B$2:$B$501,0))=0,"",INDEX('Per Invoice'!$A$2:$A$501,MATCH($D10,'Per Invoice'!$B$2:$B$501,0))),"")) | W10: =IF($D10="","",V10*AM10/100) | AJ10: =IF($D10="","",AO10*AM10) | AK10: =IF($D10="","",AM10-AJ10) | AL10: =IF($D10="","",AK10-W10) | AO10: =IF($D10="","",IF($AR10=1,Settings!$C$6,Settings!$C$7)*1) | AP10: =IF($D10="","",IF(COUNTIF($D$2:$D10,$D10)=1,1,0)) | AQ10: =IF($AP10=1,SUMPRODUCT(--($AS$2:$AS$1501<$AS10))+1,"") | AR10: =IF($D10="","",IF(OR($AN10=TRUE(),$AN10="TRUE"),0,1)) | AS10: =IF($AP10=1,IFERROR(IF(VALUE($D10)<100000000,VALUE($D10),1000000000),IFERROR(IF(VALUE(MID($D10,2,20))<100000000,VALUE(MID($D10,2,20)),1000000000),1000000000))+ROW()/100000,"")
A11: =IF($D11="","",IFERROR(IF(INDEX('Per Invoice'!$A$2:$A$501,MATCH($D11,'Per Invoice'!$B$2:$B$501,0))=0,"",INDEX('Per Invoice'!$A$2:$A$501,MATCH($D11,'Per Invoice'!$B$2:$B$501,0))),"")) | W11: =IF($D11="","",V11*AM11/100) | AJ11: =IF($D11="","",AO11*AM11) | AK11: =IF($D11="","",AM11-AJ11) | AL11: =IF($D11="","",AK11-W11) | AO11: =IF($D11="","",IF($AR11=1,Settings!$C$6,Settings!$C$7)*1) | AP11: =IF($D11="","",IF(COUNTIF($D$2:$D11,$D11)=1,1,0)) | AQ11: =IF($AP11=1,SUMPRODUCT(--($AS$2:$AS$1501<$AS11))+1,"") | AR11: =IF($D11="","",IF(OR($AN11=TRUE(),$AN11="TRUE"),0,1)) | AS11: =IF($AP11=1,IFERROR(IF(VALUE($D11)<100000000,VALUE($D11),1000000000),IFERROR(IF(VALUE(MID($D11,2,20))<100000000,VALUE(MID($D11,2,20)),1000000000),1000000000))+ROW()/100000,"")
A12: =IF($D12="","",IFERROR(IF(INDEX('Per Invoice'!$A$2:$A$501,MATCH($D12,'Per Invoice'!$B$2:$B$501,0))=0,"",INDEX('Per Invoice'!$A$2:$A$501,MATCH($D12,'Per Invoice'!$B$2:$B$501,0))),"")) | W12: =IF($D12="","",V12*AM12/100) | AJ12: =IF($D12="","",AO12*AM12) | AK12: =IF($D12="","",AM12-AJ12) | AL12: =IF($D12="","",AK12-W12) | AO12: =IF($D12="","",IF($AR12=1,Settings!$C$6,Settings!$C$7)*1) | AP12: =IF($D12="","",IF(COUNTIF($D$2:$D12,$D12)=1,1,0)) | AQ12: =IF($AP12=1,SUMPRODUCT(--($AS$2:$AS$1501<$AS12))+1,"") | AR12: =IF($D12="","",IF(OR($AN12=TRUE(),$AN12="TRUE"),0,1)) | AS12: =IF($AP12=1,IFERROR(IF(VALUE($D12)<100000000,VALUE($D12),1000000000),IFERROR(IF(VALUE(MID($D12,2,20))<100000000,VALUE(MID($D12,2,20)),1000000000),1000000000))+ROW()/100000,"")
A13: =IF($D13="","",IFERROR(IF(INDEX('Per Invoice'!$A$2:$A$501,MATCH($D13,'Per Invoice'!$B$2:$B$501,0))=0,"",INDEX('Per Invoice'!$A$2:$A$501,MATCH($D13,'Per Invoice'!$B$2:$B$501,0))),"")) | W13: =IF($D13="","",V13*AM13/100) | AJ13: =IF($D13="","",AO13*AM13) | AK13: =IF($D13="","",AM13-AJ13) | AL13: =IF($D13="","",AK13-W13) | AO13: =IF($D13="","",IF($AR13=1,Settings!$C$6,Settings!$C$7)*1) | AP13: =IF($D13="","",IF(COUNTIF($D$2:$D13,$D13)=1,1,0)) | AQ13: =IF($AP13=1,SUMPRODUCT(--($AS$2:$AS$1501<$AS13))+1,"") | AR13: =IF($D13="","",IF(OR($AN13=TRUE(),$AN13="TRUE"),0,1)) | AS13: =IF($AP13=1,IFERROR(IF(VALUE($D13)<100000000,VALUE($D13),1000000000),IFERROR(IF(VALUE(MID($D13,2,20))<100000000,VALUE(MID($D13,2,20)),1000000000),1000000000))+ROW()/100000,"")
... A1501: =IF($D1501="","",IFERROR(IF(INDEX('Per Invoice'!$A$2:$A$501,MATCH($D1501,'Per Invoice'!$B$2:$B$501,0))=0,"",INDEX('Per Invoice'!$A$2:$A$501,MATCH($D1501,'Per Invoice'!$B$2:$B$501,0))),"")) | W1501: =IF($D1501="","",V1501*AM1501/100) | AJ1501: =IF($D1501="","",AO1501*AM1501) | AK1501: =IF($D1501="","",AM1501-AJ1501) | AL1501: =IF($D1501="","",AK1501-W1501) | AO1501: =IF($D1501="","",IF($AR1501=1,Settings!$C$6,Settings!$C$7)*1) | AP1501: =IF($D1501="","",IF(COUNTIF($D$2:$D1501,$D1501)=1,1,0)) | AQ1501: =IF($AP1501=1,SUMPRODUCT(--($AS$2:$AS$1501<$AS1501))+1,"") | AR1501: =IF($D1501="","",IF(OR($AN1501=TRUE(),$AN1501="TRUE"),0,1)) | AS1501: =IF($AP1501=1,IFERROR(IF(VALUE($D1501)<100000000,VALUE($D1501),1000000000),IFERROR(IF(VALUE(MID($D1501,2,20))<100000000,VALUE(MID($D1501,2,20)),1000000000),1000000000))+ROW()/100000,"")

Sheet Per Invoice
A1: Invoice | B1: Order Number | C1: ERX ID | D1: Payer | E1: Approval Reference | F1: Branch | G1: Order Status | H1: Order Type | I1: Payer | J1: Card Number | K1: Co Payment (%) | L1: Co val | M1: Creation Date | N1: Card Holder Name | O1: IMP % | P1: IMP | Q1: IMP VAL | R1: LOC % | S1: LOC | T1: LOC VAL | U1: TOTAL VAL | V1: SUBTOTAL | W1: Grand Total | X1: NET | Y1: Src Row (helper) | Z1: Payer Key (helper)
B2: =IF($Y2="","",INDEX('Per Line'!$D$2:$D$1501,$Y2)&"") | C2: =IF($Y2="","",INDEX('Per Line'!$B$2:$B$1501,$Y2)&"") | E2: =IF($Y2="","",INDEX('Per Line'!$G$2:$G$1501,$Y2)&"") | F2: =IF($Y2="","",INDEX('Per Line'!$K$2:$K$1501,$Y2)&"") | G2: =IF($Y2="","",INDEX('Per Line'!$L$2:$L$1501,$Y2)&"") | H2: =IF($Y2="","",INDEX('Per Line'!$P$2:$P$1501,$Y2)&"") | I2: =IF($Y2="","",INDEX('Per Line'!$R$2:$R$1501,$Y2)&"") | J2: =IF($Y2="","",INDEX('Per Line'!$U$2:$U$1501,$Y2)&"") | K2: =IF($Y2="","",INDEX('Per Line'!$V$2:$V$1501,$Y2)) | L2: =IF($Y2="","",K2*W2/100) | M2: =IF($Y2="","",INDEX('Per Line'!$X$2:$X$1501,$Y2)) | N2: =IF($Y2="","",INDEX('Per Line'!$S$2:$S$1501,$Y2)&"") | O2: =IF($Y2="","",Settings!$C$7) | P2: =IF($Y2="","",SUMIFS('Per Line'!$AM$2:$AM$1501,'Per Line'!$D$2:$D$1501,$B2,'Per Line'!$AR$2:$AR$1501,0)) | Q2: =IF($Y2="","",P2*O2) | R2: =IF($Y2="","",Settings!$C$6) | S2: =IF($Y2="","",SUMIFS('Per Line'!$AM$2:$AM$1501,'Per Line'!$D$2:$D$1501,$B2,'Per Line'!$AR$2:$AR$1501,1)) | T2: =IF($Y2="","",S2*R2) | U2: =IF($Y2="","",T2+Q2) | V2: =IF($Y2="","",W2-U2) | W2: =IF($Y2="","",P2+S2) | X2: =IF($Y2="","",W2-U2-L2) | Y2: =IF(ROWS($Y$2:$Y2)<=MAX('Per Line'!$AQ$2:$AQ$1501),MATCH(ROWS($Y$2:$Y2),'Per Line'!$AQ$2:$AQ$1501,0),"") | Z2: =IF($Y2="","",D2&"|"&COUNTIF($D$2:$D2,D2))
B3: =IF($Y3="","",INDEX('Per Line'!$D$2:$D$1501,$Y3)&"") | C3: =IF($Y3="","",INDEX('Per Line'!$B$2:$B$1501,$Y3)&"") | E3: =IF($Y3="","",INDEX('Per Line'!$G$2:$G$1501,$Y3)&"") | F3: =IF($Y3="","",INDEX('Per Line'!$K$2:$K$1501,$Y3)&"") | G3: =IF($Y3="","",INDEX('Per Line'!$L$2:$L$1501,$Y3)&"") | H3: =IF($Y3="","",INDEX('Per Line'!$P$2:$P$1501,$Y3)&"") | I3: =IF($Y3="","",INDEX('Per Line'!$R$2:$R$1501,$Y3)&"") | J3: =IF($Y3="","",INDEX('Per Line'!$U$2:$U$1501,$Y3)&"") | K3: =IF($Y3="","",INDEX('Per Line'!$V$2:$V$1501,$Y3)) | L3: =IF($Y3="","",K3*W3/100) | M3: =IF($Y3="","",INDEX('Per Line'!$X$2:$X$1501,$Y3)) | N3: =IF($Y3="","",INDEX('Per Line'!$S$2:$S$1501,$Y3)&"") | O3: =IF($Y3="","",Settings!$C$7) | P3: =IF($Y3="","",SUMIFS('Per Line'!$AM$2:$AM$1501,'Per Line'!$D$2:$D$1501,$B3,'Per Line'!$AR$2:$AR$1501,0)) | Q3: =IF($Y3="","",P3*O3) | R3: =IF($Y3="","",Settings!$C$6) | S3: =IF($Y3="","",SUMIFS('Per Line'!$AM$2:$AM$1501,'Per Line'!$D$2:$D$1501,$B3,'Per Line'!$AR$2:$AR$1501,1)) | T3: =IF($Y3="","",S3*R3) | U3: =IF($Y3="","",T3+Q3) | V3: =IF($Y3="","",W3-U3) | W3: =IF($Y3="","",P3+S3) | X3: =IF($Y3="","",W3-U3-L3) | Y3: =IF(ROWS($Y$2:$Y3)<=MAX('Per Line'!$AQ$2:$AQ$1501),MATCH(ROWS($Y$2:$Y3),'Per Line'!$AQ$2:$AQ$1501,0),"") | Z3: =IF($Y3="","",D3&"|"&COUNTIF($D$2:$D3,D3))
B4: =IF($Y4="","",INDEX('Per Line'!$D$2:$D$1501,$Y4)&"") | C4: =IF($Y4="","",INDEX('Per Line'!$B$2:$B$1501,$Y4)&"") | E4: =IF($Y4="","",INDEX('Per Line'!$G$2:$G$1501,$Y4)&"") | F4: =IF($Y4="","",INDEX('Per Line'!$K$2:$K$1501,$Y4)&"") | G4: =IF($Y4="","",INDEX('Per Line'!$L$2:$L$1501,$Y4)&"") | H4: =IF($Y4="","",INDEX('Per Line'!$P$2:$P$1501,$Y4)&"") | I4: =IF($Y4="","",INDEX('Per Line'!$R$2:$R$1501,$Y4)&"") | J4: =IF($Y4="","",INDEX('Per Line'!$U$2:$U$1501,$Y4)&"") | K4: =IF($Y4="","",INDEX('Per Line'!$V$2:$V$1501,$Y4)) | L4: =IF($Y4="","",K4*W4/100) | M4: =IF($Y4="","",INDEX('Per Line'!$X$2:$X$1501,$Y4)) | N4: =IF($Y4="","",INDEX('Per Line'!$S$2:$S$1501,$Y4)&"") | O4: =IF($Y4="","",Settings!$C$7) | P4: =IF($Y4="","",SUMIFS('Per Line'!$AM$2:$AM$1501,'Per Line'!$D$2:$D$1501,$B4,'Per Line'!$AR$2:$AR$1501,0)) | Q4: =IF($Y4="","",P4*O4) | R4: =IF($Y4="","",Settings!$C$6) | S4: =IF($Y4="","",SUMIFS('Per Line'!$AM$2:$AM$1501,'Per Line'!$D$2:$D$1501,$B4,'Per Line'!$AR$2:$AR$1501,1)) | T4: =IF($Y4="","",S4*R4) | U4: =IF($Y4="","",T4+Q4) | V4: =IF($Y4="","",W4-U4) | W4: =IF($Y4="","",P4+S4) | X4: =IF($Y4="","",W4-U4-L4) | Y4: =IF(ROWS($Y$2:$Y4)<=MAX('Per Line'!$AQ$2:$AQ$1501),MATCH(ROWS($Y$2:$Y4),'Per Line'!$AQ$2:$AQ$1501,0),"") | Z4: =IF($Y4="","",D4&"|"&COUNTIF($D$2:$D4,D4))
B5: =IF($Y5="","",INDEX('Per Line'!$D$2:$D$1501,$Y5)&"") | C5: =IF($Y5="","",INDEX('Per Line'!$B$2:$B$1501,$Y5)&"") | E5: =IF($Y5="","",INDEX('Per Line'!$G$2:$G$1501,$Y5)&"") | F5: =IF($Y5="","",INDEX('Per Line'!$K$2:$K$1501,$Y5)&"") | G5: =IF($Y5="","",INDEX('Per Line'!$L$2:$L$1501,$Y5)&"") | H5: =IF($Y5="","",INDEX('Per Line'!$P$2:$P$1501,$Y5)&"") | I5: =IF($Y5="","",INDEX('Per Line'!$R$2:$R$1501,$Y5)&"") | J5: =IF($Y5="","",INDEX('Per Line'!$U$2:$U$1501,$Y5)&"") | K5: =IF($Y5="","",INDEX('Per Line'!$V$2:$V$1501,$Y5)) | L5: =IF($Y5="","",K5*W5/100) | M5: =IF($Y5="","",INDEX('Per Line'!$X$2:$X$1501,$Y5)) | N5: =IF($Y5="","",INDEX('Per Line'!$S$2:$S$1501,$Y5)&"") | O5: =IF($Y5="","",Settings!$C$7) | P5: =IF($Y5="","",SUMIFS('Per Line'!$AM$2:$AM$1501,'Per Line'!$D$2:$D$1501,$B5,'Per Line'!$AR$2:$AR$1501,0)) | Q5: =IF($Y5="","",P5*O5) | R5: =IF($Y5="","",Settings!$C$6) | S5: =IF($Y5="","",SUMIFS('Per Line'!$AM$2:$AM$1501,'Per Line'!$D$2:$D$1501,$B5,'Per Line'!$AR$2:$AR$1501,1)) | T5: =IF($Y5="","",S5*R5) | U5: =IF($Y5="","",T5+Q5) | V5: =IF($Y5="","",W5-U5) | W5: =IF($Y5="","",P5+S5) | X5: =IF($Y5="","",W5-U5-L5) | Y5: =IF(ROWS($Y$2:$Y5)<=MAX('Per Line'!$AQ$2:$AQ$1501),MATCH(ROWS($Y$2:$Y5),'Per Line'!$AQ$2:$AQ$1501,0),"") | Z5: =IF($Y5="","",D5&"|"&COUNTIF($D$2:$D5,D5))
B6: =IF($Y6="","",INDEX('Per Line'!$D$2:$D$1501,$Y6)&"") | C6: =IF($Y6="","",INDEX('Per Line'!$B$2:$B$1501,$Y6)&"") | E6: =IF($Y6="","",INDEX('Per Line'!$G$2:$G$1501,$Y6)&"") | F6: =IF($Y6="","",INDEX('Per Line'!$K$2:$K$1501,$Y6)&"") | G6: =IF($Y6="","",INDEX('Per Line'!$L$2:$L$1501,$Y6)&"") | H6: =IF($Y6="","",INDEX('Per Line'!$P$2:$P$1501,$Y6)&"") | I6: =IF($Y6="","",INDEX('Per Line'!$R$2:$R$1501,$Y6)&"") | J6: =IF($Y6="","",INDEX('Per Line'!$U$2:$U$1501,$Y6)&"") | K6: =IF($Y6="","",INDEX('Per Line'!$V$2:$V$1501,$Y6)) | L6: =IF($Y6="","",K6*W6/100) | M6: =IF($Y6="","",INDEX('Per Line'!$X$2:$X$1501,$Y6)) | N6: =IF($Y6="","",INDEX('Per Line'!$S$2:$S$1501,$Y6)&"") | O6: =IF($Y6="","",Settings!$C$7) | P6: =IF($Y6="","",SUMIFS('Per Line'!$AM$2:$AM$1501,'Per Line'!$D$2:$D$1501,$B6,'Per Line'!$AR$2:$AR$1501,0)) | Q6: =IF($Y6="","",P6*O6) | R6: =IF($Y6="","",Settings!$C$6) | S6: =IF($Y6="","",SUMIFS('Per Line'!$AM$2:$AM$1501,'Per Line'!$D$2:$D$1501,$B6,'Per Line'!$AR$2:$AR$1501,1)) | T6: =IF($Y6="","",S6*R6) | U6: =IF($Y6="","",T6+Q6) | V6: =IF($Y6="","",W6-U6) | W6: =IF($Y6="","",P6+S6) | X6: =IF($Y6="","",W6-U6-L6) | Y6: =IF(ROWS($Y$2:$Y6)<=MAX('Per Line'!$AQ$2:$AQ$1501),MATCH(ROWS($Y$2:$Y6),'Per Line'!$AQ$2:$AQ$1501,0),"") | Z6: =IF($Y6="","",D6&"|"&COUNTIF($D$2:$D6,D6))
B7: =IF($Y7="","",INDEX('Per Line'!$D$2:$D$1501,$Y7)&"") | C7: =IF($Y7="","",INDEX('Per Line'!$B$2:$B$1501,$Y7)&"") | E7: =IF($Y7="","",INDEX('Per Line'!$G$2:$G$1501,$Y7)&"") | F7: =IF($Y7="","",INDEX('Per Line'!$K$2:$K$1501,$Y7)&"") | G7: =IF($Y7="","",INDEX('Per Line'!$L$2:$L$1501,$Y7)&"") | H7: =IF($Y7="","",INDEX('Per Line'!$P$2:$P$1501,$Y7)&"") | I7: =IF($Y7="","",INDEX('Per Line'!$R$2:$R$1501,$Y7)&"") | J7: =IF($Y7="","",INDEX('Per Line'!$U$2:$U$1501,$Y7)&"") | K7: =IF($Y7="","",INDEX('Per Line'!$V$2:$V$1501,$Y7)) | L7: =IF($Y7="","",K7*W7/100) | M7: =IF($Y7="","",INDEX('Per Line'!$X$2:$X$1501,$Y7)) | N7: =IF($Y7="","",INDEX('Per Line'!$S$2:$S$1501,$Y7)&"") | O7: =IF($Y7="","",Settings!$C$7) | P7: =IF($Y7="","",SUMIFS('Per Line'!$AM$2:$AM$1501,'Per Line'!$D$2:$D$1501,$B7,'Per Line'!$AR$2:$AR$1501,0)) | Q7: =IF($Y7="","",P7*O7) | R7: =IF($Y7="","",Settings!$C$6) | S7: =IF($Y7="","",SUMIFS('Per Line'!$AM$2:$AM$1501,'Per Line'!$D$2:$D$1501,$B7,'Per Line'!$AR$2:$AR$1501,1)) | T7: =IF($Y7="","",S7*R7) | U7: =IF($Y7="","",T7+Q7) | V7: =IF($Y7="","",W7-U7) | W7: =IF($Y7="","",P7+S7) | X7: =IF($Y7="","",W7-U7-L7) | Y7: =IF(ROWS($Y$2:$Y7)<=MAX('Per Line'!$AQ$2:$AQ$1501),MATCH(ROWS($Y$2:$Y7),'Per Line'!$AQ$2:$AQ$1501,0),"") | Z7: =IF($Y7="","",D7&"|"&COUNTIF($D$2:$D7,D7))
B8: =IF($Y8="","",INDEX('Per Line'!$D$2:$D$1501,$Y8)&"") | C8: =IF($Y8="","",INDEX('Per Line'!$B$2:$B$1501,$Y8)&"") | E8: =IF($Y8="","",INDEX('Per Line'!$G$2:$G$1501,$Y8)&"") | F8: =IF($Y8="","",INDEX('Per Line'!$K$2:$K$1501,$Y8)&"") | G8: =IF($Y8="","",INDEX('Per Line'!$L$2:$L$1501,$Y8)&"") | H8: =IF($Y8="","",INDEX('Per Line'!$P$2:$P$1501,$Y8)&"") | I8: =IF($Y8="","",INDEX('Per Line'!$R$2:$R$1501,$Y8)&"") | J8: =IF($Y8="","",INDEX('Per Line'!$U$2:$U$1501,$Y8)&"") | K8: =IF($Y8="","",INDEX('Per Line'!$V$2:$V$1501,$Y8)) | L8: =IF($Y8="","",K8*W8/100) | M8: =IF($Y8="","",INDEX('Per Line'!$X$2:$X$1501,$Y8)) | N8: =IF($Y8="","",INDEX('Per Line'!$S$2:$S$1501,$Y8)&"") | O8: =IF($Y8="","",Settings!$C$7) | P8: =IF($Y8="","",SUMIFS('Per Line'!$AM$2:$AM$1501,'Per Line'!$D$2:$D$1501,$B8,'Per Line'!$AR$2:$AR$1501,0)) | Q8: =IF($Y8="","",P8*O8) | R8: =IF($Y8="","",Settings!$C$6) | S8: =IF($Y8="","",SUMIFS('Per Line'!$AM$2:$AM$1501,'Per Line'!$D$2:$D$1501,$B8,'Per Line'!$AR$2:$AR$1501,1)) | T8: =IF($Y8="","",S8*R8) | U8: =IF($Y8="","",T8+Q8) | V8: =IF($Y8="","",W8-U8) | W8: =IF($Y8="","",P8+S8) | X8: =IF($Y8="","",W8-U8-L8) | Y8: =IF(ROWS($Y$2:$Y8)<=MAX('Per Line'!$AQ$2:$AQ$1501),MATCH(ROWS($Y$2:$Y8),'Per Line'!$AQ$2:$AQ$1501,0),"") | Z8: =IF($Y8="","",D8&"|"&COUNTIF($D$2:$D8,D8))
B9: =IF($Y9="","",INDEX('Per Line'!$D$2:$D$1501,$Y9)&"") | C9: =IF($Y9="","",INDEX('Per Line'!$B$2:$B$1501,$Y9)&"") | E9: =IF($Y9="","",INDEX('Per Line'!$G$2:$G$1501,$Y9)&"") | F9: =IF($Y9="","",INDEX('Per Line'!$K$2:$K$1501,$Y9)&"") | G9: =IF($Y9="","",INDEX('Per Line'!$L$2:$L$1501,$Y9)&"") | H9: =IF($Y9="","",INDEX('Per Line'!$P$2:$P$1501,$Y9)&"") | I9: =IF($Y9="","",INDEX('Per Line'!$R$2:$R$1501,$Y9)&"") | J9: =IF($Y9="","",INDEX('Per Line'!$U$2:$U$1501,$Y9)&"") | K9: =IF($Y9="","",INDEX('Per Line'!$V$2:$V$1501,$Y9)) | L9: =IF($Y9="","",K9*W9/100) | M9: =IF($Y9="","",INDEX('Per Line'!$X$2:$X$1501,$Y9)) | N9: =IF($Y9="","",INDEX('Per Line'!$S$2:$S$1501,$Y9)&"") | O9: =IF($Y9="","",Settings!$C$7) | P9: =IF($Y9="","",SUMIFS('Per Line'!$AM$2:$AM$1501,'Per Line'!$D$2:$D$1501,$B9,'Per Line'!$AR$2:$AR$1501,0)) | Q9: =IF($Y9="","",P9*O9) | R9: =IF($Y9="","",Settings!$C$6) | S9: =IF($Y9="","",SUMIFS('Per Line'!$AM$2:$AM$1501,'Per Line'!$D$2:$D$1501,$B9,'Per Line'!$AR$2:$AR$1501,1)) | T9: =IF($Y9="","",S9*R9) | U9: =IF($Y9="","",T9+Q9) | V9: =IF($Y9="","",W9-U9) | W9: =IF($Y9="","",P9+S9) | X9: =IF($Y9="","",W9-U9-L9) | Y9: =IF(ROWS($Y$2:$Y9)<=MAX('Per Line'!$AQ$2:$AQ$1501),MATCH(ROWS($Y$2:$Y9),'Per Line'!$AQ$2:$AQ$1501,0),"") | Z9: =IF($Y9="","",D9&"|"&COUNTIF($D$2:$D9,D9))
B10: =IF($Y10="","",INDEX('Per Line'!$D$2:$D$1501,$Y10)&"") | C10: =IF($Y10="","",INDEX('Per Line'!$B$2:$B$1501,$Y10)&"") | E10: =IF($Y10="","",INDEX('Per Line'!$G$2:$G$1501,$Y10)&"") | F10: =IF($Y10="","",INDEX('Per Line'!$K$2:$K$1501,$Y10)&"") | G10: =IF($Y10="","",INDEX('Per Line'!$L$2:$L$1501,$Y10)&"") | H10: =IF($Y10="","",INDEX('Per Line'!$P$2:$P$1501,$Y10)&"") | I10: =IF($Y10="","",INDEX('Per Line'!$R$2:$R$1501,$Y10)&"") | J10: =IF($Y10="","",INDEX('Per Line'!$U$2:$U$1501,$Y10)&"") | K10: =IF($Y10="","",INDEX('Per Line'!$V$2:$V$1501,$Y10)) | L10: =IF($Y10="","",K10*W10/100) | M10: =IF($Y10="","",INDEX('Per Line'!$X$2:$X$1501,$Y10)) | N10: =IF($Y10="","",INDEX('Per Line'!$S$2:$S$1501,$Y10)&"") | O10: =IF($Y10="","",Settings!$C$7) | P10: =IF($Y10="","",SUMIFS('Per Line'!$AM$2:$AM$1501,'Per Line'!$D$2:$D$1501,$B10,'Per Line'!$AR$2:$AR$1501,0)) | Q10: =IF($Y10="","",P10*O10) | R10: =IF($Y10="","",Settings!$C$6) | S10: =IF($Y10="","",SUMIFS('Per Line'!$AM$2:$AM$1501,'Per Line'!$D$2:$D$1501,$B10,'Per Line'!$AR$2:$AR$1501,1)) | T10: =IF($Y10="","",S10*R10) | U10: =IF($Y10="","",T10+Q10) | V10: =IF($Y10="","",W10-U10) | W10: =IF($Y10="","",P10+S10) | X10: =IF($Y10="","",W10-U10-L10) | Y10: =IF(ROWS($Y$2:$Y10)<=MAX('Per Line'!$AQ$2:$AQ$1501),MATCH(ROWS($Y$2:$Y10),'Per Line'!$AQ$2:$AQ$1501,0),"") | Z10: =IF($Y10="","",D10&"|"&COUNTIF($D$2:$D10,D10))
B11: =IF($Y11="","",INDEX('Per Line'!$D$2:$D$1501,$Y11)&"") | C11: =IF($Y11="","",INDEX('Per Line'!$B$2:$B$1501,$Y11)&"") | E11: =IF($Y11="","",INDEX('Per Line'!$G$2:$G$1501,$Y11)&"") | F11: =IF($Y11="","",INDEX('Per Line'!$K$2:$K$1501,$Y11)&"") | G11: =IF($Y11="","",INDEX('Per Line'!$L$2:$L$1501,$Y11)&"") | H11: =IF($Y11="","",INDEX('Per Line'!$P$2:$P$1501,$Y11)&"") | I11: =IF($Y11="","",INDEX('Per Line'!$R$2:$R$1501,$Y11)&"") | J11: =IF($Y11="","",INDEX('Per Line'!$U$2:$U$1501,$Y11)&"") | K11: =IF($Y11="","",INDEX('Per Line'!$V$2:$V$1501,$Y11)) | L11: =IF($Y11="","",K11*W11/100) | M11: =IF($Y11="","",INDEX('Per Line'!$X$2:$X$1501,$Y11)) | N11: =IF($Y11="","",INDEX('Per Line'!$S$2:$S$1501,$Y11)&"") | O11: =IF($Y11="","",Settings!$C$7) | P11: =IF($Y11="","",SUMIFS('Per Line'!$AM$2:$AM$1501,'Per Line'!$D$2:$D$1501,$B11,'Per Line'!$AR$2:$AR$1501,0)) | Q11: =IF($Y11="","",P11*O11) | R11: =IF($Y11="","",Settings!$C$6) | S11: =IF($Y11="","",SUMIFS('Per Line'!$AM$2:$AM$1501,'Per Line'!$D$2:$D$1501,$B11,'Per Line'!$AR$2:$AR$1501,1)) | T11: =IF($Y11="","",S11*R11) | U11: =IF($Y11="","",T11+Q11) | V11: =IF($Y11="","",W11-U11) | W11: =IF($Y11="","",P11+S11) | X11: =IF($Y11="","",W11-U11-L11) | Y11: =IF(ROWS($Y$2:$Y11)<=MAX('Per Line'!$AQ$2:$AQ$1501),MATCH(ROWS($Y$2:$Y11),'Per Line'!$AQ$2:$AQ$1501,0),"") | Z11: =IF($Y11="","",D11&"|"&COUNTIF($D$2:$D11,D11))
B12: =IF($Y12="","",INDEX('Per Line'!$D$2:$D$1501,$Y12)&"") | C12: =IF($Y12="","",INDEX('Per Line'!$B$2:$B$1501,$Y12)&"") | E12: =IF($Y12="","",INDEX('Per Line'!$G$2:$G$1501,$Y12)&"") | F12: =IF($Y12="","",INDEX('Per Line'!$K$2:$K$1501,$Y12)&"") | G12: =IF($Y12="","",INDEX('Per Line'!$L$2:$L$1501,$Y12)&"") | H12: =IF($Y12="","",INDEX('Per Line'!$P$2:$P$1501,$Y12)&"") | I12: =IF($Y12="","",INDEX('Per Line'!$R$2:$R$1501,$Y12)&"") | J12: =IF($Y12="","",INDEX('Per Line'!$U$2:$U$1501,$Y12)&"") | K12: =IF($Y12="","",INDEX('Per Line'!$V$2:$V$1501,$Y12)) | L12: =IF($Y12="","",K12*W12/100) | M12: =IF($Y12="","",INDEX('Per Line'!$X$2:$X$1501,$Y12)) | N12: =IF($Y12="","",INDEX('Per Line'!$S$2:$S$1501,$Y12)&"") | O12: =IF($Y12="","",Settings!$C$7) | P12: =IF($Y12="","",SUMIFS('Per Line'!$AM$2:$AM$1501,'Per Line'!$D$2:$D$1501,$B12,'Per Line'!$AR$2:$AR$1501,0)) | Q12: =IF($Y12="","",P12*O12) | R12: =IF($Y12="","",Settings!$C$6) | S12: =IF($Y12="","",SUMIFS('Per Line'!$AM$2:$AM$1501,'Per Line'!$D$2:$D$1501,$B12,'Per Line'!$AR$2:$AR$1501,1)) | T12: =IF($Y12="","",S12*R12) | U12: =IF($Y12="","",T12+Q12) | V12: =IF($Y12="","",W12-U12) | W12: =IF($Y12="","",P12+S12) | X12: =IF($Y12="","",W12-U12-L12) | Y12: =IF(ROWS($Y$2:$Y12)<=MAX('Per Line'!$AQ$2:$AQ$1501),MATCH(ROWS($Y$2:$Y12),'Per Line'!$AQ$2:$AQ$1501,0),"") | Z12: =IF($Y12="","",D12&"|"&COUNTIF($D$2:$D12,D12))
B13: =IF($Y13="","",INDEX('Per Line'!$D$2:$D$1501,$Y13)&"") | C13: =IF($Y13="","",INDEX('Per Line'!$B$2:$B$1501,$Y13)&"") | E13: =IF($Y13="","",INDEX('Per Line'!$G$2:$G$1501,$Y13)&"") | F13: =IF($Y13="","",INDEX('Per Line'!$K$2:$K$1501,$Y13)&"") | G13: =IF($Y13="","",INDEX('Per Line'!$L$2:$L$1501,$Y13)&"") | H13: =IF($Y13="","",INDEX('Per Line'!$P$2:$P$1501,$Y13)&"") | I13: =IF($Y13="","",INDEX('Per Line'!$R$2:$R$1501,$Y13)&"") | J13: =IF($Y13="","",INDEX('Per Line'!$U$2:$U$1501,$Y13)&"") | K13: =IF($Y13="","",INDEX('Per Line'!$V$2:$V$1501,$Y13)) | L13: =IF($Y13="","",K13*W13/100) | M13: =IF($Y13="","",INDEX('Per Line'!$X$2:$X$1501,$Y13)) | N13: =IF($Y13="","",INDEX('Per Line'!$S$2:$S$1501,$Y13)&"") | O13: =IF($Y13="","",Settings!$C$7) | P13: =IF($Y13="","",SUMIFS('Per Line'!$AM$2:$AM$1501,'Per Line'!$D$2:$D$1501,$B13,'Per Line'!$AR$2:$AR$1501,0)) | Q13: =IF($Y13="","",P13*O13) | R13: =IF($Y13="","",Settings!$C$6) | S13: =IF($Y13="","",SUMIFS('Per Line'!$AM$2:$AM$1501,'Per Line'!$D$2:$D$1501,$B13,'Per Line'!$AR$2:$AR$1501,1)) | T13: =IF($Y13="","",S13*R13) | U13: =IF($Y13="","",T13+Q13) | V13: =IF($Y13="","",W13-U13) | W13: =IF($Y13="","",P13+S13) | X13: =IF($Y13="","",W13-U13-L13) | Y13: =IF(ROWS($Y$2:$Y13)<=MAX('Per Line'!$AQ$2:$AQ$1501),MATCH(ROWS($Y$2:$Y13),'Per Line'!$AQ$2:$AQ$1501,0),"") | Z13: =IF($Y13="","",D13&"|"&COUNTIF($D$2:$D13,D13))
... B501: =IF($Y501="","",INDEX('Per Line'!$D$2:$D$1501,$Y501)&"") | C501: =IF($Y501="","",INDEX('Per Line'!$B$2:$B$1501,$Y501)&"") | E501: =IF($Y501="","",INDEX('Per Line'!$G$2:$G$1501,$Y501)&"") | F501: =IF($Y501="","",INDEX('Per Line'!$K$2:$K$1501,$Y501)&"") | G501: =IF($Y501="","",INDEX('Per Line'!$L$2:$L$1501,$Y501)&"") | H501: =IF($Y501="","",INDEX('Per Line'!$P$2:$P$1501,$Y501)&"") | I501: =IF($Y501="","",INDEX('Per Line'!$R$2:$R$1501,$Y501)&"") | J501: =IF($Y501="","",INDEX('Per Line'!$U$2:$U$1501,$Y501)&"") | K501: =IF($Y501="","",INDEX('Per Line'!$V$2:$V$1501,$Y501)) | L501: =IF($Y501="","",K501*W501/100) | M501: =IF($Y501="","",INDEX('Per Line'!$X$2:$X$1501,$Y501)) | N501: =IF($Y501="","",INDEX('Per Line'!$S$2:$S$1501,$Y501)&"") | O501: =IF($Y501="","",Settings!$C$7) | P501: =IF($Y501="","",SUMIFS('Per Line'!$AM$2:$AM$1501,'Per Line'!$D$2:$D$1501,$B501,'Per Line'!$AR$2:$AR$1501,0)) | Q501: =IF($Y501="","",P501*O501) | R501: =IF($Y501="","",Settings!$C$6) | S501: =IF($Y501="","",SUMIFS('Per Line'!$AM$2:$AM$1501,'Per Line'!$D$2:$D$1501,$B501,'Per Line'!$AR$2:$AR$1501,1)) | T501: =IF($Y501="","",S501*R501) | U501: =IF($Y501="","",T501+Q501) | V501: =IF($Y501="","",W501-U501) | W501: =IF($Y501="","",P501+S501) | X501: =IF($Y501="","",W501-U501-L501) | Y501: =IF(ROWS($Y$2:$Y501)<=MAX('Per Line'!$AQ$2:$AQ$1501),MATCH(ROWS($Y$2:$Y501),'Per Line'!$AQ$2:$AQ$1501,0),"") | Z501: =IF($Y501="","",D501&"|"&COUNTIF($D$2:$D501,D501))

Sheet Mohandes
A1: Invoice | B1: Order Number | C1: ERX ID | D1: Payer | E1: Approval Reference | F1: Branch | G1: Order Status | H1: Order Type | I1: Payer | J1: Card Number | K1: Co Payment (%) | L1: Co val | M1: Creation Date | N1: Card Holder Name | O1: IMP % | P1: IMP | Q1: IMP VAL | R1: LOC % | S1: LOC | T1: LOC VAL | U1: TOTAL VAL | V1: SUBTOTAL | W1: Grand Total | X1: NET | Y1: Src Row (helper)
A2: =IF($Y2="","",IF(INDEX('Per Invoice'!A$2:A$501,$Y2)="","",INDEX('Per Invoice'!A$2:A$501,$Y2))) | B2: =IF($Y2="","",IF(INDEX('Per Invoice'!B$2:B$501,$Y2)="","",INDEX('Per Invoice'!B$2:B$501,$Y2))) | C2: =IF($Y2="","",IF(INDEX('Per Invoice'!C$2:C$501,$Y2)="","",INDEX('Per Invoice'!C$2:C$501,$Y2))) | D2: =IF($Y2="","",IF(INDEX('Per Invoice'!D$2:D$501,$Y2)="","",INDEX('Per Invoice'!D$2:D$501,$Y2))) | E2: =IF($Y2="","",IF(INDEX('Per Invoice'!E$2:E$501,$Y2)="","",INDEX('Per Invoice'!E$2:E$501,$Y2))) | F2: =IF($Y2="","",IF(INDEX('Per Invoice'!F$2:F$501,$Y2)="","",INDEX('Per Invoice'!F$2:F$501,$Y2))) | G2: =IF($Y2="","",IF(INDEX('Per Invoice'!G$2:G$501,$Y2)="","",INDEX('Per Invoice'!G$2:G$501,$Y2))) | H2: =IF($Y2="","",IF(INDEX('Per Invoice'!H$2:H$501,$Y2)="","",INDEX('Per Invoice'!H$2:H$501,$Y2))) | ... X2: =IF($Y2="","",IF(INDEX('Per Invoice'!X$2:X$501,$Y2)="","",INDEX('Per Invoice'!X$2:X$501,$Y2))) | Y2: =IFERROR(MATCH(Settings!$C$26&"|"&ROWS($Y$2:$Y2),'Per Invoice'!$Z$2:$Z$501,0),"")
A3: =IF($Y3="","",IF(INDEX('Per Invoice'!A$2:A$501,$Y3)="","",INDEX('Per Invoice'!A$2:A$501,$Y3))) | B3: =IF($Y3="","",IF(INDEX('Per Invoice'!B$2:B$501,$Y3)="","",INDEX('Per Invoice'!B$2:B$501,$Y3))) | C3: =IF($Y3="","",IF(INDEX('Per Invoice'!C$2:C$501,$Y3)="","",INDEX('Per Invoice'!C$2:C$501,$Y3))) | D3: =IF($Y3="","",IF(INDEX('Per Invoice'!D$2:D$501,$Y3)="","",INDEX('Per Invoice'!D$2:D$501,$Y3))) | E3: =IF($Y3="","",IF(INDEX('Per Invoice'!E$2:E$501,$Y3)="","",INDEX('Per Invoice'!E$2:E$501,$Y3))) | F3: =IF($Y3="","",IF(INDEX('Per Invoice'!F$2:F$501,$Y3)="","",INDEX('Per Invoice'!F$2:F$501,$Y3))) | G3: =IF($Y3="","",IF(INDEX('Per Invoice'!G$2:G$501,$Y3)="","",INDEX('Per Invoice'!G$2:G$501,$Y3))) | H3: =IF($Y3="","",IF(INDEX('Per Invoice'!H$2:H$501,$Y3)="","",INDEX('Per Invoice'!H$2:H$501,$Y3))) | ... X3: =IF($Y3="","",IF(INDEX('Per Invoice'!X$2:X$501,$Y3)="","",INDEX('Per Invoice'!X$2:X$501,$Y3))) | Y3: =IFERROR(MATCH(Settings!$C$26&"|"&ROWS($Y$2:$Y3),'Per Invoice'!$Z$2:$Z$501,0),"")
A4: =IF($Y4="","",IF(INDEX('Per Invoice'!A$2:A$501,$Y4)="","",INDEX('Per Invoice'!A$2:A$501,$Y4))) | B4: =IF($Y4="","",IF(INDEX('Per Invoice'!B$2:B$501,$Y4)="","",INDEX('Per Invoice'!B$2:B$501,$Y4))) | C4: =IF($Y4="","",IF(INDEX('Per Invoice'!C$2:C$501,$Y4)="","",INDEX('Per Invoice'!C$2:C$501,$Y4))) | D4: =IF($Y4="","",IF(INDEX('Per Invoice'!D$2:D$501,$Y4)="","",INDEX('Per Invoice'!D$2:D$501,$Y4))) | E4: =IF($Y4="","",IF(INDEX('Per Invoice'!E$2:E$501,$Y4)="","",INDEX('Per Invoice'!E$2:E$501,$Y4))) | F4: =IF($Y4="","",IF(INDEX('Per Invoice'!F$2:F$501,$Y4)="","",INDEX('Per Invoice'!F$2:F$501,$Y4))) | G4: =IF($Y4="","",IF(INDEX('Per Invoice'!G$2:G$501,$Y4)="","",INDEX('Per Invoice'!G$2:G$501,$Y4))) | H4: =IF($Y4="","",IF(INDEX('Per Invoice'!H$2:H$501,$Y4)="","",INDEX('Per Invoice'!H$2:H$501,$Y4))) | ... X4: =IF($Y4="","",IF(INDEX('Per Invoice'!X$2:X$501,$Y4)="","",INDEX('Per Invoice'!X$2:X$501,$Y4))) | Y4: =IFERROR(MATCH(Settings!$C$26&"|"&ROWS($Y$2:$Y4),'Per Invoice'!$Z$2:$Z$501,0),"")
A5: =IF($Y5="","",IF(INDEX('Per Invoice'!A$2:A$501,$Y5)="","",INDEX('Per Invoice'!A$2:A$501,$Y5))) | B5: =IF($Y5="","",IF(INDEX('Per Invoice'!B$2:B$501,$Y5)="","",INDEX('Per Invoice'!B$2:B$501,$Y5))) | C5: =IF($Y5="","",IF(INDEX('Per Invoice'!C$2:C$501,$Y5)="","",INDEX('Per Invoice'!C$2:C$501,$Y5))) | D5: =IF($Y5="","",IF(INDEX('Per Invoice'!D$2:D$501,$Y5)="","",INDEX('Per Invoice'!D$2:D$501,$Y5))) | E5: =IF($Y5="","",IF(INDEX('Per Invoice'!E$2:E$501,$Y5)="","",INDEX('Per Invoice'!E$2:E$501,$Y5))) | F5: =IF($Y5="","",IF(INDEX('Per Invoice'!F$2:F$501,$Y5)="","",INDEX('Per Invoice'!F$2:F$501,$Y5))) | G5: =IF($Y5="","",IF(INDEX('Per Invoice'!G$2:G$501,$Y5)="","",INDEX('Per Invoice'!G$2:G$501,$Y5))) | H5: =IF($Y5="","",IF(INDEX('Per Invoice'!H$2:H$501,$Y5)="","",INDEX('Per Invoice'!H$2:H$501,$Y5))) | ... X5: =IF($Y5="","",IF(INDEX('Per Invoice'!X$2:X$501,$Y5)="","",INDEX('Per Invoice'!X$2:X$501,$Y5))) | Y5: =IFERROR(MATCH(Settings!$C$26&"|"&ROWS($Y$2:$Y5),'Per Invoice'!$Z$2:$Z$501,0),"")
A6: =IF($Y6="","",IF(INDEX('Per Invoice'!A$2:A$501,$Y6)="","",INDEX('Per Invoice'!A$2:A$501,$Y6))) | B6: =IF($Y6="","",IF(INDEX('Per Invoice'!B$2:B$501,$Y6)="","",INDEX('Per Invoice'!B$2:B$501,$Y6))) | C6: =IF($Y6="","",IF(INDEX('Per Invoice'!C$2:C$501,$Y6)="","",INDEX('Per Invoice'!C$2:C$501,$Y6))) | D6: =IF($Y6="","",IF(INDEX('Per Invoice'!D$2:D$501,$Y6)="","",INDEX('Per Invoice'!D$2:D$501,$Y6))) | E6: =IF($Y6="","",IF(INDEX('Per Invoice'!E$2:E$501,$Y6)="","",INDEX('Per Invoice'!E$2:E$501,$Y6))) | F6: =IF($Y6="","",IF(INDEX('Per Invoice'!F$2:F$501,$Y6)="","",INDEX('Per Invoice'!F$2:F$501,$Y6))) | G6: =IF($Y6="","",IF(INDEX('Per Invoice'!G$2:G$501,$Y6)="","",INDEX('Per Invoice'!G$2:G$501,$Y6))) | H6: =IF($Y6="","",IF(INDEX('Per Invoice'!H$2:H$501,$Y6)="","",INDEX('Per Invoice'!H$2:H$501,$Y6))) | ... X6: =IF($Y6="","",IF(INDEX('Per Invoice'!X$2:X$501,$Y6)="","",INDEX('Per Invoice'!X$2:X$501,$Y6))) | Y6: =IFERROR(MATCH(Settings!$C$26&"|"&ROWS($Y$2:$Y6),'Per Invoice'!$Z$2:$Z$501,0),"")
A7: =IF($Y7="","",IF(INDEX('Per Invoice'!A$2:A$501,$Y7)="","",INDEX('Per Invoice'!A$2:A$501,$Y7))) | B7: =IF($Y7="","",IF(INDEX('Per Invoice'!B$2:B$501,$Y7)="","",INDEX('Per Invoice'!B$2:B$501,$Y7))) | C7: =IF($Y7="","",IF(INDEX('Per Invoice'!C$2:C$501,$Y7)="","",INDEX('Per Invoice'!C$2:C$501,$Y7))) | D7: =IF($Y7="","",IF(INDEX('Per Invoice'!D$2:D$501,$Y7)="","",INDEX('Per Invoice'!D$2:D$501,$Y7))) | E7: =IF($Y7="","",IF(INDEX('Per Invoice'!E$2:E$501,$Y7)="","",INDEX('Per Invoice'!E$2:E$501,$Y7))) | F7: =IF($Y7="","",IF(INDEX('Per Invoice'!F$2:F$501,$Y7)="","",INDEX('Per Invoice'!F$2:F$501,$Y7))) | G7: =IF($Y7="","",IF(INDEX('Per Invoice'!G$2:G$501,$Y7)="","",INDEX('Per Invoice'!G$2:G$501,$Y7))) | H7: =IF($Y7="","",IF(INDEX('Per Invoice'!H$2:H$501,$Y7)="","",INDEX('Per Invoice'!H$2:H$501,$Y7))) | ... X7: =IF($Y7="","",IF(INDEX('Per Invoice'!X$2:X$501,$Y7)="","",INDEX('Per Invoice'!X$2:X$501,$Y7))) | Y7: =IFERROR(MATCH(Settings!$C$26&"|"&ROWS($Y$2:$Y7),'Per Invoice'!$Z$2:$Z$501,0),"")
A8: =IF($Y8="","",IF(INDEX('Per Invoice'!A$2:A$501,$Y8)="","",INDEX('Per Invoice'!A$2:A$501,$Y8))) | B8: =IF($Y8="","",IF(INDEX('Per Invoice'!B$2:B$501,$Y8)="","",INDEX('Per Invoice'!B$2:B$501,$Y8))) | C8: =IF($Y8="","",IF(INDEX('Per Invoice'!C$2:C$501,$Y8)="","",INDEX('Per Invoice'!C$2:C$501,$Y8))) | D8: =IF($Y8="","",IF(INDEX('Per Invoice'!D$2:D$501,$Y8)="","",INDEX('Per Invoice'!D$2:D$501,$Y8))) | E8: =IF($Y8="","",IF(INDEX('Per Invoice'!E$2:E$501,$Y8)="","",INDEX('Per Invoice'!E$2:E$501,$Y8))) | F8: =IF($Y8="","",IF(INDEX('Per Invoice'!F$2:F$501,$Y8)="","",INDEX('Per Invoice'!F$2:F$501,$Y8))) | G8: =IF($Y8="","",IF(INDEX('Per Invoice'!G$2:G$501,$Y8)="","",INDEX('Per Invoice'!G$2:G$501,$Y8))) | H8: =IF($Y8="","",IF(INDEX('Per Invoice'!H$2:H$501,$Y8)="","",INDEX('Per Invoice'!H$2:H$501,$Y8))) | ... X8: =IF($Y8="","",IF(INDEX('Per Invoice'!X$2:X$501,$Y8)="","",INDEX('Per Invoice'!X$2:X$501,$Y8))) | Y8: =IFERROR(MATCH(Settings!$C$26&"|"&ROWS($Y$2:$Y8),'Per Invoice'!$Z$2:$Z$501,0),"")
A9: =IF($Y9="","",IF(INDEX('Per Invoice'!A$2:A$501,$Y9)="","",INDEX('Per Invoice'!A$2:A$501,$Y9))) | B9: =IF($Y9="","",IF(INDEX('Per Invoice'!B$2:B$501,$Y9)="","",INDEX('Per Invoice'!B$2:B$501,$Y9))) | C9: =IF($Y9="","",IF(INDEX('Per Invoice'!C$2:C$501,$Y9)="","",INDEX('Per Invoice'!C$2:C$501,$Y9))) | D9: =IF($Y9="","",IF(INDEX('Per Invoice'!D$2:D$501,$Y9)="","",INDEX('Per Invoice'!D$2:D$501,$Y9))) | E9: =IF($Y9="","",IF(INDEX('Per Invoice'!E$2:E$501,$Y9)="","",INDEX('Per Invoice'!E$2:E$501,$Y9))) | F9: =IF($Y9="","",IF(INDEX('Per Invoice'!F$2:F$501,$Y9)="","",INDEX('Per Invoice'!F$2:F$501,$Y9))) | G9: =IF($Y9="","",IF(INDEX('Per Invoice'!G$2:G$501,$Y9)="","",INDEX('Per Invoice'!G$2:G$501,$Y9))) | H9: =IF($Y9="","",IF(INDEX('Per Invoice'!H$2:H$501,$Y9)="","",INDEX('Per Invoice'!H$2:H$501,$Y9))) | ... X9: =IF($Y9="","",IF(INDEX('Per Invoice'!X$2:X$501,$Y9)="","",INDEX('Per Invoice'!X$2:X$501,$Y9))) | Y9: =IFERROR(MATCH(Settings!$C$26&"|"&ROWS($Y$2:$Y9),'Per Invoice'!$Z$2:$Z$501,0),"")
A10: =IF($Y10="","",IF(INDEX('Per Invoice'!A$2:A$501,$Y10)="","",INDEX('Per Invoice'!A$2:A$501,$Y10))) | B10: =IF($Y10="","",IF(INDEX('Per Invoice'!B$2:B$501,$Y10)="","",INDEX('Per Invoice'!B$2:B$501,$Y10))) | C10: =IF($Y10="","",IF(INDEX('Per Invoice'!C$2:C$501,$Y10)="","",INDEX('Per Invoice'!C$2:C$501,$Y10))) | D10: =IF($Y10="","",IF(INDEX('Per Invoice'!D$2:D$501,$Y10)="","",INDEX('Per Invoice'!D$2:D$501,$Y10))) | E10: =IF($Y10="","",IF(INDEX('Per Invoice'!E$2:E$501,$Y10)="","",INDEX('Per Invoice'!E$2:E$501,$Y10))) | F10: =IF($Y10="","",IF(INDEX('Per Invoice'!F$2:F$501,$Y10)="","",INDEX('Per Invoice'!F$2:F$501,$Y10))) | G10: =IF($Y10="","",IF(INDEX('Per Invoice'!G$2:G$501,$Y10)="","",INDEX('Per Invoice'!G$2:G$501,$Y10))) | H10: =IF($Y10="","",IF(INDEX('Per Invoice'!H$2:H$501,$Y10)="","",INDEX('Per Invoice'!H$2:H$501,$Y10))) | ... X10: =IF($Y10="","",IF(INDEX('Per Invoice'!X$2:X$501,$Y10)="","",INDEX('Per Invoice'!X$2:X$501,$Y10))) | Y10: =IFERROR(MATCH(Settings!$C$26&"|"&ROWS($Y$2:$Y10),'Per Invoice'!$Z$2:$Z$501,0),"")
A11: =IF($Y11="","",IF(INDEX('Per Invoice'!A$2:A$501,$Y11)="","",INDEX('Per Invoice'!A$2:A$501,$Y11))) | B11: =IF($Y11="","",IF(INDEX('Per Invoice'!B$2:B$501,$Y11)="","",INDEX('Per Invoice'!B$2:B$501,$Y11))) | C11: =IF($Y11="","",IF(INDEX('Per Invoice'!C$2:C$501,$Y11)="","",INDEX('Per Invoice'!C$2:C$501,$Y11))) | D11: =IF($Y11="","",IF(INDEX('Per Invoice'!D$2:D$501,$Y11)="","",INDEX('Per Invoice'!D$2:D$501,$Y11))) | E11: =IF($Y11="","",IF(INDEX('Per Invoice'!E$2:E$501,$Y11)="","",INDEX('Per Invoice'!E$2:E$501,$Y11))) | F11: =IF($Y11="","",IF(INDEX('Per Invoice'!F$2:F$501,$Y11)="","",INDEX('Per Invoice'!F$2:F$501,$Y11))) | G11: =IF($Y11="","",IF(INDEX('Per Invoice'!G$2:G$501,$Y11)="","",INDEX('Per Invoice'!G$2:G$501,$Y11))) | H11: =IF($Y11="","",IF(INDEX('Per Invoice'!H$2:H$501,$Y11)="","",INDEX('Per Invoice'!H$2:H$501,$Y11))) | ... X11: =IF($Y11="","",IF(INDEX('Per Invoice'!X$2:X$501,$Y11)="","",INDEX('Per Invoice'!X$2:X$501,$Y11))) | Y11: =IFERROR(MATCH(Settings!$C$26&"|"&ROWS($Y$2:$Y11),'Per Invoice'!$Z$2:$Z$501,0),"")
A12: =IF($Y12="","",IF(INDEX('Per Invoice'!A$2:A$501,$Y12)="","",INDEX('Per Invoice'!A$2:A$501,$Y12))) | B12: =IF($Y12="","",IF(INDEX('Per Invoice'!B$2:B$501,$Y12)="","",INDEX('Per Invoice'!B$2:B$501,$Y12))) | C12: =IF($Y12="","",IF(INDEX('Per Invoice'!C$2:C$501,$Y12)="","",INDEX('Per Invoice'!C$2:C$501,$Y12))) | D12: =IF($Y12="","",IF(INDEX('Per Invoice'!D$2:D$501,$Y12)="","",INDEX('Per Invoice'!D$2:D$501,$Y12))) | E12: =IF($Y12="","",IF(INDEX('Per Invoice'!E$2:E$501,$Y12)="","",INDEX('Per Invoice'!E$2:E$501,$Y12))) | F12: =IF($Y12="","",IF(INDEX('Per Invoice'!F$2:F$501,$Y12)="","",INDEX('Per Invoice'!F$2:F$501,$Y12))) | G12: =IF($Y12="","",IF(INDEX('Per Invoice'!G$2:G$501,$Y12)="","",INDEX('Per Invoice'!G$2:G$501,$Y12))) | H12: =IF($Y12="","",IF(INDEX('Per Invoice'!H$2:H$501,$Y12)="","",INDEX('Per Invoice'!H$2:H$501,$Y12))) | ... X12: =IF($Y12="","",IF(INDEX('Per Invoice'!X$2:X$501,$Y12)="","",INDEX('Per Invoice'!X$2:X$501,$Y12))) | Y12: =IFERROR(MATCH(Settings!$C$26&"|"&ROWS($Y$2:$Y12),'Per Invoice'!$Z$2:$Z$501,0),"")
A13: =IF($Y13="","",IF(INDEX('Per Invoice'!A$2:A$501,$Y13)="","",INDEX('Per Invoice'!A$2:A$501,$Y13))) | B13: =IF($Y13="","",IF(INDEX('Per Invoice'!B$2:B$501,$Y13)="","",INDEX('Per Invoice'!B$2:B$501,$Y13))) | C13: =IF($Y13="","",IF(INDEX('Per Invoice'!C$2:C$501,$Y13)="","",INDEX('Per Invoice'!C$2:C$501,$Y13))) | D13: =IF($Y13="","",IF(INDEX('Per Invoice'!D$2:D$501,$Y13)="","",INDEX('Per Invoice'!D$2:D$501,$Y13))) | E13: =IF($Y13="","",IF(INDEX('Per Invoice'!E$2:E$501,$Y13)="","",INDEX('Per Invoice'!E$2:E$501,$Y13))) | F13: =IF($Y13="","",IF(INDEX('Per Invoice'!F$2:F$501,$Y13)="","",INDEX('Per Invoice'!F$2:F$501,$Y13))) | G13: =IF($Y13="","",IF(INDEX('Per Invoice'!G$2:G$501,$Y13)="","",INDEX('Per Invoice'!G$2:G$501,$Y13))) | H13: =IF($Y13="","",IF(INDEX('Per Invoice'!H$2:H$501,$Y13)="","",INDEX('Per Invoice'!H$2:H$501,$Y13))) | ... X13: =IF($Y13="","",IF(INDEX('Per Invoice'!X$2:X$501,$Y13)="","",INDEX('Per Invoice'!X$2:X$501,$Y13))) | Y13: =IFERROR(MATCH(Settings!$C$26&"|"&ROWS($Y$2:$Y13),'Per Invoice'!$Z$2:$Z$501,0),"")
... A301: =IF($Y301="","",IF(INDEX('Per Invoice'!A$2:A$501,$Y301)="","",INDEX('Per Invoice'!A$2:A$501,$Y301))) | B301: =IF($Y301="","",IF(INDEX('Per Invoice'!B$2:B$501,$Y301)="","",INDEX('Per Invoice'!B$2:B$501,$Y301))) | C301: =IF($Y301="","",IF(INDEX('Per Invoice'!C$2:C$501,$Y301)="","",INDEX('Per Invoice'!C$2:C$501,$Y301))) | D301: =IF($Y301="","",IF(INDEX('Per Invoice'!D$2:D$501,$Y301)="","",INDEX('Per Invoice'!D$2:D$501,$Y301))) | E301: =IF($Y301="","",IF(INDEX('Per Invoice'!E$2:E$501,$Y301)="","",INDEX('Per Invoice'!E$2:E$501,$Y301))) | F301: =IF($Y301="","",IF(INDEX('Per Invoice'!F$2:F$501,$Y301)="","",INDEX('Per Invoice'!F$2:F$501,$Y301))) | G301: =IF($Y301="","",IF(INDEX('Per Invoice'!G$2:G$501,$Y301)="","",INDEX('Per Invoice'!G$2:G$501,$Y301))) | H301: =IF($Y301="","",IF(INDEX('Per Invoice'!H$2:H$501,$Y301)="","",INDEX('Per Invoice'!H$2:H$501,$Y301))) | ... X301: =IF($Y301="","",IF(INDEX('Per Invoice'!X$2:X$501,$Y301)="","",INDEX('Per Invoice'!X$2:X$501,$Y301))) | Y301: =IFERROR(MATCH(Settings!$C$26&"|"&ROWS($Y$2:$Y301),'Per Invoice'!$Z$2:$Z$501,0),"")

Sheet Arope
A1: Invoice | B1: Order Number | C1: ERX ID | D1: Payer | E1: Approval Reference | F1: Branch | G1: Order Status | H1: Order Type | I1: Payer | J1: Card Number | K1: Co Payment (%) | L1: Co val | M1: Creation Date | N1: Card Holder Name | O1: IMP % | P1: IMP | Q1: IMP VAL | R1: LOC % | S1: LOC | T1: LOC VAL | U1: TOTAL VAL | V1: SUBTOTAL | W1: Grand Total | X1: NET | Y1: Src Row (helper)
A2: =IF($Y2="","",IF(INDEX('Per Invoice'!A$2:A$501,$Y2)="","",INDEX('Per Invoice'!A$2:A$501,$Y2))) | B2: =IF($Y2="","",IF(INDEX('Per Invoice'!B$2:B$501,$Y2)="","",INDEX('Per Invoice'!B$2:B$501,$Y2))) | C2: =IF($Y2="","",IF(INDEX('Per Invoice'!C$2:C$501,$Y2)="","",INDEX('Per Invoice'!C$2:C$501,$Y2))) | D2: =IF($Y2="","",IF(INDEX('Per Invoice'!D$2:D$501,$Y2)="","",INDEX('Per Invoice'!D$2:D$501,$Y2))) | E2: =IF($Y2="","",IF(INDEX('Per Invoice'!E$2:E$501,$Y2)="","",INDEX('Per Invoice'!E$2:E$501,$Y2))) | F2: =IF($Y2="","",IF(INDEX('Per Invoice'!F$2:F$501,$Y2)="","",INDEX('Per Invoice'!F$2:F$501,$Y2))) | G2: =IF($Y2="","",IF(INDEX('Per Invoice'!G$2:G$501,$Y2)="","",INDEX('Per Invoice'!G$2:G$501,$Y2))) | H2: =IF($Y2="","",IF(INDEX('Per Invoice'!H$2:H$501,$Y2)="","",INDEX('Per Invoice'!H$2:H$501,$Y2))) | ... X2: =IF($Y2="","",IF(INDEX('Per Invoice'!X$2:X$501,$Y2)="","",INDEX('Per Invoice'!X$2:X$501,$Y2))) | Y2: =IFERROR(MATCH(Settings!$C$27&"|"&ROWS($Y$2:$Y2),'Per Invoice'!$Z$2:$Z$501,0),"")
A3: =IF($Y3="","",IF(INDEX('Per Invoice'!A$2:A$501,$Y3)="","",INDEX('Per Invoice'!A$2:A$501,$Y3))) | B3: =IF($Y3="","",IF(INDEX('Per Invoice'!B$2:B$501,$Y3)="","",INDEX('Per Invoice'!B$2:B$501,$Y3))) | C3: =IF($Y3="","",IF(INDEX('Per Invoice'!C$2:C$501,$Y3)="","",INDEX('Per Invoice'!C$2:C$501,$Y3))) | D3: =IF($Y3="","",IF(INDEX('Per Invoice'!D$2:D$501,$Y3)="","",INDEX('Per Invoice'!D$2:D$501,$Y3))) | E3: =IF($Y3="","",IF(INDEX('Per Invoice'!E$2:E$501,$Y3)="","",INDEX('Per Invoice'!E$2:E$501,$Y3))) | F3: =IF($Y3="","",IF(INDEX('Per Invoice'!F$2:F$501,$Y3)="","",INDEX('Per Invoice'!F$2:F$501,$Y3))) | G3: =IF($Y3="","",IF(INDEX('Per Invoice'!G$2:G$501,$Y3)="","",INDEX('Per Invoice'!G$2:G$501,$Y3))) | H3: =IF($Y3="","",IF(INDEX('Per Invoice'!H$2:H$501,$Y3)="","",INDEX('Per Invoice'!H$2:H$501,$Y3))) | ... X3: =IF($Y3="","",IF(INDEX('Per Invoice'!X$2:X$501,$Y3)="","",INDEX('Per Invoice'!X$2:X$501,$Y3))) | Y3: =IFERROR(MATCH(Settings!$C$27&"|"&ROWS($Y$2:$Y3),'Per Invoice'!$Z$2:$Z$501,0),"")
A4: =IF($Y4="","",IF(INDEX('Per Invoice'!A$2:A$501,$Y4)="","",INDEX('Per Invoice'!A$2:A$501,$Y4))) | B4: =IF($Y4="","",IF(INDEX('Per Invoice'!B$2:B$501,$Y4)="","",INDEX('Per Invoice'!B$2:B$501,$Y4))) | C4: =IF($Y4="","",IF(INDEX('Per Invoice'!C$2:C$501,$Y4)="","",INDEX('Per Invoice'!C$2:C$501,$Y4))) | D4: =IF($Y4="","",IF(INDEX('Per Invoice'!D$2:D$501,$Y4)="","",INDEX('Per Invoice'!D$2:D$501,$Y4))) | E4: =IF($Y4="","",IF(INDEX('Per Invoice'!E$2:E$501,$Y4)="","",INDEX('Per Invoice'!E$2:E$501,$Y4))) | F4: =IF($Y4="","",IF(INDEX('Per Invoice'!F$2:F$501,$Y4)="","",INDEX('Per Invoice'!F$2:F$501,$Y4))) | G4: =IF($Y4="","",IF(INDEX('Per Invoice'!G$2:G$501,$Y4)="","",INDEX('Per Invoice'!G$2:G$501,$Y4))) | H4: =IF($Y4="","",IF(INDEX('Per Invoice'!H$2:H$501,$Y4)="","",INDEX('Per Invoice'!H$2:H$501,$Y4))) | ... X4: =IF($Y4="","",IF(INDEX('Per Invoice'!X$2:X$501,$Y4)="","",INDEX('Per Invoice'!X$2:X$501,$Y4))) | Y4: =IFERROR(MATCH(Settings!$C$27&"|"&ROWS($Y$2:$Y4),'Per Invoice'!$Z$2:$Z$501,0),"")
A5: =IF($Y5="","",IF(INDEX('Per Invoice'!A$2:A$501,$Y5)="","",INDEX('Per Invoice'!A$2:A$501,$Y5))) | B5: =IF($Y5="","",IF(INDEX('Per Invoice'!B$2:B$501,$Y5)="","",INDEX('Per Invoice'!B$2:B$501,$Y5))) | C5: =IF($Y5="","",IF(INDEX('Per Invoice'!C$2:C$501,$Y5)="","",INDEX('Per Invoice'!C$2:C$501,$Y5))) | D5: =IF($Y5="","",IF(INDEX('Per Invoice'!D$2:D$501,$Y5)="","",INDEX('Per Invoice'!D$2:D$501,$Y5))) | E5: =IF($Y5="","",IF(INDEX('Per Invoice'!E$2:E$501,$Y5)="","",INDEX('Per Invoice'!E$2:E$501,$Y5))) | F5: =IF($Y5="","",IF(INDEX('Per Invoice'!F$2:F$501,$Y5)="","",INDEX('Per Invoice'!F$2:F$501,$Y5))) | G5: =IF($Y5="","",IF(INDEX('Per Invoice'!G$2:G$501,$Y5)="","",INDEX('Per Invoice'!G$2:G$501,$Y5))) | H5: =IF($Y5="","",IF(INDEX('Per Invoice'!H$2:H$501,$Y5)="","",INDEX('Per Invoice'!H$2:H$501,$Y5))) | ... X5: =IF($Y5="","",IF(INDEX('Per Invoice'!X$2:X$501,$Y5)="","",INDEX('Per Invoice'!X$2:X$501,$Y5))) | Y5: =IFERROR(MATCH(Settings!$C$27&"|"&ROWS($Y$2:$Y5),'Per Invoice'!$Z$2:$Z$501,0),"")
A6: =IF($Y6="","",IF(INDEX('Per Invoice'!A$2:A$501,$Y6)="","",INDEX('Per Invoice'!A$2:A$501,$Y6))) | B6: =IF($Y6="","",IF(INDEX('Per Invoice'!B$2:B$501,$Y6)="","",INDEX('Per Invoice'!B$2:B$501,$Y6))) | C6: =IF($Y6="","",IF(INDEX('Per Invoice'!C$2:C$501,$Y6)="","",INDEX('Per Invoice'!C$2:C$501,$Y6))) | D6: =IF($Y6="","",IF(INDEX('Per Invoice'!D$2:D$501,$Y6)="","",INDEX('Per Invoice'!D$2:D$501,$Y6))) | E6: =IF($Y6="","",IF(INDEX('Per Invoice'!E$2:E$501,$Y6)="","",INDEX('Per Invoice'!E$2:E$501,$Y6))) | F6: =IF($Y6="","",IF(INDEX('Per Invoice'!F$2:F$501,$Y6)="","",INDEX('Per Invoice'!F$2:F$501,$Y6))) | G6: =IF($Y6="","",IF(INDEX('Per Invoice'!G$2:G$501,$Y6)="","",INDEX('Per Invoice'!G$2:G$501,$Y6))) | H6: =IF($Y6="","",IF(INDEX('Per Invoice'!H$2:H$501,$Y6)="","",INDEX('Per Invoice'!H$2:H$501,$Y6))) | ... X6: =IF($Y6="","",IF(INDEX('Per Invoice'!X$2:X$501,$Y6)="","",INDEX('Per Invoice'!X$2:X$501,$Y6))) | Y6: =IFERROR(MATCH(Settings!$C$27&"|"&ROWS($Y$2:$Y6),'Per Invoice'!$Z$2:$Z$501,0),"")
A7: =IF($Y7="","",IF(INDEX('Per Invoice'!A$2:A$501,$Y7)="","",INDEX('Per Invoice'!A$2:A$501,$Y7))) | B7: =IF($Y7="","",IF(INDEX('Per Invoice'!B$2:B$501,$Y7)="","",INDEX('Per Invoice'!B$2:B$501,$Y7))) | C7: =IF($Y7="","",IF(INDEX('Per Invoice'!C$2:C$501,$Y7)="","",INDEX('Per Invoice'!C$2:C$501,$Y7))) | D7: =IF($Y7="","",IF(INDEX('Per Invoice'!D$2:D$501,$Y7)="","",INDEX('Per Invoice'!D$2:D$501,$Y7))) | E7: =IF($Y7="","",IF(INDEX('Per Invoice'!E$2:E$501,$Y7)="","",INDEX('Per Invoice'!E$2:E$501,$Y7))) | F7: =IF($Y7="","",IF(INDEX('Per Invoice'!F$2:F$501,$Y7)="","",INDEX('Per Invoice'!F$2:F$501,$Y7))) | G7: =IF($Y7="","",IF(INDEX('Per Invoice'!G$2:G$501,$Y7)="","",INDEX('Per Invoice'!G$2:G$501,$Y7))) | H7: =IF($Y7="","",IF(INDEX('Per Invoice'!H$2:H$501,$Y7)="","",INDEX('Per Invoice'!H$2:H$501,$Y7))) | ... X7: =IF($Y7="","",IF(INDEX('Per Invoice'!X$2:X$501,$Y7)="","",INDEX('Per Invoice'!X$2:X$501,$Y7))) | Y7: =IFERROR(MATCH(Settings!$C$27&"|"&ROWS($Y$2:$Y7),'Per Invoice'!$Z$2:$Z$501,0),"")
A8: =IF($Y8="","",IF(INDEX('Per Invoice'!A$2:A$501,$Y8)="","",INDEX('Per Invoice'!A$2:A$501,$Y8))) | B8: =IF($Y8="","",IF(INDEX('Per Invoice'!B$2:B$501,$Y8)="","",INDEX('Per Invoice'!B$2:B$501,$Y8))) | C8: =IF($Y8="","",IF(INDEX('Per Invoice'!C$2:C$501,$Y8)="","",INDEX('Per Invoice'!C$2:C$501,$Y8))) | D8: =IF($Y8="","",IF(INDEX('Per Invoice'!D$2:D$501,$Y8)="","",INDEX('Per Invoice'!D$2:D$501,$Y8))) | E8: =IF($Y8="","",IF(INDEX('Per Invoice'!E$2:E$501,$Y8)="","",INDEX('Per Invoice'!E$2:E$501,$Y8))) | F8: =IF($Y8="","",IF(INDEX('Per Invoice'!F$2:F$501,$Y8)="","",INDEX('Per Invoice'!F$2:F$501,$Y8))) | G8: =IF($Y8="","",IF(INDEX('Per Invoice'!G$2:G$501,$Y8)="","",INDEX('Per Invoice'!G$2:G$501,$Y8))) | H8: =IF($Y8="","",IF(INDEX('Per Invoice'!H$2:H$501,$Y8)="","",INDEX('Per Invoice'!H$2:H$501,$Y8))) | ... X8: =IF($Y8="","",IF(INDEX('Per Invoice'!X$2:X$501,$Y8)="","",INDEX('Per Invoice'!X$2:X$501,$Y8))) | Y8: =IFERROR(MATCH(Settings!$C$27&"|"&ROWS($Y$2:$Y8),'Per Invoice'!$Z$2:$Z$501,0),"")
A9: =IF($Y9="","",IF(INDEX('Per Invoice'!A$2:A$501,$Y9)="","",INDEX('Per Invoice'!A$2:A$501,$Y9))) | B9: =IF($Y9="","",IF(INDEX('Per Invoice'!B$2:B$501,$Y9)="","",INDEX('Per Invoice'!B$2:B$501,$Y9))) | C9: =IF($Y9="","",IF(INDEX('Per Invoice'!C$2:C$501,$Y9)="","",INDEX('Per Invoice'!C$2:C$501,$Y9))) | D9: =IF($Y9="","",IF(INDEX('Per Invoice'!D$2:D$501,$Y9)="","",INDEX('Per Invoice'!D$2:D$501,$Y9))) | E9: =IF($Y9="","",IF(INDEX('Per Invoice'!E$2:E$501,$Y9)="","",INDEX('Per Invoice'!E$2:E$501,$Y9))) | F9: =IF($Y9="","",IF(INDEX('Per Invoice'!F$2:F$501,$Y9)="","",INDEX('Per Invoice'!F$2:F$501,$Y9))) | G9: =IF($Y9="","",IF(INDEX('Per Invoice'!G$2:G$501,$Y9)="","",INDEX('Per Invoice'!G$2:G$501,$Y9))) | H9: =IF($Y9="","",IF(INDEX('Per Invoice'!H$2:H$501,$Y9)="","",INDEX('Per Invoice'!H$2:H$501,$Y9))) | ... X9: =IF($Y9="","",IF(INDEX('Per Invoice'!X$2:X$501,$Y9)="","",INDEX('Per Invoice'!X$2:X$501,$Y9))) | Y9: =IFERROR(MATCH(Settings!$C$27&"|"&ROWS($Y$2:$Y9),'Per Invoice'!$Z$2:$Z$501,0),"")
