Workbook

Sheet How To Use
A1: Claims Template - MEDRIGHT HPM (Chronic)
A3: Monthly steps
A4: 1. Open the 'Per Line' tab. Delete the old data in the BLUE columns only (row 2 down). Never delete the green or grey columns.
A5: 2. Paste the new month's data as VALUES starting at A2, into the blue columns: A-P, R-AC, AH-AP (same order as the system export).
A6: 3. Green columns (Q, AD, AE, AF, AG) and the grey helper columns (AQ-AU) calculate automatically - do not paste over them.
A7: 4. 'Per Invoice' fills itself from 'Per Line' (one row per Order #, split into IMP / Local). No pivot table, no refresh.
A8: 5. The columns you type yourself in 'Per Invoice' (blue headers): A 'Invoice', AF 'N MR'. Everything else is formula. Type them AFTER pasting the month data (they follow the row, not the order).
A9: 6. The tabs, the Arabic 'Template ...' sheets and 'Summary' fill themselves from 'Per Invoice'. Column 'Site Tab (##)' decides which tab each invoice goes to (rule and limit are in Settings).
A10: 7. Open 'Settings' and check STATUS says OK (Per Line = Per Invoice, and every invoice has a payer that is listed in Settings).
A12: Colour legend
A13: Blue header = typed/pasted by you (raw data, and 'Invoice' in Per Invoice). Green header = formula (do not paste over). Grey header = helper formula (do not touch). Yellow cell (Settings) = editable rate.
A15: Calculation rules (taken from the October 2026 sheet)
... A21: Capacity: up to 1,500 lines and 400 invoices per month. A line with an empty Order # is ignored.

Sheet Settings
B1: Company settings & checks
B3: Insurance Company | C3: MEDRIGHT HPM | D3: Informational only
B4: Corporate | C4: MedRight | D4: Informational only
B5: Sheet type | C5: Chronic | D5: Informational only
B6: Local products rebate % | C6: 0.13 | D6: Source: Oct sheet (Rebates = 13 on Local lines).
B7: Imported (IMP) products rebate % | C7: 0.05 | D7: Source: Oct sheet (Rebates = 5 on non-local lines).
B8: Special rebate % (Special Rebates? = Yes) | C8: 0.03 | D8: Lines flagged Special Rebates? = Yes get this rate (local or imported).
B9: Month totals / reconciliation
B10: Lines loaded | C10: =COUNTA('Per Line'!$E$2:$E$1501)
B11: Invoices (unique Order #) | C11: =MAX('Per Line'!$AR$2:$AR$1501)
B12: Invoices shown in Per Invoice | C12: =SUMPRODUCT(--('Per Invoice'!$B$2:$B$401<>""))
B13: Grand Total - Per Line (Product Total) | C13: =SUM('Per Line'!$Z$2:$Z$1501)
B14: Grand Total - Per Invoice | C14: =SUM('Per Invoice'!$AD$2:$AD$401)
B15: Discount - Per Line | C15: =SUM('Per Line'!$AE$2:$AE$1501)
B16: Discount - Per Invoice | C16: =SUM('Per Invoice'!$AB$2:$AB$401)
B17: Co val - Per Line | C17: =SUM('Per Line'!$Q$2:$Q$1501)
B18: Co val - Per Invoice | C18: =SUM('Per Invoice'!$P$2:$P$401)
B19: Net - Per Line | C19: =SUM('Per Line'!$AG$2:$AG$1501)
B20: Net - Per Invoice | C20: =SUM('Per Invoice'!$AE$2:$AE$401)
B21: Max Limit adjustment (Co val, Per Invoice only) | C21: 0 | D21: This company's Per Invoice has no Max Limit rule.
B23: STATUS | C23: =IF(C10=0,"No data loaded",IF(COUNTA('Per Line'!$E:$E)-1>1500,"TOO MANY LINES - extend template",IF(C11>400,"TOO MANY INVOICES - extend template",IF(AND(ROUND(C13-C14,2)=0,ROUND(C15-C16,2)=0,ROUND(C17+C21-C18,2)=0,ROUND(C19-C21-C20,2)=0,C11=C12,C29=0,MAX(D26:D27)<=400),"OK","CHECK - Per Line and Per Invoice do not match")))) | D23: Must say OK after you paste the month data.
B25: Site tabs | C25: Site name exactly as in the Site Tab (##) column | D25: Invoices (formula)
B26: FULL MATCH | C26: FULL MATCH | D26: =IF(C26="",0,COUNTIF('Per Invoice'!$C$2:$C$401,C26))
B27: NOT MATCH | C27: NOT MATCH | D27: =IF(C27="",0,COUNTIF('Per Invoice'!$C$2:$C$401,C27))
B29: Invoices not in any site tab (must be 0) | C29: =C11-SUM(D26:D27) | D29: If not 0: a new site appeared. Type its exact name in one of the empty yellow cells above (Extra 1 ... Extra n); the tab Extra n then shows it. Each tab holds up to 400 invoices.

Sheet Summary
A1: Match | B1: Count of Order # | C1: Sum of CO VAL | D1: Sum of SUBTOTAL | E1: Sum of NET
A2: =IF(Settings!$C$26="","",Settings!$C$26) | B2: =IF($A2="","",COUNTIF('Per Invoice'!$C$2:$C$401,$A2)) | C2: =IF($A2="","",SUMIFS('Per Invoice'!$P$2:$P$401,'Per Invoice'!$C$2:$C$401,$A2)) | D2: =IF($A2="","",SUMIFS('Per Invoice'!$AC$2:$AC$401,'Per Invoice'!$C$2:$C$401,$A2)) | E2: =IF($A2="","",SUMIFS('Per Invoice'!$AE$2:$AE$401,'Per Invoice'!$C$2:$C$401,$A2))
A3: =IF(Settings!$C$27="","",Settings!$C$27) | B3: =IF($A3="","",COUNTIF('Per Invoice'!$C$2:$C$401,$A3)) | C3: =IF($A3="","",SUMIFS('Per Invoice'!$P$2:$P$401,'Per Invoice'!$C$2:$C$401,$A3)) | D3: =IF($A3="","",SUMIFS('Per Invoice'!$AC$2:$AC$401,'Per Invoice'!$C$2:$C$401,$A3)) | E3: =IF($A3="","",SUMIFS('Per Invoice'!$AE$2:$AE$401,'Per Invoice'!$C$2:$C$401,$A3))
A4: Grand Total | B4: =SUM(B2:B3) | C4: =SUM(C2:C3) | D4: =SUM(D2:D3) | E4: =SUM(E2:E3)

Sheet Per Line
A1: Cycle | B1: Ticket # | C1: Stage | D1: Approval Ref | E1: Order # | F1: Channel | G1: Create At | H1: Insurance Company | I1: Country Portal ID | J1: Corporate | K1: Card | L1: Name | M1: Status | N1: Local Rebates | O1: Imported Rebates | P1: Order Co Payment | Q1: Co val | R1: By Patient | S1: heisenberg id | T1: Product Name | U1: Local | V1: Unit | W1: Quantity | X1: Delivered Quantity | Y1: Unit Price | Z1: Product Total | AA1: Product Delivered Total | AB1: ERX ID | AC1: Special Rebates? | AD1: Rebates | AE1: Discount | AF1: Subtotal | AG1: Net | AH1: Approval Type | AI1: Max Limit | AJ1: Exceeding Limit | AK1: Amount collected from customer | AL1: By Patient (Delivered) | AM1: Dispense Number | AN1: Dispense Date | AO1: Has OTP? | AP1: Match | AQ1: Order 1st Row (helper) | AR1: Invoice # (helper) | AS1: Is Local (helper) | AT1: Is Special (helper) | AU1: Sort Key (helper)
Q2: =IF($E2="","",P2*Z2/100) | AD2: =IF($E2="","",IF($AT2=1,Settings!$C$8,IF($AS2=1,Settings!$C$6,Settings!$C$7))*100) | AE2: =IF($E2="","",Z2*AD2/100) | AF2: =IF($E2="","",Z2-AE2) | AG2: =IF($E2="","",AF2-Q2) | AQ2: =IF($E2="","",IF(COUNTIF($E$2:$E2,$E2)=1,1,0)) | AR2: =IF($AQ2=1,SUMPRODUCT(--($AU$2:$AU$1501<$AU2))+1,"") | AS2: =IF($E2="","",IF(OR($U2=TRUE(),$U2="TRUE"),1,0)) | AT2: =IF($E2="","",IF($AC2="Yes",1,0)) | AU2: =IF($AQ2=1,IFERROR(IF(VALUE($E2)<100000000,VALUE($E2),1000000000),IFERROR(IF(VALUE(MID($E2,2,20))<100000000,VALUE(MID($E2,2,20)),1000000000),1000000000))+ROW()/100000,"")
Q3: =IF($E3="","",P3*Z3/100) | AD3: =IF($E3="","",IF($AT3=1,Settings!$C$8,IF($AS3=1,Settings!$C$6,Settings!$C$7))*100) | AE3: =IF($E3="","",Z3*AD3/100) | AF3: =IF($E3="","",Z3-AE3) | AG3: =IF($E3="","",AF3-Q3) | AQ3: =IF($E3="","",IF(COUNTIF($E$2:$E3,$E3)=1,1,0)) | AR3: =IF($AQ3=1,SUMPRODUCT(--($AU$2:$AU$1501<$AU3))+1,"") | AS3: =IF($E3="","",IF(OR($U3=TRUE(),$U3="TRUE"),1,0)) | AT3: =IF($E3="","",IF($AC3="Yes",1,0)) | AU3: =IF($AQ3=1,IFERROR(IF(VALUE($E3)<100000000,VALUE($E3),1000000000),IFERROR(IF(VALUE(MID($E3,2,20))<100000000,VALUE(MID($E3,2,20)),1000000000),1000000000))+ROW()/100000,"")
Q4: =IF($E4="","",P4*Z4/100) | AD4: =IF($E4="","",IF($AT4=1,Settings!$C$8,IF($AS4=1,Settings!$C$6,Settings!$C$7))*100) | AE4: =IF($E4="","",Z4*AD4/100) | AF4: =IF($E4="","",Z4-AE4) | AG4: =IF($E4="","",AF4-Q4) | AQ4: =IF($E4="","",IF(COUNTIF($E$2:$E4,$E4)=1,1,0)) | AR4: =IF($AQ4=1,SUMPRODUCT(--($AU$2:$AU$1501<$AU4))+1,"") | AS4: =IF($E4="","",IF(OR($U4=TRUE(),$U4="TRUE"),1,0)) | AT4: =IF($E4="","",IF($AC4="Yes",1,0)) | AU4: =IF($AQ4=1,IFERROR(IF(VALUE($E4)<100000000,VALUE($E4),1000000000),IFERROR(IF(VALUE(MID($E4,2,20))<100000000,VALUE(MID($E4,2,20)),1000000000),1000000000))+ROW()/100000,"")
Q5: =IF($E5="","",P5*Z5/100) | AD5: =IF($E5="","",IF($AT5=1,Settings!$C$8,IF($AS5=1,Settings!$C$6,Settings!$C$7))*100) | AE5: =IF($E5="","",Z5*AD5/100) | AF5: =IF($E5="","",Z5-AE5) | AG5: =IF($E5="","",AF5-Q5) | AQ5: =IF($E5="","",IF(COUNTIF($E$2:$E5,$E5)=1,1,0)) | AR5: =IF($AQ5=1,SUMPRODUCT(--($AU$2:$AU$1501<$AU5))+1,"") | AS5: =IF($E5="","",IF(OR($U5=TRUE(),$U5="TRUE"),1,0)) | AT5: =IF($E5="","",IF($AC5="Yes",1,0)) | AU5: =IF($AQ5=1,IFERROR(IF(VALUE($E5)<100000000,VALUE($E5),1000000000),IFERROR(IF(VALUE(MID($E5,2,20))<100000000,VALUE(MID($E5,2,20)),1000000000),1000000000))+ROW()/100000,"")
Q6: =IF($E6="","",P6*Z6/100) | AD6: =IF($E6="","",IF($AT6=1,Settings!$C$8,IF($AS6=1,Settings!$C$6,Settings!$C$7))*100) | AE6: =IF($E6="","",Z6*AD6/100) | AF6: =IF($E6="","",Z6-AE6) | AG6: =IF($E6="","",AF6-Q6) | AQ6: =IF($E6="","",IF(COUNTIF($E$2:$E6,$E6)=1,1,0)) | AR6: =IF($AQ6=1,SUMPRODUCT(--($AU$2:$AU$1501<$AU6))+1,"") | AS6: =IF($E6="","",IF(OR($U6=TRUE(),$U6="TRUE"),1,0)) | AT6: =IF($E6="","",IF($AC6="Yes",1,0)) | AU6: =IF($AQ6=1,IFERROR(IF(VALUE($E6)<100000000,VALUE($E6),1000000000),IFERROR(IF(VALUE(MID($E6,2,20))<100000000,VALUE(MID($E6,2,20)),1000000000),1000000000))+ROW()/100000,"")
Q7: =IF($E7="","",P7*Z7/100) | AD7: =IF($E7="","",IF($AT7=1,Settings!$C$8,IF($AS7=1,Settings!$C$6,Settings!$C$7))*100) | AE7: =IF($E7="","",Z7*AD7/100) | AF7: =IF($E7="","",Z7-AE7) | AG7: =IF($E7="","",AF7-Q7) | AQ7: =IF($E7="","",IF(COUNTIF($E$2:$E7,$E7)=1,1,0)) | AR7: =IF($AQ7=1,SUMPRODUCT(--($AU$2:$AU$1501<$AU7))+1,"") | AS7: =IF($E7="","",IF(OR($U7=TRUE(),$U7="TRUE"),1,0)) | AT7: =IF($E7="","",IF($AC7="Yes",1,0)) | AU7: =IF($AQ7=1,IFERROR(IF(VALUE($E7)<100000000,VALUE($E7),1000000000),IFERROR(IF(VALUE(MID($E7,2,20))<100000000,VALUE(MID($E7,2,20)),1000000000),1000000000))+ROW()/100000,"")
Q8: =IF($E8="","",P8*Z8/100) | AD8: =IF($E8="","",IF($AT8=1,Settings!$C$8,IF($AS8=1,Settings!$C$6,Settings!$C$7))*100) | AE8: =IF($E8="","",Z8*AD8/100) | AF8: =IF($E8="","",Z8-AE8) | AG8: =IF($E8="","",AF8-Q8) | AQ8: =IF($E8="","",IF(COUNTIF($E$2:$E8,$E8)=1,1,0)) | AR8: =IF($AQ8=1,SUMPRODUCT(--($AU$2:$AU$1501<$AU8))+1,"") | AS8: =IF($E8="","",IF(OR($U8=TRUE(),$U8="TRUE"),1,0)) | AT8: =IF($E8="","",IF($AC8="Yes",1,0)) | AU8: =IF($AQ8=1,IFERROR(IF(VALUE($E8)<100000000,VALUE($E8),1000000000),IFERROR(IF(VALUE(MID($E8,2,20))<100000000,VALUE(MID($E8,2,20)),1000000000),1000000000))+ROW()/100000,"")
Q9: =IF($E9="","",P9*Z9/100) | AD9: =IF($E9="","",IF($AT9=1,Settings!$C$8,IF($AS9=1,Settings!$C$6,Settings!$C$7))*100) | AE9: =IF($E9="","",Z9*AD9/100) | AF9: =IF($E9="","",Z9-AE9) | AG9: =IF($E9="","",AF9-Q9) | AQ9: =IF($E9="","",IF(COUNTIF($E$2:$E9,$E9)=1,1,0)) | AR9: =IF($AQ9=1,SUMPRODUCT(--($AU$2:$AU$1501<$AU9))+1,"") | AS9: =IF($E9="","",IF(OR($U9=TRUE(),$U9="TRUE"),1,0)) | AT9: =IF($E9="","",IF($AC9="Yes",1,0)) | AU9: =IF($AQ9=1,IFERROR(IF(VALUE($E9)<100000000,VALUE($E9),1000000000),IFERROR(IF(VALUE(MID($E9,2,20))<100000000,VALUE(MID($E9,2,20)),1000000000),1000000000))+ROW()/100000,"")
Q10: =IF($E10="","",P10*Z10/100) | AD10: =IF($E10="","",IF($AT10=1,Settings!$C$8,IF($AS10=1,Settings!$C$6,Settings!$C$7))*100) | AE10: =IF($E10="","",Z10*AD10/100) | AF10: =IF($E10="","",Z10-AE10) | AG10: =IF($E10="","",AF10-Q10) | AQ10: =IF($E10="","",IF(COUNTIF($E$2:$E10,$E10)=1,1,0)) | AR10: =IF($AQ10=1,SUMPRODUCT(--($AU$2:$AU$1501<$AU10))+1,"") | AS10: =IF($E10="","",IF(OR($U10=TRUE(),$U10="TRUE"),1,0)) | AT10: =IF($E10="","",IF($AC10="Yes",1,0)) | AU10: =IF($AQ10=1,IFERROR(IF(VALUE($E10)<100000000,VALUE($E10),1000000000),IFERROR(IF(VALUE(MID($E10,2,20))<100000000,VALUE(MID($E10,2,20)),1000000000),1000000000))+ROW()/100000,"")
Q11: =IF($E11="","",P11*Z11/100) | AD11: =IF($E11="","",IF($AT11=1,Settings!$C$8,IF($AS11=1,Settings!$C$6,Settings!$C$7))*100) | AE11: =IF($E11="","",Z11*AD11/100) | AF11: =IF($E11="","",Z11-AE11) | AG11: =IF($E11="","",AF11-Q11) | AQ11: =IF($E11="","",IF(COUNTIF($E$2:$E11,$E11)=1,1,0)) | AR11: =IF($AQ11=1,SUMPRODUCT(--($AU$2:$AU$1501<$AU11))+1,"") | AS11: =IF($E11="","",IF(OR($U11=TRUE(),$U11="TRUE"),1,0)) | AT11: =IF($E11="","",IF($AC11="Yes",1,0)) | AU11: =IF($AQ11=1,IFERROR(IF(VALUE($E11)<100000000,VALUE($E11),1000000000),IFERROR(IF(VALUE(MID($E11,2,20))<100000000,VALUE(MID($E11,2,20)),1000000000),1000000000))+ROW()/100000,"")
Q12: =IF($E12="","",P12*Z12/100) | AD12: =IF($E12="","",IF($AT12=1,Settings!$C$8,IF($AS12=1,Settings!$C$6,Settings!$C$7))*100) | AE12: =IF($E12="","",Z12*AD12/100) | AF12: =IF($E12="","",Z12-AE12) | AG12: =IF($E12="","",AF12-Q12) | AQ12: =IF($E12="","",IF(COUNTIF($E$2:$E12,$E12)=1,1,0)) | AR12: =IF($AQ12=1,SUMPRODUCT(--($AU$2:$AU$1501<$AU12))+1,"") | AS12: =IF($E12="","",IF(OR($U12=TRUE(),$U12="TRUE"),1,0)) | AT12: =IF($E12="","",IF($AC12="Yes",1,0)) | AU12: =IF($AQ12=1,IFERROR(IF(VALUE($E12)<100000000,VALUE($E12),1000000000),IFERROR(IF(VALUE(MID($E12,2,20))<100000000,VALUE(MID($E12,2,20)),1000000000),1000000000))+ROW()/100000,"")
Q13: =IF($E13="","",P13*Z13/100) | AD13: =IF($E13="","",IF($AT13=1,Settings!$C$8,IF($AS13=1,Settings!$C$6,Settings!$C$7))*100) | AE13: =IF($E13="","",Z13*AD13/100) | AF13: =IF($E13="","",Z13-AE13) | AG13: =IF($E13="","",AF13-Q13) | AQ13: =IF($E13="","",IF(COUNTIF($E$2:$E13,$E13)=1,1,0)) | AR13: =IF($AQ13=1,SUMPRODUCT(--($AU$2:$AU$1501<$AU13))+1,"") | AS13: =IF($E13="","",IF(OR($U13=TRUE(),$U13="TRUE"),1,0)) | AT13: =IF($E13="","",IF($AC13="Yes",1,0)) | AU13: =IF($AQ13=1,IFERROR(IF(VALUE($E13)<100000000,VALUE($E13),1000000000),IFERROR(IF(VALUE(MID($E13,2,20))<100000000,VALUE(MID($E13,2,20)),1000000000),1000000000))+ROW()/100000,"")
... Q1501: =IF($E1501="","",P1501*Z1501/100) | AD1501: =IF($E1501="","",IF($AT1501=1,Settings!$C$8,IF($AS1501=1,Settings!$C$6,Settings!$C$7))*100) | AE1501: =IF($E1501="","",Z1501*AD1501/100) | AF1501: =IF($E1501="","",Z1501-AE1501) | AG1501: =IF($E1501="","",AF1501-Q1501) | AQ1501: =IF($E1501="","",IF(COUNTIF($E$2:$E1501,$E1501)=1,1,0)) | AR1501: =IF($AQ1501=1,SUMPRODUCT(--($AU$2:$AU$1501<$AU1501))+1,"") | AS1501: =IF($E1501="","",IF(OR($U1501=TRUE(),$U1501="TRUE"),1,0)) | AT1501: =IF($E1501="","",IF($AC1501="Yes",1,0)) | AU1501: =IF($AQ1501=1,IFERROR(IF(VALUE($E1501)<100000000,VALUE($E1501),1000000000),IFERROR(IF(VALUE(MID($E1501,2,20))<100000000,VALUE(MID($E1501,2,20)),1000000000),1000000000))+ROW()/100000,"")

Sheet Per Invoice
A1: Invoice | B1: Order # | C1: Match Tab | D1: Cycle | E1: Ticket # | F1: Stage | G1: Approval Ref | H1: Channel | I1: Create At | J1: Insurance Company | K1: Corporate | L1: Card | M1: Name | N1: Status | O1: Order Co Payment | P1: Co val | Q1: By Patient | R1: ERX ID | S1: SPECIAL REBATES % | T1: SPECIAL REBATES | U1: SPECIAL REBATES VAL | V1: IMP % | W1: IMP | X1: IMP VAL | Y1: LOCAL % | Z1: LOCAL | AA1: LOCAL VAL | AB1: TOTAL VAL | AC1: SUBTOTAL | AD1: Grand Total | AE1: NET | AF1: N MR | AG1: D | AH1: Src Row (helper) | AI1: Payer Key (helper)
B2: =IF($AH2="","",INDEX('Per Line'!$E$2:$E$1501,$AH2)&"") | C2: =IF($AH2="","",IF(INDEX('Per Line'!$AP$2:$AP$1501,$AH2)="NOT MATCH","NOT MATCH","FULL MATCH")) | D2: =IF($AH2="","",INDEX('Per Line'!$A$2:$A$1501,$AH2)&"") | E2: =IF($AH2="","",INDEX('Per Line'!$B$2:$B$1501,$AH2)) | F2: =IF($AH2="","",INDEX('Per Line'!$C$2:$C$1501,$AH2)&"") | G2: =IF($AH2="","",INDEX('Per Line'!$D$2:$D$1501,$AH2)&"") | H2: =IF($AH2="","",INDEX('Per Line'!$F$2:$F$1501,$AH2)&"") | I2: =IF($AH2="","",INDEX('Per Line'!$G$2:$G$1501,$AH2)) | J2: =IF($AH2="","",INDEX('Per Line'!$H$2:$H$1501,$AH2)&"") | K2: =IF($AH2="","",INDEX('Per Line'!$J$2:$J$1501,$AH2)&"") | L2: =IF($AH2="","",INDEX('Per Line'!$K$2:$K$1501,$AH2)&"") | M2: =IF($AH2="","",INDEX('Per Line'!$L$2:$L$1501,$AH2)&"") | N2: =IF($AH2="","",INDEX('Per Line'!$M$2:$M$1501,$AH2)&"") | O2: =IF($AH2="","",INDEX('Per Line'!$P$2:$P$1501,$AH2)) | P2: =IF($AH2="","",O2*AD2/100) | Q2: =IF($AH2="","",INDEX('Per Line'!$R$2:$R$1501,$AH2)&"") | R2: =IF($AH2="","",INDEX('Per Line'!$AB$2:$AB$1501,$AH2)&"") | S2: =IF($AH2="","",Settings!$C$8) | T2: =IF($AH2="","",SUMIFS('Per Line'!$Z$2:$Z$1501,'Per Line'!$E$2:$E$1501,$B2,'Per Line'!$AT$2:$AT$1501,1)) | U2: =IF($AH2="","",T2*S2) | V2: =IF($AH2="","",Settings!$C$7) | W2: =IF($AH2="","",SUMIFS('Per Line'!$Z$2:$Z$1501,'Per Line'!$E$2:$E$1501,$B2,'Per Line'!$AS$2:$AS$1501,0,'Per Line'!$AT$2:$AT$1501,0)) | X2: =IF($AH2="","",W2*V2) | Y2: =IF($AH2="","",Settings!$C$6) | Z2: =IF($AH2="","",SUMIFS('Per Line'!$Z$2:$Z$1501,'Per Line'!$E$2:$E$1501,$B2,'Per Line'!$AS$2:$AS$1501,1,'Per Line'!$AT$2:$AT$1501,0)) | AA2: =IF($AH2="","",Z2*Y2) | AB2: =IF($AH2="","",AA2+X2+U2) | AC2: =IF($AH2="","",AD2-AB2) | AD2: =IF($AH2="","",W2+Z2+T2) | AE2: =IF($AH2="","",AD2-AB2-P2) | AG2: =IF($AH2="","",AE2-N(AF2)) | AH2: =IF(ROWS($AH$2:$AH2)<=MAX('Per Line'!$AR$2:$AR$1501),MATCH(ROWS($AH$2:$AH2),'Per Line'!$AR$2:$AR$1501,0),"") | AI2: =IF($AH2="","",C2&"|"&COUNTIF($C$2:$C2,C2))
B3: =IF($AH3="","",INDEX('Per Line'!$E$2:$E$1501,$AH3)&"") | C3: =IF($AH3="","",IF(INDEX('Per Line'!$AP$2:$AP$1501,$AH3)="NOT MATCH","NOT MATCH","FULL MATCH")) | D3: =IF($AH3="","",INDEX('Per Line'!$A$2:$A$1501,$AH3)&"") | E3: =IF($AH3="","",INDEX('Per Line'!$B$2:$B$1501,$AH3)) | F3: =IF($AH3="","",INDEX('Per Line'!$C$2:$C$1501,$AH3)&"") | G3: =IF($AH3="","",INDEX('Per Line'!$D$2:$D$1501,$AH3)&"") | H3: =IF($AH3="","",INDEX('Per Line'!$F$2:$F$1501,$AH3)&"") | I3: =IF($AH3="","",INDEX('Per Line'!$G$2:$G$1501,$AH3)) | J3: =IF($AH3="","",INDEX('Per Line'!$H$2:$H$1501,$AH3)&"") | K3: =IF($AH3="","",INDEX('Per Line'!$J$2:$J$1501,$AH3)&"") | L3: =IF($AH3="","",INDEX('Per Line'!$K$2:$K$1501,$AH3)&"") | M3: =IF($AH3="","",INDEX('Per Line'!$L$2:$L$1501,$AH3)&"") | N3: =IF($AH3="","",INDEX('Per Line'!$M$2:$M$1501,$AH3)&"") | O3: =IF($AH3="","",INDEX('Per Line'!$P$2:$P$1501,$AH3)) | P3: =IF($AH3="","",O3*AD3/100) | Q3: =IF($AH3="","",INDEX('Per Line'!$R$2:$R$1501,$AH3)&"") | R3: =IF($AH3="","",INDEX('Per Line'!$AB$2:$AB$1501,$AH3)&"") | S3: =IF($AH3="","",Settings!$C$8) | T3: =IF($AH3="","",SUMIFS('Per Line'!$Z$2:$Z$1501,'Per Line'!$E$2:$E$1501,$B3,'Per Line'!$AT$2:$AT$1501,1)) | U3: =IF($AH3="","",T3*S3) | V3: =IF($AH3="","",Settings!$C$7) | W3: =IF($AH3="","",SUMIFS('Per Line'!$Z$2:$Z$1501,'Per Line'!$E$2:$E$1501,$B3,'Per Line'!$AS$2:$AS$1501,0,'Per Line'!$AT$2:$AT$1501,0)) | X3: =IF($AH3="","",W3*V3) | Y3: =IF($AH3="","",Settings!$C$6) | Z3: =IF($AH3="","",SUMIFS('Per Line'!$Z$2:$Z$1501,'Per Line'!$E$2:$E$1501,$B3,'Per Line'!$AS$2:$AS$1501,1,'Per Line'!$AT$2:$AT$1501,0)) | AA3: =IF($AH3="","",Z3*Y3) | AB3: =IF($AH3="","",AA3+X3+U3) | AC3: =IF($AH3="","",AD3-AB3) | AD3: =IF($AH3="","",W3+Z3+T3) | AE3: =IF($AH3="","",AD3-AB3-P3) | AG3: =IF($AH3="","",AE3-N(AF3)) | AH3: =IF(ROWS($AH$2:$AH3)<=MAX('Per Line'!$AR$2:$AR$1501),MATCH(ROWS($AH$2:$AH3),'Per Line'!$AR$2:$AR$1501,0),"") | AI3: =IF($AH3="","",C3&"|"&COUNTIF($C$2:$C3,C3))
B4: =IF($AH4="","",INDEX('Per Line'!$E$2:$E$1501,$AH4)&"") | C4: =IF($AH4="","",IF(INDEX('Per Line'!$AP$2:$AP$1501,$AH4)="NOT MATCH","NOT MATCH","FULL MATCH")) | D4: =IF($AH4="","",INDEX('Per Line'!$A$2:$A$1501,$AH4)&"") | E4: =IF($AH4="","",INDEX('Per Line'!$B$2:$B$1501,$AH4)) | F4: =IF($AH4="","",INDEX('Per Line'!$C$2:$C$1501,$AH4)&"") | G4: =IF($AH4="","",INDEX('Per Line'!$D$2:$D$1501,$AH4)&"") | H4: =IF($AH4="","",INDEX('Per Line'!$F$2:$F$1501,$AH4)&"") | I4: =IF($AH4="","",INDEX('Per Line'!$G$2:$G$1501,$AH4)) | J4: =IF($AH4="","",INDEX('Per Line'!$H$2:$H$1501,$AH4)&"") | K4: =IF($AH4="","",INDEX('Per Line'!$J$2:$J$1501,$AH4)&"") | L4: =IF($AH4="","",INDEX('Per Line'!$K$2:$K$1501,$AH4)&"") | M4: =IF($AH4="","",INDEX('Per Line'!$L$2:$L$1501,$AH4)&"") | N4: =IF($AH4="","",INDEX('Per Line'!$M$2:$M$1501,$AH4)&"") | O4: =IF($AH4="","",INDEX('Per Line'!$P$2:$P$1501,$AH4)) | P4: =IF($AH4="","",O4*AD4/100) | Q4: =IF($AH4="","",INDEX('Per Line'!$R$2:$R$1501,$AH4)&"") | R4: =IF($AH4="","",INDEX('Per Line'!$AB$2:$AB$1501,$AH4)&"") | S4: =IF($AH4="","",Settings!$C$8) | T4: =IF($AH4="","",SUMIFS('Per Line'!$Z$2:$Z$1501,'Per Line'!$E$2:$E$1501,$B4,'Per Line'!$AT$2:$AT$1501,1)) | U4: =IF($AH4="","",T4*S4) | V4: =IF($AH4="","",Settings!$C$7) | W4: =IF($AH4="","",SUMIFS('Per Line'!$Z$2:$Z$1501,'Per Line'!$E$2:$E$1501,$B4,'Per Line'!$AS$2:$AS$1501,0,'Per Line'!$AT$2:$AT$1501,0)) | X4: =IF($AH4="","",W4*V4) | Y4: =IF($AH4="","",Settings!$C$6) | Z4: =IF($AH4="","",SUMIFS('Per Line'!$Z$2:$Z$1501,'Per Line'!$E$2:$E$1501,$B4,'Per Line'!$AS$2:$AS$1501,1,'Per Line'!$AT$2:$AT$1501,0)) | AA4: =IF($AH4="","",Z4*Y4) | AB4: =IF($AH4="","",AA4+X4+U4) | AC4: =IF($AH4="","",AD4-AB4) | AD4: =IF($AH4="","",W4+Z4+T4) | AE4: =IF($AH4="","",AD4-AB4-P4) | AG4: =IF($AH4="","",AE4-N(AF4)) | AH4: =IF(ROWS($AH$2:$AH4)<=MAX('Per Line'!$AR$2:$AR$1501),MATCH(ROWS($AH$2:$AH4),'Per Line'!$AR$2:$AR$1501,0),"") | AI4: =IF($AH4="","",C4&"|"&COUNTIF($C$2:$C4,C4))
B5: =IF($AH5="","",INDEX('Per Line'!$E$2:$E$1501,$AH5)&"") | C5: =IF($AH5="","",IF(INDEX('Per Line'!$AP$2:$AP$1501,$AH5)="NOT MATCH","NOT MATCH","FULL MATCH")) | D5: =IF($AH5="","",INDEX('Per Line'!$A$2:$A$1501,$AH5)&"") | E5: =IF($AH5="","",INDEX('Per Line'!$B$2:$B$1501,$AH5)) | F5: =IF($AH5="","",INDEX('Per Line'!$C$2:$C$1501,$AH5)&"") | G5: =IF($AH5="","",INDEX('Per Line'!$D$2:$D$1501,$AH5)&"") | H5: =IF($AH5="","",INDEX('Per Line'!$F$2:$F$1501,$AH5)&"") | I5: =IF($AH5="","",INDEX('Per Line'!$G$2:$G$1501,$AH5)) | J5: =IF($AH5="","",INDEX('Per Line'!$H$2:$H$1501,$AH5)&"") | K5: =IF($AH5="","",INDEX('Per Line'!$J$2:$J$1501,$AH5)&"") | L5: =IF($AH5="","",INDEX('Per Line'!$K$2:$K$1501,$AH5)&"") | M5: =IF($AH5="","",INDEX('Per Line'!$L$2:$L$1501,$AH5)&"") | N5: =IF($AH5="","",INDEX('Per Line'!$M$2:$M$1501,$AH5)&"") | O5: =IF($AH5="","",INDEX('Per Line'!$P$2:$P$1501,$AH5)) | P5: =IF($AH5="","",O5*AD5/100) | Q5: =IF($AH5="","",INDEX('Per Line'!$R$2:$R$1501,$AH5)&"") | R5: =IF($AH5="","",INDEX('Per Line'!$AB$2:$AB$1501,$AH5)&"") | S5: =IF($AH5="","",Settings!$C$8) | T5: =IF($AH5="","",SUMIFS('Per Line'!$Z$2:$Z$1501,'Per Line'!$E$2:$E$1501,$B5,'Per Line'!$AT$2:$AT$1501,1)) | U5: =IF($AH5="","",T5*S5) | V5: =IF($AH5="","",Settings!$C$7) | W5: =IF($AH5="","",SUMIFS('Per Line'!$Z$2:$Z$1501,'Per Line'!$E$2:$E$1501,$B5,'Per Line'!$AS$2:$AS$1501,0,'Per Line'!$AT$2:$AT$1501,0)) | X5: =IF($AH5="","",W5*V5) | Y5: =IF($AH5="","",Settings!$C$6) | Z5: =IF($AH5="","",SUMIFS('Per Line'!$Z$2:$Z$1501,'Per Line'!$E$2:$E$1501,$B5,'Per Line'!$AS$2:$AS$1501,1,'Per Line'!$AT$2:$AT$1501,0)) | AA5: =IF($AH5="","",Z5*Y5) | AB5: =IF($AH5="","",AA5+X5+U5) | AC5: =IF($AH5="","",AD5-AB5) | AD5: =IF($AH5="","",W5+Z5+T5) | AE5: =IF($AH5="","",AD5-AB5-P5) | AG5: =IF($AH5="","",AE5-N(AF5)) | AH5: =IF(ROWS($AH$2:$AH5)<=MAX('Per Line'!$AR$2:$AR$1501),MATCH(ROWS($AH$2:$AH5),'Per Line'!$AR$2:$AR$1501,0),"") | AI5: =IF($AH5="","",C5&"|"&COUNTIF($C$2:$C5,C5))
B6: =IF($AH6="","",INDEX('Per Line'!$E$2:$E$1501,$AH6)&"") | C6: =IF($AH6="","",IF(INDEX('Per Line'!$AP$2:$AP$1501,$AH6)="NOT MATCH","NOT MATCH","FULL MATCH")) | D6: =IF($AH6="","",INDEX('Per Line'!$A$2:$A$1501,$AH6)&"") | E6: =IF($AH6="","",INDEX('Per Line'!$B$2:$B$1501,$AH6)) | F6: =IF($AH6="","",INDEX('Per Line'!$C$2:$C$1501,$AH6)&"") | G6: =IF($AH6="","",INDEX('Per Line'!$D$2:$D$1501,$AH6)&"") | H6: =IF($AH6="","",INDEX('Per Line'!$F$2:$F$1501,$AH6)&"") | I6: =IF($AH6="","",INDEX('Per Line'!$G$2:$G$1501,$AH6)) | J6: =IF($AH6="","",INDEX('Per Line'!$H$2:$H$1501,$AH6)&"") | K6: =IF($AH6="","",INDEX('Per Line'!$J$2:$J$1501,$AH6)&"") | L6: =IF($AH6="","",INDEX('Per Line'!$K$2:$K$1501,$AH6)&"") | M6: =IF($AH6="","",INDEX('Per Line'!$L$2:$L$1501,$AH6)&"") | N6: =IF($AH6="","",INDEX('Per Line'!$M$2:$M$1501,$AH6)&"") | O6: =IF($AH6="","",INDEX('Per Line'!$P$2:$P$1501,$AH6)) | P6: =IF($AH6="","",O6*AD6/100) | Q6: =IF($AH6="","",INDEX('Per Line'!$R$2:$R$1501,$AH6)&"") | R6: =IF($AH6="","",INDEX('Per Line'!$AB$2:$AB$1501,$AH6)&"") | S6: =IF($AH6="","",Settings!$C$8) | T6: =IF($AH6="","",SUMIFS('Per Line'!$Z$2:$Z$1501,'Per Line'!$E$2:$E$1501,$B6,'Per Line'!$AT$2:$AT$1501,1)) | U6: =IF($AH6="","",T6*S6) | V6: =IF($AH6="","",Settings!$C$7) | W6: =IF($AH6="","",SUMIFS('Per Line'!$Z$2:$Z$1501,'Per Line'!$E$2:$E$1501,$B6,'Per Line'!$AS$2:$AS$1501,0,'Per Line'!$AT$2:$AT$1501,0)) | X6: =IF($AH6="","",W6*V6) | Y6: =IF($AH6="","",Settings!$C$6) | Z6: =IF($AH6="","",SUMIFS('Per Line'!$Z$2:$Z$1501,'Per Line'!$E$2:$E$1501,$B6,'Per Line'!$AS$2:$AS$1501,1,'Per Line'!$AT$2:$AT$1501,0)) | AA6: =IF($AH6="","",Z6*Y6) | AB6: =IF($AH6="","",AA6+X6+U6) | AC6: =IF($AH6="","",AD6-AB6) | AD6: =IF($AH6="","",W6+Z6+T6) | AE6: =IF($AH6="","",AD6-AB6-P6) | AG6: =IF($AH6="","",AE6-N(AF6)) | AH6: =IF(ROWS($AH$2:$AH6)<=MAX('Per Line'!$AR$2:$AR$1501),MATCH(ROWS($AH$2:$AH6),'Per Line'!$AR$2:$AR$1501,0),"") | AI6: =IF($AH6="","",C6&"|"&COUNTIF($C$2:$C6,C6))
B7: =IF($AH7="","",INDEX('Per Line'!$E$2:$E$1501,$AH7)&"") | C7: =IF($AH7="","",IF(INDEX('Per Line'!$AP$2:$AP$1501,$AH7)="NOT MATCH","NOT MATCH","FULL MATCH")) | D7: =IF($AH7="","",INDEX('Per Line'!$A$2:$A$1501,$AH7)&"") | E7: =IF($AH7="","",INDEX('Per Line'!$B$2:$B$1501,$AH7)) | F7: =IF($AH7="","",INDEX('Per Line'!$C$2:$C$1501,$AH7)&"") | G7: =IF($AH7="","",INDEX('Per Line'!$D$2:$D$1501,$AH7)&"") | H7: =IF($AH7="","",INDEX('Per Line'!$F$2:$F$1501,$AH7)&"") | I7: =IF($AH7="","",INDEX('Per Line'!$G$2:$G$1501,$AH7)) | J7: =IF($AH7="","",INDEX('Per Line'!$H$2:$H$1501,$AH7)&"") | K7: =IF($AH7="","",INDEX('Per Line'!$J$2:$J$1501,$AH7)&"") | L7: =IF($AH7="","",INDEX('Per Line'!$K$2:$K$1501,$AH7)&"") | M7: =IF($AH7="","",INDEX('Per Line'!$L$2:$L$1501,$AH7)&"") | N7: =IF($AH7="","",INDEX('Per Line'!$M$2:$M$1501,$AH7)&"") | O7: =IF($AH7="","",INDEX('Per Line'!$P$2:$P$1501,$AH7)) | P7: =IF($AH7="","",O7*AD7/100) | Q7: =IF($AH7="","",INDEX('Per Line'!$R$2:$R$1501,$AH7)&"") | R7: =IF($AH7="","",INDEX('Per Line'!$AB$2:$AB$1501,$AH7)&"") | S7: =IF($AH7="","",Settings!$C$8) | T7: =IF($AH7="","",SUMIFS('Per Line'!$Z$2:$Z$1501,'Per Line'!$E$2:$E$1501,$B7,'Per Line'!$AT$2:$AT$1501,1)) | U7: =IF($AH7="","",T7*S7) | V7: =IF($AH7="","",Settings!$C$7) | W7: =IF($AH7="","",SUMIFS('Per Line'!$Z$2:$Z$1501,'Per Line'!$E$2:$E$1501,$B7,'Per Line'!$AS$2:$AS$1501,0,'Per Line'!$AT$2:$AT$1501,0)) | X7: =IF($AH7="","",W7*V7) | Y7: =IF($AH7="","",Settings!$C$6) | Z7: =IF($AH7="","",SUMIFS('Per Line'!$Z$2:$Z$1501,'Per Line'!$E$2:$E$1501,$B7,'Per Line'!$AS$2:$AS$1501,1,'Per Line'!$AT$2:$AT$1501,0)) | AA7: =IF($AH7="","",Z7*Y7) | AB7: =IF($AH7="","",AA7+X7+U7) | AC7: =IF($AH7="","",AD7-AB7) | AD7: =IF($AH7="","",W7+Z7+T7) | AE7: =IF($AH7="","",AD7-AB7-P7) | AG7: =IF($AH7="","",AE7-N(AF7)) | AH7: =IF(ROWS($AH$2:$AH7)<=MAX('Per Line'!$AR$2:$AR$1501),MATCH(ROWS($AH$2:$AH7),'Per Line'!$AR$2:$AR$1501,0),"") | AI7: =IF($AH7="","",C7&"|"&COUNTIF($C$2:$C7,C7))
B8: =IF($AH8="","",INDEX('Per Line'!$E$2:$E$1501,$AH8)&"") | C8: =IF($AH8="","",IF(INDEX('Per Line'!$AP$2:$AP$1501,$AH8)="NOT MATCH","NOT MATCH","FULL MATCH")) | D8: =IF($AH8="","",INDEX('Per Line'!$A$2:$A$1501,$AH8)&"") | E8: =IF($AH8="","",INDEX('Per Line'!$B$2:$B$1501,$AH8)) | F8: =IF($AH8="","",INDEX('Per Line'!$C$2:$C$1501,$AH8)&"") | G8: =IF($AH8="","",INDEX('Per Line'!$D$2:$D$1501,$AH8)&"") | H8: =IF($AH8="","",INDEX('Per Line'!$F$2:$F$1501,$AH8)&"") | I8: =IF($AH8="","",INDEX('Per Line'!$G$2:$G$1501,$AH8)) | J8: =IF($AH8="","",INDEX('Per Line'!$H$2:$H$1501,$AH8)&"") | K8: =IF($AH8="","",INDEX('Per Line'!$J$2:$J$1501,$AH8)&"") | L8: =IF($AH8="","",INDEX('Per Line'!$K$2:$K$1501,$AH8)&"") | M8: =IF($AH8="","",INDEX('Per Line'!$L$2:$L$1501,$AH8)&"") | N8: =IF($AH8="","",INDEX('Per Line'!$M$2:$M$1501,$AH8)&"") | O8: =IF($AH8="","",INDEX('Per Line'!$P$2:$P$1501,$AH8)) | P8: =IF($AH8="","",O8*AD8/100) | Q8: =IF($AH8="","",INDEX('Per Line'!$R$2:$R$1501,$AH8)&"") | R8: =IF($AH8="","",INDEX('Per Line'!$AB$2:$AB$1501,$AH8)&"") | S8: =IF($AH8="","",Settings!$C$8) | T8: =IF($AH8="","",SUMIFS('Per Line'!$Z$2:$Z$1501,'Per Line'!$E$2:$E$1501,$B8,'Per Line'!$AT$2:$AT$1501,1)) | U8: =IF($AH8="","",T8*S8) | V8: =IF($AH8="","",Settings!$C$7) | W8: =IF($AH8="","",SUMIFS('Per Line'!$Z$2:$Z$1501,'Per Line'!$E$2:$E$1501,$B8,'Per Line'!$AS$2:$AS$1501,0,'Per Line'!$AT$2:$AT$1501,0)) | X8: =IF($AH8="","",W8*V8) | Y8: =IF($AH8="","",Settings!$C$6) | Z8: =IF($AH8="","",SUMIFS('Per Line'!$Z$2:$Z$1501,'Per Line'!$E$2:$E$1501,$B8,'Per Line'!$AS$2:$AS$1501,1,'Per Line'!$AT$2:$AT$1501,0)) | AA8: =IF($AH8="","",Z8*Y8) | AB8: =IF($AH8="","",AA8+X8+U8) | AC8: =IF($AH8="","",AD8-AB8) | AD8: =IF($AH8="","",W8+Z8+T8) | AE8: =IF($AH8="","",AD8-AB8-P8) | AG8: =IF($AH8="","",AE8-N(AF8)) | AH8: =IF(ROWS($AH$2:$AH8)<=MAX('Per Line'!$AR$2:$AR$1501),MATCH(ROWS($AH$2:$AH8),'Per Line'!$AR$2:$AR$1501,0),"") | AI8: =IF($AH8="","",C8&"|"&COUNTIF($C$2:$C8,C8))
B9: =IF($AH9="","",INDEX('Per Line'!$E$2:$E$1501,$AH9)&"") | C9: =IF($AH9="","",IF(INDEX('Per Line'!$AP$2:$AP$1501,$AH9)="NOT MATCH","NOT MATCH","FULL MATCH")) | D9: =IF($AH9="","",INDEX('Per Line'!$A$2:$A$1501,$AH9)&"") | E9: =IF($AH9="","",INDEX('Per Line'!$B$2:$B$1501,$AH9)) | F9: =IF($AH9="","",INDEX('Per Line'!$C$2:$C$1501,$AH9)&"") | G9: =IF($AH9="","",INDEX('Per Line'!$D$2:$D$1501,$AH9)&"") | H9: =IF($AH9="","",INDEX('Per Line'!$F$2:$F$1501,$AH9)&"") | I9: =IF($AH9="","",INDEX('Per Line'!$G$2:$G$1501,$AH9)) | J9: =IF($AH9="","",INDEX('Per Line'!$H$2:$H$1501,$AH9)&"") | K9: =IF($AH9="","",INDEX('Per Line'!$J$2:$J$1501,$AH9)&"") | L9: =IF($AH9="","",INDEX('Per Line'!$K$2:$K$1501,$AH9)&"") | M9: =IF($AH9="","",INDEX('Per Line'!$L$2:$L$1501,$AH9)&"") | N9: =IF($AH9="","",INDEX('Per Line'!$M$2:$M$1501,$AH9)&"") | O9: =IF($AH9="","",INDEX('Per Line'!$P$2:$P$1501,$AH9)) | P9: =IF($AH9="","",O9*AD9/100) | Q9: =IF($AH9="","",INDEX('Per Line'!$R$2:$R$1501,$AH9)&"") | R9: =IF($AH9="","",INDEX('Per Line'!$AB$2:$AB$1501,$AH9)&"") | S9: =IF($AH9="","",Settings!$C$8) | T9: =IF($AH9="","",SUMIFS('Per Line'!$Z$2:$Z$1501,'Per Line'!$E$2:$E$1501,$B9,'Per Line'!$AT$2:$AT$1501,1)) | U9: =IF($AH9="","",T9*S9) | V9: =IF($AH9="","",Settings!$C$7) | W9: =IF($AH9="","",SUMIFS('Per Line'!$Z$2:$Z$1501,'Per Line'!$E$2:$E$1501,$B9,'Per Line'!$AS$2:$AS$1501,0,'Per Line'!$AT$2:$AT$1501,0)) | X9: =IF($AH9="","",W9*V9) | Y9: =IF($AH9="","",Settings!$C$6) | Z9: =IF($AH9="","",SUMIFS('Per Line'!$Z$2:$Z$1501,'Per Line'!$E$2:$E$1501,$B9,'Per Line'!$AS$2:$AS$1501,1,'Per Line'!$AT$2:$AT$1501,0)) | AA9: =IF($AH9="","",Z9*Y9) | AB9: =IF($AH9="","",AA9+X9+U9) | AC9: =IF($AH9="","",AD9-AB9) | AD9: =IF($AH9="","",W9+Z9+T9) | AE9: =IF($AH9="","",AD9-AB9-P9) | AG9: =IF($AH9="","",AE9-N(AF9)) | AH9: =IF(ROWS($AH$2:$AH9)<=MAX('Per Line'!$AR$2:$AR$1501),MATCH(ROWS($AH$2:$AH9),'Per Line'!$AR$2:$AR$1501,0),"") | AI9: =IF($AH9="","",C9&"|"&COUNTIF($C$2:$C9,C9))
B10: =IF($AH10="","",INDEX('Per Line'!$E$2:$E$1501,$AH10)&"") | C10: =IF($AH10="","",IF(INDEX('Per Line'!$AP$2:$AP$1501,$AH10)="NOT MATCH","NOT MATCH","FULL MATCH")) | D10: =IF($AH10="","",INDEX('Per Line'!$A$2:$A$1501,$AH10)&"") | E10: =IF($AH10="","",INDEX('Per Line'!$B$2:$B$1501,$AH10)) | F10: =IF($AH10="","",INDEX('Per Line'!$C$2:$C$1501,$AH10)&"") | G10: =IF($AH10="","",INDEX('Per Line'!$D$2:$D$1501,$AH10)&"") | H10: =IF($AH10="","",INDEX('Per Line'!$F$2:$F$1501,$AH10)&"") | I10: =IF($AH10="","",INDEX('Per Line'!$G$2:$G$1501,$AH10)) | J10: =IF($AH10="","",INDEX('Per Line'!$H$2:$H$1501,$AH10)&"") | K10: =IF($AH10="","",INDEX('Per Line'!$J$2:$J$1501,$AH10)&"") | L10: =IF($AH10="","",INDEX('Per Line'!$K$2:$K$1501,$AH10)&"") | M10: =IF($AH10="","",INDEX('Per Line'!$L$2:$L$1501,$AH10)&"") | N10: =IF($AH10="","",INDEX('Per Line'!$M$2:$M$1501,$AH10)&"") | O10: =IF($AH10="","",INDEX('Per Line'!$P$2:$P$1501,$AH10)) | P10: =IF($AH10="","",O10*AD10/100) | Q10: =IF($AH10="","",INDEX('Per Line'!$R$2:$R$1501,$AH10)&"") | R10: =IF($AH10="","",INDEX('Per Line'!$AB$2:$AB$1501,$AH10)&"") | S10: =IF($AH10="","",Settings!$C$8) | T10: =IF($AH10="","",SUMIFS('Per Line'!$Z$2:$Z$1501,'Per Line'!$E$2:$E$1501,$B10,'Per Line'!$AT$2:$AT$1501,1)) | U10: =IF($AH10="","",T10*S10) | V10: =IF($AH10="","",Settings!$C$7) | W10: =IF($AH10="","",SUMIFS('Per Line'!$Z$2:$Z$1501,'Per Line'!$E$2:$E$1501,$B10,'Per Line'!$AS$2:$AS$1501,0,'Per Line'!$AT$2:$AT$1501,0)) | X10: =IF($AH10="","",W10*V10) | Y10: =IF($AH10="","",Settings!$C$6) | Z10: =IF($AH10="","",SUMIFS('Per Line'!$Z$2:$Z$1501,'Per Line'!$E$2:$E$1501,$B10,'Per Line'!$AS$2:$AS$1501,1,'Per Line'!$AT$2:$AT$1501,0)) | AA10: =IF($AH10="","",Z10*Y10) | AB10: =IF($AH10="","",AA10+X10+U10) | AC10: =IF($AH10="","",AD10-AB10) | AD10: =IF($AH10="","",W10+Z10+T10) | AE10: =IF($AH10="","",AD10-AB10-P10) | AG10: =IF($AH10="","",AE10-N(AF10)) | AH10: =IF(ROWS($AH$2:$AH10)<=MAX('Per Line'!$AR$2:$AR$1501),MATCH(ROWS($AH$2:$AH10),'Per Line'!$AR$2:$AR$1501,0),"") | AI10: =IF($AH10="","",C10&"|"&COUNTIF($C$2:$C10,C10))
B11: =IF($AH11="","",INDEX('Per Line'!$E$2:$E$1501,$AH11)&"") | C11: =IF($AH11="","",IF(INDEX('Per Line'!$AP$2:$AP$1501,$AH11)="NOT MATCH","NOT MATCH","FULL MATCH")) | D11: =IF($AH11="","",INDEX('Per Line'!$A$2:$A$1501,$AH11)&"") | E11: =IF($AH11="","",INDEX('Per Line'!$B$2:$B$1501,$AH11)) | F11: =IF($AH11="","",INDEX('Per Line'!$C$2:$C$1501,$AH11)&"") | G11: =IF($AH11="","",INDEX('Per Line'!$D$2:$D$1501,$AH11)&"") | H11: =IF($AH11="","",INDEX('Per Line'!$F$2:$F$1501,$AH11)&"") | I11: =IF($AH11="","",INDEX('Per Line'!$G$2:$G$1501,$AH11)) | J11: =IF($AH11="","",INDEX('Per Line'!$H$2:$H$1501,$AH11)&"") | K11: =IF($AH11="","",INDEX('Per Line'!$J$2:$J$1501,$AH11)&"") | L11: =IF($AH11="","",INDEX('Per Line'!$K$2:$K$1501,$AH11)&"") | M11: =IF($AH11="","",INDEX('Per Line'!$L$2:$L$1501,$AH11)&"") | N11: =IF($AH11="","",INDEX('Per Line'!$M$2:$M$1501,$AH11)&"") | O11: =IF($AH11="","",INDEX('Per Line'!$P$2:$P$1501,$AH11)) | P11: =IF($AH11="","",O11*AD11/100) | Q11: =IF($AH11="","",INDEX('Per Line'!$R$2:$R$1501,$AH11)&"") | R11: =IF($AH11="","",INDEX('Per Line'!$AB$2:$AB$1501,$AH11)&"") | S11: =IF($AH11="","",Settings!$C$8) | T11: =IF($AH11="","",SUMIFS('Per Line'!$Z$2:$Z$1501,'Per Line'!$E$2:$E$1501,$B11,'Per Line'!$AT$2:$AT$1501,1)) | U11: =IF($AH11="","",T11*S11) | V11: =IF($AH11="","",Settings!$C$7) | W11: =IF($AH11="","",SUMIFS('Per Line'!$Z$2:$Z$1501,'Per Line'!$E$2:$E$1501,$B11,'Per Line'!$AS$2:$AS$1501,0,'Per Line'!$AT$2:$AT$1501,0)) | X11: =IF($AH11="","",W11*V11) | Y11: =IF($AH11="","",Settings!$C$6) | Z11: =IF($AH11="","",SUMIFS('Per Line'!$Z$2:$Z$1501,'Per Line'!$E$2:$E$1501,$B11,'Per Line'!$AS$2:$AS$1501,1,'Per Line'!$AT$2:$AT$1501,0)) | AA11: =IF($AH11="","",Z11*Y11) | AB11: =IF($AH11="","",AA11+X11+U11) | AC11: =IF($AH11="","",AD11-AB11) | AD11: =IF($AH11="","",W11+Z11+T11) | AE11: =IF($AH11="","",AD11-AB11-P11) | AG11: =IF($AH11="","",AE11-N(AF11)) | AH11: =IF(ROWS($AH$2:$AH11)<=MAX('Per Line'!$AR$2:$AR$1501),MATCH(ROWS($AH$2:$AH11),'Per Line'!$AR$2:$AR$1501,0),"") | AI11: =IF($AH11="","",C11&"|"&COUNTIF($C$2:$C11,C11))
B12: =IF($AH12="","",INDEX('Per Line'!$E$2:$E$1501,$AH12)&"") | C12: =IF($AH12="","",IF(INDEX('Per Line'!$AP$2:$AP$1501,$AH12)="NOT MATCH","NOT MATCH","FULL MATCH")) | D12: =IF($AH12="","",INDEX('Per Line'!$A$2:$A$1501,$AH12)&"") | E12: =IF($AH12="","",INDEX('Per Line'!$B$2:$B$1501,$AH12)) | F12: =IF($AH12="","",INDEX('Per Line'!$C$2:$C$1501,$AH12)&"") | G12: =IF($AH12="","",INDEX('Per Line'!$D$2:$D$1501,$AH12)&"") | H12: =IF($AH12="","",INDEX('Per Line'!$F$2:$F$1501,$AH12)&"") | I12: =IF($AH12="","",INDEX('Per Line'!$G$2:$G$1501,$AH12)) | J12: =IF($AH12="","",INDEX('Per Line'!$H$2:$H$1501,$AH12)&"") | K12: =IF($AH12="","",INDEX('Per Line'!$J$2:$J$1501,$AH12)&"") | L12: =IF($AH12="","",INDEX('Per Line'!$K$2:$K$1501,$AH12)&"") | M12: =IF($AH12="","",INDEX('Per Line'!$L$2:$L$1501,$AH12)&"") | N12: =IF($AH12="","",INDEX('Per Line'!$M$2:$M$1501,$AH12)&"") | O12: =IF($AH12="","",INDEX('Per Line'!$P$2:$P$1501,$AH12)) | P12: =IF($AH12="","",O12*AD12/100) | Q12: =IF($AH12="","",INDEX('Per Line'!$R$2:$R$1501,$AH12)&"") | R12: =IF($AH12="","",INDEX('Per Line'!$AB$2:$AB$1501,$AH12)&"") | S12: =IF($AH12="","",Settings!$C$8) | T12: =IF($AH12="","",SUMIFS('Per Line'!$Z$2:$Z$1501,'Per Line'!$E$2:$E$1501,$B12,'Per Line'!$AT$2:$AT$1501,1)) | U12: =IF($AH12="","",T12*S12) | V12: =IF($AH12="","",Settings!$C$7) | W12: =IF($AH12="","",SUMIFS('Per Line'!$Z$2:$Z$1501,'Per Line'!$E$2:$E$1501,$B12,'Per Line'!$AS$2:$AS$1501,0,'Per Line'!$AT$2:$AT$1501,0)) | X12: =IF($AH12="","",W12*V12) | Y12: =IF($AH12="","",Settings!$C$6) | Z12: =IF($AH12="","",SUMIFS('Per Line'!$Z$2:$Z$1501,'Per Line'!$E$2:$E$1501,$B12,'Per Line'!$AS$2:$AS$1501,1,'Per Line'!$AT$2:$AT$1501,0)) | AA12: =IF($AH12="","",Z12*Y12) | AB12: =IF($AH12="","",AA12+X12+U12) | AC12: =IF($AH12="","",AD12-AB12) | AD12: =IF($AH12="","",W12+Z12+T12) | AE12: =IF($AH12="","",AD12-AB12-P12) | AG12: =IF($AH12="","",AE12-N(AF12)) | AH12: =IF(ROWS($AH$2:$AH12)<=MAX('Per Line'!$AR$2:$AR$1501),MATCH(ROWS($AH$2:$AH12),'Per Line'!$AR$2:$AR$1501,0),"") | AI12: =IF($AH12="","",C12&"|"&COUNTIF($C$2:$C12,C12))
B13: =IF($AH13="","",INDEX('Per Line'!$E$2:$E$1501,$AH13)&"") | C13: =IF($AH13="","",IF(INDEX('Per Line'!$AP$2:$AP$1501,$AH13)="NOT MATCH","NOT MATCH","FULL MATCH")) | D13: =IF($AH13="","",INDEX('Per Line'!$A$2:$A$1501,$AH13)&"") | E13: =IF($AH13="","",INDEX('Per Line'!$B$2:$B$1501,$AH13)) | F13: =IF($AH13="","",INDEX('Per Line'!$C$2:$C$1501,$AH13)&"") | G13: =IF($AH13="","",INDEX('Per Line'!$D$2:$D$1501,$AH13)&"") | H13: =IF($AH13="","",INDEX('Per Line'!$F$2:$F$1501,$AH13)&"") | I13: =IF($AH13="","",INDEX('Per Line'!$G$2:$G$1501,$AH13)) | J13: =IF($AH13="","",INDEX('Per Line'!$H$2:$H$1501,$AH13)&"") | K13: =IF($AH13="","",INDEX('Per Line'!$J$2:$J$1501,$AH13)&"") | L13: =IF($AH13="","",INDEX('Per Line'!$K$2:$K$1501,$AH13)&"") | M13: =IF($AH13="","",INDEX('Per Line'!$L$2:$L$1501,$AH13)&"") | N13: =IF($AH13="","",INDEX('Per Line'!$M$2:$M$1501,$AH13)&"") | O13: =IF($AH13="","",INDEX('Per Line'!$P$2:$P$1501,$AH13)) | P13: =IF($AH13="","",O13*AD13/100) | Q13: =IF($AH13="","",INDEX('Per Line'!$R$2:$R$1501,$AH13)&"") | R13: =IF($AH13="","",INDEX('Per Line'!$AB$2:$AB$1501,$AH13)&"") | S13: =IF($AH13="","",Settings!$C$8) | T13: =IF($AH13="","",SUMIFS('Per Line'!$Z$2:$Z$1501,'Per Line'!$E$2:$E$1501,$B13,'Per Line'!$AT$2:$AT$1501,1)) | U13: =IF($AH13="","",T13*S13) | V13: =IF($AH13="","",Settings!$C$7) | W13: =IF($AH13="","",SUMIFS('Per Line'!$Z$2:$Z$1501,'Per Line'!$E$2:$E$1501,$B13,'Per Line'!$AS$2:$AS$1501,0,'Per Line'!$AT$2:$AT$1501,0)) | X13: =IF($AH13="","",W13*V13) | Y13: =IF($AH13="","",Settings!$C$6) | Z13: =IF($AH13="","",SUMIFS('Per Line'!$Z$2:$Z$1501,'Per Line'!$E$2:$E$1501,$B13,'Per Line'!$AS$2:$AS$1501,1,'Per Line'!$AT$2:$AT$1501,0)) | AA13: =IF($AH13="","",Z13*Y13) | AB13: =IF($AH13="","",AA13+X13+U13) | AC13: =IF($AH13="","",AD13-AB13) | AD13: =IF($AH13="","",W13+Z13+T13) | AE13: =IF($AH13="","",AD13-AB13-P13) | AG13: =IF($AH13="","",AE13-N(AF13)) | AH13: =IF(ROWS($AH$2:$AH13)<=MAX('Per Line'!$AR$2:$AR$1501),MATCH(ROWS($AH$2:$AH13),'Per Line'!$AR$2:$AR$1501,0),"") | AI13: =IF($AH13="","",C13&"|"&COUNTIF($C$2:$C13,C13))
... B401: =IF($AH401="","",INDEX('Per Line'!$E$2:$E$1501,$AH401)&"") | C401: =IF($AH401="","",IF(INDEX('Per Line'!$AP$2:$AP$1501,$AH401)="NOT MATCH","NOT MATCH","FULL MATCH")) | D401: =IF($AH401="","",INDEX('Per Line'!$A$2:$A$1501,$AH401)&"") | E401: =IF($AH401="","",INDEX('Per Line'!$B$2:$B$1501,$AH401)) | F401: =IF($AH401="","",INDEX('Per Line'!$C$2:$C$1501,$AH401)&"") | G401: =IF($AH401="","",INDEX('Per Line'!$D$2:$D$1501,$AH401)&"") | H401: =IF($AH401="","",INDEX('Per Line'!$F$2:$F$1501,$AH401)&"") | I401: =IF($AH401="","",INDEX('Per Line'!$G$2:$G$1501,$AH401)) | J401: =IF($AH401="","",INDEX('Per Line'!$H$2:$H$1501,$AH401)&"") | K401: =IF($AH401="","",INDEX('Per Line'!$J$2:$J$1501,$AH401)&"") | L401: =IF($AH401="","",INDEX('Per Line'!$K$2:$K$1501,$AH401)&"") | M401: =IF($AH401="","",INDEX('Per Line'!$L$2:$L$1501,$AH401)&"") | N401: =IF($AH401="","",INDEX('Per Line'!$M$2:$M$1501,$AH401)&"") | O401: =IF($AH401="","",INDEX('Per Line'!$P$2:$P$1501,$AH401)) | P401: =IF($AH401="","",O401*AD401/100) | Q401: =IF($AH401="","",INDEX('Per Line'!$R$2:$R$1501,$AH401)&"") | R401: =IF($AH401="","",INDEX('Per Line'!$AB$2:$AB$1501,$AH401)&"") | S401: =IF($AH401="","",Settings!$C$8) | T401: =IF($AH401="","",SUMIFS('Per Line'!$Z$2:$Z$1501,'Per Line'!$E$2:$E$1501,$B401,'Per Line'!$AT$2:$AT$1501,1)) | U401: =IF($AH401="","",T401*S401) | V401: =IF($AH401="","",Settings!$C$7) | W401: =IF($AH401="","",SUMIFS('Per Line'!$Z$2:$Z$1501,'Per Line'!$E$2:$E$1501,$B401,'Per Line'!$AS$2:$AS$1501,0,'Per Line'!$AT$2:$AT$1501,0)) | X401: =IF($AH401="","",W401*V401) | Y401: =IF($AH401="","",Settings!$C$6) | Z401: =IF($AH401="","",SUMIFS('Per Line'!$Z$2:$Z$1501,'Per Line'!$E$2:$E$1501,$B401,'Per Line'!$AS$2:$AS$1501,1,'Per Line'!$AT$2:$AT$1501,0)) | AA401: =IF($AH401="","",Z401*Y401) | AB401: =IF($AH401="","",AA401+X401+U401) | AC401: =IF($AH401="","",AD401-AB401) | AD401: =IF($AH401="","",W401+Z401+T401) | AE401: =IF($AH401="","",AD401-AB401-P401) | AG401: =IF($AH401="","",AE401-N(AF401)) | AH401: =IF(ROWS($AH$2:$AH401)<=MAX('Per Line'!$AR$2:$AR$1501),MATCH(ROWS($AH$2:$AH401),'Per Line'!$AR$2:$AR$1501,0),"") | AI401: =IF($AH401="","",C401&"|"&COUNTIF($C$2:$C401,C401))

Sheet FULL MATCH
A1: Invoice | B1: Order # | C1: Match Tab | D1: Cycle | E1: Ticket # | F1: Stage | G1: Approval Ref | H1: Channel | I1: Create At | J1: Insurance Company | K1: Corporate | L1: Card | M1: Name | N1: Status | O1: Order Co Payment | P1: Co val | Q1: By Patient | R1: ERX ID | S1: SPECIAL REBATES % | T1: SPECIAL REBATES | U1: SPECIAL REBATES VAL | V1: IMP % | W1: IMP | X1: IMP VAL | Y1: LOCAL % | Z1: LOCAL | AA1: LOCAL VAL | AB1: TOTAL VAL | AC1: SUBTOTAL | AD1: Grand Total | AE1: NET | AF1: N MR | AG1: D | AH1: Src Row (helper)
A2: =IF($AH2="","",IF(INDEX('Per Invoice'!A$2:A$401,$AH2)="","",INDEX('Per Invoice'!A$2:A$401,$AH2))) | B2: =IF($AH2="","",IF(INDEX('Per Invoice'!B$2:B$401,$AH2)="","",INDEX('Per Invoice'!B$2:B$401,$AH2))) | C2: =IF($AH2="","",IF(INDEX('Per Invoice'!C$2:C$401,$AH2)="","",INDEX('Per Invoice'!C$2:C$401,$AH2))) | D2: =IF($AH2="","",IF(INDEX('Per Invoice'!D$2:D$401,$AH2)="","",INDEX('Per Invoice'!D$2:D$401,$AH2))) | E2: =IF($AH2="","",IF(INDEX('Per Invoice'!E$2:E$401,$AH2)="","",INDEX('Per Invoice'!E$2:E$401,$AH2))) | F2: =IF($AH2="","",IF(INDEX('Per Invoice'!F$2:F$401,$AH2)="","",INDEX('Per Invoice'!F$2:F$401,$AH2))) | G2: =IF($AH2="","",IF(INDEX('Per Invoice'!G$2:G$401,$AH2)="","",INDEX('Per Invoice'!G$2:G$401,$AH2))) | H2: =IF($AH2="","",IF(INDEX('Per Invoice'!H$2:H$401,$AH2)="","",INDEX('Per Invoice'!H$2:H$401,$AH2))) | ... AG2: =IF($AH2="","",IF(INDEX('Per Invoice'!AG$2:AG$401,$AH2)="","",INDEX('Per Invoice'!AG$2:AG$401,$AH2))) | AH2: =IFERROR(MATCH(Settings!$C$26&"|"&ROWS($AH$2:$AH2),'Per Invoice'!$AI$2:$AI$401,0),"")
A3: =IF($AH3="","",IF(INDEX('Per Invoice'!A$2:A$401,$AH3)="","",INDEX('Per Invoice'!A$2:A$401,$AH3))) | B3: =IF($AH3="","",IF(INDEX('Per Invoice'!B$2:B$401,$AH3)="","",INDEX('Per Invoice'!B$2:B$401,$AH3))) | C3: =IF($AH3="","",IF(INDEX('Per Invoice'!C$2:C$401,$AH3)="","",INDEX('Per Invoice'!C$2:C$401,$AH3))) | D3: =IF($AH3="","",IF(INDEX('Per Invoice'!D$2:D$401,$AH3)="","",INDEX('Per Invoice'!D$2:D$401,$AH3))) | E3: =IF($AH3="","",IF(INDEX('Per Invoice'!E$2:E$401,$AH3)="","",INDEX('Per Invoice'!E$2:E$401,$AH3))) | F3: =IF($AH3="","",IF(INDEX('Per Invoice'!F$2:F$401,$AH3)="","",INDEX('Per Invoice'!F$2:F$401,$AH3))) | G3: =IF($AH3="","",IF(INDEX('Per Invoice'!G$2:G$401,$AH3)="","",INDEX('Per Invoice'!G$2:G$401,$AH3))) | H3: =IF($AH3="","",IF(INDEX('Per Invoice'!H$2:H$401,$AH3)="","",INDEX('Per Invoice'!H$2:H$401,$AH3))) | ... AG3: =IF($AH3="","",IF(INDEX('Per Invoice'!AG$2:AG$401,$AH3)="","",INDEX('Per Invoice'!AG$2:AG$401,$AH3))) | AH3: =IFERROR(MATCH(Settings!$C$26&"|"&ROWS($AH$2:$AH3),'Per Invoice'!$AI$2:$AI$401,0),"")
A4: =IF($AH4="","",IF(INDEX('Per Invoice'!A$2:A$401,$AH4)="","",INDEX('Per Invoice'!A$2:A$401,$AH4))) | B4: =IF($AH4="","",IF(INDEX('Per Invoice'!B$2:B$401,$AH4)="","",INDEX('Per Invoice'!B$2:B$401,$AH4))) | C4: =IF($AH4="","",IF(INDEX('Per Invoice'!C$2:C$401,$AH4)="","",INDEX('Per Invoice'!C$2:C$401,$AH4))) | D4: =IF($AH4="","",IF(INDEX('Per Invoice'!D$2:D$401,$AH4)="","",INDEX('Per Invoice'!D$2:D$401,$AH4))) | E4: =IF($AH4="","",IF(INDEX('Per Invoice'!E$2:E$401,$AH4)="","",INDEX('Per Invoice'!E$2:E$401,$AH4))) | F4: =IF($AH4="","",IF(INDEX('Per Invoice'!F$2:F$401,$AH4)="","",INDEX('Per Invoice'!F$2:F$401,$AH4))) | G4: =IF($AH4="","",IF(INDEX('Per Invoice'!G$2:G$401,$AH4)="","",INDEX('Per Invoice'!G$2:G$401,$AH4))) | H4: =IF($AH4="","",IF(INDEX('Per Invoice'!H$2:H$401,$AH4)="","",INDEX('Per Invoice'!H$2:H$401,$AH4))) | ... AG4: =IF($AH4="","",IF(INDEX('Per Invoice'!AG$2:AG$401,$AH4)="","",INDEX('Per Invoice'!AG$2:AG$401,$AH4))) | AH4: =IFERROR(MATCH(Settings!$C$26&"|"&ROWS($AH$2:$AH4),'Per Invoice'!$AI$2:$AI$401,0),"")
A5: =IF($AH5="","",IF(INDEX('Per Invoice'!A$2:A$401,$AH5)="","",INDEX('Per Invoice'!A$2:A$401,$AH5))) | B5: =IF($AH5="","",IF(INDEX('Per Invoice'!B$2:B$401,$AH5)="","",INDEX('Per Invoice'!B$2:B$401,$AH5))) | C5: =IF($AH5="","",IF(INDEX('Per Invoice'!C$2:C$401,$AH5)="","",INDEX('Per Invoice'!C$2:C$401,$AH5))) | D5: =IF($AH5="","",IF(INDEX('Per Invoice'!D$2:D$401,$AH5)="","",INDEX('Per Invoice'!D$2:D$401,$AH5))) | E5: =IF($AH5="","",IF(INDEX('Per Invoice'!E$2:E$401,$AH5)="","",INDEX('Per Invoice'!E$2:E$401,$AH5))) | F5: =IF($AH5="","",IF(INDEX('Per Invoice'!F$2:F$401,$AH5)="","",INDEX('Per Invoice'!F$2:F$401,$AH5))) | G5: =IF($AH5="","",IF(INDEX('Per Invoice'!G$2:G$401,$AH5)="","",INDEX('Per Invoice'!G$2:G$401,$AH5))) | H5: =IF($AH5="","",IF(INDEX('Per Invoice'!H$2:H$401,$AH5)="","",INDEX('Per Invoice'!H$2:H$401,$AH5))) | ... AG5: =IF($AH5="","",IF(INDEX('Per Invoice'!AG$2:AG$401,$AH5)="","",INDEX('Per Invoice'!AG$2:AG$401,$AH5))) | AH5: =IFERROR(MATCH(Settings!$C$26&"|"&ROWS($AH$2:$AH5),'Per Invoice'!$AI$2:$AI$401,0),"")
A6: =IF($AH6="","",IF(INDEX('Per Invoice'!A$2:A$401,$AH6)="","",INDEX('Per Invoice'!A$2:A$401,$AH6))) | B6: =IF($AH6="","",IF(INDEX('Per Invoice'!B$2:B$401,$AH6)="","",INDEX('Per Invoice'!B$2:B$401,$AH6))) | C6: =IF($AH6="","",IF(INDEX('Per Invoice'!C$2:C$401,$AH6)="","",INDEX('Per Invoice'!C$2:C$401,$AH6))) | D6: =IF($AH6="","",IF(INDEX('Per Invoice'!D$2:D$401,$AH6)="","",INDEX('Per Invoice'!D$2:D$401,$AH6))) | E6: =IF($AH6="","",IF(INDEX('Per Invoice'!E$2:E$401,$AH6)="","",INDEX('Per Invoice'!E$2:E$401,$AH6))) | F6: =IF($AH6="","",IF(INDEX('Per Invoice'!F$2:F$401,$AH6)="","",INDEX('Per Invoice'!F$2:F$401,$AH6))) | G6: =IF($AH6="","",IF(INDEX('Per Invoice'!G$2:G$401,$AH6)="","",INDEX('Per Invoice'!G$2:G$401,$AH6))) | H6: =IF($AH6="","",IF(INDEX('Per Invoice'!H$2:H$401,$AH6)="","",INDEX('Per Invoice'!H$2:H$401,$AH6))) | ... AG6: =IF($AH6="","",IF(INDEX('Per Invoice'!AG$2:AG$401,$AH6)="","",INDEX('Per Invoice'!AG$2:AG$401,$AH6))) | AH6: =IFERROR(MATCH(Settings!$C$26&"|"&ROWS($AH$2:$AH6),'Per Invoice'!$AI$2:$AI$401,0),"")
A7: =IF($AH7="","",IF(INDEX('Per Invoice'!A$2:A$401,$AH7)="","",INDEX('Per Invoice'!A$2:A$401,$AH7))) | B7: =IF($AH7="","",IF(INDEX('Per Invoice'!B$2:B$401,$AH7)="","",INDEX('Per Invoice'!B$2:B$401,$AH7))) | C7: =IF($AH7="","",IF(INDEX('Per Invoice'!C$2:C$401,$AH7)="","",INDEX('Per Invoice'!C$2:C$401,$AH7))) | D7: =IF($AH7="","",IF(INDEX('Per Invoice'!D$2:D$401,$AH7)="","",INDEX('Per Invoice'!D$2:D$401,$AH7))) | E7: =IF($AH7="","",IF(INDEX('Per Invoice'!E$2:E$401,$AH7)="","",INDEX('Per Invoice'!E$2:E$401,$AH7))) | F7: =IF($AH7="","",IF(INDEX('Per Invoice'!F$2:F$401,$AH7)="","",INDEX('Per Invoice'!F$2:F$401,$AH7))) | G7: =IF($AH7="","",IF(INDEX('Per Invoice'!G$2:G$401,$AH7)="","",INDEX('Per Invoice'!G$2:G$401,$AH7))) | H7: =IF($AH7="","",IF(INDEX('Per Invoice'!H$2:H$401,$AH7)="","",INDEX('Per Invoice'!H$2:H$401,$AH7))) | ... AG7: =IF($AH7="","",IF(INDEX('Per Invoice'!AG$2:AG$401,$AH7)="","",INDEX('Per Invoice'!AG$2:AG$401,$AH7))) | AH7: =IFERROR(MATCH(Settings!$C$26&"|"&ROWS($AH$2:$AH7),'Per Invoice'!$AI$2:$AI$401,0),"")
A8: =IF($AH8="","",IF(INDEX('Per Invoice'!A$2:A$401,$AH8)="","",INDEX('Per Invoice'!A$2:A$401,$AH8))) | B8: =IF($AH8="","",IF(INDEX('Per Invoice'!B$2:B$401,$AH8)="","",INDEX('Per Invoice'!B$2:B$401,$AH8))) | C8: =IF($AH8="","",IF(INDEX('Per Invoice'!C$2:C$401,$AH8)="","",INDEX('Per Invoice'!C$2:C$401,$AH8))) | D8: =IF($AH8="","",IF(INDEX('Per Invoice'!D$2:D$401,$AH8)="","",INDEX('Per Invoice'!D$2:D$401,$AH8))) | E8: =IF($AH8="","",IF(INDEX('Per Invoice'!E$2:E$401,$AH8)="","",INDEX('Per Invoice'!E$2:E$401,$AH8))) | F8: =IF($AH8="","",IF(INDEX('Per Invoice'!F$2:F$401,$AH8)="","",INDEX('Per Invoice'!F$2:F$401,$AH8))) | G8: =IF($AH8="","",IF(INDEX('Per Invoice'!G$2:G$401,$AH8)="","",INDEX('Per Invoice'!G$2:G$401,$AH8))) | H8: =IF($AH8="","",IF(INDEX('Per Invoice'!H$2:H$401,$AH8)="","",INDEX('Per Invoice'!H$2:H$401,$AH8))) | ... AG8: =IF($AH8="","",IF(INDEX('Per Invoice'!AG$2:AG$401,$AH8)="","",INDEX('Per Invoice'!AG$2:AG$401,$AH8))) | AH8: =IFERROR(MATCH(Settings!$C$26&"|"&ROWS($AH$2:$AH8),'Per Invoice'!$AI$2:$AI$401,0),"")
A9: =IF($AH9="","",IF(INDEX('Per Invoice'!A$2:A$401,$AH9)="","",INDEX('Per Invoice'!A$2:A$401,$AH9))) | B9: =IF($AH9="","",IF(INDEX('Per Invoice'!B$2:B$401,$AH9)="","",INDEX('Per Invoice'!B$2:B$401,$AH9))) | C9: =IF($AH9="","",IF(INDEX('Per Invoice'!C$2:C$401,$AH9)="","",INDEX('Per Invoice'!C$2:C$401,$AH9))) | D9: =IF($AH9="","",IF(INDEX('Per Invoice'!D$2:D$401,$AH9)="","",INDEX('Per Invoice'!D$2:D$401,$AH9))) | E9: =IF($AH9="","",IF(INDEX('Per Invoice'!E$2:E$401,$AH9)="","",INDEX('Per Invoice'!E$2:E$401,$AH9))) | F9: =IF($AH9="","",IF(INDEX('Per Invoice'!F$2:F$401,$AH9)="","",INDEX('Per Invoice'!F$2:F$401,$AH9))) | G9: =IF($AH9="","",IF(INDEX('Per Invoice'!G$2:G$401,$AH9)="","",INDEX('Per Invoice'!G$2:G$401,$AH9))) | H9: =IF($AH9="","",IF(INDEX('Per Invoice'!H$2:H$401,$AH9)="","",INDEX('Per Invoice'!H$2:H$401,$AH9))) | ... AG9: =IF($AH9="","",IF(INDEX('Per Invoice'!AG$2:AG$401,$AH9)="","",INDEX('Per Invoice'!AG$2:AG$401,$AH9))) | AH9: =IFERROR(MATCH(Settings!$C$26&"|"&ROWS($AH$2:$AH9),'Per Invoice'!$AI$2:$AI$401,0),"")
A10: =IF($AH10="","",IF(INDEX('Per Invoice'!A$2:A$401,$AH10)="","",INDEX('Per Invoice'!A$2:A$401,$AH10))) | B10: =IF($AH10="","",IF(INDEX('Per Invoice'!B$2:B$401,$AH10)="","",INDEX('Per Invoice'!B$2:B$401,$AH10))) | C10: =IF($AH10="","",IF(INDEX('Per Invoice'!C$2:C$401,$AH10)="","",INDEX('Per Invoice'!C$2:C$401,$AH10))) | D10: =IF($AH10="","",IF(INDEX('Per Invoice'!D$2:D$401,$AH10)="","",INDEX('Per Invoice'!D$2:D$401,$AH10))) | E10: =IF($AH10="","",IF(INDEX('Per Invoice'!E$2:E$401,$AH10)="","",INDEX('Per Invoice'!E$2:E$401,$AH10))) | F10: =IF($AH10="","",IF(INDEX('Per Invoice'!F$2:F$401,$AH10)="","",INDEX('Per Invoice'!F$2:F$401,$AH10))) | G10: =IF($AH10="","",IF(INDEX('Per Invoice'!G$2:G$401,$AH10)="","",INDEX('Per Invoice'!G$2:G$401,$AH10))) | H10: =IF($AH10="","",IF(INDEX('Per Invoice'!H$2:H$401,$AH10)="","",INDEX('Per Invoice'!H$2:H$401,$AH10))) | ... AG10: =IF($AH10="","",IF(INDEX('Per Invoice'!AG$2:AG$401,$AH10)="","",INDEX('Per Invoice'!AG$2:AG$401,$AH10))) | AH10: =IFERROR(MATCH(Settings!$C$26&"|"&ROWS($AH$2:$AH10),'Per Invoice'!$AI$2:$AI$401,0),"")
A11: =IF($AH11="","",IF(INDEX('Per Invoice'!A$2:A$401,$AH11)="","",INDEX('Per Invoice'!A$2:A$401,$AH11))) | B11: =IF($AH11="","",IF(INDEX('Per Invoice'!B$2:B$401,$AH11)="","",INDEX('Per Invoice'!B$2:B$401,$AH11))) | C11: =IF($AH11="","",IF(INDEX('Per Invoice'!C$2:C$401,$AH11)="","",INDEX('Per Invoice'!C$2:C$401,$AH11))) | D11: =IF($AH11="","",IF(INDEX('Per Invoice'!D$2:D$401,$AH11)="","",INDEX('Per Invoice'!D$2:D$401,$AH11))) | E11: =IF($AH11="","",IF(INDEX('Per Invoice'!E$2:E$401,$AH11)="","",INDEX('Per Invoice'!E$2:E$401,$AH11))) | F11: =IF($AH11="","",IF(INDEX('Per Invoice'!F$2:F$401,$AH11)="","",INDEX('Per Invoice'!F$2:F$401,$AH11))) | G11: =IF($AH11="","",IF(INDEX('Per Invoice'!G$2:G$401,$AH11)="","",INDEX('Per Invoice'!G$2:G$401,$AH11))) | H11: =IF($AH11="","",IF(INDEX('Per Invoice'!H$2:H$401,$AH11)="","",INDEX('Per Invoice'!H$2:H$401,$AH11))) | ... AG11: =IF($AH11="","",IF(INDEX('Per Invoice'!AG$2:AG$401,$AH11)="","",INDEX('Per Invoice'!AG$2:AG$401,$AH11))) | AH11: =IFERROR(MATCH(Settings!$C$26&"|"&ROWS($AH$2:$AH11),'Per Invoice'!$AI$2:$AI$401,0),"")
A12: =IF($AH12="","",IF(INDEX('Per Invoice'!A$2:A$401,$AH12)="","",INDEX('Per Invoice'!A$2:A$401,$AH12))) | B12: =IF($AH12="","",IF(INDEX('Per Invoice'!B$2:B$401,$AH12)="","",INDEX('Per Invoice'!B$2:B$401,$AH12))) | C12: =IF($AH12="","",IF(INDEX('Per Invoice'!C$2:C$401,$AH12)="","",INDEX('Per Invoice'!C$2:C$401,$AH12))) | D12: =IF($AH12="","",IF(INDEX('Per Invoice'!D$2:D$401,$AH12)="","",INDEX('Per Invoice'!D$2:D$401,$AH12))) | E12: =IF($AH12="","",IF(INDEX('Per Invoice'!E$2:E$401,$AH12)="","",INDEX('Per Invoice'!E$2:E$401,$AH12))) | F12: =IF($AH12="","",IF(INDEX('Per Invoice'!F$2:F$401,$AH12)="","",INDEX('Per Invoice'!F$2:F$401,$AH12))) | G12: =IF($AH12="","",IF(INDEX('Per Invoice'!G$2:G$401,$AH12)="","",INDEX('Per Invoice'!G$2:G$401,$AH12))) | H12: =IF($AH12="","",IF(INDEX('Per Invoice'!H$2:H$401,$AH12)="","",INDEX('Per Invoice'!H$2:H$401,$AH12))) | ... AG12: =IF($AH12="","",IF(INDEX('Per Invoice'!AG$2:AG$401,$AH12)="","",INDEX('Per Invoice'!AG$2:AG$401,$AH12))) | AH12: =IFERROR(MATCH(Settings!$C$26&"|"&ROWS($AH$2:$AH12),'Per Invoice'!$AI$2:$AI$401,0),"")
A13: =IF($AH13="","",IF(INDEX('Per Invoice'!A$2:A$401,$AH13)="","",INDEX('Per Invoice'!A$2:A$401,$AH13))) | B13: =IF($AH13="","",IF(INDEX('Per Invoice'!B$2:B$401,$AH13)="","",INDEX('Per Invoice'!B$2:B$401,$AH13))) | C13: =IF($AH13="","",IF(INDEX('Per Invoice'!C$2:C$401,$AH13)="","",INDEX('Per Invoice'!C$2:C$401,$AH13))) | D13: =IF($AH13="","",IF(INDEX('Per Invoice'!D$2:D$401,$AH13)="","",INDEX('Per Invoice'!D$2:D$401,$AH13))) | E13: =IF($AH13="","",IF(INDEX('Per Invoice'!E$2:E$401,$AH13)="","",INDEX('Per Invoice'!E$2:E$401,$AH13))) | F13: =IF($AH13="","",IF(INDEX('Per Invoice'!F$2:F$401,$AH13)="","",INDEX('Per Invoice'!F$2:F$401,$AH13))) | G13: =IF($AH13="","",IF(INDEX('Per Invoice'!G$2:G$401,$AH13)="","",INDEX('Per Invoice'!G$2:G$401,$AH13))) | H13: =IF($AH13="","",IF(INDEX('Per Invoice'!H$2:H$401,$AH13)="","",INDEX('Per Invoice'!H$2:H$401,$AH13))) | ... AG13: =IF($AH13="","",IF(INDEX('Per Invoice'!AG$2:AG$401,$AH13)="","",INDEX('Per Invoice'!AG$2:AG$401,$AH13))) | AH13: =IFERROR(MATCH(Settings!$C$26&"|"&ROWS($AH$2:$AH13),'Per Invoice'!$AI$2:$AI$401,0),"")
... A401: =IF($AH401="","",IF(INDEX('Per Invoice'!A$2:A$401,$AH401)="","",INDEX('Per Invoice'!A$2:A$401,$AH401))) | B401: =IF($AH401="","",IF(INDEX('Per Invoice'!B$2:B$401,$AH401)="","",INDEX('Per Invoice'!B$2:B$401,$AH401))) | C401: =IF($AH401="","",IF(INDEX('Per Invoice'!C$2:C$401,$AH401)="","",INDEX('Per Invoice'!C$2:C$401,$AH401))) | D401: =IF($AH401="","",IF(INDEX('Per Invoice'!D$2:D$401,$AH401)="","",INDEX('Per Invoice'!D$2:D$401,$AH401))) | E401: =IF($AH401="","",IF(INDEX('Per Invoice'!E$2:E$401,$AH401)="","",INDEX('Per Invoice'!E$2:E$401,$AH401))) | F401: =IF($AH401="","",IF(INDEX('Per Invoice'!F$2:F$401,$AH401)="","",INDEX('Per Invoice'!F$2:F$401,$AH401))) | G401: =IF($AH401="","",IF(INDEX('Per Invoice'!G$2:G$401,$AH401)="","",INDEX('Per Invoice'!G$2:G$401,$AH401))) | H401: =IF($AH401="","",IF(INDEX('Per Invoice'!H$2:H$401,$AH401)="","",INDEX('Per Invoice'!H$2:H$401,$AH401))) | ... AG401: =IF($AH401="","",IF(INDEX('Per Invoice'!AG$2:AG$401,$AH401)="","",INDEX('Per Invoice'!AG$2:AG$401,$AH401))) | AH401: =IFERROR(MATCH(Settings!$C$26&"|"&ROWS($AH$2:$AH401),'Per Invoice'!$AI$2:$AI$401,0),"")

Sheet NOT MATCH
A1: Invoice | B1: Order # | C1: Match Tab | D1: Cycle | E1: Ticket # | F1: Stage | G1: Approval Ref | H1: Channel | I1: Create At | J1: Insurance Company | K1: Corporate | L1: Card | M1: Name | N1: Status | O1: Order Co Payment | P1: Co val | Q1: By Patient | R1: ERX ID | S1: SPECIAL REBATES % | T1: SPECIAL REBATES | U1: SPECIAL REBATES VAL | V1: IMP % | W1: IMP | X1: IMP VAL | Y1: LOCAL % | Z1: LOCAL | AA1: LOCAL VAL | AB1: TOTAL VAL | AC1: SUBTOTAL | AD1: Grand Total | AE1: NET | AF1: N MR | AG1: D | AH1: Src Row (helper)
A2: =IF($AH2="","",IF(INDEX('Per Invoice'!A$2:A$401,$AH2)="","",INDEX('Per Invoice'!A$2:A$401,$AH2))) | B2: =IF($AH2="","",IF(INDEX('Per Invoice'!B$2:B$401,$AH2)="","",INDEX('Per Invoice'!B$2:B$401,$AH2))) | C2: =IF($AH2="","",IF(INDEX('Per Invoice'!C$2:C$401,$AH2)="","",INDEX('Per Invoice'!C$2:C$401,$AH2))) | D2: =IF($AH2="","",IF(INDEX('Per Invoice'!D$2:D$401,$AH2)="","",INDEX('Per Invoice'!D$2:D$401,$AH2))) | E2: =IF($AH2="","",IF(INDEX('Per Invoice'!E$2:E$401,$AH2)="","",INDEX('Per Invoice'!E$2:E$401,$AH2))) | F2: =IF($AH2="","",IF(INDEX('Per Invoice'!F$2:F$401,$AH2)="","",INDEX('Per Invoice'!F$2:F$401,$AH2))) | G2: =IF($AH2="","",IF(INDEX('Per Invoice'!G$2:G$401,$AH2)="","",INDEX('Per Invoice'!G$2:G$401,$AH2))) | H2: =IF($AH2="","",IF(INDEX('Per Invoice'!H$2:H$401,$AH2)="","",INDEX('Per Invoice'!H$2:H$401,$AH2))) | ... AG2: =IF($AH2="","",IF(INDEX('Per Invoice'!AG$2:AG$401,$AH2)="","",INDEX('Per Invoice'!AG$2:AG$401,$AH2))) | AH2: =IFERROR(MATCH(Settings!$C$27&"|"&ROWS($AH$2:$AH2),'Per Invoice'!$AI$2:$AI$401,0),"")
A3: =IF($AH3="","",IF(INDEX('Per Invoice'!A$2:A$401,$AH3)="","",INDEX('Per Invoice'!A$2:A$401,$AH3))) | B3: =IF($AH3="","",IF(INDEX('Per Invoice'!B$2:B$401,$AH3)="","",INDEX('Per Invoice'!B$2:B$401,$AH3))) | C3: =IF($AH3="","",IF(INDEX('Per Invoice'!C$2:C$401,$AH3)="","",INDEX('Per Invoice'!C$2:C$401,$AH3))) | D3: =IF($AH3="","",IF(INDEX('Per Invoice'!D$2:D$401,$AH3)="","",INDEX('Per Invoice'!D$2:D$401,$AH3))) | E3: =IF($AH3="","",IF(INDEX('Per Invoice'!E$2:E$401,$AH3)="","",INDEX('Per Invoice'!E$2:E$401,$AH3))) | F3: =IF($AH3="","",IF(INDEX('Per Invoice'!F$2:F$401,$AH3)="","",INDEX('Per Invoice'!F$2:F$401,$AH3))) | G3: =IF($AH3="","",IF(INDEX('Per Invoice'!G$2:G$401,$AH3)="","",INDEX('Per Invoice'!G$2:G$401,$AH3))) | H3: =IF($AH3="","",IF(INDEX('Per Invoice'!H$2:H$401,$AH3)="","",INDEX('Per Invoice'!H$2:H$401,$AH3))) | ... AG3: =IF($AH3="","",IF(INDEX('Per Invoice'!AG$2:AG$401,$AH3)="","",INDEX('Per Invoice'!AG$2:AG$401,$AH3))) | AH3: =IFERROR(MATCH(Settings!$C$27&"|"&ROWS($AH$2:$AH3),'Per Invoice'!$AI$2:$AI$401,0),"")
A4: =IF($AH4="","",IF(INDEX('Per Invoice'!A$2:A$401,$AH4)="","",INDEX('Per Invoice'!A$2:A$401,$AH4))) | B4: =IF($AH4="","",IF(INDEX('Per Invoice'!B$2:B$401,$AH4)="","",INDEX('Per Invoice'!B$2:B$401,$AH4))) | C4: =IF($AH4="","",IF(INDEX('Per Invoice'!C$2:C$401,$AH4)="","",INDEX('Per Invoice'!C$2:C$401,$AH4))) | D4: =IF($AH4="","",IF(INDEX('Per Invoice'!D$2:D$401,$AH4)="","",INDEX('Per Invoice'!D$2:D$401,$AH4))) | E4: =IF($AH4="","",IF(INDEX('Per Invoice'!E$2:E$401,$AH4)="","",INDEX('Per Invoice'!E$2:E$401,$AH4))) | F4: =IF($AH4="","",IF(INDEX('Per Invoice'!F$2:F$401,$AH4)="","",INDEX('Per Invoice'!F$2:F$401,$AH4))) | G4: =IF($AH4="","",IF(INDEX('Per Invoice'!G$2:G$401,$AH4)="","",INDEX('Per Invoice'!G$2:G$401,$AH4))) | H4: =IF($AH4="","",IF(INDEX('Per Invoice'!H$2:H$401,$AH4)="","",INDEX('Per Invoice'!H$2:H$401,$AH4))) | ... AG4: =IF($AH4="","",IF(INDEX('Per Invoice'!AG$2:AG$401,$AH4)="","",INDEX('Per Invoice'!AG$2:AG$401,$AH4))) | AH4: =IFERROR(MATCH(Settings!$C$27&"|"&ROWS($AH$2:$AH4),'Per Invoice'!$AI$2:$AI$401,0),"")
A5: =IF($AH5="","",IF(INDEX('Per Invoice'!A$2:A$401,$AH5)="","",INDEX('Per Invoice'!A$2:A$401,$AH5))) | B5: =IF($AH5="","",IF(INDEX('Per Invoice'!B$2:B$401,$AH5)="","",INDEX('Per Invoice'!B$2:B$401,$AH5))) | C5: =IF($AH5="","",IF(INDEX('Per Invoice'!C$2:C$401,$AH5)="","",INDEX('Per Invoice'!C$2:C$401,$AH5))) | D5: =IF($AH5="","",IF(INDEX('Per Invoice'!D$2:D$401,$AH5)="","",INDEX('Per Invoice'!D$2:D$401,$AH5))) | E5: =IF($AH5="","",IF(INDEX('Per Invoice'!E$2:E$401,$AH5)="","",INDEX('Per Invoice'!E$2:E$401,$AH5))) | F5: =IF($AH5="","",IF(INDEX('Per Invoice'!F$2:F$401,$AH5)="","",INDEX('Per Invoice'!F$2:F$401,$AH5))) | G5: =IF($AH5="","",IF(INDEX('Per Invoice'!G$2:G$401,$AH5)="","",INDEX('Per Invoice'!G$2:G$401,$AH5))) | H5: =IF($AH5="","",IF(INDEX('Per Invoice'!H$2:H$401,$AH5)="","",INDEX('Per Invoice'!H$2:H$401,$AH5))) | ... AG5: =IF($AH5="","",IF(INDEX('Per Invoice'!AG$2:AG$401,$AH5)="","",INDEX('Per Invoice'!AG$2:AG$401,$AH5))) | AH5: =IFERROR(MATCH(Settings!$C$27&"|"&ROWS($AH$2:$AH5),'Per Invoice'!$AI$2:$AI$401,0),"")
