Workbook

Sheet How To Use
B1: METLIFE - VPN - CLAIM FORM TEMPLATE
B3: Colours: blue header = pasted or typed by you, green header = formula (do not paste over it), grey header = helper, yellow = editable setting.
B5: 1. In 'Per Line', paste the lines of the sheet from row 2 into the blue columns: A-X, AB-AC, AE-AF.
B6: Do NOT paste over the green formula columns: Y-AA, AD (they calculate Discount, Co val, Subtotal and Net from the Total Approved, Rebates % and Copay % you pasted).
B7: Paste the columns in the same order as the source sheet. Rebates % and Copay % come from the sheet, so there are no rates to set. If a Rebates % is typed as a fraction below 1 (for example 0.12), the template reads it as a percent (12).
B8: 2. 'Per Invoice' fills itself: one row per So, in the order the orders first appear in 'Per Line'. Type Invoice, ERX, Card in the blue columns.
B9: 3. Segments (Above Claim Form / Below Claim Form) are decided by the Lot number. The Lot to segment table is in 'Settings' (yellow cells): add any new Lot there.
B10: The tabs 'Per Invoice Above Claim Form' and 'Per Invoice Below Claim Form' fill themselves from 'Per Invoice', and 'Summary' shows the count and totals per segment.
B11: 4. Open 'Settings': STATUS must say OK. If it says CHECK, a total in 'Per Line' differs from 'Per Invoice', there are more orders than the template has room for, or a Lot is missing from the segment table.
B13: To start a new month: clear the blue cells in 'Per Line' (row 2 down) and the blue cells in 'Per Invoice', then paste again.

Sheet Settings
B1: METLIFE - VPN - CLAIM FORM - SETTINGS
B3: Insurance company | C3: Metlife | D3: Rebates % and Copay % are typed on every line of the export, so there are no rates to set here.
B4: Type | C4: VPN - Claim Form
B5: Month (as in the source sheet) | C5: August 2026
B9: Reconciliation (Per Line vs Per Invoice)
B10: Lines loaded | C10: =COUNTA('Per Line'!$D$2:$D$3001)
B11: Invoices (unique So) | C11: =MAX('Per Line'!$AG$2:$AG$3001)
B12: Invoices shown in Per Invoice | C12: =COUNTIF('Per Invoice'!$C$2:$C$801,"?*")+COUNT('Per Invoice'!$C$2:$C$801)
B13: Total Approved - Per Line | C13: =SUM('Per Line'!$X$2:$X$3001)
B14: Total Approved - Per Invoice | C14: =SUM('Per Invoice'!$I$2:$I$801)
B15: Discount - Per Line | C15: =SUM('Per Line'!$Y$2:$Y$3001)
B16: Discount - Per Invoice | C16: =SUM('Per Invoice'!$J$2:$J$801)
B17: Co val - Per Line | C17: =SUM('Per Line'!$Z$2:$Z$3001)
B18: Co val - Per Invoice | C18: =SUM('Per Invoice'!$K$2:$K$801)
B19: Net - Per Line | C19: =SUM('Per Line'!$AD$2:$AD$3001)
B20: Net - Per Invoice | C20: =SUM('Per Invoice'!$M$2:$M$801)
B21: Orders that do not fit in Per Invoice (must be 0) | C21: =MAX(0,C11-800)
B22: Orders whose Lot is not in the segment table below (must be 0) | C22: =COUNTIF('Per Invoice'!$B$2:$B$801,"Unassigned")
B23: STATUS | C23: =IF(C10=0,"No data loaded",IF(AND(C21=0,C12=C11,ABS(C13-C14)<0.01,ABS(C15-C16)<0.01,ABS(C17-C18)<0.01,ABS(C19-C20)<0.01,C22=0),"OK","CHECK")) | D23: Per Line has room for 3000 lines and Per Invoice for 800 invoices.
B25: Segment table: which Lot belongs to which segment
B26: Lot number | C26: Segment | D26: Add a new Lot here when it appears in Per Line. Segment must be spelled exactly: Above Claim Form / Below Claim Form
B27: 26158332 | C27: Above Claim Form
B28: 26158333 | C28: Below Claim Form

Sheet Summary
A1: Segment | B1: Count of So | C1: Sum of Total Approved | D1: Sum of dis | E1: Sum of Paid Amount | F1: Sum of Subtotal | G1: Sum of Net Amt
A2: Above Claim Form | B2: =COUNTIF('Per Invoice'!$B$2:$B$801,A2) | C2: =SUMIFS('Per Invoice'!$I$2:$I$801,'Per Invoice'!$B$2:$B$801,$A2) | D2: =SUMIFS('Per Invoice'!$J$2:$J$801,'Per Invoice'!$B$2:$B$801,$A2) | E2: =SUMIFS('Per Invoice'!$K$2:$K$801,'Per Invoice'!$B$2:$B$801,$A2) | F2: =SUMIFS('Per Invoice'!$L$2:$L$801,'Per Invoice'!$B$2:$B$801,$A2) | G2: =SUMIFS('Per Invoice'!$M$2:$M$801,'Per Invoice'!$B$2:$B$801,$A2)
A3: Below Claim Form | B3: =COUNTIF('Per Invoice'!$B$2:$B$801,A3) | C3: =SUMIFS('Per Invoice'!$I$2:$I$801,'Per Invoice'!$B$2:$B$801,$A3) | D3: =SUMIFS('Per Invoice'!$J$2:$J$801,'Per Invoice'!$B$2:$B$801,$A3) | E3: =SUMIFS('Per Invoice'!$K$2:$K$801,'Per Invoice'!$B$2:$B$801,$A3) | F3: =SUMIFS('Per Invoice'!$L$2:$L$801,'Per Invoice'!$B$2:$B$801,$A3) | G3: =SUMIFS('Per Invoice'!$M$2:$M$801,'Per Invoice'!$B$2:$B$801,$A3)
A4: Other / Unassigned | B4: =B5-SUM(B2:B3) | C4: =C5-SUM(C2:C3) | D4: =D5-SUM(D2:D3) | E4: =E5-SUM(E2:E3) | F4: =F5-SUM(F2:F3) | G4: =G5-SUM(G2:G3)
A5: Grand Total | B5: =COUNTIF('Per Invoice'!$C$2:$C$801,"?*") | C5: =SUM('Per Invoice'!$I$2:$I$801) | D5: =SUM('Per Invoice'!$J$2:$J$801) | E5: =SUM('Per Invoice'!$K$2:$K$801) | F5: =SUM('Per Invoice'!$L$2:$L$801) | G5: =SUM('Per Invoice'!$M$2:$M$801)

Sheet Per Line
A1: Lot | B1: Glob Med Ref | C1: SSNBR | D1: So | E1: Status | F1: Dependent code | G1: Individual Number | H1: Provider code | I1: Provider Name | J1: real Provider Code | K1: real Provider Name | L1: Concat | M1: DIAG 1(ICD9) | N1: HZB ID | O1: Item code | P1: Globemed Item Code | Q1: Item description | R1: Comment1 | S1: Comment2 | T1: Alternative | U1: Unit Type Dispensed | V1: Svc Date | W1: Qty Approved | X1: Total Approved | Y1: dis | Z1: Paid Amount | AA1: Subtotal | AB1: Co% | AC1: Rebates | AD1: Net Amt | AE1: Group No. | AF1: Certificate No. | AG1: Order Seq (helper)
Y2: =IF(D2="","",X2*IF(AND(ISNUMBER(AC2),AC2>0,AC2<1),AC2*100,AC2)/100) | Z2: =IF(D2="","",AB2*AA2/100) | AA2: =IF(D2="","",X2-Y2) | AD2: =IF(D2="","",AA2-Z2) | AG2: =IF(D2="","",N(AG1)+IF(MATCH(D2,$D$2:$D$3001,0)=ROW()-1,1,0))
Y3: =IF(D3="","",X3*IF(AND(ISNUMBER(AC3),AC3>0,AC3<1),AC3*100,AC3)/100) | Z3: =IF(D3="","",AB3*AA3/100) | AA3: =IF(D3="","",X3-Y3) | AD3: =IF(D3="","",AA3-Z3) | AG3: =IF(D3="","",N(AG2)+IF(MATCH(D3,$D$2:$D$3001,0)=ROW()-1,1,0))
Y4: =IF(D4="","",X4*IF(AND(ISNUMBER(AC4),AC4>0,AC4<1),AC4*100,AC4)/100) | Z4: =IF(D4="","",AB4*AA4/100) | AA4: =IF(D4="","",X4-Y4) | AD4: =IF(D4="","",AA4-Z4) | AG4: =IF(D4="","",N(AG3)+IF(MATCH(D4,$D$2:$D$3001,0)=ROW()-1,1,0))
Y5: =IF(D5="","",X5*IF(AND(ISNUMBER(AC5),AC5>0,AC5<1),AC5*100,AC5)/100) | Z5: =IF(D5="","",AB5*AA5/100) | AA5: =IF(D5="","",X5-Y5) | AD5: =IF(D5="","",AA5-Z5) | AG5: =IF(D5="","",N(AG4)+IF(MATCH(D5,$D$2:$D$3001,0)=ROW()-1,1,0))
Y6: =IF(D6="","",X6*IF(AND(ISNUMBER(AC6),AC6>0,AC6<1),AC6*100,AC6)/100) | Z6: =IF(D6="","",AB6*AA6/100) | AA6: =IF(D6="","",X6-Y6) | AD6: =IF(D6="","",AA6-Z6) | AG6: =IF(D6="","",N(AG5)+IF(MATCH(D6,$D$2:$D$3001,0)=ROW()-1,1,0))
Y7: =IF(D7="","",X7*IF(AND(ISNUMBER(AC7),AC7>0,AC7<1),AC7*100,AC7)/100) | Z7: =IF(D7="","",AB7*AA7/100) | AA7: =IF(D7="","",X7-Y7) | AD7: =IF(D7="","",AA7-Z7) | AG7: =IF(D7="","",N(AG6)+IF(MATCH(D7,$D$2:$D$3001,0)=ROW()-1,1,0))
Y8: =IF(D8="","",X8*IF(AND(ISNUMBER(AC8),AC8>0,AC8<1),AC8*100,AC8)/100) | Z8: =IF(D8="","",AB8*AA8/100) | AA8: =IF(D8="","",X8-Y8) | AD8: =IF(D8="","",AA8-Z8) | AG8: =IF(D8="","",N(AG7)+IF(MATCH(D8,$D$2:$D$3001,0)=ROW()-1,1,0))
Y9: =IF(D9="","",X9*IF(AND(ISNUMBER(AC9),AC9>0,AC9<1),AC9*100,AC9)/100) | Z9: =IF(D9="","",AB9*AA9/100) | AA9: =IF(D9="","",X9-Y9) | AD9: =IF(D9="","",AA9-Z9) | AG9: =IF(D9="","",N(AG8)+IF(MATCH(D9,$D$2:$D$3001,0)=ROW()-1,1,0))
Y10: =IF(D10="","",X10*IF(AND(ISNUMBER(AC10),AC10>0,AC10<1),AC10*100,AC10)/100) | Z10: =IF(D10="","",AB10*AA10/100) | AA10: =IF(D10="","",X10-Y10) | AD10: =IF(D10="","",AA10-Z10) | AG10: =IF(D10="","",N(AG9)+IF(MATCH(D10,$D$2:$D$3001,0)=ROW()-1,1,0))
Y11: =IF(D11="","",X11*IF(AND(ISNUMBER(AC11),AC11>0,AC11<1),AC11*100,AC11)/100) | Z11: =IF(D11="","",AB11*AA11/100) | AA11: =IF(D11="","",X11-Y11) | AD11: =IF(D11="","",AA11-Z11) | AG11: =IF(D11="","",N(AG10)+IF(MATCH(D11,$D$2:$D$3001,0)=ROW()-1,1,0))
Y12: =IF(D12="","",X12*IF(AND(ISNUMBER(AC12),AC12>0,AC12<1),AC12*100,AC12)/100) | Z12: =IF(D12="","",AB12*AA12/100) | AA12: =IF(D12="","",X12-Y12) | AD12: =IF(D12="","",AA12-Z12) | AG12: =IF(D12="","",N(AG11)+IF(MATCH(D12,$D$2:$D$3001,0)=ROW()-1,1,0))
Y13: =IF(D13="","",X13*IF(AND(ISNUMBER(AC13),AC13>0,AC13<1),AC13*100,AC13)/100) | Z13: =IF(D13="","",AB13*AA13/100) | AA13: =IF(D13="","",X13-Y13) | AD13: =IF(D13="","",AA13-Z13) | AG13: =IF(D13="","",N(AG12)+IF(MATCH(D13,$D$2:$D$3001,0)=ROW()-1,1,0))
... Y3001: =IF(D3001="","",X3001*IF(AND(ISNUMBER(AC3001),AC3001>0,AC3001<1),AC3001*100,AC3001)/100) | Z3001: =IF(D3001="","",AB3001*AA3001/100) | AA3001: =IF(D3001="","",X3001-Y3001) | AD3001: =IF(D3001="","",AA3001-Z3001) | AG3001: =IF(D3001="","",N(AG3000)+IF(MATCH(D3001,$D$2:$D$3001,0)=ROW()-1,1,0))

Sheet Per Invoice
A1: Invoice | B1: Seg | C1: So | D1: SSNBR | E1: Lot | F1: ERX | G1: Card | H1: Svc Date | I1: Sum of Total Approved | J1: Sum of dis | K1: Sum of Paid Amount | L1: Sum of Subtotal | M1: Sum of Net Amt | N1: Src Row (helper) | O1: Above Claim Form Seq (helper) | P1: Below Claim Form Seq (helper)
B2: =IF($N2="","",IFERROR(INDEX(Settings!$C$27:$C$36,MATCH(E2,Settings!$B$27:$B$36,0)),"Unassigned")) | C2: =IF($N2="","",INDEX('Per Line'!$D$2:$D$3001,$N2)) | D2: =IF($N2="","",INDEX('Per Line'!$C$2:$C$3001,$N2)) | E2: =IF($N2="","",INDEX('Per Line'!$A$2:$A$3001,$N2)) | H2: =IF($N2="","",INDEX('Per Line'!$V$2:$V$3001,$N2)) | I2: =IF($N2="","",SUMIFS('Per Line'!$X$2:$X$3001,'Per Line'!$D$2:$D$3001,$C2)) | J2: =IF($N2="","",SUMIFS('Per Line'!$Y$2:$Y$3001,'Per Line'!$D$2:$D$3001,$C2)) | K2: =IF($N2="","",SUMIFS('Per Line'!$Z$2:$Z$3001,'Per Line'!$D$2:$D$3001,$C2)) | L2: =IF($N2="","",I2-J2) | M2: =IF($N2="","",L2-K2) | N2: =IF(ROWS($N$2:$N2)<=MAX('Per Line'!$AG$2:$AG$3001),MATCH(ROWS($N$2:$N2),'Per Line'!$AG$2:$AG$3001,0),"") | O2: =IF(B2="Above Claim Form",COUNTIF($B$2:B2,"Above Claim Form"),"") | P2: =IF(B2="Below Claim Form",COUNTIF($B$2:B2,"Below Claim Form"),"")
B3: =IF($N3="","",IFERROR(INDEX(Settings!$C$27:$C$36,MATCH(E3,Settings!$B$27:$B$36,0)),"Unassigned")) | C3: =IF($N3="","",INDEX('Per Line'!$D$2:$D$3001,$N3)) | D3: =IF($N3="","",INDEX('Per Line'!$C$2:$C$3001,$N3)) | E3: =IF($N3="","",INDEX('Per Line'!$A$2:$A$3001,$N3)) | H3: =IF($N3="","",INDEX('Per Line'!$V$2:$V$3001,$N3)) | I3: =IF($N3="","",SUMIFS('Per Line'!$X$2:$X$3001,'Per Line'!$D$2:$D$3001,$C3)) | J3: =IF($N3="","",SUMIFS('Per Line'!$Y$2:$Y$3001,'Per Line'!$D$2:$D$3001,$C3)) | K3: =IF($N3="","",SUMIFS('Per Line'!$Z$2:$Z$3001,'Per Line'!$D$2:$D$3001,$C3)) | L3: =IF($N3="","",I3-J3) | M3: =IF($N3="","",L3-K3) | N3: =IF(ROWS($N$2:$N3)<=MAX('Per Line'!$AG$2:$AG$3001),MATCH(ROWS($N$2:$N3),'Per Line'!$AG$2:$AG$3001,0),"") | O3: =IF(B3="Above Claim Form",COUNTIF($B$2:B3,"Above Claim Form"),"") | P3: =IF(B3="Below Claim Form",COUNTIF($B$2:B3,"Below Claim Form"),"")
B4: =IF($N4="","",IFERROR(INDEX(Settings!$C$27:$C$36,MATCH(E4,Settings!$B$27:$B$36,0)),"Unassigned")) | C4: =IF($N4="","",INDEX('Per Line'!$D$2:$D$3001,$N4)) | D4: =IF($N4="","",INDEX('Per Line'!$C$2:$C$3001,$N4)) | E4: =IF($N4="","",INDEX('Per Line'!$A$2:$A$3001,$N4)) | H4: =IF($N4="","",INDEX('Per Line'!$V$2:$V$3001,$N4)) | I4: =IF($N4="","",SUMIFS('Per Line'!$X$2:$X$3001,'Per Line'!$D$2:$D$3001,$C4)) | J4: =IF($N4="","",SUMIFS('Per Line'!$Y$2:$Y$3001,'Per Line'!$D$2:$D$3001,$C4)) | K4: =IF($N4="","",SUMIFS('Per Line'!$Z$2:$Z$3001,'Per Line'!$D$2:$D$3001,$C4)) | L4: =IF($N4="","",I4-J4) | M4: =IF($N4="","",L4-K4) | N4: =IF(ROWS($N$2:$N4)<=MAX('Per Line'!$AG$2:$AG$3001),MATCH(ROWS($N$2:$N4),'Per Line'!$AG$2:$AG$3001,0),"") | O4: =IF(B4="Above Claim Form",COUNTIF($B$2:B4,"Above Claim Form"),"") | P4: =IF(B4="Below Claim Form",COUNTIF($B$2:B4,"Below Claim Form"),"")
B5: =IF($N5="","",IFERROR(INDEX(Settings!$C$27:$C$36,MATCH(E5,Settings!$B$27:$B$36,0)),"Unassigned")) | C5: =IF($N5="","",INDEX('Per Line'!$D$2:$D$3001,$N5)) | D5: =IF($N5="","",INDEX('Per Line'!$C$2:$C$3001,$N5)) | E5: =IF($N5="","",INDEX('Per Line'!$A$2:$A$3001,$N5)) | H5: =IF($N5="","",INDEX('Per Line'!$V$2:$V$3001,$N5)) | I5: =IF($N5="","",SUMIFS('Per Line'!$X$2:$X$3001,'Per Line'!$D$2:$D$3001,$C5)) | J5: =IF($N5="","",SUMIFS('Per Line'!$Y$2:$Y$3001,'Per Line'!$D$2:$D$3001,$C5)) | K5: =IF($N5="","",SUMIFS('Per Line'!$Z$2:$Z$3001,'Per Line'!$D$2:$D$3001,$C5)) | L5: =IF($N5="","",I5-J5) | M5: =IF($N5="","",L5-K5) | N5: =IF(ROWS($N$2:$N5)<=MAX('Per Line'!$AG$2:$AG$3001),MATCH(ROWS($N$2:$N5),'Per Line'!$AG$2:$AG$3001,0),"") | O5: =IF(B5="Above Claim Form",COUNTIF($B$2:B5,"Above Claim Form"),"") | P5: =IF(B5="Below Claim Form",COUNTIF($B$2:B5,"Below Claim Form"),"")
B6: =IF($N6="","",IFERROR(INDEX(Settings!$C$27:$C$36,MATCH(E6,Settings!$B$27:$B$36,0)),"Unassigned")) | C6: =IF($N6="","",INDEX('Per Line'!$D$2:$D$3001,$N6)) | D6: =IF($N6="","",INDEX('Per Line'!$C$2:$C$3001,$N6)) | E6: =IF($N6="","",INDEX('Per Line'!$A$2:$A$3001,$N6)) | H6: =IF($N6="","",INDEX('Per Line'!$V$2:$V$3001,$N6)) | I6: =IF($N6="","",SUMIFS('Per Line'!$X$2:$X$3001,'Per Line'!$D$2:$D$3001,$C6)) | J6: =IF($N6="","",SUMIFS('Per Line'!$Y$2:$Y$3001,'Per Line'!$D$2:$D$3001,$C6)) | K6: =IF($N6="","",SUMIFS('Per Line'!$Z$2:$Z$3001,'Per Line'!$D$2:$D$3001,$C6)) | L6: =IF($N6="","",I6-J6) | M6: =IF($N6="","",L6-K6) | N6: =IF(ROWS($N$2:$N6)<=MAX('Per Line'!$AG$2:$AG$3001),MATCH(ROWS($N$2:$N6),'Per Line'!$AG$2:$AG$3001,0),"") | O6: =IF(B6="Above Claim Form",COUNTIF($B$2:B6,"Above Claim Form"),"") | P6: =IF(B6="Below Claim Form",COUNTIF($B$2:B6,"Below Claim Form"),"")
B7: =IF($N7="","",IFERROR(INDEX(Settings!$C$27:$C$36,MATCH(E7,Settings!$B$27:$B$36,0)),"Unassigned")) | C7: =IF($N7="","",INDEX('Per Line'!$D$2:$D$3001,$N7)) | D7: =IF($N7="","",INDEX('Per Line'!$C$2:$C$3001,$N7)) | E7: =IF($N7="","",INDEX('Per Line'!$A$2:$A$3001,$N7)) | H7: =IF($N7="","",INDEX('Per Line'!$V$2:$V$3001,$N7)) | I7: =IF($N7="","",SUMIFS('Per Line'!$X$2:$X$3001,'Per Line'!$D$2:$D$3001,$C7)) | J7: =IF($N7="","",SUMIFS('Per Line'!$Y$2:$Y$3001,'Per Line'!$D$2:$D$3001,$C7)) | K7: =IF($N7="","",SUMIFS('Per Line'!$Z$2:$Z$3001,'Per Line'!$D$2:$D$3001,$C7)) | L7: =IF($N7="","",I7-J7) | M7: =IF($N7="","",L7-K7) | N7: =IF(ROWS($N$2:$N7)<=MAX('Per Line'!$AG$2:$AG$3001),MATCH(ROWS($N$2:$N7),'Per Line'!$AG$2:$AG$3001,0),"") | O7: =IF(B7="Above Claim Form",COUNTIF($B$2:B7,"Above Claim Form"),"") | P7: =IF(B7="Below Claim Form",COUNTIF($B$2:B7,"Below Claim Form"),"")
B8: =IF($N8="","",IFERROR(INDEX(Settings!$C$27:$C$36,MATCH(E8,Settings!$B$27:$B$36,0)),"Unassigned")) | C8: =IF($N8="","",INDEX('Per Line'!$D$2:$D$3001,$N8)) | D8: =IF($N8="","",INDEX('Per Line'!$C$2:$C$3001,$N8)) | E8: =IF($N8="","",INDEX('Per Line'!$A$2:$A$3001,$N8)) | H8: =IF($N8="","",INDEX('Per Line'!$V$2:$V$3001,$N8)) | I8: =IF($N8="","",SUMIFS('Per Line'!$X$2:$X$3001,'Per Line'!$D$2:$D$3001,$C8)) | J8: =IF($N8="","",SUMIFS('Per Line'!$Y$2:$Y$3001,'Per Line'!$D$2:$D$3001,$C8)) | K8: =IF($N8="","",SUMIFS('Per Line'!$Z$2:$Z$3001,'Per Line'!$D$2:$D$3001,$C8)) | L8: =IF($N8="","",I8-J8) | M8: =IF($N8="","",L8-K8) | N8: =IF(ROWS($N$2:$N8)<=MAX('Per Line'!$AG$2:$AG$3001),MATCH(ROWS($N$2:$N8),'Per Line'!$AG$2:$AG$3001,0),"") | O8: =IF(B8="Above Claim Form",COUNTIF($B$2:B8,"Above Claim Form"),"") | P8: =IF(B8="Below Claim Form",COUNTIF($B$2:B8,"Below Claim Form"),"")
B9: =IF($N9="","",IFERROR(INDEX(Settings!$C$27:$C$36,MATCH(E9,Settings!$B$27:$B$36,0)),"Unassigned")) | C9: =IF($N9="","",INDEX('Per Line'!$D$2:$D$3001,$N9)) | D9: =IF($N9="","",INDEX('Per Line'!$C$2:$C$3001,$N9)) | E9: =IF($N9="","",INDEX('Per Line'!$A$2:$A$3001,$N9)) | H9: =IF($N9="","",INDEX('Per Line'!$V$2:$V$3001,$N9)) | I9: =IF($N9="","",SUMIFS('Per Line'!$X$2:$X$3001,'Per Line'!$D$2:$D$3001,$C9)) | J9: =IF($N9="","",SUMIFS('Per Line'!$Y$2:$Y$3001,'Per Line'!$D$2:$D$3001,$C9)) | K9: =IF($N9="","",SUMIFS('Per Line'!$Z$2:$Z$3001,'Per Line'!$D$2:$D$3001,$C9)) | L9: =IF($N9="","",I9-J9) | M9: =IF($N9="","",L9-K9) | N9: =IF(ROWS($N$2:$N9)<=MAX('Per Line'!$AG$2:$AG$3001),MATCH(ROWS($N$2:$N9),'Per Line'!$AG$2:$AG$3001,0),"") | O9: =IF(B9="Above Claim Form",COUNTIF($B$2:B9,"Above Claim Form"),"") | P9: =IF(B9="Below Claim Form",COUNTIF($B$2:B9,"Below Claim Form"),"")
B10: =IF($N10="","",IFERROR(INDEX(Settings!$C$27:$C$36,MATCH(E10,Settings!$B$27:$B$36,0)),"Unassigned")) | C10: =IF($N10="","",INDEX('Per Line'!$D$2:$D$3001,$N10)) | D10: =IF($N10="","",INDEX('Per Line'!$C$2:$C$3001,$N10)) | E10: =IF($N10="","",INDEX('Per Line'!$A$2:$A$3001,$N10)) | H10: =IF($N10="","",INDEX('Per Line'!$V$2:$V$3001,$N10)) | I10: =IF($N10="","",SUMIFS('Per Line'!$X$2:$X$3001,'Per Line'!$D$2:$D$3001,$C10)) | J10: =IF($N10="","",SUMIFS('Per Line'!$Y$2:$Y$3001,'Per Line'!$D$2:$D$3001,$C10)) | K10: =IF($N10="","",SUMIFS('Per Line'!$Z$2:$Z$3001,'Per Line'!$D$2:$D$3001,$C10)) | L10: =IF($N10="","",I10-J10) | M10: =IF($N10="","",L10-K10) | N10: =IF(ROWS($N$2:$N10)<=MAX('Per Line'!$AG$2:$AG$3001),MATCH(ROWS($N$2:$N10),'Per Line'!$AG$2:$AG$3001,0),"") | O10: =IF(B10="Above Claim Form",COUNTIF($B$2:B10,"Above Claim Form"),"") | P10: =IF(B10="Below Claim Form",COUNTIF($B$2:B10,"Below Claim Form"),"")
B11: =IF($N11="","",IFERROR(INDEX(Settings!$C$27:$C$36,MATCH(E11,Settings!$B$27:$B$36,0)),"Unassigned")) | C11: =IF($N11="","",INDEX('Per Line'!$D$2:$D$3001,$N11)) | D11: =IF($N11="","",INDEX('Per Line'!$C$2:$C$3001,$N11)) | E11: =IF($N11="","",INDEX('Per Line'!$A$2:$A$3001,$N11)) | H11: =IF($N11="","",INDEX('Per Line'!$V$2:$V$3001,$N11)) | I11: =IF($N11="","",SUMIFS('Per Line'!$X$2:$X$3001,'Per Line'!$D$2:$D$3001,$C11)) | J11: =IF($N11="","",SUMIFS('Per Line'!$Y$2:$Y$3001,'Per Line'!$D$2:$D$3001,$C11)) | K11: =IF($N11="","",SUMIFS('Per Line'!$Z$2:$Z$3001,'Per Line'!$D$2:$D$3001,$C11)) | L11: =IF($N11="","",I11-J11) | M11: =IF($N11="","",L11-K11) | N11: =IF(ROWS($N$2:$N11)<=MAX('Per Line'!$AG$2:$AG$3001),MATCH(ROWS($N$2:$N11),'Per Line'!$AG$2:$AG$3001,0),"") | O11: =IF(B11="Above Claim Form",COUNTIF($B$2:B11,"Above Claim Form"),"") | P11: =IF(B11="Below Claim Form",COUNTIF($B$2:B11,"Below Claim Form"),"")
B12: =IF($N12="","",IFERROR(INDEX(Settings!$C$27:$C$36,MATCH(E12,Settings!$B$27:$B$36,0)),"Unassigned")) | C12: =IF($N12="","",INDEX('Per Line'!$D$2:$D$3001,$N12)) | D12: =IF($N12="","",INDEX('Per Line'!$C$2:$C$3001,$N12)) | E12: =IF($N12="","",INDEX('Per Line'!$A$2:$A$3001,$N12)) | H12: =IF($N12="","",INDEX('Per Line'!$V$2:$V$3001,$N12)) | I12: =IF($N12="","",SUMIFS('Per Line'!$X$2:$X$3001,'Per Line'!$D$2:$D$3001,$C12)) | J12: =IF($N12="","",SUMIFS('Per Line'!$Y$2:$Y$3001,'Per Line'!$D$2:$D$3001,$C12)) | K12: =IF($N12="","",SUMIFS('Per Line'!$Z$2:$Z$3001,'Per Line'!$D$2:$D$3001,$C12)) | L12: =IF($N12="","",I12-J12) | M12: =IF($N12="","",L12-K12) | N12: =IF(ROWS($N$2:$N12)<=MAX('Per Line'!$AG$2:$AG$3001),MATCH(ROWS($N$2:$N12),'Per Line'!$AG$2:$AG$3001,0),"") | O12: =IF(B12="Above Claim Form",COUNTIF($B$2:B12,"Above Claim Form"),"") | P12: =IF(B12="Below Claim Form",COUNTIF($B$2:B12,"Below Claim Form"),"")
B13: =IF($N13="","",IFERROR(INDEX(Settings!$C$27:$C$36,MATCH(E13,Settings!$B$27:$B$36,0)),"Unassigned")) | C13: =IF($N13="","",INDEX('Per Line'!$D$2:$D$3001,$N13)) | D13: =IF($N13="","",INDEX('Per Line'!$C$2:$C$3001,$N13)) | E13: =IF($N13="","",INDEX('Per Line'!$A$2:$A$3001,$N13)) | H13: =IF($N13="","",INDEX('Per Line'!$V$2:$V$3001,$N13)) | I13: =IF($N13="","",SUMIFS('Per Line'!$X$2:$X$3001,'Per Line'!$D$2:$D$3001,$C13)) | J13: =IF($N13="","",SUMIFS('Per Line'!$Y$2:$Y$3001,'Per Line'!$D$2:$D$3001,$C13)) | K13: =IF($N13="","",SUMIFS('Per Line'!$Z$2:$Z$3001,'Per Line'!$D$2:$D$3001,$C13)) | L13: =IF($N13="","",I13-J13) | M13: =IF($N13="","",L13-K13) | N13: =IF(ROWS($N$2:$N13)<=MAX('Per Line'!$AG$2:$AG$3001),MATCH(ROWS($N$2:$N13),'Per Line'!$AG$2:$AG$3001,0),"") | O13: =IF(B13="Above Claim Form",COUNTIF($B$2:B13,"Above Claim Form"),"") | P13: =IF(B13="Below Claim Form",COUNTIF($B$2:B13,"Below Claim Form"),"")
... B801: =IF($N801="","",IFERROR(INDEX(Settings!$C$27:$C$36,MATCH(E801,Settings!$B$27:$B$36,0)),"Unassigned")) | C801: =IF($N801="","",INDEX('Per Line'!$D$2:$D$3001,$N801)) | D801: =IF($N801="","",INDEX('Per Line'!$C$2:$C$3001,$N801)) | E801: =IF($N801="","",INDEX('Per Line'!$A$2:$A$3001,$N801)) | H801: =IF($N801="","",INDEX('Per Line'!$V$2:$V$3001,$N801)) | I801: =IF($N801="","",SUMIFS('Per Line'!$X$2:$X$3001,'Per Line'!$D$2:$D$3001,$C801)) | J801: =IF($N801="","",SUMIFS('Per Line'!$Y$2:$Y$3001,'Per Line'!$D$2:$D$3001,$C801)) | K801: =IF($N801="","",SUMIFS('Per Line'!$Z$2:$Z$3001,'Per Line'!$D$2:$D$3001,$C801)) | L801: =IF($N801="","",I801-J801) | M801: =IF($N801="","",L801-K801) | N801: =IF(ROWS($N$2:$N801)<=MAX('Per Line'!$AG$2:$AG$3001),MATCH(ROWS($N$2:$N801),'Per Line'!$AG$2:$AG$3001,0),"") | O801: =IF(B801="Above Claim Form",COUNTIF($B$2:B801,"Above Claim Form"),"") | P801: =IF(B801="Below Claim Form",COUNTIF($B$2:B801,"Below Claim Form"),"")

Sheet Per Invoice Above Claim Form
A1: Invoice | B1: Seg | C1: So | D1: SSNBR | E1: Lot | F1: ERX | G1: Card | H1: Svc Date | I1: Sum of Total Approved | J1: Sum of dis | K1: Sum of Paid Amount | L1: Sum of Subtotal | M1: Sum of Net Amt | N1: Per Invoice Row (helper)
A2: =IF($N2="","",IF(INDEX('Per Invoice'!$A$2:$A$801,$N2)="","",INDEX('Per Invoice'!$A$2:$A$801,$N2))) | B2: =IF($N2="","",IF(INDEX('Per Invoice'!$B$2:$B$801,$N2)="","",INDEX('Per Invoice'!$B$2:$B$801,$N2))) | C2: =IF($N2="","",IF(INDEX('Per Invoice'!$C$2:$C$801,$N2)="","",INDEX('Per Invoice'!$C$2:$C$801,$N2))) | D2: =IF($N2="","",IF(INDEX('Per Invoice'!$D$2:$D$801,$N2)="","",INDEX('Per Invoice'!$D$2:$D$801,$N2))) | E2: =IF($N2="","",IF(INDEX('Per Invoice'!$E$2:$E$801,$N2)="","",INDEX('Per Invoice'!$E$2:$E$801,$N2))) | F2: =IF($N2="","",IF(INDEX('Per Invoice'!$F$2:$F$801,$N2)="","",INDEX('Per Invoice'!$F$2:$F$801,$N2))) | G2: =IF($N2="","",IF(INDEX('Per Invoice'!$G$2:$G$801,$N2)="","",INDEX('Per Invoice'!$G$2:$G$801,$N2))) | H2: =IF($N2="","",IF(INDEX('Per Invoice'!$H$2:$H$801,$N2)="","",INDEX('Per Invoice'!$H$2:$H$801,$N2))) | I2: =IF($N2="","",IF(INDEX('Per Invoice'!$I$2:$I$801,$N2)="","",INDEX('Per Invoice'!$I$2:$I$801,$N2))) | J2: =IF($N2="","",IF(INDEX('Per Invoice'!$J$2:$J$801,$N2)="","",INDEX('Per Invoice'!$J$2:$J$801,$N2))) | K2: =IF($N2="","",IF(INDEX('Per Invoice'!$K$2:$K$801,$N2)="","",INDEX('Per Invoice'!$K$2:$K$801,$N2))) | L2: =IF($N2="","",IF(INDEX('Per Invoice'!$L$2:$L$801,$N2)="","",INDEX('Per Invoice'!$L$2:$L$801,$N2))) | M2: =IF($N2="","",IF(INDEX('Per Invoice'!$M$2:$M$801,$N2)="","",INDEX('Per Invoice'!$M$2:$M$801,$N2))) | N2: =IF(ROWS($N$2:$N2)<=COUNT('Per Invoice'!$O$2:$O$801),MATCH(ROWS($N$2:$N2),'Per Invoice'!$O$2:$O$801,0),"")
A3: =IF($N3="","",IF(INDEX('Per Invoice'!$A$2:$A$801,$N3)="","",INDEX('Per Invoice'!$A$2:$A$801,$N3))) | B3: =IF($N3="","",IF(INDEX('Per Invoice'!$B$2:$B$801,$N3)="","",INDEX('Per Invoice'!$B$2:$B$801,$N3))) | C3: =IF($N3="","",IF(INDEX('Per Invoice'!$C$2:$C$801,$N3)="","",INDEX('Per Invoice'!$C$2:$C$801,$N3))) | D3: =IF($N3="","",IF(INDEX('Per Invoice'!$D$2:$D$801,$N3)="","",INDEX('Per Invoice'!$D$2:$D$801,$N3))) | E3: =IF($N3="","",IF(INDEX('Per Invoice'!$E$2:$E$801,$N3)="","",INDEX('Per Invoice'!$E$2:$E$801,$N3))) | F3: =IF($N3="","",IF(INDEX('Per Invoice'!$F$2:$F$801,$N3)="","",INDEX('Per Invoice'!$F$2:$F$801,$N3))) | G3: =IF($N3="","",IF(INDEX('Per Invoice'!$G$2:$G$801,$N3)="","",INDEX('Per Invoice'!$G$2:$G$801,$N3))) | H3: =IF($N3="","",IF(INDEX('Per Invoice'!$H$2:$H$801,$N3)="","",INDEX('Per Invoice'!$H$2:$H$801,$N3))) | I3: =IF($N3="","",IF(INDEX('Per Invoice'!$I$2:$I$801,$N3)="","",INDEX('Per Invoice'!$I$2:$I$801,$N3))) | J3: =IF($N3="","",IF(INDEX('Per Invoice'!$J$2:$J$801,$N3)="","",INDEX('Per Invoice'!$J$2:$J$801,$N3))) | K3: =IF($N3="","",IF(INDEX('Per Invoice'!$K$2:$K$801,$N3)="","",INDEX('Per Invoice'!$K$2:$K$801,$N3))) | L3: =IF($N3="","",IF(INDEX('Per Invoice'!$L$2:$L$801,$N3)="","",INDEX('Per Invoice'!$L$2:$L$801,$N3))) | M3: =IF($N3="","",IF(INDEX('Per Invoice'!$M$2:$M$801,$N3)="","",INDEX('Per Invoice'!$M$2:$M$801,$N3))) | N3: =IF(ROWS($N$2:$N3)<=COUNT('Per Invoice'!$O$2:$O$801),MATCH(ROWS($N$2:$N3),'Per Invoice'!$O$2:$O$801,0),"")
A4: =IF($N4="","",IF(INDEX('Per Invoice'!$A$2:$A$801,$N4)="","",INDEX('Per Invoice'!$A$2:$A$801,$N4))) | B4: =IF($N4="","",IF(INDEX('Per Invoice'!$B$2:$B$801,$N4)="","",INDEX('Per Invoice'!$B$2:$B$801,$N4))) | C4: =IF($N4="","",IF(INDEX('Per Invoice'!$C$2:$C$801,$N4)="","",INDEX('Per Invoice'!$C$2:$C$801,$N4))) | D4: =IF($N4="","",IF(INDEX('Per Invoice'!$D$2:$D$801,$N4)="","",INDEX('Per Invoice'!$D$2:$D$801,$N4))) | E4: =IF($N4="","",IF(INDEX('Per Invoice'!$E$2:$E$801,$N4)="","",INDEX('Per Invoice'!$E$2:$E$801,$N4))) | F4: =IF($N4="","",IF(INDEX('Per Invoice'!$F$2:$F$801,$N4)="","",INDEX('Per Invoice'!$F$2:$F$801,$N4))) | G4: =IF($N4="","",IF(INDEX('Per Invoice'!$G$2:$G$801,$N4)="","",INDEX('Per Invoice'!$G$2:$G$801,$N4))) | H4: =IF($N4="","",IF(INDEX('Per Invoice'!$H$2:$H$801,$N4)="","",INDEX('Per Invoice'!$H$2:$H$801,$N4))) | I4: =IF($N4="","",IF(INDEX('Per Invoice'!$I$2:$I$801,$N4)="","",INDEX('Per Invoice'!$I$2:$I$801,$N4))) | J4: =IF($N4="","",IF(INDEX('Per Invoice'!$J$2:$J$801,$N4)="","",INDEX('Per Invoice'!$J$2:$J$801,$N4))) | K4: =IF($N4="","",IF(INDEX('Per Invoice'!$K$2:$K$801,$N4)="","",INDEX('Per Invoice'!$K$2:$K$801,$N4))) | L4: =IF($N4="","",IF(INDEX('Per Invoice'!$L$2:$L$801,$N4)="","",INDEX('Per Invoice'!$L$2:$L$801,$N4))) | M4: =IF($N4="","",IF(INDEX('Per Invoice'!$M$2:$M$801,$N4)="","",INDEX('Per Invoice'!$M$2:$M$801,$N4))) | N4: =IF(ROWS($N$2:$N4)<=COUNT('Per Invoice'!$O$2:$O$801),MATCH(ROWS($N$2:$N4),'Per Invoice'!$O$2:$O$801,0),"")
A5: =IF($N5="","",IF(INDEX('Per Invoice'!$A$2:$A$801,$N5)="","",INDEX('Per Invoice'!$A$2:$A$801,$N5))) | B5: =IF($N5="","",IF(INDEX('Per Invoice'!$B$2:$B$801,$N5)="","",INDEX('Per Invoice'!$B$2:$B$801,$N5))) | C5: =IF($N5="","",IF(INDEX('Per Invoice'!$C$2:$C$801,$N5)="","",INDEX('Per Invoice'!$C$2:$C$801,$N5))) | D5: =IF($N5="","",IF(INDEX('Per Invoice'!$D$2:$D$801,$N5)="","",INDEX('Per Invoice'!$D$2:$D$801,$N5))) | E5: =IF($N5="","",IF(INDEX('Per Invoice'!$E$2:$E$801,$N5)="","",INDEX('Per Invoice'!$E$2:$E$801,$N5))) | F5: =IF($N5="","",IF(INDEX('Per Invoice'!$F$2:$F$801,$N5)="","",INDEX('Per Invoice'!$F$2:$F$801,$N5))) | G5: =IF($N5="","",IF(INDEX('Per Invoice'!$G$2:$G$801,$N5)="","",INDEX('Per Invoice'!$G$2:$G$801,$N5))) | H5: =IF($N5="","",IF(INDEX('Per Invoice'!$H$2:$H$801,$N5)="","",INDEX('Per Invoice'!$H$2:$H$801,$N5))) | I5: =IF($N5="","",IF(INDEX('Per Invoice'!$I$2:$I$801,$N5)="","",INDEX('Per Invoice'!$I$2:$I$801,$N5))) | J5: =IF($N5="","",IF(INDEX('Per Invoice'!$J$2:$J$801,$N5)="","",INDEX('Per Invoice'!$J$2:$J$801,$N5))) | K5: =IF($N5="","",IF(INDEX('Per Invoice'!$K$2:$K$801,$N5)="","",INDEX('Per Invoice'!$K$2:$K$801,$N5))) | L5: =IF($N5="","",IF(INDEX('Per Invoice'!$L$2:$L$801,$N5)="","",INDEX('Per Invoice'!$L$2:$L$801,$N5))) | M5: =IF($N5="","",IF(INDEX('Per Invoice'!$M$2:$M$801,$N5)="","",INDEX('Per Invoice'!$M$2:$M$801,$N5))) | N5: =IF(ROWS($N$2:$N5)<=COUNT('Per Invoice'!$O$2:$O$801),MATCH(ROWS($N$2:$N5),'Per Invoice'!$O$2:$O$801,0),"")
A6: =IF($N6="","",IF(INDEX('Per Invoice'!$A$2:$A$801,$N6)="","",INDEX('Per Invoice'!$A$2:$A$801,$N6))) | B6: =IF($N6="","",IF(INDEX('Per Invoice'!$B$2:$B$801,$N6)="","",INDEX('Per Invoice'!$B$2:$B$801,$N6))) | C6: =IF($N6="","",IF(INDEX('Per Invoice'!$C$2:$C$801,$N6)="","",INDEX('Per Invoice'!$C$2:$C$801,$N6))) | D6: =IF($N6="","",IF(INDEX('Per Invoice'!$D$2:$D$801,$N6)="","",INDEX('Per Invoice'!$D$2:$D$801,$N6))) | E6: =IF($N6="","",IF(INDEX('Per Invoice'!$E$2:$E$801,$N6)="","",INDEX('Per Invoice'!$E$2:$E$801,$N6))) | F6: =IF($N6="","",IF(INDEX('Per Invoice'!$F$2:$F$801,$N6)="","",INDEX('Per Invoice'!$F$2:$F$801,$N6))) | G6: =IF($N6="","",IF(INDEX('Per Invoice'!$G$2:$G$801,$N6)="","",INDEX('Per Invoice'!$G$2:$G$801,$N6))) | H6: =IF($N6="","",IF(INDEX('Per Invoice'!$H$2:$H$801,$N6)="","",INDEX('Per Invoice'!$H$2:$H$801,$N6))) | I6: =IF($N6="","",IF(INDEX('Per Invoice'!$I$2:$I$801,$N6)="","",INDEX('Per Invoice'!$I$2:$I$801,$N6))) | J6: =IF($N6="","",IF(INDEX('Per Invoice'!$J$2:$J$801,$N6)="","",INDEX('Per Invoice'!$J$2:$J$801,$N6))) | K6: =IF($N6="","",IF(INDEX('Per Invoice'!$K$2:$K$801,$N6)="","",INDEX('Per Invoice'!$K$2:$K$801,$N6))) | L6: =IF($N6="","",IF(INDEX('Per Invoice'!$L$2:$L$801,$N6)="","",INDEX('Per Invoice'!$L$2:$L$801,$N6))) | M6: =IF($N6="","",IF(INDEX('Per Invoice'!$M$2:$M$801,$N6)="","",INDEX('Per Invoice'!$M$2:$M$801,$N6))) | N6: =IF(ROWS($N$2:$N6)<=COUNT('Per Invoice'!$O$2:$O$801),MATCH(ROWS($N$2:$N6),'Per Invoice'!$O$2:$O$801,0),"")
A7: =IF($N7="","",IF(INDEX('Per Invoice'!$A$2:$A$801,$N7)="","",INDEX('Per Invoice'!$A$2:$A$801,$N7))) | B7: =IF($N7="","",IF(INDEX('Per Invoice'!$B$2:$B$801,$N7)="","",INDEX('Per Invoice'!$B$2:$B$801,$N7))) | C7: =IF($N7="","",IF(INDEX('Per Invoice'!$C$2:$C$801,$N7)="","",INDEX('Per Invoice'!$C$2:$C$801,$N7))) | D7: =IF($N7="","",IF(INDEX('Per Invoice'!$D$2:$D$801,$N7)="","",INDEX('Per Invoice'!$D$2:$D$801,$N7))) | E7: =IF($N7="","",IF(INDEX('Per Invoice'!$E$2:$E$801,$N7)="","",INDEX('Per Invoice'!$E$2:$E$801,$N7))) | F7: =IF($N7="","",IF(INDEX('Per Invoice'!$F$2:$F$801,$N7)="","",INDEX('Per Invoice'!$F$2:$F$801,$N7))) | G7: =IF($N7="","",IF(INDEX('Per Invoice'!$G$2:$G$801,$N7)="","",INDEX('Per Invoice'!$G$2:$G$801,$N7))) | H7: =IF($N7="","",IF(INDEX('Per Invoice'!$H$2:$H$801,$N7)="","",INDEX('Per Invoice'!$H$2:$H$801,$N7))) | I7: =IF($N7="","",IF(INDEX('Per Invoice'!$I$2:$I$801,$N7)="","",INDEX('Per Invoice'!$I$2:$I$801,$N7))) | J7: =IF($N7="","",IF(INDEX('Per Invoice'!$J$2:$J$801,$N7)="","",INDEX('Per Invoice'!$J$2:$J$801,$N7))) | K7: =IF($N7="","",IF(INDEX('Per Invoice'!$K$2:$K$801,$N7)="","",INDEX('Per Invoice'!$K$2:$K$801,$N7))) | L7: =IF($N7="","",IF(INDEX('Per Invoice'!$L$2:$L$801,$N7)="","",INDEX('Per Invoice'!$L$2:$L$801,$N7))) | M7: =IF($N7="","",IF(INDEX('Per Invoice'!$M$2:$M$801,$N7)="","",INDEX('Per Invoice'!$M$2:$M$801,$N7))) | N7: =IF(ROWS($N$2:$N7)<=COUNT('Per Invoice'!$O$2:$O$801),MATCH(ROWS($N$2:$N7),'Per Invoice'!$O$2:$O$801,0),"")
A8: =IF($N8="","",IF(INDEX('Per Invoice'!$A$2:$A$801,$N8)="","",INDEX('Per Invoice'!$A$2:$A$801,$N8))) | B8: =IF($N8="","",IF(INDEX('Per Invoice'!$B$2:$B$801,$N8)="","",INDEX('Per Invoice'!$B$2:$B$801,$N8))) | C8: =IF($N8="","",IF(INDEX('Per Invoice'!$C$2:$C$801,$N8)="","",INDEX('Per Invoice'!$C$2:$C$801,$N8))) | D8: =IF($N8="","",IF(INDEX('Per Invoice'!$D$2:$D$801,$N8)="","",INDEX('Per Invoice'!$D$2:$D$801,$N8))) | E8: =IF($N8="","",IF(INDEX('Per Invoice'!$E$2:$E$801,$N8)="","",INDEX('Per Invoice'!$E$2:$E$801,$N8))) | F8: =IF($N8="","",IF(INDEX('Per Invoice'!$F$2:$F$801,$N8)="","",INDEX('Per Invoice'!$F$2:$F$801,$N8))) | G8: =IF($N8="","",IF(INDEX('Per Invoice'!$G$2:$G$801,$N8)="","",INDEX('Per Invoice'!$G$2:$G$801,$N8))) | H8: =IF($N8="","",IF(INDEX('Per Invoice'!$H$2:$H$801,$N8)="","",INDEX('Per Invoice'!$H$2:$H$801,$N8))) | I8: =IF($N8="","",IF(INDEX('Per Invoice'!$I$2:$I$801,$N8)="","",INDEX('Per Invoice'!$I$2:$I$801,$N8))) | J8: =IF($N8="","",IF(INDEX('Per Invoice'!$J$2:$J$801,$N8)="","",INDEX('Per Invoice'!$J$2:$J$801,$N8))) | K8: =IF($N8="","",IF(INDEX('Per Invoice'!$K$2:$K$801,$N8)="","",INDEX('Per Invoice'!$K$2:$K$801,$N8))) | L8: =IF($N8="","",IF(INDEX('Per Invoice'!$L$2:$L$801,$N8)="","",INDEX('Per Invoice'!$L$2:$L$801,$N8))) | M8: =IF($N8="","",IF(INDEX('Per Invoice'!$M$2:$M$801,$N8)="","",INDEX('Per Invoice'!$M$2:$M$801,$N8))) | N8: =IF(ROWS($N$2:$N8)<=COUNT('Per Invoice'!$O$2:$O$801),MATCH(ROWS($N$2:$N8),'Per Invoice'!$O$2:$O$801,0),"")
A9: =IF($N9="","",IF(INDEX('Per Invoice'!$A$2:$A$801,$N9)="","",INDEX('Per Invoice'!$A$2:$A$801,$N9))) | B9: =IF($N9="","",IF(INDEX('Per Invoice'!$B$2:$B$801,$N9)="","",INDEX('Per Invoice'!$B$2:$B$801,$N9))) | C9: =IF($N9="","",IF(INDEX('Per Invoice'!$C$2:$C$801,$N9)="","",INDEX('Per Invoice'!$C$2:$C$801,$N9))) | D9: =IF($N9="","",IF(INDEX('Per Invoice'!$D$2:$D$801,$N9)="","",INDEX('Per Invoice'!$D$2:$D$801,$N9))) | E9: =IF($N9="","",IF(INDEX('Per Invoice'!$E$2:$E$801,$N9)="","",INDEX('Per Invoice'!$E$2:$E$801,$N9))) | F9: =IF($N9="","",IF(INDEX('Per Invoice'!$F$2:$F$801,$N9)="","",INDEX('Per Invoice'!$F$2:$F$801,$N9))) | G9: =IF($N9="","",IF(INDEX('Per Invoice'!$G$2:$G$801,$N9)="","",INDEX('Per Invoice'!$G$2:$G$801,$N9))) | H9: =IF($N9="","",IF(INDEX('Per Invoice'!$H$2:$H$801,$N9)="","",INDEX('Per Invoice'!$H$2:$H$801,$N9))) | I9: =IF($N9="","",IF(INDEX('Per Invoice'!$I$2:$I$801,$N9)="","",INDEX('Per Invoice'!$I$2:$I$801,$N9))) | J9: =IF($N9="","",IF(INDEX('Per Invoice'!$J$2:$J$801,$N9)="","",INDEX('Per Invoice'!$J$2:$J$801,$N9))) | K9: =IF($N9="","",IF(INDEX('Per Invoice'!$K$2:$K$801,$N9)="","",INDEX('Per Invoice'!$K$2:$K$801,$N9))) | L9: =IF($N9="","",IF(INDEX('Per Invoice'!$L$2:$L$801,$N9)="","",INDEX('Per Invoice'!$L$2:$L$801,$N9))) | M9: =IF($N9="","",IF(INDEX('Per Invoice'!$M$2:$M$801,$N9)="","",INDEX('Per Invoice'!$M$2:$M$801,$N9))) | N9: =IF(ROWS($N$2:$N9)<=COUNT('Per Invoice'!$O$2:$O$801),MATCH(ROWS($N$2:$N9),'Per Invoice'!$O$2:$O$801,0),"")
A10: =IF($N10="","",IF(INDEX('Per Invoice'!$A$2:$A$801,$N10)="","",INDEX('Per Invoice'!$A$2:$A$801,$N10))) | B10: =IF($N10="","",IF(INDEX('Per Invoice'!$B$2:$B$801,$N10)="","",INDEX('Per Invoice'!$B$2:$B$801,$N10))) | C10: =IF($N10="","",IF(INDEX('Per Invoice'!$C$2:$C$801,$N10)="","",INDEX('Per Invoice'!$C$2:$C$801,$N10))) | D10: =IF($N10="","",IF(INDEX('Per Invoice'!$D$2:$D$801,$N10)="","",INDEX('Per Invoice'!$D$2:$D$801,$N10))) | E10: =IF($N10="","",IF(INDEX('Per Invoice'!$E$2:$E$801,$N10)="","",INDEX('Per Invoice'!$E$2:$E$801,$N10))) | F10: =IF($N10="","",IF(INDEX('Per Invoice'!$F$2:$F$801,$N10)="","",INDEX('Per Invoice'!$F$2:$F$801,$N10))) | G10: =IF($N10="","",IF(INDEX('Per Invoice'!$G$2:$G$801,$N10)="","",INDEX('Per Invoice'!$G$2:$G$801,$N10))) | H10: =IF($N10="","",IF(INDEX('Per Invoice'!$H$2:$H$801,$N10)="","",INDEX('Per Invoice'!$H$2:$H$801,$N10))) | I10: =IF($N10="","",IF(INDEX('Per Invoice'!$I$2:$I$801,$N10)="","",INDEX('Per Invoice'!$I$2:$I$801,$N10))) | J10: =IF($N10="","",IF(INDEX('Per Invoice'!$J$2:$J$801,$N10)="","",INDEX('Per Invoice'!$J$2:$J$801,$N10))) | K10: =IF($N10="","",IF(INDEX('Per Invoice'!$K$2:$K$801,$N10)="","",INDEX('Per Invoice'!$K$2:$K$801,$N10))) | L10: =IF($N10="","",IF(INDEX('Per Invoice'!$L$2:$L$801,$N10)="","",INDEX('Per Invoice'!$L$2:$L$801,$N10))) | M10: =IF($N10="","",IF(INDEX('Per Invoice'!$M$2:$M$801,$N10)="","",INDEX('Per Invoice'!$M$2:$M$801,$N10))) | N10: =IF(ROWS($N$2:$N10)<=COUNT('Per Invoice'!$O$2:$O$801),MATCH(ROWS($N$2:$N10),'Per Invoice'!$O$2:$O$801,0),"")
A11: =IF($N11="","",IF(INDEX('Per Invoice'!$A$2:$A$801,$N11)="","",INDEX('Per Invoice'!$A$2:$A$801,$N11))) | B11: =IF($N11="","",IF(INDEX('Per Invoice'!$B$2:$B$801,$N11)="","",INDEX('Per Invoice'!$B$2:$B$801,$N11))) | C11: =IF($N11="","",IF(INDEX('Per Invoice'!$C$2:$C$801,$N11)="","",INDEX('Per Invoice'!$C$2:$C$801,$N11))) | D11: =IF($N11="","",IF(INDEX('Per Invoice'!$D$2:$D$801,$N11)="","",INDEX('Per Invoice'!$D$2:$D$801,$N11))) | E11: =IF($N11="","",IF(INDEX('Per Invoice'!$E$2:$E$801,$N11)="","",INDEX('Per Invoice'!$E$2:$E$801,$N11))) | F11: =IF($N11="","",IF(INDEX('Per Invoice'!$F$2:$F$801,$N11)="","",INDEX('Per Invoice'!$F$2:$F$801,$N11))) | G11: =IF($N11="","",IF(INDEX('Per Invoice'!$G$2:$G$801,$N11)="","",INDEX('Per Invoice'!$G$2:$G$801,$N11))) | H11: =IF($N11="","",IF(INDEX('Per Invoice'!$H$2:$H$801,$N11)="","",INDEX('Per Invoice'!$H$2:$H$801,$N11))) | I11: =IF($N11="","",IF(INDEX('Per Invoice'!$I$2:$I$801,$N11)="","",INDEX('Per Invoice'!$I$2:$I$801,$N11))) | J11: =IF($N11="","",IF(INDEX('Per Invoice'!$J$2:$J$801,$N11)="","",INDEX('Per Invoice'!$J$2:$J$801,$N11))) | K11: =IF($N11="","",IF(INDEX('Per Invoice'!$K$2:$K$801,$N11)="","",INDEX('Per Invoice'!$K$2:$K$801,$N11))) | L11: =IF($N11="","",IF(INDEX('Per Invoice'!$L$2:$L$801,$N11)="","",INDEX('Per Invoice'!$L$2:$L$801,$N11))) | M11: =IF($N11="","",IF(INDEX('Per Invoice'!$M$2:$M$801,$N11)="","",INDEX('Per Invoice'!$M$2:$M$801,$N11))) | N11: =IF(ROWS($N$2:$N11)<=COUNT('Per Invoice'!$O$2:$O$801),MATCH(ROWS($N$2:$N11),'Per Invoice'!$O$2:$O$801,0),"")
A12: =IF($N12="","",IF(INDEX('Per Invoice'!$A$2:$A$801,$N12)="","",INDEX('Per Invoice'!$A$2:$A$801,$N12))) | B12: =IF($N12="","",IF(INDEX('Per Invoice'!$B$2:$B$801,$N12)="","",INDEX('Per Invoice'!$B$2:$B$801,$N12))) | C12: =IF($N12="","",IF(INDEX('Per Invoice'!$C$2:$C$801,$N12)="","",INDEX('Per Invoice'!$C$2:$C$801,$N12))) | D12: =IF($N12="","",IF(INDEX('Per Invoice'!$D$2:$D$801,$N12)="","",INDEX('Per Invoice'!$D$2:$D$801,$N12))) | E12: =IF($N12="","",IF(INDEX('Per Invoice'!$E$2:$E$801,$N12)="","",INDEX('Per Invoice'!$E$2:$E$801,$N12))) | F12: =IF($N12="","",IF(INDEX('Per Invoice'!$F$2:$F$801,$N12)="","",INDEX('Per Invoice'!$F$2:$F$801,$N12))) | G12: =IF($N12="","",IF(INDEX('Per Invoice'!$G$2:$G$801,$N12)="","",INDEX('Per Invoice'!$G$2:$G$801,$N12))) | H12: =IF($N12="","",IF(INDEX('Per Invoice'!$H$2:$H$801,$N12)="","",INDEX('Per Invoice'!$H$2:$H$801,$N12))) | I12: =IF($N12="","",IF(INDEX('Per Invoice'!$I$2:$I$801,$N12)="","",INDEX('Per Invoice'!$I$2:$I$801,$N12))) | J12: =IF($N12="","",IF(INDEX('Per Invoice'!$J$2:$J$801,$N12)="","",INDEX('Per Invoice'!$J$2:$J$801,$N12))) | K12: =IF($N12="","",IF(INDEX('Per Invoice'!$K$2:$K$801,$N12)="","",INDEX('Per Invoice'!$K$2:$K$801,$N12))) | L12: =IF($N12="","",IF(INDEX('Per Invoice'!$L$2:$L$801,$N12)="","",INDEX('Per Invoice'!$L$2:$L$801,$N12))) | M12: =IF($N12="","",IF(INDEX('Per Invoice'!$M$2:$M$801,$N12)="","",INDEX('Per Invoice'!$M$2:$M$801,$N12))) | N12: =IF(ROWS($N$2:$N12)<=COUNT('Per Invoice'!$O$2:$O$801),MATCH(ROWS($N$2:$N12),'Per Invoice'!$O$2:$O$801,0),"")
A13: =IF($N13="","",IF(INDEX('Per Invoice'!$A$2:$A$801,$N13)="","",INDEX('Per Invoice'!$A$2:$A$801,$N13))) | B13: =IF($N13="","",IF(INDEX('Per Invoice'!$B$2:$B$801,$N13)="","",INDEX('Per Invoice'!$B$2:$B$801,$N13))) | C13: =IF($N13="","",IF(INDEX('Per Invoice'!$C$2:$C$801,$N13)="","",INDEX('Per Invoice'!$C$2:$C$801,$N13))) | D13: =IF($N13="","",IF(INDEX('Per Invoice'!$D$2:$D$801,$N13)="","",INDEX('Per Invoice'!$D$2:$D$801,$N13))) | E13: =IF($N13="","",IF(INDEX('Per Invoice'!$E$2:$E$801,$N13)="","",INDEX('Per Invoice'!$E$2:$E$801,$N13))) | F13: =IF($N13="","",IF(INDEX('Per Invoice'!$F$2:$F$801,$N13)="","",INDEX('Per Invoice'!$F$2:$F$801,$N13))) | G13: =IF($N13="","",IF(INDEX('Per Invoice'!$G$2:$G$801,$N13)="","",INDEX('Per Invoice'!$G$2:$G$801,$N13))) | H13: =IF($N13="","",IF(INDEX('Per Invoice'!$H$2:$H$801,$N13)="","",INDEX('Per Invoice'!$H$2:$H$801,$N13))) | I13: =IF($N13="","",IF(INDEX('Per Invoice'!$I$2:$I$801,$N13)="","",INDEX('Per Invoice'!$I$2:$I$801,$N13))) | J13: =IF($N13="","",IF(INDEX('Per Invoice'!$J$2:$J$801,$N13)="","",INDEX('Per Invoice'!$J$2:$J$801,$N13))) | K13: =IF($N13="","",IF(INDEX('Per Invoice'!$K$2:$K$801,$N13)="","",INDEX('Per Invoice'!$K$2:$K$801,$N13))) | L13: =IF($N13="","",IF(INDEX('Per Invoice'!$L$2:$L$801,$N13)="","",INDEX('Per Invoice'!$L$2:$L$801,$N13))) | M13: =IF($N13="","",IF(INDEX('Per Invoice'!$M$2:$M$801,$N13)="","",INDEX('Per Invoice'!$M$2:$M$801,$N13))) | N13: =IF(ROWS($N$2:$N13)<=COUNT('Per Invoice'!$O$2:$O$801),MATCH(ROWS($N$2:$N13),'Per Invoice'!$O$2:$O$801,0),"")
... A801: =IF($N801="","",IF(INDEX('Per Invoice'!$A$2:$A$801,$N801)="","",INDEX('Per Invoice'!$A$2:$A$801,$N801))) | B801: =IF($N801="","",IF(INDEX('Per Invoice'!$B$2:$B$801,$N801)="","",INDEX('Per Invoice'!$B$2:$B$801,$N801))) | C801: =IF($N801="","",IF(INDEX('Per Invoice'!$C$2:$C$801,$N801)="","",INDEX('Per Invoice'!$C$2:$C$801,$N801))) | D801: =IF($N801="","",IF(INDEX('Per Invoice'!$D$2:$D$801,$N801)="","",INDEX('Per Invoice'!$D$2:$D$801,$N801))) | E801: =IF($N801="","",IF(INDEX('Per Invoice'!$E$2:$E$801,$N801)="","",INDEX('Per Invoice'!$E$2:$E$801,$N801))) | F801: =IF($N801="","",IF(INDEX('Per Invoice'!$F$2:$F$801,$N801)="","",INDEX('Per Invoice'!$F$2:$F$801,$N801))) | G801: =IF($N801="","",IF(INDEX('Per Invoice'!$G$2:$G$801,$N801)="","",INDEX('Per Invoice'!$G$2:$G$801,$N801))) | H801: =IF($N801="","",IF(INDEX('Per Invoice'!$H$2:$H$801,$N801)="","",INDEX('Per Invoice'!$H$2:$H$801,$N801))) | I801: =IF($N801="","",IF(INDEX('Per Invoice'!$I$2:$I$801,$N801)="","",INDEX('Per Invoice'!$I$2:$I$801,$N801))) | J801: =IF($N801="","",IF(INDEX('Per Invoice'!$J$2:$J$801,$N801)="","",INDEX('Per Invoice'!$J$2:$J$801,$N801))) | K801: =IF($N801="","",IF(INDEX('Per Invoice'!$K$2:$K$801,$N801)="","",INDEX('Per Invoice'!$K$2:$K$801,$N801))) | L801: =IF($N801="","",IF(INDEX('Per Invoice'!$L$2:$L$801,$N801)="","",INDEX('Per Invoice'!$L$2:$L$801,$N801))) | M801: =IF($N801="","",IF(INDEX('Per Invoice'!$M$2:$M$801,$N801)="","",INDEX('Per Invoice'!$M$2:$M$801,$N801))) | N801: =IF(ROWS($N$2:$N801)<=COUNT('Per Invoice'!$O$2:$O$801),MATCH(ROWS($N$2:$N801),'Per Invoice'!$O$2:$O$801,0),"")

Sheet Per Invoice Below Claim Form
A1: Invoice | B1: Seg | C1: So | D1: SSNBR | E1: Lot | F1: ERX | G1: Card | H1: Svc Date | I1: Sum of Total Approved | J1: Sum of dis | K1: Sum of Paid Amount | L1: Sum of Subtotal | M1: Sum of Net Amt | N1: Per Invoice Row (helper)
A2: =IF($N2="","",IF(INDEX('Per Invoice'!$A$2:$A$801,$N2)="","",INDEX('Per Invoice'!$A$2:$A$801,$N2))) | B2: =IF($N2="","",IF(INDEX('Per Invoice'!$B$2:$B$801,$N2)="","",INDEX('Per Invoice'!$B$2:$B$801,$N2))) | C2: =IF($N2="","",IF(INDEX('Per Invoice'!$C$2:$C$801,$N2)="","",INDEX('Per Invoice'!$C$2:$C$801,$N2))) | D2: =IF($N2="","",IF(INDEX('Per Invoice'!$D$2:$D$801,$N2)="","",INDEX('Per Invoice'!$D$2:$D$801,$N2))) | E2: =IF($N2="","",IF(INDEX('Per Invoice'!$E$2:$E$801,$N2)="","",INDEX('Per Invoice'!$E$2:$E$801,$N2))) | F2: =IF($N2="","",IF(INDEX('Per Invoice'!$F$2:$F$801,$N2)="","",INDEX('Per Invoice'!$F$2:$F$801,$N2))) | G2: =IF($N2="","",IF(INDEX('Per Invoice'!$G$2:$G$801,$N2)="","",INDEX('Per Invoice'!$G$2:$G$801,$N2))) | H2: =IF($N2="","",IF(INDEX('Per Invoice'!$H$2:$H$801,$N2)="","",INDEX('Per Invoice'!$H$2:$H$801,$N2))) | I2: =IF($N2="","",IF(INDEX('Per Invoice'!$I$2:$I$801,$N2)="","",INDEX('Per Invoice'!$I$2:$I$801,$N2))) | J2: =IF($N2="","",IF(INDEX('Per Invoice'!$J$2:$J$801,$N2)="","",INDEX('Per Invoice'!$J$2:$J$801,$N2))) | K2: =IF($N2="","",IF(INDEX('Per Invoice'!$K$2:$K$801,$N2)="","",INDEX('Per Invoice'!$K$2:$K$801,$N2))) | L2: =IF($N2="","",IF(INDEX('Per Invoice'!$L$2:$L$801,$N2)="","",INDEX('Per Invoice'!$L$2:$L$801,$N2))) | M2: =IF($N2="","",IF(INDEX('Per Invoice'!$M$2:$M$801,$N2)="","",INDEX('Per Invoice'!$M$2:$M$801,$N2))) | N2: =IF(ROWS($N$2:$N2)<=COUNT('Per Invoice'!$P$2:$P$801),MATCH(ROWS($N$2:$N2),'Per Invoice'!$P$2:$P$801,0),"")
A3: =IF($N3="","",IF(INDEX('Per Invoice'!$A$2:$A$801,$N3)="","",INDEX('Per Invoice'!$A$2:$A$801,$N3))) | B3: =IF($N3="","",IF(INDEX('Per Invoice'!$B$2:$B$801,$N3)="","",INDEX('Per Invoice'!$B$2:$B$801,$N3))) | C3: =IF($N3="","",IF(INDEX('Per Invoice'!$C$2:$C$801,$N3)="","",INDEX('Per Invoice'!$C$2:$C$801,$N3))) | D3: =IF($N3="","",IF(INDEX('Per Invoice'!$D$2:$D$801,$N3)="","",INDEX('Per Invoice'!$D$2:$D$801,$N3))) | E3: =IF($N3="","",IF(INDEX('Per Invoice'!$E$2:$E$801,$N3)="","",INDEX('Per Invoice'!$E$2:$E$801,$N3))) | F3: =IF($N3="","",IF(INDEX('Per Invoice'!$F$2:$F$801,$N3)="","",INDEX('Per Invoice'!$F$2:$F$801,$N3))) | G3: =IF($N3="","",IF(INDEX('Per Invoice'!$G$2:$G$801,$N3)="","",INDEX('Per Invoice'!$G$2:$G$801,$N3))) | H3: =IF($N3="","",IF(INDEX('Per Invoice'!$H$2:$H$801,$N3)="","",INDEX('Per Invoice'!$H$2:$H$801,$N3))) | I3: =IF($N3="","",IF(INDEX('Per Invoice'!$I$2:$I$801,$N3)="","",INDEX('Per Invoice'!$I$2:$I$801,$N3))) | J3: =IF($N3="","",IF(INDEX('Per Invoice'!$J$2:$J$801,$N3)="","",INDEX('Per Invoice'!$J$2:$J$801,$N3))) | K3: =IF($N3="","",IF(INDEX('Per Invoice'!$K$2:$K$801,$N3)="","",INDEX('Per Invoice'!$K$2:$K$801,$N3))) | L3: =IF($N3="","",IF(INDEX('Per Invoice'!$L$2:$L$801,$N3)="","",INDEX('Per Invoice'!$L$2:$L$801,$N3))) | M3: =IF($N3="","",IF(INDEX('Per Invoice'!$M$2:$M$801,$N3)="","",INDEX('Per Invoice'!$M$2:$M$801,$N3))) | N3: =IF(ROWS($N$2:$N3)<=COUNT('Per Invoice'!$P$2:$P$801),MATCH(ROWS($N$2:$N3),'Per Invoice'!$P$2:$P$801,0),"")
A4: =IF($N4="","",IF(INDEX('Per Invoice'!$A$2:$A$801,$N4)="","",INDEX('Per Invoice'!$A$2:$A$801,$N4))) | B4: =IF($N4="","",IF(INDEX('Per Invoice'!$B$2:$B$801,$N4)="","",INDEX('Per Invoice'!$B$2:$B$801,$N4))) | C4: =IF($N4="","",IF(INDEX('Per Invoice'!$C$2:$C$801,$N4)="","",INDEX('Per Invoice'!$C$2:$C$801,$N4))) | D4: =IF($N4="","",IF(INDEX('Per Invoice'!$D$2:$D$801,$N4)="","",INDEX('Per Invoice'!$D$2:$D$801,$N4))) | E4: =IF($N4="","",IF(INDEX('Per Invoice'!$E$2:$E$801,$N4)="","",INDEX('Per Invoice'!$E$2:$E$801,$N4))) | F4: =IF($N4="","",IF(INDEX('Per Invoice'!$F$2:$F$801,$N4)="","",INDEX('Per Invoice'!$F$2:$F$801,$N4))) | G4: =IF($N4="","",IF(INDEX('Per Invoice'!$G$2:$G$801,$N4)="","",INDEX('Per Invoice'!$G$2:$G$801,$N4))) | H4: =IF($N4="","",IF(INDEX('Per Invoice'!$H$2:$H$801,$N4)="","",INDEX('Per Invoice'!$H$2:$H$801,$N4))) | I4: =IF($N4="","",IF(INDEX('Per Invoice'!$I$2:$I$801,$N4)="","",INDEX('Per Invoice'!$I$2:$I$801,$N4))) | J4: =IF($N4="","",IF(INDEX('Per Invoice'!$J$2:$J$801,$N4)="","",INDEX('Per Invoice'!$J$2:$J$801,$N4))) | K4: =IF($N4="","",IF(INDEX('Per Invoice'!$K$2:$K$801,$N4)="","",INDEX('Per Invoice'!$K$2:$K$801,$N4))) | L4: =IF($N4="","",IF(INDEX('Per Invoice'!$L$2:$L$801,$N4)="","",INDEX('Per Invoice'!$L$2:$L$801,$N4))) | M4: =IF($N4="","",IF(INDEX('Per Invoice'!$M$2:$M$801,$N4)="","",INDEX('Per Invoice'!$M$2:$M$801,$N4))) | N4: =IF(ROWS($N$2:$N4)<=COUNT('Per Invoice'!$P$2:$P$801),MATCH(ROWS($N$2:$N4),'Per Invoice'!$P$2:$P$801,0),"")
A5: =IF($N5="","",IF(INDEX('Per Invoice'!$A$2:$A$801,$N5)="","",INDEX('Per Invoice'!$A$2:$A$801,$N5))) | B5: =IF($N5="","",IF(INDEX('Per Invoice'!$B$2:$B$801,$N5)="","",INDEX('Per Invoice'!$B$2:$B$801,$N5))) | C5: =IF($N5="","",IF(INDEX('Per Invoice'!$C$2:$C$801,$N5)="","",INDEX('Per Invoice'!$C$2:$C$801,$N5))) | D5: =IF($N5="","",IF(INDEX('Per Invoice'!$D$2:$D$801,$N5)="","",INDEX('Per Invoice'!$D$2:$D$801,$N5))) | E5: =IF($N5="","",IF(INDEX('Per Invoice'!$E$2:$E$801,$N5)="","",INDEX('Per Invoice'!$E$2:$E$801,$N5))) | F5: =IF($N5="","",IF(INDEX('Per Invoice'!$F$2:$F$801,$N5)="","",INDEX('Per Invoice'!$F$2:$F$801,$N5))) | G5: =IF($N5="","",IF(INDEX('Per Invoice'!$G$2:$G$801,$N5)="","",INDEX('Per Invoice'!$G$2:$G$801,$N5))) | H5: =IF($N5="","",IF(INDEX('Per Invoice'!$H$2:$H$801,$N5)="","",INDEX('Per Invoice'!$H$2:$H$801,$N5))) | I5: =IF($N5="","",IF(INDEX('Per Invoice'!$I$2:$I$801,$N5)="","",INDEX('Per Invoice'!$I$2:$I$801,$N5))) | J5: =IF($N5="","",IF(INDEX('Per Invoice'!$J$2:$J$801,$N5)="","",INDEX('Per Invoice'!$J$2:$J$801,$N5))) | K5: =IF($N5="","",IF(INDEX('Per Invoice'!$K$2:$K$801,$N5)="","",INDEX('Per Invoice'!$K$2:$K$801,$N5))) | L5: =IF($N5="","",IF(INDEX('Per Invoice'!$L$2:$L$801,$N5)="","",INDEX('Per Invoice'!$L$2:$L$801,$N5))) | M5: =IF($N5="","",IF(INDEX('Per Invoice'!$M$2:$M$801,$N5)="","",INDEX('Per Invoice'!$M$2:$M$801,$N5))) | N5: =IF(ROWS($N$2:$N5)<=COUNT('Per Invoice'!$P$2:$P$801),MATCH(ROWS($N$2:$N5),'Per Invoice'!$P$2:$P$801,0),"")
A6: =IF($N6="","",IF(INDEX('Per Invoice'!$A$2:$A$801,$N6)="","",INDEX('Per Invoice'!$A$2:$A$801,$N6))) | B6: =IF($N6="","",IF(INDEX('Per Invoice'!$B$2:$B$801,$N6)="","",INDEX('Per Invoice'!$B$2:$B$801,$N6))) | C6: =IF($N6="","",IF(INDEX('Per Invoice'!$C$2:$C$801,$N6)="","",INDEX('Per Invoice'!$C$2:$C$801,$N6))) | D6: =IF($N6="","",IF(INDEX('Per Invoice'!$D$2:$D$801,$N6)="","",INDEX('Per Invoice'!$D$2:$D$801,$N6))) | E6: =IF($N6="","",IF(INDEX('Per Invoice'!$E$2:$E$801,$N6)="","",INDEX('Per Invoice'!$E$2:$E$801,$N6))) | F6: =IF($N6="","",IF(INDEX('Per Invoice'!$F$2:$F$801,$N6)="","",INDEX('Per Invoice'!$F$2:$F$801,$N6))) | G6: =IF($N6="","",IF(INDEX('Per Invoice'!$G$2:$G$801,$N6)="","",INDEX('Per Invoice'!$G$2:$G$801,$N6))) | H6: =IF($N6="","",IF(INDEX('Per Invoice'!$H$2:$H$801,$N6)="","",INDEX('Per Invoice'!$H$2:$H$801,$N6))) | I6: =IF($N6="","",IF(INDEX('Per Invoice'!$I$2:$I$801,$N6)="","",INDEX('Per Invoice'!$I$2:$I$801,$N6))) | J6: =IF($N6="","",IF(INDEX('Per Invoice'!$J$2:$J$801,$N6)="","",INDEX('Per Invoice'!$J$2:$J$801,$N6))) | K6: =IF($N6="","",IF(INDEX('Per Invoice'!$K$2:$K$801,$N6)="","",INDEX('Per Invoice'!$K$2:$K$801,$N6))) | L6: =IF($N6="","",IF(INDEX('Per Invoice'!$L$2:$L$801,$N6)="","",INDEX('Per Invoice'!$L$2:$L$801,$N6))) | M6: =IF($N6="","",IF(INDEX('Per Invoice'!$M$2:$M$801,$N6)="","",INDEX('Per Invoice'!$M$2:$M$801,$N6))) | N6: =IF(ROWS($N$2:$N6)<=COUNT('Per Invoice'!$P$2:$P$801),MATCH(ROWS($N$2:$N6),'Per Invoice'!$P$2:$P$801,0),"")
A7: =IF($N7="","",IF(INDEX('Per Invoice'!$A$2:$A$801,$N7)="","",INDEX('Per Invoice'!$A$2:$A$801,$N7))) | B7: =IF($N7="","",IF(INDEX('Per Invoice'!$B$2:$B$801,$N7)="","",INDEX('Per Invoice'!$B$2:$B$801,$N7))) | C7: =IF($N7="","",IF(INDEX('Per Invoice'!$C$2:$C$801,$N7)="","",INDEX('Per Invoice'!$C$2:$C$801,$N7))) | D7: =IF($N7="","",IF(INDEX('Per Invoice'!$D$2:$D$801,$N7)="","",INDEX('Per Invoice'!$D$2:$D$801,$N7))) | E7: =IF($N7="","",IF(INDEX('Per Invoice'!$E$2:$E$801,$N7)="","",INDEX('Per Invoice'!$E$2:$E$801,$N7))) | F7: =IF($N7="","",IF(INDEX('Per Invoice'!$F$2:$F$801,$N7)="","",INDEX('Per Invoice'!$F$2:$F$801,$N7))) | G7: =IF($N7="","",IF(INDEX('Per Invoice'!$G$2:$G$801,$N7)="","",INDEX('Per Invoice'!$G$2:$G$801,$N7))) | H7: =IF($N7="","",IF(INDEX('Per Invoice'!$H$2:$H$801,$N7)="","",INDEX('Per Invoice'!$H$2:$H$801,$N7))) | I7: =IF($N7="","",IF(INDEX('Per Invoice'!$I$2:$I$801,$N7)="","",INDEX('Per Invoice'!$I$2:$I$801,$N7))) | J7: =IF($N7="","",IF(INDEX('Per Invoice'!$J$2:$J$801,$N7)="","",INDEX('Per Invoice'!$J$2:$J$801,$N7))) | K7: =IF($N7="","",IF(INDEX('Per Invoice'!$K$2:$K$801,$N7)="","",INDEX('Per Invoice'!$K$2:$K$801,$N7))) | L7: =IF($N7="","",IF(INDEX('Per Invoice'!$L$2:$L$801,$N7)="","",INDEX('Per Invoice'!$L$2:$L$801,$N7))) | M7: =IF($N7="","",IF(INDEX('Per Invoice'!$M$2:$M$801,$N7)="","",INDEX('Per Invoice'!$M$2:$M$801,$N7))) | N7: =IF(ROWS($N$2:$N7)<=COUNT('Per Invoice'!$P$2:$P$801),MATCH(ROWS($N$2:$N7),'Per Invoice'!$P$2:$P$801,0),"")
A8: =IF($N8="","",IF(INDEX('Per Invoice'!$A$2:$A$801,$N8)="","",INDEX('Per Invoice'!$A$2:$A$801,$N8))) | B8: =IF($N8="","",IF(INDEX('Per Invoice'!$B$2:$B$801,$N8)="","",INDEX('Per Invoice'!$B$2:$B$801,$N8))) | C8: =IF($N8="","",IF(INDEX('Per Invoice'!$C$2:$C$801,$N8)="","",INDEX('Per Invoice'!$C$2:$C$801,$N8))) | D8: =IF($N8="","",IF(INDEX('Per Invoice'!$D$2:$D$801,$N8)="","",INDEX('Per Invoice'!$D$2:$D$801,$N8))) | E8: =IF($N8="","",IF(INDEX('Per Invoice'!$E$2:$E$801,$N8)="","",INDEX('Per Invoice'!$E$2:$E$801,$N8))) | F8: =IF($N8="","",IF(INDEX('Per Invoice'!$F$2:$F$801,$N8)="","",INDEX('Per Invoice'!$F$2:$F$801,$N8))) | G8: =IF($N8="","",IF(INDEX('Per Invoice'!$G$2:$G$801,$N8)="","",INDEX('Per Invoice'!$G$2:$G$801,$N8))) | H8: =IF($N8="","",IF(INDEX('Per Invoice'!$H$2:$H$801,$N8)="","",INDEX('Per Invoice'!$H$2:$H$801,$N8))) | I8: =IF($N8="","",IF(INDEX('Per Invoice'!$I$2:$I$801,$N8)="","",INDEX('Per Invoice'!$I$2:$I$801,$N8))) | J8: =IF($N8="","",IF(INDEX('Per Invoice'!$J$2:$J$801,$N8)="","",INDEX('Per Invoice'!$J$2:$J$801,$N8))) | K8: =IF($N8="","",IF(INDEX('Per Invoice'!$K$2:$K$801,$N8)="","",INDEX('Per Invoice'!$K$2:$K$801,$N8))) | L8: =IF($N8="","",IF(INDEX('Per Invoice'!$L$2:$L$801,$N8)="","",INDEX('Per Invoice'!$L$2:$L$801,$N8))) | M8: =IF($N8="","",IF(INDEX('Per Invoice'!$M$2:$M$801,$N8)="","",INDEX('Per Invoice'!$M$2:$M$801,$N8))) | N8: =IF(ROWS($N$2:$N8)<=COUNT('Per Invoice'!$P$2:$P$801),MATCH(ROWS($N$2:$N8),'Per Invoice'!$P$2:$P$801,0),"")
A9: =IF($N9="","",IF(INDEX('Per Invoice'!$A$2:$A$801,$N9)="","",INDEX('Per Invoice'!$A$2:$A$801,$N9))) | B9: =IF($N9="","",IF(INDEX('Per Invoice'!$B$2:$B$801,$N9)="","",INDEX('Per Invoice'!$B$2:$B$801,$N9))) | C9: =IF($N9="","",IF(INDEX('Per Invoice'!$C$2:$C$801,$N9)="","",INDEX('Per Invoice'!$C$2:$C$801,$N9))) | D9: =IF($N9="","",IF(INDEX('Per Invoice'!$D$2:$D$801,$N9)="","",INDEX('Per Invoice'!$D$2:$D$801,$N9))) | E9: =IF($N9="","",IF(INDEX('Per Invoice'!$E$2:$E$801,$N9)="","",INDEX('Per Invoice'!$E$2:$E$801,$N9))) | F9: =IF($N9="","",IF(INDEX('Per Invoice'!$F$2:$F$801,$N9)="","",INDEX('Per Invoice'!$F$2:$F$801,$N9))) | G9: =IF($N9="","",IF(INDEX('Per Invoice'!$G$2:$G$801,$N9)="","",INDEX('Per Invoice'!$G$2:$G$801,$N9))) | H9: =IF($N9="","",IF(INDEX('Per Invoice'!$H$2:$H$801,$N9)="","",INDEX('Per Invoice'!$H$2:$H$801,$N9))) | I9: =IF($N9="","",IF(INDEX('Per Invoice'!$I$2:$I$801,$N9)="","",INDEX('Per Invoice'!$I$2:$I$801,$N9))) | J9: =IF($N9="","",IF(INDEX('Per Invoice'!$J$2:$J$801,$N9)="","",INDEX('Per Invoice'!$J$2:$J$801,$N9))) | K9: =IF($N9="","",IF(INDEX('Per Invoice'!$K$2:$K$801,$N9)="","",INDEX('Per Invoice'!$K$2:$K$801,$N9))) | L9: =IF($N9="","",IF(INDEX('Per Invoice'!$L$2:$L$801,$N9)="","",INDEX('Per Invoice'!$L$2:$L$801,$N9))) | M9: =IF($N9="","",IF(INDEX('Per Invoice'!$M$2:$M$801,$N9)="","",INDEX('Per Invoice'!$M$2:$M$801,$N9))) | N9: =IF(ROWS($N$2:$N9)<=COUNT('Per Invoice'!$P$2:$P$801),MATCH(ROWS($N$2:$N9),'Per Invoice'!$P$2:$P$801,0),"")
A10: =IF($N10="","",IF(INDEX('Per Invoice'!$A$2:$A$801,$N10)="","",INDEX('Per Invoice'!$A$2:$A$801,$N10))) | B10: =IF($N10="","",IF(INDEX('Per Invoice'!$B$2:$B$801,$N10)="","",INDEX('Per Invoice'!$B$2:$B$801,$N10))) | C10: =IF($N10="","",IF(INDEX('Per Invoice'!$C$2:$C$801,$N10)="","",INDEX('Per Invoice'!$C$2:$C$801,$N10))) | D10: =IF($N10="","",IF(INDEX('Per Invoice'!$D$2:$D$801,$N10)="","",INDEX('Per Invoice'!$D$2:$D$801,$N10))) | E10: =IF($N10="","",IF(INDEX('Per Invoice'!$E$2:$E$801,$N10)="","",INDEX('Per Invoice'!$E$2:$E$801,$N10))) | F10: =IF($N10="","",IF(INDEX('Per Invoice'!$F$2:$F$801,$N10)="","",INDEX('Per Invoice'!$F$2:$F$801,$N10))) | G10: =IF($N10="","",IF(INDEX('Per Invoice'!$G$2:$G$801,$N10)="","",INDEX('Per Invoice'!$G$2:$G$801,$N10))) | H10: =IF($N10="","",IF(INDEX('Per Invoice'!$H$2:$H$801,$N10)="","",INDEX('Per Invoice'!$H$2:$H$801,$N10))) | I10: =IF($N10="","",IF(INDEX('Per Invoice'!$I$2:$I$801,$N10)="","",INDEX('Per Invoice'!$I$2:$I$801,$N10))) | J10: =IF($N10="","",IF(INDEX('Per Invoice'!$J$2:$J$801,$N10)="","",INDEX('Per Invoice'!$J$2:$J$801,$N10))) | K10: =IF($N10="","",IF(INDEX('Per Invoice'!$K$2:$K$801,$N10)="","",INDEX('Per Invoice'!$K$2:$K$801,$N10))) | L10: =IF($N10="","",IF(INDEX('Per Invoice'!$L$2:$L$801,$N10)="","",INDEX('Per Invoice'!$L$2:$L$801,$N10))) | M10: =IF($N10="","",IF(INDEX('Per Invoice'!$M$2:$M$801,$N10)="","",INDEX('Per Invoice'!$M$2:$M$801,$N10))) | N10: =IF(ROWS($N$2:$N10)<=COUNT('Per Invoice'!$P$2:$P$801),MATCH(ROWS($N$2:$N10),'Per Invoice'!$P$2:$P$801,0),"")
A11: =IF($N11="","",IF(INDEX('Per Invoice'!$A$2:$A$801,$N11)="","",INDEX('Per Invoice'!$A$2:$A$801,$N11))) | B11: =IF($N11="","",IF(INDEX('Per Invoice'!$B$2:$B$801,$N11)="","",INDEX('Per Invoice'!$B$2:$B$801,$N11))) | C11: =IF($N11="","",IF(INDEX('Per Invoice'!$C$2:$C$801,$N11)="","",INDEX('Per Invoice'!$C$2:$C$801,$N11))) | D11: =IF($N11="","",IF(INDEX('Per Invoice'!$D$2:$D$801,$N11)="","",INDEX('Per Invoice'!$D$2:$D$801,$N11))) | E11: =IF($N11="","",IF(INDEX('Per Invoice'!$E$2:$E$801,$N11)="","",INDEX('Per Invoice'!$E$2:$E$801,$N11))) | F11: =IF($N11="","",IF(INDEX('Per Invoice'!$F$2:$F$801,$N11)="","",INDEX('Per Invoice'!$F$2:$F$801,$N11))) | G11: =IF($N11="","",IF(INDEX('Per Invoice'!$G$2:$G$801,$N11)="","",INDEX('Per Invoice'!$G$2:$G$801,$N11))) | H11: =IF($N11="","",IF(INDEX('Per Invoice'!$H$2:$H$801,$N11)="","",INDEX('Per Invoice'!$H$2:$H$801,$N11))) | I11: =IF($N11="","",IF(INDEX('Per Invoice'!$I$2:$I$801,$N11)="","",INDEX('Per Invoice'!$I$2:$I$801,$N11))) | J11: =IF($N11="","",IF(INDEX('Per Invoice'!$J$2:$J$801,$N11)="","",INDEX('Per Invoice'!$J$2:$J$801,$N11))) | K11: =IF($N11="","",IF(INDEX('Per Invoice'!$K$2:$K$801,$N11)="","",INDEX('Per Invoice'!$K$2:$K$801,$N11))) | L11: =IF($N11="","",IF(INDEX('Per Invoice'!$L$2:$L$801,$N11)="","",INDEX('Per Invoice'!$L$2:$L$801,$N11))) | M11: =IF($N11="","",IF(INDEX('Per Invoice'!$M$2:$M$801,$N11)="","",INDEX('Per Invoice'!$M$2:$M$801,$N11))) | N11: =IF(ROWS($N$2:$N11)<=COUNT('Per Invoice'!$P$2:$P$801),MATCH(ROWS($N$2:$N11),'Per Invoice'!$P$2:$P$801,0),"")
A12: =IF($N12="","",IF(INDEX('Per Invoice'!$A$2:$A$801,$N12)="","",INDEX('Per Invoice'!$A$2:$A$801,$N12))) | B12: =IF($N12="","",IF(INDEX('Per Invoice'!$B$2:$B$801,$N12)="","",INDEX('Per Invoice'!$B$2:$B$801,$N12))) | C12: =IF($N12="","",IF(INDEX('Per Invoice'!$C$2:$C$801,$N12)="","",INDEX('Per Invoice'!$C$2:$C$801,$N12))) | D12: =IF($N12="","",IF(INDEX('Per Invoice'!$D$2:$D$801,$N12)="","",INDEX('Per Invoice'!$D$2:$D$801,$N12))) | E12: =IF($N12="","",IF(INDEX('Per Invoice'!$E$2:$E$801,$N12)="","",INDEX('Per Invoice'!$E$2:$E$801,$N12))) | F12: =IF($N12="","",IF(INDEX('Per Invoice'!$F$2:$F$801,$N12)="","",INDEX('Per Invoice'!$F$2:$F$801,$N12))) | G12: =IF($N12="","",IF(INDEX('Per Invoice'!$G$2:$G$801,$N12)="","",INDEX('Per Invoice'!$G$2:$G$801,$N12))) | H12: =IF($N12="","",IF(INDEX('Per Invoice'!$H$2:$H$801,$N12)="","",INDEX('Per Invoice'!$H$2:$H$801,$N12))) | I12: =IF($N12="","",IF(INDEX('Per Invoice'!$I$2:$I$801,$N12)="","",INDEX('Per Invoice'!$I$2:$I$801,$N12))) | J12: =IF($N12="","",IF(INDEX('Per Invoice'!$J$2:$J$801,$N12)="","",INDEX('Per Invoice'!$J$2:$J$801,$N12))) | K12: =IF($N12="","",IF(INDEX('Per Invoice'!$K$2:$K$801,$N12)="","",INDEX('Per Invoice'!$K$2:$K$801,$N12))) | L12: =IF($N12="","",IF(INDEX('Per Invoice'!$L$2:$L$801,$N12)="","",INDEX('Per Invoice'!$L$2:$L$801,$N12))) | M12: =IF($N12="","",IF(INDEX('Per Invoice'!$M$2:$M$801,$N12)="","",INDEX('Per Invoice'!$M$2:$M$801,$N12))) | N12: =IF(ROWS($N$2:$N12)<=COUNT('Per Invoice'!$P$2:$P$801),MATCH(ROWS($N$2:$N12),'Per Invoice'!$P$2:$P$801,0),"")
A13: =IF($N13="","",IF(INDEX('Per Invoice'!$A$2:$A$801,$N13)="","",INDEX('Per Invoice'!$A$2:$A$801,$N13))) | B13: =IF($N13="","",IF(INDEX('Per Invoice'!$B$2:$B$801,$N13)="","",INDEX('Per Invoice'!$B$2:$B$801,$N13))) | C13: =IF($N13="","",IF(INDEX('Per Invoice'!$C$2:$C$801,$N13)="","",INDEX('Per Invoice'!$C$2:$C$801,$N13))) | D13: =IF($N13="","",IF(INDEX('Per Invoice'!$D$2:$D$801,$N13)="","",INDEX('Per Invoice'!$D$2:$D$801,$N13))) | E13: =IF($N13="","",IF(INDEX('Per Invoice'!$E$2:$E$801,$N13)="","",INDEX('Per Invoice'!$E$2:$E$801,$N13))) | F13: =IF($N13="","",IF(INDEX('Per Invoice'!$F$2:$F$801,$N13)="","",INDEX('Per Invoice'!$F$2:$F$801,$N13))) | G13: =IF($N13="","",IF(INDEX('Per Invoice'!$G$2:$G$801,$N13)="","",INDEX('Per Invoice'!$G$2:$G$801,$N13))) | H13: =IF($N13="","",IF(INDEX('Per Invoice'!$H$2:$H$801,$N13)="","",INDEX('Per Invoice'!$H$2:$H$801,$N13))) | I13: =IF($N13="","",IF(INDEX('Per Invoice'!$I$2:$I$801,$N13)="","",INDEX('Per Invoice'!$I$2:$I$801,$N13))) | J13: =IF($N13="","",IF(INDEX('Per Invoice'!$J$2:$J$801,$N13)="","",INDEX('Per Invoice'!$J$2:$J$801,$N13))) | K13: =IF($N13="","",IF(INDEX('Per Invoice'!$K$2:$K$801,$N13)="","",INDEX('Per Invoice'!$K$2:$K$801,$N13))) | L13: =IF($N13="","",IF(INDEX('Per Invoice'!$L$2:$L$801,$N13)="","",INDEX('Per Invoice'!$L$2:$L$801,$N13))) | M13: =IF($N13="","",IF(INDEX('Per Invoice'!$M$2:$M$801,$N13)="","",INDEX('Per Invoice'!$M$2:$M$801,$N13))) | N13: =IF(ROWS($N$2:$N13)<=COUNT('Per Invoice'!$P$2:$P$801),MATCH(ROWS($N$2:$N13),'Per Invoice'!$P$2:$P$801,0),"")
