Workbook

Sheet How To Use
A1: Claims Template - NEXT CARE (Walk In)
A3: Monthly steps
A4: 1. Open the 'Per Line' tab. Delete the old data in the BLUE columns only (row 2 down). Never delete the green or grey columns.
A5: 2. Paste the new month's data as VALUES starting at A2, into the blue columns: B-I, K-O, S-Y (same order as the system export).
A6: 3. Green columns (A, J, P, Q, R) and the grey helper columns (Z-AC) calculate automatically - do not paste over them.
A7: 4. 'Per Invoice' fills itself from 'Per Line' (one row per Order #, split into IMP / Local). No pivot table, no refresh.
A8: 5. The ONLY manual column in 'Per Invoice' is column A 'Invoice' (blue): type it yourself. Everything else is formula.
A9: 6. The tabs, the Arabic 'Template ...' sheets and 'Summary' fill themselves from 'Per Invoice'. Column '##' decides which tab each invoice goes to (rule and limit are in Settings).
A10: 7. Open 'Settings' and check STATUS says OK (Per Line = Per Invoice, and every invoice has a payer that is listed in Settings).
A12: Colour legend
A13: Blue header = typed/pasted by you (raw data, and 'Invoice' in Per Invoice). Green header = formula (do not paste over). Grey header = helper formula (do not touch). Yellow cell (Settings) = editable rate.
A15: Calculation rules (taken from the September 2026 sheet)
... A23: 'Payer' and 'Payment term' come with every line. The tab of each invoice is the Payer when it is Orient / Allianz, otherwise the Payment term (3 & 12(60) or 9 & 16(20)). Rates: 'Settings' C6 / C7 for 9 & 16, G6 / G7 for 3 & 12.

Sheet Settings
B1: Company settings & checks
B3: Insurance Company | C3: NEXT CARE | D3: Informational only
B4: Corporate | C4: Next Care (all corporates) | D4: Informational only
B5: Sheet type | C5: Walk In | D5: Informational only | F5: Rates when Payment Term contains 3&12
B6: Local products rebate % | C6: 0.16 | D6: Source: Next Care sheet (Rebates typed on every line: 16 / 12 for Local, 9 / 3 for Imported). | F6: Local products rebate % (3&12) | G6: 0.12 | H6: All other Payment Terms use the rates in C6 / C7.
B7: Imported (IMP) products rebate % | C7: 0.09 | D7: Source: Next Care sheet. | F7: Imported (IMP) products rebate % (3&12) | G7: 0.03
B9: Month totals / reconciliation
B10: Lines loaded | C10: =COUNTA('Per Line'!$B$2:$B$3001)
B11: Invoices (unique Order #) | C11: =MAX('Per Line'!$AA$2:$AA$3001)
B12: Invoices shown in Per Invoice | C12: =SUMPRODUCT(--('Per Invoice'!$B$2:$B$801<>""))
B13: Grand Total - Per Line (Product Total) | C13: =SUM('Per Line'!$O$2:$O$3001)
B14: Grand Total - Per Invoice | C14: =SUM('Per Invoice'!$V$2:$V$801)
B15: Discount - Per Line | C15: =SUM('Per Line'!$P$2:$P$3001)
B16: Discount - Per Invoice | C16: =SUM('Per Invoice'!$S$2:$S$801)
B17: Co val - Per Line | C17: =SUM('Per Line'!$J$2:$J$3001)
B18: Co val - Per Invoice | C18: =SUM('Per Invoice'!$K$2:$K$801)
B19: Net - Per Line | C19: =SUM('Per Line'!$R$2:$R$3001)
B20: Net - Per Invoice | C20: =SUM('Per Invoice'!$U$2:$U$801)
B21: Max Limit adjustment (Co val, Per Invoice only) | C21: 0 | D21: This company's Per Invoice has no Max Limit rule.
B23: STATUS | C23: =IF(C10=0,"No data loaded",IF(COUNTA('Per Line'!$B:$B)-1>3000,"TOO MANY LINES - extend template",IF(C11>800,"TOO MANY INVOICES - extend template",IF(AND(ROUND(C13-C14,2)=0,ROUND(C15-C16,2)=0,ROUND(C17+C21-C18,2)=0,ROUND(C19-C21-C20,2)=0,C11=C12,C34=0,MAX(D26:D32)<=300),"OK","CHECK - Per Line and Per Invoice do not match")))) | D23: Must say OK after you paste the month data.
B25: Site tabs | C25: Site name exactly as in the ## column | D25: Invoices (formula)
B26: Orient | C26: Orient Insurance Company | D26: =IF(C26="",0,COUNTIF('Per Invoice'!$D$2:$D$801,C26))
B27: Allianz | C27: Allianz | D27: =IF(C27="",0,COUNTIF('Per Invoice'!$D$2:$D$801,C27))
B28: 3 & 12(60) | C28: 3 & 12(60) | D28: =IF(C28="",0,COUNTIF('Per Invoice'!$D$2:$D$801,C28))
B29: 9 & 16(20) | C29: 9 & 16(20) | D29: =IF(C29="",0,COUNTIF('Per Invoice'!$D$2:$D$801,C29))
B30: Extra 1 | D30: =IF(C30="",0,COUNTIF('Per Invoice'!$D$2:$D$801,C30))
B31: Extra 2 | D31: =IF(C31="",0,COUNTIF('Per Invoice'!$D$2:$D$801,C31))
B32: Extra 3 | D32: =IF(C32="",0,COUNTIF('Per Invoice'!$D$2:$D$801,C32))
B34: Invoices not in any site tab (must be 0) | C34: =C11-SUM(D26:D32) | D34: If not 0: a new site appeared. Type its exact name in one of the empty yellow cells above (Extra 1 ... Extra n); the tab Extra n then shows it. Each tab holds up to 300 invoices.

Sheet Summary
A1: ## | B1: No_Invoice | C1: Copayment | D1: Subtotal | E1: Net
A2: =IF(Settings!$C$26="","",Settings!$C$26) | B2: =IF($A2="","",COUNTIF('Per Invoice'!$D$2:$D$801,$A2)) | C2: =IF($A2="","",SUMIFS('Per Invoice'!$K$2:$K$801,'Per Invoice'!$D$2:$D$801,$A2)) | D2: =IF($A2="","",SUMIFS('Per Invoice'!$T$2:$T$801,'Per Invoice'!$D$2:$D$801,$A2)) | E2: =IF($A2="","",SUMIFS('Per Invoice'!$U$2:$U$801,'Per Invoice'!$D$2:$D$801,$A2))
A3: =IF(Settings!$C$27="","",Settings!$C$27) | B3: =IF($A3="","",COUNTIF('Per Invoice'!$D$2:$D$801,$A3)) | C3: =IF($A3="","",SUMIFS('Per Invoice'!$K$2:$K$801,'Per Invoice'!$D$2:$D$801,$A3)) | D3: =IF($A3="","",SUMIFS('Per Invoice'!$T$2:$T$801,'Per Invoice'!$D$2:$D$801,$A3)) | E3: =IF($A3="","",SUMIFS('Per Invoice'!$U$2:$U$801,'Per Invoice'!$D$2:$D$801,$A3))
A4: =IF(Settings!$C$28="","",Settings!$C$28) | B4: =IF($A4="","",COUNTIF('Per Invoice'!$D$2:$D$801,$A4)) | C4: =IF($A4="","",SUMIFS('Per Invoice'!$K$2:$K$801,'Per Invoice'!$D$2:$D$801,$A4)) | D4: =IF($A4="","",SUMIFS('Per Invoice'!$T$2:$T$801,'Per Invoice'!$D$2:$D$801,$A4)) | E4: =IF($A4="","",SUMIFS('Per Invoice'!$U$2:$U$801,'Per Invoice'!$D$2:$D$801,$A4))
A5: =IF(Settings!$C$29="","",Settings!$C$29) | B5: =IF($A5="","",COUNTIF('Per Invoice'!$D$2:$D$801,$A5)) | C5: =IF($A5="","",SUMIFS('Per Invoice'!$K$2:$K$801,'Per Invoice'!$D$2:$D$801,$A5)) | D5: =IF($A5="","",SUMIFS('Per Invoice'!$T$2:$T$801,'Per Invoice'!$D$2:$D$801,$A5)) | E5: =IF($A5="","",SUMIFS('Per Invoice'!$U$2:$U$801,'Per Invoice'!$D$2:$D$801,$A5))
A6: =IF(Settings!$C$30="","",Settings!$C$30) | B6: =IF($A6="","",COUNTIF('Per Invoice'!$D$2:$D$801,$A6)) | C6: =IF($A6="","",SUMIFS('Per Invoice'!$K$2:$K$801,'Per Invoice'!$D$2:$D$801,$A6)) | D6: =IF($A6="","",SUMIFS('Per Invoice'!$T$2:$T$801,'Per Invoice'!$D$2:$D$801,$A6)) | E6: =IF($A6="","",SUMIFS('Per Invoice'!$U$2:$U$801,'Per Invoice'!$D$2:$D$801,$A6))
A7: =IF(Settings!$C$31="","",Settings!$C$31) | B7: =IF($A7="","",COUNTIF('Per Invoice'!$D$2:$D$801,$A7)) | C7: =IF($A7="","",SUMIFS('Per Invoice'!$K$2:$K$801,'Per Invoice'!$D$2:$D$801,$A7)) | D7: =IF($A7="","",SUMIFS('Per Invoice'!$T$2:$T$801,'Per Invoice'!$D$2:$D$801,$A7)) | E7: =IF($A7="","",SUMIFS('Per Invoice'!$U$2:$U$801,'Per Invoice'!$D$2:$D$801,$A7))
A8: =IF(Settings!$C$32="","",Settings!$C$32) | B8: =IF($A8="","",COUNTIF('Per Invoice'!$D$2:$D$801,$A8)) | C8: =IF($A8="","",SUMIFS('Per Invoice'!$K$2:$K$801,'Per Invoice'!$D$2:$D$801,$A8)) | D8: =IF($A8="","",SUMIFS('Per Invoice'!$T$2:$T$801,'Per Invoice'!$D$2:$D$801,$A8)) | E8: =IF($A8="","",SUMIFS('Per Invoice'!$U$2:$U$801,'Per Invoice'!$D$2:$D$801,$A8))
A9: Grand Total | B9: =SUM(B2:B8) | C9: =SUM(C2:C8) | D9: =SUM(D2:D8) | E9: =SUM(E2:E8)

Sheet Per Line
A1: Invoice | B1: Pos Reference | C1: Approval | D1: payment term | E1: Payer | F1: Insurance Company | G1: Name | H1: Card Number | I1: Co Payment % | J1: Co val | K1: Heisenberg id | L1: Product | M1: Delivered Qty | N1: Delivered Price | O1: Total Delivered | P1: Discount | Q1: Subtotal | R1: Net | S1: Order Amount Total | T1: Payment Amount | U1: Payment Type | V1: Create Date | W1: Order Reference | X1: Rebates | Y1: Product Template - Product Tmpl → Is Local | Z1: Order 1st Row (helper) | AA1: Invoice # (helper) | AB1: Is Local (helper) | AC1: Sort Key (helper)
A2: =IF($B2="","",IFERROR(IF(INDEX('Per Invoice'!$A$2:$A$801,MATCH($B2,'Per Invoice'!$B$2:$B$801,0))=0,"",INDEX('Per Invoice'!$A$2:$A$801,MATCH($B2,'Per Invoice'!$B$2:$B$801,0))),"")) | J2: =IF($B2="","",I2*Q2/100) | P2: =IF($B2="","",O2*X2/100) | Q2: =IF($B2="","",O2-P2) | R2: =IF($B2="","",Q2-J2) | Z2: =IF($B2="","",IF(COUNTIF($B$2:$B2,$B2)=1,1,0)) | AA2: =IF($Z2=1,SUMPRODUCT(--($AC$2:$AC$3001<$AC2))+1,"") | AB2: =IF($B2="","",IF(OR($Y2=TRUE(),$Y2="TRUE"),1,IF(AND($Y2<>"",OR($Y2=FALSE(),$Y2="FALSE")),0,IF(MIN(ABS($X2/100-Settings!$C$6),ABS($X2/100-Settings!$G$6))<=MIN(ABS($X2/100-Settings!$C$7),ABS($X2/100-Settings!$G$7)),1,0)))) | AC2: =IF($Z2=1,IFERROR(IF(VALUE($B2)<100000000,VALUE($B2),1000000000),IFERROR(IF(VALUE(MID($B2,2,20))<100000000,VALUE(MID($B2,2,20)),1000000000),1000000000))+ROW()/100000,"")
A3: =IF($B3="","",IFERROR(IF(INDEX('Per Invoice'!$A$2:$A$801,MATCH($B3,'Per Invoice'!$B$2:$B$801,0))=0,"",INDEX('Per Invoice'!$A$2:$A$801,MATCH($B3,'Per Invoice'!$B$2:$B$801,0))),"")) | J3: =IF($B3="","",I3*Q3/100) | P3: =IF($B3="","",O3*X3/100) | Q3: =IF($B3="","",O3-P3) | R3: =IF($B3="","",Q3-J3) | Z3: =IF($B3="","",IF(COUNTIF($B$2:$B3,$B3)=1,1,0)) | AA3: =IF($Z3=1,SUMPRODUCT(--($AC$2:$AC$3001<$AC3))+1,"") | AB3: =IF($B3="","",IF(OR($Y3=TRUE(),$Y3="TRUE"),1,IF(AND($Y3<>"",OR($Y3=FALSE(),$Y3="FALSE")),0,IF(MIN(ABS($X3/100-Settings!$C$6),ABS($X3/100-Settings!$G$6))<=MIN(ABS($X3/100-Settings!$C$7),ABS($X3/100-Settings!$G$7)),1,0)))) | AC3: =IF($Z3=1,IFERROR(IF(VALUE($B3)<100000000,VALUE($B3),1000000000),IFERROR(IF(VALUE(MID($B3,2,20))<100000000,VALUE(MID($B3,2,20)),1000000000),1000000000))+ROW()/100000,"")
A4: =IF($B4="","",IFERROR(IF(INDEX('Per Invoice'!$A$2:$A$801,MATCH($B4,'Per Invoice'!$B$2:$B$801,0))=0,"",INDEX('Per Invoice'!$A$2:$A$801,MATCH($B4,'Per Invoice'!$B$2:$B$801,0))),"")) | J4: =IF($B4="","",I4*Q4/100) | P4: =IF($B4="","",O4*X4/100) | Q4: =IF($B4="","",O4-P4) | R4: =IF($B4="","",Q4-J4) | Z4: =IF($B4="","",IF(COUNTIF($B$2:$B4,$B4)=1,1,0)) | AA4: =IF($Z4=1,SUMPRODUCT(--($AC$2:$AC$3001<$AC4))+1,"") | AB4: =IF($B4="","",IF(OR($Y4=TRUE(),$Y4="TRUE"),1,IF(AND($Y4<>"",OR($Y4=FALSE(),$Y4="FALSE")),0,IF(MIN(ABS($X4/100-Settings!$C$6),ABS($X4/100-Settings!$G$6))<=MIN(ABS($X4/100-Settings!$C$7),ABS($X4/100-Settings!$G$7)),1,0)))) | AC4: =IF($Z4=1,IFERROR(IF(VALUE($B4)<100000000,VALUE($B4),1000000000),IFERROR(IF(VALUE(MID($B4,2,20))<100000000,VALUE(MID($B4,2,20)),1000000000),1000000000))+ROW()/100000,"")
A5: =IF($B5="","",IFERROR(IF(INDEX('Per Invoice'!$A$2:$A$801,MATCH($B5,'Per Invoice'!$B$2:$B$801,0))=0,"",INDEX('Per Invoice'!$A$2:$A$801,MATCH($B5,'Per Invoice'!$B$2:$B$801,0))),"")) | J5: =IF($B5="","",I5*Q5/100) | P5: =IF($B5="","",O5*X5/100) | Q5: =IF($B5="","",O5-P5) | R5: =IF($B5="","",Q5-J5) | Z5: =IF($B5="","",IF(COUNTIF($B$2:$B5,$B5)=1,1,0)) | AA5: =IF($Z5=1,SUMPRODUCT(--($AC$2:$AC$3001<$AC5))+1,"") | AB5: =IF($B5="","",IF(OR($Y5=TRUE(),$Y5="TRUE"),1,IF(AND($Y5<>"",OR($Y5=FALSE(),$Y5="FALSE")),0,IF(MIN(ABS($X5/100-Settings!$C$6),ABS($X5/100-Settings!$G$6))<=MIN(ABS($X5/100-Settings!$C$7),ABS($X5/100-Settings!$G$7)),1,0)))) | AC5: =IF($Z5=1,IFERROR(IF(VALUE($B5)<100000000,VALUE($B5),1000000000),IFERROR(IF(VALUE(MID($B5,2,20))<100000000,VALUE(MID($B5,2,20)),1000000000),1000000000))+ROW()/100000,"")
A6: =IF($B6="","",IFERROR(IF(INDEX('Per Invoice'!$A$2:$A$801,MATCH($B6,'Per Invoice'!$B$2:$B$801,0))=0,"",INDEX('Per Invoice'!$A$2:$A$801,MATCH($B6,'Per Invoice'!$B$2:$B$801,0))),"")) | J6: =IF($B6="","",I6*Q6/100) | P6: =IF($B6="","",O6*X6/100) | Q6: =IF($B6="","",O6-P6) | R6: =IF($B6="","",Q6-J6) | Z6: =IF($B6="","",IF(COUNTIF($B$2:$B6,$B6)=1,1,0)) | AA6: =IF($Z6=1,SUMPRODUCT(--($AC$2:$AC$3001<$AC6))+1,"") | AB6: =IF($B6="","",IF(OR($Y6=TRUE(),$Y6="TRUE"),1,IF(AND($Y6<>"",OR($Y6=FALSE(),$Y6="FALSE")),0,IF(MIN(ABS($X6/100-Settings!$C$6),ABS($X6/100-Settings!$G$6))<=MIN(ABS($X6/100-Settings!$C$7),ABS($X6/100-Settings!$G$7)),1,0)))) | AC6: =IF($Z6=1,IFERROR(IF(VALUE($B6)<100000000,VALUE($B6),1000000000),IFERROR(IF(VALUE(MID($B6,2,20))<100000000,VALUE(MID($B6,2,20)),1000000000),1000000000))+ROW()/100000,"")
A7: =IF($B7="","",IFERROR(IF(INDEX('Per Invoice'!$A$2:$A$801,MATCH($B7,'Per Invoice'!$B$2:$B$801,0))=0,"",INDEX('Per Invoice'!$A$2:$A$801,MATCH($B7,'Per Invoice'!$B$2:$B$801,0))),"")) | J7: =IF($B7="","",I7*Q7/100) | P7: =IF($B7="","",O7*X7/100) | Q7: =IF($B7="","",O7-P7) | R7: =IF($B7="","",Q7-J7) | Z7: =IF($B7="","",IF(COUNTIF($B$2:$B7,$B7)=1,1,0)) | AA7: =IF($Z7=1,SUMPRODUCT(--($AC$2:$AC$3001<$AC7))+1,"") | AB7: =IF($B7="","",IF(OR($Y7=TRUE(),$Y7="TRUE"),1,IF(AND($Y7<>"",OR($Y7=FALSE(),$Y7="FALSE")),0,IF(MIN(ABS($X7/100-Settings!$C$6),ABS($X7/100-Settings!$G$6))<=MIN(ABS($X7/100-Settings!$C$7),ABS($X7/100-Settings!$G$7)),1,0)))) | AC7: =IF($Z7=1,IFERROR(IF(VALUE($B7)<100000000,VALUE($B7),1000000000),IFERROR(IF(VALUE(MID($B7,2,20))<100000000,VALUE(MID($B7,2,20)),1000000000),1000000000))+ROW()/100000,"")
A8: =IF($B8="","",IFERROR(IF(INDEX('Per Invoice'!$A$2:$A$801,MATCH($B8,'Per Invoice'!$B$2:$B$801,0))=0,"",INDEX('Per Invoice'!$A$2:$A$801,MATCH($B8,'Per Invoice'!$B$2:$B$801,0))),"")) | J8: =IF($B8="","",I8*Q8/100) | P8: =IF($B8="","",O8*X8/100) | Q8: =IF($B8="","",O8-P8) | R8: =IF($B8="","",Q8-J8) | Z8: =IF($B8="","",IF(COUNTIF($B$2:$B8,$B8)=1,1,0)) | AA8: =IF($Z8=1,SUMPRODUCT(--($AC$2:$AC$3001<$AC8))+1,"") | AB8: =IF($B8="","",IF(OR($Y8=TRUE(),$Y8="TRUE"),1,IF(AND($Y8<>"",OR($Y8=FALSE(),$Y8="FALSE")),0,IF(MIN(ABS($X8/100-Settings!$C$6),ABS($X8/100-Settings!$G$6))<=MIN(ABS($X8/100-Settings!$C$7),ABS($X8/100-Settings!$G$7)),1,0)))) | AC8: =IF($Z8=1,IFERROR(IF(VALUE($B8)<100000000,VALUE($B8),1000000000),IFERROR(IF(VALUE(MID($B8,2,20))<100000000,VALUE(MID($B8,2,20)),1000000000),1000000000))+ROW()/100000,"")
A9: =IF($B9="","",IFERROR(IF(INDEX('Per Invoice'!$A$2:$A$801,MATCH($B9,'Per Invoice'!$B$2:$B$801,0))=0,"",INDEX('Per Invoice'!$A$2:$A$801,MATCH($B9,'Per Invoice'!$B$2:$B$801,0))),"")) | J9: =IF($B9="","",I9*Q9/100) | P9: =IF($B9="","",O9*X9/100) | Q9: =IF($B9="","",O9-P9) | R9: =IF($B9="","",Q9-J9) | Z9: =IF($B9="","",IF(COUNTIF($B$2:$B9,$B9)=1,1,0)) | AA9: =IF($Z9=1,SUMPRODUCT(--($AC$2:$AC$3001<$AC9))+1,"") | AB9: =IF($B9="","",IF(OR($Y9=TRUE(),$Y9="TRUE"),1,IF(AND($Y9<>"",OR($Y9=FALSE(),$Y9="FALSE")),0,IF(MIN(ABS($X9/100-Settings!$C$6),ABS($X9/100-Settings!$G$6))<=MIN(ABS($X9/100-Settings!$C$7),ABS($X9/100-Settings!$G$7)),1,0)))) | AC9: =IF($Z9=1,IFERROR(IF(VALUE($B9)<100000000,VALUE($B9),1000000000),IFERROR(IF(VALUE(MID($B9,2,20))<100000000,VALUE(MID($B9,2,20)),1000000000),1000000000))+ROW()/100000,"")
A10: =IF($B10="","",IFERROR(IF(INDEX('Per Invoice'!$A$2:$A$801,MATCH($B10,'Per Invoice'!$B$2:$B$801,0))=0,"",INDEX('Per Invoice'!$A$2:$A$801,MATCH($B10,'Per Invoice'!$B$2:$B$801,0))),"")) | J10: =IF($B10="","",I10*Q10/100) | P10: =IF($B10="","",O10*X10/100) | Q10: =IF($B10="","",O10-P10) | R10: =IF($B10="","",Q10-J10) | Z10: =IF($B10="","",IF(COUNTIF($B$2:$B10,$B10)=1,1,0)) | AA10: =IF($Z10=1,SUMPRODUCT(--($AC$2:$AC$3001<$AC10))+1,"") | AB10: =IF($B10="","",IF(OR($Y10=TRUE(),$Y10="TRUE"),1,IF(AND($Y10<>"",OR($Y10=FALSE(),$Y10="FALSE")),0,IF(MIN(ABS($X10/100-Settings!$C$6),ABS($X10/100-Settings!$G$6))<=MIN(ABS($X10/100-Settings!$C$7),ABS($X10/100-Settings!$G$7)),1,0)))) | AC10: =IF($Z10=1,IFERROR(IF(VALUE($B10)<100000000,VALUE($B10),1000000000),IFERROR(IF(VALUE(MID($B10,2,20))<100000000,VALUE(MID($B10,2,20)),1000000000),1000000000))+ROW()/100000,"")
A11: =IF($B11="","",IFERROR(IF(INDEX('Per Invoice'!$A$2:$A$801,MATCH($B11,'Per Invoice'!$B$2:$B$801,0))=0,"",INDEX('Per Invoice'!$A$2:$A$801,MATCH($B11,'Per Invoice'!$B$2:$B$801,0))),"")) | J11: =IF($B11="","",I11*Q11/100) | P11: =IF($B11="","",O11*X11/100) | Q11: =IF($B11="","",O11-P11) | R11: =IF($B11="","",Q11-J11) | Z11: =IF($B11="","",IF(COUNTIF($B$2:$B11,$B11)=1,1,0)) | AA11: =IF($Z11=1,SUMPRODUCT(--($AC$2:$AC$3001<$AC11))+1,"") | AB11: =IF($B11="","",IF(OR($Y11=TRUE(),$Y11="TRUE"),1,IF(AND($Y11<>"",OR($Y11=FALSE(),$Y11="FALSE")),0,IF(MIN(ABS($X11/100-Settings!$C$6),ABS($X11/100-Settings!$G$6))<=MIN(ABS($X11/100-Settings!$C$7),ABS($X11/100-Settings!$G$7)),1,0)))) | AC11: =IF($Z11=1,IFERROR(IF(VALUE($B11)<100000000,VALUE($B11),1000000000),IFERROR(IF(VALUE(MID($B11,2,20))<100000000,VALUE(MID($B11,2,20)),1000000000),1000000000))+ROW()/100000,"")
A12: =IF($B12="","",IFERROR(IF(INDEX('Per Invoice'!$A$2:$A$801,MATCH($B12,'Per Invoice'!$B$2:$B$801,0))=0,"",INDEX('Per Invoice'!$A$2:$A$801,MATCH($B12,'Per Invoice'!$B$2:$B$801,0))),"")) | J12: =IF($B12="","",I12*Q12/100) | P12: =IF($B12="","",O12*X12/100) | Q12: =IF($B12="","",O12-P12) | R12: =IF($B12="","",Q12-J12) | Z12: =IF($B12="","",IF(COUNTIF($B$2:$B12,$B12)=1,1,0)) | AA12: =IF($Z12=1,SUMPRODUCT(--($AC$2:$AC$3001<$AC12))+1,"") | AB12: =IF($B12="","",IF(OR($Y12=TRUE(),$Y12="TRUE"),1,IF(AND($Y12<>"",OR($Y12=FALSE(),$Y12="FALSE")),0,IF(MIN(ABS($X12/100-Settings!$C$6),ABS($X12/100-Settings!$G$6))<=MIN(ABS($X12/100-Settings!$C$7),ABS($X12/100-Settings!$G$7)),1,0)))) | AC12: =IF($Z12=1,IFERROR(IF(VALUE($B12)<100000000,VALUE($B12),1000000000),IFERROR(IF(VALUE(MID($B12,2,20))<100000000,VALUE(MID($B12,2,20)),1000000000),1000000000))+ROW()/100000,"")
A13: =IF($B13="","",IFERROR(IF(INDEX('Per Invoice'!$A$2:$A$801,MATCH($B13,'Per Invoice'!$B$2:$B$801,0))=0,"",INDEX('Per Invoice'!$A$2:$A$801,MATCH($B13,'Per Invoice'!$B$2:$B$801,0))),"")) | J13: =IF($B13="","",I13*Q13/100) | P13: =IF($B13="","",O13*X13/100) | Q13: =IF($B13="","",O13-P13) | R13: =IF($B13="","",Q13-J13) | Z13: =IF($B13="","",IF(COUNTIF($B$2:$B13,$B13)=1,1,0)) | AA13: =IF($Z13=1,SUMPRODUCT(--($AC$2:$AC$3001<$AC13))+1,"") | AB13: =IF($B13="","",IF(OR($Y13=TRUE(),$Y13="TRUE"),1,IF(AND($Y13<>"",OR($Y13=FALSE(),$Y13="FALSE")),0,IF(MIN(ABS($X13/100-Settings!$C$6),ABS($X13/100-Settings!$G$6))<=MIN(ABS($X13/100-Settings!$C$7),ABS($X13/100-Settings!$G$7)),1,0)))) | AC13: =IF($Z13=1,IFERROR(IF(VALUE($B13)<100000000,VALUE($B13),1000000000),IFERROR(IF(VALUE(MID($B13,2,20))<100000000,VALUE(MID($B13,2,20)),1000000000),1000000000))+ROW()/100000,"")
... A3001: =IF($B3001="","",IFERROR(IF(INDEX('Per Invoice'!$A$2:$A$801,MATCH($B3001,'Per Invoice'!$B$2:$B$801,0))=0,"",INDEX('Per Invoice'!$A$2:$A$801,MATCH($B3001,'Per Invoice'!$B$2:$B$801,0))),"")) | J3001: =IF($B3001="","",I3001*Q3001/100) | P3001: =IF($B3001="","",O3001*X3001/100) | Q3001: =IF($B3001="","",O3001-P3001) | R3001: =IF($B3001="","",Q3001-J3001) | Z3001: =IF($B3001="","",IF(COUNTIF($B$2:$B3001,$B3001)=1,1,0)) | AA3001: =IF($Z3001=1,SUMPRODUCT(--($AC$2:$AC$3001<$AC3001))+1,"") | AB3001: =IF($B3001="","",IF(OR($Y3001=TRUE(),$Y3001="TRUE"),1,IF(AND($Y3001<>"",OR($Y3001=FALSE(),$Y3001="FALSE")),0,IF(MIN(ABS($X3001/100-Settings!$C$6),ABS($X3001/100-Settings!$G$6))<=MIN(ABS($X3001/100-Settings!$C$7),ABS($X3001/100-Settings!$G$7)),1,0)))) | AC3001: =IF($Z3001=1,IFERROR(IF(VALUE($B3001)<100000000,VALUE($B3001),1000000000),IFERROR(IF(VALUE(MID($B3001,2,20))<100000000,VALUE(MID($B3001,2,20)),1000000000),1000000000))+ROW()/100000,"")

Sheet Per Invoice
A1: Invoice | B1: Pos Reference | C1: Approval | D1: ## | E1: Payer | F1: Payment term | G1: Insurance Company | H1: Name | I1: Card Number | J1: Co Payment % | K1: Co val | L1: Create Date | M1: Imp% | N1: Imp | O1: Imp_Val | P1: Local% | Q1: Local | R1: Local_Val | S1: Discount | T1: Subtotal | U1: Net | V1: Grand Total | W1: Src Row (helper) | X1: Payer Key (helper)
B2: =IF($W2="","",INDEX('Per Line'!$B$2:$B$3001,$W2)&"") | C2: =IF($W2="","",INDEX('Per Line'!$C$2:$C$3001,$W2)&"") | D2: =IF($W2="","",IF(OR(TRIM(E2)="Orient Insurance Company",TRIM(E2)="Allianz"),TRIM(E2),TRIM(F2))) | E2: =IF($W2="","",INDEX('Per Line'!$E$2:$E$3001,$W2)&"") | F2: =IF($W2="","",INDEX('Per Line'!$D$2:$D$3001,$W2)&"") | G2: =IF($W2="","",INDEX('Per Line'!$F$2:$F$3001,$W2)&"") | H2: =IF($W2="","",INDEX('Per Line'!$G$2:$G$3001,$W2)&"") | I2: =IF($W2="","",INDEX('Per Line'!$H$2:$H$3001,$W2)&"") | J2: =IF($W2="","",INDEX('Per Line'!$I$2:$I$3001,$W2)) | K2: =IF($W2="","",J2*T2/100) | L2: =IF($W2="","",INDEX('Per Line'!$V$2:$V$3001,$W2)) | M2: =IF($W2="","",IF(ISNUMBER(SEARCH("3&12",SUBSTITUTE(F2," ",""))),Settings!$G$7,Settings!$C$7)) | N2: =IF($W2="","",SUMIFS('Per Line'!$O$2:$O$3001,'Per Line'!$B$2:$B$3001,$B2,'Per Line'!$AB$2:$AB$3001,0)) | O2: =IF($W2="","",N2*M2) | P2: =IF($W2="","",IF(ISNUMBER(SEARCH("3&12",SUBSTITUTE(F2," ",""))),Settings!$G$6,Settings!$C$6)) | Q2: =IF($W2="","",SUMIFS('Per Line'!$O$2:$O$3001,'Per Line'!$B$2:$B$3001,$B2,'Per Line'!$AB$2:$AB$3001,1)) | R2: =IF($W2="","",Q2*P2) | S2: =IF($W2="","",R2+O2) | T2: =IF($W2="","",V2-S2) | U2: =IF($W2="","",V2-S2-K2) | V2: =IF($W2="","",N2+Q2) | W2: =IF(ROWS($W$2:$W2)<=MAX('Per Line'!$AA$2:$AA$3001),MATCH(ROWS($W$2:$W2),'Per Line'!$AA$2:$AA$3001,0),"") | X2: =IF($W2="","",D2&"|"&COUNTIF($D$2:$D2,D2))
B3: =IF($W3="","",INDEX('Per Line'!$B$2:$B$3001,$W3)&"") | C3: =IF($W3="","",INDEX('Per Line'!$C$2:$C$3001,$W3)&"") | D3: =IF($W3="","",IF(OR(TRIM(E3)="Orient Insurance Company",TRIM(E3)="Allianz"),TRIM(E3),TRIM(F3))) | E3: =IF($W3="","",INDEX('Per Line'!$E$2:$E$3001,$W3)&"") | F3: =IF($W3="","",INDEX('Per Line'!$D$2:$D$3001,$W3)&"") | G3: =IF($W3="","",INDEX('Per Line'!$F$2:$F$3001,$W3)&"") | H3: =IF($W3="","",INDEX('Per Line'!$G$2:$G$3001,$W3)&"") | I3: =IF($W3="","",INDEX('Per Line'!$H$2:$H$3001,$W3)&"") | J3: =IF($W3="","",INDEX('Per Line'!$I$2:$I$3001,$W3)) | K3: =IF($W3="","",J3*T3/100) | L3: =IF($W3="","",INDEX('Per Line'!$V$2:$V$3001,$W3)) | M3: =IF($W3="","",IF(ISNUMBER(SEARCH("3&12",SUBSTITUTE(F3," ",""))),Settings!$G$7,Settings!$C$7)) | N3: =IF($W3="","",SUMIFS('Per Line'!$O$2:$O$3001,'Per Line'!$B$2:$B$3001,$B3,'Per Line'!$AB$2:$AB$3001,0)) | O3: =IF($W3="","",N3*M3) | P3: =IF($W3="","",IF(ISNUMBER(SEARCH("3&12",SUBSTITUTE(F3," ",""))),Settings!$G$6,Settings!$C$6)) | Q3: =IF($W3="","",SUMIFS('Per Line'!$O$2:$O$3001,'Per Line'!$B$2:$B$3001,$B3,'Per Line'!$AB$2:$AB$3001,1)) | R3: =IF($W3="","",Q3*P3) | S3: =IF($W3="","",R3+O3) | T3: =IF($W3="","",V3-S3) | U3: =IF($W3="","",V3-S3-K3) | V3: =IF($W3="","",N3+Q3) | W3: =IF(ROWS($W$2:$W3)<=MAX('Per Line'!$AA$2:$AA$3001),MATCH(ROWS($W$2:$W3),'Per Line'!$AA$2:$AA$3001,0),"") | X3: =IF($W3="","",D3&"|"&COUNTIF($D$2:$D3,D3))
B4: =IF($W4="","",INDEX('Per Line'!$B$2:$B$3001,$W4)&"") | C4: =IF($W4="","",INDEX('Per Line'!$C$2:$C$3001,$W4)&"") | D4: =IF($W4="","",IF(OR(TRIM(E4)="Orient Insurance Company",TRIM(E4)="Allianz"),TRIM(E4),TRIM(F4))) | E4: =IF($W4="","",INDEX('Per Line'!$E$2:$E$3001,$W4)&"") | F4: =IF($W4="","",INDEX('Per Line'!$D$2:$D$3001,$W4)&"") | G4: =IF($W4="","",INDEX('Per Line'!$F$2:$F$3001,$W4)&"") | H4: =IF($W4="","",INDEX('Per Line'!$G$2:$G$3001,$W4)&"") | I4: =IF($W4="","",INDEX('Per Line'!$H$2:$H$3001,$W4)&"") | J4: =IF($W4="","",INDEX('Per Line'!$I$2:$I$3001,$W4)) | K4: =IF($W4="","",J4*T4/100) | L4: =IF($W4="","",INDEX('Per Line'!$V$2:$V$3001,$W4)) | M4: =IF($W4="","",IF(ISNUMBER(SEARCH("3&12",SUBSTITUTE(F4," ",""))),Settings!$G$7,Settings!$C$7)) | N4: =IF($W4="","",SUMIFS('Per Line'!$O$2:$O$3001,'Per Line'!$B$2:$B$3001,$B4,'Per Line'!$AB$2:$AB$3001,0)) | O4: =IF($W4="","",N4*M4) | P4: =IF($W4="","",IF(ISNUMBER(SEARCH("3&12",SUBSTITUTE(F4," ",""))),Settings!$G$6,Settings!$C$6)) | Q4: =IF($W4="","",SUMIFS('Per Line'!$O$2:$O$3001,'Per Line'!$B$2:$B$3001,$B4,'Per Line'!$AB$2:$AB$3001,1)) | R4: =IF($W4="","",Q4*P4) | S4: =IF($W4="","",R4+O4) | T4: =IF($W4="","",V4-S4) | U4: =IF($W4="","",V4-S4-K4) | V4: =IF($W4="","",N4+Q4) | W4: =IF(ROWS($W$2:$W4)<=MAX('Per Line'!$AA$2:$AA$3001),MATCH(ROWS($W$2:$W4),'Per Line'!$AA$2:$AA$3001,0),"") | X4: =IF($W4="","",D4&"|"&COUNTIF($D$2:$D4,D4))
B5: =IF($W5="","",INDEX('Per Line'!$B$2:$B$3001,$W5)&"") | C5: =IF($W5="","",INDEX('Per Line'!$C$2:$C$3001,$W5)&"") | D5: =IF($W5="","",IF(OR(TRIM(E5)="Orient Insurance Company",TRIM(E5)="Allianz"),TRIM(E5),TRIM(F5))) | E5: =IF($W5="","",INDEX('Per Line'!$E$2:$E$3001,$W5)&"") | F5: =IF($W5="","",INDEX('Per Line'!$D$2:$D$3001,$W5)&"") | G5: =IF($W5="","",INDEX('Per Line'!$F$2:$F$3001,$W5)&"") | H5: =IF($W5="","",INDEX('Per Line'!$G$2:$G$3001,$W5)&"") | I5: =IF($W5="","",INDEX('Per Line'!$H$2:$H$3001,$W5)&"") | J5: =IF($W5="","",INDEX('Per Line'!$I$2:$I$3001,$W5)) | K5: =IF($W5="","",J5*T5/100) | L5: =IF($W5="","",INDEX('Per Line'!$V$2:$V$3001,$W5)) | M5: =IF($W5="","",IF(ISNUMBER(SEARCH("3&12",SUBSTITUTE(F5," ",""))),Settings!$G$7,Settings!$C$7)) | N5: =IF($W5="","",SUMIFS('Per Line'!$O$2:$O$3001,'Per Line'!$B$2:$B$3001,$B5,'Per Line'!$AB$2:$AB$3001,0)) | O5: =IF($W5="","",N5*M5) | P5: =IF($W5="","",IF(ISNUMBER(SEARCH("3&12",SUBSTITUTE(F5," ",""))),Settings!$G$6,Settings!$C$6)) | Q5: =IF($W5="","",SUMIFS('Per Line'!$O$2:$O$3001,'Per Line'!$B$2:$B$3001,$B5,'Per Line'!$AB$2:$AB$3001,1)) | R5: =IF($W5="","",Q5*P5) | S5: =IF($W5="","",R5+O5) | T5: =IF($W5="","",V5-S5) | U5: =IF($W5="","",V5-S5-K5) | V5: =IF($W5="","",N5+Q5) | W5: =IF(ROWS($W$2:$W5)<=MAX('Per Line'!$AA$2:$AA$3001),MATCH(ROWS($W$2:$W5),'Per Line'!$AA$2:$AA$3001,0),"") | X5: =IF($W5="","",D5&"|"&COUNTIF($D$2:$D5,D5))
B6: =IF($W6="","",INDEX('Per Line'!$B$2:$B$3001,$W6)&"") | C6: =IF($W6="","",INDEX('Per Line'!$C$2:$C$3001,$W6)&"") | D6: =IF($W6="","",IF(OR(TRIM(E6)="Orient Insurance Company",TRIM(E6)="Allianz"),TRIM(E6),TRIM(F6))) | E6: =IF($W6="","",INDEX('Per Line'!$E$2:$E$3001,$W6)&"") | F6: =IF($W6="","",INDEX('Per Line'!$D$2:$D$3001,$W6)&"") | G6: =IF($W6="","",INDEX('Per Line'!$F$2:$F$3001,$W6)&"") | H6: =IF($W6="","",INDEX('Per Line'!$G$2:$G$3001,$W6)&"") | I6: =IF($W6="","",INDEX('Per Line'!$H$2:$H$3001,$W6)&"") | J6: =IF($W6="","",INDEX('Per Line'!$I$2:$I$3001,$W6)) | K6: =IF($W6="","",J6*T6/100) | L6: =IF($W6="","",INDEX('Per Line'!$V$2:$V$3001,$W6)) | M6: =IF($W6="","",IF(ISNUMBER(SEARCH("3&12",SUBSTITUTE(F6," ",""))),Settings!$G$7,Settings!$C$7)) | N6: =IF($W6="","",SUMIFS('Per Line'!$O$2:$O$3001,'Per Line'!$B$2:$B$3001,$B6,'Per Line'!$AB$2:$AB$3001,0)) | O6: =IF($W6="","",N6*M6) | P6: =IF($W6="","",IF(ISNUMBER(SEARCH("3&12",SUBSTITUTE(F6," ",""))),Settings!$G$6,Settings!$C$6)) | Q6: =IF($W6="","",SUMIFS('Per Line'!$O$2:$O$3001,'Per Line'!$B$2:$B$3001,$B6,'Per Line'!$AB$2:$AB$3001,1)) | R6: =IF($W6="","",Q6*P6) | S6: =IF($W6="","",R6+O6) | T6: =IF($W6="","",V6-S6) | U6: =IF($W6="","",V6-S6-K6) | V6: =IF($W6="","",N6+Q6) | W6: =IF(ROWS($W$2:$W6)<=MAX('Per Line'!$AA$2:$AA$3001),MATCH(ROWS($W$2:$W6),'Per Line'!$AA$2:$AA$3001,0),"") | X6: =IF($W6="","",D6&"|"&COUNTIF($D$2:$D6,D6))
B7: =IF($W7="","",INDEX('Per Line'!$B$2:$B$3001,$W7)&"") | C7: =IF($W7="","",INDEX('Per Line'!$C$2:$C$3001,$W7)&"") | D7: =IF($W7="","",IF(OR(TRIM(E7)="Orient Insurance Company",TRIM(E7)="Allianz"),TRIM(E7),TRIM(F7))) | E7: =IF($W7="","",INDEX('Per Line'!$E$2:$E$3001,$W7)&"") | F7: =IF($W7="","",INDEX('Per Line'!$D$2:$D$3001,$W7)&"") | G7: =IF($W7="","",INDEX('Per Line'!$F$2:$F$3001,$W7)&"") | H7: =IF($W7="","",INDEX('Per Line'!$G$2:$G$3001,$W7)&"") | I7: =IF($W7="","",INDEX('Per Line'!$H$2:$H$3001,$W7)&"") | J7: =IF($W7="","",INDEX('Per Line'!$I$2:$I$3001,$W7)) | K7: =IF($W7="","",J7*T7/100) | L7: =IF($W7="","",INDEX('Per Line'!$V$2:$V$3001,$W7)) | M7: =IF($W7="","",IF(ISNUMBER(SEARCH("3&12",SUBSTITUTE(F7," ",""))),Settings!$G$7,Settings!$C$7)) | N7: =IF($W7="","",SUMIFS('Per Line'!$O$2:$O$3001,'Per Line'!$B$2:$B$3001,$B7,'Per Line'!$AB$2:$AB$3001,0)) | O7: =IF($W7="","",N7*M7) | P7: =IF($W7="","",IF(ISNUMBER(SEARCH("3&12",SUBSTITUTE(F7," ",""))),Settings!$G$6,Settings!$C$6)) | Q7: =IF($W7="","",SUMIFS('Per Line'!$O$2:$O$3001,'Per Line'!$B$2:$B$3001,$B7,'Per Line'!$AB$2:$AB$3001,1)) | R7: =IF($W7="","",Q7*P7) | S7: =IF($W7="","",R7+O7) | T7: =IF($W7="","",V7-S7) | U7: =IF($W7="","",V7-S7-K7) | V7: =IF($W7="","",N7+Q7) | W7: =IF(ROWS($W$2:$W7)<=MAX('Per Line'!$AA$2:$AA$3001),MATCH(ROWS($W$2:$W7),'Per Line'!$AA$2:$AA$3001,0),"") | X7: =IF($W7="","",D7&"|"&COUNTIF($D$2:$D7,D7))
B8: =IF($W8="","",INDEX('Per Line'!$B$2:$B$3001,$W8)&"") | C8: =IF($W8="","",INDEX('Per Line'!$C$2:$C$3001,$W8)&"") | D8: =IF($W8="","",IF(OR(TRIM(E8)="Orient Insurance Company",TRIM(E8)="Allianz"),TRIM(E8),TRIM(F8))) | E8: =IF($W8="","",INDEX('Per Line'!$E$2:$E$3001,$W8)&"") | F8: =IF($W8="","",INDEX('Per Line'!$D$2:$D$3001,$W8)&"") | G8: =IF($W8="","",INDEX('Per Line'!$F$2:$F$3001,$W8)&"") | H8: =IF($W8="","",INDEX('Per Line'!$G$2:$G$3001,$W8)&"") | I8: =IF($W8="","",INDEX('Per Line'!$H$2:$H$3001,$W8)&"") | J8: =IF($W8="","",INDEX('Per Line'!$I$2:$I$3001,$W8)) | K8: =IF($W8="","",J8*T8/100) | L8: =IF($W8="","",INDEX('Per Line'!$V$2:$V$3001,$W8)) | M8: =IF($W8="","",IF(ISNUMBER(SEARCH("3&12",SUBSTITUTE(F8," ",""))),Settings!$G$7,Settings!$C$7)) | N8: =IF($W8="","",SUMIFS('Per Line'!$O$2:$O$3001,'Per Line'!$B$2:$B$3001,$B8,'Per Line'!$AB$2:$AB$3001,0)) | O8: =IF($W8="","",N8*M8) | P8: =IF($W8="","",IF(ISNUMBER(SEARCH("3&12",SUBSTITUTE(F8," ",""))),Settings!$G$6,Settings!$C$6)) | Q8: =IF($W8="","",SUMIFS('Per Line'!$O$2:$O$3001,'Per Line'!$B$2:$B$3001,$B8,'Per Line'!$AB$2:$AB$3001,1)) | R8: =IF($W8="","",Q8*P8) | S8: =IF($W8="","",R8+O8) | T8: =IF($W8="","",V8-S8) | U8: =IF($W8="","",V8-S8-K8) | V8: =IF($W8="","",N8+Q8) | W8: =IF(ROWS($W$2:$W8)<=MAX('Per Line'!$AA$2:$AA$3001),MATCH(ROWS($W$2:$W8),'Per Line'!$AA$2:$AA$3001,0),"") | X8: =IF($W8="","",D8&"|"&COUNTIF($D$2:$D8,D8))
B9: =IF($W9="","",INDEX('Per Line'!$B$2:$B$3001,$W9)&"") | C9: =IF($W9="","",INDEX('Per Line'!$C$2:$C$3001,$W9)&"") | D9: =IF($W9="","",IF(OR(TRIM(E9)="Orient Insurance Company",TRIM(E9)="Allianz"),TRIM(E9),TRIM(F9))) | E9: =IF($W9="","",INDEX('Per Line'!$E$2:$E$3001,$W9)&"") | F9: =IF($W9="","",INDEX('Per Line'!$D$2:$D$3001,$W9)&"") | G9: =IF($W9="","",INDEX('Per Line'!$F$2:$F$3001,$W9)&"") | H9: =IF($W9="","",INDEX('Per Line'!$G$2:$G$3001,$W9)&"") | I9: =IF($W9="","",INDEX('Per Line'!$H$2:$H$3001,$W9)&"") | J9: =IF($W9="","",INDEX('Per Line'!$I$2:$I$3001,$W9)) | K9: =IF($W9="","",J9*T9/100) | L9: =IF($W9="","",INDEX('Per Line'!$V$2:$V$3001,$W9)) | M9: =IF($W9="","",IF(ISNUMBER(SEARCH("3&12",SUBSTITUTE(F9," ",""))),Settings!$G$7,Settings!$C$7)) | N9: =IF($W9="","",SUMIFS('Per Line'!$O$2:$O$3001,'Per Line'!$B$2:$B$3001,$B9,'Per Line'!$AB$2:$AB$3001,0)) | O9: =IF($W9="","",N9*M9) | P9: =IF($W9="","",IF(ISNUMBER(SEARCH("3&12",SUBSTITUTE(F9," ",""))),Settings!$G$6,Settings!$C$6)) | Q9: =IF($W9="","",SUMIFS('Per Line'!$O$2:$O$3001,'Per Line'!$B$2:$B$3001,$B9,'Per Line'!$AB$2:$AB$3001,1)) | R9: =IF($W9="","",Q9*P9) | S9: =IF($W9="","",R9+O9) | T9: =IF($W9="","",V9-S9) | U9: =IF($W9="","",V9-S9-K9) | V9: =IF($W9="","",N9+Q9) | W9: =IF(ROWS($W$2:$W9)<=MAX('Per Line'!$AA$2:$AA$3001),MATCH(ROWS($W$2:$W9),'Per Line'!$AA$2:$AA$3001,0),"") | X9: =IF($W9="","",D9&"|"&COUNTIF($D$2:$D9,D9))
B10: =IF($W10="","",INDEX('Per Line'!$B$2:$B$3001,$W10)&"") | C10: =IF($W10="","",INDEX('Per Line'!$C$2:$C$3001,$W10)&"") | D10: =IF($W10="","",IF(OR(TRIM(E10)="Orient Insurance Company",TRIM(E10)="Allianz"),TRIM(E10),TRIM(F10))) | E10: =IF($W10="","",INDEX('Per Line'!$E$2:$E$3001,$W10)&"") | F10: =IF($W10="","",INDEX('Per Line'!$D$2:$D$3001,$W10)&"") | G10: =IF($W10="","",INDEX('Per Line'!$F$2:$F$3001,$W10)&"") | H10: =IF($W10="","",INDEX('Per Line'!$G$2:$G$3001,$W10)&"") | I10: =IF($W10="","",INDEX('Per Line'!$H$2:$H$3001,$W10)&"") | J10: =IF($W10="","",INDEX('Per Line'!$I$2:$I$3001,$W10)) | K10: =IF($W10="","",J10*T10/100) | L10: =IF($W10="","",INDEX('Per Line'!$V$2:$V$3001,$W10)) | M10: =IF($W10="","",IF(ISNUMBER(SEARCH("3&12",SUBSTITUTE(F10," ",""))),Settings!$G$7,Settings!$C$7)) | N10: =IF($W10="","",SUMIFS('Per Line'!$O$2:$O$3001,'Per Line'!$B$2:$B$3001,$B10,'Per Line'!$AB$2:$AB$3001,0)) | O10: =IF($W10="","",N10*M10) | P10: =IF($W10="","",IF(ISNUMBER(SEARCH("3&12",SUBSTITUTE(F10," ",""))),Settings!$G$6,Settings!$C$6)) | Q10: =IF($W10="","",SUMIFS('Per Line'!$O$2:$O$3001,'Per Line'!$B$2:$B$3001,$B10,'Per Line'!$AB$2:$AB$3001,1)) | R10: =IF($W10="","",Q10*P10) | S10: =IF($W10="","",R10+O10) | T10: =IF($W10="","",V10-S10) | U10: =IF($W10="","",V10-S10-K10) | V10: =IF($W10="","",N10+Q10) | W10: =IF(ROWS($W$2:$W10)<=MAX('Per Line'!$AA$2:$AA$3001),MATCH(ROWS($W$2:$W10),'Per Line'!$AA$2:$AA$3001,0),"") | X10: =IF($W10="","",D10&"|"&COUNTIF($D$2:$D10,D10))
B11: =IF($W11="","",INDEX('Per Line'!$B$2:$B$3001,$W11)&"") | C11: =IF($W11="","",INDEX('Per Line'!$C$2:$C$3001,$W11)&"") | D11: =IF($W11="","",IF(OR(TRIM(E11)="Orient Insurance Company",TRIM(E11)="Allianz"),TRIM(E11),TRIM(F11))) | E11: =IF($W11="","",INDEX('Per Line'!$E$2:$E$3001,$W11)&"") | F11: =IF($W11="","",INDEX('Per Line'!$D$2:$D$3001,$W11)&"") | G11: =IF($W11="","",INDEX('Per Line'!$F$2:$F$3001,$W11)&"") | H11: =IF($W11="","",INDEX('Per Line'!$G$2:$G$3001,$W11)&"") | I11: =IF($W11="","",INDEX('Per Line'!$H$2:$H$3001,$W11)&"") | J11: =IF($W11="","",INDEX('Per Line'!$I$2:$I$3001,$W11)) | K11: =IF($W11="","",J11*T11/100) | L11: =IF($W11="","",INDEX('Per Line'!$V$2:$V$3001,$W11)) | M11: =IF($W11="","",IF(ISNUMBER(SEARCH("3&12",SUBSTITUTE(F11," ",""))),Settings!$G$7,Settings!$C$7)) | N11: =IF($W11="","",SUMIFS('Per Line'!$O$2:$O$3001,'Per Line'!$B$2:$B$3001,$B11,'Per Line'!$AB$2:$AB$3001,0)) | O11: =IF($W11="","",N11*M11) | P11: =IF($W11="","",IF(ISNUMBER(SEARCH("3&12",SUBSTITUTE(F11," ",""))),Settings!$G$6,Settings!$C$6)) | Q11: =IF($W11="","",SUMIFS('Per Line'!$O$2:$O$3001,'Per Line'!$B$2:$B$3001,$B11,'Per Line'!$AB$2:$AB$3001,1)) | R11: =IF($W11="","",Q11*P11) | S11: =IF($W11="","",R11+O11) | T11: =IF($W11="","",V11-S11) | U11: =IF($W11="","",V11-S11-K11) | V11: =IF($W11="","",N11+Q11) | W11: =IF(ROWS($W$2:$W11)<=MAX('Per Line'!$AA$2:$AA$3001),MATCH(ROWS($W$2:$W11),'Per Line'!$AA$2:$AA$3001,0),"") | X11: =IF($W11="","",D11&"|"&COUNTIF($D$2:$D11,D11))
B12: =IF($W12="","",INDEX('Per Line'!$B$2:$B$3001,$W12)&"") | C12: =IF($W12="","",INDEX('Per Line'!$C$2:$C$3001,$W12)&"") | D12: =IF($W12="","",IF(OR(TRIM(E12)="Orient Insurance Company",TRIM(E12)="Allianz"),TRIM(E12),TRIM(F12))) | E12: =IF($W12="","",INDEX('Per Line'!$E$2:$E$3001,$W12)&"") | F12: =IF($W12="","",INDEX('Per Line'!$D$2:$D$3001,$W12)&"") | G12: =IF($W12="","",INDEX('Per Line'!$F$2:$F$3001,$W12)&"") | H12: =IF($W12="","",INDEX('Per Line'!$G$2:$G$3001,$W12)&"") | I12: =IF($W12="","",INDEX('Per Line'!$H$2:$H$3001,$W12)&"") | J12: =IF($W12="","",INDEX('Per Line'!$I$2:$I$3001,$W12)) | K12: =IF($W12="","",J12*T12/100) | L12: =IF($W12="","",INDEX('Per Line'!$V$2:$V$3001,$W12)) | M12: =IF($W12="","",IF(ISNUMBER(SEARCH("3&12",SUBSTITUTE(F12," ",""))),Settings!$G$7,Settings!$C$7)) | N12: =IF($W12="","",SUMIFS('Per Line'!$O$2:$O$3001,'Per Line'!$B$2:$B$3001,$B12,'Per Line'!$AB$2:$AB$3001,0)) | O12: =IF($W12="","",N12*M12) | P12: =IF($W12="","",IF(ISNUMBER(SEARCH("3&12",SUBSTITUTE(F12," ",""))),Settings!$G$6,Settings!$C$6)) | Q12: =IF($W12="","",SUMIFS('Per Line'!$O$2:$O$3001,'Per Line'!$B$2:$B$3001,$B12,'Per Line'!$AB$2:$AB$3001,1)) | R12: =IF($W12="","",Q12*P12) | S12: =IF($W12="","",R12+O12) | T12: =IF($W12="","",V12-S12) | U12: =IF($W12="","",V12-S12-K12) | V12: =IF($W12="","",N12+Q12) | W12: =IF(ROWS($W$2:$W12)<=MAX('Per Line'!$AA$2:$AA$3001),MATCH(ROWS($W$2:$W12),'Per Line'!$AA$2:$AA$3001,0),"") | X12: =IF($W12="","",D12&"|"&COUNTIF($D$2:$D12,D12))
B13: =IF($W13="","",INDEX('Per Line'!$B$2:$B$3001,$W13)&"") | C13: =IF($W13="","",INDEX('Per Line'!$C$2:$C$3001,$W13)&"") | D13: =IF($W13="","",IF(OR(TRIM(E13)="Orient Insurance Company",TRIM(E13)="Allianz"),TRIM(E13),TRIM(F13))) | E13: =IF($W13="","",INDEX('Per Line'!$E$2:$E$3001,$W13)&"") | F13: =IF($W13="","",INDEX('Per Line'!$D$2:$D$3001,$W13)&"") | G13: =IF($W13="","",INDEX('Per Line'!$F$2:$F$3001,$W13)&"") | H13: =IF($W13="","",INDEX('Per Line'!$G$2:$G$3001,$W13)&"") | I13: =IF($W13="","",INDEX('Per Line'!$H$2:$H$3001,$W13)&"") | J13: =IF($W13="","",INDEX('Per Line'!$I$2:$I$3001,$W13)) | K13: =IF($W13="","",J13*T13/100) | L13: =IF($W13="","",INDEX('Per Line'!$V$2:$V$3001,$W13)) | M13: =IF($W13="","",IF(ISNUMBER(SEARCH("3&12",SUBSTITUTE(F13," ",""))),Settings!$G$7,Settings!$C$7)) | N13: =IF($W13="","",SUMIFS('Per Line'!$O$2:$O$3001,'Per Line'!$B$2:$B$3001,$B13,'Per Line'!$AB$2:$AB$3001,0)) | O13: =IF($W13="","",N13*M13) | P13: =IF($W13="","",IF(ISNUMBER(SEARCH("3&12",SUBSTITUTE(F13," ",""))),Settings!$G$6,Settings!$C$6)) | Q13: =IF($W13="","",SUMIFS('Per Line'!$O$2:$O$3001,'Per Line'!$B$2:$B$3001,$B13,'Per Line'!$AB$2:$AB$3001,1)) | R13: =IF($W13="","",Q13*P13) | S13: =IF($W13="","",R13+O13) | T13: =IF($W13="","",V13-S13) | U13: =IF($W13="","",V13-S13-K13) | V13: =IF($W13="","",N13+Q13) | W13: =IF(ROWS($W$2:$W13)<=MAX('Per Line'!$AA$2:$AA$3001),MATCH(ROWS($W$2:$W13),'Per Line'!$AA$2:$AA$3001,0),"") | X13: =IF($W13="","",D13&"|"&COUNTIF($D$2:$D13,D13))
... B801: =IF($W801="","",INDEX('Per Line'!$B$2:$B$3001,$W801)&"") | C801: =IF($W801="","",INDEX('Per Line'!$C$2:$C$3001,$W801)&"") | D801: =IF($W801="","",IF(OR(TRIM(E801)="Orient Insurance Company",TRIM(E801)="Allianz"),TRIM(E801),TRIM(F801))) | E801: =IF($W801="","",INDEX('Per Line'!$E$2:$E$3001,$W801)&"") | F801: =IF($W801="","",INDEX('Per Line'!$D$2:$D$3001,$W801)&"") | G801: =IF($W801="","",INDEX('Per Line'!$F$2:$F$3001,$W801)&"") | H801: =IF($W801="","",INDEX('Per Line'!$G$2:$G$3001,$W801)&"") | I801: =IF($W801="","",INDEX('Per Line'!$H$2:$H$3001,$W801)&"") | J801: =IF($W801="","",INDEX('Per Line'!$I$2:$I$3001,$W801)) | K801: =IF($W801="","",J801*T801/100) | L801: =IF($W801="","",INDEX('Per Line'!$V$2:$V$3001,$W801)) | M801: =IF($W801="","",IF(ISNUMBER(SEARCH("3&12",SUBSTITUTE(F801," ",""))),Settings!$G$7,Settings!$C$7)) | N801: =IF($W801="","",SUMIFS('Per Line'!$O$2:$O$3001,'Per Line'!$B$2:$B$3001,$B801,'Per Line'!$AB$2:$AB$3001,0)) | O801: =IF($W801="","",N801*M801) | P801: =IF($W801="","",IF(ISNUMBER(SEARCH("3&12",SUBSTITUTE(F801," ",""))),Settings!$G$6,Settings!$C$6)) | Q801: =IF($W801="","",SUMIFS('Per Line'!$O$2:$O$3001,'Per Line'!$B$2:$B$3001,$B801,'Per Line'!$AB$2:$AB$3001,1)) | R801: =IF($W801="","",Q801*P801) | S801: =IF($W801="","",R801+O801) | T801: =IF($W801="","",V801-S801) | U801: =IF($W801="","",V801-S801-K801) | V801: =IF($W801="","",N801+Q801) | W801: =IF(ROWS($W$2:$W801)<=MAX('Per Line'!$AA$2:$AA$3001),MATCH(ROWS($W$2:$W801),'Per Line'!$AA$2:$AA$3001,0),"") | X801: =IF($W801="","",D801&"|"&COUNTIF($D$2:$D801,D801))

Sheet Orient
A1: Invoice | B1: Pos Reference | C1: Approval | D1: ## | E1: Payer | F1: Payment term | G1: Insurance Company | H1: Name | I1: Card Number | J1: Co Payment % | K1: Co val | L1: Create Date | M1: Imp% | N1: Imp | O1: Imp_Val | P1: Local% | Q1: Local | R1: Local_Val | S1: Discount | T1: Subtotal | U1: Net | V1: Grand Total | W1: Src Row (helper)
A2: =IF($W2="","",IF(INDEX('Per Invoice'!A$2:A$801,$W2)="","",INDEX('Per Invoice'!A$2:A$801,$W2))) | B2: =IF($W2="","",IF(INDEX('Per Invoice'!B$2:B$801,$W2)="","",INDEX('Per Invoice'!B$2:B$801,$W2))) | C2: =IF($W2="","",IF(INDEX('Per Invoice'!C$2:C$801,$W2)="","",INDEX('Per Invoice'!C$2:C$801,$W2))) | D2: =IF($W2="","",IF(INDEX('Per Invoice'!D$2:D$801,$W2)="","",INDEX('Per Invoice'!D$2:D$801,$W2))) | E2: =IF($W2="","",IF(INDEX('Per Invoice'!E$2:E$801,$W2)="","",INDEX('Per Invoice'!E$2:E$801,$W2))) | F2: =IF($W2="","",IF(INDEX('Per Invoice'!F$2:F$801,$W2)="","",INDEX('Per Invoice'!F$2:F$801,$W2))) | G2: =IF($W2="","",IF(INDEX('Per Invoice'!G$2:G$801,$W2)="","",INDEX('Per Invoice'!G$2:G$801,$W2))) | H2: =IF($W2="","",IF(INDEX('Per Invoice'!H$2:H$801,$W2)="","",INDEX('Per Invoice'!H$2:H$801,$W2))) | ... V2: =IF($W2="","",IF(INDEX('Per Invoice'!V$2:V$801,$W2)="","",INDEX('Per Invoice'!V$2:V$801,$W2))) | W2: =IFERROR(MATCH(Settings!$C$26&"|"&ROWS($W$2:$W2),'Per Invoice'!$X$2:$X$801,0),"")
A3: =IF($W3="","",IF(INDEX('Per Invoice'!A$2:A$801,$W3)="","",INDEX('Per Invoice'!A$2:A$801,$W3))) | B3: =IF($W3="","",IF(INDEX('Per Invoice'!B$2:B$801,$W3)="","",INDEX('Per Invoice'!B$2:B$801,$W3))) | C3: =IF($W3="","",IF(INDEX('Per Invoice'!C$2:C$801,$W3)="","",INDEX('Per Invoice'!C$2:C$801,$W3))) | D3: =IF($W3="","",IF(INDEX('Per Invoice'!D$2:D$801,$W3)="","",INDEX('Per Invoice'!D$2:D$801,$W3))) | E3: =IF($W3="","",IF(INDEX('Per Invoice'!E$2:E$801,$W3)="","",INDEX('Per Invoice'!E$2:E$801,$W3))) | F3: =IF($W3="","",IF(INDEX('Per Invoice'!F$2:F$801,$W3)="","",INDEX('Per Invoice'!F$2:F$801,$W3))) | G3: =IF($W3="","",IF(INDEX('Per Invoice'!G$2:G$801,$W3)="","",INDEX('Per Invoice'!G$2:G$801,$W3))) | H3: =IF($W3="","",IF(INDEX('Per Invoice'!H$2:H$801,$W3)="","",INDEX('Per Invoice'!H$2:H$801,$W3))) | ... V3: =IF($W3="","",IF(INDEX('Per Invoice'!V$2:V$801,$W3)="","",INDEX('Per Invoice'!V$2:V$801,$W3))) | W3: =IFERROR(MATCH(Settings!$C$26&"|"&ROWS($W$2:$W3),'Per Invoice'!$X$2:$X$801,0),"")
A4: =IF($W4="","",IF(INDEX('Per Invoice'!A$2:A$801,$W4)="","",INDEX('Per Invoice'!A$2:A$801,$W4))) | B4: =IF($W4="","",IF(INDEX('Per Invoice'!B$2:B$801,$W4)="","",INDEX('Per Invoice'!B$2:B$801,$W4))) | C4: =IF($W4="","",IF(INDEX('Per Invoice'!C$2:C$801,$W4)="","",INDEX('Per Invoice'!C$2:C$801,$W4))) | D4: =IF($W4="","",IF(INDEX('Per Invoice'!D$2:D$801,$W4)="","",INDEX('Per Invoice'!D$2:D$801,$W4))) | E4: =IF($W4="","",IF(INDEX('Per Invoice'!E$2:E$801,$W4)="","",INDEX('Per Invoice'!E$2:E$801,$W4))) | F4: =IF($W4="","",IF(INDEX('Per Invoice'!F$2:F$801,$W4)="","",INDEX('Per Invoice'!F$2:F$801,$W4))) | G4: =IF($W4="","",IF(INDEX('Per Invoice'!G$2:G$801,$W4)="","",INDEX('Per Invoice'!G$2:G$801,$W4))) | H4: =IF($W4="","",IF(INDEX('Per Invoice'!H$2:H$801,$W4)="","",INDEX('Per Invoice'!H$2:H$801,$W4))) | ... V4: =IF($W4="","",IF(INDEX('Per Invoice'!V$2:V$801,$W4)="","",INDEX('Per Invoice'!V$2:V$801,$W4))) | W4: =IFERROR(MATCH(Settings!$C$26&"|"&ROWS($W$2:$W4),'Per Invoice'!$X$2:$X$801,0),"")
A5: =IF($W5="","",IF(INDEX('Per Invoice'!A$2:A$801,$W5)="","",INDEX('Per Invoice'!A$2:A$801,$W5))) | B5: =IF($W5="","",IF(INDEX('Per Invoice'!B$2:B$801,$W5)="","",INDEX('Per Invoice'!B$2:B$801,$W5))) | C5: =IF($W5="","",IF(INDEX('Per Invoice'!C$2:C$801,$W5)="","",INDEX('Per Invoice'!C$2:C$801,$W5))) | D5: =IF($W5="","",IF(INDEX('Per Invoice'!D$2:D$801,$W5)="","",INDEX('Per Invoice'!D$2:D$801,$W5))) | E5: =IF($W5="","",IF(INDEX('Per Invoice'!E$2:E$801,$W5)="","",INDEX('Per Invoice'!E$2:E$801,$W5))) | F5: =IF($W5="","",IF(INDEX('Per Invoice'!F$2:F$801,$W5)="","",INDEX('Per Invoice'!F$2:F$801,$W5))) | G5: =IF($W5="","",IF(INDEX('Per Invoice'!G$2:G$801,$W5)="","",INDEX('Per Invoice'!G$2:G$801,$W5))) | H5: =IF($W5="","",IF(INDEX('Per Invoice'!H$2:H$801,$W5)="","",INDEX('Per Invoice'!H$2:H$801,$W5))) | ... V5: =IF($W5="","",IF(INDEX('Per Invoice'!V$2:V$801,$W5)="","",INDEX('Per Invoice'!V$2:V$801,$W5))) | W5: =IFERROR(MATCH(Settings!$C$26&"|"&ROWS($W$2:$W5),'Per Invoice'!$X$2:$X$801,0),"")
A6: =IF($W6="","",IF(INDEX('Per Invoice'!A$2:A$801,$W6)="","",INDEX('Per Invoice'!A$2:A$801,$W6))) | B6: =IF($W6="","",IF(INDEX('Per Invoice'!B$2:B$801,$W6)="","",INDEX('Per Invoice'!B$2:B$801,$W6))) | C6: =IF($W6="","",IF(INDEX('Per Invoice'!C$2:C$801,$W6)="","",INDEX('Per Invoice'!C$2:C$801,$W6))) | D6: =IF($W6="","",IF(INDEX('Per Invoice'!D$2:D$801,$W6)="","",INDEX('Per Invoice'!D$2:D$801,$W6))) | E6: =IF($W6="","",IF(INDEX('Per Invoice'!E$2:E$801,$W6)="","",INDEX('Per Invoice'!E$2:E$801,$W6))) | F6: =IF($W6="","",IF(INDEX('Per Invoice'!F$2:F$801,$W6)="","",INDEX('Per Invoice'!F$2:F$801,$W6))) | G6: =IF($W6="","",IF(INDEX('Per Invoice'!G$2:G$801,$W6)="","",INDEX('Per Invoice'!G$2:G$801,$W6))) | H6: =IF($W6="","",IF(INDEX('Per Invoice'!H$2:H$801,$W6)="","",INDEX('Per Invoice'!H$2:H$801,$W6))) | ... V6: =IF($W6="","",IF(INDEX('Per Invoice'!V$2:V$801,$W6)="","",INDEX('Per Invoice'!V$2:V$801,$W6))) | W6: =IFERROR(MATCH(Settings!$C$26&"|"&ROWS($W$2:$W6),'Per Invoice'!$X$2:$X$801,0),"")
A7: =IF($W7="","",IF(INDEX('Per Invoice'!A$2:A$801,$W7)="","",INDEX('Per Invoice'!A$2:A$801,$W7))) | B7: =IF($W7="","",IF(INDEX('Per Invoice'!B$2:B$801,$W7)="","",INDEX('Per Invoice'!B$2:B$801,$W7))) | C7: =IF($W7="","",IF(INDEX('Per Invoice'!C$2:C$801,$W7)="","",INDEX('Per Invoice'!C$2:C$801,$W7))) | D7: =IF($W7="","",IF(INDEX('Per Invoice'!D$2:D$801,$W7)="","",INDEX('Per Invoice'!D$2:D$801,$W7))) | E7: =IF($W7="","",IF(INDEX('Per Invoice'!E$2:E$801,$W7)="","",INDEX('Per Invoice'!E$2:E$801,$W7))) | F7: =IF($W7="","",IF(INDEX('Per Invoice'!F$2:F$801,$W7)="","",INDEX('Per Invoice'!F$2:F$801,$W7))) | G7: =IF($W7="","",IF(INDEX('Per Invoice'!G$2:G$801,$W7)="","",INDEX('Per Invoice'!G$2:G$801,$W7))) | H7: =IF($W7="","",IF(INDEX('Per Invoice'!H$2:H$801,$W7)="","",INDEX('Per Invoice'!H$2:H$801,$W7))) | ... V7: =IF($W7="","",IF(INDEX('Per Invoice'!V$2:V$801,$W7)="","",INDEX('Per Invoice'!V$2:V$801,$W7))) | W7: =IFERROR(MATCH(Settings!$C$26&"|"&ROWS($W$2:$W7),'Per Invoice'!$X$2:$X$801,0),"")
A8: =IF($W8="","",IF(INDEX('Per Invoice'!A$2:A$801,$W8)="","",INDEX('Per Invoice'!A$2:A$801,$W8))) | B8: =IF($W8="","",IF(INDEX('Per Invoice'!B$2:B$801,$W8)="","",INDEX('Per Invoice'!B$2:B$801,$W8))) | C8: =IF($W8="","",IF(INDEX('Per Invoice'!C$2:C$801,$W8)="","",INDEX('Per Invoice'!C$2:C$801,$W8))) | D8: =IF($W8="","",IF(INDEX('Per Invoice'!D$2:D$801,$W8)="","",INDEX('Per Invoice'!D$2:D$801,$W8))) | E8: =IF($W8="","",IF(INDEX('Per Invoice'!E$2:E$801,$W8)="","",INDEX('Per Invoice'!E$2:E$801,$W8))) | F8: =IF($W8="","",IF(INDEX('Per Invoice'!F$2:F$801,$W8)="","",INDEX('Per Invoice'!F$2:F$801,$W8))) | G8: =IF($W8="","",IF(INDEX('Per Invoice'!G$2:G$801,$W8)="","",INDEX('Per Invoice'!G$2:G$801,$W8))) | H8: =IF($W8="","",IF(INDEX('Per Invoice'!H$2:H$801,$W8)="","",INDEX('Per Invoice'!H$2:H$801,$W8))) | ... V8: =IF($W8="","",IF(INDEX('Per Invoice'!V$2:V$801,$W8)="","",INDEX('Per Invoice'!V$2:V$801,$W8))) | W8: =IFERROR(MATCH(Settings!$C$26&"|"&ROWS($W$2:$W8),'Per Invoice'!$X$2:$X$801,0),"")
A9: =IF($W9="","",IF(INDEX('Per Invoice'!A$2:A$801,$W9)="","",INDEX('Per Invoice'!A$2:A$801,$W9))) | B9: =IF($W9="","",IF(INDEX('Per Invoice'!B$2:B$801,$W9)="","",INDEX('Per Invoice'!B$2:B$801,$W9))) | C9: =IF($W9="","",IF(INDEX('Per Invoice'!C$2:C$801,$W9)="","",INDEX('Per Invoice'!C$2:C$801,$W9))) | D9: =IF($W9="","",IF(INDEX('Per Invoice'!D$2:D$801,$W9)="","",INDEX('Per Invoice'!D$2:D$801,$W9))) | E9: =IF($W9="","",IF(INDEX('Per Invoice'!E$2:E$801,$W9)="","",INDEX('Per Invoice'!E$2:E$801,$W9))) | F9: =IF($W9="","",IF(INDEX('Per Invoice'!F$2:F$801,$W9)="","",INDEX('Per Invoice'!F$2:F$801,$W9))) | G9: =IF($W9="","",IF(INDEX('Per Invoice'!G$2:G$801,$W9)="","",INDEX('Per Invoice'!G$2:G$801,$W9))) | H9: =IF($W9="","",IF(INDEX('Per Invoice'!H$2:H$801,$W9)="","",INDEX('Per Invoice'!H$2:H$801,$W9))) | ... V9: =IF($W9="","",IF(INDEX('Per Invoice'!V$2:V$801,$W9)="","",INDEX('Per Invoice'!V$2:V$801,$W9))) | W9: =IFERROR(MATCH(Settings!$C$26&"|"&ROWS($W$2:$W9),'Per Invoice'!$X$2:$X$801,0),"")
A10: =IF($W10="","",IF(INDEX('Per Invoice'!A$2:A$801,$W10)="","",INDEX('Per Invoice'!A$2:A$801,$W10))) | B10: =IF($W10="","",IF(INDEX('Per Invoice'!B$2:B$801,$W10)="","",INDEX('Per Invoice'!B$2:B$801,$W10))) | C10: =IF($W10="","",IF(INDEX('Per Invoice'!C$2:C$801,$W10)="","",INDEX('Per Invoice'!C$2:C$801,$W10))) | D10: =IF($W10="","",IF(INDEX('Per Invoice'!D$2:D$801,$W10)="","",INDEX('Per Invoice'!D$2:D$801,$W10))) | E10: =IF($W10="","",IF(INDEX('Per Invoice'!E$2:E$801,$W10)="","",INDEX('Per Invoice'!E$2:E$801,$W10))) | F10: =IF($W10="","",IF(INDEX('Per Invoice'!F$2:F$801,$W10)="","",INDEX('Per Invoice'!F$2:F$801,$W10))) | G10: =IF($W10="","",IF(INDEX('Per Invoice'!G$2:G$801,$W10)="","",INDEX('Per Invoice'!G$2:G$801,$W10))) | H10: =IF($W10="","",IF(INDEX('Per Invoice'!H$2:H$801,$W10)="","",INDEX('Per Invoice'!H$2:H$801,$W10))) | ... V10: =IF($W10="","",IF(INDEX('Per Invoice'!V$2:V$801,$W10)="","",INDEX('Per Invoice'!V$2:V$801,$W10))) | W10: =IFERROR(MATCH(Settings!$C$26&"|"&ROWS($W$2:$W10),'Per Invoice'!$X$2:$X$801,0),"")
A11: =IF($W11="","",IF(INDEX('Per Invoice'!A$2:A$801,$W11)="","",INDEX('Per Invoice'!A$2:A$801,$W11))) | B11: =IF($W11="","",IF(INDEX('Per Invoice'!B$2:B$801,$W11)="","",INDEX('Per Invoice'!B$2:B$801,$W11))) | C11: =IF($W11="","",IF(INDEX('Per Invoice'!C$2:C$801,$W11)="","",INDEX('Per Invoice'!C$2:C$801,$W11))) | D11: =IF($W11="","",IF(INDEX('Per Invoice'!D$2:D$801,$W11)="","",INDEX('Per Invoice'!D$2:D$801,$W11))) | E11: =IF($W11="","",IF(INDEX('Per Invoice'!E$2:E$801,$W11)="","",INDEX('Per Invoice'!E$2:E$801,$W11))) | F11: =IF($W11="","",IF(INDEX('Per Invoice'!F$2:F$801,$W11)="","",INDEX('Per Invoice'!F$2:F$801,$W11))) | G11: =IF($W11="","",IF(INDEX('Per Invoice'!G$2:G$801,$W11)="","",INDEX('Per Invoice'!G$2:G$801,$W11))) | H11: =IF($W11="","",IF(INDEX('Per Invoice'!H$2:H$801,$W11)="","",INDEX('Per Invoice'!H$2:H$801,$W11))) | ... V11: =IF($W11="","",IF(INDEX('Per Invoice'!V$2:V$801,$W11)="","",INDEX('Per Invoice'!V$2:V$801,$W11))) | W11: =IFERROR(MATCH(Settings!$C$26&"|"&ROWS($W$2:$W11),'Per Invoice'!$X$2:$X$801,0),"")
A12: =IF($W12="","",IF(INDEX('Per Invoice'!A$2:A$801,$W12)="","",INDEX('Per Invoice'!A$2:A$801,$W12))) | B12: =IF($W12="","",IF(INDEX('Per Invoice'!B$2:B$801,$W12)="","",INDEX('Per Invoice'!B$2:B$801,$W12))) | C12: =IF($W12="","",IF(INDEX('Per Invoice'!C$2:C$801,$W12)="","",INDEX('Per Invoice'!C$2:C$801,$W12))) | D12: =IF($W12="","",IF(INDEX('Per Invoice'!D$2:D$801,$W12)="","",INDEX('Per Invoice'!D$2:D$801,$W12))) | E12: =IF($W12="","",IF(INDEX('Per Invoice'!E$2:E$801,$W12)="","",INDEX('Per Invoice'!E$2:E$801,$W12))) | F12: =IF($W12="","",IF(INDEX('Per Invoice'!F$2:F$801,$W12)="","",INDEX('Per Invoice'!F$2:F$801,$W12))) | G12: =IF($W12="","",IF(INDEX('Per Invoice'!G$2:G$801,$W12)="","",INDEX('Per Invoice'!G$2:G$801,$W12))) | H12: =IF($W12="","",IF(INDEX('Per Invoice'!H$2:H$801,$W12)="","",INDEX('Per Invoice'!H$2:H$801,$W12))) | ... V12: =IF($W12="","",IF(INDEX('Per Invoice'!V$2:V$801,$W12)="","",INDEX('Per Invoice'!V$2:V$801,$W12))) | W12: =IFERROR(MATCH(Settings!$C$26&"|"&ROWS($W$2:$W12),'Per Invoice'!$X$2:$X$801,0),"")
A13: =IF($W13="","",IF(INDEX('Per Invoice'!A$2:A$801,$W13)="","",INDEX('Per Invoice'!A$2:A$801,$W13))) | B13: =IF($W13="","",IF(INDEX('Per Invoice'!B$2:B$801,$W13)="","",INDEX('Per Invoice'!B$2:B$801,$W13))) | C13: =IF($W13="","",IF(INDEX('Per Invoice'!C$2:C$801,$W13)="","",INDEX('Per Invoice'!C$2:C$801,$W13))) | D13: =IF($W13="","",IF(INDEX('Per Invoice'!D$2:D$801,$W13)="","",INDEX('Per Invoice'!D$2:D$801,$W13))) | E13: =IF($W13="","",IF(INDEX('Per Invoice'!E$2:E$801,$W13)="","",INDEX('Per Invoice'!E$2:E$801,$W13))) | F13: =IF($W13="","",IF(INDEX('Per Invoice'!F$2:F$801,$W13)="","",INDEX('Per Invoice'!F$2:F$801,$W13))) | G13: =IF($W13="","",IF(INDEX('Per Invoice'!G$2:G$801,$W13)="","",INDEX('Per Invoice'!G$2:G$801,$W13))) | H13: =IF($W13="","",IF(INDEX('Per Invoice'!H$2:H$801,$W13)="","",INDEX('Per Invoice'!H$2:H$801,$W13))) | ... V13: =IF($W13="","",IF(INDEX('Per Invoice'!V$2:V$801,$W13)="","",INDEX('Per Invoice'!V$2:V$801,$W13))) | W13: =IFERROR(MATCH(Settings!$C$26&"|"&ROWS($W$2:$W13),'Per Invoice'!$X$2:$X$801,0),"")
... A301: =IF($W301="","",IF(INDEX('Per Invoice'!A$2:A$801,$W301)="","",INDEX('Per Invoice'!A$2:A$801,$W301))) | B301: =IF($W301="","",IF(INDEX('Per Invoice'!B$2:B$801,$W301)="","",INDEX('Per Invoice'!B$2:B$801,$W301))) | C301: =IF($W301="","",IF(INDEX('Per Invoice'!C$2:C$801,$W301)="","",INDEX('Per Invoice'!C$2:C$801,$W301))) | D301: =IF($W301="","",IF(INDEX('Per Invoice'!D$2:D$801,$W301)="","",INDEX('Per Invoice'!D$2:D$801,$W301))) | E301: =IF($W301="","",IF(INDEX('Per Invoice'!E$2:E$801,$W301)="","",INDEX('Per Invoice'!E$2:E$801,$W301))) | F301: =IF($W301="","",IF(INDEX('Per Invoice'!F$2:F$801,$W301)="","",INDEX('Per Invoice'!F$2:F$801,$W301))) | G301: =IF($W301="","",IF(INDEX('Per Invoice'!G$2:G$801,$W301)="","",INDEX('Per Invoice'!G$2:G$801,$W301))) | H301: =IF($W301="","",IF(INDEX('Per Invoice'!H$2:H$801,$W301)="","",INDEX('Per Invoice'!H$2:H$801,$W301))) | ... V301: =IF($W301="","",IF(INDEX('Per Invoice'!V$2:V$801,$W301)="","",INDEX('Per Invoice'!V$2:V$801,$W301))) | W301: =IFERROR(MATCH(Settings!$C$26&"|"&ROWS($W$2:$W301),'Per Invoice'!$X$2:$X$801,0),"")

Sheet Allianz
A1: Invoice | B1: Pos Reference | C1: Approval | D1: ## | E1: Payer | F1: Payment term | G1: Insurance Company | H1: Name | I1: Card Number | J1: Co Payment % | K1: Co val | L1: Create Date | M1: Imp% | N1: Imp | O1: Imp_Val | P1: Local% | Q1: Local | R1: Local_Val | S1: Discount | T1: Subtotal | U1: Net | V1: Grand Total | W1: Src Row (helper)
A2: =IF($W2="","",IF(INDEX('Per Invoice'!A$2:A$801,$W2)="","",INDEX('Per Invoice'!A$2:A$801,$W2))) | B2: =IF($W2="","",IF(INDEX('Per Invoice'!B$2:B$801,$W2)="","",INDEX('Per Invoice'!B$2:B$801,$W2))) | C2: =IF($W2="","",IF(INDEX('Per Invoice'!C$2:C$801,$W2)="","",INDEX('Per Invoice'!C$2:C$801,$W2))) | D2: =IF($W2="","",IF(INDEX('Per Invoice'!D$2:D$801,$W2)="","",INDEX('Per Invoice'!D$2:D$801,$W2))) | E2: =IF($W2="","",IF(INDEX('Per Invoice'!E$2:E$801,$W2)="","",INDEX('Per Invoice'!E$2:E$801,$W2))) | F2: =IF($W2="","",IF(INDEX('Per Invoice'!F$2:F$801,$W2)="","",INDEX('Per Invoice'!F$2:F$801,$W2))) | G2: =IF($W2="","",IF(INDEX('Per Invoice'!G$2:G$801,$W2)="","",INDEX('Per Invoice'!G$2:G$801,$W2))) | H2: =IF($W2="","",IF(INDEX('Per Invoice'!H$2:H$801,$W2)="","",INDEX('Per Invoice'!H$2:H$801,$W2))) | ... V2: =IF($W2="","",IF(INDEX('Per Invoice'!V$2:V$801,$W2)="","",INDEX('Per Invoice'!V$2:V$801,$W2))) | W2: =IFERROR(MATCH(Settings!$C$27&"|"&ROWS($W$2:$W2),'Per Invoice'!$X$2:$X$801,0),"")
A3: =IF($W3="","",IF(INDEX('Per Invoice'!A$2:A$801,$W3)="","",INDEX('Per Invoice'!A$2:A$801,$W3))) | B3: =IF($W3="","",IF(INDEX('Per Invoice'!B$2:B$801,$W3)="","",INDEX('Per Invoice'!B$2:B$801,$W3))) | C3: =IF($W3="","",IF(INDEX('Per Invoice'!C$2:C$801,$W3)="","",INDEX('Per Invoice'!C$2:C$801,$W3))) | D3: =IF($W3="","",IF(INDEX('Per Invoice'!D$2:D$801,$W3)="","",INDEX('Per Invoice'!D$2:D$801,$W3))) | E3: =IF($W3="","",IF(INDEX('Per Invoice'!E$2:E$801,$W3)="","",INDEX('Per Invoice'!E$2:E$801,$W3))) | F3: =IF($W3="","",IF(INDEX('Per Invoice'!F$2:F$801,$W3)="","",INDEX('Per Invoice'!F$2:F$801,$W3))) | G3: =IF($W3="","",IF(INDEX('Per Invoice'!G$2:G$801,$W3)="","",INDEX('Per Invoice'!G$2:G$801,$W3))) | H3: =IF($W3="","",IF(INDEX('Per Invoice'!H$2:H$801,$W3)="","",INDEX('Per Invoice'!H$2:H$801,$W3))) | ... V3: =IF($W3="","",IF(INDEX('Per Invoice'!V$2:V$801,$W3)="","",INDEX('Per Invoice'!V$2:V$801,$W3))) | W3: =IFERROR(MATCH(Settings!$C$27&"|"&ROWS($W$2:$W3),'Per Invoice'!$X$2:$X$801,0),"")
A4: =IF($W4="","",IF(INDEX('Per Invoice'!A$2:A$801,$W4)="","",INDEX('Per Invoice'!A$2:A$801,$W4))) | B4: =IF($W4="","",IF(INDEX('Per Invoice'!B$2:B$801,$W4)="","",INDEX('Per Invoice'!B$2:B$801,$W4))) | C4: =IF($W4="","",IF(INDEX('Per Invoice'!C$2:C$801,$W4)="","",INDEX('Per Invoice'!C$2:C$801,$W4))) | D4: =IF($W4="","",IF(INDEX('Per Invoice'!D$2:D$801,$W4)="","",INDEX('Per Invoice'!D$2:D$801,$W4))) | E4: =IF($W4="","",IF(INDEX('Per Invoice'!E$2:E$801,$W4)="","",INDEX('Per Invoice'!E$2:E$801,$W4))) | F4: =IF($W4="","",IF(INDEX('Per Invoice'!F$2:F$801,$W4)="","",INDEX('Per Invoice'!F$2:F$801,$W4))) | G4: =IF($W4="","",IF(INDEX('Per Invoice'!G$2:G$801,$W4)="","",INDEX('Per Invoice'!G$2:G$801,$W4))) | H4: =IF($W4="","",IF(INDEX('Per Invoice'!H$2:H$801,$W4)="","",INDEX('Per Invoice'!H$2:H$801,$W4))) | ... V4: =IF($W4="","",IF(INDEX('Per Invoice'!V$2:V$801,$W4)="","",INDEX('Per Invoice'!V$2:V$801,$W4))) | W4: =IFERROR(MATCH(Settings!$C$27&"|"&ROWS($W$2:$W4),'Per Invoice'!$X$2:$X$801,0),"")
A5: =IF($W5="","",IF(INDEX('Per Invoice'!A$2:A$801,$W5)="","",INDEX('Per Invoice'!A$2:A$801,$W5))) | B5: =IF($W5="","",IF(INDEX('Per Invoice'!B$2:B$801,$W5)="","",INDEX('Per Invoice'!B$2:B$801,$W5))) | C5: =IF($W5="","",IF(INDEX('Per Invoice'!C$2:C$801,$W5)="","",INDEX('Per Invoice'!C$2:C$801,$W5))) | D5: =IF($W5="","",IF(INDEX('Per Invoice'!D$2:D$801,$W5)="","",INDEX('Per Invoice'!D$2:D$801,$W5))) | E5: =IF($W5="","",IF(INDEX('Per Invoice'!E$2:E$801,$W5)="","",INDEX('Per Invoice'!E$2:E$801,$W5))) | F5: =IF($W5="","",IF(INDEX('Per Invoice'!F$2:F$801,$W5)="","",INDEX('Per Invoice'!F$2:F$801,$W5))) | G5: =IF($W5="","",IF(INDEX('Per Invoice'!G$2:G$801,$W5)="","",INDEX('Per Invoice'!G$2:G$801,$W5))) | H5: =IF($W5="","",IF(INDEX('Per Invoice'!H$2:H$801,$W5)="","",INDEX('Per Invoice'!H$2:H$801,$W5))) | ... V5: =IF($W5="","",IF(INDEX('Per Invoice'!V$2:V$801,$W5)="","",INDEX('Per Invoice'!V$2:V$801,$W5))) | W5: =IFERROR(MATCH(Settings!$C$27&"|"&ROWS($W$2:$W5),'Per Invoice'!$X$2:$X$801,0),"")
A6: =IF($W6="","",IF(INDEX('Per Invoice'!A$2:A$801,$W6)="","",INDEX('Per Invoice'!A$2:A$801,$W6))) | B6: =IF($W6="","",IF(INDEX('Per Invoice'!B$2:B$801,$W6)="","",INDEX('Per Invoice'!B$2:B$801,$W6))) | C6: =IF($W6="","",IF(INDEX('Per Invoice'!C$2:C$801,$W6)="","",INDEX('Per Invoice'!C$2:C$801,$W6))) | D6: =IF($W6="","",IF(INDEX('Per Invoice'!D$2:D$801,$W6)="","",INDEX('Per Invoice'!D$2:D$801,$W6))) | E6: =IF($W6="","",IF(INDEX('Per Invoice'!E$2:E$801,$W6)="","",INDEX('Per Invoice'!E$2:E$801,$W6))) | F6: =IF($W6="","",IF(INDEX('Per Invoice'!F$2:F$801,$W6)="","",INDEX('Per Invoice'!F$2:F$801,$W6))) | G6: =IF($W6="","",IF(INDEX('Per Invoice'!G$2:G$801,$W6)="","",INDEX('Per Invoice'!G$2:G$801,$W6))) | H6: =IF($W6="","",IF(INDEX('Per Invoice'!H$2:H$801,$W6)="","",INDEX('Per Invoice'!H$2:H$801,$W6))) | ... V6: =IF($W6="","",IF(INDEX('Per Invoice'!V$2:V$801,$W6)="","",INDEX('Per Invoice'!V$2:V$801,$W6))) | W6: =IFERROR(MATCH(Settings!$C$27&"|"&ROWS($W$2:$W6),'Per Invoice'!$X$2:$X$801,0),"")
A7: =IF($W7="","",IF(INDEX('Per Invoice'!A$2:A$801,$W7)="","",INDEX('Per Invoice'!A$2:A$801,$W7))) | B7: =IF($W7="","",IF(INDEX('Per Invoice'!B$2:B$801,$W7)="","",INDEX('Per Invoice'!B$2:B$801,$W7))) | C7: =IF($W7="","",IF(INDEX('Per Invoice'!C$2:C$801,$W7)="","",INDEX('Per Invoice'!C$2:C$801,$W7))) | D7: =IF($W7="","",IF(INDEX('Per Invoice'!D$2:D$801,$W7)="","",INDEX('Per Invoice'!D$2:D$801,$W7))) | E7: =IF($W7="","",IF(INDEX('Per Invoice'!E$2:E$801,$W7)="","",INDEX('Per Invoice'!E$2:E$801,$W7))) | F7: =IF($W7="","",IF(INDEX('Per Invoice'!F$2:F$801,$W7)="","",INDEX('Per Invoice'!F$2:F$801,$W7))) | G7: =IF($W7="","",IF(INDEX('Per Invoice'!G$2:G$801,$W7)="","",INDEX('Per Invoice'!G$2:G$801,$W7))) | H7: =IF($W7="","",IF(INDEX('Per Invoice'!H$2:H$801,$W7)="","",INDEX('Per Invoice'!H$2:H$801,$W7))) | ... V7: =IF($W7="","",IF(INDEX('Per Invoice'!V$2:V$801,$W7)="","",INDEX('Per Invoice'!V$2:V$801,$W7))) | W7: =IFERROR(MATCH(Settings!$C$27&"|"&ROWS($W$2:$W7),'Per Invoice'!$X$2:$X$801,0),"")
A8: =IF($W8="","",IF(INDEX('Per Invoice'!A$2:A$801,$W8)="","",INDEX('Per Invoice'!A$2:A$801,$W8))) | B8: =IF($W8="","",IF(INDEX('Per Invoice'!B$2:B$801,$W8)="","",INDEX('Per Invoice'!B$2:B$801,$W8))) | C8: =IF($W8="","",IF(INDEX('Per Invoice'!C$2:C$801,$W8)="","",INDEX('Per Invoice'!C$2:C$801,$W8))) | D8: =IF($W8="","",IF(INDEX('Per Invoice'!D$2:D$801,$W8)="","",INDEX('Per Invoice'!D$2:D$801,$W8))) | E8: =IF($W8="","",IF(INDEX('Per Invoice'!E$2:E$801,$W8)="","",INDEX('Per Invoice'!E$2:E$801,$W8))) | F8: =IF($W8="","",IF(INDEX('Per Invoice'!F$2:F$801,$W8)="","",INDEX('Per Invoice'!F$2:F$801,$W8))) | G8: =IF($W8="","",IF(INDEX('Per Invoice'!G$2:G$801,$W8)="","",INDEX('Per Invoice'!G$2:G$801,$W8))) | H8: =IF($W8="","",IF(INDEX('Per Invoice'!H$2:H$801,$W8)="","",INDEX('Per Invoice'!H$2:H$801,$W8))) | ... V8: =IF($W8="","",IF(INDEX('Per Invoice'!V$2:V$801,$W8)="","",INDEX('Per Invoice'!V$2:V$801,$W8))) | W8: =IFERROR(MATCH(Settings!$C$27&"|"&ROWS($W$2:$W8),'Per Invoice'!$X$2:$X$801,0),"")
A9: =IF($W9="","",IF(INDEX('Per Invoice'!A$2:A$801,$W9)="","",INDEX('Per Invoice'!A$2:A$801,$W9))) | B9: =IF($W9="","",IF(INDEX('Per Invoice'!B$2:B$801,$W9)="","",INDEX('Per Invoice'!B$2:B$801,$W9))) | C9: =IF($W9="","",IF(INDEX('Per Invoice'!C$2:C$801,$W9)="","",INDEX('Per Invoice'!C$2:C$801,$W9))) | D9: =IF($W9="","",IF(INDEX('Per Invoice'!D$2:D$801,$W9)="","",INDEX('Per Invoice'!D$2:D$801,$W9))) | E9: =IF($W9="","",IF(INDEX('Per Invoice'!E$2:E$801,$W9)="","",INDEX('Per Invoice'!E$2:E$801,$W9))) | F9: =IF($W9="","",IF(INDEX('Per Invoice'!F$2:F$801,$W9)="","",INDEX('Per Invoice'!F$2:F$801,$W9))) | G9: =IF($W9="","",IF(INDEX('Per Invoice'!G$2:G$801,$W9)="","",INDEX('Per Invoice'!G$2:G$801,$W9))) | H9: =IF($W9="","",IF(INDEX('Per Invoice'!H$2:H$801,$W9)="","",INDEX('Per Invoice'!H$2:H$801,$W9))) | ... V9: =IF($W9="","",IF(INDEX('Per Invoice'!V$2:V$801,$W9)="","",INDEX('Per Invoice'!V$2:V$801,$W9))) | W9: =IFERROR(MATCH(Settings!$C$27&"|"&ROWS($W$2:$W9),'Per Invoice'!$X$2:$X$801,0),"")
