Workbook

Sheet How To Use
A1: Claims Template - PETROJET (Chronic)
A3: Monthly steps
A4: 1. Open the 'Per Line' tab. Delete the old data in the BLUE columns only (row 2 down). Never delete the green or grey columns.
A5: 2. Paste the new month's data as VALUES starting at A2, into the blue columns: A-L, N-V, AA-AH (same order as the system export).
A6: 3. Green columns (M, W, X, Y, Z) and the grey helper columns (AI-AM) calculate automatically - do not paste over them.
A7: 4. 'Per Invoice' fills itself from 'Per Line' (one row per Order #, split into IMP / Local). No pivot table, no refresh.
A8: 5. The ONLY manual column in 'Per Invoice' is column B 'Invoice' (blue): type it yourself. Everything else is formula.
A9: 6. One tab per site and 'Summary' fill themselves from 'Per Invoice'. Column C 'Site Tab (##)' decides the tab: the Corporate name, and 'P1', 'P2' ... when a site has more than the invoices-per-tab limit in Settings (C8).
A10: 7. Open 'Settings' and check STATUS says OK (Per Line = Per Invoice, and every invoice has a payer that is listed in Settings).
A12: Colour legend
A13: Blue header = typed/pasted by you (raw data, and 'Invoice' in Per Invoice). Green header = formula (do not paste over). Grey header = helper formula (do not touch). Yellow cell (Settings) = editable rate.
A15: Calculation rules (taken from the September 2026 sheet)
... A21: Capacity: up to 7,000 lines and 1,300 invoices per month. A line with an empty Order # is ignored.

Sheet Settings
B1: Company settings & checks
B3: Insurance Company | C3: PETROJET | D3: Informational only
B4: Corporate | C4: All Petrojet sites (one tab each - see Settings) | D4: Informational only
B5: Sheet type | C5: Chronic | D5: Informational only | F5: Special lines that STILL get a rebate (product name contains)
B6: Local products rebate % | C6: 0.16 | D6: Source: Sep sheets (Rebates = 16 on Local lines). | F6: PENFIL | G6: Special Rebates? = Yes gives 0% EXCEPT when the product name contains one of these words (insulin pens, ...).
B7: Imported (IMP) products rebate % | C7: 0.08 | D7: Source: Sep sheets (Rebates = 8 on non-local lines). | F7: FLEXPEN
B8: Max invoices per site tab | C8: 100 | D8: A site (Corporate) with more invoices than this is split into "<site> P1", "<site> P2" ... tabs. | F8: FLEXTOUCH
B9: Month totals / reconciliation | F9: SOLOSTAR
B10: Lines loaded | C10: =COUNTA('Per Line'!$C$2:$C$7001) | F10: IU
B11: Invoices (unique Order #) | C11: =MAX('Per Line'!$AJ$2:$AJ$7001) | F11: I.U
B12: Invoices shown in Per Invoice | C12: =SUMPRODUCT(--('Per Invoice'!$A$2:$A$1301<>"")) | F12: 100U
B13: Grand Total - Per Line (Product Total) | C13: =SUM('Per Line'!$T$2:$T$7001)
B14: Grand Total - Per Invoice | C14: =SUM('Per Invoice'!$Y$2:$Y$1301)
B15: Discount - Per Line | C15: =SUM('Per Line'!$X$2:$X$7001)
B16: Discount - Per Invoice | C16: =SUM('Per Invoice'!$W$2:$W$1301)
B17: Co val - Per Line | C17: =SUM('Per Line'!$M$2:$M$7001)
B18: Co val - Per Invoice | C18: =SUM('Per Invoice'!$N$2:$N$1301)
B19: Net - Per Line | C19: =SUM('Per Line'!$Z$2:$Z$7001)
B20: Net - Per Invoice | C20: =SUM('Per Invoice'!$Z$2:$Z$1301)
B21: Max Limit adjustment (Co val, Per Invoice only) | C21: 0 | D21: This company's Per Invoice has no Max Limit rule.
B23: STATUS | C23: =IF(C10=0,"No data loaded",IF(COUNTA('Per Line'!$C:$C)-1>7000,"TOO MANY LINES - extend template",IF(C11>1300,"TOO MANY INVOICES - extend template",IF(AND(ROUND(C13-C14,2)=0,ROUND(C15-C16,2)=0,ROUND(C17+C21-C18,2)=0,ROUND(C19-C21-C20,2)=0,C11=C12,C51=0,MAX(D26:D49)<=100),"OK","CHECK - Per Line and Per Invoice do not match")))) | D23: Must say OK after you paste the month data.
B25: Site tabs | C25: Site name exactly as in the Site Tab (##) column | D25: Invoices (formula)
B26: Petrojet Haram 4th line | C26: Petrojet Haram 4th line | D26: =IF(C26="",0,COUNTIF('Per Invoice'!$C$2:$C$1301,C26))
B27: Petrojet North (Pensioners) | C27: Petrojet North (Pensioners) | D27: =IF(C27="",0,COUNTIF('Per Invoice'!$C$2:$C$1301,C27))
B28: Petrojet North (Pensioners) P1 | C28: Petrojet North (Pensioners) P1 | D28: =IF(C28="",0,COUNTIF('Per Invoice'!$C$2:$C$1301,C28))
B29: Petrojet North (Pensioners) P2 | C29: Petrojet North (Pensioners) P2 | D29: =IF(C29="",0,COUNTIF('Per Invoice'!$C$2:$C$1301,C29))
B30: Petrojet North | C30: Petrojet North | D30: =IF(C30="",0,COUNTIF('Per Invoice'!$C$2:$C$1301,C30))
B31: Petrojet North P1 | C31: Petrojet North P1 | D31: =IF(C31="",0,COUNTIF('Per Invoice'!$C$2:$C$1301,C31))
B32: Petrojet North P2 | C32: Petrojet North P2 | D32: =IF(C32="",0,COUNTIF('Per Invoice'!$C$2:$C$1301,C32))
B33: Petrojet Central Shops | C33: Petrojet Central Shops | D33: =IF(C33="",0,COUNTIF('Per Invoice'!$C$2:$C$1301,C33))
B34: Petrojet Central Shops P1 | C34: Petrojet Central Shops P1 | D34: =IF(C34="",0,COUNTIF('Per Invoice'!$C$2:$C$1301,C34))
B35: Petrojet Central Shops P2 | C35: Petrojet Central Shops P2 | D35: =IF(C35="",0,COUNTIF('Per Invoice'!$C$2:$C$1301,C35))
B36: Petrojet Assiut | C36: Petrojet Assiut | D36: =IF(C36="",0,COUNTIF('Per Invoice'!$C$2:$C$1301,C36))
B37: Petrojet Assiut P1 | C37: Petrojet Assiut P1 | D37: =IF(C37="",0,COUNTIF('Per Invoice'!$C$2:$C$1301,C37))
... B45: Petrojet البنية 1600 فدن | C45: Petrojet البنية 1600 فدن | D45: =IF(C45="",0,COUNTIF('Per Invoice'!$C$2:$C$1301,C45))
B46: Extra 1 | D46: =IF(C46="",0,COUNTIF('Per Invoice'!$C$2:$C$1301,C46))
B47: Extra 2 | D47: =IF(C47="",0,COUNTIF('Per Invoice'!$C$2:$C$1301,C47))
B48: Extra 3 | D48: =IF(C48="",0,COUNTIF('Per Invoice'!$C$2:$C$1301,C48))
B49: Extra 4 | D49: =IF(C49="",0,COUNTIF('Per Invoice'!$C$2:$C$1301,C49))
B51: Invoices not in any site tab (must be 0) | C51: =C11-SUM(D26:D49) | D51: If not 0: a new site appeared. Type its exact name in one of the empty yellow cells above (Extra 1 ... Extra 4); the tab Extra n then shows it. Each tab holds up to 100 invoices.

Sheet Summary
A1: Row Labels | B1: Count of Order # | C1: Sum of CO VAL | D1: Sum of SUBTOTAL | E1: Sum of Grand Total | F1: Sum of NET
A2: =IF(Settings!$C$26="","",Settings!$C$26) | B2: =IF($A2="","",COUNTIF('Per Invoice'!$C$2:$C$1301,$A2)) | C2: =IF($A2="","",SUMIFS('Per Invoice'!$N$2:$N$1301,'Per Invoice'!$C$2:$C$1301,$A2)) | D2: =IF($A2="","",SUMIFS('Per Invoice'!$X$2:$X$1301,'Per Invoice'!$C$2:$C$1301,$A2)) | E2: =IF($A2="","",SUMIFS('Per Invoice'!$Y$2:$Y$1301,'Per Invoice'!$C$2:$C$1301,$A2)) | F2: =IF($A2="","",SUMIFS('Per Invoice'!$Z$2:$Z$1301,'Per Invoice'!$C$2:$C$1301,$A2))
A3: =IF(Settings!$C$27="","",Settings!$C$27) | B3: =IF($A3="","",COUNTIF('Per Invoice'!$C$2:$C$1301,$A3)) | C3: =IF($A3="","",SUMIFS('Per Invoice'!$N$2:$N$1301,'Per Invoice'!$C$2:$C$1301,$A3)) | D3: =IF($A3="","",SUMIFS('Per Invoice'!$X$2:$X$1301,'Per Invoice'!$C$2:$C$1301,$A3)) | E3: =IF($A3="","",SUMIFS('Per Invoice'!$Y$2:$Y$1301,'Per Invoice'!$C$2:$C$1301,$A3)) | F3: =IF($A3="","",SUMIFS('Per Invoice'!$Z$2:$Z$1301,'Per Invoice'!$C$2:$C$1301,$A3))
A4: =IF(Settings!$C$28="","",Settings!$C$28) | B4: =IF($A4="","",COUNTIF('Per Invoice'!$C$2:$C$1301,$A4)) | C4: =IF($A4="","",SUMIFS('Per Invoice'!$N$2:$N$1301,'Per Invoice'!$C$2:$C$1301,$A4)) | D4: =IF($A4="","",SUMIFS('Per Invoice'!$X$2:$X$1301,'Per Invoice'!$C$2:$C$1301,$A4)) | E4: =IF($A4="","",SUMIFS('Per Invoice'!$Y$2:$Y$1301,'Per Invoice'!$C$2:$C$1301,$A4)) | F4: =IF($A4="","",SUMIFS('Per Invoice'!$Z$2:$Z$1301,'Per Invoice'!$C$2:$C$1301,$A4))
A5: =IF(Settings!$C$29="","",Settings!$C$29) | B5: =IF($A5="","",COUNTIF('Per Invoice'!$C$2:$C$1301,$A5)) | C5: =IF($A5="","",SUMIFS('Per Invoice'!$N$2:$N$1301,'Per Invoice'!$C$2:$C$1301,$A5)) | D5: =IF($A5="","",SUMIFS('Per Invoice'!$X$2:$X$1301,'Per Invoice'!$C$2:$C$1301,$A5)) | E5: =IF($A5="","",SUMIFS('Per Invoice'!$Y$2:$Y$1301,'Per Invoice'!$C$2:$C$1301,$A5)) | F5: =IF($A5="","",SUMIFS('Per Invoice'!$Z$2:$Z$1301,'Per Invoice'!$C$2:$C$1301,$A5))
A6: =IF(Settings!$C$30="","",Settings!$C$30) | B6: =IF($A6="","",COUNTIF('Per Invoice'!$C$2:$C$1301,$A6)) | C6: =IF($A6="","",SUMIFS('Per Invoice'!$N$2:$N$1301,'Per Invoice'!$C$2:$C$1301,$A6)) | D6: =IF($A6="","",SUMIFS('Per Invoice'!$X$2:$X$1301,'Per Invoice'!$C$2:$C$1301,$A6)) | E6: =IF($A6="","",SUMIFS('Per Invoice'!$Y$2:$Y$1301,'Per Invoice'!$C$2:$C$1301,$A6)) | F6: =IF($A6="","",SUMIFS('Per Invoice'!$Z$2:$Z$1301,'Per Invoice'!$C$2:$C$1301,$A6))
A7: =IF(Settings!$C$31="","",Settings!$C$31) | B7: =IF($A7="","",COUNTIF('Per Invoice'!$C$2:$C$1301,$A7)) | C7: =IF($A7="","",SUMIFS('Per Invoice'!$N$2:$N$1301,'Per Invoice'!$C$2:$C$1301,$A7)) | D7: =IF($A7="","",SUMIFS('Per Invoice'!$X$2:$X$1301,'Per Invoice'!$C$2:$C$1301,$A7)) | E7: =IF($A7="","",SUMIFS('Per Invoice'!$Y$2:$Y$1301,'Per Invoice'!$C$2:$C$1301,$A7)) | F7: =IF($A7="","",SUMIFS('Per Invoice'!$Z$2:$Z$1301,'Per Invoice'!$C$2:$C$1301,$A7))
A8: =IF(Settings!$C$32="","",Settings!$C$32) | B8: =IF($A8="","",COUNTIF('Per Invoice'!$C$2:$C$1301,$A8)) | C8: =IF($A8="","",SUMIFS('Per Invoice'!$N$2:$N$1301,'Per Invoice'!$C$2:$C$1301,$A8)) | D8: =IF($A8="","",SUMIFS('Per Invoice'!$X$2:$X$1301,'Per Invoice'!$C$2:$C$1301,$A8)) | E8: =IF($A8="","",SUMIFS('Per Invoice'!$Y$2:$Y$1301,'Per Invoice'!$C$2:$C$1301,$A8)) | F8: =IF($A8="","",SUMIFS('Per Invoice'!$Z$2:$Z$1301,'Per Invoice'!$C$2:$C$1301,$A8))
A9: =IF(Settings!$C$33="","",Settings!$C$33) | B9: =IF($A9="","",COUNTIF('Per Invoice'!$C$2:$C$1301,$A9)) | C9: =IF($A9="","",SUMIFS('Per Invoice'!$N$2:$N$1301,'Per Invoice'!$C$2:$C$1301,$A9)) | D9: =IF($A9="","",SUMIFS('Per Invoice'!$X$2:$X$1301,'Per Invoice'!$C$2:$C$1301,$A9)) | E9: =IF($A9="","",SUMIFS('Per Invoice'!$Y$2:$Y$1301,'Per Invoice'!$C$2:$C$1301,$A9)) | F9: =IF($A9="","",SUMIFS('Per Invoice'!$Z$2:$Z$1301,'Per Invoice'!$C$2:$C$1301,$A9))
A10: =IF(Settings!$C$34="","",Settings!$C$34) | B10: =IF($A10="","",COUNTIF('Per Invoice'!$C$2:$C$1301,$A10)) | C10: =IF($A10="","",SUMIFS('Per Invoice'!$N$2:$N$1301,'Per Invoice'!$C$2:$C$1301,$A10)) | D10: =IF($A10="","",SUMIFS('Per Invoice'!$X$2:$X$1301,'Per Invoice'!$C$2:$C$1301,$A10)) | E10: =IF($A10="","",SUMIFS('Per Invoice'!$Y$2:$Y$1301,'Per Invoice'!$C$2:$C$1301,$A10)) | F10: =IF($A10="","",SUMIFS('Per Invoice'!$Z$2:$Z$1301,'Per Invoice'!$C$2:$C$1301,$A10))
A11: =IF(Settings!$C$35="","",Settings!$C$35) | B11: =IF($A11="","",COUNTIF('Per Invoice'!$C$2:$C$1301,$A11)) | C11: =IF($A11="","",SUMIFS('Per Invoice'!$N$2:$N$1301,'Per Invoice'!$C$2:$C$1301,$A11)) | D11: =IF($A11="","",SUMIFS('Per Invoice'!$X$2:$X$1301,'Per Invoice'!$C$2:$C$1301,$A11)) | E11: =IF($A11="","",SUMIFS('Per Invoice'!$Y$2:$Y$1301,'Per Invoice'!$C$2:$C$1301,$A11)) | F11: =IF($A11="","",SUMIFS('Per Invoice'!$Z$2:$Z$1301,'Per Invoice'!$C$2:$C$1301,$A11))
A12: =IF(Settings!$C$36="","",Settings!$C$36) | B12: =IF($A12="","",COUNTIF('Per Invoice'!$C$2:$C$1301,$A12)) | C12: =IF($A12="","",SUMIFS('Per Invoice'!$N$2:$N$1301,'Per Invoice'!$C$2:$C$1301,$A12)) | D12: =IF($A12="","",SUMIFS('Per Invoice'!$X$2:$X$1301,'Per Invoice'!$C$2:$C$1301,$A12)) | E12: =IF($A12="","",SUMIFS('Per Invoice'!$Y$2:$Y$1301,'Per Invoice'!$C$2:$C$1301,$A12)) | F12: =IF($A12="","",SUMIFS('Per Invoice'!$Z$2:$Z$1301,'Per Invoice'!$C$2:$C$1301,$A12))
A13: =IF(Settings!$C$37="","",Settings!$C$37) | B13: =IF($A13="","",COUNTIF('Per Invoice'!$C$2:$C$1301,$A13)) | C13: =IF($A13="","",SUMIFS('Per Invoice'!$N$2:$N$1301,'Per Invoice'!$C$2:$C$1301,$A13)) | D13: =IF($A13="","",SUMIFS('Per Invoice'!$X$2:$X$1301,'Per Invoice'!$C$2:$C$1301,$A13)) | E13: =IF($A13="","",SUMIFS('Per Invoice'!$Y$2:$Y$1301,'Per Invoice'!$C$2:$C$1301,$A13)) | F13: =IF($A13="","",SUMIFS('Per Invoice'!$Z$2:$Z$1301,'Per Invoice'!$C$2:$C$1301,$A13))
A14: =IF(Settings!$C$38="","",Settings!$C$38) | B14: =IF($A14="","",COUNTIF('Per Invoice'!$C$2:$C$1301,$A14)) | C14: =IF($A14="","",SUMIFS('Per Invoice'!$N$2:$N$1301,'Per Invoice'!$C$2:$C$1301,$A14)) | D14: =IF($A14="","",SUMIFS('Per Invoice'!$X$2:$X$1301,'Per Invoice'!$C$2:$C$1301,$A14)) | E14: =IF($A14="","",SUMIFS('Per Invoice'!$Y$2:$Y$1301,'Per Invoice'!$C$2:$C$1301,$A14)) | F14: =IF($A14="","",SUMIFS('Per Invoice'!$Z$2:$Z$1301,'Per Invoice'!$C$2:$C$1301,$A14))
A15: =IF(Settings!$C$39="","",Settings!$C$39) | B15: =IF($A15="","",COUNTIF('Per Invoice'!$C$2:$C$1301,$A15)) | C15: =IF($A15="","",SUMIFS('Per Invoice'!$N$2:$N$1301,'Per Invoice'!$C$2:$C$1301,$A15)) | D15: =IF($A15="","",SUMIFS('Per Invoice'!$X$2:$X$1301,'Per Invoice'!$C$2:$C$1301,$A15)) | E15: =IF($A15="","",SUMIFS('Per Invoice'!$Y$2:$Y$1301,'Per Invoice'!$C$2:$C$1301,$A15)) | F15: =IF($A15="","",SUMIFS('Per Invoice'!$Z$2:$Z$1301,'Per Invoice'!$C$2:$C$1301,$A15))
A16: =IF(Settings!$C$40="","",Settings!$C$40) | B16: =IF($A16="","",COUNTIF('Per Invoice'!$C$2:$C$1301,$A16)) | C16: =IF($A16="","",SUMIFS('Per Invoice'!$N$2:$N$1301,'Per Invoice'!$C$2:$C$1301,$A16)) | D16: =IF($A16="","",SUMIFS('Per Invoice'!$X$2:$X$1301,'Per Invoice'!$C$2:$C$1301,$A16)) | E16: =IF($A16="","",SUMIFS('Per Invoice'!$Y$2:$Y$1301,'Per Invoice'!$C$2:$C$1301,$A16)) | F16: =IF($A16="","",SUMIFS('Per Invoice'!$Z$2:$Z$1301,'Per Invoice'!$C$2:$C$1301,$A16))
A17: =IF(Settings!$C$41="","",Settings!$C$41) | B17: =IF($A17="","",COUNTIF('Per Invoice'!$C$2:$C$1301,$A17)) | C17: =IF($A17="","",SUMIFS('Per Invoice'!$N$2:$N$1301,'Per Invoice'!$C$2:$C$1301,$A17)) | D17: =IF($A17="","",SUMIFS('Per Invoice'!$X$2:$X$1301,'Per Invoice'!$C$2:$C$1301,$A17)) | E17: =IF($A17="","",SUMIFS('Per Invoice'!$Y$2:$Y$1301,'Per Invoice'!$C$2:$C$1301,$A17)) | F17: =IF($A17="","",SUMIFS('Per Invoice'!$Z$2:$Z$1301,'Per Invoice'!$C$2:$C$1301,$A17))
A18: =IF(Settings!$C$42="","",Settings!$C$42) | B18: =IF($A18="","",COUNTIF('Per Invoice'!$C$2:$C$1301,$A18)) | C18: =IF($A18="","",SUMIFS('Per Invoice'!$N$2:$N$1301,'Per Invoice'!$C$2:$C$1301,$A18)) | D18: =IF($A18="","",SUMIFS('Per Invoice'!$X$2:$X$1301,'Per Invoice'!$C$2:$C$1301,$A18)) | E18: =IF($A18="","",SUMIFS('Per Invoice'!$Y$2:$Y$1301,'Per Invoice'!$C$2:$C$1301,$A18)) | F18: =IF($A18="","",SUMIFS('Per Invoice'!$Z$2:$Z$1301,'Per Invoice'!$C$2:$C$1301,$A18))
A19: =IF(Settings!$C$43="","",Settings!$C$43) | B19: =IF($A19="","",COUNTIF('Per Invoice'!$C$2:$C$1301,$A19)) | C19: =IF($A19="","",SUMIFS('Per Invoice'!$N$2:$N$1301,'Per Invoice'!$C$2:$C$1301,$A19)) | D19: =IF($A19="","",SUMIFS('Per Invoice'!$X$2:$X$1301,'Per Invoice'!$C$2:$C$1301,$A19)) | E19: =IF($A19="","",SUMIFS('Per Invoice'!$Y$2:$Y$1301,'Per Invoice'!$C$2:$C$1301,$A19)) | F19: =IF($A19="","",SUMIFS('Per Invoice'!$Z$2:$Z$1301,'Per Invoice'!$C$2:$C$1301,$A19))
A20: =IF(Settings!$C$44="","",Settings!$C$44) | B20: =IF($A20="","",COUNTIF('Per Invoice'!$C$2:$C$1301,$A20)) | C20: =IF($A20="","",SUMIFS('Per Invoice'!$N$2:$N$1301,'Per Invoice'!$C$2:$C$1301,$A20)) | D20: =IF($A20="","",SUMIFS('Per Invoice'!$X$2:$X$1301,'Per Invoice'!$C$2:$C$1301,$A20)) | E20: =IF($A20="","",SUMIFS('Per Invoice'!$Y$2:$Y$1301,'Per Invoice'!$C$2:$C$1301,$A20)) | F20: =IF($A20="","",SUMIFS('Per Invoice'!$Z$2:$Z$1301,'Per Invoice'!$C$2:$C$1301,$A20))
A21: =IF(Settings!$C$45="","",Settings!$C$45) | B21: =IF($A21="","",COUNTIF('Per Invoice'!$C$2:$C$1301,$A21)) | C21: =IF($A21="","",SUMIFS('Per Invoice'!$N$2:$N$1301,'Per Invoice'!$C$2:$C$1301,$A21)) | D21: =IF($A21="","",SUMIFS('Per Invoice'!$X$2:$X$1301,'Per Invoice'!$C$2:$C$1301,$A21)) | E21: =IF($A21="","",SUMIFS('Per Invoice'!$Y$2:$Y$1301,'Per Invoice'!$C$2:$C$1301,$A21)) | F21: =IF($A21="","",SUMIFS('Per Invoice'!$Z$2:$Z$1301,'Per Invoice'!$C$2:$C$1301,$A21))
A22: =IF(Settings!$C$46="","",Settings!$C$46) | B22: =IF($A22="","",COUNTIF('Per Invoice'!$C$2:$C$1301,$A22)) | C22: =IF($A22="","",SUMIFS('Per Invoice'!$N$2:$N$1301,'Per Invoice'!$C$2:$C$1301,$A22)) | D22: =IF($A22="","",SUMIFS('Per Invoice'!$X$2:$X$1301,'Per Invoice'!$C$2:$C$1301,$A22)) | E22: =IF($A22="","",SUMIFS('Per Invoice'!$Y$2:$Y$1301,'Per Invoice'!$C$2:$C$1301,$A22)) | F22: =IF($A22="","",SUMIFS('Per Invoice'!$Z$2:$Z$1301,'Per Invoice'!$C$2:$C$1301,$A22))
A23: =IF(Settings!$C$47="","",Settings!$C$47) | B23: =IF($A23="","",COUNTIF('Per Invoice'!$C$2:$C$1301,$A23)) | C23: =IF($A23="","",SUMIFS('Per Invoice'!$N$2:$N$1301,'Per Invoice'!$C$2:$C$1301,$A23)) | D23: =IF($A23="","",SUMIFS('Per Invoice'!$X$2:$X$1301,'Per Invoice'!$C$2:$C$1301,$A23)) | E23: =IF($A23="","",SUMIFS('Per Invoice'!$Y$2:$Y$1301,'Per Invoice'!$C$2:$C$1301,$A23)) | F23: =IF($A23="","",SUMIFS('Per Invoice'!$Z$2:$Z$1301,'Per Invoice'!$C$2:$C$1301,$A23))
A24: =IF(Settings!$C$48="","",Settings!$C$48) | B24: =IF($A24="","",COUNTIF('Per Invoice'!$C$2:$C$1301,$A24)) | C24: =IF($A24="","",SUMIFS('Per Invoice'!$N$2:$N$1301,'Per Invoice'!$C$2:$C$1301,$A24)) | D24: =IF($A24="","",SUMIFS('Per Invoice'!$X$2:$X$1301,'Per Invoice'!$C$2:$C$1301,$A24)) | E24: =IF($A24="","",SUMIFS('Per Invoice'!$Y$2:$Y$1301,'Per Invoice'!$C$2:$C$1301,$A24)) | F24: =IF($A24="","",SUMIFS('Per Invoice'!$Z$2:$Z$1301,'Per Invoice'!$C$2:$C$1301,$A24))
A25: =IF(Settings!$C$49="","",Settings!$C$49) | B25: =IF($A25="","",COUNTIF('Per Invoice'!$C$2:$C$1301,$A25)) | C25: =IF($A25="","",SUMIFS('Per Invoice'!$N$2:$N$1301,'Per Invoice'!$C$2:$C$1301,$A25)) | D25: =IF($A25="","",SUMIFS('Per Invoice'!$X$2:$X$1301,'Per Invoice'!$C$2:$C$1301,$A25)) | E25: =IF($A25="","",SUMIFS('Per Invoice'!$Y$2:$Y$1301,'Per Invoice'!$C$2:$C$1301,$A25)) | F25: =IF($A25="","",SUMIFS('Per Invoice'!$Z$2:$Z$1301,'Per Invoice'!$C$2:$C$1301,$A25))
A26: Grand Total | B26: =SUM(B2:B25) | C26: =SUM(C2:C25) | D26: =SUM(D2:D25) | E26: =SUM(E2:E25) | F26: =SUM(F2:F25)

Sheet Per Line
A1: Cycle | B1: Stage | C1: Order # | D1: Channel | E1: Create At | F1: Insurance Company | G1: Country Portal ID | H1: Card | I1: Corporate | J1: Name | K1: Status | L1: Order Co Payment | M1: Co val | N1: heisenberg id | O1: Product Name | P1: Local | Q1: Unit | R1: Quantity | S1: Unit Price | T1: Product Total | U1: ERX ID | V1: Special Rebates? | W1: Rebates | X1: Discount | Y1: Subtotal | Z1: Net | AA1: Approval Type | AB1: Max Limit | AC1: Exceeding Limit | AD1: Amount collected from customer | AE1: By Patient (Delivered) | AF1: Dispense Number | AG1: Dispense Date | AH1: Has OTP? | AI1: Order 1st Row (helper) | AJ1: Invoice # (helper) | AK1: Is Local (helper) | AL1: Is Special (helper) | AM1: Sort Key (helper)
M2: =IF($C2="","",L2*T2/100) | W2: =IF($C2="","",IF($AL2=1,0,IF($AK2=1,Settings!$C$6,Settings!$C$7))*100) | X2: =IF($C2="","",T2*W2/100) | Y2: =IF($C2="","",T2-X2) | Z2: =IF($C2="","",Y2-M2) | AI2: =IF($C2="","",IF(COUNTIF($C$2:$C2,$C2)=1,1,0)) | AJ2: =IF($AI2=1,SUMPRODUCT(--($AM$2:$AM$7001<$AM2))+1,"") | AK2: =IF($C2="","",IF(OR($P2=TRUE(),$P2="TRUE"),1,0)) | AL2: =IF($C2="","",IF(AND($V2="Yes",SUMPRODUCT((LEN(Settings!$F$6:$F$13)>0)*ISNUMBER(SEARCH(Settings!$F$6:$F$13,$O2)))=0),1,0)) | AM2: =IF($AI2=1,IFERROR(IF(VALUE($C2)<100000000,VALUE($C2),1000000000),IFERROR(IF(VALUE(MID($C2,2,20))<100000000,VALUE(MID($C2,2,20)),1000000000),1000000000))+ROW()/100000,"")
M3: =IF($C3="","",L3*T3/100) | W3: =IF($C3="","",IF($AL3=1,0,IF($AK3=1,Settings!$C$6,Settings!$C$7))*100) | X3: =IF($C3="","",T3*W3/100) | Y3: =IF($C3="","",T3-X3) | Z3: =IF($C3="","",Y3-M3) | AI3: =IF($C3="","",IF(COUNTIF($C$2:$C3,$C3)=1,1,0)) | AJ3: =IF($AI3=1,SUMPRODUCT(--($AM$2:$AM$7001<$AM3))+1,"") | AK3: =IF($C3="","",IF(OR($P3=TRUE(),$P3="TRUE"),1,0)) | AL3: =IF($C3="","",IF(AND($V3="Yes",SUMPRODUCT((LEN(Settings!$F$6:$F$13)>0)*ISNUMBER(SEARCH(Settings!$F$6:$F$13,$O3)))=0),1,0)) | AM3: =IF($AI3=1,IFERROR(IF(VALUE($C3)<100000000,VALUE($C3),1000000000),IFERROR(IF(VALUE(MID($C3,2,20))<100000000,VALUE(MID($C3,2,20)),1000000000),1000000000))+ROW()/100000,"")
M4: =IF($C4="","",L4*T4/100) | W4: =IF($C4="","",IF($AL4=1,0,IF($AK4=1,Settings!$C$6,Settings!$C$7))*100) | X4: =IF($C4="","",T4*W4/100) | Y4: =IF($C4="","",T4-X4) | Z4: =IF($C4="","",Y4-M4) | AI4: =IF($C4="","",IF(COUNTIF($C$2:$C4,$C4)=1,1,0)) | AJ4: =IF($AI4=1,SUMPRODUCT(--($AM$2:$AM$7001<$AM4))+1,"") | AK4: =IF($C4="","",IF(OR($P4=TRUE(),$P4="TRUE"),1,0)) | AL4: =IF($C4="","",IF(AND($V4="Yes",SUMPRODUCT((LEN(Settings!$F$6:$F$13)>0)*ISNUMBER(SEARCH(Settings!$F$6:$F$13,$O4)))=0),1,0)) | AM4: =IF($AI4=1,IFERROR(IF(VALUE($C4)<100000000,VALUE($C4),1000000000),IFERROR(IF(VALUE(MID($C4,2,20))<100000000,VALUE(MID($C4,2,20)),1000000000),1000000000))+ROW()/100000,"")
M5: =IF($C5="","",L5*T5/100) | W5: =IF($C5="","",IF($AL5=1,0,IF($AK5=1,Settings!$C$6,Settings!$C$7))*100) | X5: =IF($C5="","",T5*W5/100) | Y5: =IF($C5="","",T5-X5) | Z5: =IF($C5="","",Y5-M5) | AI5: =IF($C5="","",IF(COUNTIF($C$2:$C5,$C5)=1,1,0)) | AJ5: =IF($AI5=1,SUMPRODUCT(--($AM$2:$AM$7001<$AM5))+1,"") | AK5: =IF($C5="","",IF(OR($P5=TRUE(),$P5="TRUE"),1,0)) | AL5: =IF($C5="","",IF(AND($V5="Yes",SUMPRODUCT((LEN(Settings!$F$6:$F$13)>0)*ISNUMBER(SEARCH(Settings!$F$6:$F$13,$O5)))=0),1,0)) | AM5: =IF($AI5=1,IFERROR(IF(VALUE($C5)<100000000,VALUE($C5),1000000000),IFERROR(IF(VALUE(MID($C5,2,20))<100000000,VALUE(MID($C5,2,20)),1000000000),1000000000))+ROW()/100000,"")
M6: =IF($C6="","",L6*T6/100) | W6: =IF($C6="","",IF($AL6=1,0,IF($AK6=1,Settings!$C$6,Settings!$C$7))*100) | X6: =IF($C6="","",T6*W6/100) | Y6: =IF($C6="","",T6-X6) | Z6: =IF($C6="","",Y6-M6) | AI6: =IF($C6="","",IF(COUNTIF($C$2:$C6,$C6)=1,1,0)) | AJ6: =IF($AI6=1,SUMPRODUCT(--($AM$2:$AM$7001<$AM6))+1,"") | AK6: =IF($C6="","",IF(OR($P6=TRUE(),$P6="TRUE"),1,0)) | AL6: =IF($C6="","",IF(AND($V6="Yes",SUMPRODUCT((LEN(Settings!$F$6:$F$13)>0)*ISNUMBER(SEARCH(Settings!$F$6:$F$13,$O6)))=0),1,0)) | AM6: =IF($AI6=1,IFERROR(IF(VALUE($C6)<100000000,VALUE($C6),1000000000),IFERROR(IF(VALUE(MID($C6,2,20))<100000000,VALUE(MID($C6,2,20)),1000000000),1000000000))+ROW()/100000,"")
M7: =IF($C7="","",L7*T7/100) | W7: =IF($C7="","",IF($AL7=1,0,IF($AK7=1,Settings!$C$6,Settings!$C$7))*100) | X7: =IF($C7="","",T7*W7/100) | Y7: =IF($C7="","",T7-X7) | Z7: =IF($C7="","",Y7-M7) | AI7: =IF($C7="","",IF(COUNTIF($C$2:$C7,$C7)=1,1,0)) | AJ7: =IF($AI7=1,SUMPRODUCT(--($AM$2:$AM$7001<$AM7))+1,"") | AK7: =IF($C7="","",IF(OR($P7=TRUE(),$P7="TRUE"),1,0)) | AL7: =IF($C7="","",IF(AND($V7="Yes",SUMPRODUCT((LEN(Settings!$F$6:$F$13)>0)*ISNUMBER(SEARCH(Settings!$F$6:$F$13,$O7)))=0),1,0)) | AM7: =IF($AI7=1,IFERROR(IF(VALUE($C7)<100000000,VALUE($C7),1000000000),IFERROR(IF(VALUE(MID($C7,2,20))<100000000,VALUE(MID($C7,2,20)),1000000000),1000000000))+ROW()/100000,"")
M8: =IF($C8="","",L8*T8/100) | W8: =IF($C8="","",IF($AL8=1,0,IF($AK8=1,Settings!$C$6,Settings!$C$7))*100) | X8: =IF($C8="","",T8*W8/100) | Y8: =IF($C8="","",T8-X8) | Z8: =IF($C8="","",Y8-M8) | AI8: =IF($C8="","",IF(COUNTIF($C$2:$C8,$C8)=1,1,0)) | AJ8: =IF($AI8=1,SUMPRODUCT(--($AM$2:$AM$7001<$AM8))+1,"") | AK8: =IF($C8="","",IF(OR($P8=TRUE(),$P8="TRUE"),1,0)) | AL8: =IF($C8="","",IF(AND($V8="Yes",SUMPRODUCT((LEN(Settings!$F$6:$F$13)>0)*ISNUMBER(SEARCH(Settings!$F$6:$F$13,$O8)))=0),1,0)) | AM8: =IF($AI8=1,IFERROR(IF(VALUE($C8)<100000000,VALUE($C8),1000000000),IFERROR(IF(VALUE(MID($C8,2,20))<100000000,VALUE(MID($C8,2,20)),1000000000),1000000000))+ROW()/100000,"")
M9: =IF($C9="","",L9*T9/100) | W9: =IF($C9="","",IF($AL9=1,0,IF($AK9=1,Settings!$C$6,Settings!$C$7))*100) | X9: =IF($C9="","",T9*W9/100) | Y9: =IF($C9="","",T9-X9) | Z9: =IF($C9="","",Y9-M9) | AI9: =IF($C9="","",IF(COUNTIF($C$2:$C9,$C9)=1,1,0)) | AJ9: =IF($AI9=1,SUMPRODUCT(--($AM$2:$AM$7001<$AM9))+1,"") | AK9: =IF($C9="","",IF(OR($P9=TRUE(),$P9="TRUE"),1,0)) | AL9: =IF($C9="","",IF(AND($V9="Yes",SUMPRODUCT((LEN(Settings!$F$6:$F$13)>0)*ISNUMBER(SEARCH(Settings!$F$6:$F$13,$O9)))=0),1,0)) | AM9: =IF($AI9=1,IFERROR(IF(VALUE($C9)<100000000,VALUE($C9),1000000000),IFERROR(IF(VALUE(MID($C9,2,20))<100000000,VALUE(MID($C9,2,20)),1000000000),1000000000))+ROW()/100000,"")
M10: =IF($C10="","",L10*T10/100) | W10: =IF($C10="","",IF($AL10=1,0,IF($AK10=1,Settings!$C$6,Settings!$C$7))*100) | X10: =IF($C10="","",T10*W10/100) | Y10: =IF($C10="","",T10-X10) | Z10: =IF($C10="","",Y10-M10) | AI10: =IF($C10="","",IF(COUNTIF($C$2:$C10,$C10)=1,1,0)) | AJ10: =IF($AI10=1,SUMPRODUCT(--($AM$2:$AM$7001<$AM10))+1,"") | AK10: =IF($C10="","",IF(OR($P10=TRUE(),$P10="TRUE"),1,0)) | AL10: =IF($C10="","",IF(AND($V10="Yes",SUMPRODUCT((LEN(Settings!$F$6:$F$13)>0)*ISNUMBER(SEARCH(Settings!$F$6:$F$13,$O10)))=0),1,0)) | AM10: =IF($AI10=1,IFERROR(IF(VALUE($C10)<100000000,VALUE($C10),1000000000),IFERROR(IF(VALUE(MID($C10,2,20))<100000000,VALUE(MID($C10,2,20)),1000000000),1000000000))+ROW()/100000,"")
M11: =IF($C11="","",L11*T11/100) | W11: =IF($C11="","",IF($AL11=1,0,IF($AK11=1,Settings!$C$6,Settings!$C$7))*100) | X11: =IF($C11="","",T11*W11/100) | Y11: =IF($C11="","",T11-X11) | Z11: =IF($C11="","",Y11-M11) | AI11: =IF($C11="","",IF(COUNTIF($C$2:$C11,$C11)=1,1,0)) | AJ11: =IF($AI11=1,SUMPRODUCT(--($AM$2:$AM$7001<$AM11))+1,"") | AK11: =IF($C11="","",IF(OR($P11=TRUE(),$P11="TRUE"),1,0)) | AL11: =IF($C11="","",IF(AND($V11="Yes",SUMPRODUCT((LEN(Settings!$F$6:$F$13)>0)*ISNUMBER(SEARCH(Settings!$F$6:$F$13,$O11)))=0),1,0)) | AM11: =IF($AI11=1,IFERROR(IF(VALUE($C11)<100000000,VALUE($C11),1000000000),IFERROR(IF(VALUE(MID($C11,2,20))<100000000,VALUE(MID($C11,2,20)),1000000000),1000000000))+ROW()/100000,"")
M12: =IF($C12="","",L12*T12/100) | W12: =IF($C12="","",IF($AL12=1,0,IF($AK12=1,Settings!$C$6,Settings!$C$7))*100) | X12: =IF($C12="","",T12*W12/100) | Y12: =IF($C12="","",T12-X12) | Z12: =IF($C12="","",Y12-M12) | AI12: =IF($C12="","",IF(COUNTIF($C$2:$C12,$C12)=1,1,0)) | AJ12: =IF($AI12=1,SUMPRODUCT(--($AM$2:$AM$7001<$AM12))+1,"") | AK12: =IF($C12="","",IF(OR($P12=TRUE(),$P12="TRUE"),1,0)) | AL12: =IF($C12="","",IF(AND($V12="Yes",SUMPRODUCT((LEN(Settings!$F$6:$F$13)>0)*ISNUMBER(SEARCH(Settings!$F$6:$F$13,$O12)))=0),1,0)) | AM12: =IF($AI12=1,IFERROR(IF(VALUE($C12)<100000000,VALUE($C12),1000000000),IFERROR(IF(VALUE(MID($C12,2,20))<100000000,VALUE(MID($C12,2,20)),1000000000),1000000000))+ROW()/100000,"")
M13: =IF($C13="","",L13*T13/100) | W13: =IF($C13="","",IF($AL13=1,0,IF($AK13=1,Settings!$C$6,Settings!$C$7))*100) | X13: =IF($C13="","",T13*W13/100) | Y13: =IF($C13="","",T13-X13) | Z13: =IF($C13="","",Y13-M13) | AI13: =IF($C13="","",IF(COUNTIF($C$2:$C13,$C13)=1,1,0)) | AJ13: =IF($AI13=1,SUMPRODUCT(--($AM$2:$AM$7001<$AM13))+1,"") | AK13: =IF($C13="","",IF(OR($P13=TRUE(),$P13="TRUE"),1,0)) | AL13: =IF($C13="","",IF(AND($V13="Yes",SUMPRODUCT((LEN(Settings!$F$6:$F$13)>0)*ISNUMBER(SEARCH(Settings!$F$6:$F$13,$O13)))=0),1,0)) | AM13: =IF($AI13=1,IFERROR(IF(VALUE($C13)<100000000,VALUE($C13),1000000000),IFERROR(IF(VALUE(MID($C13,2,20))<100000000,VALUE(MID($C13,2,20)),1000000000),1000000000))+ROW()/100000,"")
... M7001: =IF($C7001="","",L7001*T7001/100) | W7001: =IF($C7001="","",IF($AL7001=1,0,IF($AK7001=1,Settings!$C$6,Settings!$C$7))*100) | X7001: =IF($C7001="","",T7001*W7001/100) | Y7001: =IF($C7001="","",T7001-X7001) | Z7001: =IF($C7001="","",Y7001-M7001) | AI7001: =IF($C7001="","",IF(COUNTIF($C$2:$C7001,$C7001)=1,1,0)) | AJ7001: =IF($AI7001=1,SUMPRODUCT(--($AM$2:$AM$7001<$AM7001))+1,"") | AK7001: =IF($C7001="","",IF(OR($P7001=TRUE(),$P7001="TRUE"),1,0)) | AL7001: =IF($C7001="","",IF(AND($V7001="Yes",SUMPRODUCT((LEN(Settings!$F$6:$F$13)>0)*ISNUMBER(SEARCH(Settings!$F$6:$F$13,$O7001)))=0),1,0)) | AM7001: =IF($AI7001=1,IFERROR(IF(VALUE($C7001)<100000000,VALUE($C7001),1000000000),IFERROR(IF(VALUE(MID($C7001,2,20))<100000000,VALUE(MID($C7001,2,20)),1000000000),1000000000))+ROW()/100000,"")

Sheet Per Invoice
A1: Order # | B1: Invoice | C1: Site Tab (##) | D1: Cycle | E1: Stage | F1: Channel | G1: Create At | H1: Insurance Company | I1: Corporate | J1: card | K1: Name | L1: Status | M1: Order Co Payment | N1: Co val | O1: ERX ID | P1: SP | Q1: IMP% | R1: IMP | S1: IMP VAL | T1: LOCAL% | U1: LOCAL | V1: LOCAL VAL | W1: TOTAL VAL | X1: SUBTOTAL | Y1: Grand Total | Z1: NET | AA1: Src Row (helper) | AB1: Payer Key (helper)
A2: =IF($AA2="","",INDEX('Per Line'!$C$2:$C$7001,$AA2)&"") | C2: =IF($AA2="","",IF(COUNTIF($I$2:$I$1301,I2)<=Settings!$C$8,I2,I2&" P"&ROUNDUP(COUNTIF($I$2:$I2,I2)/Settings!$C$8,0))) | D2: =IF($AA2="","",INDEX('Per Line'!$A$2:$A$7001,$AA2)&"") | E2: =IF($AA2="","",INDEX('Per Line'!$B$2:$B$7001,$AA2)&"") | F2: =IF($AA2="","",INDEX('Per Line'!$D$2:$D$7001,$AA2)&"") | G2: =IF($AA2="","",INDEX('Per Line'!$E$2:$E$7001,$AA2)) | H2: =IF($AA2="","",INDEX('Per Line'!$F$2:$F$7001,$AA2)&"") | I2: =IF($AA2="","",INDEX('Per Line'!$I$2:$I$7001,$AA2)&"") | J2: =IF($AA2="","",INDEX('Per Line'!$H$2:$H$7001,$AA2)&"") | K2: =IF($AA2="","",INDEX('Per Line'!$J$2:$J$7001,$AA2)&"") | L2: =IF($AA2="","",INDEX('Per Line'!$K$2:$K$7001,$AA2)&"") | M2: =IF($AA2="","",INDEX('Per Line'!$L$2:$L$7001,$AA2)) | N2: =IF($AA2="","",M2*Y2/100) | O2: =IF($AA2="","",INDEX('Per Line'!$U$2:$U$7001,$AA2)&"") | P2: =IF($AA2="","",SUMIFS('Per Line'!$T$2:$T$7001,'Per Line'!$C$2:$C$7001,$A2,'Per Line'!$AL$2:$AL$7001,1)) | Q2: =IF($AA2="","",Settings!$C$7) | R2: =IF($AA2="","",SUMIFS('Per Line'!$T$2:$T$7001,'Per Line'!$C$2:$C$7001,$A2,'Per Line'!$AK$2:$AK$7001,0,'Per Line'!$AL$2:$AL$7001,0)) | S2: =IF($AA2="","",R2*Q2) | T2: =IF($AA2="","",Settings!$C$6) | U2: =IF($AA2="","",SUMIFS('Per Line'!$T$2:$T$7001,'Per Line'!$C$2:$C$7001,$A2,'Per Line'!$AK$2:$AK$7001,1,'Per Line'!$AL$2:$AL$7001,0)) | V2: =IF($AA2="","",U2*T2) | W2: =IF($AA2="","",V2+S2) | X2: =IF($AA2="","",Y2-W2) | Y2: =IF($AA2="","",R2+U2+P2) | Z2: =IF($AA2="","",Y2-W2-N2) | AA2: =IF(ROWS($AA$2:$AA2)<=MAX('Per Line'!$AJ$2:$AJ$7001),MATCH(ROWS($AA$2:$AA2),'Per Line'!$AJ$2:$AJ$7001,0),"") | AB2: =IF($AA2="","",C2&"|"&COUNTIF($C$2:$C2,C2))
A3: =IF($AA3="","",INDEX('Per Line'!$C$2:$C$7001,$AA3)&"") | C3: =IF($AA3="","",IF(COUNTIF($I$2:$I$1301,I3)<=Settings!$C$8,I3,I3&" P"&ROUNDUP(COUNTIF($I$2:$I3,I3)/Settings!$C$8,0))) | D3: =IF($AA3="","",INDEX('Per Line'!$A$2:$A$7001,$AA3)&"") | E3: =IF($AA3="","",INDEX('Per Line'!$B$2:$B$7001,$AA3)&"") | F3: =IF($AA3="","",INDEX('Per Line'!$D$2:$D$7001,$AA3)&"") | G3: =IF($AA3="","",INDEX('Per Line'!$E$2:$E$7001,$AA3)) | H3: =IF($AA3="","",INDEX('Per Line'!$F$2:$F$7001,$AA3)&"") | I3: =IF($AA3="","",INDEX('Per Line'!$I$2:$I$7001,$AA3)&"") | J3: =IF($AA3="","",INDEX('Per Line'!$H$2:$H$7001,$AA3)&"") | K3: =IF($AA3="","",INDEX('Per Line'!$J$2:$J$7001,$AA3)&"") | L3: =IF($AA3="","",INDEX('Per Line'!$K$2:$K$7001,$AA3)&"") | M3: =IF($AA3="","",INDEX('Per Line'!$L$2:$L$7001,$AA3)) | N3: =IF($AA3="","",M3*Y3/100) | O3: =IF($AA3="","",INDEX('Per Line'!$U$2:$U$7001,$AA3)&"") | P3: =IF($AA3="","",SUMIFS('Per Line'!$T$2:$T$7001,'Per Line'!$C$2:$C$7001,$A3,'Per Line'!$AL$2:$AL$7001,1)) | Q3: =IF($AA3="","",Settings!$C$7) | R3: =IF($AA3="","",SUMIFS('Per Line'!$T$2:$T$7001,'Per Line'!$C$2:$C$7001,$A3,'Per Line'!$AK$2:$AK$7001,0,'Per Line'!$AL$2:$AL$7001,0)) | S3: =IF($AA3="","",R3*Q3) | T3: =IF($AA3="","",Settings!$C$6) | U3: =IF($AA3="","",SUMIFS('Per Line'!$T$2:$T$7001,'Per Line'!$C$2:$C$7001,$A3,'Per Line'!$AK$2:$AK$7001,1,'Per Line'!$AL$2:$AL$7001,0)) | V3: =IF($AA3="","",U3*T3) | W3: =IF($AA3="","",V3+S3) | X3: =IF($AA3="","",Y3-W3) | Y3: =IF($AA3="","",R3+U3+P3) | Z3: =IF($AA3="","",Y3-W3-N3) | AA3: =IF(ROWS($AA$2:$AA3)<=MAX('Per Line'!$AJ$2:$AJ$7001),MATCH(ROWS($AA$2:$AA3),'Per Line'!$AJ$2:$AJ$7001,0),"") | AB3: =IF($AA3="","",C3&"|"&COUNTIF($C$2:$C3,C3))
A4: =IF($AA4="","",INDEX('Per Line'!$C$2:$C$7001,$AA4)&"") | C4: =IF($AA4="","",IF(COUNTIF($I$2:$I$1301,I4)<=Settings!$C$8,I4,I4&" P"&ROUNDUP(COUNTIF($I$2:$I4,I4)/Settings!$C$8,0))) | D4: =IF($AA4="","",INDEX('Per Line'!$A$2:$A$7001,$AA4)&"") | E4: =IF($AA4="","",INDEX('Per Line'!$B$2:$B$7001,$AA4)&"") | F4: =IF($AA4="","",INDEX('Per Line'!$D$2:$D$7001,$AA4)&"") | G4: =IF($AA4="","",INDEX('Per Line'!$E$2:$E$7001,$AA4)) | H4: =IF($AA4="","",INDEX('Per Line'!$F$2:$F$7001,$AA4)&"") | I4: =IF($AA4="","",INDEX('Per Line'!$I$2:$I$7001,$AA4)&"") | J4: =IF($AA4="","",INDEX('Per Line'!$H$2:$H$7001,$AA4)&"") | K4: =IF($AA4="","",INDEX('Per Line'!$J$2:$J$7001,$AA4)&"") | L4: =IF($AA4="","",INDEX('Per Line'!$K$2:$K$7001,$AA4)&"") | M4: =IF($AA4="","",INDEX('Per Line'!$L$2:$L$7001,$AA4)) | N4: =IF($AA4="","",M4*Y4/100) | O4: =IF($AA4="","",INDEX('Per Line'!$U$2:$U$7001,$AA4)&"") | P4: =IF($AA4="","",SUMIFS('Per Line'!$T$2:$T$7001,'Per Line'!$C$2:$C$7001,$A4,'Per Line'!$AL$2:$AL$7001,1)) | Q4: =IF($AA4="","",Settings!$C$7) | R4: =IF($AA4="","",SUMIFS('Per Line'!$T$2:$T$7001,'Per Line'!$C$2:$C$7001,$A4,'Per Line'!$AK$2:$AK$7001,0,'Per Line'!$AL$2:$AL$7001,0)) | S4: =IF($AA4="","",R4*Q4) | T4: =IF($AA4="","",Settings!$C$6) | U4: =IF($AA4="","",SUMIFS('Per Line'!$T$2:$T$7001,'Per Line'!$C$2:$C$7001,$A4,'Per Line'!$AK$2:$AK$7001,1,'Per Line'!$AL$2:$AL$7001,0)) | V4: =IF($AA4="","",U4*T4) | W4: =IF($AA4="","",V4+S4) | X4: =IF($AA4="","",Y4-W4) | Y4: =IF($AA4="","",R4+U4+P4) | Z4: =IF($AA4="","",Y4-W4-N4) | AA4: =IF(ROWS($AA$2:$AA4)<=MAX('Per Line'!$AJ$2:$AJ$7001),MATCH(ROWS($AA$2:$AA4),'Per Line'!$AJ$2:$AJ$7001,0),"") | AB4: =IF($AA4="","",C4&"|"&COUNTIF($C$2:$C4,C4))
A5: =IF($AA5="","",INDEX('Per Line'!$C$2:$C$7001,$AA5)&"") | C5: =IF($AA5="","",IF(COUNTIF($I$2:$I$1301,I5)<=Settings!$C$8,I5,I5&" P"&ROUNDUP(COUNTIF($I$2:$I5,I5)/Settings!$C$8,0))) | D5: =IF($AA5="","",INDEX('Per Line'!$A$2:$A$7001,$AA5)&"") | E5: =IF($AA5="","",INDEX('Per Line'!$B$2:$B$7001,$AA5)&"") | F5: =IF($AA5="","",INDEX('Per Line'!$D$2:$D$7001,$AA5)&"") | G5: =IF($AA5="","",INDEX('Per Line'!$E$2:$E$7001,$AA5)) | H5: =IF($AA5="","",INDEX('Per Line'!$F$2:$F$7001,$AA5)&"") | I5: =IF($AA5="","",INDEX('Per Line'!$I$2:$I$7001,$AA5)&"") | J5: =IF($AA5="","",INDEX('Per Line'!$H$2:$H$7001,$AA5)&"") | K5: =IF($AA5="","",INDEX('Per Line'!$J$2:$J$7001,$AA5)&"") | L5: =IF($AA5="","",INDEX('Per Line'!$K$2:$K$7001,$AA5)&"") | M5: =IF($AA5="","",INDEX('Per Line'!$L$2:$L$7001,$AA5)) | N5: =IF($AA5="","",M5*Y5/100) | O5: =IF($AA5="","",INDEX('Per Line'!$U$2:$U$7001,$AA5)&"") | P5: =IF($AA5="","",SUMIFS('Per Line'!$T$2:$T$7001,'Per Line'!$C$2:$C$7001,$A5,'Per Line'!$AL$2:$AL$7001,1)) | Q5: =IF($AA5="","",Settings!$C$7) | R5: =IF($AA5="","",SUMIFS('Per Line'!$T$2:$T$7001,'Per Line'!$C$2:$C$7001,$A5,'Per Line'!$AK$2:$AK$7001,0,'Per Line'!$AL$2:$AL$7001,0)) | S5: =IF($AA5="","",R5*Q5) | T5: =IF($AA5="","",Settings!$C$6) | U5: =IF($AA5="","",SUMIFS('Per Line'!$T$2:$T$7001,'Per Line'!$C$2:$C$7001,$A5,'Per Line'!$AK$2:$AK$7001,1,'Per Line'!$AL$2:$AL$7001,0)) | V5: =IF($AA5="","",U5*T5) | W5: =IF($AA5="","",V5+S5) | X5: =IF($AA5="","",Y5-W5) | Y5: =IF($AA5="","",R5+U5+P5) | Z5: =IF($AA5="","",Y5-W5-N5) | AA5: =IF(ROWS($AA$2:$AA5)<=MAX('Per Line'!$AJ$2:$AJ$7001),MATCH(ROWS($AA$2:$AA5),'Per Line'!$AJ$2:$AJ$7001,0),"") | AB5: =IF($AA5="","",C5&"|"&COUNTIF($C$2:$C5,C5))
A6: =IF($AA6="","",INDEX('Per Line'!$C$2:$C$7001,$AA6)&"") | C6: =IF($AA6="","",IF(COUNTIF($I$2:$I$1301,I6)<=Settings!$C$8,I6,I6&" P"&ROUNDUP(COUNTIF($I$2:$I6,I6)/Settings!$C$8,0))) | D6: =IF($AA6="","",INDEX('Per Line'!$A$2:$A$7001,$AA6)&"") | E6: =IF($AA6="","",INDEX('Per Line'!$B$2:$B$7001,$AA6)&"") | F6: =IF($AA6="","",INDEX('Per Line'!$D$2:$D$7001,$AA6)&"") | G6: =IF($AA6="","",INDEX('Per Line'!$E$2:$E$7001,$AA6)) | H6: =IF($AA6="","",INDEX('Per Line'!$F$2:$F$7001,$AA6)&"") | I6: =IF($AA6="","",INDEX('Per Line'!$I$2:$I$7001,$AA6)&"") | J6: =IF($AA6="","",INDEX('Per Line'!$H$2:$H$7001,$AA6)&"") | K6: =IF($AA6="","",INDEX('Per Line'!$J$2:$J$7001,$AA6)&"") | L6: =IF($AA6="","",INDEX('Per Line'!$K$2:$K$7001,$AA6)&"") | M6: =IF($AA6="","",INDEX('Per Line'!$L$2:$L$7001,$AA6)) | N6: =IF($AA6="","",M6*Y6/100) | O6: =IF($AA6="","",INDEX('Per Line'!$U$2:$U$7001,$AA6)&"") | P6: =IF($AA6="","",SUMIFS('Per Line'!$T$2:$T$7001,'Per Line'!$C$2:$C$7001,$A6,'Per Line'!$AL$2:$AL$7001,1)) | Q6: =IF($AA6="","",Settings!$C$7) | R6: =IF($AA6="","",SUMIFS('Per Line'!$T$2:$T$7001,'Per Line'!$C$2:$C$7001,$A6,'Per Line'!$AK$2:$AK$7001,0,'Per Line'!$AL$2:$AL$7001,0)) | S6: =IF($AA6="","",R6*Q6) | T6: =IF($AA6="","",Settings!$C$6) | U6: =IF($AA6="","",SUMIFS('Per Line'!$T$2:$T$7001,'Per Line'!$C$2:$C$7001,$A6,'Per Line'!$AK$2:$AK$7001,1,'Per Line'!$AL$2:$AL$7001,0)) | V6: =IF($AA6="","",U6*T6) | W6: =IF($AA6="","",V6+S6) | X6: =IF($AA6="","",Y6-W6) | Y6: =IF($AA6="","",R6+U6+P6) | Z6: =IF($AA6="","",Y6-W6-N6) | AA6: =IF(ROWS($AA$2:$AA6)<=MAX('Per Line'!$AJ$2:$AJ$7001),MATCH(ROWS($AA$2:$AA6),'Per Line'!$AJ$2:$AJ$7001,0),"") | AB6: =IF($AA6="","",C6&"|"&COUNTIF($C$2:$C6,C6))
A7: =IF($AA7="","",INDEX('Per Line'!$C$2:$C$7001,$AA7)&"") | C7: =IF($AA7="","",IF(COUNTIF($I$2:$I$1301,I7)<=Settings!$C$8,I7,I7&" P"&ROUNDUP(COUNTIF($I$2:$I7,I7)/Settings!$C$8,0))) | D7: =IF($AA7="","",INDEX('Per Line'!$A$2:$A$7001,$AA7)&"") | E7: =IF($AA7="","",INDEX('Per Line'!$B$2:$B$7001,$AA7)&"") | F7: =IF($AA7="","",INDEX('Per Line'!$D$2:$D$7001,$AA7)&"") | G7: =IF($AA7="","",INDEX('Per Line'!$E$2:$E$7001,$AA7)) | H7: =IF($AA7="","",INDEX('Per Line'!$F$2:$F$7001,$AA7)&"") | I7: =IF($AA7="","",INDEX('Per Line'!$I$2:$I$7001,$AA7)&"") | J7: =IF($AA7="","",INDEX('Per Line'!$H$2:$H$7001,$AA7)&"") | K7: =IF($AA7="","",INDEX('Per Line'!$J$2:$J$7001,$AA7)&"") | L7: =IF($AA7="","",INDEX('Per Line'!$K$2:$K$7001,$AA7)&"") | M7: =IF($AA7="","",INDEX('Per Line'!$L$2:$L$7001,$AA7)) | N7: =IF($AA7="","",M7*Y7/100) | O7: =IF($AA7="","",INDEX('Per Line'!$U$2:$U$7001,$AA7)&"") | P7: =IF($AA7="","",SUMIFS('Per Line'!$T$2:$T$7001,'Per Line'!$C$2:$C$7001,$A7,'Per Line'!$AL$2:$AL$7001,1)) | Q7: =IF($AA7="","",Settings!$C$7) | R7: =IF($AA7="","",SUMIFS('Per Line'!$T$2:$T$7001,'Per Line'!$C$2:$C$7001,$A7,'Per Line'!$AK$2:$AK$7001,0,'Per Line'!$AL$2:$AL$7001,0)) | S7: =IF($AA7="","",R7*Q7) | T7: =IF($AA7="","",Settings!$C$6) | U7: =IF($AA7="","",SUMIFS('Per Line'!$T$2:$T$7001,'Per Line'!$C$2:$C$7001,$A7,'Per Line'!$AK$2:$AK$7001,1,'Per Line'!$AL$2:$AL$7001,0)) | V7: =IF($AA7="","",U7*T7) | W7: =IF($AA7="","",V7+S7) | X7: =IF($AA7="","",Y7-W7) | Y7: =IF($AA7="","",R7+U7+P7) | Z7: =IF($AA7="","",Y7-W7-N7) | AA7: =IF(ROWS($AA$2:$AA7)<=MAX('Per Line'!$AJ$2:$AJ$7001),MATCH(ROWS($AA$2:$AA7),'Per Line'!$AJ$2:$AJ$7001,0),"") | AB7: =IF($AA7="","",C7&"|"&COUNTIF($C$2:$C7,C7))
A8: =IF($AA8="","",INDEX('Per Line'!$C$2:$C$7001,$AA8)&"") | C8: =IF($AA8="","",IF(COUNTIF($I$2:$I$1301,I8)<=Settings!$C$8,I8,I8&" P"&ROUNDUP(COUNTIF($I$2:$I8,I8)/Settings!$C$8,0))) | D8: =IF($AA8="","",INDEX('Per Line'!$A$2:$A$7001,$AA8)&"") | E8: =IF($AA8="","",INDEX('Per Line'!$B$2:$B$7001,$AA8)&"") | F8: =IF($AA8="","",INDEX('Per Line'!$D$2:$D$7001,$AA8)&"") | G8: =IF($AA8="","",INDEX('Per Line'!$E$2:$E$7001,$AA8)) | H8: =IF($AA8="","",INDEX('Per Line'!$F$2:$F$7001,$AA8)&"") | I8: =IF($AA8="","",INDEX('Per Line'!$I$2:$I$7001,$AA8)&"") | J8: =IF($AA8="","",INDEX('Per Line'!$H$2:$H$7001,$AA8)&"") | K8: =IF($AA8="","",INDEX('Per Line'!$J$2:$J$7001,$AA8)&"") | L8: =IF($AA8="","",INDEX('Per Line'!$K$2:$K$7001,$AA8)&"") | M8: =IF($AA8="","",INDEX('Per Line'!$L$2:$L$7001,$AA8)) | N8: =IF($AA8="","",M8*Y8/100) | O8: =IF($AA8="","",INDEX('Per Line'!$U$2:$U$7001,$AA8)&"") | P8: =IF($AA8="","",SUMIFS('Per Line'!$T$2:$T$7001,'Per Line'!$C$2:$C$7001,$A8,'Per Line'!$AL$2:$AL$7001,1)) | Q8: =IF($AA8="","",Settings!$C$7) | R8: =IF($AA8="","",SUMIFS('Per Line'!$T$2:$T$7001,'Per Line'!$C$2:$C$7001,$A8,'Per Line'!$AK$2:$AK$7001,0,'Per Line'!$AL$2:$AL$7001,0)) | S8: =IF($AA8="","",R8*Q8) | T8: =IF($AA8="","",Settings!$C$6) | U8: =IF($AA8="","",SUMIFS('Per Line'!$T$2:$T$7001,'Per Line'!$C$2:$C$7001,$A8,'Per Line'!$AK$2:$AK$7001,1,'Per Line'!$AL$2:$AL$7001,0)) | V8: =IF($AA8="","",U8*T8) | W8: =IF($AA8="","",V8+S8) | X8: =IF($AA8="","",Y8-W8) | Y8: =IF($AA8="","",R8+U8+P8) | Z8: =IF($AA8="","",Y8-W8-N8) | AA8: =IF(ROWS($AA$2:$AA8)<=MAX('Per Line'!$AJ$2:$AJ$7001),MATCH(ROWS($AA$2:$AA8),'Per Line'!$AJ$2:$AJ$7001,0),"") | AB8: =IF($AA8="","",C8&"|"&COUNTIF($C$2:$C8,C8))
A9: =IF($AA9="","",INDEX('Per Line'!$C$2:$C$7001,$AA9)&"") | C9: =IF($AA9="","",IF(COUNTIF($I$2:$I$1301,I9)<=Settings!$C$8,I9,I9&" P"&ROUNDUP(COUNTIF($I$2:$I9,I9)/Settings!$C$8,0))) | D9: =IF($AA9="","",INDEX('Per Line'!$A$2:$A$7001,$AA9)&"") | E9: =IF($AA9="","",INDEX('Per Line'!$B$2:$B$7001,$AA9)&"") | F9: =IF($AA9="","",INDEX('Per Line'!$D$2:$D$7001,$AA9)&"") | G9: =IF($AA9="","",INDEX('Per Line'!$E$2:$E$7001,$AA9)) | H9: =IF($AA9="","",INDEX('Per Line'!$F$2:$F$7001,$AA9)&"") | I9: =IF($AA9="","",INDEX('Per Line'!$I$2:$I$7001,$AA9)&"") | J9: =IF($AA9="","",INDEX('Per Line'!$H$2:$H$7001,$AA9)&"") | K9: =IF($AA9="","",INDEX('Per Line'!$J$2:$J$7001,$AA9)&"") | L9: =IF($AA9="","",INDEX('Per Line'!$K$2:$K$7001,$AA9)&"") | M9: =IF($AA9="","",INDEX('Per Line'!$L$2:$L$7001,$AA9)) | N9: =IF($AA9="","",M9*Y9/100) | O9: =IF($AA9="","",INDEX('Per Line'!$U$2:$U$7001,$AA9)&"") | P9: =IF($AA9="","",SUMIFS('Per Line'!$T$2:$T$7001,'Per Line'!$C$2:$C$7001,$A9,'Per Line'!$AL$2:$AL$7001,1)) | Q9: =IF($AA9="","",Settings!$C$7) | R9: =IF($AA9="","",SUMIFS('Per Line'!$T$2:$T$7001,'Per Line'!$C$2:$C$7001,$A9,'Per Line'!$AK$2:$AK$7001,0,'Per Line'!$AL$2:$AL$7001,0)) | S9: =IF($AA9="","",R9*Q9) | T9: =IF($AA9="","",Settings!$C$6) | U9: =IF($AA9="","",SUMIFS('Per Line'!$T$2:$T$7001,'Per Line'!$C$2:$C$7001,$A9,'Per Line'!$AK$2:$AK$7001,1,'Per Line'!$AL$2:$AL$7001,0)) | V9: =IF($AA9="","",U9*T9) | W9: =IF($AA9="","",V9+S9) | X9: =IF($AA9="","",Y9-W9) | Y9: =IF($AA9="","",R9+U9+P9) | Z9: =IF($AA9="","",Y9-W9-N9) | AA9: =IF(ROWS($AA$2:$AA9)<=MAX('Per Line'!$AJ$2:$AJ$7001),MATCH(ROWS($AA$2:$AA9),'Per Line'!$AJ$2:$AJ$7001,0),"") | AB9: =IF($AA9="","",C9&"|"&COUNTIF($C$2:$C9,C9))
A10: =IF($AA10="","",INDEX('Per Line'!$C$2:$C$7001,$AA10)&"") | C10: =IF($AA10="","",IF(COUNTIF($I$2:$I$1301,I10)<=Settings!$C$8,I10,I10&" P"&ROUNDUP(COUNTIF($I$2:$I10,I10)/Settings!$C$8,0))) | D10: =IF($AA10="","",INDEX('Per Line'!$A$2:$A$7001,$AA10)&"") | E10: =IF($AA10="","",INDEX('Per Line'!$B$2:$B$7001,$AA10)&"") | F10: =IF($AA10="","",INDEX('Per Line'!$D$2:$D$7001,$AA10)&"") | G10: =IF($AA10="","",INDEX('Per Line'!$E$2:$E$7001,$AA10)) | H10: =IF($AA10="","",INDEX('Per Line'!$F$2:$F$7001,$AA10)&"") | I10: =IF($AA10="","",INDEX('Per Line'!$I$2:$I$7001,$AA10)&"") | J10: =IF($AA10="","",INDEX('Per Line'!$H$2:$H$7001,$AA10)&"") | K10: =IF($AA10="","",INDEX('Per Line'!$J$2:$J$7001,$AA10)&"") | L10: =IF($AA10="","",INDEX('Per Line'!$K$2:$K$7001,$AA10)&"") | M10: =IF($AA10="","",INDEX('Per Line'!$L$2:$L$7001,$AA10)) | N10: =IF($AA10="","",M10*Y10/100) | O10: =IF($AA10="","",INDEX('Per Line'!$U$2:$U$7001,$AA10)&"") | P10: =IF($AA10="","",SUMIFS('Per Line'!$T$2:$T$7001,'Per Line'!$C$2:$C$7001,$A10,'Per Line'!$AL$2:$AL$7001,1)) | Q10: =IF($AA10="","",Settings!$C$7) | R10: =IF($AA10="","",SUMIFS('Per Line'!$T$2:$T$7001,'Per Line'!$C$2:$C$7001,$A10,'Per Line'!$AK$2:$AK$7001,0,'Per Line'!$AL$2:$AL$7001,0)) | S10: =IF($AA10="","",R10*Q10) | T10: =IF($AA10="","",Settings!$C$6) | U10: =IF($AA10="","",SUMIFS('Per Line'!$T$2:$T$7001,'Per Line'!$C$2:$C$7001,$A10,'Per Line'!$AK$2:$AK$7001,1,'Per Line'!$AL$2:$AL$7001,0)) | V10: =IF($AA10="","",U10*T10) | W10: =IF($AA10="","",V10+S10) | X10: =IF($AA10="","",Y10-W10) | Y10: =IF($AA10="","",R10+U10+P10) | Z10: =IF($AA10="","",Y10-W10-N10) | AA10: =IF(ROWS($AA$2:$AA10)<=MAX('Per Line'!$AJ$2:$AJ$7001),MATCH(ROWS($AA$2:$AA10),'Per Line'!$AJ$2:$AJ$7001,0),"") | AB10: =IF($AA10="","",C10&"|"&COUNTIF($C$2:$C10,C10))
A11: =IF($AA11="","",INDEX('Per Line'!$C$2:$C$7001,$AA11)&"") | C11: =IF($AA11="","",IF(COUNTIF($I$2:$I$1301,I11)<=Settings!$C$8,I11,I11&" P"&ROUNDUP(COUNTIF($I$2:$I11,I11)/Settings!$C$8,0))) | D11: =IF($AA11="","",INDEX('Per Line'!$A$2:$A$7001,$AA11)&"") | E11: =IF($AA11="","",INDEX('Per Line'!$B$2:$B$7001,$AA11)&"") | F11: =IF($AA11="","",INDEX('Per Line'!$D$2:$D$7001,$AA11)&"") | G11: =IF($AA11="","",INDEX('Per Line'!$E$2:$E$7001,$AA11)) | H11: =IF($AA11="","",INDEX('Per Line'!$F$2:$F$7001,$AA11)&"") | I11: =IF($AA11="","",INDEX('Per Line'!$I$2:$I$7001,$AA11)&"") | J11: =IF($AA11="","",INDEX('Per Line'!$H$2:$H$7001,$AA11)&"") | K11: =IF($AA11="","",INDEX('Per Line'!$J$2:$J$7001,$AA11)&"") | L11: =IF($AA11="","",INDEX('Per Line'!$K$2:$K$7001,$AA11)&"") | M11: =IF($AA11="","",INDEX('Per Line'!$L$2:$L$7001,$AA11)) | N11: =IF($AA11="","",M11*Y11/100) | O11: =IF($AA11="","",INDEX('Per Line'!$U$2:$U$7001,$AA11)&"") | P11: =IF($AA11="","",SUMIFS('Per Line'!$T$2:$T$7001,'Per Line'!$C$2:$C$7001,$A11,'Per Line'!$AL$2:$AL$7001,1)) | Q11: =IF($AA11="","",Settings!$C$7) | R11: =IF($AA11="","",SUMIFS('Per Line'!$T$2:$T$7001,'Per Line'!$C$2:$C$7001,$A11,'Per Line'!$AK$2:$AK$7001,0,'Per Line'!$AL$2:$AL$7001,0)) | S11: =IF($AA11="","",R11*Q11) | T11: =IF($AA11="","",Settings!$C$6) | U11: =IF($AA11="","",SUMIFS('Per Line'!$T$2:$T$7001,'Per Line'!$C$2:$C$7001,$A11,'Per Line'!$AK$2:$AK$7001,1,'Per Line'!$AL$2:$AL$7001,0)) | V11: =IF($AA11="","",U11*T11) | W11: =IF($AA11="","",V11+S11) | X11: =IF($AA11="","",Y11-W11) | Y11: =IF($AA11="","",R11+U11+P11) | Z11: =IF($AA11="","",Y11-W11-N11) | AA11: =IF(ROWS($AA$2:$AA11)<=MAX('Per Line'!$AJ$2:$AJ$7001),MATCH(ROWS($AA$2:$AA11),'Per Line'!$AJ$2:$AJ$7001,0),"") | AB11: =IF($AA11="","",C11&"|"&COUNTIF($C$2:$C11,C11))
A12: =IF($AA12="","",INDEX('Per Line'!$C$2:$C$7001,$AA12)&"") | C12: =IF($AA12="","",IF(COUNTIF($I$2:$I$1301,I12)<=Settings!$C$8,I12,I12&" P"&ROUNDUP(COUNTIF($I$2:$I12,I12)/Settings!$C$8,0))) | D12: =IF($AA12="","",INDEX('Per Line'!$A$2:$A$7001,$AA12)&"") | E12: =IF($AA12="","",INDEX('Per Line'!$B$2:$B$7001,$AA12)&"") | F12: =IF($AA12="","",INDEX('Per Line'!$D$2:$D$7001,$AA12)&"") | G12: =IF($AA12="","",INDEX('Per Line'!$E$2:$E$7001,$AA12)) | H12: =IF($AA12="","",INDEX('Per Line'!$F$2:$F$7001,$AA12)&"") | I12: =IF($AA12="","",INDEX('Per Line'!$I$2:$I$7001,$AA12)&"") | J12: =IF($AA12="","",INDEX('Per Line'!$H$2:$H$7001,$AA12)&"") | K12: =IF($AA12="","",INDEX('Per Line'!$J$2:$J$7001,$AA12)&"") | L12: =IF($AA12="","",INDEX('Per Line'!$K$2:$K$7001,$AA12)&"") | M12: =IF($AA12="","",INDEX('Per Line'!$L$2:$L$7001,$AA12)) | N12: =IF($AA12="","",M12*Y12/100) | O12: =IF($AA12="","",INDEX('Per Line'!$U$2:$U$7001,$AA12)&"") | P12: =IF($AA12="","",SUMIFS('Per Line'!$T$2:$T$7001,'Per Line'!$C$2:$C$7001,$A12,'Per Line'!$AL$2:$AL$7001,1)) | Q12: =IF($AA12="","",Settings!$C$7) | R12: =IF($AA12="","",SUMIFS('Per Line'!$T$2:$T$7001,'Per Line'!$C$2:$C$7001,$A12,'Per Line'!$AK$2:$AK$7001,0,'Per Line'!$AL$2:$AL$7001,0)) | S12: =IF($AA12="","",R12*Q12) | T12: =IF($AA12="","",Settings!$C$6) | U12: =IF($AA12="","",SUMIFS('Per Line'!$T$2:$T$7001,'Per Line'!$C$2:$C$7001,$A12,'Per Line'!$AK$2:$AK$7001,1,'Per Line'!$AL$2:$AL$7001,0)) | V12: =IF($AA12="","",U12*T12) | W12: =IF($AA12="","",V12+S12) | X12: =IF($AA12="","",Y12-W12) | Y12: =IF($AA12="","",R12+U12+P12) | Z12: =IF($AA12="","",Y12-W12-N12) | AA12: =IF(ROWS($AA$2:$AA12)<=MAX('Per Line'!$AJ$2:$AJ$7001),MATCH(ROWS($AA$2:$AA12),'Per Line'!$AJ$2:$AJ$7001,0),"") | AB12: =IF($AA12="","",C12&"|"&COUNTIF($C$2:$C12,C12))
A13: =IF($AA13="","",INDEX('Per Line'!$C$2:$C$7001,$AA13)&"") | C13: =IF($AA13="","",IF(COUNTIF($I$2:$I$1301,I13)<=Settings!$C$8,I13,I13&" P"&ROUNDUP(COUNTIF($I$2:$I13,I13)/Settings!$C$8,0))) | D13: =IF($AA13="","",INDEX('Per Line'!$A$2:$A$7001,$AA13)&"") | E13: =IF($AA13="","",INDEX('Per Line'!$B$2:$B$7001,$AA13)&"") | F13: =IF($AA13="","",INDEX('Per Line'!$D$2:$D$7001,$AA13)&"") | G13: =IF($AA13="","",INDEX('Per Line'!$E$2:$E$7001,$AA13)) | H13: =IF($AA13="","",INDEX('Per Line'!$F$2:$F$7001,$AA13)&"") | I13: =IF($AA13="","",INDEX('Per Line'!$I$2:$I$7001,$AA13)&"") | J13: =IF($AA13="","",INDEX('Per Line'!$H$2:$H$7001,$AA13)&"") | K13: =IF($AA13="","",INDEX('Per Line'!$J$2:$J$7001,$AA13)&"") | L13: =IF($AA13="","",INDEX('Per Line'!$K$2:$K$7001,$AA13)&"") | M13: =IF($AA13="","",INDEX('Per Line'!$L$2:$L$7001,$AA13)) | N13: =IF($AA13="","",M13*Y13/100) | O13: =IF($AA13="","",INDEX('Per Line'!$U$2:$U$7001,$AA13)&"") | P13: =IF($AA13="","",SUMIFS('Per Line'!$T$2:$T$7001,'Per Line'!$C$2:$C$7001,$A13,'Per Line'!$AL$2:$AL$7001,1)) | Q13: =IF($AA13="","",Settings!$C$7) | R13: =IF($AA13="","",SUMIFS('Per Line'!$T$2:$T$7001,'Per Line'!$C$2:$C$7001,$A13,'Per Line'!$AK$2:$AK$7001,0,'Per Line'!$AL$2:$AL$7001,0)) | S13: =IF($AA13="","",R13*Q13) | T13: =IF($AA13="","",Settings!$C$6) | U13: =IF($AA13="","",SUMIFS('Per Line'!$T$2:$T$7001,'Per Line'!$C$2:$C$7001,$A13,'Per Line'!$AK$2:$AK$7001,1,'Per Line'!$AL$2:$AL$7001,0)) | V13: =IF($AA13="","",U13*T13) | W13: =IF($AA13="","",V13+S13) | X13: =IF($AA13="","",Y13-W13) | Y13: =IF($AA13="","",R13+U13+P13) | Z13: =IF($AA13="","",Y13-W13-N13) | AA13: =IF(ROWS($AA$2:$AA13)<=MAX('Per Line'!$AJ$2:$AJ$7001),MATCH(ROWS($AA$2:$AA13),'Per Line'!$AJ$2:$AJ$7001,0),"") | AB13: =IF($AA13="","",C13&"|"&COUNTIF($C$2:$C13,C13))
... A1301: =IF($AA1301="","",INDEX('Per Line'!$C$2:$C$7001,$AA1301)&"") | C1301: =IF($AA1301="","",IF(COUNTIF($I$2:$I$1301,I1301)<=Settings!$C$8,I1301,I1301&" P"&ROUNDUP(COUNTIF($I$2:$I1301,I1301)/Settings!$C$8,0))) | D1301: =IF($AA1301="","",INDEX('Per Line'!$A$2:$A$7001,$AA1301)&"") | E1301: =IF($AA1301="","",INDEX('Per Line'!$B$2:$B$7001,$AA1301)&"") | F1301: =IF($AA1301="","",INDEX('Per Line'!$D$2:$D$7001,$AA1301)&"") | G1301: =IF($AA1301="","",INDEX('Per Line'!$E$2:$E$7001,$AA1301)) | H1301: =IF($AA1301="","",INDEX('Per Line'!$F$2:$F$7001,$AA1301)&"") | I1301: =IF($AA1301="","",INDEX('Per Line'!$I$2:$I$7001,$AA1301)&"") | J1301: =IF($AA1301="","",INDEX('Per Line'!$H$2:$H$7001,$AA1301)&"") | K1301: =IF($AA1301="","",INDEX('Per Line'!$J$2:$J$7001,$AA1301)&"") | L1301: =IF($AA1301="","",INDEX('Per Line'!$K$2:$K$7001,$AA1301)&"") | M1301: =IF($AA1301="","",INDEX('Per Line'!$L$2:$L$7001,$AA1301)) | N1301: =IF($AA1301="","",M1301*Y1301/100) | O1301: =IF($AA1301="","",INDEX('Per Line'!$U$2:$U$7001,$AA1301)&"") | P1301: =IF($AA1301="","",SUMIFS('Per Line'!$T$2:$T$7001,'Per Line'!$C$2:$C$7001,$A1301,'Per Line'!$AL$2:$AL$7001,1)) | Q1301: =IF($AA1301="","",Settings!$C$7) | R1301: =IF($AA1301="","",SUMIFS('Per Line'!$T$2:$T$7001,'Per Line'!$C$2:$C$7001,$A1301,'Per Line'!$AK$2:$AK$7001,0,'Per Line'!$AL$2:$AL$7001,0)) | S1301: =IF($AA1301="","",R1301*Q1301) | T1301: =IF($AA1301="","",Settings!$C$6) | U1301: =IF($AA1301="","",SUMIFS('Per Line'!$T$2:$T$7001,'Per Line'!$C$2:$C$7001,$A1301,'Per Line'!$AK$2:$AK$7001,1,'Per Line'!$AL$2:$AL$7001,0)) | V1301: =IF($AA1301="","",U1301*T1301) | W1301: =IF($AA1301="","",V1301+S1301) | X1301: =IF($AA1301="","",Y1301-W1301) | Y1301: =IF($AA1301="","",R1301+U1301+P1301) | Z1301: =IF($AA1301="","",Y1301-W1301-N1301) | AA1301: =IF(ROWS($AA$2:$AA1301)<=MAX('Per Line'!$AJ$2:$AJ$7001),MATCH(ROWS($AA$2:$AA1301),'Per Line'!$AJ$2:$AJ$7001,0),"") | AB1301: =IF($AA1301="","",C1301&"|"&COUNTIF($C$2:$C1301,C1301))

Sheet Petrojet Haram 4th line
A1: Order # | B1: Invoice | C1: Site Tab (##) | D1: Cycle | E1: Stage | F1: Channel | G1: Create At | H1: Insurance Company | I1: Corporate | J1: card | K1: Name | L1: Status | M1: Order Co Payment | N1: Co val | O1: ERX ID | P1: SP | Q1: IMP% | R1: IMP | S1: IMP VAL | T1: LOCAL% | U1: LOCAL | V1: LOCAL VAL | W1: TOTAL VAL | X1: SUBTOTAL | Y1: Grand Total | Z1: NET | AA1: Src Row (helper)
A2: =IF($AA2="","",IF(INDEX('Per Invoice'!A$2:A$1301,$AA2)="","",INDEX('Per Invoice'!A$2:A$1301,$AA2))) | B2: =IF($AA2="","",IF(INDEX('Per Invoice'!B$2:B$1301,$AA2)="","",INDEX('Per Invoice'!B$2:B$1301,$AA2))) | C2: =IF($AA2="","",IF(INDEX('Per Invoice'!C$2:C$1301,$AA2)="","",INDEX('Per Invoice'!C$2:C$1301,$AA2))) | D2: =IF($AA2="","",IF(INDEX('Per Invoice'!D$2:D$1301,$AA2)="","",INDEX('Per Invoice'!D$2:D$1301,$AA2))) | E2: =IF($AA2="","",IF(INDEX('Per Invoice'!E$2:E$1301,$AA2)="","",INDEX('Per Invoice'!E$2:E$1301,$AA2))) | F2: =IF($AA2="","",IF(INDEX('Per Invoice'!F$2:F$1301,$AA2)="","",INDEX('Per Invoice'!F$2:F$1301,$AA2))) | G2: =IF($AA2="","",IF(INDEX('Per Invoice'!G$2:G$1301,$AA2)="","",INDEX('Per Invoice'!G$2:G$1301,$AA2))) | H2: =IF($AA2="","",IF(INDEX('Per Invoice'!H$2:H$1301,$AA2)="","",INDEX('Per Invoice'!H$2:H$1301,$AA2))) | ... Z2: =IF($AA2="","",IF(INDEX('Per Invoice'!Z$2:Z$1301,$AA2)="","",INDEX('Per Invoice'!Z$2:Z$1301,$AA2))) | AA2: =IFERROR(MATCH(Settings!$C$26&"|"&ROWS($AA$2:$AA2),'Per Invoice'!$AB$2:$AB$1301,0),"")
A3: =IF($AA3="","",IF(INDEX('Per Invoice'!A$2:A$1301,$AA3)="","",INDEX('Per Invoice'!A$2:A$1301,$AA3))) | B3: =IF($AA3="","",IF(INDEX('Per Invoice'!B$2:B$1301,$AA3)="","",INDEX('Per Invoice'!B$2:B$1301,$AA3))) | C3: =IF($AA3="","",IF(INDEX('Per Invoice'!C$2:C$1301,$AA3)="","",INDEX('Per Invoice'!C$2:C$1301,$AA3))) | D3: =IF($AA3="","",IF(INDEX('Per Invoice'!D$2:D$1301,$AA3)="","",INDEX('Per Invoice'!D$2:D$1301,$AA3))) | E3: =IF($AA3="","",IF(INDEX('Per Invoice'!E$2:E$1301,$AA3)="","",INDEX('Per Invoice'!E$2:E$1301,$AA3))) | F3: =IF($AA3="","",IF(INDEX('Per Invoice'!F$2:F$1301,$AA3)="","",INDEX('Per Invoice'!F$2:F$1301,$AA3))) | G3: =IF($AA3="","",IF(INDEX('Per Invoice'!G$2:G$1301,$AA3)="","",INDEX('Per Invoice'!G$2:G$1301,$AA3))) | H3: =IF($AA3="","",IF(INDEX('Per Invoice'!H$2:H$1301,$AA3)="","",INDEX('Per Invoice'!H$2:H$1301,$AA3))) | ... Z3: =IF($AA3="","",IF(INDEX('Per Invoice'!Z$2:Z$1301,$AA3)="","",INDEX('Per Invoice'!Z$2:Z$1301,$AA3))) | AA3: =IFERROR(MATCH(Settings!$C$26&"|"&ROWS($AA$2:$AA3),'Per Invoice'!$AB$2:$AB$1301,0),"")
A4: =IF($AA4="","",IF(INDEX('Per Invoice'!A$2:A$1301,$AA4)="","",INDEX('Per Invoice'!A$2:A$1301,$AA4))) | B4: =IF($AA4="","",IF(INDEX('Per Invoice'!B$2:B$1301,$AA4)="","",INDEX('Per Invoice'!B$2:B$1301,$AA4))) | C4: =IF($AA4="","",IF(INDEX('Per Invoice'!C$2:C$1301,$AA4)="","",INDEX('Per Invoice'!C$2:C$1301,$AA4))) | D4: =IF($AA4="","",IF(INDEX('Per Invoice'!D$2:D$1301,$AA4)="","",INDEX('Per Invoice'!D$2:D$1301,$AA4))) | E4: =IF($AA4="","",IF(INDEX('Per Invoice'!E$2:E$1301,$AA4)="","",INDEX('Per Invoice'!E$2:E$1301,$AA4))) | F4: =IF($AA4="","",IF(INDEX('Per Invoice'!F$2:F$1301,$AA4)="","",INDEX('Per Invoice'!F$2:F$1301,$AA4))) | G4: =IF($AA4="","",IF(INDEX('Per Invoice'!G$2:G$1301,$AA4)="","",INDEX('Per Invoice'!G$2:G$1301,$AA4))) | H4: =IF($AA4="","",IF(INDEX('Per Invoice'!H$2:H$1301,$AA4)="","",INDEX('Per Invoice'!H$2:H$1301,$AA4))) | ... Z4: =IF($AA4="","",IF(INDEX('Per Invoice'!Z$2:Z$1301,$AA4)="","",INDEX('Per Invoice'!Z$2:Z$1301,$AA4))) | AA4: =IFERROR(MATCH(Settings!$C$26&"|"&ROWS($AA$2:$AA4),'Per Invoice'!$AB$2:$AB$1301,0),"")
A5: =IF($AA5="","",IF(INDEX('Per Invoice'!A$2:A$1301,$AA5)="","",INDEX('Per Invoice'!A$2:A$1301,$AA5))) | B5: =IF($AA5="","",IF(INDEX('Per Invoice'!B$2:B$1301,$AA5)="","",INDEX('Per Invoice'!B$2:B$1301,$AA5))) | C5: =IF($AA5="","",IF(INDEX('Per Invoice'!C$2:C$1301,$AA5)="","",INDEX('Per Invoice'!C$2:C$1301,$AA5))) | D5: =IF($AA5="","",IF(INDEX('Per Invoice'!D$2:D$1301,$AA5)="","",INDEX('Per Invoice'!D$2:D$1301,$AA5))) | E5: =IF($AA5="","",IF(INDEX('Per Invoice'!E$2:E$1301,$AA5)="","",INDEX('Per Invoice'!E$2:E$1301,$AA5))) | F5: =IF($AA5="","",IF(INDEX('Per Invoice'!F$2:F$1301,$AA5)="","",INDEX('Per Invoice'!F$2:F$1301,$AA5))) | G5: =IF($AA5="","",IF(INDEX('Per Invoice'!G$2:G$1301,$AA5)="","",INDEX('Per Invoice'!G$2:G$1301,$AA5))) | H5: =IF($AA5="","",IF(INDEX('Per Invoice'!H$2:H$1301,$AA5)="","",INDEX('Per Invoice'!H$2:H$1301,$AA5))) | ... Z5: =IF($AA5="","",IF(INDEX('Per Invoice'!Z$2:Z$1301,$AA5)="","",INDEX('Per Invoice'!Z$2:Z$1301,$AA5))) | AA5: =IFERROR(MATCH(Settings!$C$26&"|"&ROWS($AA$2:$AA5),'Per Invoice'!$AB$2:$AB$1301,0),"")
A6: =IF($AA6="","",IF(INDEX('Per Invoice'!A$2:A$1301,$AA6)="","",INDEX('Per Invoice'!A$2:A$1301,$AA6))) | B6: =IF($AA6="","",IF(INDEX('Per Invoice'!B$2:B$1301,$AA6)="","",INDEX('Per Invoice'!B$2:B$1301,$AA6))) | C6: =IF($AA6="","",IF(INDEX('Per Invoice'!C$2:C$1301,$AA6)="","",INDEX('Per Invoice'!C$2:C$1301,$AA6))) | D6: =IF($AA6="","",IF(INDEX('Per Invoice'!D$2:D$1301,$AA6)="","",INDEX('Per Invoice'!D$2:D$1301,$AA6))) | E6: =IF($AA6="","",IF(INDEX('Per Invoice'!E$2:E$1301,$AA6)="","",INDEX('Per Invoice'!E$2:E$1301,$AA6))) | F6: =IF($AA6="","",IF(INDEX('Per Invoice'!F$2:F$1301,$AA6)="","",INDEX('Per Invoice'!F$2:F$1301,$AA6))) | G6: =IF($AA6="","",IF(INDEX('Per Invoice'!G$2:G$1301,$AA6)="","",INDEX('Per Invoice'!G$2:G$1301,$AA6))) | H6: =IF($AA6="","",IF(INDEX('Per Invoice'!H$2:H$1301,$AA6)="","",INDEX('Per Invoice'!H$2:H$1301,$AA6))) | ... Z6: =IF($AA6="","",IF(INDEX('Per Invoice'!Z$2:Z$1301,$AA6)="","",INDEX('Per Invoice'!Z$2:Z$1301,$AA6))) | AA6: =IFERROR(MATCH(Settings!$C$26&"|"&ROWS($AA$2:$AA6),'Per Invoice'!$AB$2:$AB$1301,0),"")
A7: =IF($AA7="","",IF(INDEX('Per Invoice'!A$2:A$1301,$AA7)="","",INDEX('Per Invoice'!A$2:A$1301,$AA7))) | B7: =IF($AA7="","",IF(INDEX('Per Invoice'!B$2:B$1301,$AA7)="","",INDEX('Per Invoice'!B$2:B$1301,$AA7))) | C7: =IF($AA7="","",IF(INDEX('Per Invoice'!C$2:C$1301,$AA7)="","",INDEX('Per Invoice'!C$2:C$1301,$AA7))) | D7: =IF($AA7="","",IF(INDEX('Per Invoice'!D$2:D$1301,$AA7)="","",INDEX('Per Invoice'!D$2:D$1301,$AA7))) | E7: =IF($AA7="","",IF(INDEX('Per Invoice'!E$2:E$1301,$AA7)="","",INDEX('Per Invoice'!E$2:E$1301,$AA7))) | F7: =IF($AA7="","",IF(INDEX('Per Invoice'!F$2:F$1301,$AA7)="","",INDEX('Per Invoice'!F$2:F$1301,$AA7))) | G7: =IF($AA7="","",IF(INDEX('Per Invoice'!G$2:G$1301,$AA7)="","",INDEX('Per Invoice'!G$2:G$1301,$AA7))) | H7: =IF($AA7="","",IF(INDEX('Per Invoice'!H$2:H$1301,$AA7)="","",INDEX('Per Invoice'!H$2:H$1301,$AA7))) | ... Z7: =IF($AA7="","",IF(INDEX('Per Invoice'!Z$2:Z$1301,$AA7)="","",INDEX('Per Invoice'!Z$2:Z$1301,$AA7))) | AA7: =IFERROR(MATCH(Settings!$C$26&"|"&ROWS($AA$2:$AA7),'Per Invoice'!$AB$2:$AB$1301,0),"")
A8: =IF($AA8="","",IF(INDEX('Per Invoice'!A$2:A$1301,$AA8)="","",INDEX('Per Invoice'!A$2:A$1301,$AA8))) | B8: =IF($AA8="","",IF(INDEX('Per Invoice'!B$2:B$1301,$AA8)="","",INDEX('Per Invoice'!B$2:B$1301,$AA8))) | C8: =IF($AA8="","",IF(INDEX('Per Invoice'!C$2:C$1301,$AA8)="","",INDEX('Per Invoice'!C$2:C$1301,$AA8))) | D8: =IF($AA8="","",IF(INDEX('Per Invoice'!D$2:D$1301,$AA8)="","",INDEX('Per Invoice'!D$2:D$1301,$AA8))) | E8: =IF($AA8="","",IF(INDEX('Per Invoice'!E$2:E$1301,$AA8)="","",INDEX('Per Invoice'!E$2:E$1301,$AA8))) | F8: =IF($AA8="","",IF(INDEX('Per Invoice'!F$2:F$1301,$AA8)="","",INDEX('Per Invoice'!F$2:F$1301,$AA8))) | G8: =IF($AA8="","",IF(INDEX('Per Invoice'!G$2:G$1301,$AA8)="","",INDEX('Per Invoice'!G$2:G$1301,$AA8))) | H8: =IF($AA8="","",IF(INDEX('Per Invoice'!H$2:H$1301,$AA8)="","",INDEX('Per Invoice'!H$2:H$1301,$AA8))) | ... Z8: =IF($AA8="","",IF(INDEX('Per Invoice'!Z$2:Z$1301,$AA8)="","",INDEX('Per Invoice'!Z$2:Z$1301,$AA8))) | AA8: =IFERROR(MATCH(Settings!$C$26&"|"&ROWS($AA$2:$AA8),'Per Invoice'!$AB$2:$AB$1301,0),"")
A9: =IF($AA9="","",IF(INDEX('Per Invoice'!A$2:A$1301,$AA9)="","",INDEX('Per Invoice'!A$2:A$1301,$AA9))) | B9: =IF($AA9="","",IF(INDEX('Per Invoice'!B$2:B$1301,$AA9)="","",INDEX('Per Invoice'!B$2:B$1301,$AA9))) | C9: =IF($AA9="","",IF(INDEX('Per Invoice'!C$2:C$1301,$AA9)="","",INDEX('Per Invoice'!C$2:C$1301,$AA9))) | D9: =IF($AA9="","",IF(INDEX('Per Invoice'!D$2:D$1301,$AA9)="","",INDEX('Per Invoice'!D$2:D$1301,$AA9))) | E9: =IF($AA9="","",IF(INDEX('Per Invoice'!E$2:E$1301,$AA9)="","",INDEX('Per Invoice'!E$2:E$1301,$AA9))) | F9: =IF($AA9="","",IF(INDEX('Per Invoice'!F$2:F$1301,$AA9)="","",INDEX('Per Invoice'!F$2:F$1301,$AA9))) | G9: =IF($AA9="","",IF(INDEX('Per Invoice'!G$2:G$1301,$AA9)="","",INDEX('Per Invoice'!G$2:G$1301,$AA9))) | H9: =IF($AA9="","",IF(INDEX('Per Invoice'!H$2:H$1301,$AA9)="","",INDEX('Per Invoice'!H$2:H$1301,$AA9))) | ... Z9: =IF($AA9="","",IF(INDEX('Per Invoice'!Z$2:Z$1301,$AA9)="","",INDEX('Per Invoice'!Z$2:Z$1301,$AA9))) | AA9: =IFERROR(MATCH(Settings!$C$26&"|"&ROWS($AA$2:$AA9),'Per Invoice'!$AB$2:$AB$1301,0),"")
A10: =IF($AA10="","",IF(INDEX('Per Invoice'!A$2:A$1301,$AA10)="","",INDEX('Per Invoice'!A$2:A$1301,$AA10))) | B10: =IF($AA10="","",IF(INDEX('Per Invoice'!B$2:B$1301,$AA10)="","",INDEX('Per Invoice'!B$2:B$1301,$AA10))) | C10: =IF($AA10="","",IF(INDEX('Per Invoice'!C$2:C$1301,$AA10)="","",INDEX('Per Invoice'!C$2:C$1301,$AA10))) | D10: =IF($AA10="","",IF(INDEX('Per Invoice'!D$2:D$1301,$AA10)="","",INDEX('Per Invoice'!D$2:D$1301,$AA10))) | E10: =IF($AA10="","",IF(INDEX('Per Invoice'!E$2:E$1301,$AA10)="","",INDEX('Per Invoice'!E$2:E$1301,$AA10))) | F10: =IF($AA10="","",IF(INDEX('Per Invoice'!F$2:F$1301,$AA10)="","",INDEX('Per Invoice'!F$2:F$1301,$AA10))) | G10: =IF($AA10="","",IF(INDEX('Per Invoice'!G$2:G$1301,$AA10)="","",INDEX('Per Invoice'!G$2:G$1301,$AA10))) | H10: =IF($AA10="","",IF(INDEX('Per Invoice'!H$2:H$1301,$AA10)="","",INDEX('Per Invoice'!H$2:H$1301,$AA10))) | ... Z10: =IF($AA10="","",IF(INDEX('Per Invoice'!Z$2:Z$1301,$AA10)="","",INDEX('Per Invoice'!Z$2:Z$1301,$AA10))) | AA10: =IFERROR(MATCH(Settings!$C$26&"|"&ROWS($AA$2:$AA10),'Per Invoice'!$AB$2:$AB$1301,0),"")
