Workbook

Sheet How To Use
A1: Claims Template - SAINCO (Walk In)
A3: Monthly steps
A4: 1. Open the 'Per Line' tab. Delete the old data in the BLUE columns only (row 2 down). Never delete the green or grey columns.
A5: 2. Paste the new month's data as VALUES starting at A2, into the blue columns: B-F, H-L, P-S (same order as the system export).
A6: 3. Green columns (A, G, M, N, O, T) and the grey helper columns (U-X) calculate automatically - do not paste over them.
A7: 4. 'Per Invoice' fills itself from 'Per Line' (one row per Order #, split into IMP / Local). No pivot table, no refresh.
A8: 5. The ONLY manual column in 'Per Invoice' is column C 'Invoice' (blue): type it yourself. Everything else is formula.
A9: 6. The tabs, the Arabic 'Statement ...' sheets and 'Summary' fill themselves from 'Per Invoice'. Column 'Copay Tab (##)' decides which tab each invoice goes to (rule and limit are in Settings).
A10: 7. Open 'Settings' and check STATUS says OK (Per Line = Per Invoice, and every invoice has a payer that is listed in Settings).
A12: Colour legend
A13: Blue header = typed/pasted by you (raw data, and 'Invoice' in Per Invoice). Green header = formula (do not paste over). Grey header = helper formula (do not touch). Yellow cell (Settings) = editable rate.
A15: Calculation rules (taken from the August 2026 sheet)
... A21: Capacity: up to 1,500 lines and 400 invoices per month. A line with an empty Order # is ignored.

Sheet Settings
B1: Company settings & checks
B3: Insurance Company | C3: SAINCO | D3: Informational only
B4: Corporate | C4: - | D4: Informational only
B5: Sheet type | C5: Walk In | D5: Informational only
B6: Local products rebate % | C6: 0.16 | D6: Source: Aug sheet (Rebates = 16 on Local lines).
B7: Imported (IMP) products rebate % | C7: 0.06 | D7: Source: Aug sheet (Rebates = 6 on non-local lines).
B9: Month totals / reconciliation
B10: Lines loaded | C10: =COUNTA('Per Line'!$B$2:$B$1501)
B11: Invoices (unique Order #) | C11: =MAX('Per Line'!$V$2:$V$1501)
B12: Invoices shown in Per Invoice | C12: =SUMPRODUCT(--('Per Invoice'!$A$2:$A$401<>""))
B13: Grand Total - Per Line (Product Total) | C13: =SUM('Per Line'!$L$2:$L$1501)
B14: Grand Total - Per Invoice | C14: =SUM('Per Invoice'!$S$2:$S$401)
B15: Discount - Per Line | C15: =SUM('Per Line'!$M$2:$M$1501)
B16: Discount - Per Invoice | C16: =SUM('Per Invoice'!$Q$2:$Q$401)
B17: Co val - Per Line | C17: =SUM('Per Line'!$G$2:$G$1501)
B18: Co val - Per Invoice | C18: =SUM('Per Invoice'!$H$2:$H$401)
B19: Net - Per Line | C19: =SUM('Per Line'!$O$2:$O$1501)
B20: Net - Per Invoice | C20: =SUM('Per Invoice'!$T$2:$T$401)
B21: Max Limit adjustment (Co val, Per Invoice only) | C21: 0 | D21: This company's Per Invoice has no Max Limit rule.
B23: STATUS | C23: =IF(C10=0,"No data loaded",IF(COUNTA('Per Line'!$B:$B)-1>1500,"TOO MANY LINES - extend template",IF(C11>400,"TOO MANY INVOICES - extend template",IF(AND(ROUND(C13-C14,2)=0,ROUND(C15-C16,2)=0,ROUND(C17+C21-C18,2)=0,ROUND(C19-C21-C20,2)=0,C11=C12,C32=0,MAX(D26:D30)<=300),"OK","CHECK - Per Line and Per Invoice do not match")))) | D23: Must say OK after you paste the month data.
B25: Copay tabs | C25: Copay name exactly as in the Copay Tab (##) column | D25: Invoices (formula)
B26: COPY 30 % | C26: COPY 30 % | D26: =IF(C26="",0,COUNTIF('Per Invoice'!$B$2:$B$401,C26))
B27: COPY 20 % | C27: COPY 20 % | D27: =IF(C27="",0,COUNTIF('Per Invoice'!$B$2:$B$401,C27))
B28: COPY 10 % | C28: COPY 10 % | D28: =IF(C28="",0,COUNTIF('Per Invoice'!$B$2:$B$401,C28))
B29: Extra 1 | D29: =IF(C29="",0,COUNTIF('Per Invoice'!$B$2:$B$401,C29))
B30: Extra 2 | D30: =IF(C30="",0,COUNTIF('Per Invoice'!$B$2:$B$401,C30))
B32: Invoices not in any copay tab (must be 0) | C32: =C11-SUM(D26:D30) | D32: If not 0: a new copay appeared. Type its exact name in one of the empty yellow cells above (Extra 1 ... Extra n); the tab Extra n then shows it. Each tab holds up to 300 invoices.

Sheet Summary
A1: Copay tab | B1: Count of Orders | C1: Local | D1: Imported | E1: Grand Total | F1: Discount | G1: Patient share (CO VAL) | H1: Net
A2: =IF(Settings!$C$26="","",Settings!$C$26) | B2: =IF($A2="","",COUNTIF('Per Invoice'!$B$2:$B$401,$A2)) | C2: =IF($A2="","",SUMIFS('Per Invoice'!$O$2:$O$401,'Per Invoice'!$B$2:$B$401,$A2)) | D2: =IF($A2="","",SUMIFS('Per Invoice'!$L$2:$L$401,'Per Invoice'!$B$2:$B$401,$A2)) | E2: =IF($A2="","",SUMIFS('Per Invoice'!$S$2:$S$401,'Per Invoice'!$B$2:$B$401,$A2)) | F2: =IF($A2="","",SUMIFS('Per Invoice'!$Q$2:$Q$401,'Per Invoice'!$B$2:$B$401,$A2)) | G2: =IF($A2="","",SUMIFS('Per Invoice'!$H$2:$H$401,'Per Invoice'!$B$2:$B$401,$A2)) | H2: =IF($A2="","",SUMIFS('Per Invoice'!$T$2:$T$401,'Per Invoice'!$B$2:$B$401,$A2))
A3: =IF(Settings!$C$27="","",Settings!$C$27) | B3: =IF($A3="","",COUNTIF('Per Invoice'!$B$2:$B$401,$A3)) | C3: =IF($A3="","",SUMIFS('Per Invoice'!$O$2:$O$401,'Per Invoice'!$B$2:$B$401,$A3)) | D3: =IF($A3="","",SUMIFS('Per Invoice'!$L$2:$L$401,'Per Invoice'!$B$2:$B$401,$A3)) | E3: =IF($A3="","",SUMIFS('Per Invoice'!$S$2:$S$401,'Per Invoice'!$B$2:$B$401,$A3)) | F3: =IF($A3="","",SUMIFS('Per Invoice'!$Q$2:$Q$401,'Per Invoice'!$B$2:$B$401,$A3)) | G3: =IF($A3="","",SUMIFS('Per Invoice'!$H$2:$H$401,'Per Invoice'!$B$2:$B$401,$A3)) | H3: =IF($A3="","",SUMIFS('Per Invoice'!$T$2:$T$401,'Per Invoice'!$B$2:$B$401,$A3))
A4: =IF(Settings!$C$28="","",Settings!$C$28) | B4: =IF($A4="","",COUNTIF('Per Invoice'!$B$2:$B$401,$A4)) | C4: =IF($A4="","",SUMIFS('Per Invoice'!$O$2:$O$401,'Per Invoice'!$B$2:$B$401,$A4)) | D4: =IF($A4="","",SUMIFS('Per Invoice'!$L$2:$L$401,'Per Invoice'!$B$2:$B$401,$A4)) | E4: =IF($A4="","",SUMIFS('Per Invoice'!$S$2:$S$401,'Per Invoice'!$B$2:$B$401,$A4)) | F4: =IF($A4="","",SUMIFS('Per Invoice'!$Q$2:$Q$401,'Per Invoice'!$B$2:$B$401,$A4)) | G4: =IF($A4="","",SUMIFS('Per Invoice'!$H$2:$H$401,'Per Invoice'!$B$2:$B$401,$A4)) | H4: =IF($A4="","",SUMIFS('Per Invoice'!$T$2:$T$401,'Per Invoice'!$B$2:$B$401,$A4))
A5: =IF(Settings!$C$29="","",Settings!$C$29) | B5: =IF($A5="","",COUNTIF('Per Invoice'!$B$2:$B$401,$A5)) | C5: =IF($A5="","",SUMIFS('Per Invoice'!$O$2:$O$401,'Per Invoice'!$B$2:$B$401,$A5)) | D5: =IF($A5="","",SUMIFS('Per Invoice'!$L$2:$L$401,'Per Invoice'!$B$2:$B$401,$A5)) | E5: =IF($A5="","",SUMIFS('Per Invoice'!$S$2:$S$401,'Per Invoice'!$B$2:$B$401,$A5)) | F5: =IF($A5="","",SUMIFS('Per Invoice'!$Q$2:$Q$401,'Per Invoice'!$B$2:$B$401,$A5)) | G5: =IF($A5="","",SUMIFS('Per Invoice'!$H$2:$H$401,'Per Invoice'!$B$2:$B$401,$A5)) | H5: =IF($A5="","",SUMIFS('Per Invoice'!$T$2:$T$401,'Per Invoice'!$B$2:$B$401,$A5))
A6: =IF(Settings!$C$30="","",Settings!$C$30) | B6: =IF($A6="","",COUNTIF('Per Invoice'!$B$2:$B$401,$A6)) | C6: =IF($A6="","",SUMIFS('Per Invoice'!$O$2:$O$401,'Per Invoice'!$B$2:$B$401,$A6)) | D6: =IF($A6="","",SUMIFS('Per Invoice'!$L$2:$L$401,'Per Invoice'!$B$2:$B$401,$A6)) | E6: =IF($A6="","",SUMIFS('Per Invoice'!$S$2:$S$401,'Per Invoice'!$B$2:$B$401,$A6)) | F6: =IF($A6="","",SUMIFS('Per Invoice'!$Q$2:$Q$401,'Per Invoice'!$B$2:$B$401,$A6)) | G6: =IF($A6="","",SUMIFS('Per Invoice'!$H$2:$H$401,'Per Invoice'!$B$2:$B$401,$A6)) | H6: =IF($A6="","",SUMIFS('Per Invoice'!$T$2:$T$401,'Per Invoice'!$B$2:$B$401,$A6))
A7: Grand Total | B7: =SUM(B2:B6) | C7: =SUM(C2:C6) | D7: =SUM(D2:D6) | E7: =SUM(E2:E6) | F7: =SUM(F2:F6) | G7: =SUM(G2:G6) | H7: =SUM(H2:H6)

Sheet Per Line
A1: inv | B1: Pos Reference | C1: Insurance Company | D1: Name | E1: Card Number | F1: Co Payment % | G1: Co val | H1: Heisenberg id | I1: Product | J1: Delivered Qty | K1: Delivered Price | L1: Total Delivered | M1: Discount | N1: Subtotal | O1: Net | P1: Payment Type | Q1: Session | R1: Create Date | S1: Product Template - Product Tmpl → Is Local | T1: Rebates | U1: Order 1st Row (helper) | V1: Invoice # (helper) | W1: Is Local (helper) | X1: Sort Key (helper)
A2: =IF($B2="","",IFERROR(IF(INDEX('Per Invoice'!$C$2:$C$401,MATCH($B2,'Per Invoice'!$A$2:$A$401,0))=0,"",INDEX('Per Invoice'!$C$2:$C$401,MATCH($B2,'Per Invoice'!$A$2:$A$401,0))),"")) | G2: =IF($B2="","",F2*L2/100) | M2: =IF($B2="","",L2*T2/100) | N2: =IF($B2="","",L2-M2) | O2: =IF($B2="","",N2-G2) | T2: =IF($B2="","",IF($W2=1,Settings!$C$6,Settings!$C$7)*100) | U2: =IF($B2="","",IF(COUNTIF($B$2:$B2,$B2)=1,1,0)) | V2: =IF($U2=1,SUMPRODUCT(--($X$2:$X$1501<$X2))+1,"") | W2: =IF($B2="","",IF(OR($S2=TRUE(),$S2="TRUE"),1,0)) | X2: =IF($U2=1,IFERROR(IF(VALUE($B2)<100000000,VALUE($B2),1000000000),IFERROR(IF(VALUE(MID($B2,2,20))<100000000,VALUE(MID($B2,2,20)),1000000000),1000000000))+ROW()/100000,"")
A3: =IF($B3="","",IFERROR(IF(INDEX('Per Invoice'!$C$2:$C$401,MATCH($B3,'Per Invoice'!$A$2:$A$401,0))=0,"",INDEX('Per Invoice'!$C$2:$C$401,MATCH($B3,'Per Invoice'!$A$2:$A$401,0))),"")) | G3: =IF($B3="","",F3*L3/100) | M3: =IF($B3="","",L3*T3/100) | N3: =IF($B3="","",L3-M3) | O3: =IF($B3="","",N3-G3) | T3: =IF($B3="","",IF($W3=1,Settings!$C$6,Settings!$C$7)*100) | U3: =IF($B3="","",IF(COUNTIF($B$2:$B3,$B3)=1,1,0)) | V3: =IF($U3=1,SUMPRODUCT(--($X$2:$X$1501<$X3))+1,"") | W3: =IF($B3="","",IF(OR($S3=TRUE(),$S3="TRUE"),1,0)) | X3: =IF($U3=1,IFERROR(IF(VALUE($B3)<100000000,VALUE($B3),1000000000),IFERROR(IF(VALUE(MID($B3,2,20))<100000000,VALUE(MID($B3,2,20)),1000000000),1000000000))+ROW()/100000,"")
A4: =IF($B4="","",IFERROR(IF(INDEX('Per Invoice'!$C$2:$C$401,MATCH($B4,'Per Invoice'!$A$2:$A$401,0))=0,"",INDEX('Per Invoice'!$C$2:$C$401,MATCH($B4,'Per Invoice'!$A$2:$A$401,0))),"")) | G4: =IF($B4="","",F4*L4/100) | M4: =IF($B4="","",L4*T4/100) | N4: =IF($B4="","",L4-M4) | O4: =IF($B4="","",N4-G4) | T4: =IF($B4="","",IF($W4=1,Settings!$C$6,Settings!$C$7)*100) | U4: =IF($B4="","",IF(COUNTIF($B$2:$B4,$B4)=1,1,0)) | V4: =IF($U4=1,SUMPRODUCT(--($X$2:$X$1501<$X4))+1,"") | W4: =IF($B4="","",IF(OR($S4=TRUE(),$S4="TRUE"),1,0)) | X4: =IF($U4=1,IFERROR(IF(VALUE($B4)<100000000,VALUE($B4),1000000000),IFERROR(IF(VALUE(MID($B4,2,20))<100000000,VALUE(MID($B4,2,20)),1000000000),1000000000))+ROW()/100000,"")
A5: =IF($B5="","",IFERROR(IF(INDEX('Per Invoice'!$C$2:$C$401,MATCH($B5,'Per Invoice'!$A$2:$A$401,0))=0,"",INDEX('Per Invoice'!$C$2:$C$401,MATCH($B5,'Per Invoice'!$A$2:$A$401,0))),"")) | G5: =IF($B5="","",F5*L5/100) | M5: =IF($B5="","",L5*T5/100) | N5: =IF($B5="","",L5-M5) | O5: =IF($B5="","",N5-G5) | T5: =IF($B5="","",IF($W5=1,Settings!$C$6,Settings!$C$7)*100) | U5: =IF($B5="","",IF(COUNTIF($B$2:$B5,$B5)=1,1,0)) | V5: =IF($U5=1,SUMPRODUCT(--($X$2:$X$1501<$X5))+1,"") | W5: =IF($B5="","",IF(OR($S5=TRUE(),$S5="TRUE"),1,0)) | X5: =IF($U5=1,IFERROR(IF(VALUE($B5)<100000000,VALUE($B5),1000000000),IFERROR(IF(VALUE(MID($B5,2,20))<100000000,VALUE(MID($B5,2,20)),1000000000),1000000000))+ROW()/100000,"")
A6: =IF($B6="","",IFERROR(IF(INDEX('Per Invoice'!$C$2:$C$401,MATCH($B6,'Per Invoice'!$A$2:$A$401,0))=0,"",INDEX('Per Invoice'!$C$2:$C$401,MATCH($B6,'Per Invoice'!$A$2:$A$401,0))),"")) | G6: =IF($B6="","",F6*L6/100) | M6: =IF($B6="","",L6*T6/100) | N6: =IF($B6="","",L6-M6) | O6: =IF($B6="","",N6-G6) | T6: =IF($B6="","",IF($W6=1,Settings!$C$6,Settings!$C$7)*100) | U6: =IF($B6="","",IF(COUNTIF($B$2:$B6,$B6)=1,1,0)) | V6: =IF($U6=1,SUMPRODUCT(--($X$2:$X$1501<$X6))+1,"") | W6: =IF($B6="","",IF(OR($S6=TRUE(),$S6="TRUE"),1,0)) | X6: =IF($U6=1,IFERROR(IF(VALUE($B6)<100000000,VALUE($B6),1000000000),IFERROR(IF(VALUE(MID($B6,2,20))<100000000,VALUE(MID($B6,2,20)),1000000000),1000000000))+ROW()/100000,"")
A7: =IF($B7="","",IFERROR(IF(INDEX('Per Invoice'!$C$2:$C$401,MATCH($B7,'Per Invoice'!$A$2:$A$401,0))=0,"",INDEX('Per Invoice'!$C$2:$C$401,MATCH($B7,'Per Invoice'!$A$2:$A$401,0))),"")) | G7: =IF($B7="","",F7*L7/100) | M7: =IF($B7="","",L7*T7/100) | N7: =IF($B7="","",L7-M7) | O7: =IF($B7="","",N7-G7) | T7: =IF($B7="","",IF($W7=1,Settings!$C$6,Settings!$C$7)*100) | U7: =IF($B7="","",IF(COUNTIF($B$2:$B7,$B7)=1,1,0)) | V7: =IF($U7=1,SUMPRODUCT(--($X$2:$X$1501<$X7))+1,"") | W7: =IF($B7="","",IF(OR($S7=TRUE(),$S7="TRUE"),1,0)) | X7: =IF($U7=1,IFERROR(IF(VALUE($B7)<100000000,VALUE($B7),1000000000),IFERROR(IF(VALUE(MID($B7,2,20))<100000000,VALUE(MID($B7,2,20)),1000000000),1000000000))+ROW()/100000,"")
A8: =IF($B8="","",IFERROR(IF(INDEX('Per Invoice'!$C$2:$C$401,MATCH($B8,'Per Invoice'!$A$2:$A$401,0))=0,"",INDEX('Per Invoice'!$C$2:$C$401,MATCH($B8,'Per Invoice'!$A$2:$A$401,0))),"")) | G8: =IF($B8="","",F8*L8/100) | M8: =IF($B8="","",L8*T8/100) | N8: =IF($B8="","",L8-M8) | O8: =IF($B8="","",N8-G8) | T8: =IF($B8="","",IF($W8=1,Settings!$C$6,Settings!$C$7)*100) | U8: =IF($B8="","",IF(COUNTIF($B$2:$B8,$B8)=1,1,0)) | V8: =IF($U8=1,SUMPRODUCT(--($X$2:$X$1501<$X8))+1,"") | W8: =IF($B8="","",IF(OR($S8=TRUE(),$S8="TRUE"),1,0)) | X8: =IF($U8=1,IFERROR(IF(VALUE($B8)<100000000,VALUE($B8),1000000000),IFERROR(IF(VALUE(MID($B8,2,20))<100000000,VALUE(MID($B8,2,20)),1000000000),1000000000))+ROW()/100000,"")
A9: =IF($B9="","",IFERROR(IF(INDEX('Per Invoice'!$C$2:$C$401,MATCH($B9,'Per Invoice'!$A$2:$A$401,0))=0,"",INDEX('Per Invoice'!$C$2:$C$401,MATCH($B9,'Per Invoice'!$A$2:$A$401,0))),"")) | G9: =IF($B9="","",F9*L9/100) | M9: =IF($B9="","",L9*T9/100) | N9: =IF($B9="","",L9-M9) | O9: =IF($B9="","",N9-G9) | T9: =IF($B9="","",IF($W9=1,Settings!$C$6,Settings!$C$7)*100) | U9: =IF($B9="","",IF(COUNTIF($B$2:$B9,$B9)=1,1,0)) | V9: =IF($U9=1,SUMPRODUCT(--($X$2:$X$1501<$X9))+1,"") | W9: =IF($B9="","",IF(OR($S9=TRUE(),$S9="TRUE"),1,0)) | X9: =IF($U9=1,IFERROR(IF(VALUE($B9)<100000000,VALUE($B9),1000000000),IFERROR(IF(VALUE(MID($B9,2,20))<100000000,VALUE(MID($B9,2,20)),1000000000),1000000000))+ROW()/100000,"")
A10: =IF($B10="","",IFERROR(IF(INDEX('Per Invoice'!$C$2:$C$401,MATCH($B10,'Per Invoice'!$A$2:$A$401,0))=0,"",INDEX('Per Invoice'!$C$2:$C$401,MATCH($B10,'Per Invoice'!$A$2:$A$401,0))),"")) | G10: =IF($B10="","",F10*L10/100) | M10: =IF($B10="","",L10*T10/100) | N10: =IF($B10="","",L10-M10) | O10: =IF($B10="","",N10-G10) | T10: =IF($B10="","",IF($W10=1,Settings!$C$6,Settings!$C$7)*100) | U10: =IF($B10="","",IF(COUNTIF($B$2:$B10,$B10)=1,1,0)) | V10: =IF($U10=1,SUMPRODUCT(--($X$2:$X$1501<$X10))+1,"") | W10: =IF($B10="","",IF(OR($S10=TRUE(),$S10="TRUE"),1,0)) | X10: =IF($U10=1,IFERROR(IF(VALUE($B10)<100000000,VALUE($B10),1000000000),IFERROR(IF(VALUE(MID($B10,2,20))<100000000,VALUE(MID($B10,2,20)),1000000000),1000000000))+ROW()/100000,"")
A11: =IF($B11="","",IFERROR(IF(INDEX('Per Invoice'!$C$2:$C$401,MATCH($B11,'Per Invoice'!$A$2:$A$401,0))=0,"",INDEX('Per Invoice'!$C$2:$C$401,MATCH($B11,'Per Invoice'!$A$2:$A$401,0))),"")) | G11: =IF($B11="","",F11*L11/100) | M11: =IF($B11="","",L11*T11/100) | N11: =IF($B11="","",L11-M11) | O11: =IF($B11="","",N11-G11) | T11: =IF($B11="","",IF($W11=1,Settings!$C$6,Settings!$C$7)*100) | U11: =IF($B11="","",IF(COUNTIF($B$2:$B11,$B11)=1,1,0)) | V11: =IF($U11=1,SUMPRODUCT(--($X$2:$X$1501<$X11))+1,"") | W11: =IF($B11="","",IF(OR($S11=TRUE(),$S11="TRUE"),1,0)) | X11: =IF($U11=1,IFERROR(IF(VALUE($B11)<100000000,VALUE($B11),1000000000),IFERROR(IF(VALUE(MID($B11,2,20))<100000000,VALUE(MID($B11,2,20)),1000000000),1000000000))+ROW()/100000,"")
A12: =IF($B12="","",IFERROR(IF(INDEX('Per Invoice'!$C$2:$C$401,MATCH($B12,'Per Invoice'!$A$2:$A$401,0))=0,"",INDEX('Per Invoice'!$C$2:$C$401,MATCH($B12,'Per Invoice'!$A$2:$A$401,0))),"")) | G12: =IF($B12="","",F12*L12/100) | M12: =IF($B12="","",L12*T12/100) | N12: =IF($B12="","",L12-M12) | O12: =IF($B12="","",N12-G12) | T12: =IF($B12="","",IF($W12=1,Settings!$C$6,Settings!$C$7)*100) | U12: =IF($B12="","",IF(COUNTIF($B$2:$B12,$B12)=1,1,0)) | V12: =IF($U12=1,SUMPRODUCT(--($X$2:$X$1501<$X12))+1,"") | W12: =IF($B12="","",IF(OR($S12=TRUE(),$S12="TRUE"),1,0)) | X12: =IF($U12=1,IFERROR(IF(VALUE($B12)<100000000,VALUE($B12),1000000000),IFERROR(IF(VALUE(MID($B12,2,20))<100000000,VALUE(MID($B12,2,20)),1000000000),1000000000))+ROW()/100000,"")
A13: =IF($B13="","",IFERROR(IF(INDEX('Per Invoice'!$C$2:$C$401,MATCH($B13,'Per Invoice'!$A$2:$A$401,0))=0,"",INDEX('Per Invoice'!$C$2:$C$401,MATCH($B13,'Per Invoice'!$A$2:$A$401,0))),"")) | G13: =IF($B13="","",F13*L13/100) | M13: =IF($B13="","",L13*T13/100) | N13: =IF($B13="","",L13-M13) | O13: =IF($B13="","",N13-G13) | T13: =IF($B13="","",IF($W13=1,Settings!$C$6,Settings!$C$7)*100) | U13: =IF($B13="","",IF(COUNTIF($B$2:$B13,$B13)=1,1,0)) | V13: =IF($U13=1,SUMPRODUCT(--($X$2:$X$1501<$X13))+1,"") | W13: =IF($B13="","",IF(OR($S13=TRUE(),$S13="TRUE"),1,0)) | X13: =IF($U13=1,IFERROR(IF(VALUE($B13)<100000000,VALUE($B13),1000000000),IFERROR(IF(VALUE(MID($B13,2,20))<100000000,VALUE(MID($B13,2,20)),1000000000),1000000000))+ROW()/100000,"")
... A1501: =IF($B1501="","",IFERROR(IF(INDEX('Per Invoice'!$C$2:$C$401,MATCH($B1501,'Per Invoice'!$A$2:$A$401,0))=0,"",INDEX('Per Invoice'!$C$2:$C$401,MATCH($B1501,'Per Invoice'!$A$2:$A$401,0))),"")) | G1501: =IF($B1501="","",F1501*L1501/100) | M1501: =IF($B1501="","",L1501*T1501/100) | N1501: =IF($B1501="","",L1501-M1501) | O1501: =IF($B1501="","",N1501-G1501) | T1501: =IF($B1501="","",IF($W1501=1,Settings!$C$6,Settings!$C$7)*100) | U1501: =IF($B1501="","",IF(COUNTIF($B$2:$B1501,$B1501)=1,1,0)) | V1501: =IF($U1501=1,SUMPRODUCT(--($X$2:$X$1501<$X1501))+1,"") | W1501: =IF($B1501="","",IF(OR($S1501=TRUE(),$S1501="TRUE"),1,0)) | X1501: =IF($U1501=1,IFERROR(IF(VALUE($B1501)<100000000,VALUE($B1501),1000000000),IFERROR(IF(VALUE(MID($B1501,2,20))<100000000,VALUE(MID($B1501,2,20)),1000000000),1000000000))+ROW()/100000,"")

Sheet Per Invoice
A1: Pos Reference | B1: Copay Tab (##) | C1: Invoice | D1: Insurance Company | E1: Name | F1: Card Number | G1: Co Payment % | H1: Co val | I1: Create Date | J1: Session | K1: IMP% | L1: IMP | M1: IMP VAL | N1: LOCAL% | O1: LOCAL | P1: LOCAL VAL | Q1: TOTAL VAL | R1: SUBTOTAL | S1: Grand Total | T1: NET | U1: Src Row (helper) | V1: Payer Key (helper)
A2: =IF($U2="","",INDEX('Per Line'!$B$2:$B$1501,$U2)&"") | B2: =IF($U2="","","COPY "&G2&" %") | D2: =IF($U2="","",INDEX('Per Line'!$C$2:$C$1501,$U2)&"") | E2: =IF($U2="","",INDEX('Per Line'!$D$2:$D$1501,$U2)&"") | F2: =IF($U2="","",INDEX('Per Line'!$E$2:$E$1501,$U2)&"") | G2: =IF($U2="","",INDEX('Per Line'!$F$2:$F$1501,$U2)) | H2: =IF($U2="","",G2*S2/100) | I2: =IF($U2="","",INDEX('Per Line'!$R$2:$R$1501,$U2)) | J2: =IF($U2="","",INDEX('Per Line'!$Q$2:$Q$1501,$U2)&"") | K2: =IF($U2="","",Settings!$C$7) | L2: =IF($U2="","",SUMIFS('Per Line'!$L$2:$L$1501,'Per Line'!$B$2:$B$1501,$A2,'Per Line'!$W$2:$W$1501,0)) | M2: =IF($U2="","",L2*K2) | N2: =IF($U2="","",Settings!$C$6) | O2: =IF($U2="","",SUMIFS('Per Line'!$L$2:$L$1501,'Per Line'!$B$2:$B$1501,$A2,'Per Line'!$W$2:$W$1501,1)) | P2: =IF($U2="","",O2*N2) | Q2: =IF($U2="","",P2+M2) | R2: =IF($U2="","",S2-Q2) | S2: =IF($U2="","",L2+O2) | T2: =IF($U2="","",S2-Q2-H2) | U2: =IF(ROWS($U$2:$U2)<=MAX('Per Line'!$V$2:$V$1501),MATCH(ROWS($U$2:$U2),'Per Line'!$V$2:$V$1501,0),"") | V2: =IF($U2="","",B2&"|"&COUNTIF($B$2:$B2,B2))
A3: =IF($U3="","",INDEX('Per Line'!$B$2:$B$1501,$U3)&"") | B3: =IF($U3="","","COPY "&G3&" %") | D3: =IF($U3="","",INDEX('Per Line'!$C$2:$C$1501,$U3)&"") | E3: =IF($U3="","",INDEX('Per Line'!$D$2:$D$1501,$U3)&"") | F3: =IF($U3="","",INDEX('Per Line'!$E$2:$E$1501,$U3)&"") | G3: =IF($U3="","",INDEX('Per Line'!$F$2:$F$1501,$U3)) | H3: =IF($U3="","",G3*S3/100) | I3: =IF($U3="","",INDEX('Per Line'!$R$2:$R$1501,$U3)) | J3: =IF($U3="","",INDEX('Per Line'!$Q$2:$Q$1501,$U3)&"") | K3: =IF($U3="","",Settings!$C$7) | L3: =IF($U3="","",SUMIFS('Per Line'!$L$2:$L$1501,'Per Line'!$B$2:$B$1501,$A3,'Per Line'!$W$2:$W$1501,0)) | M3: =IF($U3="","",L3*K3) | N3: =IF($U3="","",Settings!$C$6) | O3: =IF($U3="","",SUMIFS('Per Line'!$L$2:$L$1501,'Per Line'!$B$2:$B$1501,$A3,'Per Line'!$W$2:$W$1501,1)) | P3: =IF($U3="","",O3*N3) | Q3: =IF($U3="","",P3+M3) | R3: =IF($U3="","",S3-Q3) | S3: =IF($U3="","",L3+O3) | T3: =IF($U3="","",S3-Q3-H3) | U3: =IF(ROWS($U$2:$U3)<=MAX('Per Line'!$V$2:$V$1501),MATCH(ROWS($U$2:$U3),'Per Line'!$V$2:$V$1501,0),"") | V3: =IF($U3="","",B3&"|"&COUNTIF($B$2:$B3,B3))
A4: =IF($U4="","",INDEX('Per Line'!$B$2:$B$1501,$U4)&"") | B4: =IF($U4="","","COPY "&G4&" %") | D4: =IF($U4="","",INDEX('Per Line'!$C$2:$C$1501,$U4)&"") | E4: =IF($U4="","",INDEX('Per Line'!$D$2:$D$1501,$U4)&"") | F4: =IF($U4="","",INDEX('Per Line'!$E$2:$E$1501,$U4)&"") | G4: =IF($U4="","",INDEX('Per Line'!$F$2:$F$1501,$U4)) | H4: =IF($U4="","",G4*S4/100) | I4: =IF($U4="","",INDEX('Per Line'!$R$2:$R$1501,$U4)) | J4: =IF($U4="","",INDEX('Per Line'!$Q$2:$Q$1501,$U4)&"") | K4: =IF($U4="","",Settings!$C$7) | L4: =IF($U4="","",SUMIFS('Per Line'!$L$2:$L$1501,'Per Line'!$B$2:$B$1501,$A4,'Per Line'!$W$2:$W$1501,0)) | M4: =IF($U4="","",L4*K4) | N4: =IF($U4="","",Settings!$C$6) | O4: =IF($U4="","",SUMIFS('Per Line'!$L$2:$L$1501,'Per Line'!$B$2:$B$1501,$A4,'Per Line'!$W$2:$W$1501,1)) | P4: =IF($U4="","",O4*N4) | Q4: =IF($U4="","",P4+M4) | R4: =IF($U4="","",S4-Q4) | S4: =IF($U4="","",L4+O4) | T4: =IF($U4="","",S4-Q4-H4) | U4: =IF(ROWS($U$2:$U4)<=MAX('Per Line'!$V$2:$V$1501),MATCH(ROWS($U$2:$U4),'Per Line'!$V$2:$V$1501,0),"") | V4: =IF($U4="","",B4&"|"&COUNTIF($B$2:$B4,B4))
A5: =IF($U5="","",INDEX('Per Line'!$B$2:$B$1501,$U5)&"") | B5: =IF($U5="","","COPY "&G5&" %") | D5: =IF($U5="","",INDEX('Per Line'!$C$2:$C$1501,$U5)&"") | E5: =IF($U5="","",INDEX('Per Line'!$D$2:$D$1501,$U5)&"") | F5: =IF($U5="","",INDEX('Per Line'!$E$2:$E$1501,$U5)&"") | G5: =IF($U5="","",INDEX('Per Line'!$F$2:$F$1501,$U5)) | H5: =IF($U5="","",G5*S5/100) | I5: =IF($U5="","",INDEX('Per Line'!$R$2:$R$1501,$U5)) | J5: =IF($U5="","",INDEX('Per Line'!$Q$2:$Q$1501,$U5)&"") | K5: =IF($U5="","",Settings!$C$7) | L5: =IF($U5="","",SUMIFS('Per Line'!$L$2:$L$1501,'Per Line'!$B$2:$B$1501,$A5,'Per Line'!$W$2:$W$1501,0)) | M5: =IF($U5="","",L5*K5) | N5: =IF($U5="","",Settings!$C$6) | O5: =IF($U5="","",SUMIFS('Per Line'!$L$2:$L$1501,'Per Line'!$B$2:$B$1501,$A5,'Per Line'!$W$2:$W$1501,1)) | P5: =IF($U5="","",O5*N5) | Q5: =IF($U5="","",P5+M5) | R5: =IF($U5="","",S5-Q5) | S5: =IF($U5="","",L5+O5) | T5: =IF($U5="","",S5-Q5-H5) | U5: =IF(ROWS($U$2:$U5)<=MAX('Per Line'!$V$2:$V$1501),MATCH(ROWS($U$2:$U5),'Per Line'!$V$2:$V$1501,0),"") | V5: =IF($U5="","",B5&"|"&COUNTIF($B$2:$B5,B5))
A6: =IF($U6="","",INDEX('Per Line'!$B$2:$B$1501,$U6)&"") | B6: =IF($U6="","","COPY "&G6&" %") | D6: =IF($U6="","",INDEX('Per Line'!$C$2:$C$1501,$U6)&"") | E6: =IF($U6="","",INDEX('Per Line'!$D$2:$D$1501,$U6)&"") | F6: =IF($U6="","",INDEX('Per Line'!$E$2:$E$1501,$U6)&"") | G6: =IF($U6="","",INDEX('Per Line'!$F$2:$F$1501,$U6)) | H6: =IF($U6="","",G6*S6/100) | I6: =IF($U6="","",INDEX('Per Line'!$R$2:$R$1501,$U6)) | J6: =IF($U6="","",INDEX('Per Line'!$Q$2:$Q$1501,$U6)&"") | K6: =IF($U6="","",Settings!$C$7) | L6: =IF($U6="","",SUMIFS('Per Line'!$L$2:$L$1501,'Per Line'!$B$2:$B$1501,$A6,'Per Line'!$W$2:$W$1501,0)) | M6: =IF($U6="","",L6*K6) | N6: =IF($U6="","",Settings!$C$6) | O6: =IF($U6="","",SUMIFS('Per Line'!$L$2:$L$1501,'Per Line'!$B$2:$B$1501,$A6,'Per Line'!$W$2:$W$1501,1)) | P6: =IF($U6="","",O6*N6) | Q6: =IF($U6="","",P6+M6) | R6: =IF($U6="","",S6-Q6) | S6: =IF($U6="","",L6+O6) | T6: =IF($U6="","",S6-Q6-H6) | U6: =IF(ROWS($U$2:$U6)<=MAX('Per Line'!$V$2:$V$1501),MATCH(ROWS($U$2:$U6),'Per Line'!$V$2:$V$1501,0),"") | V6: =IF($U6="","",B6&"|"&COUNTIF($B$2:$B6,B6))
A7: =IF($U7="","",INDEX('Per Line'!$B$2:$B$1501,$U7)&"") | B7: =IF($U7="","","COPY "&G7&" %") | D7: =IF($U7="","",INDEX('Per Line'!$C$2:$C$1501,$U7)&"") | E7: =IF($U7="","",INDEX('Per Line'!$D$2:$D$1501,$U7)&"") | F7: =IF($U7="","",INDEX('Per Line'!$E$2:$E$1501,$U7)&"") | G7: =IF($U7="","",INDEX('Per Line'!$F$2:$F$1501,$U7)) | H7: =IF($U7="","",G7*S7/100) | I7: =IF($U7="","",INDEX('Per Line'!$R$2:$R$1501,$U7)) | J7: =IF($U7="","",INDEX('Per Line'!$Q$2:$Q$1501,$U7)&"") | K7: =IF($U7="","",Settings!$C$7) | L7: =IF($U7="","",SUMIFS('Per Line'!$L$2:$L$1501,'Per Line'!$B$2:$B$1501,$A7,'Per Line'!$W$2:$W$1501,0)) | M7: =IF($U7="","",L7*K7) | N7: =IF($U7="","",Settings!$C$6) | O7: =IF($U7="","",SUMIFS('Per Line'!$L$2:$L$1501,'Per Line'!$B$2:$B$1501,$A7,'Per Line'!$W$2:$W$1501,1)) | P7: =IF($U7="","",O7*N7) | Q7: =IF($U7="","",P7+M7) | R7: =IF($U7="","",S7-Q7) | S7: =IF($U7="","",L7+O7) | T7: =IF($U7="","",S7-Q7-H7) | U7: =IF(ROWS($U$2:$U7)<=MAX('Per Line'!$V$2:$V$1501),MATCH(ROWS($U$2:$U7),'Per Line'!$V$2:$V$1501,0),"") | V7: =IF($U7="","",B7&"|"&COUNTIF($B$2:$B7,B7))
A8: =IF($U8="","",INDEX('Per Line'!$B$2:$B$1501,$U8)&"") | B8: =IF($U8="","","COPY "&G8&" %") | D8: =IF($U8="","",INDEX('Per Line'!$C$2:$C$1501,$U8)&"") | E8: =IF($U8="","",INDEX('Per Line'!$D$2:$D$1501,$U8)&"") | F8: =IF($U8="","",INDEX('Per Line'!$E$2:$E$1501,$U8)&"") | G8: =IF($U8="","",INDEX('Per Line'!$F$2:$F$1501,$U8)) | H8: =IF($U8="","",G8*S8/100) | I8: =IF($U8="","",INDEX('Per Line'!$R$2:$R$1501,$U8)) | J8: =IF($U8="","",INDEX('Per Line'!$Q$2:$Q$1501,$U8)&"") | K8: =IF($U8="","",Settings!$C$7) | L8: =IF($U8="","",SUMIFS('Per Line'!$L$2:$L$1501,'Per Line'!$B$2:$B$1501,$A8,'Per Line'!$W$2:$W$1501,0)) | M8: =IF($U8="","",L8*K8) | N8: =IF($U8="","",Settings!$C$6) | O8: =IF($U8="","",SUMIFS('Per Line'!$L$2:$L$1501,'Per Line'!$B$2:$B$1501,$A8,'Per Line'!$W$2:$W$1501,1)) | P8: =IF($U8="","",O8*N8) | Q8: =IF($U8="","",P8+M8) | R8: =IF($U8="","",S8-Q8) | S8: =IF($U8="","",L8+O8) | T8: =IF($U8="","",S8-Q8-H8) | U8: =IF(ROWS($U$2:$U8)<=MAX('Per Line'!$V$2:$V$1501),MATCH(ROWS($U$2:$U8),'Per Line'!$V$2:$V$1501,0),"") | V8: =IF($U8="","",B8&"|"&COUNTIF($B$2:$B8,B8))
A9: =IF($U9="","",INDEX('Per Line'!$B$2:$B$1501,$U9)&"") | B9: =IF($U9="","","COPY "&G9&" %") | D9: =IF($U9="","",INDEX('Per Line'!$C$2:$C$1501,$U9)&"") | E9: =IF($U9="","",INDEX('Per Line'!$D$2:$D$1501,$U9)&"") | F9: =IF($U9="","",INDEX('Per Line'!$E$2:$E$1501,$U9)&"") | G9: =IF($U9="","",INDEX('Per Line'!$F$2:$F$1501,$U9)) | H9: =IF($U9="","",G9*S9/100) | I9: =IF($U9="","",INDEX('Per Line'!$R$2:$R$1501,$U9)) | J9: =IF($U9="","",INDEX('Per Line'!$Q$2:$Q$1501,$U9)&"") | K9: =IF($U9="","",Settings!$C$7) | L9: =IF($U9="","",SUMIFS('Per Line'!$L$2:$L$1501,'Per Line'!$B$2:$B$1501,$A9,'Per Line'!$W$2:$W$1501,0)) | M9: =IF($U9="","",L9*K9) | N9: =IF($U9="","",Settings!$C$6) | O9: =IF($U9="","",SUMIFS('Per Line'!$L$2:$L$1501,'Per Line'!$B$2:$B$1501,$A9,'Per Line'!$W$2:$W$1501,1)) | P9: =IF($U9="","",O9*N9) | Q9: =IF($U9="","",P9+M9) | R9: =IF($U9="","",S9-Q9) | S9: =IF($U9="","",L9+O9) | T9: =IF($U9="","",S9-Q9-H9) | U9: =IF(ROWS($U$2:$U9)<=MAX('Per Line'!$V$2:$V$1501),MATCH(ROWS($U$2:$U9),'Per Line'!$V$2:$V$1501,0),"") | V9: =IF($U9="","",B9&"|"&COUNTIF($B$2:$B9,B9))
A10: =IF($U10="","",INDEX('Per Line'!$B$2:$B$1501,$U10)&"") | B10: =IF($U10="","","COPY "&G10&" %") | D10: =IF($U10="","",INDEX('Per Line'!$C$2:$C$1501,$U10)&"") | E10: =IF($U10="","",INDEX('Per Line'!$D$2:$D$1501,$U10)&"") | F10: =IF($U10="","",INDEX('Per Line'!$E$2:$E$1501,$U10)&"") | G10: =IF($U10="","",INDEX('Per Line'!$F$2:$F$1501,$U10)) | H10: =IF($U10="","",G10*S10/100) | I10: =IF($U10="","",INDEX('Per Line'!$R$2:$R$1501,$U10)) | J10: =IF($U10="","",INDEX('Per Line'!$Q$2:$Q$1501,$U10)&"") | K10: =IF($U10="","",Settings!$C$7) | L10: =IF($U10="","",SUMIFS('Per Line'!$L$2:$L$1501,'Per Line'!$B$2:$B$1501,$A10,'Per Line'!$W$2:$W$1501,0)) | M10: =IF($U10="","",L10*K10) | N10: =IF($U10="","",Settings!$C$6) | O10: =IF($U10="","",SUMIFS('Per Line'!$L$2:$L$1501,'Per Line'!$B$2:$B$1501,$A10,'Per Line'!$W$2:$W$1501,1)) | P10: =IF($U10="","",O10*N10) | Q10: =IF($U10="","",P10+M10) | R10: =IF($U10="","",S10-Q10) | S10: =IF($U10="","",L10+O10) | T10: =IF($U10="","",S10-Q10-H10) | U10: =IF(ROWS($U$2:$U10)<=MAX('Per Line'!$V$2:$V$1501),MATCH(ROWS($U$2:$U10),'Per Line'!$V$2:$V$1501,0),"") | V10: =IF($U10="","",B10&"|"&COUNTIF($B$2:$B10,B10))
A11: =IF($U11="","",INDEX('Per Line'!$B$2:$B$1501,$U11)&"") | B11: =IF($U11="","","COPY "&G11&" %") | D11: =IF($U11="","",INDEX('Per Line'!$C$2:$C$1501,$U11)&"") | E11: =IF($U11="","",INDEX('Per Line'!$D$2:$D$1501,$U11)&"") | F11: =IF($U11="","",INDEX('Per Line'!$E$2:$E$1501,$U11)&"") | G11: =IF($U11="","",INDEX('Per Line'!$F$2:$F$1501,$U11)) | H11: =IF($U11="","",G11*S11/100) | I11: =IF($U11="","",INDEX('Per Line'!$R$2:$R$1501,$U11)) | J11: =IF($U11="","",INDEX('Per Line'!$Q$2:$Q$1501,$U11)&"") | K11: =IF($U11="","",Settings!$C$7) | L11: =IF($U11="","",SUMIFS('Per Line'!$L$2:$L$1501,'Per Line'!$B$2:$B$1501,$A11,'Per Line'!$W$2:$W$1501,0)) | M11: =IF($U11="","",L11*K11) | N11: =IF($U11="","",Settings!$C$6) | O11: =IF($U11="","",SUMIFS('Per Line'!$L$2:$L$1501,'Per Line'!$B$2:$B$1501,$A11,'Per Line'!$W$2:$W$1501,1)) | P11: =IF($U11="","",O11*N11) | Q11: =IF($U11="","",P11+M11) | R11: =IF($U11="","",S11-Q11) | S11: =IF($U11="","",L11+O11) | T11: =IF($U11="","",S11-Q11-H11) | U11: =IF(ROWS($U$2:$U11)<=MAX('Per Line'!$V$2:$V$1501),MATCH(ROWS($U$2:$U11),'Per Line'!$V$2:$V$1501,0),"") | V11: =IF($U11="","",B11&"|"&COUNTIF($B$2:$B11,B11))
A12: =IF($U12="","",INDEX('Per Line'!$B$2:$B$1501,$U12)&"") | B12: =IF($U12="","","COPY "&G12&" %") | D12: =IF($U12="","",INDEX('Per Line'!$C$2:$C$1501,$U12)&"") | E12: =IF($U12="","",INDEX('Per Line'!$D$2:$D$1501,$U12)&"") | F12: =IF($U12="","",INDEX('Per Line'!$E$2:$E$1501,$U12)&"") | G12: =IF($U12="","",INDEX('Per Line'!$F$2:$F$1501,$U12)) | H12: =IF($U12="","",G12*S12/100) | I12: =IF($U12="","",INDEX('Per Line'!$R$2:$R$1501,$U12)) | J12: =IF($U12="","",INDEX('Per Line'!$Q$2:$Q$1501,$U12)&"") | K12: =IF($U12="","",Settings!$C$7) | L12: =IF($U12="","",SUMIFS('Per Line'!$L$2:$L$1501,'Per Line'!$B$2:$B$1501,$A12,'Per Line'!$W$2:$W$1501,0)) | M12: =IF($U12="","",L12*K12) | N12: =IF($U12="","",Settings!$C$6) | O12: =IF($U12="","",SUMIFS('Per Line'!$L$2:$L$1501,'Per Line'!$B$2:$B$1501,$A12,'Per Line'!$W$2:$W$1501,1)) | P12: =IF($U12="","",O12*N12) | Q12: =IF($U12="","",P12+M12) | R12: =IF($U12="","",S12-Q12) | S12: =IF($U12="","",L12+O12) | T12: =IF($U12="","",S12-Q12-H12) | U12: =IF(ROWS($U$2:$U12)<=MAX('Per Line'!$V$2:$V$1501),MATCH(ROWS($U$2:$U12),'Per Line'!$V$2:$V$1501,0),"") | V12: =IF($U12="","",B12&"|"&COUNTIF($B$2:$B12,B12))
A13: =IF($U13="","",INDEX('Per Line'!$B$2:$B$1501,$U13)&"") | B13: =IF($U13="","","COPY "&G13&" %") | D13: =IF($U13="","",INDEX('Per Line'!$C$2:$C$1501,$U13)&"") | E13: =IF($U13="","",INDEX('Per Line'!$D$2:$D$1501,$U13)&"") | F13: =IF($U13="","",INDEX('Per Line'!$E$2:$E$1501,$U13)&"") | G13: =IF($U13="","",INDEX('Per Line'!$F$2:$F$1501,$U13)) | H13: =IF($U13="","",G13*S13/100) | I13: =IF($U13="","",INDEX('Per Line'!$R$2:$R$1501,$U13)) | J13: =IF($U13="","",INDEX('Per Line'!$Q$2:$Q$1501,$U13)&"") | K13: =IF($U13="","",Settings!$C$7) | L13: =IF($U13="","",SUMIFS('Per Line'!$L$2:$L$1501,'Per Line'!$B$2:$B$1501,$A13,'Per Line'!$W$2:$W$1501,0)) | M13: =IF($U13="","",L13*K13) | N13: =IF($U13="","",Settings!$C$6) | O13: =IF($U13="","",SUMIFS('Per Line'!$L$2:$L$1501,'Per Line'!$B$2:$B$1501,$A13,'Per Line'!$W$2:$W$1501,1)) | P13: =IF($U13="","",O13*N13) | Q13: =IF($U13="","",P13+M13) | R13: =IF($U13="","",S13-Q13) | S13: =IF($U13="","",L13+O13) | T13: =IF($U13="","",S13-Q13-H13) | U13: =IF(ROWS($U$2:$U13)<=MAX('Per Line'!$V$2:$V$1501),MATCH(ROWS($U$2:$U13),'Per Line'!$V$2:$V$1501,0),"") | V13: =IF($U13="","",B13&"|"&COUNTIF($B$2:$B13,B13))
... A401: =IF($U401="","",INDEX('Per Line'!$B$2:$B$1501,$U401)&"") | B401: =IF($U401="","","COPY "&G401&" %") | D401: =IF($U401="","",INDEX('Per Line'!$C$2:$C$1501,$U401)&"") | E401: =IF($U401="","",INDEX('Per Line'!$D$2:$D$1501,$U401)&"") | F401: =IF($U401="","",INDEX('Per Line'!$E$2:$E$1501,$U401)&"") | G401: =IF($U401="","",INDEX('Per Line'!$F$2:$F$1501,$U401)) | H401: =IF($U401="","",G401*S401/100) | I401: =IF($U401="","",INDEX('Per Line'!$R$2:$R$1501,$U401)) | J401: =IF($U401="","",INDEX('Per Line'!$Q$2:$Q$1501,$U401)&"") | K401: =IF($U401="","",Settings!$C$7) | L401: =IF($U401="","",SUMIFS('Per Line'!$L$2:$L$1501,'Per Line'!$B$2:$B$1501,$A401,'Per Line'!$W$2:$W$1501,0)) | M401: =IF($U401="","",L401*K401) | N401: =IF($U401="","",Settings!$C$6) | O401: =IF($U401="","",SUMIFS('Per Line'!$L$2:$L$1501,'Per Line'!$B$2:$B$1501,$A401,'Per Line'!$W$2:$W$1501,1)) | P401: =IF($U401="","",O401*N401) | Q401: =IF($U401="","",P401+M401) | R401: =IF($U401="","",S401-Q401) | S401: =IF($U401="","",L401+O401) | T401: =IF($U401="","",S401-Q401-H401) | U401: =IF(ROWS($U$2:$U401)<=MAX('Per Line'!$V$2:$V$1501),MATCH(ROWS($U$2:$U401),'Per Line'!$V$2:$V$1501,0),"") | V401: =IF($U401="","",B401&"|"&COUNTIF($B$2:$B401,B401))

Sheet COPY 30 %
A1: Pos Reference | B1: Copay Tab (##) | C1: Invoice | D1: Insurance Company | E1: Name | F1: Card Number | G1: Co Payment % | H1: Co val | I1: Create Date | J1: Session | K1: IMP% | L1: IMP | M1: IMP VAL | N1: LOCAL% | O1: LOCAL | P1: LOCAL VAL | Q1: TOTAL VAL | R1: SUBTOTAL | S1: Grand Total | T1: NET | U1: Src Row (helper)
A2: =IF($U2="","",IF(INDEX('Per Invoice'!A$2:A$401,$U2)="","",INDEX('Per Invoice'!A$2:A$401,$U2))) | B2: =IF($U2="","",IF(INDEX('Per Invoice'!B$2:B$401,$U2)="","",INDEX('Per Invoice'!B$2:B$401,$U2))) | C2: =IF($U2="","",IF(INDEX('Per Invoice'!C$2:C$401,$U2)="","",INDEX('Per Invoice'!C$2:C$401,$U2))) | D2: =IF($U2="","",IF(INDEX('Per Invoice'!D$2:D$401,$U2)="","",INDEX('Per Invoice'!D$2:D$401,$U2))) | E2: =IF($U2="","",IF(INDEX('Per Invoice'!E$2:E$401,$U2)="","",INDEX('Per Invoice'!E$2:E$401,$U2))) | F2: =IF($U2="","",IF(INDEX('Per Invoice'!F$2:F$401,$U2)="","",INDEX('Per Invoice'!F$2:F$401,$U2))) | G2: =IF($U2="","",IF(INDEX('Per Invoice'!G$2:G$401,$U2)="","",INDEX('Per Invoice'!G$2:G$401,$U2))) | H2: =IF($U2="","",IF(INDEX('Per Invoice'!H$2:H$401,$U2)="","",INDEX('Per Invoice'!H$2:H$401,$U2))) | ... T2: =IF($U2="","",IF(INDEX('Per Invoice'!T$2:T$401,$U2)="","",INDEX('Per Invoice'!T$2:T$401,$U2))) | U2: =IFERROR(MATCH(Settings!$C$26&"|"&ROWS($U$2:$U2),'Per Invoice'!$V$2:$V$401,0),"")
A3: =IF($U3="","",IF(INDEX('Per Invoice'!A$2:A$401,$U3)="","",INDEX('Per Invoice'!A$2:A$401,$U3))) | B3: =IF($U3="","",IF(INDEX('Per Invoice'!B$2:B$401,$U3)="","",INDEX('Per Invoice'!B$2:B$401,$U3))) | C3: =IF($U3="","",IF(INDEX('Per Invoice'!C$2:C$401,$U3)="","",INDEX('Per Invoice'!C$2:C$401,$U3))) | D3: =IF($U3="","",IF(INDEX('Per Invoice'!D$2:D$401,$U3)="","",INDEX('Per Invoice'!D$2:D$401,$U3))) | E3: =IF($U3="","",IF(INDEX('Per Invoice'!E$2:E$401,$U3)="","",INDEX('Per Invoice'!E$2:E$401,$U3))) | F3: =IF($U3="","",IF(INDEX('Per Invoice'!F$2:F$401,$U3)="","",INDEX('Per Invoice'!F$2:F$401,$U3))) | G3: =IF($U3="","",IF(INDEX('Per Invoice'!G$2:G$401,$U3)="","",INDEX('Per Invoice'!G$2:G$401,$U3))) | H3: =IF($U3="","",IF(INDEX('Per Invoice'!H$2:H$401,$U3)="","",INDEX('Per Invoice'!H$2:H$401,$U3))) | ... T3: =IF($U3="","",IF(INDEX('Per Invoice'!T$2:T$401,$U3)="","",INDEX('Per Invoice'!T$2:T$401,$U3))) | U3: =IFERROR(MATCH(Settings!$C$26&"|"&ROWS($U$2:$U3),'Per Invoice'!$V$2:$V$401,0),"")
A4: =IF($U4="","",IF(INDEX('Per Invoice'!A$2:A$401,$U4)="","",INDEX('Per Invoice'!A$2:A$401,$U4))) | B4: =IF($U4="","",IF(INDEX('Per Invoice'!B$2:B$401,$U4)="","",INDEX('Per Invoice'!B$2:B$401,$U4))) | C4: =IF($U4="","",IF(INDEX('Per Invoice'!C$2:C$401,$U4)="","",INDEX('Per Invoice'!C$2:C$401,$U4))) | D4: =IF($U4="","",IF(INDEX('Per Invoice'!D$2:D$401,$U4)="","",INDEX('Per Invoice'!D$2:D$401,$U4))) | E4: =IF($U4="","",IF(INDEX('Per Invoice'!E$2:E$401,$U4)="","",INDEX('Per Invoice'!E$2:E$401,$U4))) | F4: =IF($U4="","",IF(INDEX('Per Invoice'!F$2:F$401,$U4)="","",INDEX('Per Invoice'!F$2:F$401,$U4))) | G4: =IF($U4="","",IF(INDEX('Per Invoice'!G$2:G$401,$U4)="","",INDEX('Per Invoice'!G$2:G$401,$U4))) | H4: =IF($U4="","",IF(INDEX('Per Invoice'!H$2:H$401,$U4)="","",INDEX('Per Invoice'!H$2:H$401,$U4))) | ... T4: =IF($U4="","",IF(INDEX('Per Invoice'!T$2:T$401,$U4)="","",INDEX('Per Invoice'!T$2:T$401,$U4))) | U4: =IFERROR(MATCH(Settings!$C$26&"|"&ROWS($U$2:$U4),'Per Invoice'!$V$2:$V$401,0),"")
A5: =IF($U5="","",IF(INDEX('Per Invoice'!A$2:A$401,$U5)="","",INDEX('Per Invoice'!A$2:A$401,$U5))) | B5: =IF($U5="","",IF(INDEX('Per Invoice'!B$2:B$401,$U5)="","",INDEX('Per Invoice'!B$2:B$401,$U5))) | C5: =IF($U5="","",IF(INDEX('Per Invoice'!C$2:C$401,$U5)="","",INDEX('Per Invoice'!C$2:C$401,$U5))) | D5: =IF($U5="","",IF(INDEX('Per Invoice'!D$2:D$401,$U5)="","",INDEX('Per Invoice'!D$2:D$401,$U5))) | E5: =IF($U5="","",IF(INDEX('Per Invoice'!E$2:E$401,$U5)="","",INDEX('Per Invoice'!E$2:E$401,$U5))) | F5: =IF($U5="","",IF(INDEX('Per Invoice'!F$2:F$401,$U5)="","",INDEX('Per Invoice'!F$2:F$401,$U5))) | G5: =IF($U5="","",IF(INDEX('Per Invoice'!G$2:G$401,$U5)="","",INDEX('Per Invoice'!G$2:G$401,$U5))) | H5: =IF($U5="","",IF(INDEX('Per Invoice'!H$2:H$401,$U5)="","",INDEX('Per Invoice'!H$2:H$401,$U5))) | ... T5: =IF($U5="","",IF(INDEX('Per Invoice'!T$2:T$401,$U5)="","",INDEX('Per Invoice'!T$2:T$401,$U5))) | U5: =IFERROR(MATCH(Settings!$C$26&"|"&ROWS($U$2:$U5),'Per Invoice'!$V$2:$V$401,0),"")
A6: =IF($U6="","",IF(INDEX('Per Invoice'!A$2:A$401,$U6)="","",INDEX('Per Invoice'!A$2:A$401,$U6))) | B6: =IF($U6="","",IF(INDEX('Per Invoice'!B$2:B$401,$U6)="","",INDEX('Per Invoice'!B$2:B$401,$U6))) | C6: =IF($U6="","",IF(INDEX('Per Invoice'!C$2:C$401,$U6)="","",INDEX('Per Invoice'!C$2:C$401,$U6))) | D6: =IF($U6="","",IF(INDEX('Per Invoice'!D$2:D$401,$U6)="","",INDEX('Per Invoice'!D$2:D$401,$U6))) | E6: =IF($U6="","",IF(INDEX('Per Invoice'!E$2:E$401,$U6)="","",INDEX('Per Invoice'!E$2:E$401,$U6))) | F6: =IF($U6="","",IF(INDEX('Per Invoice'!F$2:F$401,$U6)="","",INDEX('Per Invoice'!F$2:F$401,$U6))) | G6: =IF($U6="","",IF(INDEX('Per Invoice'!G$2:G$401,$U6)="","",INDEX('Per Invoice'!G$2:G$401,$U6))) | H6: =IF($U6="","",IF(INDEX('Per Invoice'!H$2:H$401,$U6)="","",INDEX('Per Invoice'!H$2:H$401,$U6))) | ... T6: =IF($U6="","",IF(INDEX('Per Invoice'!T$2:T$401,$U6)="","",INDEX('Per Invoice'!T$2:T$401,$U6))) | U6: =IFERROR(MATCH(Settings!$C$26&"|"&ROWS($U$2:$U6),'Per Invoice'!$V$2:$V$401,0),"")
A7: =IF($U7="","",IF(INDEX('Per Invoice'!A$2:A$401,$U7)="","",INDEX('Per Invoice'!A$2:A$401,$U7))) | B7: =IF($U7="","",IF(INDEX('Per Invoice'!B$2:B$401,$U7)="","",INDEX('Per Invoice'!B$2:B$401,$U7))) | C7: =IF($U7="","",IF(INDEX('Per Invoice'!C$2:C$401,$U7)="","",INDEX('Per Invoice'!C$2:C$401,$U7))) | D7: =IF($U7="","",IF(INDEX('Per Invoice'!D$2:D$401,$U7)="","",INDEX('Per Invoice'!D$2:D$401,$U7))) | E7: =IF($U7="","",IF(INDEX('Per Invoice'!E$2:E$401,$U7)="","",INDEX('Per Invoice'!E$2:E$401,$U7))) | F7: =IF($U7="","",IF(INDEX('Per Invoice'!F$2:F$401,$U7)="","",INDEX('Per Invoice'!F$2:F$401,$U7))) | G7: =IF($U7="","",IF(INDEX('Per Invoice'!G$2:G$401,$U7)="","",INDEX('Per Invoice'!G$2:G$401,$U7))) | H7: =IF($U7="","",IF(INDEX('Per Invoice'!H$2:H$401,$U7)="","",INDEX('Per Invoice'!H$2:H$401,$U7))) | ... T7: =IF($U7="","",IF(INDEX('Per Invoice'!T$2:T$401,$U7)="","",INDEX('Per Invoice'!T$2:T$401,$U7))) | U7: =IFERROR(MATCH(Settings!$C$26&"|"&ROWS($U$2:$U7),'Per Invoice'!$V$2:$V$401,0),"")
A8: =IF($U8="","",IF(INDEX('Per Invoice'!A$2:A$401,$U8)="","",INDEX('Per Invoice'!A$2:A$401,$U8))) | B8: =IF($U8="","",IF(INDEX('Per Invoice'!B$2:B$401,$U8)="","",INDEX('Per Invoice'!B$2:B$401,$U8))) | C8: =IF($U8="","",IF(INDEX('Per Invoice'!C$2:C$401,$U8)="","",INDEX('Per Invoice'!C$2:C$401,$U8))) | D8: =IF($U8="","",IF(INDEX('Per Invoice'!D$2:D$401,$U8)="","",INDEX('Per Invoice'!D$2:D$401,$U8))) | E8: =IF($U8="","",IF(INDEX('Per Invoice'!E$2:E$401,$U8)="","",INDEX('Per Invoice'!E$2:E$401,$U8))) | F8: =IF($U8="","",IF(INDEX('Per Invoice'!F$2:F$401,$U8)="","",INDEX('Per Invoice'!F$2:F$401,$U8))) | G8: =IF($U8="","",IF(INDEX('Per Invoice'!G$2:G$401,$U8)="","",INDEX('Per Invoice'!G$2:G$401,$U8))) | H8: =IF($U8="","",IF(INDEX('Per Invoice'!H$2:H$401,$U8)="","",INDEX('Per Invoice'!H$2:H$401,$U8))) | ... T8: =IF($U8="","",IF(INDEX('Per Invoice'!T$2:T$401,$U8)="","",INDEX('Per Invoice'!T$2:T$401,$U8))) | U8: =IFERROR(MATCH(Settings!$C$26&"|"&ROWS($U$2:$U8),'Per Invoice'!$V$2:$V$401,0),"")
A9: =IF($U9="","",IF(INDEX('Per Invoice'!A$2:A$401,$U9)="","",INDEX('Per Invoice'!A$2:A$401,$U9))) | B9: =IF($U9="","",IF(INDEX('Per Invoice'!B$2:B$401,$U9)="","",INDEX('Per Invoice'!B$2:B$401,$U9))) | C9: =IF($U9="","",IF(INDEX('Per Invoice'!C$2:C$401,$U9)="","",INDEX('Per Invoice'!C$2:C$401,$U9))) | D9: =IF($U9="","",IF(INDEX('Per Invoice'!D$2:D$401,$U9)="","",INDEX('Per Invoice'!D$2:D$401,$U9))) | E9: =IF($U9="","",IF(INDEX('Per Invoice'!E$2:E$401,$U9)="","",INDEX('Per Invoice'!E$2:E$401,$U9))) | F9: =IF($U9="","",IF(INDEX('Per Invoice'!F$2:F$401,$U9)="","",INDEX('Per Invoice'!F$2:F$401,$U9))) | G9: =IF($U9="","",IF(INDEX('Per Invoice'!G$2:G$401,$U9)="","",INDEX('Per Invoice'!G$2:G$401,$U9))) | H9: =IF($U9="","",IF(INDEX('Per Invoice'!H$2:H$401,$U9)="","",INDEX('Per Invoice'!H$2:H$401,$U9))) | ... T9: =IF($U9="","",IF(INDEX('Per Invoice'!T$2:T$401,$U9)="","",INDEX('Per Invoice'!T$2:T$401,$U9))) | U9: =IFERROR(MATCH(Settings!$C$26&"|"&ROWS($U$2:$U9),'Per Invoice'!$V$2:$V$401,0),"")
A10: =IF($U10="","",IF(INDEX('Per Invoice'!A$2:A$401,$U10)="","",INDEX('Per Invoice'!A$2:A$401,$U10))) | B10: =IF($U10="","",IF(INDEX('Per Invoice'!B$2:B$401,$U10)="","",INDEX('Per Invoice'!B$2:B$401,$U10))) | C10: =IF($U10="","",IF(INDEX('Per Invoice'!C$2:C$401,$U10)="","",INDEX('Per Invoice'!C$2:C$401,$U10))) | D10: =IF($U10="","",IF(INDEX('Per Invoice'!D$2:D$401,$U10)="","",INDEX('Per Invoice'!D$2:D$401,$U10))) | E10: =IF($U10="","",IF(INDEX('Per Invoice'!E$2:E$401,$U10)="","",INDEX('Per Invoice'!E$2:E$401,$U10))) | F10: =IF($U10="","",IF(INDEX('Per Invoice'!F$2:F$401,$U10)="","",INDEX('Per Invoice'!F$2:F$401,$U10))) | G10: =IF($U10="","",IF(INDEX('Per Invoice'!G$2:G$401,$U10)="","",INDEX('Per Invoice'!G$2:G$401,$U10))) | H10: =IF($U10="","",IF(INDEX('Per Invoice'!H$2:H$401,$U10)="","",INDEX('Per Invoice'!H$2:H$401,$U10))) | ... T10: =IF($U10="","",IF(INDEX('Per Invoice'!T$2:T$401,$U10)="","",INDEX('Per Invoice'!T$2:T$401,$U10))) | U10: =IFERROR(MATCH(Settings!$C$26&"|"&ROWS($U$2:$U10),'Per Invoice'!$V$2:$V$401,0),"")
A11: =IF($U11="","",IF(INDEX('Per Invoice'!A$2:A$401,$U11)="","",INDEX('Per Invoice'!A$2:A$401,$U11))) | B11: =IF($U11="","",IF(INDEX('Per Invoice'!B$2:B$401,$U11)="","",INDEX('Per Invoice'!B$2:B$401,$U11))) | C11: =IF($U11="","",IF(INDEX('Per Invoice'!C$2:C$401,$U11)="","",INDEX('Per Invoice'!C$2:C$401,$U11))) | D11: =IF($U11="","",IF(INDEX('Per Invoice'!D$2:D$401,$U11)="","",INDEX('Per Invoice'!D$2:D$401,$U11))) | E11: =IF($U11="","",IF(INDEX('Per Invoice'!E$2:E$401,$U11)="","",INDEX('Per Invoice'!E$2:E$401,$U11))) | F11: =IF($U11="","",IF(INDEX('Per Invoice'!F$2:F$401,$U11)="","",INDEX('Per Invoice'!F$2:F$401,$U11))) | G11: =IF($U11="","",IF(INDEX('Per Invoice'!G$2:G$401,$U11)="","",INDEX('Per Invoice'!G$2:G$401,$U11))) | H11: =IF($U11="","",IF(INDEX('Per Invoice'!H$2:H$401,$U11)="","",INDEX('Per Invoice'!H$2:H$401,$U11))) | ... T11: =IF($U11="","",IF(INDEX('Per Invoice'!T$2:T$401,$U11)="","",INDEX('Per Invoice'!T$2:T$401,$U11))) | U11: =IFERROR(MATCH(Settings!$C$26&"|"&ROWS($U$2:$U11),'Per Invoice'!$V$2:$V$401,0),"")
A12: =IF($U12="","",IF(INDEX('Per Invoice'!A$2:A$401,$U12)="","",INDEX('Per Invoice'!A$2:A$401,$U12))) | B12: =IF($U12="","",IF(INDEX('Per Invoice'!B$2:B$401,$U12)="","",INDEX('Per Invoice'!B$2:B$401,$U12))) | C12: =IF($U12="","",IF(INDEX('Per Invoice'!C$2:C$401,$U12)="","",INDEX('Per Invoice'!C$2:C$401,$U12))) | D12: =IF($U12="","",IF(INDEX('Per Invoice'!D$2:D$401,$U12)="","",INDEX('Per Invoice'!D$2:D$401,$U12))) | E12: =IF($U12="","",IF(INDEX('Per Invoice'!E$2:E$401,$U12)="","",INDEX('Per Invoice'!E$2:E$401,$U12))) | F12: =IF($U12="","",IF(INDEX('Per Invoice'!F$2:F$401,$U12)="","",INDEX('Per Invoice'!F$2:F$401,$U12))) | G12: =IF($U12="","",IF(INDEX('Per Invoice'!G$2:G$401,$U12)="","",INDEX('Per Invoice'!G$2:G$401,$U12))) | H12: =IF($U12="","",IF(INDEX('Per Invoice'!H$2:H$401,$U12)="","",INDEX('Per Invoice'!H$2:H$401,$U12))) | ... T12: =IF($U12="","",IF(INDEX('Per Invoice'!T$2:T$401,$U12)="","",INDEX('Per Invoice'!T$2:T$401,$U12))) | U12: =IFERROR(MATCH(Settings!$C$26&"|"&ROWS($U$2:$U12),'Per Invoice'!$V$2:$V$401,0),"")
A13: =IF($U13="","",IF(INDEX('Per Invoice'!A$2:A$401,$U13)="","",INDEX('Per Invoice'!A$2:A$401,$U13))) | B13: =IF($U13="","",IF(INDEX('Per Invoice'!B$2:B$401,$U13)="","",INDEX('Per Invoice'!B$2:B$401,$U13))) | C13: =IF($U13="","",IF(INDEX('Per Invoice'!C$2:C$401,$U13)="","",INDEX('Per Invoice'!C$2:C$401,$U13))) | D13: =IF($U13="","",IF(INDEX('Per Invoice'!D$2:D$401,$U13)="","",INDEX('Per Invoice'!D$2:D$401,$U13))) | E13: =IF($U13="","",IF(INDEX('Per Invoice'!E$2:E$401,$U13)="","",INDEX('Per Invoice'!E$2:E$401,$U13))) | F13: =IF($U13="","",IF(INDEX('Per Invoice'!F$2:F$401,$U13)="","",INDEX('Per Invoice'!F$2:F$401,$U13))) | G13: =IF($U13="","",IF(INDEX('Per Invoice'!G$2:G$401,$U13)="","",INDEX('Per Invoice'!G$2:G$401,$U13))) | H13: =IF($U13="","",IF(INDEX('Per Invoice'!H$2:H$401,$U13)="","",INDEX('Per Invoice'!H$2:H$401,$U13))) | ... T13: =IF($U13="","",IF(INDEX('Per Invoice'!T$2:T$401,$U13)="","",INDEX('Per Invoice'!T$2:T$401,$U13))) | U13: =IFERROR(MATCH(Settings!$C$26&"|"&ROWS($U$2:$U13),'Per Invoice'!$V$2:$V$401,0),"")
... A301: =IF($U301="","",IF(INDEX('Per Invoice'!A$2:A$401,$U301)="","",INDEX('Per Invoice'!A$2:A$401,$U301))) | B301: =IF($U301="","",IF(INDEX('Per Invoice'!B$2:B$401,$U301)="","",INDEX('Per Invoice'!B$2:B$401,$U301))) | C301: =IF($U301="","",IF(INDEX('Per Invoice'!C$2:C$401,$U301)="","",INDEX('Per Invoice'!C$2:C$401,$U301))) | D301: =IF($U301="","",IF(INDEX('Per Invoice'!D$2:D$401,$U301)="","",INDEX('Per Invoice'!D$2:D$401,$U301))) | E301: =IF($U301="","",IF(INDEX('Per Invoice'!E$2:E$401,$U301)="","",INDEX('Per Invoice'!E$2:E$401,$U301))) | F301: =IF($U301="","",IF(INDEX('Per Invoice'!F$2:F$401,$U301)="","",INDEX('Per Invoice'!F$2:F$401,$U301))) | G301: =IF($U301="","",IF(INDEX('Per Invoice'!G$2:G$401,$U301)="","",INDEX('Per Invoice'!G$2:G$401,$U301))) | H301: =IF($U301="","",IF(INDEX('Per Invoice'!H$2:H$401,$U301)="","",INDEX('Per Invoice'!H$2:H$401,$U301))) | ... T301: =IF($U301="","",IF(INDEX('Per Invoice'!T$2:T$401,$U301)="","",INDEX('Per Invoice'!T$2:T$401,$U301))) | U301: =IFERROR(MATCH(Settings!$C$26&"|"&ROWS($U$2:$U301),'Per Invoice'!$V$2:$V$401,0),"")

Sheet COPY 20 %
A1: Pos Reference | B1: Copay Tab (##) | C1: Invoice | D1: Insurance Company | E1: Name | F1: Card Number | G1: Co Payment % | H1: Co val | I1: Create Date | J1: Session | K1: IMP% | L1: IMP | M1: IMP VAL | N1: LOCAL% | O1: LOCAL | P1: LOCAL VAL | Q1: TOTAL VAL | R1: SUBTOTAL | S1: Grand Total | T1: NET | U1: Src Row (helper)
A2: =IF($U2="","",IF(INDEX('Per Invoice'!A$2:A$401,$U2)="","",INDEX('Per Invoice'!A$2:A$401,$U2))) | B2: =IF($U2="","",IF(INDEX('Per Invoice'!B$2:B$401,$U2)="","",INDEX('Per Invoice'!B$2:B$401,$U2))) | C2: =IF($U2="","",IF(INDEX('Per Invoice'!C$2:C$401,$U2)="","",INDEX('Per Invoice'!C$2:C$401,$U2))) | D2: =IF($U2="","",IF(INDEX('Per Invoice'!D$2:D$401,$U2)="","",INDEX('Per Invoice'!D$2:D$401,$U2))) | E2: =IF($U2="","",IF(INDEX('Per Invoice'!E$2:E$401,$U2)="","",INDEX('Per Invoice'!E$2:E$401,$U2))) | F2: =IF($U2="","",IF(INDEX('Per Invoice'!F$2:F$401,$U2)="","",INDEX('Per Invoice'!F$2:F$401,$U2))) | G2: =IF($U2="","",IF(INDEX('Per Invoice'!G$2:G$401,$U2)="","",INDEX('Per Invoice'!G$2:G$401,$U2))) | H2: =IF($U2="","",IF(INDEX('Per Invoice'!H$2:H$401,$U2)="","",INDEX('Per Invoice'!H$2:H$401,$U2))) | ... T2: =IF($U2="","",IF(INDEX('Per Invoice'!T$2:T$401,$U2)="","",INDEX('Per Invoice'!T$2:T$401,$U2))) | U2: =IFERROR(MATCH(Settings!$C$27&"|"&ROWS($U$2:$U2),'Per Invoice'!$V$2:$V$401,0),"")
A3: =IF($U3="","",IF(INDEX('Per Invoice'!A$2:A$401,$U3)="","",INDEX('Per Invoice'!A$2:A$401,$U3))) | B3: =IF($U3="","",IF(INDEX('Per Invoice'!B$2:B$401,$U3)="","",INDEX('Per Invoice'!B$2:B$401,$U3))) | C3: =IF($U3="","",IF(INDEX('Per Invoice'!C$2:C$401,$U3)="","",INDEX('Per Invoice'!C$2:C$401,$U3))) | D3: =IF($U3="","",IF(INDEX('Per Invoice'!D$2:D$401,$U3)="","",INDEX('Per Invoice'!D$2:D$401,$U3))) | E3: =IF($U3="","",IF(INDEX('Per Invoice'!E$2:E$401,$U3)="","",INDEX('Per Invoice'!E$2:E$401,$U3))) | F3: =IF($U3="","",IF(INDEX('Per Invoice'!F$2:F$401,$U3)="","",INDEX('Per Invoice'!F$2:F$401,$U3))) | G3: =IF($U3="","",IF(INDEX('Per Invoice'!G$2:G$401,$U3)="","",INDEX('Per Invoice'!G$2:G$401,$U3))) | H3: =IF($U3="","",IF(INDEX('Per Invoice'!H$2:H$401,$U3)="","",INDEX('Per Invoice'!H$2:H$401,$U3))) | ... T3: =IF($U3="","",IF(INDEX('Per Invoice'!T$2:T$401,$U3)="","",INDEX('Per Invoice'!T$2:T$401,$U3))) | U3: =IFERROR(MATCH(Settings!$C$27&"|"&ROWS($U$2:$U3),'Per Invoice'!$V$2:$V$401,0),"")
A4: =IF($U4="","",IF(INDEX('Per Invoice'!A$2:A$401,$U4)="","",INDEX('Per Invoice'!A$2:A$401,$U4))) | B4: =IF($U4="","",IF(INDEX('Per Invoice'!B$2:B$401,$U4)="","",INDEX('Per Invoice'!B$2:B$401,$U4))) | C4: =IF($U4="","",IF(INDEX('Per Invoice'!C$2:C$401,$U4)="","",INDEX('Per Invoice'!C$2:C$401,$U4))) | D4: =IF($U4="","",IF(INDEX('Per Invoice'!D$2:D$401,$U4)="","",INDEX('Per Invoice'!D$2:D$401,$U4))) | E4: =IF($U4="","",IF(INDEX('Per Invoice'!E$2:E$401,$U4)="","",INDEX('Per Invoice'!E$2:E$401,$U4))) | F4: =IF($U4="","",IF(INDEX('Per Invoice'!F$2:F$401,$U4)="","",INDEX('Per Invoice'!F$2:F$401,$U4))) | G4: =IF($U4="","",IF(INDEX('Per Invoice'!G$2:G$401,$U4)="","",INDEX('Per Invoice'!G$2:G$401,$U4))) | H4: =IF($U4="","",IF(INDEX('Per Invoice'!H$2:H$401,$U4)="","",INDEX('Per Invoice'!H$2:H$401,$U4))) | ... T4: =IF($U4="","",IF(INDEX('Per Invoice'!T$2:T$401,$U4)="","",INDEX('Per Invoice'!T$2:T$401,$U4))) | U4: =IFERROR(MATCH(Settings!$C$27&"|"&ROWS($U$2:$U4),'Per Invoice'!$V$2:$V$401,0),"")
A5: =IF($U5="","",IF(INDEX('Per Invoice'!A$2:A$401,$U5)="","",INDEX('Per Invoice'!A$2:A$401,$U5))) | B5: =IF($U5="","",IF(INDEX('Per Invoice'!B$2:B$401,$U5)="","",INDEX('Per Invoice'!B$2:B$401,$U5))) | C5: =IF($U5="","",IF(INDEX('Per Invoice'!C$2:C$401,$U5)="","",INDEX('Per Invoice'!C$2:C$401,$U5))) | D5: =IF($U5="","",IF(INDEX('Per Invoice'!D$2:D$401,$U5)="","",INDEX('Per Invoice'!D$2:D$401,$U5))) | E5: =IF($U5="","",IF(INDEX('Per Invoice'!E$2:E$401,$U5)="","",INDEX('Per Invoice'!E$2:E$401,$U5))) | F5: =IF($U5="","",IF(INDEX('Per Invoice'!F$2:F$401,$U5)="","",INDEX('Per Invoice'!F$2:F$401,$U5))) | G5: =IF($U5="","",IF(INDEX('Per Invoice'!G$2:G$401,$U5)="","",INDEX('Per Invoice'!G$2:G$401,$U5))) | H5: =IF($U5="","",IF(INDEX('Per Invoice'!H$2:H$401,$U5)="","",INDEX('Per Invoice'!H$2:H$401,$U5))) | ... T5: =IF($U5="","",IF(INDEX('Per Invoice'!T$2:T$401,$U5)="","",INDEX('Per Invoice'!T$2:T$401,$U5))) | U5: =IFERROR(MATCH(Settings!$C$27&"|"&ROWS($U$2:$U5),'Per Invoice'!$V$2:$V$401,0),"")
A6: =IF($U6="","",IF(INDEX('Per Invoice'!A$2:A$401,$U6)="","",INDEX('Per Invoice'!A$2:A$401,$U6))) | B6: =IF($U6="","",IF(INDEX('Per Invoice'!B$2:B$401,$U6)="","",INDEX('Per Invoice'!B$2:B$401,$U6))) | C6: =IF($U6="","",IF(INDEX('Per Invoice'!C$2:C$401,$U6)="","",INDEX('Per Invoice'!C$2:C$401,$U6))) | D6: =IF($U6="","",IF(INDEX('Per Invoice'!D$2:D$401,$U6)="","",INDEX('Per Invoice'!D$2:D$401,$U6))) | E6: =IF($U6="","",IF(INDEX('Per Invoice'!E$2:E$401,$U6)="","",INDEX('Per Invoice'!E$2:E$401,$U6))) | F6: =IF($U6="","",IF(INDEX('Per Invoice'!F$2:F$401,$U6)="","",INDEX('Per Invoice'!F$2:F$401,$U6))) | G6: =IF($U6="","",IF(INDEX('Per Invoice'!G$2:G$401,$U6)="","",INDEX('Per Invoice'!G$2:G$401,$U6))) | H6: =IF($U6="","",IF(INDEX('Per Invoice'!H$2:H$401,$U6)="","",INDEX('Per Invoice'!H$2:H$401,$U6))) | ... T6: =IF($U6="","",IF(INDEX('Per Invoice'!T$2:T$401,$U6)="","",INDEX('Per Invoice'!T$2:T$401,$U6))) | U6: =IFERROR(MATCH(Settings!$C$27&"|"&ROWS($U$2:$U6),'Per Invoice'!$V$2:$V$401,0),"")
A7: =IF($U7="","",IF(INDEX('Per Invoice'!A$2:A$401,$U7)="","",INDEX('Per Invoice'!A$2:A$401,$U7))) | B7: =IF($U7="","",IF(INDEX('Per Invoice'!B$2:B$401,$U7)="","",INDEX('Per Invoice'!B$2:B$401,$U7))) | C7: =IF($U7="","",IF(INDEX('Per Invoice'!C$2:C$401,$U7)="","",INDEX('Per Invoice'!C$2:C$401,$U7))) | D7: =IF($U7="","",IF(INDEX('Per Invoice'!D$2:D$401,$U7)="","",INDEX('Per Invoice'!D$2:D$401,$U7))) | E7: =IF($U7="","",IF(INDEX('Per Invoice'!E$2:E$401,$U7)="","",INDEX('Per Invoice'!E$2:E$401,$U7))) | F7: =IF($U7="","",IF(INDEX('Per Invoice'!F$2:F$401,$U7)="","",INDEX('Per Invoice'!F$2:F$401,$U7))) | G7: =IF($U7="","",IF(INDEX('Per Invoice'!G$2:G$401,$U7)="","",INDEX('Per Invoice'!G$2:G$401,$U7))) | H7: =IF($U7="","",IF(INDEX('Per Invoice'!H$2:H$401,$U7)="","",INDEX('Per Invoice'!H$2:H$401,$U7))) | ... T7: =IF($U7="","",IF(INDEX('Per Invoice'!T$2:T$401,$U7)="","",INDEX('Per Invoice'!T$2:T$401,$U7))) | U7: =IFERROR(MATCH(Settings!$C$27&"|"&ROWS($U$2:$U7),'Per Invoice'!$V$2:$V$401,0),"")
A8: =IF($U8="","",IF(INDEX('Per Invoice'!A$2:A$401,$U8)="","",INDEX('Per Invoice'!A$2:A$401,$U8))) | B8: =IF($U8="","",IF(INDEX('Per Invoice'!B$2:B$401,$U8)="","",INDEX('Per Invoice'!B$2:B$401,$U8))) | C8: =IF($U8="","",IF(INDEX('Per Invoice'!C$2:C$401,$U8)="","",INDEX('Per Invoice'!C$2:C$401,$U8))) | D8: =IF($U8="","",IF(INDEX('Per Invoice'!D$2:D$401,$U8)="","",INDEX('Per Invoice'!D$2:D$401,$U8))) | E8: =IF($U8="","",IF(INDEX('Per Invoice'!E$2:E$401,$U8)="","",INDEX('Per Invoice'!E$2:E$401,$U8))) | F8: =IF($U8="","",IF(INDEX('Per Invoice'!F$2:F$401,$U8)="","",INDEX('Per Invoice'!F$2:F$401,$U8))) | G8: =IF($U8="","",IF(INDEX('Per Invoice'!G$2:G$401,$U8)="","",INDEX('Per Invoice'!G$2:G$401,$U8))) | H8: =IF($U8="","",IF(INDEX('Per Invoice'!H$2:H$401,$U8)="","",INDEX('Per Invoice'!H$2:H$401,$U8))) | ... T8: =IF($U8="","",IF(INDEX('Per Invoice'!T$2:T$401,$U8)="","",INDEX('Per Invoice'!T$2:T$401,$U8))) | U8: =IFERROR(MATCH(Settings!$C$27&"|"&ROWS($U$2:$U8),'Per Invoice'!$V$2:$V$401,0),"")
A9: =IF($U9="","",IF(INDEX('Per Invoice'!A$2:A$401,$U9)="","",INDEX('Per Invoice'!A$2:A$401,$U9))) | B9: =IF($U9="","",IF(INDEX('Per Invoice'!B$2:B$401,$U9)="","",INDEX('Per Invoice'!B$2:B$401,$U9))) | C9: =IF($U9="","",IF(INDEX('Per Invoice'!C$2:C$401,$U9)="","",INDEX('Per Invoice'!C$2:C$401,$U9))) | D9: =IF($U9="","",IF(INDEX('Per Invoice'!D$2:D$401,$U9)="","",INDEX('Per Invoice'!D$2:D$401,$U9))) | E9: =IF($U9="","",IF(INDEX('Per Invoice'!E$2:E$401,$U9)="","",INDEX('Per Invoice'!E$2:E$401,$U9))) | F9: =IF($U9="","",IF(INDEX('Per Invoice'!F$2:F$401,$U9)="","",INDEX('Per Invoice'!F$2:F$401,$U9))) | G9: =IF($U9="","",IF(INDEX('Per Invoice'!G$2:G$401,$U9)="","",INDEX('Per Invoice'!G$2:G$401,$U9))) | H9: =IF($U9="","",IF(INDEX('Per Invoice'!H$2:H$401,$U9)="","",INDEX('Per Invoice'!H$2:H$401,$U9))) | ... T9: =IF($U9="","",IF(INDEX('Per Invoice'!T$2:T$401,$U9)="","",INDEX('Per Invoice'!T$2:T$401,$U9))) | U9: =IFERROR(MATCH(Settings!$C$27&"|"&ROWS($U$2:$U9),'Per Invoice'!$V$2:$V$401,0),"")
A10: =IF($U10="","",IF(INDEX('Per Invoice'!A$2:A$401,$U10)="","",INDEX('Per Invoice'!A$2:A$401,$U10))) | B10: =IF($U10="","",IF(INDEX('Per Invoice'!B$2:B$401,$U10)="","",INDEX('Per Invoice'!B$2:B$401,$U10))) | C10: =IF($U10="","",IF(INDEX('Per Invoice'!C$2:C$401,$U10)="","",INDEX('Per Invoice'!C$2:C$401,$U10))) | D10: =IF($U10="","",IF(INDEX('Per Invoice'!D$2:D$401,$U10)="","",INDEX('Per Invoice'!D$2:D$401,$U10))) | E10: =IF($U10="","",IF(INDEX('Per Invoice'!E$2:E$401,$U10)="","",INDEX('Per Invoice'!E$2:E$401,$U10))) | F10: =IF($U10="","",IF(INDEX('Per Invoice'!F$2:F$401,$U10)="","",INDEX('Per Invoice'!F$2:F$401,$U10))) | G10: =IF($U10="","",IF(INDEX('Per Invoice'!G$2:G$401,$U10)="","",INDEX('Per Invoice'!G$2:G$401,$U10))) | H10: =IF($U10="","",IF(INDEX('Per Invoice'!H$2:H$401,$U10)="","",INDEX('Per Invoice'!H$2:H$401,$U10))) | ... T10: =IF($U10="","",IF(INDEX('Per Invoice'!T$2:T$401,$U10)="","",INDEX('Per Invoice'!T$2:T$401,$U10))) | U10: =IFERROR(MATCH(Settings!$C$27&"|"&ROWS($U$2:$U10),'Per Invoice'!$V$2:$V$401,0),"")
A11: =IF($U11="","",IF(INDEX('Per Invoice'!A$2:A$401,$U11)="","",INDEX('Per Invoice'!A$2:A$401,$U11))) | B11: =IF($U11="","",IF(INDEX('Per Invoice'!B$2:B$401,$U11)="","",INDEX('Per Invoice'!B$2:B$401,$U11))) | C11: =IF($U11="","",IF(INDEX('Per Invoice'!C$2:C$401,$U11)="","",INDEX('Per Invoice'!C$2:C$401,$U11))) | D11: =IF($U11="","",IF(INDEX('Per Invoice'!D$2:D$401,$U11)="","",INDEX('Per Invoice'!D$2:D$401,$U11))) | E11: =IF($U11="","",IF(INDEX('Per Invoice'!E$2:E$401,$U11)="","",INDEX('Per Invoice'!E$2:E$401,$U11))) | F11: =IF($U11="","",IF(INDEX('Per Invoice'!F$2:F$401,$U11)="","",INDEX('Per Invoice'!F$2:F$401,$U11))) | G11: =IF($U11="","",IF(INDEX('Per Invoice'!G$2:G$401,$U11)="","",INDEX('Per Invoice'!G$2:G$401,$U11))) | H11: =IF($U11="","",IF(INDEX('Per Invoice'!H$2:H$401,$U11)="","",INDEX('Per Invoice'!H$2:H$401,$U11))) | ... T11: =IF($U11="","",IF(INDEX('Per Invoice'!T$2:T$401,$U11)="","",INDEX('Per Invoice'!T$2:T$401,$U11))) | U11: =IFERROR(MATCH(Settings!$C$27&"|"&ROWS($U$2:$U11),'Per Invoice'!$V$2:$V$401,0),"")
A12: =IF($U12="","",IF(INDEX('Per Invoice'!A$2:A$401,$U12)="","",INDEX('Per Invoice'!A$2:A$401,$U12))) | B12: =IF($U12="","",IF(INDEX('Per Invoice'!B$2:B$401,$U12)="","",INDEX('Per Invoice'!B$2:B$401,$U12))) | C12: =IF($U12="","",IF(INDEX('Per Invoice'!C$2:C$401,$U12)="","",INDEX('Per Invoice'!C$2:C$401,$U12))) | D12: =IF($U12="","",IF(INDEX('Per Invoice'!D$2:D$401,$U12)="","",INDEX('Per Invoice'!D$2:D$401,$U12))) | E12: =IF($U12="","",IF(INDEX('Per Invoice'!E$2:E$401,$U12)="","",INDEX('Per Invoice'!E$2:E$401,$U12))) | F12: =IF($U12="","",IF(INDEX('Per Invoice'!F$2:F$401,$U12)="","",INDEX('Per Invoice'!F$2:F$401,$U12))) | G12: =IF($U12="","",IF(INDEX('Per Invoice'!G$2:G$401,$U12)="","",INDEX('Per Invoice'!G$2:G$401,$U12))) | H12: =IF($U12="","",IF(INDEX('Per Invoice'!H$2:H$401,$U12)="","",INDEX('Per Invoice'!H$2:H$401,$U12))) | ... T12: =IF($U12="","",IF(INDEX('Per Invoice'!T$2:T$401,$U12)="","",INDEX('Per Invoice'!T$2:T$401,$U12))) | U12: =IFERROR(MATCH(Settings!$C$27&"|"&ROWS($U$2:$U12),'Per Invoice'!$V$2:$V$401,0),"")
A13: =IF($U13="","",IF(INDEX('Per Invoice'!A$2:A$401,$U13)="","",INDEX('Per Invoice'!A$2:A$401,$U13))) | B13: =IF($U13="","",IF(INDEX('Per Invoice'!B$2:B$401,$U13)="","",INDEX('Per Invoice'!B$2:B$401,$U13))) | C13: =IF($U13="","",IF(INDEX('Per Invoice'!C$2:C$401,$U13)="","",INDEX('Per Invoice'!C$2:C$401,$U13))) | D13: =IF($U13="","",IF(INDEX('Per Invoice'!D$2:D$401,$U13)="","",INDEX('Per Invoice'!D$2:D$401,$U13))) | E13: =IF($U13="","",IF(INDEX('Per Invoice'!E$2:E$401,$U13)="","",INDEX('Per Invoice'!E$2:E$401,$U13))) | F13: =IF($U13="","",IF(INDEX('Per Invoice'!F$2:F$401,$U13)="","",INDEX('Per Invoice'!F$2:F$401,$U13))) | G13: =IF($U13="","",IF(INDEX('Per Invoice'!G$2:G$401,$U13)="","",INDEX('Per Invoice'!G$2:G$401,$U13))) | H13: =IF($U13="","",IF(INDEX('Per Invoice'!H$2:H$401,$U13)="","",INDEX('Per Invoice'!H$2:H$401,$U13))) | ... T13: =IF($U13="","",IF(INDEX('Per Invoice'!T$2:T$401,$U13)="","",INDEX('Per Invoice'!T$2:T$401,$U13))) | U13: =IFERROR(MATCH(Settings!$C$27&"|"&ROWS($U$2:$U13),'Per Invoice'!$V$2:$V$401,0),"")
... A301: =IF($U301="","",IF(INDEX('Per Invoice'!A$2:A$401,$U301)="","",INDEX('Per Invoice'!A$2:A$401,$U301))) | B301: =IF($U301="","",IF(INDEX('Per Invoice'!B$2:B$401,$U301)="","",INDEX('Per Invoice'!B$2:B$401,$U301))) | C301: =IF($U301="","",IF(INDEX('Per Invoice'!C$2:C$401,$U301)="","",INDEX('Per Invoice'!C$2:C$401,$U301))) | D301: =IF($U301="","",IF(INDEX('Per Invoice'!D$2:D$401,$U301)="","",INDEX('Per Invoice'!D$2:D$401,$U301))) | E301: =IF($U301="","",IF(INDEX('Per Invoice'!E$2:E$401,$U301)="","",INDEX('Per Invoice'!E$2:E$401,$U301))) | F301: =IF($U301="","",IF(INDEX('Per Invoice'!F$2:F$401,$U301)="","",INDEX('Per Invoice'!F$2:F$401,$U301))) | G301: =IF($U301="","",IF(INDEX('Per Invoice'!G$2:G$401,$U301)="","",INDEX('Per Invoice'!G$2:G$401,$U301))) | H301: =IF($U301="","",IF(INDEX('Per Invoice'!H$2:H$401,$U301)="","",INDEX('Per Invoice'!H$2:H$401,$U301))) | ... T301: =IF($U301="","",IF(INDEX('Per Invoice'!T$2:T$401,$U301)="","",INDEX('Per Invoice'!T$2:T$401,$U301))) | U301: =IFERROR(MATCH(Settings!$C$27&"|"&ROWS($U$2:$U301),'Per Invoice'!$V$2:$V$401,0),"")

Sheet COPY 10 %
A1: Pos Reference | B1: Copay Tab (##) | C1: Invoice | D1: Insurance Company | E1: Name | F1: Card Number | G1: Co Payment % | H1: Co val | I1: Create Date | J1: Session | K1: IMP% | L1: IMP | M1: IMP VAL | N1: LOCAL% | O1: LOCAL | P1: LOCAL VAL | Q1: TOTAL VAL | R1: SUBTOTAL | S1: Grand Total | T1: NET | U1: Src Row (helper)
